Workbook
Name _25_de_agosto: 'RESUMEN TOTAL'!$A$4:$D$399
Name _25_de_agosto_3: 'RESUMEN TOTAL'!$A$4:$D$411
Name _30_mar: 'APAGADOS ANTENA'!#REF!
Name BONOMOcam: Hoja1!$B$2
Name CANTIDAD_DE_CAMARAS: 'RESUMEN TOTAL'!$B$1
Name COSEIDIcam: Hoja1!$B$4

Sheet RESUMEN TOTAL
A1: CANTIDAD DE CAMARAS | B1: =COUNTA(B5:B636) -> 550 | D1: PORCIENTO DE CAIDAS | L1: =(L3)/(L2+L3) -> 0.16510903 | M1: =(M3)/(M2+M3) -> 0 | N1: =(N3)/(N2+N3) -> 0 | O1: =(O3)/(O2+O3) -> 0 | P1: =(P3)/(P2+P3) -> 0 | Q1: =(Q3)/(Q2+Q3) -> 0 | R1: =(R3)/(R2+R3) -> 0 | S1: =(S3)/(S2+S3) -> 0 | ... X1: =(X3)/(X2+X3) -> 0 | Z1: =(Z3)/(Z2+Z3) -> 0 | AA1: =(AA3)/(AA2+AA3) -> 0 | AB1: =(AB3)/(AB2+AB3) -> 0 | AC1: =(AC3)/(AC2+AC3) -> 0 | AD1: =(AD3)/(AD2+AD3) -> 0 | AE1: =(AE3)/(AE2+AE3) -> 0 | AF1: =(AF3)/(AF2+AF3) -> 0 | AG1: =(AG3)/(AG2+AG3) -> 0 | ... AM1: =(AM3)/(AM2+AM3) -> 0
D2: FUNCIONAN | L2: 536 | M2: 536 | N2: 536 | O2: 536 | P2: 536 | Q2: 536 | R2: 536 | S2: 536 | T2: 536 | U2: 536 | V2: 536 | W2: 536 | X2: 536 | Y2: 536 | Z2: 536 | AA2: 536 | AB2: 536 | AC2: 536 | AD2: 536 | AE2: 536 | AF2: 536 | AG2: 536 | AH2: 536 | AI2: 536 | AJ2: 536 | AK2: 536 | AL2: 536 | AM2: 536
D3: CAIDAS | L3: =COUNTIF(L4:L636, "apagado") -> 106 | M3: =COUNTIF(M4:M636, "apagado") -> 0 | N3: =COUNTIF(N4:N636, "apagado") -> 0 | O3: =COUNTIF(O4:O636, "apagado") -> 0 | P3: =COUNTIF(P4:P636, "apagado") -> 0 | Q3: =COUNTIF(Q4:Q636, "apagado") -> 0 | R3: =COUNTIF(R4:R636, "apagado") -> 0 | S3: =COUNTIF(S4:S636, "apagado") -> 0 | ... W3: =COUNTIF(W4:W636, "apagado") -> 0 | X3: =COUNTIF(X4:X536, "apagado") -> 0 | Y3: =COUNTIF(Y4:Y536, "apagado") -> 0 | Z3: =COUNTIF(Z4:Z636, "apagado") -> 0 | AA3: =COUNTIF(AA4:AA636, "apagado") -> 0 | AB3: =COUNTIF(AB4:AB636, "apagado") -> 0 | AC3: =COUNTIF(AC4:AC636, "apagado") -> 0 | AD3: =COUNTIF(AD4:AD636, "apagado") -> 0 | AE3: =COUNTIF(AE4:AE636, "apagado") -> 0 | AF3: =COUNTIF(AF4:AF636, "apagado") -> 0 | AG3: =COUNTIF(AG4:AG636, "apagado") -> 0 | ... AM3: =COUNTIF(AM4:AM636, "apagado") -> 0
A4: Barrio | B4: [Denominacion] | C4: [Empresa Mantenimiento] | D4: [Ubicacion] | E4: [Tipo de Camara] | F4: [Tipo de Conexion] | G4: Destino | I4: DIAS FUNCIONANDO | J4: DIAS CAIDA | K4: EFECTIVIDAD | L4: 45689 | M4: 45690 | N4: 45691 | O4: 45692 | P4: 45693 | Q4: 45694 | R4: 45695 | S4: 45696 | T4: 45697 | U4: 45698 | V4: 11/2/20255 | W4: 45700 | X4: 45701 | Y4: 45702 | Z4: 45703 | AA4: 45704 | AB4: 45705 | AC4: 45706 | AD4: 45707 | AE4: 45708 | AF4: 45709 | AG4: 45710 | AH4: 45711 | AI4: 45712 | AJ4: 45713 | AK4: 45714 | AL4: 45715 | AM4: 45716
A5: ALTAMIRA | B5: ALT01 | C5: BONOMO | D5: Calchaqui y Sgto. Cabral | E5: Domo | F5: Fibra Optica | H5: 172.20.10.6 | I5: =COUNTIF(L5:AM5,"") -> 28 | J5: =COUNTIF(L5:AM5,"APAGADO") -> 0 | K5: =(I5)/(J5+I5) -> 1
A6: ALTAMIRA | B6: ALT02 | C6: BONOMO | D6: Calchaqui y Lope de Vega | E6: Domo | F6: PTO A FO | G6: CABRAL Y CALCHAQUI | H6: 172.20.12.218 | I6: =COUNTIF(L6:AM6,"") -> 28 | J6: =COUNTIF(L6:AM6,"APAGADO") -> 0 | K6: =(I6)/(J6+I6) -> 1
A7: ALTAMIRA | B7: ALT 03 | C7: BONOMO | D7: Bombero Galarza y Necochea | E7: Domo | F7: Fibra Optica | H7: 172.20.12.54 | I7: =COUNTIF(L7:AM7,"") -> 28 | J7: =COUNTIF(L7:AM7,"APAGADO") -> 0 | K7: =(I7)/(J7+I7) -> 1
A8: ALTAMIRA | B8: ALT 04 | C8: BONOMO | D8: Francia y Necochea | E8: Domo | F8: Fibra Optica | H8: 172.20.12.55 | I8: =COUNTIF(L8:AM8,"") -> 27 | J8: =COUNTIF(L8:AM8,"APAGADO") -> 1 | K8: =(I8)/(J8+I8) -> 0.96428571 | L8: APAGADO
A9: ALTAMIRA | B9: ALT05 | C9: BONOMO | D9: Av. Calchaqui y Bombero Galarza | E9: Domo | F9: PTO A FO | G9: NECOCHEA Y GALARZA | H9: 172.20.12.216 | I9: =COUNTIF(L9:AM9,"") -> 28 | J9: =COUNTIF(L9:AM9,"APAGADO") -> 0 | K9: =(I9)/(J9+I9) -> 1
A10: ALTAMIRA | B10: ALT 06 | C10: BONOMO | D10: LOPE DE VEGA Y NECOCHEA | E10: Domo | F10: PTO A FO | G10: NECOCHEA Y GALARZA | H10: 172.20.12.12 | I10: =COUNTIF(L10:AM10,"") -> 28 | J10: =COUNTIF(L10:AM10,"APAGADO") -> 0 | K10: =(I10)/(J10+I10) -> 1
A11: ALTAMIRA | B11: ALT07 | C11: BONOMO | D11: AV. CALCHAQUI Y AV. DEL TRABAJO | E11: DOMO | F11: PTO A FO | G11: CABRAL Y CALCHAQUI | H11: 172.20.10.57 | I11: =COUNTIF(L11:AM11,"") -> 28 | J11: =COUNTIF(L11:AM11,"APAGADO") -> 0 | K11: =(I11)/(J11+I11) -> 1
A12: ALTAMIRA | B12: ALT 08 | C12: BONOMO | D12: HUMAITA Y NECOCHEA | E12: DOMO | F12: Fibra Optica | H12: 172.20.11.215 | I12: =COUNTIF(L12:AM12,"") -> 28 | J12: =COUNTIF(L12:AM12,"APAGADO") -> 0 | K12: =(I12)/(J12+I12) -> 1
A13: ALTAMIRA | B13: ALT 09 | C13: BONOMO | D13: NECOCHEA Y CURUPAITY | E13: DOMO | F13: Fibra Optica | H13: 172.20.11.216 | I13: =COUNTIF(L13:AM13,"") -> 28 | J13: =COUNTIF(L13:AM13,"APAGADO") -> 0 | K13: =(I13)/(J13+I13) -> 1
A14: ALTAMIRA | B14: ALT 10 | C14: BONOMO | D14: Calchaqui y Francia | E14: Domo | F14: Radio | H14: 172.20.12.156 | I14: =COUNTIF(L14:AM14,"") -> 28 | J14: =COUNTIF(L14:AM14,"APAGADO") -> 0 | K14: =(I14)/(J14+I14) -> 1
A15: AGUSTIN RAMIREZ | B15: ARA 01 | C15: BONOMO | D15: Malambo y Tranquera | E15: Domo | F15: Fibra Optica | H15: 172.20.12.110 | I15: =COUNTIF(L15:AM15,"") -> 28 | J15: =COUNTIF(L15:AM15,"APAGADO") -> 0 | K15: =(I15)/(J15+I15) -> 1
A16: BELGRANO | B16: BEL 01 | C16: BONOMO | D16: San Martin y Dardo Rocha | E16: DOMO | F16: Fibra Optica | H16: 172.20.12.64 | I16: =COUNTIF(L16:AM16,"") -> 28 | J16: =COUNTIF(L16:AM16,"APAGADO") -> 0 | K16: =(I16)/(J16+I16) -> 1
A17: BELGRANO | B17: BEL 02 | C17: BONOMO | D17: Guardia vieja y Fronteriz | E17: DOMO | F17: Fibra Optica | H17: 172.20.10.117 | I17: =COUNTIF(L17:AM17,"") -> 28 | J17: =COUNTIF(L17:AM17,"APAGADO") -> 0 | K17: =(I17)/(J17+I17) -> 1
A18: BOSQUES CENTRO | B18: BOSQC 01 | C18: COSEIDI | D18: LUIS AGOTE E/DANUNCIO Y CAMPOAMOR | E18: Fija | F18: Radio | H18: 172.20.11.15 | I18: =COUNTIF(L18:AM18,"") -> 28 | J18: =COUNTIF(L18:AM18,"APAGADO") -> 0 | K18: =(I18)/(J18+I18) -> 1
A19: BOSQUES CENTRO | B19: BOSQC 02 | C19: COSEIDI | D19: LUIS AGOTE E/DANUNCIO Y CAMPOAMOR | E19: Fija | F19: Radio | H19: 172.20.11.16 | I19: =COUNTIF(L19:AM19,"") -> 28 | J19: =COUNTIF(L19:AM19,"APAGADO") -> 0 | K19: =(I19)/(J19+I19) -> 1
A20: BOSQUES CENTRO | B20: BOSQC 03 | C20: COSEIDI | D20: BENAVENTE Y LUIS AGOTE | E20: Fija | F20: Radio | H20: 172.20.11.13 | I20: =COUNTIF(L20:AM20,"") -> 28 | J20: =COUNTIF(L20:AM20,"APAGADO") -> 0 | K20: =(I20)/(J20+I20) -> 1
A21: BOSQUES CENTRO | B21: BOSQC 04 | C21: COSEIDI | D21: BENAVENTE Y LUIS AGOTE | E21: Fija | F21: Radio | H21: 172.20.11.113 | I21: =COUNTIF(L21:AM21,"") -> 28 | J21: =COUNTIF(L21:AM21,"APAGADO") -> 0 | K21: =(I21)/(J21+I21) -> 1
A22: BOSQUES CENTRO | B22: BOSQC 05 | C22: COSEIDI | D22: LUIS AGOTE Y RUTA 36 | E22: Fija | F22: Radio | H22: 172.20.11.17 | I22: =COUNTIF(L22:AM22,"") -> 28 | J22: =COUNTIF(L22:AM22,"APAGADO") -> 0 | K22: =(I22)/(J22+I22) -> 1
A23: BOSQUES CENTRO | B23: BOSQC 06 | C23: COSEIDI | D23: LUIS AGOTE Y RUTA 36 | E23: Fija | F23: Radio | H23: 172.20.11.18 | I23: =COUNTIF(L23:AM23,"") -> 28 | J23: =COUNTIF(L23:AM23,"APAGADO") -> 0 | K23: =(I23)/(J23+I23) -> 1
... A25: BOSQUES CENTRO | B25: PAVE01 | C25: BONOMO | D25: Touring Club y Ramallo | E25: Domo | F25: PTO A GPON | H25: 172.20.10.141 | I25: =COUNTIF(L25:AM25,"") -> 28 | J25: =COUNTIF(L25:AM25,"APAGADO") -> 0 | K25: =(I25)/(J25+I25) -> 1
A26: BOSQUES CENTRO | B26: PAVE02 | C26: COSEIDI | D26: Ramallo y Calingasta | F26: GPON | I26: =COUNTIF(L26:AM26,"") -> 28 | J26: =COUNTIF(L26:AM26,"APAGADO") -> 0 | K26: =(I26)/(J26+I26) -> 1
A27: CENTRO | B27: CEN01 | C27: BONOMO | D27: San Martin y 9 de Julio | E27: Fija | F27: Fibra Optica | H27: 172.20.11.10 | I27: =COUNTIF(L27:AM27,"") -> 27 | J27: =COUNTIF(L27:AM27,"APAGADO") -> 1 | K27: =(I27)/(J27+I27) -> 0.96428571 | L27: APAGADO
A28: CENTRO | B28: CEN02 | C28: BONOMO | D28: San Martin y Almafuerte | E28: Fija | F28: Fibra Optica | H28: 172.20.11.11 | I28: =COUNTIF(L28:AM28,"") -> 27 | J28: =COUNTIF(L28:AM28,"APAGADO") -> 1 | K28: =(I28)/(J28+I28) -> 0.96428571 | L28: APAGADO
A29: CENTRO | B29: CEN03 | C29: BONOMO | D29: San Martin y Sallares | E29: Domo | F29: Fibra Optica | H29: 172.20.12.30 | I29: =COUNTIF(L29:AM29,"") -> 28 | J29: =COUNTIF(L29:AM29,"APAGADO") -> 0 | K29: =(I29)/(J29+I29) -> 1
A30: CENTRO | B30: CEN04 | C30: BONOMO | D30: San Martin y Contreras | E30: Domo | F30: Fibra Optica | H30: 172.20.12.29 | I30: =COUNTIF(L30:AM30,"") -> 28 | J30: =COUNTIF(L30:AM30,"APAGADO") -> 0 | K30: =(I30)/(J30+I30) -> 1
A31: CENTRO | B31: CEN 05 | C31: BONOMO | D31: Bocuzzi e/España y San Martin | E31: DOMO | F31: Fibra Optica | H31: 172.20.10.200 | I31: =COUNTIF(L31:AM31,"") -> 28 | J31: =COUNTIF(L31:AM31,"APAGADO") -> 0 | K31: =(I31)/(J31+I31) -> 1
A32: CENTRO | B32: CEN06 | C32: BONOMO | D32: Monteagudo y A.del Valle | E32: Fija | F32: Fibra Optica | H32: 172.20.10.02 | I32: =COUNTIF(L32:AM32,"") -> 28 | J32: =COUNTIF(L32:AM32,"APAGADO") -> 0 | K32: =(I32)/(J32+I32) -> 1
A33: CENTRO | B33: CEN07 | C33: BONOMO | D33: San Martin y Guemes | E33: DOMO | F33: Fibra Optica | H33: 172.20.11.20 | I33: =COUNTIF(L33:AM33,"") -> 28 | J33: =COUNTIF(L33:AM33,"APAGADO") -> 0 | K33: =(I33)/(J33+I33) -> 1
A34: CENTRO | B34: CEN08 | C34: BONOMO | D34: San Martin y Pte.Peron | E34: Domo | F34: Fibra Optica | H34: 172.20.11.21 | I34: =COUNTIF(L34:AM34,"") -> 28 | J34: =COUNTIF(L34:AM34,"APAGADO") -> 0 | K34: =(I34)/(J34+I34) -> 1
A35: CENTRO | B35: CEN09 | C35: BONOMO | D35: Chacabuco y 25 de Mayo | E35: Domo | F35: Fibra Optica | H35: 172.20.11.22 | I35: =COUNTIF(L35:AM35,"") -> 28 | J35: =COUNTIF(L35:AM35,"APAGADO") -> 0 | K35: =(I35)/(J35+I35) -> 1
A36: CENTRO | B36: CEN10 | C36: BONOMO | D36: Monteagudo y Pte. Peron | E36: Domo | F36: Fibra Optica | H36: 172.20.11.23 | I36: =COUNTIF(L36:AM36,"") -> 28 | J36: =COUNTIF(L36:AM36,"APAGADO") -> 0 | K36: =(I36)/(J36+I36) -> 1
A37: CENTRO | B37: CEN11 | C37: BONOMO | D37: Monteagudo y Bocuzzi | E37: Domo | F37: Fibra Optica | H37: 172.20.10.24 | I37: =COUNTIF(L37:AM37,"") -> 28 | J37: =COUNTIF(L37:AM37,"APAGADO") -> 0 | K37: =(I37)/(J37+I37) -> 1
A38: CENTRO | B38: CEN 12 | C38: BONOMO | D38: Monteagudo y Mitre | E38: Domo | F38: Fibra Optica | H38: 172.20.10.23 | I38: =COUNTIF(L38:AM38,"") -> 28 | J38: =COUNTIF(L38:AM38,"APAGADO") -> 0 | K38: =(I38)/(J38+I38) -> 1
A39: CENTRO | B39: CEN 13 | C39: BONOMO | D39: 25 de Mayo y Maipu | E39: DOMO | F39: GPON | H39: 172.20.10.20 | I39: =COUNTIF(L39:AM39,"") -> 28 | J39: =COUNTIF(L39:AM39,"APAGADO") -> 0 | K39: =(I39)/(J39+I39) -> 1
A40: CENTRO | B40: CEN14 | C40: BONOMO | D40: Pte.Peron e/Pringles y Brown | E40: Domo | F40: Fibra Optica | H40: 172.20.10.94 | I40: =COUNTIF(L40:AM40,"") -> 28 | J40: =COUNTIF(L40:AM40,"APAGADO") -> 0 | K40: =(I40)/(J40+I40) -> 1
... A42: CENTRO | B42: CEN16 | C42: BONOMO | D42: San Martin y Pte. Peron | E42: Fija | F42: Fibra Optica | H42: 172.20.12.36 | I42: =COUNTIF(L42:AM42,"") -> 28 | J42: =COUNTIF(L42:AM42,"APAGADO") -> 0 | K42: =(I42)/(J42+I42) -> 1
...

Sheet ESTADISTICA
A1: ='RESUMEN TOTAL'!A4 -> Barrio | B1: ='RESUMEN TOTAL'!B4 -> [Denominacion] | C1: ='RESUMEN TOTAL'!D4 -> [Ubicacion] | D1: ='RESUMEN TOTAL'!E4 -> [Tipo de Camara] | E1: ='RESUMEN TOTAL'!F4 -> [Tipo de Conexion] | F1: ='RESUMEN TOTAL'!L4 -> 45689 | G1: ='RESUMEN TOTAL'!M4 -> 45690 | H1: ='RESUMEN TOTAL'!N4 -> 45691 | I1: ='RESUMEN TOTAL'!O4 -> 45692 | J1: ='RESUMEN TOTAL'!P4 -> 45693 | K1: ='RESUMEN TOTAL'!Q4 -> 45694 | L1: ='RESUMEN TOTAL'!R4 -> 45695 | M1: ='RESUMEN TOTAL'!S4 -> 45696 | ... AG1: ='RESUMEN TOTAL'!AM4 -> 45716
A2: ='RESUMEN TOTAL'!A5 -> ALTAMIRA | B2: ='RESUMEN TOTAL'!B5 -> ALT01 | C2: ='RESUMEN TOTAL'!D5 -> Calchaqui y Sgto. Cabral | D2: ='RESUMEN TOTAL'!E5 -> Domo | E2: ='RESUMEN TOTAL'!F5 -> Fibra Optica | F2: ='RESUMEN TOTAL'!L5 -> 0 | G2: ='RESUMEN TOTAL'!M5 -> 0 | H2: ='RESUMEN TOTAL'!N5 -> 0 | I2: ='RESUMEN TOTAL'!O5 -> 0 | J2: ='RESUMEN TOTAL'!P5 -> 0 | K2: ='RESUMEN TOTAL'!Q5 -> 0 | L2: ='RESUMEN TOTAL'!R5 -> 0 | M2: ='RESUMEN TOTAL'!S5 -> 0 | ... AG2: ='RESUMEN TOTAL'!AM5 -> 0
A3: ='RESUMEN TOTAL'!A6 -> ALTAMIRA | B3: ='RESUMEN TOTAL'!B6 -> ALT02 | C3: ='RESUMEN TOTAL'!D6 -> Calchaqui y Lope de Vega | D3: ='RESUMEN TOTAL'!E6 -> Domo | E3: ='RESUMEN TOTAL'!F6 -> PTO A FO | F3: ='RESUMEN TOTAL'!L6 -> 0 | G3: ='RESUMEN TOTAL'!M6 -> 0 | H3: ='RESUMEN TOTAL'!N6 -> 0 | I3: ='RESUMEN TOTAL'!O6 -> 0 | J3: ='RESUMEN TOTAL'!P6 -> 0 | K3: ='RESUMEN TOTAL'!Q6 -> 0 | L3: ='RESUMEN TOTAL'!R6 -> 0 | M3: ='RESUMEN TOTAL'!S6 -> 0 | ... AG3: ='RESUMEN TOTAL'!AM6 -> 0
A4: ='RESUMEN TOTAL'!A7 -> ALTAMIRA | B4: ='RESUMEN TOTAL'!B7 -> ALT 03 | C4: ='RESUMEN TOTAL'!D7 -> Bombero Galarza y Necochea | D4: ='RESUMEN TOTAL'!E7 -> Domo | E4: ='RESUMEN TOTAL'!F7 -> Fibra Optica | F4: ='RESUMEN TOTAL'!L7 -> 0 | G4: ='RESUMEN TOTAL'!M7 -> 0 | H4: ='RESUMEN TOTAL'!N7 -> 0 | I4: ='RESUMEN TOTAL'!O7 -> 0 | J4: ='RESUMEN TOTAL'!P7 -> 0 | K4: ='RESUMEN TOTAL'!Q7 -> 0 | L4: ='RESUMEN TOTAL'!R7 -> 0 | M4: ='RESUMEN TOTAL'!S7 -> 0 | ... AG4: ='RESUMEN TOTAL'!AM7 -> 0
A5: ='RESUMEN TOTAL'!A8 -> ALTAMIRA | B5: ='RESUMEN TOTAL'!B8 -> ALT 04 | C5: ='RESUMEN TOTAL'!D8 -> Francia y Necochea | D5: ='RESUMEN TOTAL'!E8 -> Domo | E5: ='RESUMEN TOTAL'!F8 -> Fibra Optica | F5: ='RESUMEN TOTAL'!L8 -> APAGADO | G5: ='RESUMEN TOTAL'!M8 -> 0 | H5: ='RESUMEN TOTAL'!N8 -> 0 | I5: ='RESUMEN TOTAL'!O8 -> 0 | J5: ='RESUMEN TOTAL'!P8 -> 0 | K5: ='RESUMEN TOTAL'!Q8 -> 0 | L5: ='RESUMEN TOTAL'!R8 -> 0 | M5: ='RESUMEN TOTAL'!S8 -> 0 | ... AG5: ='RESUMEN TOTAL'!AM8 -> 0
A6: ='RESUMEN TOTAL'!A9 -> ALTAMIRA | B6: ='RESUMEN TOTAL'!B9 -> ALT05 | C6: ='RESUMEN TOTAL'!D9 -> Av. Calchaqui y Bombero Galarza | D6: ='RESUMEN TOTAL'!E9 -> Domo | E6: ='RESUMEN TOTAL'!F9 -> PTO A FO | F6: ='RESUMEN TOTAL'!L9 -> 0 | G6: ='RESUMEN TOTAL'!M9 -> 0 | H6: ='RESUMEN TOTAL'!N9 -> 0 | I6: ='RESUMEN TOTAL'!O9 -> 0 | J6: ='RESUMEN TOTAL'!P9 -> 0 | K6: ='RESUMEN TOTAL'!Q9 -> 0 | L6: ='RESUMEN TOTAL'!R9 -> 0 | M6: ='RESUMEN TOTAL'!S9 -> 0 | ... AG6: ='RESUMEN TOTAL'!AM9 -> 0
A7: ='RESUMEN TOTAL'!A10 -> ALTAMIRA | B7: ='RESUMEN TOTAL'!B10 -> ALT 06 | C7: ='RESUMEN TOTAL'!D10 -> LOPE DE VEGA Y NECOCHEA | D7: ='RESUMEN TOTAL'!E10 -> Domo | E7: ='RESUMEN TOTAL'!F10 -> PTO A FO | F7: ='RESUMEN TOTAL'!L10 -> 0 | G7: ='RESUMEN TOTAL'!M10 -> 0 | H7: ='RESUMEN TOTAL'!N10 -> 0 | I7: ='RESUMEN TOTAL'!O10 -> 0 | J7: ='RESUMEN TOTAL'!P10 -> 0 | K7: ='RESUMEN TOTAL'!Q10 -> 0 | L7: ='RESUMEN TOTAL'!R10 -> 0 | M7: ='RESUMEN TOTAL'!S10 -> 0 | ... AG7: ='RESUMEN TOTAL'!AM10 -> 0
A8: ='RESUMEN TOTAL'!A11 -> ALTAMIRA | B8: ='RESUMEN TOTAL'!B11 -> ALT07 | C8: ='RESUMEN TOTAL'!D11 -> AV. CALCHAQUI Y AV. DEL TRABAJO | D8: ='RESUMEN TOTAL'!E11 -> DOMO | E8: ='RESUMEN TOTAL'!F11 -> PTO A FO | F8: ='RESUMEN TOTAL'!L11 -> 0 | G8: ='RESUMEN TOTAL'!M11 -> 0 | H8: ='RESUMEN TOTAL'!N11 -> 0 | I8: ='RESUMEN TOTAL'!O11 -> 0 | J8: ='RESUMEN TOTAL'!P11 -> 0 | K8: ='RESUMEN TOTAL'!Q11 -> 0 | L8: ='RESUMEN TOTAL'!R11 -> 0 | M8: ='RESUMEN TOTAL'!S11 -> 0 | ... AG8: ='RESUMEN TOTAL'!AM11 -> 0
A9: ='RESUMEN TOTAL'!A12 -> ALTAMIRA | B9: ='RESUMEN TOTAL'!B12 -> ALT 08 | C9: ='RESUMEN TOTAL'!D12 -> HUMAITA Y NECOCHEA | D9: ='RESUMEN TOTAL'!E12 -> DOMO | E9: ='RESUMEN TOTAL'!F12 -> Fibra Optica | F9: ='RESUMEN TOTAL'!L12 -> 0 | G9: ='RESUMEN TOTAL'!M12 -> 0 | H9: ='RESUMEN TOTAL'!N12 -> 0 | I9: ='RESUMEN TOTAL'!O12 -> 0 | J9: ='RESUMEN TOTAL'!P12 -> 0 | K9: ='RESUMEN TOTAL'!Q12 -> 0 | L9: ='RESUMEN TOTAL'!R12 -> 0 | M9: ='RESUMEN TOTAL'!S12 -> 0 | ... AG9: ='RESUMEN TOTAL'!AM12 -> 0
A10: ='RESUMEN TOTAL'!A13 -> ALTAMIRA | B10: ='RESUMEN TOTAL'!B13 -> ALT 09 | C10: ='RESUMEN TOTAL'!D13 -> NECOCHEA Y CURUPAITY | D10: ='RESUMEN TOTAL'!E13 -> DOMO | E10: ='RESUMEN TOTAL'!F13 -> Fibra Optica | F10: ='RESUMEN TOTAL'!L13 -> 0 | G10: ='RESUMEN TOTAL'!M13 -> 0 | H10: ='RESUMEN TOTAL'!N13 -> 0 | I10: ='RESUMEN TOTAL'!O13 -> 0 | J10: ='RESUMEN TOTAL'!P13 -> 0 | K10: ='RESUMEN TOTAL'!Q13 -> 0 | L10: ='RESUMEN TOTAL'!R13 -> 0 | M10: ='RESUMEN TOTAL'!S13 -> 0 | ... AG10: ='RESUMEN TOTAL'!AM13 -> 0
A11: ='RESUMEN TOTAL'!A14 -> ALTAMIRA | B11: ='RESUMEN TOTAL'!B14 -> ALT 10 | C11: ='RESUMEN TOTAL'!D14 -> Calchaqui y Francia | D11: ='RESUMEN TOTAL'!E14 -> Domo | E11: ='RESUMEN TOTAL'!F14 -> Radio | F11: ='RESUMEN TOTAL'!L14 -> 0 | G11: ='RESUMEN TOTAL'!M14 -> 0 | H11: ='RESUMEN TOTAL'!N14 -> 0 | I11: ='RESUMEN TOTAL'!O14 -> 0 | J11: ='RESUMEN TOTAL'!P14 -> 0 | K11: ='RESUMEN TOTAL'!Q14 -> 0 | L11: ='RESUMEN TOTAL'!R14 -> 0 | M11: ='RESUMEN TOTAL'!S14 -> 0 | ... AG11: ='RESUMEN TOTAL'!AM14 -> 0
A12: ='RESUMEN TOTAL'!A15 -> AGUSTIN RAMIREZ | B12: ='RESUMEN TOTAL'!B15 -> ARA 01 | C12: ='RESUMEN TOTAL'!D15 -> Malambo y Tranquera | D12: ='RESUMEN TOTAL'!E15 -> Domo | E12: ='RESUMEN TOTAL'!F15 -> Fibra Optica | F12: ='RESUMEN TOTAL'!L15 -> 0 | G12: ='RESUMEN TOTAL'!M15 -> 0 | H12: ='RESUMEN TOTAL'!N15 -> 0 | I12: ='RESUMEN TOTAL'!O15 -> 0 | J12: ='RESUMEN TOTAL'!P15 -> 0 | K12: ='RESUMEN TOTAL'!Q15 -> 0 | L12: ='RESUMEN TOTAL'!R15 -> 0 | M12: ='RESUMEN TOTAL'!S15 -> 0 | ... AG12: ='RESUMEN TOTAL'!AM15 -> 0
... A20: ='RESUMEN TOTAL'!A23 -> BOSQUES CENTRO | B20: ='RESUMEN TOTAL'!B23 -> BOSQC 06 | C20: ='RESUMEN TOTAL'!D23 -> LUIS AGOTE Y RUTA 36 | D20: ='RESUMEN TOTAL'!E23 -> Fija | E20: ='RESUMEN TOTAL'!F23 -> Radio | F20: ='RESUMEN TOTAL'!L23 -> 0 | G20: ='RESUMEN TOTAL'!M23 -> 0 | H20: ='RESUMEN TOTAL'!N23 -> 0 | I20: ='RESUMEN TOTAL'!O23 -> 0 | J20: ='RESUMEN TOTAL'!P23 -> 0 | K20: ='RESUMEN TOTAL'!Q23 -> 0 | L20: ='RESUMEN TOTAL'!R23 -> 0 | M20: ='RESUMEN TOTAL'!S23 -> 0 | ... AG20: ='RESUMEN TOTAL'!AM23 -> 0
A21: ='RESUMEN TOTAL'!A27 -> CENTRO | B21: ='RESUMEN TOTAL'!B27 -> CEN01 | C21: ='RESUMEN TOTAL'!D27 -> San Martin y 9 de Julio | D21: ='RESUMEN TOTAL'!E27 -> Fija | E21: ='RESUMEN TOTAL'!F27 -> Fibra Optica | F21: ='RESUMEN TOTAL'!L27 -> APAGADO | G21: ='RESUMEN TOTAL'!M27 -> 0 | H21: ='RESUMEN TOTAL'!N27 -> 0 | I21: ='RESUMEN TOTAL'!O27 -> 0 | J21: ='RESUMEN TOTAL'!P27 -> 0 | K21: ='RESUMEN TOTAL'!Q27 -> 0 | L21: ='RESUMEN TOTAL'!R27 -> 0 | M21: ='RESUMEN TOTAL'!S27 -> 0 | ... AG21: ='RESUMEN TOTAL'!AM27 -> 0
A22: ='RESUMEN TOTAL'!A28 -> CENTRO | B22: ='RESUMEN TOTAL'!B28 -> CEN02 | C22: ='RESUMEN TOTAL'!D28 -> San Martin y Almafuerte | D22: ='RESUMEN TOTAL'!E28 -> Fija | E22: ='RESUMEN TOTAL'!F28 -> Fibra Optica | F22: ='RESUMEN TOTAL'!L28 -> APAGADO | G22: ='RESUMEN TOTAL'!M28 -> 0 | H22: ='RESUMEN TOTAL'!N28 -> 0 | I22: ='RESUMEN TOTAL'!O28 -> 0 | J22: ='RESUMEN TOTAL'!P28 -> 0 | K22: ='RESUMEN TOTAL'!Q28 -> 0 | L22: ='RESUMEN TOTAL'!R28 -> 0 | M22: ='RESUMEN TOTAL'!S28 -> 0 | ... AG22: ='RESUMEN TOTAL'!AM28 -> 0
A23: ='RESUMEN TOTAL'!A29 -> CENTRO | B23: ='RESUMEN TOTAL'!B29 -> CEN03 | C23: ='RESUMEN TOTAL'!D29 -> San Martin y Sallares | D23: ='RESUMEN TOTAL'!E29 -> Domo | E23: ='RESUMEN TOTAL'!F29 -> Fibra Optica | F23: ='RESUMEN TOTAL'!L29 -> 0 | G23: ='RESUMEN TOTAL'!M29 -> 0 | H23: ='RESUMEN TOTAL'!N29 -> 0 | I23: ='RESUMEN TOTAL'!O29 -> 0 | J23: ='RESUMEN TOTAL'!P29 -> 0 | K23: ='RESUMEN TOTAL'!Q29 -> 0 | L23: ='RESUMEN TOTAL'!R29 -> 0 | M23: ='RESUMEN TOTAL'!S29 -> 0 | ... AG23: ='RESUMEN TOTAL'!AM29 -> 0
A24: ='RESUMEN TOTAL'!A30 -> CENTRO | B24: ='RESUMEN TOTAL'!B30 -> CEN04 | C24: ='RESUMEN TOTAL'!D30 -> San Martin y Contreras | D24: ='RESUMEN TOTAL'!E30 -> Domo | E24: ='RESUMEN TOTAL'!F30 -> Fibra Optica | F24: ='RESUMEN TOTAL'!L30 -> 0 | G24: ='RESUMEN TOTAL'!M30 -> 0 | H24: ='RESUMEN TOTAL'!N30 -> 0 | I24: ='RESUMEN TOTAL'!O30 -> 0 | J24: ='RESUMEN TOTAL'!P30 -> 0 | K24: ='RESUMEN TOTAL'!Q30 -> 0 | L24: ='RESUMEN TOTAL'!R30 -> 0 | M24: ='RESUMEN TOTAL'!S30 -> 0 | ... AG24: ='RESUMEN TOTAL'!AM30 -> 0
A25: ='RESUMEN TOTAL'!A31 -> CENTRO | B25: ='RESUMEN TOTAL'!B31 -> CEN 05 | C25: ='RESUMEN TOTAL'!D31 -> Bocuzzi e/España y San Martin | D25: ='RESUMEN TOTAL'!E31 -> DOMO | E25: ='RESUMEN TOTAL'!F31 -> Fibra Optica | F25: ='RESUMEN TOTAL'!L31 -> 0 | G25: ='RESUMEN TOTAL'!M31 -> 0 | H25: ='RESUMEN TOTAL'!N31 -> 0 | I25: ='RESUMEN TOTAL'!O31 -> 0 | J25: ='RESUMEN TOTAL'!P31 -> 0 | K25: ='RESUMEN TOTAL'!Q31 -> 0 | L25: ='RESUMEN TOTAL'!R31 -> 0 | M25: ='RESUMEN TOTAL'!S31 -> 0 | ... AG25: ='RESUMEN TOTAL'!AM31 -> 0
A26: ='RESUMEN TOTAL'!A32 -> CENTRO | B26: ='RESUMEN TOTAL'!B32 -> CEN06 | C26: ='RESUMEN TOTAL'!D32 -> Monteagudo y A.del Valle | D26: ='RESUMEN TOTAL'!E32 -> Fija | E26: ='RESUMEN TOTAL'!F32 -> Fibra Optica | F26: ='RESUMEN TOTAL'!L32 -> 0 | G26: ='RESUMEN TOTAL'!M32 -> 0 | H26: ='RESUMEN TOTAL'!N32 -> 0 | I26: ='RESUMEN TOTAL'!O32 -> 0 | J26: ='RESUMEN TOTAL'!P32 -> 0 | K26: ='RESUMEN TOTAL'!Q32 -> 0 | L26: ='RESUMEN TOTAL'!R32 -> 0 | M26: ='RESUMEN TOTAL'!S32 -> 0 | ... AG26: ='RESUMEN TOTAL'!AM32 -> 0
A27: ='RESUMEN TOTAL'!A33 -> CENTRO | B27: ='RESUMEN TOTAL'!B33 -> CEN07 | C27: ='RESUMEN TOTAL'!D33 -> San Martin y Guemes | D27: ='RESUMEN TOTAL'!E33 -> DOMO | E27: ='RESUMEN TOTAL'!F33 -> Fibra Optica | F27: ='RESUMEN TOTAL'!L33 -> 0 | G27: ='RESUMEN TOTAL'!M33 -> 0 | H27: ='RESUMEN TOTAL'!N33 -> 0 | I27: ='RESUMEN TOTAL'!O33 -> 0 | J27: ='RESUMEN TOTAL'!P33 -> 0 | K27: ='RESUMEN TOTAL'!Q33 -> 0 | L27: ='RESUMEN TOTAL'!R33 -> 0 | M27: ='RESUMEN TOTAL'!S33 -> 0 | ... AG27: ='RESUMEN TOTAL'!AM33 -> 0
A28: ='RESUMEN TOTAL'!A34 -> CENTRO | B28: ='RESUMEN TOTAL'!B34 -> CEN08 | C28: ='RESUMEN TOTAL'!D34 -> San Martin y Pte.Peron | D28: ='RESUMEN TOTAL'!E34 -> Domo | E28: ='RESUMEN TOTAL'!F34 -> Fibra Optica | F28: ='RESUMEN TOTAL'!L34 -> 0 | G28: ='RESUMEN TOTAL'!M34 -> 0 | H28: ='RESUMEN TOTAL'!N34 -> 0 | I28: ='RESUMEN TOTAL'!O34 -> 0 | J28: ='RESUMEN TOTAL'!P34 -> 0 | K28: ='RESUMEN TOTAL'!Q34 -> 0 | L28: ='RESUMEN TOTAL'!R34 -> 0 | M28: ='RESUMEN TOTAL'!S34 -> 0 | ... AG28: ='RESUMEN TOTAL'!AM34 -> 0
A29: ='RESUMEN TOTAL'!A35 -> CENTRO | B29: ='RESUMEN TOTAL'!B35 -> CEN09 | C29: ='RESUMEN TOTAL'!D35 -> Chacabuco y 25 de Mayo | D29: ='RESUMEN TOTAL'!E35 -> Domo | E29: ='RESUMEN TOTAL'!F35 -> Fibra Optica | F29: ='RESUMEN TOTAL'!L35 -> 0 | G29: ='RESUMEN TOTAL'!M35 -> 0 | H29: ='RESUMEN TOTAL'!N35 -> 0 | I29: ='RESUMEN TOTAL'!O35 -> 0 | J29: ='RESUMEN TOTAL'!P35 -> 0 | K29: ='RESUMEN TOTAL'!Q35 -> 0 | L29: ='RESUMEN TOTAL'!R35 -> 0 | M29: ='RESUMEN TOTAL'!S35 -> 0 | ... AG29: ='RESUMEN TOTAL'!AM35 -> 0
A30: ='RESUMEN TOTAL'!A36 -> CENTRO | B30: ='RESUMEN TOTAL'!B36 -> CEN10 | C30: ='RESUMEN TOTAL'!D36 -> Monteagudo y Pte. Peron | D30: ='RESUMEN TOTAL'!E36 -> Domo | E30: ='RESUMEN TOTAL'!F36 -> Fibra Optica | F30: ='RESUMEN TOTAL'!L36 -> 0 | G30: ='RESUMEN TOTAL'!M36 -> 0 | H30: ='RESUMEN TOTAL'!N36 -> 0 | I30: ='RESUMEN TOTAL'!O36 -> 0 | J30: ='RESUMEN TOTAL'!P36 -> 0 | K30: ='RESUMEN TOTAL'!Q36 -> 0 | L30: ='RESUMEN TOTAL'!R36 -> 0 | M30: ='RESUMEN TOTAL'!S36 -> 0 | ... AG30: ='RESUMEN TOTAL'!AM36 -> 0
A31: ='RESUMEN TOTAL'!A37 -> CENTRO | B31: ='RESUMEN TOTAL'!B37 -> CEN11 | C31: ='RESUMEN TOTAL'!D37 -> Monteagudo y Bocuzzi | D31: ='RESUMEN TOTAL'!E37 -> Domo | E31: ='RESUMEN TOTAL'!F37 -> Fibra Optica | F31: ='RESUMEN TOTAL'!L37 -> 0 | G31: ='RESUMEN TOTAL'!M37 -> 0 | H31: ='RESUMEN TOTAL'!N37 -> 0 | I31: ='RESUMEN TOTAL'!O37 -> 0 | J31: ='RESUMEN TOTAL'!P37 -> 0 | K31: ='RESUMEN TOTAL'!Q37 -> 0 | L31: ='RESUMEN TOTAL'!R37 -> 0 | M31: ='RESUMEN TOTAL'!S37 -> 0 | ... AG31: ='RESUMEN TOTAL'!AM37 -> 0
A32: ='RESUMEN TOTAL'!A38 -> CENTRO | B32: ='RESUMEN TOTAL'!B38 -> CEN 12 | C32: ='RESUMEN TOTAL'!D38 -> Monteagudo y Mitre | D32: ='RESUMEN TOTAL'!E38 -> Domo | E32: ='RESUMEN TOTAL'!F38 -> Fibra Optica | F32: ='RESUMEN TOTAL'!L38 -> 0 | G32: ='RESUMEN TOTAL'!M38 -> 0 | H32: ='RESUMEN TOTAL'!N38 -> 0 | I32: ='RESUMEN TOTAL'!O38 -> 0 | J32: ='RESUMEN TOTAL'!P38 -> 0 | K32: ='RESUMEN TOTAL'!Q38 -> 0 | L32: ='RESUMEN TOTAL'!R38 -> 0 | M32: ='RESUMEN TOTAL'!S38 -> 0 | ... AG32: ='RESUMEN TOTAL'!AM38 -> 0
... A107: ='RESUMEN TOTAL'!A113 -> CENTRO | B107: ='RESUMEN TOTAL'!B113 -> CEN87 | C107: ='RESUMEN TOTAL'!D113 -> 25 DE MAYO Y NEWBERY | D107: ='RESUMEN TOTAL'!E113 -> Domo | E107: ='RESUMEN TOTAL'!F113 -> GPON | F107: ='RESUMEN TOTAL'!L113 -> APAGADO | G107: ='RESUMEN TOTAL'!M113 -> 0 | H107: ='RESUMEN TOTAL'!N113 -> 0 | I107: ='RESUMEN TOTAL'!O113 -> 0 | J107: ='RESUMEN TOTAL'!P113 -> 0 | K107: ='RESUMEN TOTAL'!Q113 -> 0 | L107: ='RESUMEN TOTAL'!R113 -> 0 | M107: ='RESUMEN TOTAL'!S113 -> 0 | ... AG107: ='RESUMEN TOTAL'!AM113 -> 0
A108: ='RESUMEN TOTAL'!A115 -> SAN NICOLAS | B108: ='RESUMEN TOTAL'!B115 -> CHA01 | C108: ='RESUMEN TOTAL'!D115 -> Novak y Pte Illia | D108: ='RESUMEN TOTAL'!E115 -> Domo | E108: ='RESUMEN TOTAL'!F115 -> Radio | F108: ='RESUMEN TOTAL'!L115 -> 0 | G108: ='RESUMEN TOTAL'!M115 -> 0 | H108: ='RESUMEN TOTAL'!N115 -> 0 | I108: ='RESUMEN TOTAL'!O115 -> 0 | J108: ='RESUMEN TOTAL'!P115 -> 0 | K108: ='RESUMEN TOTAL'!Q115 -> 0 | L108: ='RESUMEN TOTAL'!R115 -> 0 | M108: ='RESUMEN TOTAL'!S115 -> 0 | ... AG108: ='RESUMEN TOTAL'!AM115 -> 0
A109: ='RESUMEN TOTAL'!A116 -> CHACABUCO | B109: ='RESUMEN TOTAL'!B116 -> CHA02 | C109: ='RESUMEN TOTAL'!D116 -> Pte. Illia y Posadas | D109: ='RESUMEN TOTAL'!E116 -> Domo | E109: ='RESUMEN TOTAL'!F116 -> Radio | F109: ='RESUMEN TOTAL'!L116 -> 0 | G109: ='RESUMEN TOTAL'!M116 -> 0 | H109: ='RESUMEN TOTAL'!N116 -> 0 | I109: ='RESUMEN TOTAL'!O116 -> 0 | J109: ='RESUMEN TOTAL'!P116 -> 0 | K109: ='RESUMEN TOTAL'!Q116 -> 0 | L109: ='RESUMEN TOTAL'!R116 -> 0 | M109: ='RESUMEN TOTAL'!S116 -> 0 | ... AG109: ='RESUMEN TOTAL'!AM116 -> 0
A110: ='RESUMEN TOTAL'!A117 -> CHACABUCO | B110: ='RESUMEN TOTAL'!B117 -> CHA03 | C110: ='RESUMEN TOTAL'!D117 -> MAIPU Y ALVAREZ THOMAS | D110: ='RESUMEN TOTAL'!E117 -> DOMO | E110: ='RESUMEN TOTAL'!F117 -> Fibra Optica | F110: ='RESUMEN TOTAL'!L117 -> 0 | G110: ='RESUMEN TOTAL'!M117 -> 0 | H110: ='RESUMEN TOTAL'!N117 -> 0 | I110: ='RESUMEN TOTAL'!O117 -> 0 | J110: ='RESUMEN TOTAL'!P117 -> 0 | K110: ='RESUMEN TOTAL'!Q117 -> 0 | L110: ='RESUMEN TOTAL'!R117 -> 0 | M110: ='RESUMEN TOTAL'!S117 -> 0 | ... AG110: ='RESUMEN TOTAL'!AM117 -> 0
A111: ='RESUMEN TOTAL'!A118 -> CHACABUCO | B111: ='RESUMEN TOTAL'!B118 -> CHA04 | C111: ='RESUMEN TOTAL'!D118 -> ESTADOS UNIDOS DE A. E ILLIA | D111: ='RESUMEN TOTAL'!E118 -> DOMO | E111: ='RESUMEN TOTAL'!F118 -> Fibra Optica | F111: ='RESUMEN TOTAL'!L118 -> 0 | G111: ='RESUMEN TOTAL'!M118 -> 0 | H111: ='RESUMEN TOTAL'!N118 -> 0 | I111: ='RESUMEN TOTAL'!O118 -> 0 | J111: ='RESUMEN TOTAL'!P118 -> 0 | K111: ='RESUMEN TOTAL'!Q118 -> 0 | L111: ='RESUMEN TOTAL'!R118 -> 0 | M111: ='RESUMEN TOTAL'!S118 -> 0 | ... AG111: ='RESUMEN TOTAL'!AM118 -> 0
A112: ='RESUMEN TOTAL'!A119 -> VILLA MONICA NUEVA | B112: ='RESUMEN TOTAL'!B119 -> COL01 | C112: ='RESUMEN TOTAL'!D119 -> Eva Peron y Cariboni | D112: ='RESUMEN TOTAL'!E119 -> Domo | E112: ='RESUMEN TOTAL'!F119 -> Radio | F112: ='RESUMEN TOTAL'!L119 -> 0 | G112: ='RESUMEN TOTAL'!M119 -> 0 | H112: ='RESUMEN TOTAL'!N119 -> 0 | I112: ='RESUMEN TOTAL'!O119 -> 0 | J112: ='RESUMEN TOTAL'!P119 -> 0 | K112: ='RESUMEN TOTAL'!Q119 -> 0 | L112: ='RESUMEN TOTAL'!R119 -> 0 | M112: ='RESUMEN TOTAL'!S119 -> 0 | ... AG112: ='RESUMEN TOTAL'!AM119 -> 0
A113: ='RESUMEN TOTAL'!A120 -> LA COLORADA ESTE | B113: ='RESUMEN TOTAL'!B120 -> COL02 | C113: ='RESUMEN TOTAL'!D120 -> Av. Eva Peron y Pompeya | D113: ='RESUMEN TOTAL'!E120 -> Domo | E113: ='RESUMEN TOTAL'!F120 -> Radio | F113: ='RESUMEN TOTAL'!L120 -> 0 | G113: ='RESUMEN TOTAL'!M120 -> 0 | H113: ='RESUMEN TOTAL'!N120 -> 0 | I113: ='RESUMEN TOTAL'!O120 -> 0 | J113: ='RESUMEN TOTAL'!P120 -> 0 | K113: ='RESUMEN TOTAL'!Q120 -> 0 | L113: ='RESUMEN TOTAL'!R120 -> 0 | M113: ='RESUMEN TOTAL'!S120 -> 0 | ... AG113: ='RESUMEN TOTAL'!AM120 -> 0
A114: ='RESUMEN TOTAL'!A121 -> LA COLORADA ESTE | B114: ='RESUMEN TOTAL'!B121 -> COL 03 | C114: ='RESUMEN TOTAL'!D121 -> CARIBONI Y LA ANCIANIDAD | D114: ='RESUMEN TOTAL'!E121 -> DOMO | E114: ='RESUMEN TOTAL'!F121 -> Radio | F114: ='RESUMEN TOTAL'!L121 -> 0 | G114: ='RESUMEN TOTAL'!M121 -> 0 | H114: ='RESUMEN TOTAL'!N121 -> 0 | I114: ='RESUMEN TOTAL'!O121 -> 0 | J114: ='RESUMEN TOTAL'!P121 -> 0 | K114: ='RESUMEN TOTAL'!Q121 -> 0 | L114: ='RESUMEN TOTAL'!R121 -> 0 | M114: ='RESUMEN TOTAL'!S121 -> 0 | ... AG114: ='RESUMEN TOTAL'!AM121 -> 0
A115: ='RESUMEN TOTAL'!A122 -> LA COLORADA ESTE | B115: ='RESUMEN TOTAL'!B122 -> COL 04 | C115: ='RESUMEN TOTAL'!D122 -> EVA PERON Y SAVIO | D115: ='RESUMEN TOTAL'!E122 -> Domo | E115: ='RESUMEN TOTAL'!F122 -> Fibra Optica | F115: ='RESUMEN TOTAL'!L122 -> 0 | G115: ='RESUMEN TOTAL'!M122 -> 0 | H115: ='RESUMEN TOTAL'!N122 -> 0 | I115: ='RESUMEN TOTAL'!O122 -> 0 | J115: ='RESUMEN TOTAL'!P122 -> 0 | K115: ='RESUMEN TOTAL'!Q122 -> 0 | L115: ='RESUMEN TOTAL'!R122 -> 0 | M115: ='RESUMEN TOTAL'!S122 -> 0 | ... AG115: ='RESUMEN TOTAL'!AM122 -> 0
A116: ='RESUMEN TOTAL'!A123 -> DON JOSE | B116: ='RESUMEN TOTAL'!B123 -> DJO01 | C116: ='RESUMEN TOTAL'!D123 -> Monteverde y Donato Alvarez | D116: ='RESUMEN TOTAL'!E123 -> Domo | E116: ='RESUMEN TOTAL'!F123 -> Radio | F116: ='RESUMEN TOTAL'!L123 -> 0 | G116: ='RESUMEN TOTAL'!M123 -> 0 | H116: ='RESUMEN TOTAL'!N123 -> 0 | I116: ='RESUMEN TOTAL'!O123 -> 0 | J116: ='RESUMEN TOTAL'!P123 -> 0 | K116: ='RESUMEN TOTAL'!Q123 -> 0 | L116: ='RESUMEN TOTAL'!R123 -> 0 | M116: ='RESUMEN TOTAL'!S123 -> 0 | ... AG116: ='RESUMEN TOTAL'!AM123 -> 0
A117: ='RESUMEN TOTAL'!A124 -> DON JOSE | B117: ='RESUMEN TOTAL'!B124 -> DJO 02 (fija 1) | C117: ='RESUMEN TOTAL'!D124 -> DONATO ALVAREZ Y EL APERO | D117: ='RESUMEN TOTAL'!E124 -> Fija | E117: ='RESUMEN TOTAL'!F124 -> PTO A FO | F117: ='RESUMEN TOTAL'!L124 -> 0 | G117: ='RESUMEN TOTAL'!M124 -> 0 | H117: ='RESUMEN TOTAL'!N124 -> 0 | I117: ='RESUMEN TOTAL'!O124 -> 0 | J117: ='RESUMEN TOTAL'!P124 -> 0 | K117: ='RESUMEN TOTAL'!Q124 -> 0 | L117: ='RESUMEN TOTAL'!R124 -> 0 | M117: ='RESUMEN TOTAL'!S124 -> 0 | ... AG117: ='RESUMEN TOTAL'!AM124 -> 0
A118: ='RESUMEN TOTAL'!A125 -> DON JOSE | B118: ='RESUMEN TOTAL'!B125 -> DJO 03 (fija 2) | C118: ='RESUMEN TOTAL'!D125 -> DONATO ALVAREZ Y EL APERO | D118: ='RESUMEN TOTAL'!E125 -> Fija | E118: ='RESUMEN TOTAL'!F125 -> PTO A FO | F118: ='RESUMEN TOTAL'!L125 -> 0 | G118: ='RESUMEN TOTAL'!M125 -> 0 | H118: ='RESUMEN TOTAL'!N125 -> 0 | I118: ='RESUMEN TOTAL'!O125 -> 0 | J118: ='RESUMEN TOTAL'!P125 -> 0 | K118: ='RESUMEN TOTAL'!Q125 -> 0 | L118: ='RESUMEN TOTAL'!R125 -> 0 | M118: ='RESUMEN TOTAL'!S125 -> 0 | ... AG118: ='RESUMEN TOTAL'!AM125 -> 0
A119: ='RESUMEN TOTAL'!A126 -> DON JOSE | B119: ='RESUMEN TOTAL'!B126 -> DJO 04 (Fija 1) | C119: ='RESUMEN TOTAL'!D126 -> MONTEVERDE Y EL INDIO | D119: ='RESUMEN TOTAL'!E126 -> Fija | E119: ='RESUMEN TOTAL'!F126 -> PTO A FO | F119: ='RESUMEN TOTAL'!L126 -> APAGADO | G119: ='RESUMEN TOTAL'!M126 -> 0 | H119: ='RESUMEN TOTAL'!N126 -> 0 | I119: ='RESUMEN TOTAL'!O126 -> 0 | J119: ='RESUMEN TOTAL'!P126 -> 0 | K119: ='RESUMEN TOTAL'!Q126 -> 0 | L119: ='RESUMEN TOTAL'!R126 -> 0 | M119: ='RESUMEN TOTAL'!S126 -> 0 | ... AG119: ='RESUMEN TOTAL'!AM126 -> 0
... A123: ='RESUMEN TOTAL'!A130 -> DON ORIONE | B123: ='RESUMEN TOTAL'!B130 -> DORIO1 | C123: ='RESUMEN TOTAL'!D130 -> AV Bosques Y Theran | D123: ='RESUMEN TOTAL'!E130 -> Domo | E123: ='RESUMEN TOTAL'!F130 -> GPON | F123: ='RESUMEN TOTAL'!L130 -> 0 | G123: ='RESUMEN TOTAL'!M130 -> 0 | H123: ='RESUMEN TOTAL'!N130 -> 0 | I123: ='RESUMEN TOTAL'!O130 -> 0 | J123: ='RESUMEN TOTAL'!P130 -> 0 | K123: ='RESUMEN TOTAL'!Q130 -> 0 | L123: ='RESUMEN TOTAL'!R130 -> 0 | M123: ='RESUMEN TOTAL'!S130 -> 0 | ... AG123: ='RESUMEN TOTAL'!AM130 -> 0
A124: ='RESUMEN TOTAL'!A132 -> EL PARQUE | B124: ='RESUMEN TOTAL'!B132 -> EPQ 01 | C124: ='RESUMEN TOTAL'!D132 -> 1282 Y GRIERSON | D124: ='RESUMEN TOTAL'!E132 -> DOMO | E124: ='RESUMEN TOTAL'!F132 -> Fibra Optica | F124: ='RESUMEN TOTAL'!L132 -> 0 | G124: ='RESUMEN TOTAL'!M132 -> 0 | H124: ='RESUMEN TOTAL'!N132 -> 0 | I124: ='RESUMEN TOTAL'!O132 -> 0 | J124: ='RESUMEN TOTAL'!P132 -> 0 | K124: ='RESUMEN TOTAL'!Q132 -> 0 | L124: ='RESUMEN TOTAL'!R132 -> 0 | M124: ='RESUMEN TOTAL'!S132 -> 0 | ... AG124: ='RESUMEN TOTAL'!AM132 -> 0
...

Sheet APAGADOS
E1: APAGADOS | F1: =COUNTIF(F3:F404, "APAGADO") -> 51 | G1: =COUNTIF(G3:G404, "APAGADO") -> 0 | H1: =COUNTIF(H3:H504, "APAGADO") -> 0 | I1: =COUNTIF(I3:I404, "APAGADO") -> 0 | J1: =COUNTIF(J3:J404, "APAGADO") -> 0 | K1: =COUNTIF(K3:K404, "APAGADO") -> 0 | L1: =COUNTIF(L3:L404, "APAGADO") -> 0 | M1: =COUNTIF(M3:M404, "APAGADO") -> 0 | N1: =COUNTIF(N3:N404, "APAGADO") -> 0 | O1: =COUNTIF(O3:O404, "APAGADO") -> 0 | P1: =COUNTIF(P3:P404, "APAGADO") -> 0 | ... AD1: =COUNTIF(AD3:AD404, "APAGADO") -> 0 | AE1: =COUNTIF(AE3:AE504, "APAGADO") -> 0 | AF1: =COUNTIF(AF3:AF404, "APAGADO") -> 0 | AG1: =COUNTIF(AG3:AG404, "APAGADO") -> 0
A2: =ESTADISTICA!A1 -> Barrio | B2: =ESTADISTICA!B1 -> [Denominacion] | C2: =ESTADISTICA!C1 -> [Ubicacion] | D2: =ESTADISTICA!D1 -> [Tipo de Camara] | E2: =ESTADISTICA!E1 -> [Tipo de Conexion] | F2: =ESTADISTICA!F1 -> 45689 | G2: =ESTADISTICA!G1 -> 45690 | H2: =ESTADISTICA!H1 -> 45691 | ... AG2: =ESTADISTICA!AG1 -> 45716
A3: =ESTADISTICA!A2 -> ALTAMIRA | B3: =ESTADISTICA!B2 -> ALT01 | C3: =ESTADISTICA!C2 -> Calchaqui y Sgto. Cabral | D3: =ESTADISTICA!D2 -> Domo | E3: =ESTADISTICA!E2 -> Fibra Optica | F3: =ESTADISTICA!F2 -> 0 | G3: =ESTADISTICA!G2 -> 0 | H3: =ESTADISTICA!H2 -> 0 | ... AG3: =ESTADISTICA!AG2 -> 0
A4: =ESTADISTICA!A3 -> ALTAMIRA | B4: =ESTADISTICA!B3 -> ALT02 | C4: =ESTADISTICA!C3 -> Calchaqui y Lope de Vega | D4: =ESTADISTICA!D3 -> Domo | E4: =ESTADISTICA!E3 -> PTO A FO | F4: =ESTADISTICA!F3 -> 0 | G4: =ESTADISTICA!G3 -> 0 | H4: =ESTADISTICA!H3 -> 0 | ... AG4: =ESTADISTICA!AG3 -> 0
A5: =ESTADISTICA!A4 -> ALTAMIRA | B5: =ESTADISTICA!B4 -> ALT 03 | C5: =ESTADISTICA!C4 -> Bombero Galarza y Necochea | D5: =ESTADISTICA!D4 -> Domo | E5: =ESTADISTICA!E4 -> Fibra Optica | F5: =ESTADISTICA!F4 -> 0 | G5: =ESTADISTICA!G4 -> 0 | H5: =ESTADISTICA!H4 -> 0 | ... AG5: =ESTADISTICA!AG4 -> 0
A6: =ESTADISTICA!A5 -> ALTAMIRA | B6: =ESTADISTICA!B5 -> ALT 04 | C6: =ESTADISTICA!C5 -> Francia y Necochea | D6: =ESTADISTICA!D5 -> Domo | E6: =ESTADISTICA!E5 -> Fibra Optica | F6: =ESTADISTICA!F5 -> APAGADO | G6: =ESTADISTICA!G5 -> 0 | H6: =ESTADISTICA!H5 -> 0 | ... AG6: =ESTADISTICA!AG5 -> 0
A7: =ESTADISTICA!A6 -> ALTAMIRA | B7: =ESTADISTICA!B6 -> ALT05 | C7: =ESTADISTICA!C6 -> Av. Calchaqui y Bombero Galarza | D7: =ESTADISTICA!D6 -> Domo | E7: =ESTADISTICA!E6 -> PTO A FO | F7: =ESTADISTICA!F6 -> 0 | G7: =ESTADISTICA!G6 -> 0 | H7: =ESTADISTICA!H6 -> 0 | ... AG7: =ESTADISTICA!AG6 -> 0
A8: =ESTADISTICA!A7 -> ALTAMIRA | B8: =ESTADISTICA!B7 -> ALT 06 | C8: =ESTADISTICA!C7 -> LOPE DE VEGA Y NECOCHEA | D8: =ESTADISTICA!D7 -> Domo | E8: =ESTADISTICA!E7 -> PTO A FO | F8: =ESTADISTICA!F7 -> 0 | G8: =ESTADISTICA!G7 -> 0 | H8: =ESTADISTICA!H7 -> 0 | ... AG8: =ESTADISTICA!AG7 -> 0
A9: =ESTADISTICA!A8 -> ALTAMIRA | B9: =ESTADISTICA!B8 -> ALT07 | C9: =ESTADISTICA!C8 -> AV. CALCHAQUI Y AV. DEL TRABAJO | D9: =ESTADISTICA!D8 -> DOMO | E9: =ESTADISTICA!E8 -> PTO A FO | F9: =ESTADISTICA!F8 -> 0 | G9: =ESTADISTICA!G8 -> 0 | H9: =ESTADISTICA!H8 -> 0 | ... AG9: =ESTADISTICA!AG8 -> 0
A10: =ESTADISTICA!A9 -> ALTAMIRA | B10: =ESTADISTICA!B9 -> ALT 08 | C10: =ESTADISTICA!C9 -> HUMAITA Y NECOCHEA | D10: =ESTADISTICA!D9 -> DOMO | E10: =ESTADISTICA!E9 -> Fibra Optica | F10: =ESTADISTICA!F9 -> 0 | G10: =ESTADISTICA!G9 -> 0 | H10: =ESTADISTICA!H9 -> 0 | ... AG10: =ESTADISTICA!AG9 -> 0
A11: =ESTADISTICA!A10 -> ALTAMIRA | B11: =ESTADISTICA!B10 -> ALT 09 | C11: =ESTADISTICA!C10 -> NECOCHEA Y CURUPAITY | D11: =ESTADISTICA!D10 -> DOMO | E11: =ESTADISTICA!E10 -> Fibra Optica | F11: =ESTADISTICA!F10 -> 0 | G11: =ESTADISTICA!G10 -> 0 | H11: =ESTADISTICA!H10 -> 0 | ... AG11: =ESTADISTICA!AG10 -> 0
A12: =ESTADISTICA!A11 -> ALTAMIRA | B12: =ESTADISTICA!B11 -> ALT 10 | C12: =ESTADISTICA!C11 -> Calchaqui y Francia | D12: =ESTADISTICA!D11 -> Domo | E12: =ESTADISTICA!E11 -> Radio | F12: =ESTADISTICA!F11 -> 0 | G12: =ESTADISTICA!G11 -> 0 | H12: =ESTADISTICA!H11 -> 0 | ... AG12: =ESTADISTICA!AG11 -> 0
A13: =ESTADISTICA!A12 -> AGUSTIN RAMIREZ | B13: =ESTADISTICA!B12 -> ARA 01 | C13: =ESTADISTICA!C12 -> Malambo y Tranquera | D13: =ESTADISTICA!D12 -> Domo | E13: =ESTADISTICA!E12 -> Fibra Optica | F13: =ESTADISTICA!F12 -> 0 | G13: =ESTADISTICA!G12 -> 0 | H13: =ESTADISTICA!H12 -> 0 | ... AG13: =ESTADISTICA!AG12 -> 0
... A124: =ESTADISTICA!A123 -> DON ORIONE | B124: =ESTADISTICA!B123 -> DORIO1 | C124: =ESTADISTICA!C123 -> AV Bosques Y Theran | D124: =ESTADISTICA!D123 -> Domo | E124: =ESTADISTICA!E123 -> GPON | F124: =ESTADISTICA!F123 -> 0 | G124: =ESTADISTICA!G123 -> 0 | H124: =ESTADISTICA!H123 -> 0 | ... AG124: =ESTADISTICA!AG123 -> 0
A125: DON ORIONE | B125: DORI02 | C125: QUINQUELA MARTIN Y AV BOSQUES | F125: =ESTADISTICA!F124 -> 0 | G125: =ESTADISTICA!G124 -> 0 | H125: =ESTADISTICA!H124 -> 0 | I125: =ESTADISTICA!I124 -> 0 | J125: =ESTADISTICA!J124 -> 0 | K125: =ESTADISTICA!K124 -> 0 | L125: =ESTADISTICA!L124 -> 0 | M125: =ESTADISTICA!M124 -> 0 | ... AG125: =ESTADISTICA!AG124 -> 0
A126: =ESTADISTICA!A124 -> EL PARQUE | B126: =ESTADISTICA!B124 -> EPQ 01 | C126: =ESTADISTICA!C124 -> 1282 Y GRIERSON | D126: =ESTADISTICA!D124 -> DOMO | E126: =ESTADISTICA!E124 -> Fibra Optica | F126: =ESTADISTICA!F124 -> 0 | G126: =ESTADISTICA!G124 -> 0 | H126: =ESTADISTICA!H124 -> 0 | ... AG126: =ESTADISTICA!AG124 -> 0
A127: =ESTADISTICA!A125 -> EL PARQUE | B127: =ESTADISTICA!B125 -> EPQ 02 | C127: =ESTADISTICA!C125 -> 1282 Y MASSE | D127: =ESTADISTICA!D125 -> DOMO | E127: =ESTADISTICA!E125 -> Fibra Optica | F127: =ESTADISTICA!F125 -> 0 | G127: =ESTADISTICA!G125 -> 0 | H127: =ESTADISTICA!H125 -> 0 | ... AG127: =ESTADISTICA!AG125 -> 0
A128: =ESTADISTICA!A126 -> EL PARQUE | B128: =ESTADISTICA!B126 -> EPQ 03 | C128: =ESTADISTICA!C126 -> 1282 Y RP 36 | D128: =ESTADISTICA!D126 -> Domo | E128: =ESTADISTICA!E126 -> Fibra Optica | F128: =ESTADISTICA!F126 -> APAGADO | G128: =ESTADISTICA!G126 -> 0 | H128: =ESTADISTICA!H126 -> 0 | ... AG128: =ESTADISTICA!AG126 -> 0
A129: =ESTADISTICA!A127 -> EL PARQUE | B129: =ESTADISTICA!B127 -> EPQ 04 | C129: =ESTADISTICA!C127 -> 1282 Y MORENO | D129: =ESTADISTICA!D127 -> DOMO | E129: =ESTADISTICA!E127 -> Fibra Optica | F129: =ESTADISTICA!F127 -> 0 | G129: =ESTADISTICA!G127 -> 0 | H129: =ESTADISTICA!H127 -> 0 | ... AG129: =ESTADISTICA!AG127 -> 0
A130: =ESTADISTICA!A128 -> LA ESMERALDA | B130: =ESTADISTICA!B128 -> ESM01 | C130: =ESTADISTICA!C128 -> Cabello y Brasil | D130: =ESTADISTICA!D128 -> Domo | E130: =ESTADISTICA!E128 -> Radio | F130: =ESTADISTICA!F128 -> 0 | G130: =ESTADISTICA!G128 -> 0 | H130: =ESTADISTICA!H128 -> 0 | ... AG130: =ESTADISTICA!AG128 -> 0
A131: =ESTADISTICA!A129 -> SAN JORGE | B131: =ESTADISTICA!B129 -> ESM02 | C131: =ESTADISTICA!C129 -> Novak y Cabello | D131: =ESTADISTICA!D129 -> Domo | E131: =ESTADISTICA!E129 -> PTO A FO | F131: =ESTADISTICA!F129 -> 0 | G131: =ESTADISTICA!G129 -> 0 | H131: =ESTADISTICA!H129 -> 0 | ... AG131: =ESTADISTICA!AG129 -> 0
A132: =ESTADISTICA!A130 -> SAN JORGE | B132: =ESTADISTICA!B130 -> ESM03 | C132: =ESTADISTICA!C130 -> Novak y Humahuaca | D132: =ESTADISTICA!D130 -> DOMO | E132: =ESTADISTICA!E130 -> PTO A FO | F132: =ESTADISTICA!F130 -> 0 | G132: =ESTADISTICA!G130 -> 0 | H132: =ESTADISTICA!H130 -> 0 | ... AG132: =ESTADISTICA!AG130 -> 0
A133: =ESTADISTICA!A131 -> LA ESMERALDA | B133: =ESTADISTICA!B131 -> ESM04 | C133: =ESTADISTICA!C131 -> Basualdo y Bengochea | D133: =ESTADISTICA!D131 -> Domo | E133: =ESTADISTICA!E131 -> Fibra Optica | F133: =ESTADISTICA!F131 -> 0 | G133: =ESTADISTICA!G131 -> 0 | H133: =ESTADISTICA!H131 -> 0 | ... AG133: =ESTADISTICA!AG131 -> 0
A134: =ESTADISTICA!A132 -> LA ESMERALDA | B134: =ESTADISTICA!B132 -> ESM05 | C134: =ESTADISTICA!C132 -> Aniceto Diaz y Villar | D134: =ESTADISTICA!D132 -> Domo | E134: =ESTADISTICA!E132 -> Fibra Optica | F134: =ESTADISTICA!F132 -> 0 | G134: =ESTADISTICA!G132 -> 0 | H134: =ESTADISTICA!H132 -> 0 | ... AG134: =ESTADISTICA!AG132 -> 0
A135: =ESTADISTICA!A133 -> LA ESMERALDA | B135: =ESTADISTICA!B133 -> ESM06 | C135: =ESTADISTICA!C133 -> Roselli y Cabello | D135: =ESTADISTICA!D133 -> Domo | E135: =ESTADISTICA!E133 -> GPON | F135: =ESTADISTICA!F133 -> 0 | G135: =ESTADISTICA!G133 -> 0 | H135: =ESTADISTICA!H133 -> 0 | ... AG135: =ESTADISTICA!AG133 -> 0
A136: =ESTADISTICA!A134 -> LA ESMERALDA | B136: =ESTADISTICA!B134 -> ESM07 | C136: =ESTADISTICA!C134 -> AV. NOVAK Y SERRANO | D136: =ESTADISTICA!D134 -> DOMO | E136: =ESTADISTICA!E134 -> PTO A FO | F136: =ESTADISTICA!F134 -> 0 | G136: =ESTADISTICA!G134 -> 0 | H136: =ESTADISTICA!H134 -> 0 | ... AG136: =ESTADISTICA!AG134 -> 0
A137: =ESTADISTICA!A135 -> LA ESMERALDA | B137: =ESTADISTICA!B135 -> ESM 08 | C137: =ESTADISTICA!C135 -> DAVINSON Y MORANCHEL | D137: =ESTADISTICA!D135 -> FIJA | E137: =ESTADISTICA!E135 -> Radio | F137: =ESTADISTICA!F135 -> 0 | G137: =ESTADISTICA!G135 -> 0 | H137: =ESTADISTICA!H135 -> 0 | ... AG137: =ESTADISTICA!AG135 -> 0
... A204: =ESTADISTICA!A202 -> MAYOL | B204: =ESTADISTICA!B202 -> MAY 04 | C204: =ESTADISTICA!C202 -> MAR CHIQUITA Y RIO JACHAL | D204: =ESTADISTICA!D202 -> DOMO | E204: =ESTADISTICA!E202 -> Radio | F204: =ESTADISTICA!F202 -> 0 | G204: =ESTADISTICA!G202 -> 0 | H204: =ESTADISTICA!H202 -> 0 | ... AG204: =ESTADISTICA!AG202 -> 0
A205: MONTE CUDINE | B205: =ESTADISTICA!B203 -> MCUD 01 | C205: =ESTADISTICA!C203 -> TINOGASTA Y SAN LORENZO | D205: =ESTADISTICA!D203 -> Domo | E205: =ESTADISTICA!E203 -> Fibra Optica | F205: =ESTADISTICA!F203 -> 0 | G205: =ESTADISTICA!G203 -> 0 | H205: =ESTADISTICA!H203 -> 0 | I205: =ESTADISTICA!I203 -> 0 | ... AG205: =ESTADISTICA!AG203 -> 0
A206: MONTE CUDINE | B206: =ESTADISTICA!B204 -> MCUD 02 | C206: =ESTADISTICA!C204 -> CALLE 115 A Y 158 | D206: =ESTADISTICA!D204 -> DOMO | E206: =ESTADISTICA!E204 -> Fibra Optica | F206: =ESTADISTICA!F204 -> 0 | G206: =ESTADISTICA!G204 -> 0 | H206: =ESTADISTICA!H204 -> 0 | I206: =ESTADISTICA!I204 -> 0 | ... AG206: =ESTADISTICA!AG204 -> 0
A207: =ESTADISTICA!A205 -> MARTIN FIERRO | B207: =ESTADISTICA!B205 -> MFI 01 | C207: =ESTADISTICA!C205 -> Belgrano y Sgto. Cabral | D207: =ESTADISTICA!D205 -> Fija | E207: =ESTADISTICA!E205 -> Fibra Optica | F207: =ESTADISTICA!F205 -> 0 | G207: =ESTADISTICA!G205 -> 0 | H207: =ESTADISTICA!H205 -> 0 | ... AG207: =ESTADISTICA!AG205 -> 0
A208: =ESTADISTICA!A206 -> LOPEZ ROMERO | B208: =ESTADISTICA!B206 -> MFI02 | C208: =ESTADISTICA!C206 -> Calchaqui y Balcarce | D208: =ESTADISTICA!D206 -> Fija | E208: =ESTADISTICA!E206 -> Fibra Optica | F208: =ESTADISTICA!F206 -> 0 | G208: =ESTADISTICA!G206 -> 0 | H208: =ESTADISTICA!H206 -> 0 | ... AG208: =ESTADISTICA!AG206 -> 0
A209: =ESTADISTICA!A208 -> MARTIN FIERRO | B209: =ESTADISTICA!B208 -> MFI04 | C209: =ESTADISTICA!C208 -> Calchaqui y balcarce | D209: =ESTADISTICA!D208 -> Domo | E209: =ESTADISTICA!E208 -> Fibra Optica | F209: =ESTADISTICA!F208 -> 0 | G209: =ESTADISTICA!G208 -> 0 | H209: =ESTADISTICA!H208 -> 0 | ... AG209: =ESTADISTICA!AG208 -> 0
A210: =ESTADISTICA!A209 -> SAN EMILIO | B210: =ESTADISTICA!B209 -> MFI 05 | C210: =ESTADISTICA!C209 -> Cno. Gral. Belgrano y Guayaquil | D210: =ESTADISTICA!D209 -> Domo | E210: =ESTADISTICA!E209 -> Fibra Optica | F210: =ESTADISTICA!F209 -> 0 | G210: =ESTADISTICA!G209 -> 0 | H210: =ESTADISTICA!H209 -> 0 | ... AG210: =ESTADISTICA!AG209 -> 0
A211: =ESTADISTICA!A210 -> SAN EMILIO | B211: =ESTADISTICA!B210 -> MFI06 | C211: =ESTADISTICA!C210 -> Con. Gral. Belgrano y Bombero Galarza | D211: =ESTADISTICA!D210 -> DOMO | E211: =ESTADISTICA!E210 -> Radio | F211: =ESTADISTICA!F210 -> 0 | G211: =ESTADISTICA!G210 -> 0 | H211: =ESTADISTICA!H210 -> 0 | ... AG211: =ESTADISTICA!AG210 -> 0
A212: =ESTADISTICA!A211 -> MARTIN FIERRO | B212: =ESTADISTICA!B211 -> MFI 07 | C212: =ESTADISTICA!C211 -> Sargento Cabral y Carlos Gardel | D212: =ESTADISTICA!D211 -> Domo | E212: =ESTADISTICA!E211 -> PTO A FO | F212: =ESTADISTICA!F211 -> 0 | G212: =ESTADISTICA!G211 -> 0 | H212: =ESTADISTICA!H211 -> 0 | ... AG212: =ESTADISTICA!AG211 -> 0
A213: =ESTADISTICA!A212 -> MARTIN FIERRO | B213: =ESTADISTICA!B212 -> MFI 08 | C213: =ESTADISTICA!C212 -> Braile y Batalla de Callao | D213: =ESTADISTICA!D212 -> Domo | E213: =ESTADISTICA!E212 -> PTO A FO | F213: =ESTADISTICA!F212 -> 0 | G213: =ESTADISTICA!G212 -> 0 | H213: =ESTADISTICA!H212 -> 0 | ... AG213: =ESTADISTICA!AG212 -> 0
A214: =ESTADISTICA!A213 -> GOBERNADOR MONTEVERDE | B214: =ESTADISTICA!B213 -> MON01 | C214: =ESTADISTICA!C213 -> San Martin y Patricias Argentinas | D214: =ESTADISTICA!D213 -> Fija | E214: =ESTADISTICA!E213 -> Fibra Optica | F214: =ESTADISTICA!F213 -> 0 | G214: =ESTADISTICA!G213 -> 0 | H214: =ESTADISTICA!H213 -> 0 | ... AG214: =ESTADISTICA!AG213 -> 0
A215: =ESTADISTICA!A214 -> GOBERNADOR MONTEVERDE | B215: =ESTADISTICA!B214 -> MON02 | C215: =ESTADISTICA!C214 -> Senzabello y Famatina | D215: =ESTADISTICA!D214 -> Domo | E215: =ESTADISTICA!E214 -> Radio | F215: =ESTADISTICA!F214 -> APAGADO | G215: =ESTADISTICA!G214 -> 0 | H215: =ESTADISTICA!H214 -> 0 | ... AG215: =ESTADISTICA!AG214 -> 0
A216: =ESTADISTICA!A215 -> GOBERNADOR MONTEVERDE | B216: =ESTADISTICA!B215 -> MON03 | C216: =ESTADISTICA!C215 -> Senzabello y Guemes | D216: =ESTADISTICA!D215 -> Domo | E216: =ESTADISTICA!E215 -> Radio | F216: =ESTADISTICA!F215 -> 0 | G216: =ESTADISTICA!G215 -> 0 | H216: =ESTADISTICA!H215 -> 0 | ... AG216: =ESTADISTICA!AG215 -> 0
...

Sheet APAGADOS FIBRA
C1: TOTAL FIBRA | D1: =COUNTIFS(E4:E401,"=Fibra Optica") -> 247
E2: APAGADOS | F2: =COUNTIFS(F4:F501, "=APAGADO",E4:E501,"=Fibra Optica") -> 32 | G2: =COUNTIFS(G4:G501, "=APAGADO",E4:E501,"=Fibra Optica") -> 0 | H2: =COUNTIFS(H4:H501, "=APAGADO",E4:E501,"=Fibra Optica") -> 0 | I2: =COUNTIFS(I4:I501, "=APAGADO",E4:E501,"=Fibra Optica") -> 0 | J2: =COUNTIFS(J4:J501, "=APAGADO",E4:E501,"=Fibra Optica") -> 0 | K2: =COUNTIFS(K4:K501, "=APAGADO",E4:E501,"=Fibra Optica") -> 0 | L2: =COUNTIFS(L4:L501, "=APAGADO",E4:E501,"=Fibra Optica") -> 0 | M2: =COUNTIFS(M4:M501, "=APAGADO",E4:E501,"=Fibra Optica") -> 0 | N2: =COUNTIFS(N4:N501, "=APAGADO",E4:E501,"=Fibra Optica") -> 0 | O2: =COUNTIFS(O4:O501, "=APAGADO",E4:E501,"=Fibra Optica") -> 0 | P2: =COUNTIFS(P4:P601, "=APAGADO",E4:E601,"=Fibra Optica") -> 0 | Q2: =COUNTIFS(Q4:Q501, "=APAGADO",E4:E501,"=Fibra Optica") -> 0 | R2: =COUNTIFS(R4:R501, "=APAGADO",E4:E501,"=Fibra Optica") -> 0 | S2: =COUNTIFS(S4:S501, "=APAGADO",E4:E501,"=Fibra Optica") -> 0 | T2: =COUNTIFS(T4:T501, "=APAGADO",E4:E501,"=Fibra Optica") -> 0 | U2: =COUNTIFS(U4:U501, "=APAGADO",E4:E501,"=Fibra Optica") -> 0 | V2: =COUNTIFS(V4:V501, "=APAGADO",E4:E501,"=Fibra Optica") -> 0 | W2: =COUNTIFS(W4:W501, "=APAGADO",E4:E501,"=Fibra Optica") -> 0 | X2: =COUNTIFS(X4:X501, "=APAGADO",E4:E501,"=Fibra Optica") -> 0 | Y2: =COUNTIFS(Y4:Y501, "=APAGADO",E4:E501,"=Fibra Optica") -> 0 | Z2: =COUNTIFS(Z4:Z501, "=APAGADO",E4:E501,"=Fibra Optica") -> 0 | AA2: =COUNTIFS(AA4:AA501, "=APAGADO",E4:E501,"=Fibra Optica") -> 0 | AB2: =COUNTIFS(AB4:AB501, "=APAGADO",E4:E501,"=Fibra Optica") -> 0 | AC2: =COUNTIFS(AC4:AC601, "=APAGADO",E4:E601,"=Fibra Optica") -> 0 | AD2: =COUNTIFS(AD4:AD501, "=APAGADO",E4:E501,"=Fibra Optica") -> 0 | AE2: =COUNTIFS(AE4:AE501, "=APAGADO",E4:E501,"=Fibra Optica") -> 0 | AF2: =COUNTIFS(AF4:AF501, "=APAGADO",E4:E501,"=Fibra Optica") -> 0 | AG2: =COUNTIFS(AG4:AG501, "=APAGADO",E4:E501,"=Fibra Optica") -> 0
A3: =ESTADISTICA!A1 -> Barrio | B3: =ESTADISTICA!B1 -> [Denominacion] | C3: =ESTADISTICA!C1 -> [Ubicacion] | D3: =ESTADISTICA!D1 -> [Tipo de Camara] | E3: =ESTADISTICA!E1 -> [Tipo de Conexion] | F3: =ESTADISTICA!F1 -> 45689 | G3: =ESTADISTICA!G1 -> 45690 | H3: =ESTADISTICA!H1 -> 45691 | ... AG3: =ESTADISTICA!AG1 -> 45716
A4: ='RESUMEN TOTAL'!A7 -> ALTAMIRA | B4: ='RESUMEN TOTAL'!B7 -> ALT 03 | C4: ='RESUMEN TOTAL'!D7 -> Bombero Galarza y Necochea | D4: ='RESUMEN TOTAL'!E7 -> Domo | E4: ='RESUMEN TOTAL'!F7 -> Fibra Optica | F4: ='RESUMEN TOTAL'!L7 -> 0 | G4: ='RESUMEN TOTAL'!M7 -> 0 | H4: ='RESUMEN TOTAL'!N7 -> 0 | I4: ='RESUMEN TOTAL'!O7 -> 0 | J4: ='RESUMEN TOTAL'!P7 -> 0 | K4: ='RESUMEN TOTAL'!Q7 -> 0 | L4: ='RESUMEN TOTAL'!R7 -> 0 | M4: ='RESUMEN TOTAL'!S7 -> 0 | ... AG4: ='RESUMEN TOTAL'!AM7 -> 0
A5: ='RESUMEN TOTAL'!A8 -> ALTAMIRA | B5: ='RESUMEN TOTAL'!B8 -> ALT 04 | C5: ='RESUMEN TOTAL'!D8 -> Francia y Necochea | D5: ='RESUMEN TOTAL'!E8 -> Domo | E5: ='RESUMEN TOTAL'!F8 -> Fibra Optica | F5: ='RESUMEN TOTAL'!L8 -> APAGADO | G5: ='RESUMEN TOTAL'!M8 -> 0 | H5: ='RESUMEN TOTAL'!N8 -> 0 | I5: ='RESUMEN TOTAL'!O8 -> 0 | J5: ='RESUMEN TOTAL'!P8 -> 0 | K5: ='RESUMEN TOTAL'!Q8 -> 0 | L5: ='RESUMEN TOTAL'!R8 -> 0 | M5: ='RESUMEN TOTAL'!S8 -> 0 | ... AG5: ='RESUMEN TOTAL'!AM8 -> 0
A6: ='RESUMEN TOTAL'!A9 -> ALTAMIRA | B6: ='RESUMEN TOTAL'!B9 -> ALT05 | C6: ='RESUMEN TOTAL'!D9 -> Av. Calchaqui y Bombero Galarza | D6: ='RESUMEN TOTAL'!E9 -> Domo | E6: ='RESUMEN TOTAL'!F9 -> PTO A FO | F6: ='RESUMEN TOTAL'!L9 -> 0 | G6: ='RESUMEN TOTAL'!M9 -> 0 | H6: ='RESUMEN TOTAL'!N9 -> 0 | I6: ='RESUMEN TOTAL'!O9 -> 0 | J6: ='RESUMEN TOTAL'!P9 -> 0 | K6: ='RESUMEN TOTAL'!Q9 -> 0 | L6: ='RESUMEN TOTAL'!R9 -> 0 | M6: ='RESUMEN TOTAL'!S9 -> 0 | ... AG6: ='RESUMEN TOTAL'!AM9 -> 0
A7: ='RESUMEN TOTAL'!A10 -> ALTAMIRA | B7: ='RESUMEN TOTAL'!B10 -> ALT 06 | C7: ='RESUMEN TOTAL'!D10 -> LOPE DE VEGA Y NECOCHEA | D7: ='RESUMEN TOTAL'!E10 -> Domo | E7: ='RESUMEN TOTAL'!F10 -> PTO A FO | F7: ='RESUMEN TOTAL'!L10 -> 0 | G7: ='RESUMEN TOTAL'!M10 -> 0 | H7: ='RESUMEN TOTAL'!N10 -> 0 | I7: ='RESUMEN TOTAL'!O10 -> 0 | J7: ='RESUMEN TOTAL'!P10 -> 0 | K7: ='RESUMEN TOTAL'!Q10 -> 0 | L7: ='RESUMEN TOTAL'!R10 -> 0 | M7: ='RESUMEN TOTAL'!S10 -> 0 | ... AG7: ='RESUMEN TOTAL'!AM10 -> 0
A8: ='RESUMEN TOTAL'!A11 -> ALTAMIRA | B8: ='RESUMEN TOTAL'!B11 -> ALT07 | C8: ='RESUMEN TOTAL'!D11 -> AV. CALCHAQUI Y AV. DEL TRABAJO | D8: ='RESUMEN TOTAL'!E11 -> DOMO | E8: ='RESUMEN TOTAL'!F11 -> PTO A FO | F8: ='RESUMEN TOTAL'!L11 -> 0 | G8: ='RESUMEN TOTAL'!M11 -> 0 | H8: ='RESUMEN TOTAL'!N11 -> 0 | I8: ='RESUMEN TOTAL'!O11 -> 0 | J8: ='RESUMEN TOTAL'!P11 -> 0 | K8: ='RESUMEN TOTAL'!Q11 -> 0 | L8: ='RESUMEN TOTAL'!R11 -> 0 | M8: ='RESUMEN TOTAL'!S11 -> 0 | ... AG8: ='RESUMEN TOTAL'!AM11 -> 0
A9: ='RESUMEN TOTAL'!A12 -> ALTAMIRA | B9: ='RESUMEN TOTAL'!B12 -> ALT 08 | C9: ='RESUMEN TOTAL'!D12 -> HUMAITA Y NECOCHEA | D9: ='RESUMEN TOTAL'!E12 -> DOMO | E9: ='RESUMEN TOTAL'!F12 -> Fibra Optica | F9: ='RESUMEN TOTAL'!L12 -> 0 | G9: ='RESUMEN TOTAL'!M12 -> 0 | H9: ='RESUMEN TOTAL'!N12 -> 0 | I9: ='RESUMEN TOTAL'!O12 -> 0 | J9: ='RESUMEN TOTAL'!P12 -> 0 | K9: ='RESUMEN TOTAL'!Q12 -> 0 | L9: ='RESUMEN TOTAL'!R12 -> 0 | M9: ='RESUMEN TOTAL'!S12 -> 0 | ... AG9: ='RESUMEN TOTAL'!AM12 -> 0
A10: ='RESUMEN TOTAL'!A13 -> ALTAMIRA | B10: ='RESUMEN TOTAL'!B13 -> ALT 09 | C10: ='RESUMEN TOTAL'!D13 -> NECOCHEA Y CURUPAITY | D10: ='RESUMEN TOTAL'!E13 -> DOMO | E10: ='RESUMEN TOTAL'!F13 -> Fibra Optica | F10: ='RESUMEN TOTAL'!L13 -> 0 | G10: ='RESUMEN TOTAL'!M13 -> 0 | H10: ='RESUMEN TOTAL'!N13 -> 0 | I10: ='RESUMEN TOTAL'!O13 -> 0 | J10: ='RESUMEN TOTAL'!P13 -> 0 | K10: ='RESUMEN TOTAL'!Q13 -> 0 | L10: ='RESUMEN TOTAL'!R13 -> 0 | M10: ='RESUMEN TOTAL'!S13 -> 0 | ... AG10: ='RESUMEN TOTAL'!AM13 -> 0
A11: ='RESUMEN TOTAL'!A14 -> ALTAMIRA | B11: ='RESUMEN TOTAL'!B14 -> ALT 10 | C11: ='RESUMEN TOTAL'!D14 -> Calchaqui y Francia | D11: ='RESUMEN TOTAL'!E14 -> Domo | E11: ='RESUMEN TOTAL'!F14 -> Radio | F11: ='RESUMEN TOTAL'!L14 -> 0 | G11: ='RESUMEN TOTAL'!M14 -> 0 | H11: ='RESUMEN TOTAL'!N14 -> 0 | I11: ='RESUMEN TOTAL'!O14 -> 0 | J11: ='RESUMEN TOTAL'!P14 -> 0 | K11: ='RESUMEN TOTAL'!Q14 -> 0 | L11: ='RESUMEN TOTAL'!R14 -> 0 | M11: ='RESUMEN TOTAL'!S14 -> 0 | ... AG11: ='RESUMEN TOTAL'!AM14 -> 0
A12: ='RESUMEN TOTAL'!A15 -> AGUSTIN RAMIREZ | B12: ='RESUMEN TOTAL'!B15 -> ARA 01 | C12: ='RESUMEN TOTAL'!D15 -> Malambo y Tranquera | D12: ='RESUMEN TOTAL'!E15 -> Domo | E12: ='RESUMEN TOTAL'!F15 -> Fibra Optica | F12: ='RESUMEN TOTAL'!L15 -> 0 | G12: ='RESUMEN TOTAL'!M15 -> 0 | H12: ='RESUMEN TOTAL'!N15 -> 0 | I12: ='RESUMEN TOTAL'!O15 -> 0 | J12: ='RESUMEN TOTAL'!P15 -> 0 | K12: ='RESUMEN TOTAL'!Q15 -> 0 | L12: ='RESUMEN TOTAL'!R15 -> 0 | M12: ='RESUMEN TOTAL'!S15 -> 0 | ... AG12: ='RESUMEN TOTAL'!AM15 -> 0
A13: ='RESUMEN TOTAL'!A16 -> BELGRANO | B13: ='RESUMEN TOTAL'!B16 -> BEL 01 | C13: ='RESUMEN TOTAL'!D16 -> San Martin y Dardo Rocha | D13: ='RESUMEN TOTAL'!E16 -> DOMO | E13: ='RESUMEN TOTAL'!F16 -> Fibra Optica | F13: ='RESUMEN TOTAL'!L16 -> 0 | G13: ='RESUMEN TOTAL'!M16 -> 0 | H13: ='RESUMEN TOTAL'!N16 -> 0 | I13: ='RESUMEN TOTAL'!O16 -> 0 | J13: ='RESUMEN TOTAL'!P16 -> 0 | K13: ='RESUMEN TOTAL'!Q16 -> 0 | L13: ='RESUMEN TOTAL'!R16 -> 0 | M13: ='RESUMEN TOTAL'!S16 -> 0 | ... AG13: ='RESUMEN TOTAL'!AM16 -> 0
A14: ='RESUMEN TOTAL'!A17 -> BELGRANO | B14: ='RESUMEN TOTAL'!B17 -> BEL 02 | C14: ='RESUMEN TOTAL'!D17 -> Guardia vieja y Fronteriz | D14: ='RESUMEN TOTAL'!E17 -> DOMO | E14: ='RESUMEN TOTAL'!F17 -> Fibra Optica | F14: ='RESUMEN TOTAL'!L17 -> 0 | G14: ='RESUMEN TOTAL'!M17 -> 0 | H14: ='RESUMEN TOTAL'!N17 -> 0 | I14: ='RESUMEN TOTAL'!O17 -> 0 | J14: ='RESUMEN TOTAL'!P17 -> 0 | K14: ='RESUMEN TOTAL'!Q17 -> 0 | L14: ='RESUMEN TOTAL'!R17 -> 0 | M14: ='RESUMEN TOTAL'!S17 -> 0 | ... AG14: ='RESUMEN TOTAL'!AM17 -> 0
A15: ='RESUMEN TOTAL'!A18 -> BOSQUES CENTRO | B15: ='RESUMEN TOTAL'!B18 -> BOSQC 01 | C15: ='RESUMEN TOTAL'!D18 -> LUIS AGOTE E/DANUNCIO Y CAMPOAMOR | D15: ='RESUMEN TOTAL'!E18 -> Fija | E15: ='RESUMEN TOTAL'!F18 -> Radio | F15: ='RESUMEN TOTAL'!L18 -> 0 | G15: ='RESUMEN TOTAL'!M18 -> 0 | H15: ='RESUMEN TOTAL'!N18 -> 0 | I15: ='RESUMEN TOTAL'!O18 -> 0 | J15: ='RESUMEN TOTAL'!P18 -> 0 | K15: ='RESUMEN TOTAL'!Q18 -> 0 | L15: ='RESUMEN TOTAL'!R18 -> 0 | M15: ='RESUMEN TOTAL'!S18 -> 0 | ... AG15: ='RESUMEN TOTAL'!AM18 -> 0
... A20: ='RESUMEN TOTAL'!A23 -> BOSQUES CENTRO | B20: ='RESUMEN TOTAL'!B23 -> BOSQC 06 | C20: ='RESUMEN TOTAL'!D23 -> LUIS AGOTE Y RUTA 36 | D20: ='RESUMEN TOTAL'!E23 -> Fija | E20: ='RESUMEN TOTAL'!F23 -> Radio | F20: ='RESUMEN TOTAL'!L23 -> 0 | G20: ='RESUMEN TOTAL'!M23 -> 0 | H20: ='RESUMEN TOTAL'!N23 -> 0 | I20: ='RESUMEN TOTAL'!O23 -> 0 | J20: ='RESUMEN TOTAL'!P23 -> 0 | K20: ='RESUMEN TOTAL'!Q23 -> 0 | L20: ='RESUMEN TOTAL'!R23 -> 0 | M20: ='RESUMEN TOTAL'!S23 -> 0 | ... AG20: ='RESUMEN TOTAL'!AM23 -> 0
A21: ='RESUMEN TOTAL'!A27 -> CENTRO | B21: ='RESUMEN TOTAL'!B27 -> CEN01 | C21: ='RESUMEN TOTAL'!D27 -> San Martin y 9 de Julio | D21: ='RESUMEN TOTAL'!E27 -> Fija | E21: ='RESUMEN TOTAL'!F27 -> Fibra Optica | F21: ='RESUMEN TOTAL'!L27 -> APAGADO | G21: ='RESUMEN TOTAL'!M27 -> 0 | H21: ='RESUMEN TOTAL'!N27 -> 0 | I21: ='RESUMEN TOTAL'!O27 -> 0 | J21: ='RESUMEN TOTAL'!P27 -> 0 | K21: ='RESUMEN TOTAL'!Q27 -> 0 | L21: ='RESUMEN TOTAL'!R27 -> 0 | M21: ='RESUMEN TOTAL'!S27 -> 0 | ... AG21: ='RESUMEN TOTAL'!AM27 -> 0
A22: ='RESUMEN TOTAL'!A28 -> CENTRO | B22: ='RESUMEN TOTAL'!B28 -> CEN02 | C22: ='RESUMEN TOTAL'!D28 -> San Martin y Almafuerte | D22: ='RESUMEN TOTAL'!E28 -> Fija | E22: ='RESUMEN TOTAL'!F28 -> Fibra Optica | F22: ='RESUMEN TOTAL'!L28 -> APAGADO | G22: ='RESUMEN TOTAL'!M28 -> 0 | H22: ='RESUMEN TOTAL'!N28 -> 0 | I22: ='RESUMEN TOTAL'!O28 -> 0 | J22: ='RESUMEN TOTAL'!P28 -> 0 | K22: ='RESUMEN TOTAL'!Q28 -> 0 | L22: ='RESUMEN TOTAL'!R28 -> 0 | M22: ='RESUMEN TOTAL'!S28 -> 0 | ... AG22: ='RESUMEN TOTAL'!AM28 -> 0
A23: ='RESUMEN TOTAL'!A29 -> CENTRO | B23: ='RESUMEN TOTAL'!B29 -> CEN03 | C23: ='RESUMEN TOTAL'!D29 -> San Martin y Sallares | D23: ='RESUMEN TOTAL'!E29 -> Domo | E23: ='RESUMEN TOTAL'!F29 -> Fibra Optica | F23: ='RESUMEN TOTAL'!L29 -> 0 | G23: ='RESUMEN TOTAL'!M29 -> 0 | H23: ='RESUMEN TOTAL'!N29 -> 0 | I23: ='RESUMEN TOTAL'!O29 -> 0 | J23: ='RESUMEN TOTAL'!P29 -> 0 | K23: ='RESUMEN TOTAL'!Q29 -> 0 | L23: ='RESUMEN TOTAL'!R29 -> 0 | M23: ='RESUMEN TOTAL'!S29 -> 0 | ... AG23: ='RESUMEN TOTAL'!AM29 -> 0
A24: ='RESUMEN TOTAL'!A30 -> CENTRO | B24: ='RESUMEN TOTAL'!B30 -> CEN04 | C24: ='RESUMEN TOTAL'!D30 -> San Martin y Contreras | D24: ='RESUMEN TOTAL'!E30 -> Domo | E24: ='RESUMEN TOTAL'!F30 -> Fibra Optica | F24: ='RESUMEN TOTAL'!L30 -> 0 | G24: ='RESUMEN TOTAL'!M30 -> 0 | H24: ='RESUMEN TOTAL'!N30 -> 0 | I24: ='RESUMEN TOTAL'!O30 -> 0 | J24: ='RESUMEN TOTAL'!P30 -> 0 | K24: ='RESUMEN TOTAL'!Q30 -> 0 | L24: ='RESUMEN TOTAL'!R30 -> 0 | M24: ='RESUMEN TOTAL'!S30 -> 0 | ... AG24: ='RESUMEN TOTAL'!AM30 -> 0
A25: ='RESUMEN TOTAL'!A31 -> CENTRO | B25: ='RESUMEN TOTAL'!B31 -> CEN 05 | C25: ='RESUMEN TOTAL'!D31 -> Bocuzzi e/España y San Martin | D25: ='RESUMEN TOTAL'!E31 -> DOMO | E25: ='RESUMEN TOTAL'!F31 -> Fibra Optica | F25: ='RESUMEN TOTAL'!L31 -> 0 | G25: ='RESUMEN TOTAL'!M31 -> 0 | H25: ='RESUMEN TOTAL'!N31 -> 0 | I25: ='RESUMEN TOTAL'!O31 -> 0 | J25: ='RESUMEN TOTAL'!P31 -> 0 | K25: ='RESUMEN TOTAL'!Q31 -> 0 | L25: ='RESUMEN TOTAL'!R31 -> 0 | M25: ='RESUMEN TOTAL'!S31 -> 0 | ... AG25: ='RESUMEN TOTAL'!AM31 -> 0
A26: ='RESUMEN TOTAL'!A32 -> CENTRO | B26: ='RESUMEN TOTAL'!B32 -> CEN06 | C26: ='RESUMEN TOTAL'!D32 -> Monteagudo y A.del Valle | D26: ='RESUMEN TOTAL'!E32 -> Fija | E26: ='RESUMEN TOTAL'!F32 -> Fibra Optica | F26: ='RESUMEN TOTAL'!L32 -> 0 | G26: ='RESUMEN TOTAL'!M32 -> 0 | H26: ='RESUMEN TOTAL'!N32 -> 0 | I26: ='RESUMEN TOTAL'!O32 -> 0 | J26: ='RESUMEN TOTAL'!P32 -> 0 | K26: ='RESUMEN TOTAL'!Q32 -> 0 | L26: ='RESUMEN TOTAL'!R32 -> 0 | M26: ='RESUMEN TOTAL'!S32 -> 0 | ... AG26: ='RESUMEN TOTAL'!AM32 -> 0
A27: ='RESUMEN TOTAL'!A33 -> CENTRO | B27: ='RESUMEN TOTAL'!B33 -> CEN07 | C27: ='RESUMEN TOTAL'!D33 -> San Martin y Guemes | D27: ='RESUMEN TOTAL'!E33 -> DOMO | E27: ='RESUMEN TOTAL'!F33 -> Fibra Optica | F27: ='RESUMEN TOTAL'!L33 -> 0 | G27: ='RESUMEN TOTAL'!M33 -> 0 | H27: ='RESUMEN TOTAL'!N33 -> 0 | I27: ='RESUMEN TOTAL'!O33 -> 0 | J27: ='RESUMEN TOTAL'!P33 -> 0 | K27: ='RESUMEN TOTAL'!Q33 -> 0 | L27: ='RESUMEN TOTAL'!R33 -> 0 | M27: ='RESUMEN TOTAL'!S33 -> 0 | ... AG27: ='RESUMEN TOTAL'!AM33 -> 0
A28: ='RESUMEN TOTAL'!A34 -> CENTRO | B28: ='RESUMEN TOTAL'!B34 -> CEN08 | C28: ='RESUMEN TOTAL'!D34 -> San Martin y Pte.Peron | D28: ='RESUMEN TOTAL'!E34 -> Domo | E28: ='RESUMEN TOTAL'!F34 -> Fibra Optica | F28: ='RESUMEN TOTAL'!L34 -> 0 | G28: ='RESUMEN TOTAL'!M34 -> 0 | H28: ='RESUMEN TOTAL'!N34 -> 0 | I28: ='RESUMEN TOTAL'!O34 -> 0 | J28: ='RESUMEN TOTAL'!P34 -> 0 | K28: ='RESUMEN TOTAL'!Q34 -> 0 | L28: ='RESUMEN TOTAL'!R34 -> 0 | M28: ='RESUMEN TOTAL'!S34 -> 0 | ... AG28: ='RESUMEN TOTAL'!AM34 -> 0
A29: ='RESUMEN TOTAL'!A35 -> CENTRO | B29: ='RESUMEN TOTAL'!B35 -> CEN09 | C29: ='RESUMEN TOTAL'!D35 -> Chacabuco y 25 de Mayo | D29: ='RESUMEN TOTAL'!E35 -> Domo | E29: ='RESUMEN TOTAL'!F35 -> Fibra Optica | F29: ='RESUMEN TOTAL'!L35 -> 0 | G29: ='RESUMEN TOTAL'!M35 -> 0 | H29: ='RESUMEN TOTAL'!N35 -> 0 | I29: ='RESUMEN TOTAL'!O35 -> 0 | J29: ='RESUMEN TOTAL'!P35 -> 0 | K29: ='RESUMEN TOTAL'!Q35 -> 0 | L29: ='RESUMEN TOTAL'!R35 -> 0 | M29: ='RESUMEN TOTAL'!S35 -> 0 | ... AG29: ='RESUMEN TOTAL'!AM35 -> 0
A30: ='RESUMEN TOTAL'!A36 -> CENTRO | B30: ='RESUMEN TOTAL'!B36 -> CEN10 | C30: ='RESUMEN TOTAL'!D36 -> Monteagudo y Pte. Peron | D30: ='RESUMEN TOTAL'!E36 -> Domo | E30: ='RESUMEN TOTAL'!F36 -> Fibra Optica | F30: ='RESUMEN TOTAL'!L36 -> 0 | G30: ='RESUMEN TOTAL'!M36 -> 0 | H30: ='RESUMEN TOTAL'!N36 -> 0 | I30: ='RESUMEN TOTAL'!O36 -> 0 | J30: ='RESUMEN TOTAL'!P36 -> 0 | K30: ='RESUMEN TOTAL'!Q36 -> 0 | L30: ='RESUMEN TOTAL'!R36 -> 0 | M30: ='RESUMEN TOTAL'!S36 -> 0 | ... AG30: ='RESUMEN TOTAL'!AM36 -> 0
A31: ='RESUMEN TOTAL'!A37 -> CENTRO | B31: ='RESUMEN TOTAL'!B37 -> CEN11 | C31: ='RESUMEN TOTAL'!D37 -> Monteagudo y Bocuzzi | D31: ='RESUMEN TOTAL'!E37 -> Domo | E31: ='RESUMEN TOTAL'!F37 -> Fibra Optica | F31: ='RESUMEN TOTAL'!L37 -> 0 | G31: ='RESUMEN TOTAL'!M37 -> 0 | H31: ='RESUMEN TOTAL'!N37 -> 0 | I31: ='RESUMEN TOTAL'!O37 -> 0 | J31: ='RESUMEN TOTAL'!P37 -> 0 | K31: ='RESUMEN TOTAL'!Q37 -> 0 | L31: ='RESUMEN TOTAL'!R37 -> 0 | M31: ='RESUMEN TOTAL'!S37 -> 0 | ... AG31: ='RESUMEN TOTAL'!AM37 -> 0
A32: ='RESUMEN TOTAL'!A38 -> CENTRO | B32: ='RESUMEN TOTAL'!B38 -> CEN 12 | C32: ='RESUMEN TOTAL'!D38 -> Monteagudo y Mitre | D32: ='RESUMEN TOTAL'!E38 -> Domo | E32: ='RESUMEN TOTAL'!F38 -> Fibra Optica | F32: ='RESUMEN TOTAL'!L38 -> 0 | G32: ='RESUMEN TOTAL'!M38 -> 0 | H32: ='RESUMEN TOTAL'!N38 -> 0 | I32: ='RESUMEN TOTAL'!O38 -> 0 | J32: ='RESUMEN TOTAL'!P38 -> 0 | K32: ='RESUMEN TOTAL'!Q38 -> 0 | L32: ='RESUMEN TOTAL'!R38 -> 0 | M32: ='RESUMEN TOTAL'!S38 -> 0 | ... AG32: ='RESUMEN TOTAL'!AM38 -> 0
