Workbook
Name _25_de_agosto: 'RESUMEN TOTAL'!$A$4:$D$396
Name _25_de_agosto_3: 'RESUMEN TOTAL'!$A$4:$D$408
Name _30_mar: 'APAGADOS ANTENA'!$AI$3
Name BONOMOcam: Hoja1!$B$2
Name CANTIDAD_DE_CAMARAS: 'RESUMEN TOTAL'!$B$1
Name COSEIDIcam: Hoja1!$B$4

Sheet RESUMEN TOTAL
A1: CANTIDAD DE CAMARAS | B1: =COUNTA(B5:B633) -> 547 | D1: PORCIENTO DE CAIDAS | L1: =(L3)/(L2+L3) -> 0.1572327 | M1: =(M3)/(M2+M3) -> 0.20474777 | N1: =(N3)/(N2+N3) -> 0 | O1: =(O3)/(O2+O3) -> 0 | P1: =(P3)/(P2+P3) -> 0 | Q1: =(Q3)/(Q2+Q3) -> 0 | R1: =(R3)/(R2+R3) -> 0 | S1: =(S3)/(S2+S3) -> 0 | ... X1: =(X3)/(X2+X3) -> 0 | Z1: =(Z3)/(Z2+Z3) -> 0 | AA1: =(AA3)/(AA2+AA3) -> 0 | AB1: =(AB3)/(AB2+AB3) -> 0 | AC1: =(AC3)/(AC2+AC3) -> 0 | AD1: =(AD3)/(AD2+AD3) -> 0 | AE1: =(AE3)/(AE2+AE3) -> 0 | AF1: =(AF3)/(AF2+AF3) -> 0 | AG1: =(AG3)/(AG2+AG3) -> 0 | ... AP1: =(AP3)/(AP2+AP3) -> 0
D2: FUNCIONAN | L2: 536 | M2: 536 | N2: 536 | O2: 536 | P2: 536 | Q2: 536 | R2: 536 | S2: 536 | T2: 536 | U2: 536 | V2: 536 | W2: 536 | X2: 536 | Y2: 536 | Z2: 536 | AA2: 536 | AB2: 536 | AC2: 536 | AD2: 536 | AE2: 536 | AF2: 536 | AG2: 536 | AH2: 536 | AI2: 536 | AJ2: 536 | AK2: 536 | AL2: 536 | AM2: 536 | AN2: 536 | AO2: 536 | AP2: 537
D3: CAIDAS | L3: =COUNTIF(L4:L633, "apagado") -> 100 | M3: =COUNTIF(M4:M633, "apagado") -> 138 | N3: =COUNTIF(N4:N633, "apagado") -> 0 | O3: =COUNTIF(O4:O633, "apagado") -> 0 | P3: =COUNTIF(P4:P633, "apagado") -> 0 | Q3: =COUNTIF(Q4:Q633, "apagado") -> 0 | R3: =COUNTIF(R4:R633, "apagado") -> 0 | S3: =COUNTIF(S4:S633, "apagado") -> 0 | ... W3: =COUNTIF(W4:W633, "apagado") -> 0 | X3: =COUNTIF(X4:X533, "apagado") -> 0 | Y3: =COUNTIF(Y4:Y533, "apagado") -> 0 | Z3: =COUNTIF(Z4:Z633, "apagado") -> 0 | AA3: =COUNTIF(AA4:AA633, "apagado") -> 0 | AB3: =COUNTIF(AB4:AB633, "apagado") -> 0 | AC3: =COUNTIF(AC4:AC633, "apagado") -> 0 | AD3: =COUNTIF(AD4:AD633, "apagado") -> 0 | AE3: =COUNTIF(AE4:AE633, "apagado") -> 0 | AF3: =COUNTIF(AF4:AF633, "apagado") -> 0 | AG3: =COUNTIF(AG4:AG633, "apagado") -> 0 | ... AP3: =COUNTIF(AP4:AP633, "apagado") -> 0
A4: Barrio | B4: [Denominacion] | C4: [Empresa Mantenimiento] | D4: [Ubicacion] | E4: [Tipo de Camara] | F4: [Tipo de Conexion] | G4: Destino | I4: DIAS FUNCIONANDO | J4: DIAS CAIDA | K4: EFECTIVIDAD | L4: 45292 | M4: 45293 | N4: 45294 | O4: 45295 | P4: 45296 | Q4: 45297 | R4: 45298 | S4: 45299 | T4: 45300 | U4: 45301 | V4: 45302 | W4: 45303 | X4: 45304 | Y4: 45305 | Z4: 45306 | AA4: 45307 | AB4: 45308 | AC4: 45309 | AD4: 45310 | AE4: 45311 | AF4: 45312 | AG4: 45313 | AH4: 45314 | AI4: 45315 | AJ4: 45316 | AK4: 45317 | AL4: 45318 | AM4: 45319 | AN4: 45320 | AO4: 45321 | AP4: 45322
A5: ALTAMIRA | B5: ALT01 | C5: BONOMO | D5: Calchaqui y Sgto. Cabral | E5: Domo | F5: Fibra Optica | H5: 172.20.10.6 | I5: =COUNTIF(L5:AM5,"") -> 28 | J5: =COUNTIF(L5:AM5,"APAGADO") -> 0 | K5: =(I5)/(J5+I5) -> 1
A6: ALTAMIRA | B6: ALT02 | C6: BONOMO | D6: Calchaqui y Lope de Vega | E6: Domo | F6: PTO A FO | G6: CABRAL Y CALCHAQUI | H6: 172.20.12.218 | I6: =COUNTIF(L6:AM6,"") -> 28 | J6: =COUNTIF(L6:AM6,"APAGADO") -> 0 | K6: =(I6)/(J6+I6) -> 1
A7: ALTAMIRA | B7: ALT 03 | C7: BONOMO | D7: Bombero Galarza y Necochea | E7: Domo | F7: Fibra Optica | H7: 172.20.12.54 | I7: =COUNTIF(L7:AM7,"") -> 28 | J7: =COUNTIF(L7:AM7,"APAGADO") -> 0 | K7: =(I7)/(J7+I7) -> 1
A8: ALTAMIRA | B8: ALT 04 | C8: BONOMO | D8: Francia y Necochea | E8: Domo | F8: Fibra Optica | H8: 172.20.12.55 | I8: =COUNTIF(L8:AM8,"") -> 28 | J8: =COUNTIF(L8:AM8,"APAGADO") -> 0 | K8: =(I8)/(J8+I8) -> 1
A9: ALTAMIRA | B9: ALT05 | C9: BONOMO | D9: Av. Calchaqui y Bombero Galarza | E9: Domo | F9: PTO A FO | G9: NECOCHEA Y GALARZA | H9: 172.20.12.216 | I9: =COUNTIF(L9:AM9,"") -> 27 | J9: =COUNTIF(L9:AM9,"APAGADO") -> 1 | K9: =(I9)/(J9+I9) -> 0.96428571 | M9: APAGADO
A10: ALTAMIRA | B10: ALT 06 | C10: BONOMO | D10: LOPE DE VEGA Y NECOCHEA | E10: Domo | F10: PTO A FO | G10: NECOCHEA Y GALARZA | H10: 172.20.12.12 | I10: =COUNTIF(L10:AM10,"") -> 28 | J10: =COUNTIF(L10:AM10,"APAGADO") -> 0 | K10: =(I10)/(J10+I10) -> 1
A11: ALTAMIRA | B11: ALT07 | C11: BONOMO | D11: AV. CALCHAQUI Y AV. DEL TRABAJO | E11: DOMO | F11: PTO A FO | G11: CABRAL Y CALCHAQUI | H11: 172.20.10.57 | I11: =COUNTIF(L11:AM11,"") -> 28 | J11: =COUNTIF(L11:AM11,"APAGADO") -> 0 | K11: =(I11)/(J11+I11) -> 1
A12: ALTAMIRA | B12: ALT 08 | C12: BONOMO | D12: HUMAITA Y NECOCHEA | E12: DOMO | F12: Fibra Optica | H12: 172.20.11.215 | I12: =COUNTIF(L12:AM12,"") -> 28 | J12: =COUNTIF(L12:AM12,"APAGADO") -> 0 | K12: =(I12)/(J12+I12) -> 1
A13: ALTAMIRA | B13: ALT 09 | C13: BONOMO | D13: NECOCHEA Y CURUPAITY | E13: DOMO | F13: Fibra Optica | H13: 172.20.11.216 | I13: =COUNTIF(L13:AM13,"") -> 28 | J13: =COUNTIF(L13:AM13,"APAGADO") -> 0 | K13: =(I13)/(J13+I13) -> 1
A14: ALTAMIRA | B14: ALT 10 | C14: BONOMO | D14: Calchaqui y Francia | E14: Domo | F14: Radio | H14: 172.20.12.156 | I14: =COUNTIF(L14:AM14,"") -> 26 | J14: =COUNTIF(L14:AM14,"APAGADO") -> 2 | K14: =(I14)/(J14+I14) -> 0.92857143 | L14: APAGADO | M14: APAGADO
A15: AGUSTIN RAMIREZ | B15: ARA 01 | C15: BONOMO | D15: Malambo y Tranquera | E15: Domo | F15: Fibra Optica | H15: 172.20.12.110 | I15: =COUNTIF(L15:AM15,"") -> 28 | J15: =COUNTIF(L15:AM15,"APAGADO") -> 0 | K15: =(I15)/(J15+I15) -> 1
A16: BELGRANO | B16: BEL 01 | C16: BONOMO | D16: San Martin y Dardo Rocha | E16: DOMO | F16: Fibra Optica | H16: 172.20.12.64 | I16: =COUNTIF(L16:AM16,"") -> 28 | J16: =COUNTIF(L16:AM16,"APAGADO") -> 0 | K16: =(I16)/(J16+I16) -> 1
A17: BELGRANO | B17: BEL 02 | C17: BONOMO | D17: Guardia vieja y Fronteriz | E17: DOMO | F17: Fibra Optica | H17: 172.20.10.117 | I17: =COUNTIF(L17:AM17,"") -> 28 | J17: =COUNTIF(L17:AM17,"APAGADO") -> 0 | K17: =(I17)/(J17+I17) -> 1
A18: BOSQUES CENTRO | B18: BOSQC 01 | C18: COSEIDI | D18: LUIS AGOTE E/DANUNCIO Y CAMPOAMOR | E18: Fija | F18: Radio | H18: 172.20.11.15 | I18: =COUNTIF(L18:AM18,"") -> 28 | J18: =COUNTIF(L18:AM18,"APAGADO") -> 0 | K18: =(I18)/(J18+I18) -> 1
A19: BOSQUES CENTRO | B19: BOSQC 02 | C19: COSEIDI | D19: LUIS AGOTE E/DANUNCIO Y CAMPOAMOR | E19: Fija | F19: Radio | H19: 172.20.11.16 | I19: =COUNTIF(L19:AM19,"") -> 28 | J19: =COUNTIF(L19:AM19,"APAGADO") -> 0 | K19: =(I19)/(J19+I19) -> 1
A20: BOSQUES CENTRO | B20: BOSQC 03 | C20: COSEIDI | D20: BENAVENTE Y LUIS AGOTE | E20: Fija | F20: Radio | H20: 172.20.11.13 | I20: =COUNTIF(L20:AM20,"") -> 28 | J20: =COUNTIF(L20:AM20,"APAGADO") -> 0 | K20: =(I20)/(J20+I20) -> 1
A21: BOSQUES CENTRO | B21: BOSQC 04 | C21: COSEIDI | D21: BENAVENTE Y LUIS AGOTE | E21: Fija | F21: Radio | H21: 172.20.11.113 | I21: =COUNTIF(L21:AM21,"") -> 28 | J21: =COUNTIF(L21:AM21,"APAGADO") -> 0 | K21: =(I21)/(J21+I21) -> 1
A22: BOSQUES CENTRO | B22: BOSQC 05 | C22: COSEIDI | D22: LUIS AGOTE Y RUTA 36 | E22: Fija | F22: Radio | H22: 172.20.11.17 | I22: =COUNTIF(L22:AM22,"") -> 28 | J22: =COUNTIF(L22:AM22,"APAGADO") -> 0 | K22: =(I22)/(J22+I22) -> 1
A23: BOSQUES CENTRO | B23: BOSQC 06 | C23: COSEIDI | D23: LUIS AGOTE Y RUTA 36 | E23: Fija | F23: Radio | H23: 172.20.11.18 | I23: =COUNTIF(L23:AM23,"") -> 28 | J23: =COUNTIF(L23:AM23,"APAGADO") -> 0 | K23: =(I23)/(J23+I23) -> 1
A24: BOSQUES CENTRO | B24: BOSQC 07 | C24: BONOMO | D24: Touring club y Sta Teresita | E24: Domo | F24: Fibra Optica | H24: 172320,10,141 | I24: =COUNTIF(L24:AM24,"") -> 28 | J24: =COUNTIF(L24:AM24,"APAGADO") -> 0 | K24: =(I24)/(J24+I24) -> 1
A25: BOSQUES CENTRO | B25: PAVE01 | C25: BONOMO | D25: Touring Club y Ramallo | E25: Domo | F25: Fibra Optica | H25: 172,20,10,144 | I25: =COUNTIF(L25:AM25,"") -> 28 | J25: =COUNTIF(L25:AM25,"APAGADO") -> 0 | K25: =(I25)/(J25+I25) -> 1
A26: CENTRO | B26: CEN01 | C26: BONOMO | D26: San Martin y 9 de Julio | E26: Fija | F26: Fibra Optica | H26: 172.20.11.10 | I26: =COUNTIF(L26:AM26,"") -> 26 | J26: =COUNTIF(L26:AM26,"APAGADO") -> 2 | K26: =(I26)/(J26+I26) -> 0.92857143 | L26: APAGADO | M26: APAGADO
A27: CENTRO | B27: CEN02 | C27: BONOMO | D27: San Martin y Almafuerte | E27: Fija | F27: Fibra Optica | H27: 172.20.11.11 | I27: =COUNTIF(L27:AM27,"") -> 26 | J27: =COUNTIF(L27:AM27,"APAGADO") -> 2 | K27: =(I27)/(J27+I27) -> 0.92857143 | L27: APAGADO | M27: APAGADO
A28: CENTRO | B28: CEN03 | C28: BONOMO | D28: San Martin y Sallares | E28: Domo | F28: Fibra Optica | H28: 172.20.12.30 | I28: =COUNTIF(L28:AM28,"") -> 28 | J28: =COUNTIF(L28:AM28,"APAGADO") -> 0 | K28: =(I28)/(J28+I28) -> 1
A29: CENTRO | B29: CEN04 | C29: BONOMO | D29: San Martin y Contreras | E29: Domo | F29: Fibra Optica | H29: 172.20.12.29 | I29: =COUNTIF(L29:AM29,"") -> 28 | J29: =COUNTIF(L29:AM29,"APAGADO") -> 0 | K29: =(I29)/(J29+I29) -> 1
A30: CENTRO | B30: CEN 05 | C30: BONOMO | D30: Bocuzzi e/España y San Martin | E30: DOMO | F30: Fibra Optica | H30: 172.20.10.200 | I30: =COUNTIF(L30:AM30,"") -> 28 | J30: =COUNTIF(L30:AM30,"APAGADO") -> 0 | K30: =(I30)/(J30+I30) -> 1
A31: CENTRO | B31: CEN06 | C31: BONOMO | D31: Monteagudo y A.del Valle | E31: Fija | F31: Fibra Optica | H31: 172.20.10.02 | I31: =COUNTIF(L31:AM31,"") -> 28 | J31: =COUNTIF(L31:AM31,"APAGADO") -> 0 | K31: =(I31)/(J31+I31) -> 1
A32: CENTRO | B32: CEN07 | C32: BONOMO | D32: San Martin y Guemes | E32: DOMO | F32: Fibra Optica | H32: 172.20.11.20 | I32: =COUNTIF(L32:AM32,"") -> 28 | J32: =COUNTIF(L32:AM32,"APAGADO") -> 0 | K32: =(I32)/(J32+I32) -> 1
A33: CENTRO | B33: CEN08 | C33: BONOMO | D33: San Martin y Pte.Peron | E33: Domo | F33: Fibra Optica | H33: 172.20.11.21 | I33: =COUNTIF(L33:AM33,"") -> 28 | J33: =COUNTIF(L33:AM33,"APAGADO") -> 0 | K33: =(I33)/(J33+I33) -> 1
A34: CENTRO | B34: CEN09 | C34: BONOMO | D34: Chacabuco y 25 de Mayo | E34: Domo | F34: Fibra Optica | H34: 172.20.11.22 | I34: =COUNTIF(L34:AM34,"") -> 28 | J34: =COUNTIF(L34:AM34,"APAGADO") -> 0 | K34: =(I34)/(J34+I34) -> 1
A35: CENTRO | B35: CEN10 | C35: BONOMO | D35: Monteagudo y Pte. Peron | E35: Domo | F35: Fibra Optica | H35: 172.20.11.23 | I35: =COUNTIF(L35:AM35,"") -> 28 | J35: =COUNTIF(L35:AM35,"APAGADO") -> 0 | K35: =(I35)/(J35+I35) -> 1
A36: CENTRO | B36: CEN11 | C36: BONOMO | D36: Monteagudo y Bocuzzi | E36: Domo | F36: Fibra Optica | H36: 172.20.10.24 | I36: =COUNTIF(L36:AM36,"") -> 28 | J36: =COUNTIF(L36:AM36,"APAGADO") -> 0 | K36: =(I36)/(J36+I36) -> 1
A37: CENTRO | B37: CEN 12 | C37: BONOMO | D37: Monteagudo y Mitre | E37: Domo | F37: Fibra Optica | H37: 172.20.10.23 | I37: =COUNTIF(L37:AM37,"") -> 28 | J37: =COUNTIF(L37:AM37,"APAGADO") -> 0 | K37: =(I37)/(J37+I37) -> 1
A38: CENTRO | B38: CEN 13 | C38: BONOMO | D38: 25 de Mayo y Maipu | E38: DOMO | F38: Fibra Optica | H38: 172.20.10.20 | I38: =COUNTIF(L38:AM38,"") -> 28 | J38: =COUNTIF(L38:AM38,"APAGADO") -> 0 | K38: =(I38)/(J38+I38) -> 1
A39: CENTRO | B39: CEN14 | C39: BONOMO | D39: Pte.Peron e/Pringles y Brown | E39: Domo | F39: Fibra Optica | H39: 172.20.10.94 | I39: =COUNTIF(L39:AM39,"") -> 28 | J39: =COUNTIF(L39:AM39,"APAGADO") -> 0 | K39: =(I39)/(J39+I39) -> 1
... A41: CENTRO | B41: CEN16 | C41: BONOMO | D41: San Martin y Pte. Peron | E41: Fija | F41: Fibra Optica | H41: 172.20.12.36 | I41: =COUNTIF(L41:AM41,"") -> 28 | J41: =COUNTIF(L41:AM41,"APAGADO") -> 0 | K41: =(I41)/(J41+I41) -> 1
...

Sheet Hoja3

Sheet ESTADISTICA
A1: ='RESUMEN TOTAL'!A4 -> Barrio | B1: ='RESUMEN TOTAL'!B4 -> [Denominacion] | C1: ='RESUMEN TOTAL'!D4 -> [Ubicacion] | D1: ='RESUMEN TOTAL'!E4 -> [Tipo de Camara] | E1: ='RESUMEN TOTAL'!F4 -> [Tipo de Conexion] | F1: ='RESUMEN TOTAL'!L4 -> 45292 | G1: ='RESUMEN TOTAL'!M4 -> 45293 | H1: ='RESUMEN TOTAL'!N4 -> 45294 | I1: ='RESUMEN TOTAL'!O4 -> 45295 | J1: ='RESUMEN TOTAL'!P4 -> 45296 | K1: ='RESUMEN TOTAL'!Q4 -> 45297 | L1: ='RESUMEN TOTAL'!R4 -> 45298 | M1: ='RESUMEN TOTAL'!S4 -> 45299 | ... AI1: ='RESUMEN TOTAL'!AO4 -> 45321
A2: ='RESUMEN TOTAL'!A5 -> ALTAMIRA | B2: ='RESUMEN TOTAL'!B5 -> ALT01 | C2: ='RESUMEN TOTAL'!D5 -> Calchaqui y Sgto. Cabral | D2: ='RESUMEN TOTAL'!E5 -> Domo | E2: ='RESUMEN TOTAL'!F5 -> Fibra Optica | F2: ='RESUMEN TOTAL'!L5 -> 0 | G2: ='RESUMEN TOTAL'!M5 -> 0 | H2: ='RESUMEN TOTAL'!N5 -> 0 | I2: ='RESUMEN TOTAL'!O5 -> 0 | J2: ='RESUMEN TOTAL'!P5 -> 0 | K2: ='RESUMEN TOTAL'!Q5 -> 0 | L2: ='RESUMEN TOTAL'!R5 -> 0 | M2: ='RESUMEN TOTAL'!S5 -> 0 | ... AI2: ='RESUMEN TOTAL'!AO5 -> 0
A3: ='RESUMEN TOTAL'!A6 -> ALTAMIRA | B3: ='RESUMEN TOTAL'!B6 -> ALT02 | C3: ='RESUMEN TOTAL'!D6 -> Calchaqui y Lope de Vega | D3: ='RESUMEN TOTAL'!E6 -> Domo | E3: ='RESUMEN TOTAL'!F6 -> PTO A FO | F3: ='RESUMEN TOTAL'!L6 -> 0 | G3: ='RESUMEN TOTAL'!M6 -> 0 | H3: ='RESUMEN TOTAL'!N6 -> 0 | I3: ='RESUMEN TOTAL'!O6 -> 0 | J3: ='RESUMEN TOTAL'!P6 -> 0 | K3: ='RESUMEN TOTAL'!Q6 -> 0 | L3: ='RESUMEN TOTAL'!R6 -> 0 | M3: ='RESUMEN TOTAL'!S6 -> 0 | ... AI3: ='RESUMEN TOTAL'!AO6 -> 0
A4: ='RESUMEN TOTAL'!A7 -> ALTAMIRA | B4: ='RESUMEN TOTAL'!B7 -> ALT 03 | C4: ='RESUMEN TOTAL'!D7 -> Bombero Galarza y Necochea | D4: ='RESUMEN TOTAL'!E7 -> Domo | E4: ='RESUMEN TOTAL'!F7 -> Fibra Optica | F4: ='RESUMEN TOTAL'!L7 -> 0 | G4: ='RESUMEN TOTAL'!M7 -> 0 | H4: ='RESUMEN TOTAL'!N7 -> 0 | I4: ='RESUMEN TOTAL'!O7 -> 0 | J4: ='RESUMEN TOTAL'!P7 -> 0 | K4: ='RESUMEN TOTAL'!Q7 -> 0 | L4: ='RESUMEN TOTAL'!R7 -> 0 | M4: ='RESUMEN TOTAL'!S7 -> 0 | ... AI4: ='RESUMEN TOTAL'!AO7 -> 0
A5: ='RESUMEN TOTAL'!A8 -> ALTAMIRA | B5: ='RESUMEN TOTAL'!B8 -> ALT 04 | C5: ='RESUMEN TOTAL'!D8 -> Francia y Necochea | D5: ='RESUMEN TOTAL'!E8 -> Domo | E5: ='RESUMEN TOTAL'!F8 -> Fibra Optica | F5: ='RESUMEN TOTAL'!L8 -> 0 | G5: ='RESUMEN TOTAL'!M8 -> 0 | H5: ='RESUMEN TOTAL'!N8 -> 0 | I5: ='RESUMEN TOTAL'!O8 -> 0 | J5: ='RESUMEN TOTAL'!P8 -> 0 | K5: ='RESUMEN TOTAL'!Q8 -> 0 | L5: ='RESUMEN TOTAL'!R8 -> 0 | M5: ='RESUMEN TOTAL'!S8 -> 0 | ... AI5: ='RESUMEN TOTAL'!AO8 -> 0
A6: ='RESUMEN TOTAL'!A9 -> ALTAMIRA | B6: ='RESUMEN TOTAL'!B9 -> ALT05 | C6: ='RESUMEN TOTAL'!D9 -> Av. Calchaqui y Bombero Galarza | D6: ='RESUMEN TOTAL'!E9 -> Domo | E6: ='RESUMEN TOTAL'!F9 -> PTO A FO | F6: ='RESUMEN TOTAL'!L9 -> 0 | G6: ='RESUMEN TOTAL'!M9 -> APAGADO | H6: ='RESUMEN TOTAL'!N9 -> 0 | I6: ='RESUMEN TOTAL'!O9 -> 0 | J6: ='RESUMEN TOTAL'!P9 -> 0 | K6: ='RESUMEN TOTAL'!Q9 -> 0 | L6: ='RESUMEN TOTAL'!R9 -> 0 | M6: ='RESUMEN TOTAL'!S9 -> 0 | ... AI6: ='RESUMEN TOTAL'!AO9 -> 0
A7: ='RESUMEN TOTAL'!A10 -> ALTAMIRA | B7: ='RESUMEN TOTAL'!B10 -> ALT 06 | C7: ='RESUMEN TOTAL'!D10 -> LOPE DE VEGA Y NECOCHEA | D7: ='RESUMEN TOTAL'!E10 -> Domo | E7: ='RESUMEN TOTAL'!F10 -> PTO A FO | F7: ='RESUMEN TOTAL'!L10 -> 0 | G7: ='RESUMEN TOTAL'!M10 -> 0 | H7: ='RESUMEN TOTAL'!N10 -> 0 | I7: ='RESUMEN TOTAL'!O10 -> 0 | J7: ='RESUMEN TOTAL'!P10 -> 0 | K7: ='RESUMEN TOTAL'!Q10 -> 0 | L7: ='RESUMEN TOTAL'!R10 -> 0 | M7: ='RESUMEN TOTAL'!S10 -> 0 | ... AI7: ='RESUMEN TOTAL'!AO10 -> 0
A8: ='RESUMEN TOTAL'!A11 -> ALTAMIRA | B8: ='RESUMEN TOTAL'!B11 -> ALT07 | C8: ='RESUMEN TOTAL'!D11 -> AV. CALCHAQUI Y AV. DEL TRABAJO | D8: ='RESUMEN TOTAL'!E11 -> DOMO | E8: ='RESUMEN TOTAL'!F11 -> PTO A FO | F8: ='RESUMEN TOTAL'!L11 -> 0 | G8: ='RESUMEN TOTAL'!M11 -> 0 | H8: ='RESUMEN TOTAL'!N11 -> 0 | I8: ='RESUMEN TOTAL'!O11 -> 0 | J8: ='RESUMEN TOTAL'!P11 -> 0 | K8: ='RESUMEN TOTAL'!Q11 -> 0 | L8: ='RESUMEN TOTAL'!R11 -> 0 | M8: ='RESUMEN TOTAL'!S11 -> 0 | ... AI8: ='RESUMEN TOTAL'!AO11 -> 0
A9: ='RESUMEN TOTAL'!A12 -> ALTAMIRA | B9: ='RESUMEN TOTAL'!B12 -> ALT 08 | C9: ='RESUMEN TOTAL'!D12 -> HUMAITA Y NECOCHEA | D9: ='RESUMEN TOTAL'!E12 -> DOMO | E9: ='RESUMEN TOTAL'!F12 -> Fibra Optica | F9: ='RESUMEN TOTAL'!L12 -> 0 | G9: ='RESUMEN TOTAL'!M12 -> 0 | H9: ='RESUMEN TOTAL'!N12 -> 0 | I9: ='RESUMEN TOTAL'!O12 -> 0 | J9: ='RESUMEN TOTAL'!P12 -> 0 | K9: ='RESUMEN TOTAL'!Q12 -> 0 | L9: ='RESUMEN TOTAL'!R12 -> 0 | M9: ='RESUMEN TOTAL'!S12 -> 0 | ... AI9: ='RESUMEN TOTAL'!AO12 -> 0
A10: ='RESUMEN TOTAL'!A13 -> ALTAMIRA | B10: ='RESUMEN TOTAL'!B13 -> ALT 09 | C10: ='RESUMEN TOTAL'!D13 -> NECOCHEA Y CURUPAITY | D10: ='RESUMEN TOTAL'!E13 -> DOMO | E10: ='RESUMEN TOTAL'!F13 -> Fibra Optica | F10: ='RESUMEN TOTAL'!L13 -> 0 | G10: ='RESUMEN TOTAL'!M13 -> 0 | H10: ='RESUMEN TOTAL'!N13 -> 0 | I10: ='RESUMEN TOTAL'!O13 -> 0 | J10: ='RESUMEN TOTAL'!P13 -> 0 | K10: ='RESUMEN TOTAL'!Q13 -> 0 | L10: ='RESUMEN TOTAL'!R13 -> 0 | M10: ='RESUMEN TOTAL'!S13 -> 0 | ... AI10: ='RESUMEN TOTAL'!AO13 -> 0
A11: ='RESUMEN TOTAL'!A14 -> ALTAMIRA | B11: ='RESUMEN TOTAL'!B14 -> ALT 10 | C11: ='RESUMEN TOTAL'!D14 -> Calchaqui y Francia | D11: ='RESUMEN TOTAL'!E14 -> Domo | E11: ='RESUMEN TOTAL'!F14 -> Radio | F11: ='RESUMEN TOTAL'!L14 -> APAGADO | G11: ='RESUMEN TOTAL'!M14 -> APAGADO | H11: ='RESUMEN TOTAL'!N14 -> 0 | I11: ='RESUMEN TOTAL'!O14 -> 0 | J11: ='RESUMEN TOTAL'!P14 -> 0 | K11: ='RESUMEN TOTAL'!Q14 -> 0 | L11: ='RESUMEN TOTAL'!R14 -> 0 | M11: ='RESUMEN TOTAL'!S14 -> 0 | ... AI11: ='RESUMEN TOTAL'!AO14 -> 0
A12: ='RESUMEN TOTAL'!A15 -> AGUSTIN RAMIREZ | B12: ='RESUMEN TOTAL'!B15 -> ARA 01 | C12: ='RESUMEN TOTAL'!D15 -> Malambo y Tranquera | D12: ='RESUMEN TOTAL'!E15 -> Domo | E12: ='RESUMEN TOTAL'!F15 -> Fibra Optica | F12: ='RESUMEN TOTAL'!L15 -> 0 | G12: ='RESUMEN TOTAL'!M15 -> 0 | H12: ='RESUMEN TOTAL'!N15 -> 0 | I12: ='RESUMEN TOTAL'!O15 -> 0 | J12: ='RESUMEN TOTAL'!P15 -> 0 | K12: ='RESUMEN TOTAL'!Q15 -> 0 | L12: ='RESUMEN TOTAL'!R15 -> 0 | M12: ='RESUMEN TOTAL'!S15 -> 0 | ... AI12: ='RESUMEN TOTAL'!AO15 -> 0
... A20: ='RESUMEN TOTAL'!A23 -> BOSQUES CENTRO | B20: ='RESUMEN TOTAL'!B23 -> BOSQC 06 | C20: ='RESUMEN TOTAL'!D23 -> LUIS AGOTE Y RUTA 36 | D20: ='RESUMEN TOTAL'!E23 -> Fija | E20: ='RESUMEN TOTAL'!F23 -> Radio | F20: ='RESUMEN TOTAL'!L23 -> 0 | G20: ='RESUMEN TOTAL'!M23 -> 0 | H20: ='RESUMEN TOTAL'!N23 -> 0 | I20: ='RESUMEN TOTAL'!O23 -> 0 | J20: ='RESUMEN TOTAL'!P23 -> 0 | K20: ='RESUMEN TOTAL'!Q23 -> 0 | L20: ='RESUMEN TOTAL'!R23 -> 0 | M20: ='RESUMEN TOTAL'!S23 -> 0 | ... AI20: ='RESUMEN TOTAL'!AO23 -> 0
A21: ='RESUMEN TOTAL'!A26 -> CENTRO | B21: ='RESUMEN TOTAL'!B26 -> CEN01 | C21: ='RESUMEN TOTAL'!D26 -> San Martin y 9 de Julio | D21: ='RESUMEN TOTAL'!E26 -> Fija | E21: ='RESUMEN TOTAL'!F26 -> Fibra Optica | F21: ='RESUMEN TOTAL'!L26 -> APAGADO | G21: ='RESUMEN TOTAL'!M26 -> APAGADO | H21: ='RESUMEN TOTAL'!N26 -> 0 | I21: ='RESUMEN TOTAL'!O26 -> 0 | J21: ='RESUMEN TOTAL'!P26 -> 0 | K21: ='RESUMEN TOTAL'!Q26 -> 0 | L21: ='RESUMEN TOTAL'!R26 -> 0 | M21: ='RESUMEN TOTAL'!S26 -> 0 | ... AI21: ='RESUMEN TOTAL'!AO26 -> 0
A22: ='RESUMEN TOTAL'!A27 -> CENTRO | B22: ='RESUMEN TOTAL'!B27 -> CEN02 | C22: ='RESUMEN TOTAL'!D27 -> San Martin y Almafuerte | D22: ='RESUMEN TOTAL'!E27 -> Fija | E22: ='RESUMEN TOTAL'!F27 -> Fibra Optica | F22: ='RESUMEN TOTAL'!L27 -> APAGADO | G22: ='RESUMEN TOTAL'!M27 -> APAGADO | H22: ='RESUMEN TOTAL'!N27 -> 0 | I22: ='RESUMEN TOTAL'!O27 -> 0 | J22: ='RESUMEN TOTAL'!P27 -> 0 | K22: ='RESUMEN TOTAL'!Q27 -> 0 | L22: ='RESUMEN TOTAL'!R27 -> 0 | M22: ='RESUMEN TOTAL'!S27 -> 0 | ... AI22: ='RESUMEN TOTAL'!AO27 -> 0
A23: ='RESUMEN TOTAL'!A28 -> CENTRO | B23: ='RESUMEN TOTAL'!B28 -> CEN03 | C23: ='RESUMEN TOTAL'!D28 -> San Martin y Sallares | D23: ='RESUMEN TOTAL'!E28 -> Domo | E23: ='RESUMEN TOTAL'!F28 -> Fibra Optica | F23: ='RESUMEN TOTAL'!L28 -> 0 | G23: ='RESUMEN TOTAL'!M28 -> 0 | H23: ='RESUMEN TOTAL'!N28 -> 0 | I23: ='RESUMEN TOTAL'!O28 -> 0 | J23: ='RESUMEN TOTAL'!P28 -> 0 | K23: ='RESUMEN TOTAL'!Q28 -> 0 | L23: ='RESUMEN TOTAL'!R28 -> 0 | M23: ='RESUMEN TOTAL'!S28 -> 0 | ... AI23: ='RESUMEN TOTAL'!AO28 -> 0
A24: ='RESUMEN TOTAL'!A29 -> CENTRO | B24: ='RESUMEN TOTAL'!B29 -> CEN04 | C24: ='RESUMEN TOTAL'!D29 -> San Martin y Contreras | D24: ='RESUMEN TOTAL'!E29 -> Domo | E24: ='RESUMEN TOTAL'!F29 -> Fibra Optica | F24: ='RESUMEN TOTAL'!L29 -> 0 | G24: ='RESUMEN TOTAL'!M29 -> 0 | H24: ='RESUMEN TOTAL'!N29 -> 0 | I24: ='RESUMEN TOTAL'!O29 -> 0 | J24: ='RESUMEN TOTAL'!P29 -> 0 | K24: ='RESUMEN TOTAL'!Q29 -> 0 | L24: ='RESUMEN TOTAL'!R29 -> 0 | M24: ='RESUMEN TOTAL'!S29 -> 0 | ... AI24: ='RESUMEN TOTAL'!AO29 -> 0
A25: ='RESUMEN TOTAL'!A30 -> CENTRO | B25: ='RESUMEN TOTAL'!B30 -> CEN 05 | C25: ='RESUMEN TOTAL'!D30 -> Bocuzzi e/España y San Martin | D25: ='RESUMEN TOTAL'!E30 -> DOMO | E25: ='RESUMEN TOTAL'!F30 -> Fibra Optica | F25: ='RESUMEN TOTAL'!L30 -> 0 | G25: ='RESUMEN TOTAL'!M30 -> 0 | H25: ='RESUMEN TOTAL'!N30 -> 0 | I25: ='RESUMEN TOTAL'!O30 -> 0 | J25: ='RESUMEN TOTAL'!P30 -> 0 | K25: ='RESUMEN TOTAL'!Q30 -> 0 | L25: ='RESUMEN TOTAL'!R30 -> 0 | M25: ='RESUMEN TOTAL'!S30 -> 0 | ... AI25: ='RESUMEN TOTAL'!AO30 -> 0
A26: ='RESUMEN TOTAL'!A31 -> CENTRO | B26: ='RESUMEN TOTAL'!B31 -> CEN06 | C26: ='RESUMEN TOTAL'!D31 -> Monteagudo y A.del Valle | D26: ='RESUMEN TOTAL'!E31 -> Fija | E26: ='RESUMEN TOTAL'!F31 -> Fibra Optica | F26: ='RESUMEN TOTAL'!L31 -> 0 | G26: ='RESUMEN TOTAL'!M31 -> 0 | H26: ='RESUMEN TOTAL'!N31 -> 0 | I26: ='RESUMEN TOTAL'!O31 -> 0 | J26: ='RESUMEN TOTAL'!P31 -> 0 | K26: ='RESUMEN TOTAL'!Q31 -> 0 | L26: ='RESUMEN TOTAL'!R31 -> 0 | M26: ='RESUMEN TOTAL'!S31 -> 0 | ... AI26: ='RESUMEN TOTAL'!AO31 -> 0
A27: ='RESUMEN TOTAL'!A32 -> CENTRO | B27: ='RESUMEN TOTAL'!B32 -> CEN07 | C27: ='RESUMEN TOTAL'!D32 -> San Martin y Guemes | D27: ='RESUMEN TOTAL'!E32 -> DOMO | E27: ='RESUMEN TOTAL'!F32 -> Fibra Optica | F27: ='RESUMEN TOTAL'!L32 -> 0 | G27: ='RESUMEN TOTAL'!M32 -> 0 | H27: ='RESUMEN TOTAL'!N32 -> 0 | I27: ='RESUMEN TOTAL'!O32 -> 0 | J27: ='RESUMEN TOTAL'!P32 -> 0 | K27: ='RESUMEN TOTAL'!Q32 -> 0 | L27: ='RESUMEN TOTAL'!R32 -> 0 | M27: ='RESUMEN TOTAL'!S32 -> 0 | ... AI27: ='RESUMEN TOTAL'!AO32 -> 0
A28: ='RESUMEN TOTAL'!A33 -> CENTRO | B28: ='RESUMEN TOTAL'!B33 -> CEN08 | C28: ='RESUMEN TOTAL'!D33 -> San Martin y Pte.Peron | D28: ='RESUMEN TOTAL'!E33 -> Domo | E28: ='RESUMEN TOTAL'!F33 -> Fibra Optica | F28: ='RESUMEN TOTAL'!L33 -> 0 | G28: ='RESUMEN TOTAL'!M33 -> 0 | H28: ='RESUMEN TOTAL'!N33 -> 0 | I28: ='RESUMEN TOTAL'!O33 -> 0 | J28: ='RESUMEN TOTAL'!P33 -> 0 | K28: ='RESUMEN TOTAL'!Q33 -> 0 | L28: ='RESUMEN TOTAL'!R33 -> 0 | M28: ='RESUMEN TOTAL'!S33 -> 0 | ... AI28: ='RESUMEN TOTAL'!AO33 -> 0
A29: ='RESUMEN TOTAL'!A34 -> CENTRO | B29: ='RESUMEN TOTAL'!B34 -> CEN09 | C29: ='RESUMEN TOTAL'!D34 -> Chacabuco y 25 de Mayo | D29: ='RESUMEN TOTAL'!E34 -> Domo | E29: ='RESUMEN TOTAL'!F34 -> Fibra Optica | F29: ='RESUMEN TOTAL'!L34 -> 0 | G29: ='RESUMEN TOTAL'!M34 -> 0 | H29: ='RESUMEN TOTAL'!N34 -> 0 | I29: ='RESUMEN TOTAL'!O34 -> 0 | J29: ='RESUMEN TOTAL'!P34 -> 0 | K29: ='RESUMEN TOTAL'!Q34 -> 0 | L29: ='RESUMEN TOTAL'!R34 -> 0 | M29: ='RESUMEN TOTAL'!S34 -> 0 | ... AI29: ='RESUMEN TOTAL'!AO34 -> 0
A30: ='RESUMEN TOTAL'!A35 -> CENTRO | B30: ='RESUMEN TOTAL'!B35 -> CEN10 | C30: ='RESUMEN TOTAL'!D35 -> Monteagudo y Pte. Peron | D30: ='RESUMEN TOTAL'!E35 -> Domo | E30: ='RESUMEN TOTAL'!F35 -> Fibra Optica | F30: ='RESUMEN TOTAL'!L35 -> 0 | G30: ='RESUMEN TOTAL'!M35 -> 0 | H30: ='RESUMEN TOTAL'!N35 -> 0 | I30: ='RESUMEN TOTAL'!O35 -> 0 | J30: ='RESUMEN TOTAL'!P35 -> 0 | K30: ='RESUMEN TOTAL'!Q35 -> 0 | L30: ='RESUMEN TOTAL'!R35 -> 0 | M30: ='RESUMEN TOTAL'!S35 -> 0 | ... AI30: ='RESUMEN TOTAL'!AO35 -> 0
A31: ='RESUMEN TOTAL'!A36 -> CENTRO | B31: ='RESUMEN TOTAL'!B36 -> CEN11 | C31: ='RESUMEN TOTAL'!D36 -> Monteagudo y Bocuzzi | D31: ='RESUMEN TOTAL'!E36 -> Domo | E31: ='RESUMEN TOTAL'!F36 -> Fibra Optica | F31: ='RESUMEN TOTAL'!L36 -> 0 | G31: ='RESUMEN TOTAL'!M36 -> 0 | H31: ='RESUMEN TOTAL'!N36 -> 0 | I31: ='RESUMEN TOTAL'!O36 -> 0 | J31: ='RESUMEN TOTAL'!P36 -> 0 | K31: ='RESUMEN TOTAL'!Q36 -> 0 | L31: ='RESUMEN TOTAL'!R36 -> 0 | M31: ='RESUMEN TOTAL'!S36 -> 0 | ... AI31: ='RESUMEN TOTAL'!AO36 -> 0
A32: ='RESUMEN TOTAL'!A37 -> CENTRO | B32: ='RESUMEN TOTAL'!B37 -> CEN 12 | C32: ='RESUMEN TOTAL'!D37 -> Monteagudo y Mitre | D32: ='RESUMEN TOTAL'!E37 -> Domo | E32: ='RESUMEN TOTAL'!F37 -> Fibra Optica | F32: ='RESUMEN TOTAL'!L37 -> 0 | G32: ='RESUMEN TOTAL'!M37 -> 0 | H32: ='RESUMEN TOTAL'!N37 -> 0 | I32: ='RESUMEN TOTAL'!O37 -> 0 | J32: ='RESUMEN TOTAL'!P37 -> 0 | K32: ='RESUMEN TOTAL'!Q37 -> 0 | L32: ='RESUMEN TOTAL'!R37 -> 0 | M32: ='RESUMEN TOTAL'!S37 -> 0 | ... AI32: ='RESUMEN TOTAL'!AO37 -> 0
... A123: ='RESUMEN TOTAL'!A128 -> DON ORIONE | B123: ='RESUMEN TOTAL'!B128 -> DORIO1 | C123: ='RESUMEN TOTAL'!D128 -> AV Bosques Y Theran | D123: ='RESUMEN TOTAL'!E128 -> Domo | E123: ='RESUMEN TOTAL'!F128 -> GPON | F123: ='RESUMEN TOTAL'!L128 -> 0 | G123: ='RESUMEN TOTAL'!M128 -> 0 | H123: ='RESUMEN TOTAL'!N128 -> 0 | I123: ='RESUMEN TOTAL'!O128 -> 0 | J123: ='RESUMEN TOTAL'!P128 -> 0 | K123: ='RESUMEN TOTAL'!Q128 -> 0 | L123: ='RESUMEN TOTAL'!R128 -> 0 | M123: ='RESUMEN TOTAL'!S128 -> 0 | ... AI123: ='RESUMEN TOTAL'!AO128 -> 0
A124: ='RESUMEN TOTAL'!A130 -> EL PARQUE | B124: ='RESUMEN TOTAL'!B130 -> EPQ 01 | C124: ='RESUMEN TOTAL'!D130 -> 1282 Y GRIERSON | D124: ='RESUMEN TOTAL'!E130 -> DOMO | E124: ='RESUMEN TOTAL'!F130 -> Fibra Optica | F124: ='RESUMEN TOTAL'!L130 -> 0 | G124: ='RESUMEN TOTAL'!M130 -> 0 | H124: ='RESUMEN TOTAL'!N130 -> 0 | I124: ='RESUMEN TOTAL'!O130 -> 0 | J124: ='RESUMEN TOTAL'!P130 -> 0 | K124: ='RESUMEN TOTAL'!Q130 -> 0 | L124: ='RESUMEN TOTAL'!R130 -> 0 | M124: ='RESUMEN TOTAL'!S130 -> 0 | ... AI124: ='RESUMEN TOTAL'!AO130 -> 0
A125: ='RESUMEN TOTAL'!A131 -> EL PARQUE | B125: ='RESUMEN TOTAL'!B131 -> EPQ 02 | C125: ='RESUMEN TOTAL'!D131 -> 1282 Y MASSE | D125: ='RESUMEN TOTAL'!E131 -> DOMO | E125: ='RESUMEN TOTAL'!F131 -> Fibra Optica | F125: ='RESUMEN TOTAL'!L131 -> 0 | G125: ='RESUMEN TOTAL'!M131 -> 0 | H125: ='RESUMEN TOTAL'!N131 -> 0 | I125: ='RESUMEN TOTAL'!O131 -> 0 | J125: ='RESUMEN TOTAL'!P131 -> 0 | K125: ='RESUMEN TOTAL'!Q131 -> 0 | L125: ='RESUMEN TOTAL'!R131 -> 0 | M125: ='RESUMEN TOTAL'!S131 -> 0 | ... AI125: ='RESUMEN TOTAL'!AO131 -> 0
A126: ='RESUMEN TOTAL'!A132 -> EL PARQUE | B126: ='RESUMEN TOTAL'!B132 -> EPQ 03 | C126: ='RESUMEN TOTAL'!D132 -> 1282 Y RP 36 | D126: ='RESUMEN TOTAL'!E132 -> Domo | E126: ='RESUMEN TOTAL'!F132 -> Fibra Optica | F126: ='RESUMEN TOTAL'!L132 -> APAGADO | G126: ='RESUMEN TOTAL'!M132 -> APAGADO | H126: ='RESUMEN TOTAL'!N132 -> 0 | I126: ='RESUMEN TOTAL'!O132 -> 0 | J126: ='RESUMEN TOTAL'!P132 -> 0 | K126: ='RESUMEN TOTAL'!Q132 -> 0 | L126: ='RESUMEN TOTAL'!R132 -> 0 | M126: ='RESUMEN TOTAL'!S132 -> 0 | ... AI126: ='RESUMEN TOTAL'!AO132 -> 0
A127: ='RESUMEN TOTAL'!A133 -> EL PARQUE | B127: ='RESUMEN TOTAL'!B133 -> EPQ 04 | C127: ='RESUMEN TOTAL'!D133 -> 1282 Y MORENO | D127: ='RESUMEN TOTAL'!E133 -> DOMO | E127: ='RESUMEN TOTAL'!F133 -> Fibra Optica | F127: ='RESUMEN TOTAL'!L133 -> 0 | G127: ='RESUMEN TOTAL'!M133 -> 0 | H127: ='RESUMEN TOTAL'!N133 -> 0 | I127: ='RESUMEN TOTAL'!O133 -> 0 | J127: ='RESUMEN TOTAL'!P133 -> 0 | K127: ='RESUMEN TOTAL'!Q133 -> 0 | L127: ='RESUMEN TOTAL'!R133 -> 0 | M127: ='RESUMEN TOTAL'!S133 -> 0 | ... AI127: ='RESUMEN TOTAL'!AO133 -> 0
A128: ='RESUMEN TOTAL'!A134 -> LA ESMERALDA | B128: ='RESUMEN TOTAL'!B134 -> ESM01 | C128: ='RESUMEN TOTAL'!D134 -> Cabello y Brasil | D128: ='RESUMEN TOTAL'!E134 -> Domo | E128: ='RESUMEN TOTAL'!F134 -> Radio | F128: ='RESUMEN TOTAL'!L134 -> APAGADO | G128: ='RESUMEN TOTAL'!M134 -> APAGADO | H128: ='RESUMEN TOTAL'!N134 -> 0 | I128: ='RESUMEN TOTAL'!O134 -> 0 | J128: ='RESUMEN TOTAL'!P134 -> 0 | K128: ='RESUMEN TOTAL'!Q134 -> 0 | L128: ='RESUMEN TOTAL'!R134 -> 0 | M128: ='RESUMEN TOTAL'!S134 -> 0 | ... AI128: ='RESUMEN TOTAL'!AO134 -> 0
A129: ='RESUMEN TOTAL'!A135 -> SAN JORGE | B129: ='RESUMEN TOTAL'!B135 -> ESM02 | C129: ='RESUMEN TOTAL'!D135 -> Novak y Cabello | D129: ='RESUMEN TOTAL'!E135 -> Domo | E129: ='RESUMEN TOTAL'!F135 -> PTO A FO | F129: ='RESUMEN TOTAL'!L135 -> 0 | G129: ='RESUMEN TOTAL'!M135 -> 0 | H129: ='RESUMEN TOTAL'!N135 -> 0 | I129: ='RESUMEN TOTAL'!O135 -> 0 | J129: ='RESUMEN TOTAL'!P135 -> 0 | K129: ='RESUMEN TOTAL'!Q135 -> 0 | L129: ='RESUMEN TOTAL'!R135 -> 0 | M129: ='RESUMEN TOTAL'!S135 -> 0 | ... AI129: ='RESUMEN TOTAL'!AO135 -> 0
A130: ='RESUMEN TOTAL'!A136 -> SAN JORGE | B130: ='RESUMEN TOTAL'!B136 -> ESM03 | C130: ='RESUMEN TOTAL'!D136 -> Novak y Humahuaca | D130: ='RESUMEN TOTAL'!E136 -> DOMO | E130: ='RESUMEN TOTAL'!F136 -> PTO A FO | F130: ='RESUMEN TOTAL'!L136 -> 0 | G130: ='RESUMEN TOTAL'!M136 -> 0 | H130: ='RESUMEN TOTAL'!N136 -> 0 | I130: ='RESUMEN TOTAL'!O136 -> 0 | J130: ='RESUMEN TOTAL'!P136 -> 0 | K130: ='RESUMEN TOTAL'!Q136 -> 0 | L130: ='RESUMEN TOTAL'!R136 -> 0 | M130: ='RESUMEN TOTAL'!S136 -> 0 | ... AI130: ='RESUMEN TOTAL'!AO136 -> 0
A131: ='RESUMEN TOTAL'!A137 -> LA ESMERALDA | B131: ='RESUMEN TOTAL'!B137 -> ESM04 | C131: ='RESUMEN TOTAL'!D137 -> Basualdo y Bengochea | D131: ='RESUMEN TOTAL'!E137 -> Domo | E131: ='RESUMEN TOTAL'!F137 -> Fibra Optica | F131: ='RESUMEN TOTAL'!L137 -> 0 | G131: ='RESUMEN TOTAL'!M137 -> 0 | H131: ='RESUMEN TOTAL'!N137 -> 0 | I131: ='RESUMEN TOTAL'!O137 -> 0 | J131: ='RESUMEN TOTAL'!P137 -> 0 | K131: ='RESUMEN TOTAL'!Q137 -> 0 | L131: ='RESUMEN TOTAL'!R137 -> 0 | M131: ='RESUMEN TOTAL'!S137 -> 0 | ... AI131: ='RESUMEN TOTAL'!AO137 -> 0
A132: ='RESUMEN TOTAL'!A138 -> LA ESMERALDA | B132: ='RESUMEN TOTAL'!B138 -> ESM05 | C132: ='RESUMEN TOTAL'!D138 -> Aniceto Diaz y Villar | D132: ='RESUMEN TOTAL'!E138 -> Domo | E132: ='RESUMEN TOTAL'!F138 -> Fibra Optica | F132: ='RESUMEN TOTAL'!L138 -> 0 | G132: ='RESUMEN TOTAL'!M138 -> 0 | H132: ='RESUMEN TOTAL'!N138 -> 0 | I132: ='RESUMEN TOTAL'!O138 -> 0 | J132: ='RESUMEN TOTAL'!P138 -> 0 | K132: ='RESUMEN TOTAL'!Q138 -> 0 | L132: ='RESUMEN TOTAL'!R138 -> 0 | M132: ='RESUMEN TOTAL'!S138 -> 0 | ... AI132: ='RESUMEN TOTAL'!AO138 -> 0
A133: ='RESUMEN TOTAL'!A139 -> LA ESMERALDA | B133: ='RESUMEN TOTAL'!B139 -> ESM06 | C133: ='RESUMEN TOTAL'!D139 -> Roselli y Cabello | D133: ='RESUMEN TOTAL'!E139 -> Domo | E133: ='RESUMEN TOTAL'!F139 -> Radio | F133: ='RESUMEN TOTAL'!L139 -> 0 | G133: ='RESUMEN TOTAL'!M139 -> 0 | H133: ='RESUMEN TOTAL'!N139 -> 0 | I133: ='RESUMEN TOTAL'!O139 -> 0 | J133: ='RESUMEN TOTAL'!P139 -> 0 | K133: ='RESUMEN TOTAL'!Q139 -> 0 | L133: ='RESUMEN TOTAL'!R139 -> 0 | M133: ='RESUMEN TOTAL'!S139 -> 0 | ... AI133: ='RESUMEN TOTAL'!AO139 -> 0
A134: ='RESUMEN TOTAL'!A140 -> LA ESMERALDA | B134: ='RESUMEN TOTAL'!B140 -> ESM07 | C134: ='RESUMEN TOTAL'!D140 -> AV. NOVAK Y SERRANO | D134: ='RESUMEN TOTAL'!E140 -> DOMO | E134: ='RESUMEN TOTAL'!F140 -> PTO A FO | F134: ='RESUMEN TOTAL'!L140 -> 0 | G134: ='RESUMEN TOTAL'!M140 -> 0 | H134: ='RESUMEN TOTAL'!N140 -> 0 | I134: ='RESUMEN TOTAL'!O140 -> 0 | J134: ='RESUMEN TOTAL'!P140 -> 0 | K134: ='RESUMEN TOTAL'!Q140 -> 0 | L134: ='RESUMEN TOTAL'!R140 -> 0 | M134: ='RESUMEN TOTAL'!S140 -> 0 | ... AI134: ='RESUMEN TOTAL'!AO140 -> 0
A135: ='RESUMEN TOTAL'!A141 -> LA ESMERALDA | B135: ='RESUMEN TOTAL'!B141 -> ESM 08 | C135: ='RESUMEN TOTAL'!D141 -> DAVINSON Y MORANCHEL | D135: ='RESUMEN TOTAL'!E141 -> FIJA | E135: ='RESUMEN TOTAL'!F141 -> Radio | F135: ='RESUMEN TOTAL'!L141 -> 0 | G135: ='RESUMEN TOTAL'!M141 -> 0 | H135: ='RESUMEN TOTAL'!N141 -> 0 | I135: ='RESUMEN TOTAL'!O141 -> 0 | J135: ='RESUMEN TOTAL'!P141 -> 0 | K135: ='RESUMEN TOTAL'!Q141 -> 0 | L135: ='RESUMEN TOTAL'!R141 -> 0 | M135: ='RESUMEN TOTAL'!S141 -> 0 | ... AI135: ='RESUMEN TOTAL'!AO141 -> 0
... A225: ='RESUMEN TOTAL'!A231 -> 9 DE JULIO | B225: ='RESUMEN TOTAL'!B231 -> NJU09 | C225: ='RESUMEN TOTAL'!D231 -> PARRILLO Y CONTRERAS | D225: ='RESUMEN TOTAL'!E231 -> DOMO | E225: ='RESUMEN TOTAL'!F231 -> Fibra Optica | F225: ='RESUMEN TOTAL'!L231 -> 0 | G225: ='RESUMEN TOTAL'!M231 -> APAGADO | H225: ='RESUMEN TOTAL'!N231 -> 0 | I225: ='RESUMEN TOTAL'!O231 -> 0 | J225: ='RESUMEN TOTAL'!P231 -> 0 | K225: ='RESUMEN TOTAL'!Q231 -> 0 | L225: ='RESUMEN TOTAL'!R231 -> 0 | M225: ='RESUMEN TOTAL'!S231 -> 0 | ... AI225: ='RESUMEN TOTAL'!AO231 -> 0
A226: ='RESUMEN TOTAL'!A233 -> PICO DE ORO | B226: ='RESUMEN TOTAL'!B233 -> PCO 01 | C226: ='RESUMEN TOTAL'!D233 -> CEMENTERIO | D226: ='RESUMEN TOTAL'!E233 -> DOMO | E226: ='RESUMEN TOTAL'!F233 -> Fibra Optica | F226: ='RESUMEN TOTAL'!L233 -> 0 | G226: ='RESUMEN TOTAL'!M233 -> APAGADO | H226: ='RESUMEN TOTAL'!N233 -> 0 | I226: ='RESUMEN TOTAL'!O233 -> 0 | J226: ='RESUMEN TOTAL'!P233 -> 0 | K226: ='RESUMEN TOTAL'!Q233 -> 0 | L226: ='RESUMEN TOTAL'!R233 -> 0 | M226: ='RESUMEN TOTAL'!S233 -> 0 | ... AI226: ='RESUMEN TOTAL'!AO233 -> 0
...

Sheet APAGADOS
E1: APAGADOS | F1: =COUNTIF(F3:F404, "APAGADO") -> 48 | G1: =COUNTIF(G3:G404, "APAGADO") -> 76 | H1: =COUNTIF(H3:H504, "APAGADO") -> 0 | I1: =COUNTIF(I3:I404, "APAGADO") -> 0 | J1: =COUNTIF(J3:J404, "APAGADO") -> 0 | K1: =COUNTIF(K3:K404, "APAGADO") -> 0 | L1: =COUNTIF(L3:L404, "APAGADO") -> 0 | M1: =COUNTIF(M3:M404, "APAGADO") -> 0 | N1: =COUNTIF(N3:N404, "APAGADO") -> 0 | O1: =COUNTIF(O3:O404, "APAGADO") -> 0 | P1: =COUNTIF(P3:P404, "APAGADO") -> 0 | ... AD1: =COUNTIF(AD3:AD404, "APAGADO") -> 0 | AE1: =COUNTIF(AE3:AE504, "APAGADO") -> 0 | AF1: =COUNTIF(AF3:AF404, "APAGADO") -> 0 | AG1: =COUNTIF(AG3:AG404, "APAGADO") -> 0 | AH1: =COUNTIF(AH3:AH404, "APAGADO") -> 0 | AI1: =COUNTIF(AI3:AI404, "APAGADO") -> 0
A2: =ESTADISTICA!A1 -> Barrio | B2: =ESTADISTICA!B1 -> [Denominacion] | C2: =ESTADISTICA!C1 -> [Ubicacion] | D2: =ESTADISTICA!D1 -> [Tipo de Camara] | E2: =ESTADISTICA!E1 -> [Tipo de Conexion] | F2: =ESTADISTICA!F1 -> 45292 | G2: =ESTADISTICA!G1 -> 45293 | H2: =ESTADISTICA!H1 -> 45294 | ... AH2: =ESTADISTICA!AH1 -> 45320 | AI2: 335
A3: =ESTADISTICA!A2 -> ALTAMIRA | B3: =ESTADISTICA!B2 -> ALT01 | C3: =ESTADISTICA!C2 -> Calchaqui y Sgto. Cabral | D3: =ESTADISTICA!D2 -> Domo | E3: =ESTADISTICA!E2 -> Fibra Optica | F3: =ESTADISTICA!F2 -> 0 | G3: =ESTADISTICA!G2 -> 0 | H3: =ESTADISTICA!H2 -> 0 | ... AI3: =ESTADISTICA!AI2 -> 0
A4: =ESTADISTICA!A3 -> ALTAMIRA | B4: =ESTADISTICA!B3 -> ALT02 | C4: =ESTADISTICA!C3 -> Calchaqui y Lope de Vega | D4: =ESTADISTICA!D3 -> Domo | E4: =ESTADISTICA!E3 -> PTO A FO | F4: =ESTADISTICA!F3 -> 0 | G4: =ESTADISTICA!G3 -> 0 | H4: =ESTADISTICA!H3 -> 0 | ... AI4: =ESTADISTICA!AI3 -> 0
A5: =ESTADISTICA!A4 -> ALTAMIRA | B5: =ESTADISTICA!B4 -> ALT 03 | C5: =ESTADISTICA!C4 -> Bombero Galarza y Necochea | D5: =ESTADISTICA!D4 -> Domo | E5: =ESTADISTICA!E4 -> Fibra Optica | F5: =ESTADISTICA!F4 -> 0 | G5: =ESTADISTICA!G4 -> 0 | H5: =ESTADISTICA!H4 -> 0 | ... AI5: =ESTADISTICA!AI4 -> 0
A6: =ESTADISTICA!A5 -> ALTAMIRA | B6: =ESTADISTICA!B5 -> ALT 04 | C6: =ESTADISTICA!C5 -> Francia y Necochea | D6: =ESTADISTICA!D5 -> Domo | E6: =ESTADISTICA!E5 -> Fibra Optica | F6: =ESTADISTICA!F5 -> 0 | G6: =ESTADISTICA!G5 -> 0 | H6: =ESTADISTICA!H5 -> 0 | ... AI6: =ESTADISTICA!AI5 -> 0
A7: =ESTADISTICA!A6 -> ALTAMIRA | B7: =ESTADISTICA!B6 -> ALT05 | C7: =ESTADISTICA!C6 -> Av. Calchaqui y Bombero Galarza | D7: =ESTADISTICA!D6 -> Domo | E7: =ESTADISTICA!E6 -> PTO A FO | F7: =ESTADISTICA!F6 -> 0 | G7: =ESTADISTICA!G6 -> APAGADO | H7: =ESTADISTICA!H6 -> 0 | ... AI7: =ESTADISTICA!AI6 -> 0
A8: =ESTADISTICA!A7 -> ALTAMIRA | B8: =ESTADISTICA!B7 -> ALT 06 | C8: =ESTADISTICA!C7 -> LOPE DE VEGA Y NECOCHEA | D8: =ESTADISTICA!D7 -> Domo | E8: =ESTADISTICA!E7 -> PTO A FO | F8: =ESTADISTICA!F7 -> 0 | G8: =ESTADISTICA!G7 -> 0 | H8: =ESTADISTICA!H7 -> 0 | ... AI8: =ESTADISTICA!AI7 -> 0
A9: =ESTADISTICA!A8 -> ALTAMIRA | B9: =ESTADISTICA!B8 -> ALT07 | C9: =ESTADISTICA!C8 -> AV. CALCHAQUI Y AV. DEL TRABAJO | D9: =ESTADISTICA!D8 -> DOMO | E9: =ESTADISTICA!E8 -> PTO A FO | F9: =ESTADISTICA!F8 -> 0 | G9: =ESTADISTICA!G8 -> 0 | H9: =ESTADISTICA!H8 -> 0 | ... AI9: =ESTADISTICA!AI8 -> 0
A10: =ESTADISTICA!A9 -> ALTAMIRA | B10: =ESTADISTICA!B9 -> ALT 08 | C10: =ESTADISTICA!C9 -> HUMAITA Y NECOCHEA | D10: =ESTADISTICA!D9 -> DOMO | E10: =ESTADISTICA!E9 -> Fibra Optica | F10: =ESTADISTICA!F9 -> 0 | G10: =ESTADISTICA!G9 -> 0 | H10: =ESTADISTICA!H9 -> 0 | ... AI10: =ESTADISTICA!AI9 -> 0
A11: =ESTADISTICA!A10 -> ALTAMIRA | B11: =ESTADISTICA!B10 -> ALT 09 | C11: =ESTADISTICA!C10 -> NECOCHEA Y CURUPAITY | D11: =ESTADISTICA!D10 -> DOMO | E11: =ESTADISTICA!E10 -> Fibra Optica | F11: =ESTADISTICA!F10 -> 0 | G11: =ESTADISTICA!G10 -> 0 | H11: =ESTADISTICA!H10 -> 0 | ... AI11: =ESTADISTICA!AI10 -> 0
A12: =ESTADISTICA!A11 -> ALTAMIRA | B12: =ESTADISTICA!B11 -> ALT 10 | C12: =ESTADISTICA!C11 -> Calchaqui y Francia | D12: =ESTADISTICA!D11 -> Domo | E12: =ESTADISTICA!E11 -> Radio | F12: =ESTADISTICA!F11 -> APAGADO | G12: =ESTADISTICA!G11 -> APAGADO | H12: =ESTADISTICA!H11 -> 0 | ... AI12: =ESTADISTICA!AI11 -> 0
A13: =ESTADISTICA!A12 -> AGUSTIN RAMIREZ | B13: =ESTADISTICA!B12 -> ARA 01 | C13: =ESTADISTICA!C12 -> Malambo y Tranquera | D13: =ESTADISTICA!D12 -> Domo | E13: =ESTADISTICA!E12 -> Fibra Optica | F13: =ESTADISTICA!F12 -> 0 | G13: =ESTADISTICA!G12 -> 0 | H13: =ESTADISTICA!H12 -> 0 | ... AI13: =ESTADISTICA!AI12 -> 0
A14: =ESTADISTICA!A13 -> BELGRANO | B14: =ESTADISTICA!B13 -> BEL 01 | C14: =ESTADISTICA!C13 -> San Martin y Dardo Rocha | D14: =ESTADISTICA!D13 -> DOMO | E14: =ESTADISTICA!E13 -> Fibra Optica | F14: =ESTADISTICA!F13 -> 0 | G14: =ESTADISTICA!G13 -> 0 | H14: =ESTADISTICA!H13 -> 0 | ... AI14: =ESTADISTICA!AI13 -> 0
... A124: =ESTADISTICA!A123 -> DON ORIONE | B124: =ESTADISTICA!B123 -> DORIO1 | C124: =ESTADISTICA!C123 -> AV Bosques Y Theran | D124: =ESTADISTICA!D123 -> Domo | E124: =ESTADISTICA!E123 -> GPON | F124: =ESTADISTICA!F123 -> 0 | G124: =ESTADISTICA!G123 -> 0 | H124: =ESTADISTICA!H123 -> 0 | ... AI124: =ESTADISTICA!AI123 -> 0
A125: DON ORIONE | B125: DORI02 | C125: QUINQUELA MARTIN Y AV BOSQUES | F125: =ESTADISTICA!F124 -> 0 | G125: =ESTADISTICA!G124 -> 0 | H125: =ESTADISTICA!H124 -> 0 | I125: =ESTADISTICA!I124 -> 0 | J125: =ESTADISTICA!J124 -> 0 | K125: =ESTADISTICA!K124 -> 0 | L125: =ESTADISTICA!L124 -> 0 | M125: =ESTADISTICA!M124 -> 0 | ... AI125: =ESTADISTICA!AI124 -> 0
A126: =ESTADISTICA!A124 -> EL PARQUE | B126: =ESTADISTICA!B124 -> EPQ 01 | C126: =ESTADISTICA!C124 -> 1282 Y GRIERSON | D126: =ESTADISTICA!D124 -> DOMO | E126: =ESTADISTICA!E124 -> Fibra Optica | F126: =ESTADISTICA!F124 -> 0 | G126: =ESTADISTICA!G124 -> 0 | H126: =ESTADISTICA!H124 -> 0 | ... AI126: =ESTADISTICA!AI124 -> 0
A127: =ESTADISTICA!A125 -> EL PARQUE | B127: =ESTADISTICA!B125 -> EPQ 02 | C127: =ESTADISTICA!C125 -> 1282 Y MASSE | D127: =ESTADISTICA!D125 -> DOMO | E127: =ESTADISTICA!E125 -> Fibra Optica | F127: =ESTADISTICA!F125 -> 0 | G127: =ESTADISTICA!G125 -> 0 | H127: =ESTADISTICA!H125 -> 0 | ... AI127: =ESTADISTICA!AI125 -> 0
A128: =ESTADISTICA!A126 -> EL PARQUE | B128: =ESTADISTICA!B126 -> EPQ 03 | C128: =ESTADISTICA!C126 -> 1282 Y RP 36 | D128: =ESTADISTICA!D126 -> Domo | E128: =ESTADISTICA!E126 -> Fibra Optica | F128: =ESTADISTICA!F126 -> APAGADO | G128: =ESTADISTICA!G126 -> APAGADO | H128: =ESTADISTICA!H126 -> 0 | ... AI128: =ESTADISTICA!AI126 -> 0
A129: =ESTADISTICA!A127 -> EL PARQUE | B129: =ESTADISTICA!B127 -> EPQ 04 | C129: =ESTADISTICA!C127 -> 1282 Y MORENO | D129: =ESTADISTICA!D127 -> DOMO | E129: =ESTADISTICA!E127 -> Fibra Optica | F129: =ESTADISTICA!F127 -> 0 | G129: =ESTADISTICA!G127 -> 0 | H129: =ESTADISTICA!H127 -> 0 | ... AI129: =ESTADISTICA!AI127 -> 0
A130: =ESTADISTICA!A128 -> LA ESMERALDA | B130: =ESTADISTICA!B128 -> ESM01 | C130: =ESTADISTICA!C128 -> Cabello y Brasil | D130: =ESTADISTICA!D128 -> Domo | E130: =ESTADISTICA!E128 -> Radio | F130: =ESTADISTICA!F128 -> APAGADO | G130: =ESTADISTICA!G128 -> APAGADO | H130: =ESTADISTICA!H128 -> 0 | ... AI130: =ESTADISTICA!AI128 -> 0
A131: =ESTADISTICA!A129 -> SAN JORGE | B131: =ESTADISTICA!B129 -> ESM02 | C131: =ESTADISTICA!C129 -> Novak y Cabello | D131: =ESTADISTICA!D129 -> Domo | E131: =ESTADISTICA!E129 -> PTO A FO | F131: =ESTADISTICA!F129 -> 0 | G131: =ESTADISTICA!G129 -> 0 | H131: =ESTADISTICA!H129 -> 0 | ... AI131: =ESTADISTICA!AI129 -> 0
A132: =ESTADISTICA!A130 -> SAN JORGE | B132: =ESTADISTICA!B130 -> ESM03 | C132: =ESTADISTICA!C130 -> Novak y Humahuaca | D132: =ESTADISTICA!D130 -> DOMO | E132: =ESTADISTICA!E130 -> PTO A FO | F132: =ESTADISTICA!F130 -> 0 | G132: =ESTADISTICA!G130 -> 0 | H132: =ESTADISTICA!H130 -> 0 | ... AI132: =ESTADISTICA!AI130 -> 0
A133: =ESTADISTICA!A131 -> LA ESMERALDA | B133: =ESTADISTICA!B131 -> ESM04 | C133: =ESTADISTICA!C131 -> Basualdo y Bengochea | D133: =ESTADISTICA!D131 -> Domo | E133: =ESTADISTICA!E131 -> Fibra Optica | F133: =ESTADISTICA!F131 -> 0 | G133: =ESTADISTICA!G131 -> 0 | H133: =ESTADISTICA!H131 -> 0 | ... AI133: =ESTADISTICA!AI131 -> 0
A134: =ESTADISTICA!A132 -> LA ESMERALDA | B134: =ESTADISTICA!B132 -> ESM05 | C134: =ESTADISTICA!C132 -> Aniceto Diaz y Villar | D134: =ESTADISTICA!D132 -> Domo | E134: =ESTADISTICA!E132 -> Fibra Optica | F134: =ESTADISTICA!F132 -> 0 | G134: =ESTADISTICA!G132 -> 0 | H134: =ESTADISTICA!H132 -> 0 | ... AI134: =ESTADISTICA!AI132 -> 0
A135: =ESTADISTICA!A133 -> LA ESMERALDA | B135: =ESTADISTICA!B133 -> ESM06 | C135: =ESTADISTICA!C133 -> Roselli y Cabello | D135: =ESTADISTICA!D133 -> Domo | E135: =ESTADISTICA!E133 -> Radio | F135: =ESTADISTICA!F133 -> 0 | G135: =ESTADISTICA!G133 -> 0 | H135: =ESTADISTICA!H133 -> 0 | ... AI135: =ESTADISTICA!AI133 -> 0
A136: =ESTADISTICA!A134 -> LA ESMERALDA | B136: =ESTADISTICA!B134 -> ESM07 | C136: =ESTADISTICA!C134 -> AV. NOVAK Y SERRANO | D136: =ESTADISTICA!D134 -> DOMO | E136: =ESTADISTICA!E134 -> PTO A FO | F136: =ESTADISTICA!F134 -> 0 | G136: =ESTADISTICA!G134 -> 0 | H136: =ESTADISTICA!H134 -> 0 | ... AI136: =ESTADISTICA!AI134 -> 0
A137: =ESTADISTICA!A135 -> LA ESMERALDA | B137: =ESTADISTICA!B135 -> ESM 08 | C137: =ESTADISTICA!C135 -> DAVINSON Y MORANCHEL | D137: =ESTADISTICA!D135 -> FIJA | E137: =ESTADISTICA!E135 -> Radio | F137: =ESTADISTICA!F135 -> 0 | G137: =ESTADISTICA!G135 -> 0 | H137: =ESTADISTICA!H135 -> 0 | ... AI137: =ESTADISTICA!AI135 -> 0
... A204: =ESTADISTICA!A202 -> MAYOL | B204: =ESTADISTICA!B202 -> MAY 04 | C204: =ESTADISTICA!C202 -> MAR CHIQUITA Y RIO JACHAL | D204: =ESTADISTICA!D202 -> DOMO | E204: =ESTADISTICA!E202 -> Radio | F204: =ESTADISTICA!F202 -> 0 | G204: =ESTADISTICA!G202 -> 0 | H204: =ESTADISTICA!H202 -> 0 | ... AI204: =ESTADISTICA!AI202 -> 0
A205: MONTE CUDINE | B205: =ESTADISTICA!B203 -> MCUD 01 | C205: =ESTADISTICA!C203 -> TINOGASTA Y SAN LORENZO | D205: =ESTADISTICA!D203 -> Domo | E205: =ESTADISTICA!E203 -> Fibra Optica | F205: =ESTADISTICA!F203 -> 0 | G205: =ESTADISTICA!G203 -> 0 | H205: =ESTADISTICA!H203 -> 0 | I205: =ESTADISTICA!I203 -> 0 | ... AI205: =ESTADISTICA!AI203 -> 0
A206: MONTE CUDINE | B206: =ESTADISTICA!B204 -> MCUD 02 | C206: =ESTADISTICA!C204 -> CALLE 115 A Y 158 | D206: =ESTADISTICA!D204 -> DOMO | E206: =ESTADISTICA!E204 -> Fibra Optica | F206: =ESTADISTICA!F204 -> 0 | G206: =ESTADISTICA!G204 -> 0 | H206: =ESTADISTICA!H204 -> 0 | I206: =ESTADISTICA!I204 -> 0 | ... AI206: =ESTADISTICA!AI204 -> 0
A207: =ESTADISTICA!A205 -> MARTIN FIERRO | B207: =ESTADISTICA!B205 -> MFI 01 | C207: =ESTADISTICA!C205 -> Belgrano y Sgto. Cabral | D207: =ESTADISTICA!D205 -> Fija | E207: =ESTADISTICA!E205 -> Fibra Optica | F207: =ESTADISTICA!F205 -> 0 | G207: =ESTADISTICA!G205 -> 0 | H207: =ESTADISTICA!H205 -> 0 | ... AI207: =ESTADISTICA!AI205 -> 0
A208: =ESTADISTICA!A206 -> LOPEZ ROMERO | B208: =ESTADISTICA!B206 -> MFI02 | C208: =ESTADISTICA!C206 -> Calchaqui y Balcarce | D208: =ESTADISTICA!D206 -> Fija | E208: =ESTADISTICA!E206 -> Fibra Optica | F208: =ESTADISTICA!F206 -> 0 | G208: =ESTADISTICA!G206 -> 0 | H208: =ESTADISTICA!H206 -> 0 | ... AI208: =ESTADISTICA!AI206 -> 0
A209: =ESTADISTICA!A208 -> MARTIN FIERRO | B209: =ESTADISTICA!B208 -> MFI04 | C209: =ESTADISTICA!C208 -> Calchaqui y balcarce | D209: =ESTADISTICA!D208 -> Domo | E209: =ESTADISTICA!E208 -> Fibra Optica | F209: =ESTADISTICA!F208 -> 0 | G209: =ESTADISTICA!G208 -> 0 | H209: =ESTADISTICA!H208 -> 0 | ... AI209: =ESTADISTICA!AI208 -> 0
A210: =ESTADISTICA!A209 -> SAN EMILIO | B210: =ESTADISTICA!B209 -> MFI 05 | C210: =ESTADISTICA!C209 -> Cno. Gral. Belgrano y Guayaquil | D210: =ESTADISTICA!D209 -> Domo | E210: =ESTADISTICA!E209 -> Fibra Optica | F210: =ESTADISTICA!F209 -> 0 | G210: =ESTADISTICA!G209 -> 0 | H210: =ESTADISTICA!H209 -> 0 | ... AI210: =ESTADISTICA!AI209 -> 0
A211: =ESTADISTICA!A210 -> SAN EMILIO | B211: =ESTADISTICA!B210 -> MFI06 | C211: =ESTADISTICA!C210 -> Con. Gral. Belgrano y Bombero Galarza | D211: =ESTADISTICA!D210 -> DOMO | E211: =ESTADISTICA!E210 -> Radio | F211: =ESTADISTICA!F210 -> 0 | G211: =ESTADISTICA!G210 -> 0 | H211: =ESTADISTICA!H210 -> 0 | ... AI211: =ESTADISTICA!AI210 -> 0
A212: =ESTADISTICA!A211 -> MARTIN FIERRO | B212: =ESTADISTICA!B211 -> MFI 07 | C212: =ESTADISTICA!C211 -> Sargento Cabral y Carlos Gardel | D212: =ESTADISTICA!D211 -> Domo | E212: =ESTADISTICA!E211 -> PTO A FO | F212: =ESTADISTICA!F211 -> 0 | G212: =ESTADISTICA!G211 -> 0 | H212: =ESTADISTICA!H211 -> 0 | ... AI212: =ESTADISTICA!AI211 -> 0
A213: =ESTADISTICA!A212 -> MARTIN FIERRO | B213: =ESTADISTICA!B212 -> MFI 08 | C213: =ESTADISTICA!C212 -> Braile y Batalla de Callao | D213: =ESTADISTICA!D212 -> Domo | E213: =ESTADISTICA!E212 -> PTO A FO | F213: =ESTADISTICA!F212 -> 0 | G213: =ESTADISTICA!G212 -> 0 | H213: =ESTADISTICA!H212 -> 0 | ... AI213: =ESTADISTICA!AI212 -> 0
A214: =ESTADISTICA!A213 -> GOBERNADOR MONTEVERDE | B214: =ESTADISTICA!B213 -> MON01 | C214: =ESTADISTICA!C213 -> San Martin y Patricias Argentinas | D214: =ESTADISTICA!D213 -> Fija | E214: =ESTADISTICA!E213 -> Fibra Optica | F214: =ESTADISTICA!F213 -> 0 | G214: =ESTADISTICA!G213 -> 0 | H214: =ESTADISTICA!H213 -> 0 | ... AI214: =ESTADISTICA!AI213 -> 0
A215: =ESTADISTICA!A214 -> GOBERNADOR MONTEVERDE | B215: =ESTADISTICA!B214 -> MON02 | C215: =ESTADISTICA!C214 -> Senzabello y Famatina | D215: =ESTADISTICA!D214 -> Domo | E215: =ESTADISTICA!E214 -> Radio | F215: =ESTADISTICA!F214 -> 0 | G215: =ESTADISTICA!G214 -> 0 | H215: =ESTADISTICA!H214 -> 0 | ... AI215: =ESTADISTICA!AI214 -> 0
...

Sheet APAGADOS FIBRA
C1: TOTAL FIBRA | D1: =COUNTIFS(E4:E401,"=Fibra Optica") -> 285
E2: APAGADOS | F2: =COUNTIFS(F4:F501, "=APAGADO",E4:E501,"=Fibra Optica") -> 40 | G2: =COUNTIFS(G4:G501, "=APAGADO",E4:E501,"=Fibra Optica") -> 68 | H2: =COUNTIFS(H4:H501, "=APAGADO",E4:E501,"=Fibra Optica") -> 0 | I2: =COUNTIFS(I4:I501, "=APAGADO",E4:E501,"=Fibra Optica") -> 0 | J2: =COUNTIFS(J4:J501, "=APAGADO",E4:E501,"=Fibra Optica") -> 0 | K2: =COUNTIFS(K4:K501, "=APAGADO",E4:E501,"=Fibra Optica") -> 0 | L2: =COUNTIFS(L4:L501, "=APAGADO",E4:E501,"=Fibra Optica") -> 0 | M2: =COUNTIFS(M4:M501, "=APAGADO",E4:E501,"=Fibra Optica") -> 0 | N2: =COUNTIFS(N4:N501, "=APAGADO",E4:E501,"=Fibra Optica") -> 0 | O2: =COUNTIFS(O4:O501, "=APAGADO",E4:E501,"=Fibra Optica") -> 0 | P2: =COUNTIFS(P4:P601, "=APAGADO",E4:E601,"=Fibra Optica") -> 0 | Q2: =COUNTIFS(Q4:Q501, "=APAGADO",E4:E501,"=Fibra Optica") -> 0 | R2: =COUNTIFS(R4:R501, "=APAGADO",E4:E501,"=Fibra Optica") -> 0 | S2: =COUNTIFS(S4:S501, "=APAGADO",E4:E501,"=Fibra Optica") -> 0 | T2: =COUNTIFS(T4:T501, "=APAGADO",E4:E501,"=Fibra Optica") -> 0 | U2: =COUNTIFS(U4:U501, "=APAGADO",E4:E501,"=Fibra Optica") -> 0 | V2: =COUNTIFS(V4:V501, "=APAGADO",E4:E501,"=Fibra Optica") -> 0 | W2: =COUNTIFS(W4:W501, "=APAGADO",E4:E501,"=Fibra Optica") -> 0 | X2: =COUNTIFS(X4:X501, "=APAGADO",E4:E501,"=Fibra Optica") -> 0 | Y2: =COUNTIFS(Y4:Y501, "=APAGADO",E4:E501,"=Fibra Optica") -> 0 | Z2: =COUNTIFS(Z4:Z501, "=APAGADO",E4:E501,"=Fibra Optica") -> 0 | AA2: =COUNTIFS(AA4:AA501, "=APAGADO",E4:E501,"=Fibra Optica") -> 0 | AB2: =COUNTIFS(AB4:AB501, "=APAGADO",E4:E501,"=Fibra Optica") -> 0 | AC2: =COUNTIFS(AC4:AC601, "=APAGADO",E4:E601,"=Fibra Optica") -> 0 | AD2: =COUNTIFS(AD4:AD501, "=APAGADO",E4:E501,"=Fibra Optica") -> 0 | AE2: =COUNTIFS(AE4:AE501, "=APAGADO",E4:E501,"=Fibra Optica") -> 0 | AF2: =COUNTIFS(AF4:AF501, "=APAGADO",E4:E501,"=Fibra Optica") -> 0 | AG2: =COUNTIFS(AG4:AG501, "=APAGADO",E4:E501,"=Fibra Optica") -> 0 | AH2: =COUNTIFS(AH4:AH501, "=APAGADO",E4:E501,"=Fibra Optica") -> 0 | AI2: =COUNTIFS(AI4:AI501, "=APAGADO",F4:F501,"=Fibra Optica") -> 0 | AJ2: =COUNTIFS(AJ4:AJ501, "=APAGADO",G4:G501,"=Fibra Optica") -> 0
A3: =ESTADISTICA!A1 -> Barrio | B3: =ESTADISTICA!B1 -> [Denominacion] | C3: =ESTADISTICA!C1 -> [Ubicacion] | D3: =ESTADISTICA!D1 -> [Tipo de Camara] | E3: =ESTADISTICA!E1 -> [Tipo de Conexion] | F3: =ESTADISTICA!F1 -> 45292 | G3: =ESTADISTICA!G1 -> 45293 | H3: =ESTADISTICA!H1 -> 45294 | ... AH3: =ESTADISTICA!AH1 -> 45320 | AI3: 304 | AJ3: 305
A4: ='RESUMEN TOTAL'!A7 -> ALTAMIRA | B4: ='RESUMEN TOTAL'!B7 -> ALT 03 | C4: ='RESUMEN TOTAL'!D7 -> Bombero Galarza y Necochea | D4: ='RESUMEN TOTAL'!E7 -> Domo | E4: ='RESUMEN TOTAL'!F7 -> Fibra Optica | F4: ='RESUMEN TOTAL'!L7 -> 0 | G4: ='RESUMEN TOTAL'!M7 -> 0 | H4: ='RESUMEN TOTAL'!N7 -> 0 | I4: ='RESUMEN TOTAL'!O7 -> 0 | J4: ='RESUMEN TOTAL'!P7 -> 0 | K4: ='RESUMEN TOTAL'!Q7 -> 0 | L4: ='RESUMEN TOTAL'!R7 -> 0 | M4: ='RESUMEN TOTAL'!S7 -> 0 | ... AI4: ='RESUMEN TOTAL'!AO7 -> 0 | AJ4: ='RESUMEN TOTAL'!#REF! -> #REF!
A5: ='RESUMEN TOTAL'!A8 -> ALTAMIRA | B5: ='RESUMEN TOTAL'!B8 -> ALT 04 | C5: ='RESUMEN TOTAL'!D8 -> Francia y Necochea | D5: ='RESUMEN TOTAL'!E8 -> Domo | E5: ='RESUMEN TOTAL'!F8 -> Fibra Optica | F5: ='RESUMEN TOTAL'!L8 -> 0 | G5: ='RESUMEN TOTAL'!M8 -> 0 | H5: ='RESUMEN TOTAL'!N8 -> 0 | I5: ='RESUMEN TOTAL'!O8 -> 0 | J5: ='RESUMEN TOTAL'!P8 -> 0 | K5: ='RESUMEN TOTAL'!Q8 -> 0 | L5: ='RESUMEN TOTAL'!R8 -> 0 | M5: ='RESUMEN TOTAL'!S8 -> 0 | ... AI5: ='RESUMEN TOTAL'!AO8 -> 0 | AJ5: ='RESUMEN TOTAL'!#REF! -> #REF!
A6: ='RESUMEN TOTAL'!A9 -> ALTAMIRA | B6: ='RESUMEN TOTAL'!B9 -> ALT05 | C6: ='RESUMEN TOTAL'!D9 -> Av. Calchaqui y Bombero Galarza | D6: ='RESUMEN TOTAL'!E9 -> Domo | E6: ='RESUMEN TOTAL'!F9 -> PTO A FO | F6: ='RESUMEN TOTAL'!L9 -> 0 | G6: ='RESUMEN TOTAL'!M9 -> APAGADO | H6: ='RESUMEN TOTAL'!N9 -> 0 | I6: ='RESUMEN TOTAL'!O9 -> 0 | J6: ='RESUMEN TOTAL'!P9 -> 0 | K6: ='RESUMEN TOTAL'!Q9 -> 0 | L6: ='RESUMEN TOTAL'!R9 -> 0 | M6: ='RESUMEN TOTAL'!S9 -> 0 | ... AI6: ='RESUMEN TOTAL'!AO9 -> 0 | AJ6: ='RESUMEN TOTAL'!#REF! -> #REF!
A7: ='RESUMEN TOTAL'!A10 -> ALTAMIRA | B7: ='RESUMEN TOTAL'!B10 -> ALT 06 | C7: ='RESUMEN TOTAL'!D10 -> LOPE DE VEGA Y NECOCHEA | D7: ='RESUMEN TOTAL'!E10 -> Domo | E7: ='RESUMEN TOTAL'!F10 -> PTO A FO | F7: ='RESUMEN TOTAL'!L10 -> 0 | G7: ='RESUMEN TOTAL'!M10 -> 0 | H7: ='RESUMEN TOTAL'!N10 -> 0 | I7: ='RESUMEN TOTAL'!O10 -> 0 | J7: ='RESUMEN TOTAL'!P10 -> 0 | K7: ='RESUMEN TOTAL'!Q10 -> 0 | L7: ='RESUMEN TOTAL'!R10 -> 0 | M7: ='RESUMEN TOTAL'!S10 -> 0 | ... AI7: ='RESUMEN TOTAL'!AO10 -> 0 | AJ7: ='RESUMEN TOTAL'!#REF! -> #REF!
A8: ='RESUMEN TOTAL'!A11 -> ALTAMIRA | B8: ='RESUMEN TOTAL'!B11 -> ALT07 | C8: ='RESUMEN TOTAL'!D11 -> AV. CALCHAQUI Y AV. DEL TRABAJO | D8: ='RESUMEN TOTAL'!E11 -> DOMO | E8: ='RESUMEN TOTAL'!F11 -> PTO A FO | F8: ='RESUMEN TOTAL'!L11 -> 0 | G8: ='RESUMEN TOTAL'!M11 -> 0 | H8: ='RESUMEN TOTAL'!N11 -> 0 | I8: ='RESUMEN TOTAL'!O11 -> 0 | J8: ='RESUMEN TOTAL'!P11 -> 0 | K8: ='RESUMEN TOTAL'!Q11 -> 0 | L8: ='RESUMEN TOTAL'!R11 -> 0 | M8: ='RESUMEN TOTAL'!S11 -> 0 | ... AI8: ='RESUMEN TOTAL'!AO11 -> 0 | AJ8: ='RESUMEN TOTAL'!#REF! -> #REF!
A9: ='RESUMEN TOTAL'!A12 -> ALTAMIRA | B9: ='RESUMEN TOTAL'!B12 -> ALT 08 | C9: ='RESUMEN TOTAL'!D12 -> HUMAITA Y NECOCHEA | D9: ='RESUMEN TOTAL'!E12 -> DOMO | E9: ='RESUMEN TOTAL'!F12 -> Fibra Optica | F9: ='RESUMEN TOTAL'!L12 -> 0 | G9: ='RESUMEN TOTAL'!M12 -> 0 | H9: ='RESUMEN TOTAL'!N12 -> 0 | I9: ='RESUMEN TOTAL'!O12 -> 0 | J9: ='RESUMEN TOTAL'!P12 -> 0 | K9: ='RESUMEN TOTAL'!Q12 -> 0 | L9: ='RESUMEN TOTAL'!R12 -> 0 | M9: ='RESUMEN TOTAL'!S12 -> 0 | ... AI9: ='RESUMEN TOTAL'!AO12 -> 0 | AJ9: ='RESUMEN TOTAL'!#REF! -> #REF!
A10: ='RESUMEN TOTAL'!A13 -> ALTAMIRA | B10: ='RESUMEN TOTAL'!B13 -> ALT 09 | C10: ='RESUMEN TOTAL'!D13 -> NECOCHEA Y CURUPAITY | D10: ='RESUMEN TOTAL'!E13 -> DOMO | E10: ='RESUMEN TOTAL'!F13 -> Fibra Optica | F10: ='RESUMEN TOTAL'!L13 -> 0 | G10: ='RESUMEN TOTAL'!M13 -> 0 | H10: ='RESUMEN TOTAL'!N13 -> 0 | I10: ='RESUMEN TOTAL'!O13 -> 0 | J10: ='RESUMEN TOTAL'!P13 -> 0 | K10: ='RESUMEN TOTAL'!Q13 -> 0 | L10: ='RESUMEN TOTAL'!R13 -> 0 | M10: ='RESUMEN TOTAL'!S13 -> 0 | ... AI10: ='RESUMEN TOTAL'!AO13 -> 0 | AJ10: ='RESUMEN TOTAL'!#REF! -> #REF!
A11: ='RESUMEN TOTAL'!A14 -> ALTAMIRA | B11: ='RESUMEN TOTAL'!B14 -> ALT 10 | C11: ='RESUMEN TOTAL'!D14 -> Calchaqui y Francia | D11: ='RESUMEN TOTAL'!E14 -> Domo | E11: ='RESUMEN TOTAL'!F14 -> Radio | F11: ='RESUMEN TOTAL'!L14 -> APAGADO | G11: ='RESUMEN TOTAL'!M14 -> APAGADO | H11: ='RESUMEN TOTAL'!N14 -> 0 | I11: ='RESUMEN TOTAL'!O14 -> 0 | J11: ='RESUMEN TOTAL'!P14 -> 0 | K11: ='RESUMEN TOTAL'!Q14 -> 0 | L11: ='RESUMEN TOTAL'!R14 -> 0 | M11: ='RESUMEN TOTAL'!S14 -> 0 | ... AI11: ='RESUMEN TOTAL'!AO14 -> 0 | AJ11: ='RESUMEN TOTAL'!#REF! -> #REF!
A12: ='RESUMEN TOTAL'!A15 -> AGUSTIN RAMIREZ | B12: ='RESUMEN TOTAL'!B15 -> ARA 01 | C12: ='RESUMEN TOTAL'!D15 -> Malambo y Tranquera | D12: ='RESUMEN TOTAL'!E15 -> Domo | E12: ='RESUMEN TOTAL'!F15 -> Fibra Optica | F12: ='RESUMEN TOTAL'!L15 -> 0 | G12: ='RESUMEN TOTAL'!M15 -> 0 | H12: ='RESUMEN TOTAL'!N15 -> 0 | I12: ='RESUMEN TOTAL'!O15 -> 0 | J12: ='RESUMEN TOTAL'!P15 -> 0 | K12: ='RESUMEN TOTAL'!Q15 -> 0 | L12: ='RESUMEN TOTAL'!R15 -> 0 | M12: ='RESUMEN TOTAL'!S15 -> 0 | ... AI12: ='RESUMEN TOTAL'!AO15 -> 0 | AJ12: ='RESUMEN TOTAL'!#REF! -> #REF!
A13: ='RESUMEN TOTAL'!A16 -> BELGRANO | B13: ='RESUMEN TOTAL'!B16 -> BEL 01 | C13: ='RESUMEN TOTAL'!D16 -> San Martin y Dardo Rocha | D13: ='RESUMEN TOTAL'!E16 -> DOMO | E13: ='RESUMEN TOTAL'!F16 -> Fibra Optica | F13: ='RESUMEN TOTAL'!L16 -> 0 | G13: ='RESUMEN TOTAL'!M16 -> 0 | H13: ='RESUMEN TOTAL'!N16 -> 0 | I13: ='RESUMEN TOTAL'!O16 -> 0 | J13: ='RESUMEN TOTAL'!P16 -> 0 | K13: ='RESUMEN TOTAL'!Q16 -> 0 | L13: ='RESUMEN TOTAL'!R16 -> 0 | M13: ='RESUMEN TOTAL'!S16 -> 0 | ... AI13: ='RESUMEN TOTAL'!AO16 -> 0 | AJ13: ='RESUMEN TOTAL'!#REF! -> #REF!
A14: ='RESUMEN TOTAL'!A17 -> BELGRANO | B14: ='RESUMEN TOTAL'!B17 -> BEL 02 | C14: ='RESUMEN TOTAL'!D17 -> Guardia vieja y Fronteriz | D14: ='RESUMEN TOTAL'!E17 -> DOMO | E14: ='RESUMEN TOTAL'!F17 -> Fibra Optica | F14: ='RESUMEN TOTAL'!L17 -> 0 | G14: ='RESUMEN TOTAL'!M17 -> 0 | H14: ='RESUMEN TOTAL'!N17 -> 0 | I14: ='RESUMEN TOTAL'!O17 -> 0 | J14: ='RESUMEN TOTAL'!P17 -> 0 | K14: ='RESUMEN TOTAL'!Q17 -> 0 | L14: ='RESUMEN TOTAL'!R17 -> 0 | M14: ='RESUMEN TOTAL'!S17 -> 0 | ... AI14: ='RESUMEN TOTAL'!AO17 -> 0 | AJ14: ='RESUMEN TOTAL'!#REF! -> #REF!
A15: ='RESUMEN TOTAL'!A18 -> BOSQUES CENTRO | B15: ='RESUMEN TOTAL'!B18 -> BOSQC 01 | C15: ='RESUMEN TOTAL'!D18 -> LUIS AGOTE E/DANUNCIO Y CAMPOAMOR | D15: ='RESUMEN TOTAL'!E18 -> Fija | E15: ='RESUMEN TOTAL'!F18 -> Radio | F15: ='RESUMEN TOTAL'!L18 -> 0 | G15: ='RESUMEN TOTAL'!M18 -> 0 | H15: ='RESUMEN TOTAL'!N18 -> 0 | I15: ='RESUMEN TOTAL'!O18 -> 0 | J15: ='RESUMEN TOTAL'!P18 -> 0 | K15: ='RESUMEN TOTAL'!Q18 -> 0 | L15: ='RESUMEN TOTAL'!R18 -> 0 | M15: ='RESUMEN TOTAL'!S18 -> 0 | ... AI15: ='RESUMEN TOTAL'!AO18 -> 0 | AJ15: ='RESUMEN TOTAL'!#REF! -> #REF!
... A20: ='RESUMEN TOTAL'!A23 -> BOSQUES CENTRO | B20: ='RESUMEN TOTAL'!B23 -> BOSQC 06 | C20: ='RESUMEN TOTAL'!D23 -> LUIS AGOTE Y RUTA 36 | D20: ='RESUMEN TOTAL'!E23 -> Fija | E20: ='RESUMEN TOTAL'!F23 -> Radio | F20: ='RESUMEN TOTAL'!L23 -> 0 | G20: ='RESUMEN TOTAL'!M23 -> 0 | H20: ='RESUMEN TOTAL'!N23 -> 0 | I20: ='RESUMEN TOTAL'!O23 -> 0 | J20: ='RESUMEN TOTAL'!P23 -> 0 | K20: ='RESUMEN TOTAL'!Q23 -> 0 | L20: ='RESUMEN TOTAL'!R23 -> 0 | M20: ='RESUMEN TOTAL'!S23 -> 0 | ... AI20: ='RESUMEN TOTAL'!AO23 -> 0 | AJ20: ='RESUMEN TOTAL'!#REF! -> #REF!
A21: ='RESUMEN TOTAL'!A26 -> CENTRO | B21: ='RESUMEN TOTAL'!B26 -> CEN01 | C21: ='RESUMEN TOTAL'!D26 -> San Martin y 9 de Julio | D21: ='RESUMEN TOTAL'!E26 -> Fija | E21: ='RESUMEN TOTAL'!F26 -> Fibra Optica | F21: ='RESUMEN TOTAL'!L26 -> APAGADO | G21: ='RESUMEN TOTAL'!M26 -> APAGADO | H21: ='RESUMEN TOTAL'!N26 -> 0 | I21: ='RESUMEN TOTAL'!O26 -> 0 | J21: ='RESUMEN TOTAL'!P26 -> 0 | K21: ='RESUMEN TOTAL'!Q26 -> 0 | L21: ='RESUMEN TOTAL'!R26 -> 0 | M21: ='RESUMEN TOTAL'!S26 -> 0 | ... AI21: ='RESUMEN TOTAL'!AO26 -> 0 | AJ21: ='RESUMEN TOTAL'!#REF! -> #REF!
A22: ='RESUMEN TOTAL'!A27 -> CENTRO | B22: ='RESUMEN TOTAL'!B27 -> CEN02 | C22: ='RESUMEN TOTAL'!D27 -> San Martin y Almafuerte | D22: ='RESUMEN TOTAL'!E27 -> Fija | E22: ='RESUMEN TOTAL'!F27 -> Fibra Optica | F22: ='RESUMEN TOTAL'!L27 -> APAGADO | G22: ='RESUMEN TOTAL'!M27 -> APAGADO | H22: ='RESUMEN TOTAL'!N27 -> 0 | I22: ='RESUMEN TOTAL'!O27 -> 0 | J22: ='RESUMEN TOTAL'!P27 -> 0 | K22: ='RESUMEN TOTAL'!Q27 -> 0 | L22: ='RESUMEN TOTAL'!R27 -> 0 | M22: ='RESUMEN TOTAL'!S27 -> 0 | ... AI22: ='RESUMEN TOTAL'!AO27 -> 0 | AJ22: ='RESUMEN TOTAL'!#REF! -> #REF!
A23: ='RESUMEN TOTAL'!A28 -> CENTRO | B23: ='RESUMEN TOTAL'!B28 -> CEN03 | C23: ='RESUMEN TOTAL'!D28 -> San Martin y Sallares | D23: ='RESUMEN TOTAL'!E28 -> Domo | E23: ='RESUMEN TOTAL'!F28 -> Fibra Optica | F23: ='RESUMEN TOTAL'!L28 -> 0 | G23: ='RESUMEN TOTAL'!M28 -> 0 | H23: ='RESUMEN TOTAL'!N28 -> 0 | I23: ='RESUMEN TOTAL'!O28 -> 0 | J23: ='RESUMEN TOTAL'!P28 -> 0 | K23: ='RESUMEN TOTAL'!Q28 -> 0 | L23: ='RESUMEN TOTAL'!R28 -> 0 | M23: ='RESUMEN TOTAL'!S28 -> 0 | ... AI23: ='RESUMEN TOTAL'!AO28 -> 0 | AJ23: ='RESUMEN TOTAL'!#REF! -> #REF!
A24: ='RESUMEN TOTAL'!A29 -> CENTRO | B24: ='RESUMEN TOTAL'!B29 -> CEN04 | C24: ='RESUMEN TOTAL'!D29 -> San Martin y Contreras | D24: ='RESUMEN TOTAL'!E29 -> Domo | E24: ='RESUMEN TOTAL'!F29 -> Fibra Optica | F24: ='RESUMEN TOTAL'!L29 -> 0 | G24: ='RESUMEN TOTAL'!M29 -> 0 | H24: ='RESUMEN TOTAL'!N29 -> 0 | I24: ='RESUMEN TOTAL'!O29 -> 0 | J24: ='RESUMEN TOTAL'!P29 -> 0 | K24: ='RESUMEN TOTAL'!Q29 -> 0 | L24: ='RESUMEN TOTAL'!R29 -> 0 | M24: ='RESUMEN TOTAL'!S29 -> 0 | ... AI24: ='RESUMEN TOTAL'!AO29 -> 0 | AJ24: ='RESUMEN TOTAL'!#REF! -> #REF!
A25: ='RESUMEN TOTAL'!A30 -> CENTRO | B25: ='RESUMEN TOTAL'!B30 -> CEN 05 | C25: ='RESUMEN TOTAL'!D30 -> Bocuzzi e/España y San Martin | D25: ='RESUMEN TOTAL'!E30 -> DOMO | E25: ='RESUMEN TOTAL'!F30 -> Fibra Optica | F25: ='RESUMEN TOTAL'!L30 -> 0 | G25: ='RESUMEN TOTAL'!M30 -> 0 | H25: ='RESUMEN TOTAL'!N30 -> 0 | I25: ='RESUMEN TOTAL'!O30 -> 0 | J25: ='RESUMEN TOTAL'!P30 -> 0 | K25: ='RESUMEN TOTAL'!Q30 -> 0 | L25: ='RESUMEN TOTAL'!R30 -> 0 | M25: ='RESUMEN TOTAL'!S30 -> 0 | ... AI25: ='RESUMEN TOTAL'!AO30 -> 0 | AJ25: ='RESUMEN TOTAL'!#REF! -> #REF!
A26: ='RESUMEN TOTAL'!A31 -> CENTRO | B26: ='RESUMEN TOTAL'!B31 -> CEN06 | C26: ='RESUMEN TOTAL'!D31 -> Monteagudo y A.del Valle | D26: ='RESUMEN TOTAL'!E31 -> Fija | E26: ='RESUMEN TOTAL'!F31 -> Fibra Optica | F26: ='RESUMEN TOTAL'!L31 -> 0 | G26: ='RESUMEN TOTAL'!M31 -> 0 | H26: ='RESUMEN TOTAL'!N31 -> 0 | I26: ='RESUMEN TOTAL'!O31 -> 0 | J26: ='RESUMEN TOTAL'!P31 -> 0 | K26: ='RESUMEN TOTAL'!Q31 -> 0 | L26: ='RESUMEN TOTAL'!R31 -> 0 | M26: ='RESUMEN TOTAL'!S31 -> 0 | ... AI26: ='RESUMEN TOTAL'!AO31 -> 0 | AJ26: ='RESUMEN TOTAL'!#REF! -> #REF!
A27: ='RESUMEN TOTAL'!A32 -> CENTRO | B27: ='RESUMEN TOTAL'!B32 -> CEN07 | C27: ='RESUMEN TOTAL'!D32 -> San Martin y Guemes | D27: ='RESUMEN TOTAL'!E32 -> DOMO | E27: ='RESUMEN TOTAL'!F32 -> Fibra Optica | F27: ='RESUMEN TOTAL'!L32 -> 0 | G27: ='RESUMEN TOTAL'!M32 -> 0 | H27: ='RESUMEN TOTAL'!N32 -> 0 | I27: ='RESUMEN TOTAL'!O32 -> 0 | J27: ='RESUMEN TOTAL'!P32 -> 0 | K27: ='RESUMEN TOTAL'!Q32 -> 0 | L27: ='RESUMEN TOTAL'!R32 -> 0 | M27: ='RESUMEN TOTAL'!S32 -> 0 | ... AI27: ='RESUMEN TOTAL'!AO32 -> 0 | AJ27: ='RESUMEN TOTAL'!#REF! -> #REF!
A28: ='RESUMEN TOTAL'!A33 -> CENTRO | B28: ='RESUMEN TOTAL'!B33 -> CEN08 | C28: ='RESUMEN TOTAL'!D33 -> San Martin y Pte.Peron | D28: ='RESUMEN TOTAL'!E33 -> Domo | E28: ='RESUMEN TOTAL'!F33 -> Fibra Optica | F28: ='RESUMEN TOTAL'!L33 -> 0 | G28: ='RESUMEN TOTAL'!M33 -> 0 | H28: ='RESUMEN TOTAL'!N33 -> 0 | I28: ='RESUMEN TOTAL'!O33 -> 0 | J28: ='RESUMEN TOTAL'!P33 -> 0 | K28: ='RESUMEN TOTAL'!Q33 -> 0 | L28: ='RESUMEN TOTAL'!R33 -> 0 | M28: ='RESUMEN TOTAL'!S33 -> 0 | ... AI28: ='RESUMEN TOTAL'!AO33 -> 0 | AJ28: ='RESUMEN TOTAL'!#REF! -> #REF!
A29: ='RESUMEN TOTAL'!A34 -> CENTRO | B29: ='RESUMEN TOTAL'!B34 -> CEN09 | C29: ='RESUMEN TOTAL'!D34 -> Chacabuco y 25 de Mayo | D29: ='RESUMEN TOTAL'!E34 -> Domo | E29: ='RESUMEN TOTAL'!F34 -> Fibra Optica | F29: ='RESUMEN TOTAL'!L34 -> 0 | G29: ='RESUMEN TOTAL'!M34 -> 0 | H29: ='RESUMEN TOTAL'!N34 -> 0 | I29: ='RESUMEN TOTAL'!O34 -> 0 | J29: ='RESUMEN TOTAL'!P34 -> 0 | K29: ='RESUMEN TOTAL'!Q34 -> 0 | L29: ='RESUMEN TOTAL'!R34 -> 0 | M29: ='RESUMEN TOTAL'!S34 -> 0 | ... AI29: ='RESUMEN TOTAL'!AO34 -> 0 | AJ29: ='RESUMEN TOTAL'!#REF! -> #REF!
