Workbook
Name _25_de_agosto: 'RESUMEN TOTAL'!$A$7:$D$425
Name _25_de_agosto_3: 'RESUMEN TOTAL'!$A$7:$D$437
Name _30_mar: #REF!
Name BONOMOcam: Hoja1!$B$2
Name CANTIDAD_DE_CAMARAS: 'RESUMEN TOTAL'!$B$1
Name COSEIDIcam: Hoja1!$B$4

Sheet RESUMEN TOTAL
A1: CANTIDAD DE CAMARAS | B1: =COUNTA(B8:B657) -> 496 | D1: PORCIENTO DE CAIDAS | L1: =(L3)/(L2+L3) -> 0.12212389 | M1: =(M3)/(M2+M3) -> 0.14629948 | N1: =(N3)/(N2+N3) -> 0.14629948 | O1: =(O3)/(O2+O3) -> 0.17056856 | P1: =(P3)/(P2+P3) -> 0.18688525 | Q1: =(Q3)/(Q2+Q3) -> 0.16917923 | R1: =(R3)/(R2+R3) -> 0.197411 | S1: =(S3)/(S2+S3) -> 0.16498316 | ... X1: =(X3)/(X2+X3) -> 0.12056738 | Z1: =(Z3)/(Z2+Z3) -> 0.11111111 | AA1: =(AA3)/(AA2+AA3) -> 0.12212389 | AB1: =(AB3)/(AB2+AB3) -> 0 | AC1: =(AC3)/(AC2+AC3) -> 0 | AD1: =(AD3)/(AD2+AD3) -> 0 | AE1: =(AE3)/(AE2+AE3) -> 0 | AF1: =(AF3)/(AF2+AF3) -> 0 | AG1: =(AG3)/(AG2+AG3) -> 0 | ... AP1: =(AP3)/(AP2+AP3) -> 0
D2: FUNCIONAN | L2: =CANTIDAD_DE_CAMARAS -> 496 | M2: =CANTIDAD_DE_CAMARAS -> 496 | N2: =CANTIDAD_DE_CAMARAS -> 496 | O2: =CANTIDAD_DE_CAMARAS -> 496 | P2: =CANTIDAD_DE_CAMARAS -> 496 | Q2: =CANTIDAD_DE_CAMARAS -> 496 | R2: =CANTIDAD_DE_CAMARAS -> 496 | S2: =CANTIDAD_DE_CAMARAS -> 496 | ... AP2: =CANTIDAD_DE_CAMARAS -> 496
D3: CAIDAS | L3: =COUNTIF(L7:L657, "apagado") -> 69 | M3: =COUNTIF(M7:M657, "apagado") -> 85 | N3: =COUNTIF(N7:N657, "apagado") -> 85 | O3: =COUNTIF(O7:O657, "apagado") -> 102 | P3: =COUNTIF(P7:P657, "apagado") -> 114 | Q3: =COUNTIF(Q7:Q657, "apagado") -> 101 | R3: =COUNTIF(R7:R657, "apagado") -> 122 | S3: =COUNTIF(S7:S657, "apagado") -> 98 | ... AP3: =COUNTIF(AP7:AP657, "apagado") -> 0
D4: APAGADOS FIBRA | L4: =COUNTIFS(L8:L611, "=APAGADO",F8:F611,"=Fibra Optica") -> 40 | M4: =COUNTIFS(M8:M611, "=APAGADO",F8:F611,"=Fibra Optica") -> 54 | N4: =COUNTIFS(N8:N611, "=APAGADO",F8:F611,"=Fibra Optica") -> 54 | O4: =COUNTIFS(O8:O611, "=APAGADO",F8:F611,"=Fibra Optica") -> 64 | P4: =COUNTIFS(P8:P611, "=APAGADO",F8:F611,"=Fibra Optica") -> 83 | Q4: =COUNTIFS(Q8:Q611, "=APAGADO",F8:F611,"=Fibra Optica") -> 68 | R4: =COUNTIFS(R8:R611, "=APAGADO",F8:F611,"=Fibra Optica") -> 88 | S4: =COUNTIFS(S8:S611, "=APAGADO",F8:F611,"=Fibra Optica") -> 69 | T4: =COUNTIFS(T8:T611, "=APAGADO",F8:F611,"=Fibra Optica") -> 43 | U4: =COUNTIFS(U8:U611, "=APAGADO",F8:F611,"=Fibra Optica") -> 49 | V4: =COUNTIFS(V8:V611, "=APAGADO",F8:F611,"=Fibra Optica") -> 48 | W4: =COUNTIFS(W8:W611, "=APAGADO",F8:F611,"=Fibra Optica") -> 39 | X4: =COUNTIFS(X8:X611, "=APAGADO",F8:F611,"=Fibra Optica") -> 44 | Y4: =COUNTIFS(Y8:Y611, "=APAGADO",F8:F611,"=Fibra Optica") -> 32 | Z4: =COUNTIFS(Z8:Z611, "=APAGADO",F8:F611,"=Fibra Optica") -> 39 | AA4: =COUNTIFS(AA8:AA611, "=APAGADO",F8:F611,"=Fibra Optica") -> 48 | AB4: =COUNTIFS(AB8:AB611, "=APAGADO",F8:F611,"=Fibra Optica") -> 0 | AC4: =COUNTIFS(AC8:AC611, "=APAGADO",F8:F611,"=Fibra Optica") -> 0 | AD4: =COUNTIFS(AD8:AD611, "=APAGADO",F8:F611,"=Fibra Optica") -> 0 | AE4: =COUNTIFS(AE8:AE611, "=APAGADO",F8:F611,"=Fibra Optica") -> 0 | AF4: =COUNTIFS(AF8:AF611, "=APAGADO",F8:F611,"=Fibra Optica") -> 0 | AG4: =COUNTIFS(AG8:AG611, "=APAGADO",F8:F611,"=Fibra Optica") -> 0 | AH4: =COUNTIFS(AH8:AH611, "=APAGADO",F8:F611,"=Fibra Optica") -> 0 | AI4: =COUNTIFS(AI8:AI611, "=APAGADO",F8:F611,"=Fibra Optica") -> 0 | AJ4: =COUNTIFS(AJ8:AJ611, "=APAGADO",F8:F611,"=Fibra Optica") -> 0 | AK4: =COUNTIFS(AK8:AK611, "=APAGADO",F8:F611,"=Fibra Optica") -> 0 | AL4: =COUNTIFS(AL8:AL611, "=APAGADO",F8:F611,"=Fibra Optica") -> 0 | AM4: =COUNTIFS(AM8:AM611, "=APAGADO",F8:F611,"=Fibra Optica") -> 0 | AN4: =COUNTIFS(AN8:AN611, "=APAGADO",F8:F611,"=Fibra Optica") -> 0 | AO4: =COUNTIFS(AO8:AO611, "=APAGADO",F8:F611,"=Fibra Optica") -> 0 | AP4: =COUNTIFS(AP8:AP611, "=APAGADO",G8:G611,"=Fibra Optica") -> 0
D5: APAGADOS RADIO | L5: =COUNTIFS(L8:L611, "=APAGADO",F8:F611,"=RADIO") -> 13 | M5: =COUNTIFS(M8:M611, "=APAGADO",F8:F611,"=RADIO") -> 15 | N5: =COUNTIFS(N8:N611, "=APAGADO",F8:F611,"=RADIO") -> 15 | O5: =COUNTIFS(O8:O611, "=APAGADO",F8:F611,"=RADIO") -> 22 | P5: =COUNTIFS(P8:P611, "=APAGADO",F8:F611,"=RADIO") -> 17 | Q5: =COUNTIFS(Q8:Q611, "=APAGADO",F8:F611,"=RADIO") -> 21 | R5: =COUNTIFS(R8:R611, "=APAGADO",F8:F611,"=RADIO") -> 21 | S5: =COUNTIFS(S8:S611, "=APAGADO",F8:F611,"=RADIO") -> 17 | T5: =COUNTIFS(T8:T611, "=APAGADO",F8:F611,"=RADIO") -> 25 | U5: =COUNTIFS(U8:U611, "=APAGADO",F8:F611,"=RADIO") -> 17 | V5: =COUNTIFS(V8:V611, "=APAGADO",F8:F611,"=RADIO") -> 17 | W5: =COUNTIFS(W8:W611, "=APAGADO",F8:F611,"=RADIO") -> 13 | X5: =COUNTIFS(X8:X611, "=APAGADO",F8:F611,"=RADIO") -> 13 | Y5: =COUNTIFS(Y8:Y611, "=APAGADO",F8:F611,"=RADIO") -> 13 | Z5: =COUNTIFS(Z8:Z611, "=APAGADO",F8:F611,"=RADIO") -> 11 | AA5: =COUNTIFS(AA8:AA611, "=APAGADO",F8:F611,"=RADIO") -> 12 | AB5: =COUNTIFS(AB8:AB611, "=APAGADO",F8:F611,"=RADIO") -> 0 | AC5: =COUNTIFS(AC8:AC611, "=APAGADO",F8:F611,"=RADIO") -> 0 | AD5: =COUNTIFS(AD8:AD611, "=APAGADO",F8:F611,"=RADIO") -> 0 | AE5: =COUNTIFS(AE8:AE611, "=APAGADO",F8:F611,"=RADIO") -> 0 | AF5: =COUNTIFS(AF8:AF611, "=APAGADO",F8:F611,"=RADIO") -> 0 | AG5: =COUNTIFS(AG8:AG611, "=APAGADO",F8:F611,"=RADIO") -> 0 | AH5: =COUNTIFS(AH8:AH611, "=APAGADO",F8:F611,"=RADIO") -> 0 | AI5: =COUNTIFS(AI8:AI611, "=APAGADO",F8:F611,"=RADIO") -> 0 | AJ5: =COUNTIFS(AJ8:AJ611, "=APAGADO",F8:F611,"=RADIO") -> 0 | AK5: =COUNTIFS(AK8:AK611, "=APAGADO",F8:F611,"=RADIO") -> 0 | AL5: =COUNTIFS(AL8:AL611, "=APAGADO",F8:F611,"=RADIO") -> 0 | AM5: =COUNTIFS(AM8:AM611, "=APAGADO",F8:F611,"=RADIO") -> 0 | AN5: =COUNTIFS(AN8:AN611, "=APAGADO",F8:F611,"=RADIO") -> 0 | AO5: =COUNTIFS(AO8:AO611, "=APAGADO",F8:F611,"=RADIO") -> 0 | AP5: =COUNTIFS(AP8:AP611, "=APAGADO",G8:G611,"=RADIO") -> 0
D6: APAGADOS ANTENA | L6: =COUNTIFS(L8:L611, "=APAGADO",F8:F611,"=PTO A FO") -> 7 | M6: =COUNTIFS(M8:M611, "=APAGADO",F8:F611,"=PTO A FO") -> 8 | N6: =COUNTIFS(N8:N611, "=APAGADO",F8:F611,"=PTO A FO") -> 8 | O6: =COUNTIFS(O8:O611, "=APAGADO",F8:F611,"=PTO A FO") -> 10 | P6: =COUNTIFS(P8:P611, "=APAGADO",F8:F611,"=PTO A FO") -> 8 | Q6: =COUNTIFS(Q8:Q611, "=APAGADO",F8:F611,"=PTO A FO") -> 6 | R6: =COUNTIFS(R8:R611, "=APAGADO",F8:F611,"=PTO A FO") -> 7 | S6: =COUNTIFS(S8:S611, "=APAGADO",F8:F611,"=PTO A FO") -> 6 | T6: =COUNTIFS(T8:T611, "=APAGADO",F8:F611,"=PTO A FO") -> 6 | U6: =COUNTIFS(U8:U611, "=APAGADO",F8:F611,"=PTO A FO") -> 6 | V6: =COUNTIFS(V8:V611, "=APAGADO",F8:F611,"=PTO A FO") -> 7 | W6: =COUNTIFS(W8:W611, "=APAGADO",F8:F611,"=PTO A FO") -> 6 | X6: =COUNTIFS(X8:X611, "=APAGADO",F8:F611,"=PTO A FO") -> 6 | Y6: =COUNTIFS(Y8:Y611, "=APAGADO",F8:F611,"=PTO A FO") -> 6 | Z6: =COUNTIFS(Z8:Z611, "=APAGADO",F8:F611,"=PTO A FO") -> 7 | AA6: =COUNTIFS(AA8:AA611, "=APAGADO",F8:F611,"=PTO A FO") -> 6 | AB6: =COUNTIFS(AB8:AB611, "=APAGADO",F8:F611,"=PTO A FO") -> 0 | AC6: =COUNTIFS(AC8:AC611, "=APAGADO",F8:F611,"=PTO A FO") -> 0 | AD6: =COUNTIFS(AD8:AD611, "=APAGADO",F8:F611,"=PTO A FO") -> 0 | AE6: =COUNTIFS(AE8:AE611, "=APAGADO",F8:F611,"=PTO A FO") -> 0 | AF6: =COUNTIFS(AF8:AF611, "=APAGADO",F8:F611,"=PTO A FO") -> 0 | AG6: =COUNTIFS(AG8:AG611, "=APAGADO",F8:F611,"=PTO A FO") -> 0 | AH6: =COUNTIFS(AH8:AH611, "=APAGADO",F8:F611,"=PTO A FO") -> 0 | AI6: =COUNTIFS(AI8:AI611, "=APAGADO",F8:F611,"=PTO A FO") -> 0 | AJ6: =COUNTIFS(AJ8:AJ611, "=APAGADO",F8:F611,"=PTO A FO") -> 0 | AK6: =COUNTIFS(AK8:AK611, "=APAGADO",F8:F611,"=PTO A FO") -> 0 | AL6: =COUNTIFS(AL8:AL611, "=APAGADO",F8:F611,"=PTO A FO") -> 0 | AM6: =COUNTIFS(AM8:AM611, "=APAGADO",F8:F611,"=PTO A FO") -> 0 | AN6: =COUNTIFS(AN8:AN611, "=APAGADO",F8:F611,"=PTO A FO") -> 0 | AO6: =COUNTIFS(AO8:AO611, "=APAGADO",F8:F611,"=PTO A FO") -> 0 | AP6: =COUNTIFS(AP8:AP611, "=APAGADO",G8:G611,"=PTO A FO") -> 0
A7: Barrio | B7: [Denominacion] | C7: [Empresa Mantenimiento] | D7: [Ubicacion] | E7: [Tipo de Camara] | F7: [Tipo de Conexion] | G7: Destino | I7: DIAS FUNCIONANDO | J7: DIAS CAIDA | K7: EFECTIVIDAD | L7: 45839 | M7: 45840 | N7: 45841 | O7: 45842 | P7: 45843 | Q7: 45844 | R7: 45845 | S7: 45846 | T7: 45847 | U7: 45848 | V7: 45849 | W7: 45850 | X7: 45851 | Y7: 45852 | Z7: 45853 | AA7: 45854 | AB7: 45855 | AC7: 45856 | AD7: 45857 | AE7: 45858 | AF7: 45859 | AG7: 45860 | AH7: 45861 | AI7: 45862 | AJ7: 45863 | AK7: 45864 | AL7: 45865 | AM7: 45866 | AN7: 45867 | AO7: 45868 | AP7: 45869
A8: ALTAMIRA | B8: ALT01 | C8: BONOMO | D8: Calchaqui y Sgto. Cabral | E8: Domo | F8: Fibra Optica | H8: 172.20.10.6 | I8: =COUNTIF(L8:AM8,"") -> 28 | J8: =COUNTIF(L8:AM8,"APAGADO") -> 0 | K8: =(I8)/(J8+I8) -> 1
A9: ALTAMIRA | B9: ALT02 | C9: BONOMO | D9: Calchaqui y Lope de Vega | E9: Domo | F9: PTO A FO | G9: CABRAL Y CALCHAQUI | H9: 172.20.12.218 | I9: =COUNTIF(L9:AM9,"") -> 28 | J9: =COUNTIF(L9:AM9,"APAGADO") -> 0 | K9: =(I9)/(J9+I9) -> 1
A10: ALTAMIRA | B10: ALT 03 | C10: BONOMO | D10: Bombero Galarza y Necochea | E10: Domo | F10: Fibra Optica | H10: 172.20.12.54 | I10: =COUNTIF(L10:AM10,"") -> 25 | J10: =COUNTIF(L10:AM10,"APAGADO") -> 3 | K10: =(I10)/(J10+I10) -> 0.89285714 | M10: APAGADO | N10: APAGADO | O10: APAGADO
A11: ALTAMIRA | B11: ALT 04 | C11: BONOMO | D11: Francia y Necochea | E11: Domo | F11: Fibra Optica | H11: 172.20.12.55 | I11: =COUNTIF(L11:AM11,"") -> 21 | J11: =COUNTIF(L11:AM11,"APAGADO") -> 7 | K11: =(I11)/(J11+I11) -> 0.75 | O11: APAGADO | P11: APAGADO | R11: APAGADO | S11: APAGADO | U11: APAGADO | V11: APAGADO | Z11: APAGADO
A12: ALTAMIRA | B12: ALT05 | C12: BONOMO | D12: Av. Calchaqui y Bombero Galarza | E12: Domo | F12: PTO A FO | G12: NECOCHEA Y GALARZA | H12: 172.20.12.216 | I12: =COUNTIF(L12:AM12,"") -> 23 | J12: =COUNTIF(L12:AM12,"APAGADO") -> 5 | K12: =(I12)/(J12+I12) -> 0.82142857 | W12: APAGADO | X12: APAGADO | Y12: APAGADO | Z12: APAGADO | AA12: APAGADO
A13: ALTAMIRA | B13: ALT 06 | C13: BONOMO | D13: LOPE DE VEGA Y NECOCHEA | E13: Domo | F13: PTO A FO | G13: NECOCHEA Y GALARZA | H13: 172.20.12.12 | I13: =COUNTIF(L13:AM13,"") -> 28 | J13: =COUNTIF(L13:AM13,"APAGADO") -> 0 | K13: =(I13)/(J13+I13) -> 1
A14: ALTAMIRA | B14: ALT07 | C14: BONOMO | D14: AV. CALCHAQUI Y AV. DEL TRABAJO | E14: DOMO | F14: PTO A FO | G14: CABRAL Y CALCHAQUI | H14: 172.20.10.57 | I14: =COUNTIF(L14:AM14,"") -> 28 | J14: =COUNTIF(L14:AM14,"APAGADO") -> 0 | K14: =(I14)/(J14+I14) -> 1
A15: ALTAMIRA | B15: ALT 08 | C15: BONOMO | D15: HUMAITA Y NECOCHEA | E15: DOMO | F15: Fibra Optica | H15: 172.20.11.215 | I15: =COUNTIF(L15:AM15,"") -> 28 | J15: =COUNTIF(L15:AM15,"APAGADO") -> 0 | K15: =(I15)/(J15+I15) -> 1
A16: ALTAMIRA | B16: ALT 09 | C16: BONOMO | D16: NECOCHEA Y CURUPAITY | E16: DOMO | F16: Fibra Optica | H16: 172.20.11.216 | I16: =COUNTIF(L16:AM16,"") -> 28 | J16: =COUNTIF(L16:AM16,"APAGADO") -> 0 | K16: =(I16)/(J16+I16) -> 1
A17: ALTAMIRA | B17: ALT 10 | C17: BONOMO | D17: Calchaqui y Francia | E17: Domo | F17: Radio | H17: 172.20.12.156 | I17: =COUNTIF(L17:AM17,"") -> 20 | J17: =COUNTIF(L17:AM17,"APAGADO") -> 8 | K17: =(I17)/(J17+I17) -> 0.71428571 | T17: APAGADO | U17: APAGADO | V17: APAGADO | W17: APAGADO | X17: APAGADO | Y17: APAGADO | Z17: APAGADO | AA17: APAGADO
A18: ALTAMIRA | B18: ALT 11 | C18: BONOMO | D18: CALCHAQUÍ Y GALARZA FIJA | E18: Fija | F18: Fibra Optica | H18: 172.20.12.241 | I18: =COUNTIF(L18:AM18,"") -> 23 | J18: =COUNTIF(L18:AM18,"APAGADO") -> 5 | K18: =(I18)/(J18+I18) -> 0.82142857 | W18: APAGADO | X18: APAGADO | Y18: APAGADO | Z18: APAGADO | AA18: APAGADO
A19: AGUSTIN RAMIREZ | B19: ARA 01 | C19: BONOMO | D19: Malambo y Tranquera | E19: Domo | F19: Fibra Optica | H19: 172.20.12.110 | I19: =COUNTIF(L19:AM19,"") -> 26 | J19: =COUNTIF(L19:AM19,"APAGADO") -> 2 | K19: =(I19)/(J19+I19) -> 0.92857143 | W19: APAGADO | X19: APAGADO
A20: BELGRANO | B20: BEL 01 | C20: BONOMO | D20: San Martin y Dardo Rocha | E20: DOMO | F20: Fibra Optica | H20: 172.20.12.64 | I20: =COUNTIF(L20:AM20,"") -> 28 | J20: =COUNTIF(L20:AM20,"APAGADO") -> 0 | K20: =(I20)/(J20+I20) -> 1
A21: BELGRANO | B21: BEL 02 | C21: BONOMO | D21: Guardia vieja y Fronteriz | E21: DOMO | F21: Fibra Optica | H21: 172.20.10.117 | I21: =COUNTIF(L21:AM21,"") -> 28 | J21: =COUNTIF(L21:AM21,"APAGADO") -> 0 | K21: =(I21)/(J21+I21) -> 1
A22: BOSQUES CENTRO | B22: BOSQC 01 | C22: COSEIDI | D22: LUIS AGOTE E/DANUNCIO Y CAMPOAMOR | E22: Fija | F22: Radio | H22: 172.20.11.15 | I22: =COUNTIF(L22:AM22,"") -> 17 | J22: =COUNTIF(L22:AM22,"APAGADO") -> 11 | K22: =(I22)/(J22+I22) -> 0.60714286 | L22: APAGADO | M22: APAGADO | N22: APAGADO | O22: APAGADO | P22: APAGADO | Q22: APAGADO | R22: APAGADO | S22: APAGADO | T22: APAGADO | U22: APAGADO | V22: APAGADO
A23: BOSQUES CENTRO | B23: BOSQC 02 | C23: COSEIDI | D23: LUIS AGOTE E/DANUNCIO Y CAMPOAMOR | E23: Fija | F23: Radio | H23: 172.20.11.16 | I23: =COUNTIF(L23:AM23,"") -> 17 | J23: =COUNTIF(L23:AM23,"APAGADO") -> 11 | K23: =(I23)/(J23+I23) -> 0.60714286 | L23: APAGADO | M23: APAGADO | N23: APAGADO | O23: APAGADO | P23: APAGADO | Q23: APAGADO | R23: APAGADO | S23: APAGADO | T23: APAGADO | U23: APAGADO | V23: APAGADO
A24: BOSQUES CENTRO | B24: BOSQC 03 | C24: COSEIDI | D24: BENAVENTE Y LUIS AGOTE | E24: Fija | F24: Radio | H24: 172.20.11.13 | I24: =COUNTIF(L24:AM24,"") -> 17 | J24: =COUNTIF(L24:AM24,"APAGADO") -> 11 | K24: =(I24)/(J24+I24) -> 0.60714286 | L24: APAGADO | M24: APAGADO | N24: APAGADO | O24: APAGADO | P24: APAGADO | Q24: APAGADO | R24: APAGADO | S24: APAGADO | T24: APAGADO | U24: APAGADO | V24: APAGADO
A25: BOSQUES CENTRO | B25: BOSQC 04 | C25: COSEIDI | D25: BENAVENTE Y LUIS AGOTE | E25: Fija | F25: Radio | H25: 172.20.11.113 | I25: =COUNTIF(L25:AM25,"") -> 17 | J25: =COUNTIF(L25:AM25,"APAGADO") -> 11 | K25: =(I25)/(J25+I25) -> 0.60714286 | L25: APAGADO | M25: APAGADO | N25: APAGADO | O25: APAGADO | P25: APAGADO | Q25: APAGADO | R25: APAGADO | S25: APAGADO | T25: APAGADO | U25: APAGADO | V25: APAGADO
A26: BOSQUES CENTRO | B26: BOSQC 05 | C26: COSEIDI | D26: LUIS AGOTE Y RUTA 36 | E26: Fija | F26: Radio | H26: 172.20.11.17 | I26: =COUNTIF(L26:AM26,"") -> 23 | J26: =COUNTIF(L26:AM26,"APAGADO") -> 5 | K26: =(I26)/(J26+I26) -> 0.82142857 | O26: APAGADO | P26: APAGADO | Q26: APAGADO | R26: APAGADO | S26: APAGADO
A27: BOSQUES CENTRO | B27: BOSQC 06 | C27: COSEIDI | D27: LUIS AGOTE Y RUTA 36 | E27: Fija | F27: Radio | H27: 172.20.11.18 | I27: =COUNTIF(L27:AM27,"") -> 23 | J27: =COUNTIF(L27:AM27,"APAGADO") -> 5 | K27: =(I27)/(J27+I27) -> 0.82142857 | O27: APAGADO | P27: APAGADO | Q27: APAGADO | R27: APAGADO | S27: APAGADO
A28: BOSQUES CENTRO | B28: BOSQC 07 | C28: BONOMO | D28: Touring club y Sta Teresita | E28: Domo | F28: Fibra Optica | H28: 172.20.10.141 | I28: =COUNTIF(L28:AM28,"") -> 28 | J28: =COUNTIF(L28:AM28,"APAGADO") -> 0 | K28: =(I28)/(J28+I28) -> 1
A29: BOSQUES CENTRO | B29: PAVE01 | C29: COSEIDI | D29: Touring Club y Ramallo | E29: Domo | F29: Fibra Optica | H29: 172.20.10.144 | I29: =COUNTIF(L29:AM29,"") -> 13 | J29: =COUNTIF(L29:AM29,"APAGADO") -> 15 | K29: =(I29)/(J29+I29) -> 0.46428571 | L29: APAGADO | M29: APAGADO | N29: APAGADO | O29: APAGADO | P29: APAGADO | Q29: APAGADO | R29: APAGADO | S29: APAGADO | T29: APAGADO | U29: APAGADO | V29: APAGADO | W29: APAGADO | X29: APAGADO | Z29: APAGADO | AA29: APAGADO
A30: BOSQUES CENTRO | B30: PAVE02 | C30: COSEIDI | D30: Ramallo y Calingasta | F30: Fibra Optica | H30: 172.20.10.37 | I30: =COUNTIF(L30:AM30,"") -> 13 | J30: =COUNTIF(L30:AM30,"APAGADO") -> 15 | K30: =(I30)/(J30+I30) -> 0.46428571 | L30: APAGADO | M30: APAGADO | N30: APAGADO | O30: APAGADO | P30: APAGADO | Q30: APAGADO | R30: APAGADO | S30: APAGADO | T30: APAGADO | U30: APAGADO | V30: APAGADO | W30: APAGADO | X30: APAGADO | Z30: APAGADO | AA30: APAGADO
A31: BOSQUES CENTRO | B31: CVA01 | C31: COSEIDI | D31: CACHEUTA Y 1355 | F31: Fibra Optica | H31: 172.20.10.59 | S31: APAGADO
A32: LA CAROLINA 2 | B32: CAR01 (Fija 1) | C32: COSEIDI | D32: Azurduy y Vergara | E32: Fija | F32: Fibra Optica | H32: 172.20.10.60 | I32: =COUNTIF(L32:AM32,"") -> 28 | J32: =COUNTIF(L32:AM32,"APAGADO") -> 0 | K32: =(I32)/(J32+I32) -> 1
A33: LA CAROLINA 2 | B33: CAR02 (Fija 2) | C33: COSEIDI | D33: Azurduy y Vergara | E33: Fija | F33: Fibra Optica | H33: 172.20.10.73 | I33: =COUNTIF(L33:AM33,"") -> 28 | J33: =COUNTIF(L33:AM33,"APAGADO") -> 0 | K33: =(I33)/(J33+I33) -> 1
A34: CENTRO | B34: CEN01 | C34: BONOMO | D34: San Martin y 9 de Julio | E34: Fija | F34: Fibra Optica | H34: 172.20.11.10 | I34: =COUNTIF(L34:AM34,"") -> 28 | J34: =COUNTIF(L34:AM34,"APAGADO") -> 0 | K34: =(I34)/(J34+I34) -> 1
A35: CENTRO | B35: CEN02 | C35: BONOMO | D35: San Martin y Almafuerte | E35: Fija | F35: Fibra Optica | H35: 172.20.11.11 | I35: =COUNTIF(L35:AM35,"") -> 28 | J35: =COUNTIF(L35:AM35,"APAGADO") -> 0 | K35: =(I35)/(J35+I35) -> 1
A36: CENTRO | B36: CEN03 | C36: BONOMO | D36: San Martin y Sallares | E36: Domo | F36: Fibra Optica | H36: 172.20.12.30 | I36: =COUNTIF(L36:AM36,"") -> 28 | J36: =COUNTIF(L36:AM36,"APAGADO") -> 0 | K36: =(I36)/(J36+I36) -> 1
A37: CENTRO | B37: CEN04 | C37: BONOMO | D37: San Martin y Contreras | E37: Domo | F37: Fibra Optica | H37: 172.20.12.29 | I37: =COUNTIF(L37:AM37,"") -> 28 | J37: =COUNTIF(L37:AM37,"APAGADO") -> 0 | K37: =(I37)/(J37+I37) -> 1
A38: CENTRO | B38: CEN 05 | C38: BONOMO | D38: Bocuzzi e/España y San Martin | E38: DOMO | F38: Fibra Optica | H38: 172.20.10.200 | I38: =COUNTIF(L38:AM38,"") -> 28 | J38: =COUNTIF(L38:AM38,"APAGADO") -> 0 | K38: =(I38)/(J38+I38) -> 1
A39: CENTRO | B39: CEN06 | C39: BONOMO | D39: Monteagudo y A.del Valle | E39: Fija | F39: Fibra Optica | H39: 172.20.10.02 | I39: =COUNTIF(L39:AM39,"") -> 12 | J39: =COUNTIF(L39:AM39,"APAGADO") -> 16 | K39: =(I39)/(J39+I39) -> 0.42857143 | L39: APAGADO | M39: APAGADO | N39: APAGADO | O39: APAGADO | P39: APAGADO | Q39: APAGADO | R39: APAGADO | S39: APAGADO | T39: APAGADO | U39: APAGADO | V39: APAGADO | W39: APAGADO | X39: APAGADO | Y39: APAGADO | Z39: APAGADO | AA39: APAGADO
A40: CENTRO | B40: CEN07 | C40: BONOMO | D40: San Martin y Guemes | E40: DOMO | F40: Fibra Optica | H40: 172.20.11.20 | I40: =COUNTIF(L40:AM40,"") -> 28 | J40: =COUNTIF(L40:AM40,"APAGADO") -> 0 | K40: =(I40)/(J40+I40) -> 1
...

Sheet AUXILIAR

Sheet informe
C1: CANTIDAD | D1: APAGADAS | E1: %
B2: TOTAL | C2: =CANTIDAD_DE_CAMARAS -> 496 | F2: 45839
A3: L | B3: CAIDAS | C3: ='RESUMEN TOTAL'!L3 -> 69 | E3: =C3/C2 -> 0.1391129
B4: LLEGAMOS NOSOTROS | C4: 2 | D4: =C3-C4 -> 67 | E4: =D4/C2 -> 0.13508065
B5: NO ESTA LA CAMARA | C5: 6 | D5: =D4-C5 -> 61 | E5: =D5/C2 -> 0.12298387
A6: L | B6: RADIO | C6: ='RESUMEN TOTAL'!L5 -> 13 | D6: =D5-C6 -> 48 | E6: =D6/C2 -> 0.096774194
B7: ANTENA DESMONTADA | C7: 10 | D7: =D6-C7 -> 38 | E7: =D7/C2 -> 0.076612903
C8: CANTIDAD | D8: APAGADAS | E8: %
A9: F | B9: BONOMO | C9: =BONOMOcam -> 269 | D9: =Hoja1!F3 -> 26 | E9: =D9/C9 -> 0.096654275
A10: F | B10: COSEIDI | C10: =COSEIDIcam -> 226 | D10: =Hoja1!F5 -> 43 | E10: =D10/C10 -> 0.19026549
C12: CANTIDAD | D12: APAGADAS | E12: %
B13: TOTAL | C13: =CANTIDAD_DE_CAMARAS -> 496 | F13: 45840
A14: M | B14: CAIDAS | C14: ='RESUMEN TOTAL'!M3 -> 85 | E14: =C14/C13 -> 0.17137097
B15: LLEGAMOS NOSOTROS | C15: 2 | D15: =C14-C15 -> 83 | E15: =D15/C13 -> 0.16733871
B16: NO ESTA LA CAMARA | C16: 6 | D16: =D15-C16 -> 77 | E16: =D16/C13 -> 0.15524194
A17: M | B17: RADIO | C17: ='RESUMEN TOTAL'!M5 -> 15 | D17: =D16-C17 -> 62 | E17: =D17/C13 -> 0.125
B18: ANTENA DESMONTADA | C18: 10 | D18: =D17-C18 -> 52 | E18: =D18/C13 -> 0.10483871
C19: CANTIDAD | D19: APAGADAS | E19: %
A20: G | B20: BONOMO | C20: =BONOMOcam -> 269 | D20: =Hoja1!G3 -> 40 | E20: =D20/C20 -> 0.14869888
A21: G | B21: COSEIDI | C21: =COSEIDIcam -> 226 | D21: =Hoja1!G5 -> 45 | E21: =D21/C21 -> 0.19911504
C23: CANTIDAD | D23: APAGADAS | E23: %
B24: TOTAL | C24: =CANTIDAD_DE_CAMARAS -> 496 | F24: 45841
A25: N | B25: CAIDAS | C25: ='RESUMEN TOTAL'!N3 -> 85 | E25: =C25/C24 -> 0.17137097
B26: LLEGAMOS NOSOTROS | C26: 25 | D26: =C25-C26 -> 60 | E26: =D26/C24 -> 0.12096774
B27: NO ESTA LA CAMARA | C27: 6 | D27: =D26-C27 -> 54 | E27: =D27/C24 -> 0.10887097
A28: N | B28: RADIO | C28: ='RESUMEN TOTAL'!N5 -> 15 | D28: =D27-C28 -> 39 | E28: =D28/C24 -> 0.078629032
B29: ANTENA DESMONTADA | C29: 10 | D29: =D28-C29 -> 29 | E29: =D29/C24 -> 0.058467742
C30: CANTIDAD | D30: APAGADAS | E30: %
B31: BONOMO | C31: =BONOMOcam -> 269 | D31: =Hoja1!H3 -> 40 | E31: =D31/C31 -> 0.14869888
B32: COSEIDI | C32: =COSEIDIcam -> 226 | D32: =Hoja1!H5 -> 45 | E32: =D32/C32 -> 0.19911504
C34: CANTIDAD | D34: APAGADAS | E34: %
B35: TOTAL | C35: =CANTIDAD_DE_CAMARAS -> 496 | F35: 45842
A36: O | B36: CAIDAS | C36: ='RESUMEN TOTAL'!O3 -> 102 | E36: =C36/C35 -> 0.20564516
B37: LLEGAMOS NOSOTROS | C37: 8 | D37: =C36-C37 -> 94 | E37: =D37/C35 -> 0.18951613
B38: NO ESTA LA CAMARA | C38: 6 | D38: =D37-C38 -> 88 | E38: =D38/C35 -> 0.17741935
A39: O | B39: RADIO | C39: ='RESUMEN TOTAL'!O5 -> 22 | D39: =D38-C39 -> 66 | E39: =D39/C35 -> 0.13306452
B40: ANTENA DESMONTADA | C40: 10 | D40: =D39-C40 -> 56 | E40: =D40/C35 -> 0.11290323
C41: CANTIDAD | D41: APAGADAS | E41: %
B42: BONOMO | C42: =BONOMOcam -> 269 | D42: =Hoja1!I3 -> 30 | E42: =D42/C42 -> 0.11152416
B43: COSEIDI | C43: =COSEIDIcam -> 226 | D43: =Hoja1!I5 -> 72 | E43: =D43/C43 -> 0.31858407
...

Sheet Hoja1
B1: CAMARAS
A2: BONOMO | B2: =COUNTIFS('RESUMEN TOTAL'!C8:C503,"=BONOMO") -> 269 | F2: 45839 | G2: 45840 | H2: 45841 | I2: 45842 | J2: 45843 | K2: 45844 | L2: 45845 | M2: 45846 | N2: 45847 | O2: 45848 | P2: 45849 | Q2: 45850 | R2: 45851 | S2: 45852 | T2: 45853 | U2: 45854 | V2: 45855 | W2: 45856 | X2: 45857 | Y2: 45858 | Z2: 45859 | AA2: 45860 | AB2: 45861 | AC2: 45862 | AD2: 45863 | AE2: 45864 | AF2: 45865 | AG2: 45866 | AH2: 45867 | AI2: 45868 | AJ2: 45869
D3: BONOMO | E3: APAGADAS BONOMO | F3: =COUNTIFS('RESUMEN TOTAL'!L8:L611,"=APAGADO",'RESUMEN TOTAL'!C8:C611,"=BONOMO") -> 26 | G3: =COUNTIFS('RESUMEN TOTAL'!M8:M611,"=APAGADO",'RESUMEN TOTAL'!C8:C611,"=BONOMO") -> 40 | H3: =COUNTIFS('RESUMEN TOTAL'!N8:N611,"=APAGADO",'RESUMEN TOTAL'!C8:C611,"=BONOMO") -> 40 | I3: =COUNTIFS('RESUMEN TOTAL'!O8:O611,"=APAGADO",'RESUMEN TOTAL'!C8:C611,"=BONOMO") -> 30 | J3: =COUNTIFS('RESUMEN TOTAL'!P8:P611,"=APAGADO",'RESUMEN TOTAL'!C8:C611,"=BONOMO") -> 40 | K3: =COUNTIFS('RESUMEN TOTAL'!Q8:Q611,"=APAGADO",'RESUMEN TOTAL'!C8:C611,"=BONOMO") -> 21 | L3: =COUNTIFS('RESUMEN TOTAL'!R8:R611,"=APAGADO",'RESUMEN TOTAL'!C8:C611,"=BONOMO") -> 41 | M3: =COUNTIFS('RESUMEN TOTAL'!S8:S611,"=APAGADO",'RESUMEN TOTAL'!C8:C611,"=BONOMO") -> 21 | N3: =COUNTIFS('RESUMEN TOTAL'!T8:T611,"=APAGADO",'RESUMEN TOTAL'!C8:C611,"=BONOMO") -> 28 | O3: =COUNTIFS('RESUMEN TOTAL'!U8:U611,"=APAGADO",'RESUMEN TOTAL'!C8:C611,"=BONOMO") -> 31 | P3: =COUNTIFS('RESUMEN TOTAL'!V8:V611,"=APAGADO",'RESUMEN TOTAL'!C8:C611,"=BONOMO") -> 28 | Q3: =COUNTIFS('RESUMEN TOTAL'!W8:W611,"=APAGADO",'RESUMEN TOTAL'!C8:C611,"=BONOMO") -> 27 | R3: =COUNTIFS('RESUMEN TOTAL'!X8:X611,"=APAGADO",'RESUMEN TOTAL'!C8:C611,"=BONOMO") -> 31 | S3: =COUNTIFS('RESUMEN TOTAL'!Y8:Y611,"=APAGADO",'RESUMEN TOTAL'!C8:C611,"=BONOMO") -> 23 | T3: =COUNTIFS('RESUMEN TOTAL'!Z8:Z611,"=APAGADO",'RESUMEN TOTAL'!C8:C611,"=BONOMO") -> 27 | U3: 0 | V3: =COUNTIFS('RESUMEN TOTAL'!AB8:AB611,"=APAGADO",'RESUMEN TOTAL'!C8:C611,"=BONOMO") -> 0 | W3: =COUNTIFS('RESUMEN TOTAL'!AC8:AC611,"=APAGADO",'RESUMEN TOTAL'!C8:C611,"=BONOMO") -> 0 | X3: =COUNTIFS('RESUMEN TOTAL'!AD8:AD611,"=APAGADO",'RESUMEN TOTAL'!C8:C611,"=BONOMO") -> 0 | Y3: =COUNTIFS('RESUMEN TOTAL'!AE8:AE611,"=APAGADO",'RESUMEN TOTAL'!C8:C611,"=BONOMO") -> 0 | Z3: =COUNTIFS('RESUMEN TOTAL'!AF8:AF611,"=APAGADO",'RESUMEN TOTAL'!C8:C611,"=BONOMO") -> 0 | AA3: =COUNTIFS('RESUMEN TOTAL'!AG8:AG611,"=APAGADO",'RESUMEN TOTAL'!C8:C611,"=BONOMO") -> 0 | AB3: =COUNTIFS('RESUMEN TOTAL'!AH8:AH611,"=APAGADO",'RESUMEN TOTAL'!C8:C611,"=BONOMO") -> 0 | AC3: =COUNTIFS('RESUMEN TOTAL'!AI8:AI611,"=APAGADO",'RESUMEN TOTAL'!C8:C611,"=BONOMO") -> 0 | AD3: =COUNTIFS('RESUMEN TOTAL'!AJ8:AJ611,"=APAGADO",'RESUMEN TOTAL'!C8:C611,"=BONOMO") -> 0 | AE3: 0 | AF3: =COUNTIFS('RESUMEN TOTAL'!AL8:AL611,"=APAGADO",'RESUMEN TOTAL'!C8:C611,"=BONOMO") -> 0 | AG3: =COUNTIFS('RESUMEN TOTAL'!AM8:AM611,"=APAGADO",'RESUMEN TOTAL'!C8:C611,"=BONOMO") -> 0 | AH3: =COUNTIFS('RESUMEN TOTAL'!AN8:AN611,"=APAGADO",'RESUMEN TOTAL'!C8:C611,"=BONOMO") -> 0 | AI3: =COUNTIFS('RESUMEN TOTAL'!AO8:AO611,"=APAGADO",'RESUMEN TOTAL'!C8:C611,"=BONOMO") -> 0 | AJ3: =COUNTIFS('RESUMEN TOTAL'!AP8:AP611,"=APAGADO",'RESUMEN TOTAL'!D8:D611,"=BONOMO") -> 0
A4: COSEIDI | B4: =COUNTIFS('RESUMEN TOTAL'!C8:C503,"=COSEIDI") -> 226 | E4: % BONOMO | F4: =F3/BONOMOcam -> 0.096654275 | G4: =G3/BONOMOcam -> 0.14869888 | H4: =H3/BONOMOcam -> 0.14869888 | I4: =I3/BONOMOcam -> 0.11152416 | J4: =J3/BONOMOcam -> 0.14869888 | K4: =K3/BONOMOcam -> 0.078066914 | L4: =L3/BONOMOcam -> 0.15241636 | M4: =M3/BONOMOcam -> 0.078066914 | ... O4: =O3/BONOMOcam -> 0.11524164 | P4: 0 | Q4: 0 | R4: 0 | S4: 0 | T4: 0 | U4: 0 | V4: 0 | W4: 0 | X4: 0 | Y4: 0 | Z4: 0 | AA4: 0 | AB4: 0 | AC4: 0 | AD4: 0 | AE4: 0 | AF4: 0 | AG4: =AG3/BONOMOcam -> 0 | AH4: =AH3/BONOMOcam -> 0 | AI4: =AI3/BONOMOcam -> 0 | AJ4: =AJ3/BONOMOcam -> 0
D5: COSEIDI | E5: APAGADAS COSEIDI | F5: =COUNTIFS('RESUMEN TOTAL'!L10:L613,"=APAGADO",'RESUMEN TOTAL'!C10:C613,"=COSEIDI") -> 43 | G5: =COUNTIFS('RESUMEN TOTAL'!M10:M613,"=APAGADO",'RESUMEN TOTAL'!C10:C613,"=COSEIDI") -> 45 | H5: =COUNTIFS('RESUMEN TOTAL'!N10:N613,"=APAGADO",'RESUMEN TOTAL'!C10:C613,"=COSEIDI") -> 45 | I5: =COUNTIFS('RESUMEN TOTAL'!O10:O613,"=APAGADO",'RESUMEN TOTAL'!C10:C613,"=COSEIDI") -> 72 | J5: =COUNTIFS('RESUMEN TOTAL'!P10:P613,"=APAGADO",'RESUMEN TOTAL'!C10:C613,"=COSEIDI") -> 74 | K5: =COUNTIFS('RESUMEN TOTAL'!Q10:Q613,"=APAGADO",'RESUMEN TOTAL'!C10:C613,"=COSEIDI") -> 80 | L5: =COUNTIFS('RESUMEN TOTAL'!R10:R613,"=APAGADO",'RESUMEN TOTAL'!C10:C613,"=COSEIDI") -> 81 | M5: =COUNTIFS('RESUMEN TOTAL'!S10:S613,"=APAGADO",'RESUMEN TOTAL'!C10:C613,"=COSEIDI") -> 77 | N5: =COUNTIFS('RESUMEN TOTAL'!T10:T613,"=APAGADO",'RESUMEN TOTAL'!C10:C613,"=COSEIDI") -> 52 | O5: =COUNTIFS('RESUMEN TOTAL'!U10:U613,"=APAGADO",'RESUMEN TOTAL'!C10:C613,"=COSEIDI") -> 47 | P5: =COUNTIFS('RESUMEN TOTAL'!V10:V613,"=APAGADO",'RESUMEN TOTAL'!C10:C613,"=COSEIDI") -> 49 | Q5: =COUNTIFS('RESUMEN TOTAL'!W10:W613,"=APAGADO",'RESUMEN TOTAL'!C10:C613,"=COSEIDI") -> 36 | R5: =COUNTIFS('RESUMEN TOTAL'!X10:X613,"=APAGADO",'RESUMEN TOTAL'!C10:C613,"=COSEIDI") -> 37 | S5: =COUNTIFS('RESUMEN TOTAL'!Y10:Y613,"=APAGADO",'RESUMEN TOTAL'!C10:C613,"=COSEIDI") -> 33 | T5: =COUNTIFS('RESUMEN TOTAL'!Z10:Z613,"=APAGADO",'RESUMEN TOTAL'!C10:C613,"=COSEIDI") -> 35 | U5: =COUNTIFS('RESUMEN TOTAL'!AA10:AA613,"=APAGADO",'RESUMEN TOTAL'!C10:C613,"=COSEIDI") -> 30 | V5: =COUNTIFS('RESUMEN TOTAL'!AB10:AB613,"=APAGADO",'RESUMEN TOTAL'!C10:C613,"=COSEIDI") -> 0 | W5: =COUNTIFS('RESUMEN TOTAL'!AC10:AC613,"=APAGADO",'RESUMEN TOTAL'!C10:C613,"=COSEIDI") -> 0 | X5: =COUNTIFS('RESUMEN TOTAL'!AD10:AD613,"=APAGADO",'RESUMEN TOTAL'!C10:C613,"=COSEIDI") -> 0 | Y5: =COUNTIFS('RESUMEN TOTAL'!AE10:AE613,"=APAGADO",'RESUMEN TOTAL'!C10:C613,"=COSEIDI") -> 0 | Z5: =COUNTIFS('RESUMEN TOTAL'!AF10:AF613,"=APAGADO",'RESUMEN TOTAL'!C10:C613,"=COSEIDI") -> 0 | AA5: =COUNTIFS('RESUMEN TOTAL'!AG10:AG613,"=APAGADO",'RESUMEN TOTAL'!C10:C613,"=COSEIDI") -> 0 | AB5: =COUNTIFS('RESUMEN TOTAL'!AH10:AH613,"=APAGADO",'RESUMEN TOTAL'!C10:C613,"=COSEIDI") -> 0 | AC5: =COUNTIFS('RESUMEN TOTAL'!AI10:AI613,"=APAGADO",'RESUMEN TOTAL'!C10:C613,"=COSEIDI") -> 0 | AD5: =COUNTIFS('RESUMEN TOTAL'!AJ10:AJ613,"=APAGADO",'RESUMEN TOTAL'!C10:C613,"=COSEIDI") -> 0 | AE5: =COUNTIFS('RESUMEN TOTAL'!AK10:AK613,"=APAGADO",'RESUMEN TOTAL'!C10:C613,"=COSEIDI") -> 0 | AF5: =COUNTIFS('RESUMEN TOTAL'!AL10:AL613,"=APAGADO",'RESUMEN TOTAL'!C10:C613,"=COSEIDI") -> 0 | AG5: =COUNTIFS('RESUMEN TOTAL'!AM10:AM613,"=APAGADO",'RESUMEN TOTAL'!C10:C613,"=COSEIDI") -> 0 | AH5: =COUNTIFS('RESUMEN TOTAL'!AN10:AN613,"=APAGADO",'RESUMEN TOTAL'!C10:C613,"=COSEIDI") -> 0 | AI5: =COUNTIFS('RESUMEN TOTAL'!AO10:AO613,"=APAGADO",'RESUMEN TOTAL'!C10:C613,"=COSEIDI") -> 0 | AJ5: =COUNTIFS('RESUMEN TOTAL'!AP10:AP613,"=APAGADO",'RESUMEN TOTAL'!D10:D613,"=COSEIDI") -> 0
E6: % COSEIDI | F6: =F5/COSEIDIcam -> 0.19026549 | G6: =G5/COSEIDIcam -> 0.19911504 | H6: =H5/COSEIDIcam -> 0.19911504 | I6: =I5/COSEIDIcam -> 0.31858407 | J6: =J5/COSEIDIcam -> 0.32743363 | K6: =K5/COSEIDIcam -> 0.3539823 | L6: =L5/COSEIDIcam -> 0.35840708 | M6: =M5/COSEIDIcam -> 0.34070796 | ... O6: =O5/COSEIDIcam -> 0.2079646 | P6: 0 | Q6: 0 | R6: 0 | S6: 0 | T6: 0 | U6: 0 | V6: 0 | W6: 0 | X6: 0 | Y6: 0 | Z6: 0 | AA6: 0 | AB6: 0 | AC6: 0 | AD6: 0 | AE6: 0 | AF6: 0 | AG6: 0 | AH6: 0 | AI6: 0 | AJ6: 0

Sheet paradas
C1: TOTAL PARADAS | D1: =COUNTIFS(A5:A602,"=paradas seguras")/2 -> 0 | E1: TOTAL DE CAMARAS EN PARADAS | H1: =COUNTIFS(A5:A602,"=paradas seguras") -> 0 | I1: TOTAL DE CAMARAS | K1: =COUNTIFS(D5:D602,"=GFIJA") -> 0 | L1: TOTAL DE INTERCOMUNICADORES | O1: =COUNTIFS(D5:D602,"=INTERCOMUNICADOR") -> 0
E2: FIJAS | F2: =COUNTIFS(F4:F601, "=APAGADO",D4:D601,"=GFIJA") -> 0 | G2: =COUNTIFS(G4:G601, "=APAGADO",D4:D601,"=GFIJA") -> 0 | H2: =COUNTIFS(H4:H601, "=APAGADO",D4:D601,"=GFIJA") -> 0 | I2: =COUNTIFS(I4:I601, "=APAGADO",D4:D601,"=GFIJA") -> 0 | J2: =COUNTIFS(J4:J601, "=APAGADO",D4:D601,"=GFIJA") -> 0 | K2: =COUNTIFS(K4:K601, "=APAGADO",D4:D601,"=GFIJA") -> 0 | L2: =COUNTIFS(L4:L601, "=APAGADO",D4:D601,"=GFIJA") -> 0 | M2: =COUNTIFS(M4:M601, "=APAGADO",D4:D601,"=GFIJA") -> 0 | N2: =COUNTIFS(N4:N601, "=APAGADO",D4:D601,"=GFIJA") -> 0 | O2: =COUNTIFS(O4:O601, "=APAGADO",D4:D601,"=GFIJA") -> 0 | P2: =COUNTIFS(P4:P601, "=APAGADO",D4:D601,"=GFIJA") -> 0 | Q2: =COUNTIFS(Q4:Q601, "=APAGADO",D4:D601,"=GFIJA") -> 0 | R2: =COUNTIFS(R4:R601, "=APAGADO",D4:D601,"=GFIJA") -> 0 | S2: =COUNTIFS(S4:S601, "=APAGADO",D4:D601,"=GFIJA") -> 0 | T2: =COUNTIFS(T4:T601, "=APAGADO",D4:D601,"=GFIJA") -> 0 | U2: =COUNTIFS(U4:U601, "=APAGADO",D4:D601,"=GFIJA") -> 0 | V2: =COUNTIFS(V4:V601, "=APAGADO",D4:D601,"=GFIJA") -> 0 | W2: =COUNTIFS(W4:W601, "=APAGADO",D4:D601,"=GFIJA") -> 0 | X2: =COUNTIFS(X4:X601, "=APAGADO",D4:D601,"=GFIJA") -> 0 | Y2: =COUNTIFS(Y4:Y601, "=APAGADO",D4:D601,"=GFIJA") -> 0 | Z2: =COUNTIFS(Z4:Z601, "=APAGADO",D4:D601,"=GFIJA") -> 0 | AA2: =COUNTIFS(AA4:AA601, "=APAGADO",D4:D601,"=GFIJA") -> 0 | AB2: =COUNTIFS(AB4:AB601, "=APAGADO",D4:D601,"=GFIJA") -> 0 | AC2: =COUNTIFS(AC4:AC601, "=APAGADO",D4:D601,"=GFIJA") -> 0 | AD2: =COUNTIFS(AD4:AD601, "=APAGADO",D4:D601,"=GFIJA") -> 0 | AE2: =COUNTIFS(AE4:AE601, "=APAGADO",D4:D601,"=GFIJA") -> 0 | AF2: =COUNTIFS(AF4:AF601, "=APAGADO",D4:D601,"=GFIJA") -> 0 | AG2: =COUNTIFS(AG4:AG601, "=APAGADO",D4:D601,"=GFIJA") -> 0 | AH2: =COUNTIFS(AH4:AH601, "=APAGADO",D4:D601,"=GFIJA") -> 0 | AI2: =COUNTIFS(AI4:AI601, "=APAGADO",D4:D601,"=GFIJA") -> 0 | AJ2: =COUNTIFS(AJ4:AJ601, "=APAGADO",E4:E601,"=GFIJA") -> 0
E3: INTERCOMUNICADOR | F3: =COUNTIFS(F6:F603, "=APAGADO",D4:D601,"=INTERCOMUNICADOR") -> 0 | G3: =COUNTIFS(G6:G603, "=APAGADO",D4:D601,"=INTERCOMUNICADOR") -> 0 | H3: =COUNTIFS(H6:H603, "=APAGADO",D4:D601,"=INTERCOMUNICADOR") -> 0 | I3: =COUNTIFS(I6:I603, "=APAGADO",D4:D601,"=INTERCOMUNICADOR") -> 0 | J3: =COUNTIFS(J6:J603, "=APAGADO",D4:D601,"=INTERCOMUNICADOR") -> 0 | K3: =COUNTIFS(K6:K603, "=APAGADO",D4:D601,"=INTERCOMUNICADOR") -> 0 | L3: =COUNTIFS(L6:L603, "=APAGADO",D4:D601,"=INTERCOMUNICADOR") -> 0 | M3: =COUNTIFS(M6:M603, "=APAGADO",D4:D601,"=INTERCOMUNICADOR") -> 0 | N3: =COUNTIFS(N6:N603, "=APAGADO",D4:D601,"=INTERCOMUNICADOR") -> 0 | O3: =COUNTIFS(O6:O603, "=APAGADO",D4:D601,"=INTERCOMUNICADOR") -> 0 | P3: =COUNTIFS(P6:P603, "=APAGADO",D4:D601,"=INTERCOMUNICADOR") -> 0 | Q3: =COUNTIFS(Q6:Q603, "=APAGADO",D4:D601,"=INTERCOMUNICADOR") -> 0 | R3: =COUNTIFS(R6:R603, "=APAGADO",D4:D601,"=INTERCOMUNICADOR") -> 0 | S3: =COUNTIFS(S6:S603, "=APAGADO",D4:D601,"=INTERCOMUNICADOR") -> 0 | T3: =COUNTIFS(T6:T603, "=APAGADO",D4:D601,"=INTERCOMUNICADOR") -> 0 | U3: =COUNTIFS(U6:U603, "=APAGADO",D4:D601,"=INTERCOMUNICADOR") -> 0 | V3: =COUNTIFS(V6:V603, "=APAGADO",D4:D601,"=INTERCOMUNICADOR") -> 0 | W3: =COUNTIFS(W6:W603, "=APAGADO",D4:D601,"=INTERCOMUNICADOR") -> 0 | X3: =COUNTIFS(X6:X603, "=APAGADO",D4:D601,"=INTERCOMUNICADOR") -> 0 | Y3: =COUNTIFS(Y6:Y603, "=APAGADO",D4:D601,"=INTERCOMUNICADOR") -> 0 | Z3: =COUNTIFS(Z6:Z603, "=APAGADO",D4:D601,"=INTERCOMUNICADOR") -> 0 | AA3: =COUNTIFS(AA6:AA603, "=APAGADO",D4:D601,"=INTERCOMUNICADOR") -> 0 | AB3: =COUNTIFS(AB6:AB603, "=APAGADO",D4:D601,"=INTERCOMUNICADOR") -> 0 | AC3: =COUNTIFS(AC6:AC603, "=APAGADO",D4:D601,"=INTERCOMUNICADOR") -> 0 | AD3: =COUNTIFS(AD6:AD603, "=APAGADO",D4:D601,"=INTERCOMUNICADOR") -> 0 | AE3: =COUNTIFS(AE6:AE603, "=APAGADO",D4:D601,"=INTERCOMUNICADOR") -> 0 | AF3: =COUNTIFS(AF6:AF603, "=APAGADO",D4:D601,"=INTERCOMUNICADOR") -> 0 | AG3: =COUNTIFS(AG6:AG603, "=APAGADO",D4:D601,"=INTERCOMUNICADOR") -> 0 | AH3: =COUNTIFS(AH6:AH603, "=APAGADO",D4:D601,"=INTERCOMUNICADOR") -> 0 | AI3: =COUNTIFS(AI6:AI603, "=APAGADO",D4:D601,"=INTERCOMUNICADOR") -> 0 | AJ3: =COUNTIFS(AJ6:AJ603, "=APAGADO",E4:E601,"=INTERCOMUNICADOR") -> 0
A4: ='RESUMEN TOTAL'!A7 -> Barrio | B4: ='RESUMEN TOTAL'!B7 -> [Denominacion] | C4: ='RESUMEN TOTAL'!D7 -> [Ubicacion] | D4: ='RESUMEN TOTAL'!E7 -> [Tipo de Camara] | E4: ='RESUMEN TOTAL'!F7 -> [Tipo de Conexion] | F4: ='RESUMEN TOTAL'!L7 -> 45839 | G4: ='RESUMEN TOTAL'!M7 -> 45840 | H4: ='RESUMEN TOTAL'!N7 -> 45841 | I4: ='RESUMEN TOTAL'!O7 -> 45842 | J4: ='RESUMEN TOTAL'!P7 -> 45843 | K4: ='RESUMEN TOTAL'!Q7 -> 45844 | L4: ='RESUMEN TOTAL'!R7 -> 45845 | M4: ='RESUMEN TOTAL'!S7 -> 45846 | ... AJ4: ='RESUMEN TOTAL'!AP7 -> 45869 | XFC4: =SUM(F4:XFB4) -> 1421474
A5: ='RESUMEN TOTAL'!A8 -> ALTAMIRA | B5: ='RESUMEN TOTAL'!B8 -> ALT01 | C5: ='RESUMEN TOTAL'!D8 -> Calchaqui y Sgto. Cabral | D5: ='RESUMEN TOTAL'!E8 -> Domo | E5: ='RESUMEN TOTAL'!F8 -> Fibra Optica | F5: ='RESUMEN TOTAL'!L8 -> 0 | G5: ='RESUMEN TOTAL'!M8 -> 0 | H5: ='RESUMEN TOTAL'!N8 -> 0 | I5: ='RESUMEN TOTAL'!O8 -> 0 | J5: ='RESUMEN TOTAL'!P8 -> 0 | K5: ='RESUMEN TOTAL'!Q8 -> 0 | L5: ='RESUMEN TOTAL'!R8 -> 0 | M5: ='RESUMEN TOTAL'!S8 -> 0 | ... AJ5: ='RESUMEN TOTAL'!AP8 -> 0
A6: ='RESUMEN TOTAL'!A9 -> ALTAMIRA | B6: ='RESUMEN TOTAL'!B9 -> ALT02 | C6: ='RESUMEN TOTAL'!D9 -> Calchaqui y Lope de Vega | D6: ='RESUMEN TOTAL'!E9 -> Domo | E6: ='RESUMEN TOTAL'!F9 -> PTO A FO | F6: ='RESUMEN TOTAL'!L9 -> 0 | G6: ='RESUMEN TOTAL'!M9 -> 0 | H6: ='RESUMEN TOTAL'!N9 -> 0 | I6: ='RESUMEN TOTAL'!O9 -> 0 | J6: ='RESUMEN TOTAL'!P9 -> 0 | K6: ='RESUMEN TOTAL'!Q9 -> 0 | L6: ='RESUMEN TOTAL'!R9 -> 0 | M6: ='RESUMEN TOTAL'!S9 -> 0 | ... AJ6: ='RESUMEN TOTAL'!AP9 -> 0
A7: ='RESUMEN TOTAL'!A10 -> ALTAMIRA | B7: ='RESUMEN TOTAL'!B10 -> ALT 03 | C7: ='RESUMEN TOTAL'!D10 -> Bombero Galarza y Necochea | D7: ='RESUMEN TOTAL'!E10 -> Domo | E7: ='RESUMEN TOTAL'!F10 -> Fibra Optica | F7: ='RESUMEN TOTAL'!L10 -> 0 | G7: ='RESUMEN TOTAL'!M10 -> APAGADO | H7: ='RESUMEN TOTAL'!N10 -> APAGADO | I7: ='RESUMEN TOTAL'!O10 -> APAGADO | J7: ='RESUMEN TOTAL'!P10 -> 0 | K7: ='RESUMEN TOTAL'!Q10 -> 0 | L7: ='RESUMEN TOTAL'!R10 -> 0 | M7: ='RESUMEN TOTAL'!S10 -> 0 | ... AJ7: ='RESUMEN TOTAL'!AP10 -> 0
A8: ='RESUMEN TOTAL'!A11 -> ALTAMIRA | B8: ='RESUMEN TOTAL'!B11 -> ALT 04 | C8: ='RESUMEN TOTAL'!D11 -> Francia y Necochea | D8: ='RESUMEN TOTAL'!E11 -> Domo | E8: ='RESUMEN TOTAL'!F11 -> Fibra Optica | F8: ='RESUMEN TOTAL'!L11 -> 0 | G8: ='RESUMEN TOTAL'!M11 -> 0 | H8: ='RESUMEN TOTAL'!N11 -> 0 | I8: ='RESUMEN TOTAL'!O11 -> APAGADO | J8: ='RESUMEN TOTAL'!P11 -> APAGADO | K8: ='RESUMEN TOTAL'!Q11 -> 0 | L8: ='RESUMEN TOTAL'!R11 -> APAGADO | M8: ='RESUMEN TOTAL'!S11 -> APAGADO | ... AJ8: ='RESUMEN TOTAL'!AP11 -> 0
A9: ='RESUMEN TOTAL'!A12 -> ALTAMIRA | B9: ='RESUMEN TOTAL'!B12 -> ALT05 | C9: ='RESUMEN TOTAL'!D12 -> Av. Calchaqui y Bombero Galarza | D9: ='RESUMEN TOTAL'!E12 -> Domo | E9: ='RESUMEN TOTAL'!F12 -> PTO A FO | F9: ='RESUMEN TOTAL'!L12 -> 0 | G9: ='RESUMEN TOTAL'!M12 -> 0 | H9: ='RESUMEN TOTAL'!N12 -> 0 | I9: ='RESUMEN TOTAL'!O12 -> 0 | J9: ='RESUMEN TOTAL'!P12 -> 0 | K9: ='RESUMEN TOTAL'!Q12 -> 0 | L9: ='RESUMEN TOTAL'!R12 -> 0 | M9: ='RESUMEN TOTAL'!S12 -> 0 | ... AJ9: ='RESUMEN TOTAL'!AP12 -> 0
A10: ='RESUMEN TOTAL'!A13 -> ALTAMIRA | B10: ='RESUMEN TOTAL'!B13 -> ALT 06 | C10: ='RESUMEN TOTAL'!D13 -> LOPE DE VEGA Y NECOCHEA | D10: ='RESUMEN TOTAL'!E13 -> Domo | E10: ='RESUMEN TOTAL'!F13 -> PTO A FO | F10: ='RESUMEN TOTAL'!L13 -> 0 | G10: ='RESUMEN TOTAL'!M13 -> 0 | H10: ='RESUMEN TOTAL'!N13 -> 0 | I10: ='RESUMEN TOTAL'!O13 -> 0 | J10: ='RESUMEN TOTAL'!P13 -> 0 | K10: ='RESUMEN TOTAL'!Q13 -> 0 | L10: ='RESUMEN TOTAL'!R13 -> 0 | M10: ='RESUMEN TOTAL'!S13 -> 0 | ... AJ10: ='RESUMEN TOTAL'!AP13 -> 0
A11: ='RESUMEN TOTAL'!A14 -> ALTAMIRA | B11: ='RESUMEN TOTAL'!B14 -> ALT07 | C11: ='RESUMEN TOTAL'!D14 -> AV. CALCHAQUI Y AV. DEL TRABAJO | D11: ='RESUMEN TOTAL'!E14 -> DOMO | E11: ='RESUMEN TOTAL'!F14 -> PTO A FO | F11: ='RESUMEN TOTAL'!L14 -> 0 | G11: ='RESUMEN TOTAL'!M14 -> 0 | H11: ='RESUMEN TOTAL'!N14 -> 0 | I11: ='RESUMEN TOTAL'!O14 -> 0 | J11: ='RESUMEN TOTAL'!P14 -> 0 | K11: ='RESUMEN TOTAL'!Q14 -> 0 | L11: ='RESUMEN TOTAL'!R14 -> 0 | M11: ='RESUMEN TOTAL'!S14 -> 0 | ... AJ11: ='RESUMEN TOTAL'!AP14 -> 0
A12: ='RESUMEN TOTAL'!A15 -> ALTAMIRA | B12: ='RESUMEN TOTAL'!B15 -> ALT 08 | C12: ='RESUMEN TOTAL'!D15 -> HUMAITA Y NECOCHEA | D12: ='RESUMEN TOTAL'!E15 -> DOMO | E12: ='RESUMEN TOTAL'!F15 -> Fibra Optica | F12: ='RESUMEN TOTAL'!L15 -> 0 | G12: ='RESUMEN TOTAL'!M15 -> 0 | H12: ='RESUMEN TOTAL'!N15 -> 0 | I12: ='RESUMEN TOTAL'!O15 -> 0 | J12: ='RESUMEN TOTAL'!P15 -> 0 | K12: ='RESUMEN TOTAL'!Q15 -> 0 | L12: ='RESUMEN TOTAL'!R15 -> 0 | M12: ='RESUMEN TOTAL'!S15 -> 0 | ... AJ12: ='RESUMEN TOTAL'!AP15 -> 0
A13: ='RESUMEN TOTAL'!A16 -> ALTAMIRA | B13: ='RESUMEN TOTAL'!B16 -> ALT 09 | C13: ='RESUMEN TOTAL'!D16 -> NECOCHEA Y CURUPAITY | D13: ='RESUMEN TOTAL'!E16 -> DOMO | E13: ='RESUMEN TOTAL'!F16 -> Fibra Optica | F13: ='RESUMEN TOTAL'!L16 -> 0 | G13: ='RESUMEN TOTAL'!M16 -> 0 | H13: ='RESUMEN TOTAL'!N16 -> 0 | I13: ='RESUMEN TOTAL'!O16 -> 0 | J13: ='RESUMEN TOTAL'!P16 -> 0 | K13: ='RESUMEN TOTAL'!Q16 -> 0 | L13: ='RESUMEN TOTAL'!R16 -> 0 | M13: ='RESUMEN TOTAL'!S16 -> 0 | ... AJ13: ='RESUMEN TOTAL'!AP16 -> 0
A14: ='RESUMEN TOTAL'!A17 -> ALTAMIRA | B14: ='RESUMEN TOTAL'!B17 -> ALT 10 | C14: ='RESUMEN TOTAL'!D17 -> Calchaqui y Francia | D14: ='RESUMEN TOTAL'!E17 -> Domo | E14: ='RESUMEN TOTAL'!F17 -> Radio | F14: ='RESUMEN TOTAL'!L17 -> 0 | G14: ='RESUMEN TOTAL'!M17 -> 0 | H14: ='RESUMEN TOTAL'!N17 -> 0 | I14: ='RESUMEN TOTAL'!O17 -> 0 | J14: ='RESUMEN TOTAL'!P17 -> 0 | K14: ='RESUMEN TOTAL'!Q17 -> 0 | L14: ='RESUMEN TOTAL'!R17 -> 0 | M14: ='RESUMEN TOTAL'!S17 -> 0 | ... AJ14: ='RESUMEN TOTAL'!AP17 -> 0
A15: ='RESUMEN TOTAL'!A18 -> ALTAMIRA | B15: ='RESUMEN TOTAL'!B18 -> ALT 11 | C15: CALCHAQUÍ Y GALARZA FIJA | D15: ='RESUMEN TOTAL'!E18 -> Fija | F15: ='RESUMEN TOTAL'!L18 -> 0 | G15: ='RESUMEN TOTAL'!M18 -> 0 | H15: ='RESUMEN TOTAL'!N18 -> 0 | I15: ='RESUMEN TOTAL'!O18 -> 0 | J15: ='RESUMEN TOTAL'!P18 -> 0 | K15: ='RESUMEN TOTAL'!Q18 -> 0 | L15: ='RESUMEN TOTAL'!R18 -> 0 | M15: ='RESUMEN TOTAL'!S18 -> 0 | ... AJ15: ='RESUMEN TOTAL'!AP18 -> 0
A16: ='RESUMEN TOTAL'!A19 -> AGUSTIN RAMIREZ | B16: ='RESUMEN TOTAL'!B19 -> ARA 01 | C16: ='RESUMEN TOTAL'!D19 -> Malambo y Tranquera | D16: ='RESUMEN TOTAL'!E19 -> Domo | E16: ='RESUMEN TOTAL'!F19 -> Fibra Optica | F16: ='RESUMEN TOTAL'!L19 -> 0 | G16: ='RESUMEN TOTAL'!M19 -> 0 | H16: ='RESUMEN TOTAL'!N19 -> 0 | I16: ='RESUMEN TOTAL'!O19 -> 0 | J16: ='RESUMEN TOTAL'!P19 -> 0 | K16: ='RESUMEN TOTAL'!Q19 -> 0 | L16: ='RESUMEN TOTAL'!R19 -> 0 | M16: ='RESUMEN TOTAL'!S19 -> 0 | ... AJ16: ='RESUMEN TOTAL'!AP19 -> 0
A17: ='RESUMEN TOTAL'!A20 -> BELGRANO | B17: ='RESUMEN TOTAL'!B20 -> BEL 01 | C17: ='RESUMEN TOTAL'!D20 -> San Martin y Dardo Rocha | D17: ='RESUMEN TOTAL'!E20 -> DOMO | E17: ='RESUMEN TOTAL'!F20 -> Fibra Optica | F17: ='RESUMEN TOTAL'!L20 -> 0 | G17: ='RESUMEN TOTAL'!M20 -> 0 | H17: ='RESUMEN TOTAL'!N20 -> 0 | I17: ='RESUMEN TOTAL'!O20 -> 0 | J17: ='RESUMEN TOTAL'!P20 -> 0 | K17: ='RESUMEN TOTAL'!Q20 -> 0 | L17: ='RESUMEN TOTAL'!R20 -> 0 | M17: ='RESUMEN TOTAL'!S20 -> 0 | ... AJ17: ='RESUMEN TOTAL'!AP20 -> 0
A18: ='RESUMEN TOTAL'!A21 -> BELGRANO | B18: ='RESUMEN TOTAL'!B21 -> BEL 02 | C18: ='RESUMEN TOTAL'!D21 -> Guardia vieja y Fronteriz | D18: ='RESUMEN TOTAL'!E21 -> DOMO | E18: ='RESUMEN TOTAL'!F21 -> Fibra Optica | F18: ='RESUMEN TOTAL'!L21 -> 0 | G18: ='RESUMEN TOTAL'!M21 -> 0 | H18: ='RESUMEN TOTAL'!N21 -> 0 | I18: ='RESUMEN TOTAL'!O21 -> 0 | J18: ='RESUMEN TOTAL'!P21 -> 0 | K18: ='RESUMEN TOTAL'!Q21 -> 0 | L18: ='RESUMEN TOTAL'!R21 -> 0 | M18: ='RESUMEN TOTAL'!S21 -> 0 | ... AJ18: ='RESUMEN TOTAL'!AP21 -> 0
A19: ='RESUMEN TOTAL'!A22 -> BOSQUES CENTRO | B19: ='RESUMEN TOTAL'!B22 -> BOSQC 01 | C19: ='RESUMEN TOTAL'!D22 -> LUIS AGOTE E/DANUNCIO Y CAMPOAMOR | D19: ='RESUMEN TOTAL'!E22 -> Fija | E19: ='RESUMEN TOTAL'!F22 -> Radio | F19: ='RESUMEN TOTAL'!L22 -> APAGADO | G19: ='RESUMEN TOTAL'!M22 -> APAGADO | H19: ='RESUMEN TOTAL'!N22 -> APAGADO | I19: ='RESUMEN TOTAL'!O22 -> APAGADO | J19: ='RESUMEN TOTAL'!P22 -> APAGADO | K19: ='RESUMEN TOTAL'!Q22 -> APAGADO | L19: ='RESUMEN TOTAL'!R22 -> APAGADO | M19: ='RESUMEN TOTAL'!S22 -> APAGADO | ... AJ19: ='RESUMEN TOTAL'!AP22 -> 0
A20: ='RESUMEN TOTAL'!A23 -> BOSQUES CENTRO | B20: ='RESUMEN TOTAL'!B23 -> BOSQC 02 | C20: ='RESUMEN TOTAL'!D23 -> LUIS AGOTE E/DANUNCIO Y CAMPOAMOR | D20: ='RESUMEN TOTAL'!E23 -> Fija | E20: ='RESUMEN TOTAL'!F23 -> Radio | F20: ='RESUMEN TOTAL'!L23 -> APAGADO | G20: ='RESUMEN TOTAL'!M23 -> APAGADO | H20: ='RESUMEN TOTAL'!N23 -> APAGADO | I20: ='RESUMEN TOTAL'!O23 -> APAGADO | J20: ='RESUMEN TOTAL'!P23 -> APAGADO | K20: ='RESUMEN TOTAL'!Q23 -> APAGADO | L20: ='RESUMEN TOTAL'!R23 -> APAGADO | M20: ='RESUMEN TOTAL'!S23 -> APAGADO | ... AJ20: ='RESUMEN TOTAL'!AP23 -> 0
A21: ='RESUMEN TOTAL'!A24 -> BOSQUES CENTRO | B21: ='RESUMEN TOTAL'!B24 -> BOSQC 03 | C21: ='RESUMEN TOTAL'!D24 -> BENAVENTE Y LUIS AGOTE | D21: ='RESUMEN TOTAL'!E24 -> Fija | E21: ='RESUMEN TOTAL'!F24 -> Radio | F21: ='RESUMEN TOTAL'!L24 -> APAGADO | G21: ='RESUMEN TOTAL'!M24 -> APAGADO | H21: ='RESUMEN TOTAL'!N24 -> APAGADO | I21: ='RESUMEN TOTAL'!O24 -> APAGADO | J21: ='RESUMEN TOTAL'!P24 -> APAGADO | K21: ='RESUMEN TOTAL'!Q24 -> APAGADO | L21: ='RESUMEN TOTAL'!R24 -> APAGADO | M21: ='RESUMEN TOTAL'!S24 -> APAGADO | ... AJ21: ='RESUMEN TOTAL'!AP24 -> 0
A22: ='RESUMEN TOTAL'!A25 -> BOSQUES CENTRO | B22: ='RESUMEN TOTAL'!B25 -> BOSQC 04 | C22: ='RESUMEN TOTAL'!D25 -> BENAVENTE Y LUIS AGOTE | D22: ='RESUMEN TOTAL'!E25 -> Fija | E22: ='RESUMEN TOTAL'!F25 -> Radio | F22: ='RESUMEN TOTAL'!L25 -> APAGADO | G22: ='RESUMEN TOTAL'!M25 -> APAGADO | H22: ='RESUMEN TOTAL'!N25 -> APAGADO | I22: ='RESUMEN TOTAL'!O25 -> APAGADO | J22: ='RESUMEN TOTAL'!P25 -> APAGADO | K22: ='RESUMEN TOTAL'!Q25 -> APAGADO | L22: ='RESUMEN TOTAL'!R25 -> APAGADO | M22: ='RESUMEN TOTAL'!S25 -> APAGADO | ... AJ22: ='RESUMEN TOTAL'!AP25 -> 0
A23: ='RESUMEN TOTAL'!A26 -> BOSQUES CENTRO | B23: ='RESUMEN TOTAL'!B26 -> BOSQC 05 | C23: ='RESUMEN TOTAL'!D26 -> LUIS AGOTE Y RUTA 36 | D23: ='RESUMEN TOTAL'!E26 -> Fija | E23: ='RESUMEN TOTAL'!F26 -> Radio | F23: ='RESUMEN TOTAL'!L26 -> 0 | G23: ='RESUMEN TOTAL'!M26 -> 0 | H23: ='RESUMEN TOTAL'!N26 -> 0 | I23: ='RESUMEN TOTAL'!O26 -> APAGADO | J23: ='RESUMEN TOTAL'!P26 -> APAGADO | K23: ='RESUMEN TOTAL'!Q26 -> APAGADO | L23: ='RESUMEN TOTAL'!R26 -> APAGADO | M23: ='RESUMEN TOTAL'!S26 -> APAGADO | ... AJ23: ='RESUMEN TOTAL'!AP26 -> 0
A24: ='RESUMEN TOTAL'!A27 -> BOSQUES CENTRO | B24: ='RESUMEN TOTAL'!B27 -> BOSQC 06 | C24: ='RESUMEN TOTAL'!D27 -> LUIS AGOTE Y RUTA 36 | D24: ='RESUMEN TOTAL'!E27 -> Fija | E24: ='RESUMEN TOTAL'!F27 -> Radio | F24: ='RESUMEN TOTAL'!L27 -> 0 | G24: ='RESUMEN TOTAL'!M27 -> 0 | H24: ='RESUMEN TOTAL'!N27 -> 0 | I24: ='RESUMEN TOTAL'!O27 -> APAGADO | J24: ='RESUMEN TOTAL'!P27 -> APAGADO | K24: ='RESUMEN TOTAL'!Q27 -> APAGADO | L24: ='RESUMEN TOTAL'!R27 -> APAGADO | M24: ='RESUMEN TOTAL'!S27 -> APAGADO | ... AJ24: ='RESUMEN TOTAL'!AP27 -> 0
A25: ='RESUMEN TOTAL'!A34 -> CENTRO | B25: ='RESUMEN TOTAL'!B34 -> CEN01 | C25: ='RESUMEN TOTAL'!D34 -> San Martin y 9 de Julio | D25: ='RESUMEN TOTAL'!E34 -> Fija | E25: ='RESUMEN TOTAL'!F34 -> Fibra Optica | F25: ='RESUMEN TOTAL'!L34 -> 0 | G25: ='RESUMEN TOTAL'!M34 -> 0 | H25: ='RESUMEN TOTAL'!N34 -> 0 | I25: ='RESUMEN TOTAL'!O34 -> 0 | J25: ='RESUMEN TOTAL'!P34 -> 0 | K25: ='RESUMEN TOTAL'!Q34 -> 0 | L25: ='RESUMEN TOTAL'!R34 -> 0 | M25: ='RESUMEN TOTAL'!S34 -> 0 | ... AJ25: ='RESUMEN TOTAL'!AP34 -> 0
A26: ='RESUMEN TOTAL'!A35 -> CENTRO | B26: ='RESUMEN TOTAL'!B35 -> CEN02 | C26: ='RESUMEN TOTAL'!D35 -> San Martin y Almafuerte | D26: ='RESUMEN TOTAL'!E35 -> Fija | E26: ='RESUMEN TOTAL'!F35 -> Fibra Optica | F26: ='RESUMEN TOTAL'!L35 -> 0 | G26: ='RESUMEN TOTAL'!M35 -> 0 | H26: ='RESUMEN TOTAL'!N35 -> 0 | I26: ='RESUMEN TOTAL'!O35 -> 0 | J26: ='RESUMEN TOTAL'!P35 -> 0 | K26: ='RESUMEN TOTAL'!Q35 -> 0 | L26: ='RESUMEN TOTAL'!R35 -> 0 | M26: ='RESUMEN TOTAL'!S35 -> 0 | ... AJ26: ='RESUMEN TOTAL'!AP35 -> 0
A27: ='RESUMEN TOTAL'!A36 -> CENTRO | B27: ='RESUMEN TOTAL'!B36 -> CEN03 | C27: ='RESUMEN TOTAL'!D36 -> San Martin y Sallares | D27: ='RESUMEN TOTAL'!E36 -> Domo | E27: ='RESUMEN TOTAL'!F36 -> Fibra Optica | F27: ='RESUMEN TOTAL'!L36 -> 0 | G27: ='RESUMEN TOTAL'!M36 -> 0 | H27: ='RESUMEN TOTAL'!N36 -> 0 | I27: ='RESUMEN TOTAL'!O36 -> 0 | J27: ='RESUMEN TOTAL'!P36 -> 0 | K27: ='RESUMEN TOTAL'!Q36 -> 0 | L27: ='RESUMEN TOTAL'!R36 -> 0 | M27: ='RESUMEN TOTAL'!S36 -> 0 | ... AJ27: ='RESUMEN TOTAL'!AP36 -> 0
A28: ='RESUMEN TOTAL'!A37 -> CENTRO | B28: ='RESUMEN TOTAL'!B37 -> CEN04 | C28: ='RESUMEN TOTAL'!D37 -> San Martin y Contreras | D28: ='RESUMEN TOTAL'!E37 -> Domo | E28: ='RESUMEN TOTAL'!F37 -> Fibra Optica | F28: ='RESUMEN TOTAL'!L37 -> 0 | G28: ='RESUMEN TOTAL'!M37 -> 0 | H28: ='RESUMEN TOTAL'!N37 -> 0 | I28: ='RESUMEN TOTAL'!O37 -> 0 | J28: ='RESUMEN TOTAL'!P37 -> 0 | K28: ='RESUMEN TOTAL'!Q37 -> 0 | L28: ='RESUMEN TOTAL'!R37 -> 0 | M28: ='RESUMEN TOTAL'!S37 -> 0 | ... AJ28: ='RESUMEN TOTAL'!AP37 -> 0
A29: ='RESUMEN TOTAL'!A38 -> CENTRO | B29: ='RESUMEN TOTAL'!B38 -> CEN 05 | C29: ='RESUMEN TOTAL'!D38 -> Bocuzzi e/España y San Martin | D29: ='RESUMEN TOTAL'!E38 -> DOMO | E29: ='RESUMEN TOTAL'!F38 -> Fibra Optica | F29: ='RESUMEN TOTAL'!L38 -> 0 | G29: ='RESUMEN TOTAL'!M38 -> 0 | H29: ='RESUMEN TOTAL'!N38 -> 0 | I29: ='RESUMEN TOTAL'!O38 -> 0 | J29: ='RESUMEN TOTAL'!P38 -> 0 | K29: ='RESUMEN TOTAL'!Q38 -> 0 | L29: ='RESUMEN TOTAL'!R38 -> 0 | M29: ='RESUMEN TOTAL'!S38 -> 0 | ... AJ29: ='RESUMEN TOTAL'!AP38 -> 0
A30: ='RESUMEN TOTAL'!A39 -> CENTRO | B30: ='RESUMEN TOTAL'!B39 -> CEN06 | C30: ='RESUMEN TOTAL'!D39 -> Monteagudo y A.del Valle | D30: ='RESUMEN TOTAL'!E39 -> Fija | E30: ='RESUMEN TOTAL'!F39 -> Fibra Optica | F30: ='RESUMEN TOTAL'!L39 -> APAGADO | G30: ='RESUMEN TOTAL'!M39 -> APAGADO | H30: ='RESUMEN TOTAL'!N39 -> APAGADO | I30: ='RESUMEN TOTAL'!O39 -> APAGADO | J30: ='RESUMEN TOTAL'!P39 -> APAGADO | K30: ='RESUMEN TOTAL'!Q39 -> APAGADO | L30: ='RESUMEN TOTAL'!R39 -> APAGADO | M30: ='RESUMEN TOTAL'!S39 -> APAGADO | ... AJ30: ='RESUMEN TOTAL'!AP39 -> 0
A31: ='RESUMEN TOTAL'!A40 -> CENTRO | B31: ='RESUMEN TOTAL'!B40 -> CEN07 | C31: ='RESUMEN TOTAL'!D40 -> San Martin y Guemes | D31: ='RESUMEN TOTAL'!E40 -> DOMO | E31: ='RESUMEN TOTAL'!F40 -> Fibra Optica | F31: ='RESUMEN TOTAL'!L40 -> 0 | G31: ='RESUMEN TOTAL'!M40 -> 0 | H31: ='RESUMEN TOTAL'!N40 -> 0 | I31: ='RESUMEN TOTAL'!O40 -> 0 | J31: ='RESUMEN TOTAL'!P40 -> 0 | K31: ='RESUMEN TOTAL'!Q40 -> 0 | L31: ='RESUMEN TOTAL'!R40 -> 0 | M31: ='RESUMEN TOTAL'!S40 -> 0 | ... AJ31: ='RESUMEN TOTAL'!AP40 -> 0
A32: ='RESUMEN TOTAL'!A41 -> CENTRO | B32: ='RESUMEN TOTAL'!B41 -> CEN08 | C32: ='RESUMEN TOTAL'!D41 -> San Martin y Pte.Peron | D32: ='RESUMEN TOTAL'!E41 -> Domo | E32: ='RESUMEN TOTAL'!F41 -> Fibra Optica | F32: ='RESUMEN TOTAL'!L41 -> 0 | G32: ='RESUMEN TOTAL'!M41 -> 0 | H32: ='RESUMEN TOTAL'!N41 -> 0 | I32: ='RESUMEN TOTAL'!O41 -> 0 | J32: ='RESUMEN TOTAL'!P41 -> 0 | K32: ='RESUMEN TOTAL'!Q41 -> 0 | L32: ='RESUMEN TOTAL'!R41 -> 0 | M32: ='RESUMEN TOTAL'!S41 -> 0 | ... AJ32: ='RESUMEN TOTAL'!AP41 -> 0
A33: ='RESUMEN TOTAL'!A42 -> CENTRO | B33: ='RESUMEN TOTAL'!B42 -> CEN09 | C33: ='RESUMEN TOTAL'!D42 -> Chacabuco y 25 de Mayo | D33: ='RESUMEN TOTAL'!E42 -> Domo | E33: ='RESUMEN TOTAL'!F42 -> Fibra Optica | F33: ='RESUMEN TOTAL'!L42 -> 0 | G33: ='RESUMEN TOTAL'!M42 -> 0 | H33: ='RESUMEN TOTAL'!N42 -> 0 | I33: ='RESUMEN TOTAL'!O42 -> 0 | J33: ='RESUMEN TOTAL'!P42 -> 0 | K33: ='RESUMEN TOTAL'!Q42 -> 0 | L33: ='RESUMEN TOTAL'!R42 -> 0 | M33: ='RESUMEN TOTAL'!S42 -> 0 | ... AJ33: ='RESUMEN TOTAL'!AP42 -> 0
A34: ='RESUMEN TOTAL'!A43 -> CENTRO | B34: ='RESUMEN TOTAL'!B43 -> CEN10 | C34: ='RESUMEN TOTAL'!D43 -> Monteagudo y Pte. Peron | D34: ='RESUMEN TOTAL'!E43 -> Domo | E34: ='RESUMEN TOTAL'!F43 -> Fibra Optica | F34: ='RESUMEN TOTAL'!L43 -> 0 | G34: ='RESUMEN TOTAL'!M43 -> 0 | H34: ='RESUMEN TOTAL'!N43 -> 0 | I34: ='RESUMEN TOTAL'!O43 -> 0 | J34: ='RESUMEN TOTAL'!P43 -> 0 | K34: ='RESUMEN TOTAL'!Q43 -> 0 | L34: ='RESUMEN TOTAL'!R43 -> 0 | M34: ='RESUMEN TOTAL'!S43 -> 0 | ... AJ34: ='RESUMEN TOTAL'!AP43 -> 0
A35: ='RESUMEN TOTAL'!A44 -> CENTRO | B35: ='RESUMEN TOTAL'!B44 -> CEN11 | C35: ='RESUMEN TOTAL'!D44 -> Monteagudo y Bocuzzi | D35: ='RESUMEN TOTAL'!E44 -> Domo | E35: ='RESUMEN TOTAL'!F44 -> Fibra Optica | F35: ='RESUMEN TOTAL'!L44 -> 0 | G35: ='RESUMEN TOTAL'!M44 -> 0 | H35: ='RESUMEN TOTAL'!N44 -> 0 | I35: ='RESUMEN TOTAL'!O44 -> 0 | J35: ='RESUMEN TOTAL'!P44 -> 0 | K35: ='RESUMEN TOTAL'!Q44 -> 0 | L35: ='RESUMEN TOTAL'!R44 -> 0 | M35: ='RESUMEN TOTAL'!S44 -> 0 | ... AJ35: ='RESUMEN TOTAL'!AP44 -> 0
A36: ='RESUMEN TOTAL'!A45 -> CENTRO | B36: ='RESUMEN TOTAL'!B45 -> CEN 12 | C36: ='RESUMEN TOTAL'!D45 -> Monteagudo y Mitre | D36: ='RESUMEN TOTAL'!E45 -> Domo | E36: ='RESUMEN TOTAL'!F45 -> Fibra Optica | F36: ='RESUMEN TOTAL'!L45 -> 0 | G36: ='RESUMEN TOTAL'!M45 -> 0 | H36: ='RESUMEN TOTAL'!N45 -> 0 | I36: ='RESUMEN TOTAL'!O45 -> 0 | J36: ='RESUMEN TOTAL'!P45 -> APAGADO | K36: ='RESUMEN TOTAL'!Q45 -> 0 | L36: ='RESUMEN TOTAL'!R45 -> APAGADO | M36: ='RESUMEN TOTAL'!S45 -> 0 | ... AJ36: ='RESUMEN TOTAL'!AP45 -> 0
... A71: ='RESUMEN TOTAL'!A80 -> CENTRO | B71: ='RESUMEN TOTAL'!B80 -> CEN47 | C71: ='RESUMEN TOTAL'!D80 -> Sallares y Brown | D71: ='RESUMEN TOTAL'!E80 -> Domo | E71: ='RESUMEN TOTAL'!F80 -> Fibra Optica | F71: ='RESUMEN TOTAL'!L80 -> 0 | G71: ='RESUMEN TOTAL'!M80 -> 0 | H71: ='RESUMEN TOTAL'!N80 -> 0 | I71: ='RESUMEN TOTAL'!O80 -> 0 | J71: ='RESUMEN TOTAL'!P80 -> 0 | K71: ='RESUMEN TOTAL'!Q80 -> 0 | L71: ='RESUMEN TOTAL'!R80 -> APAGADO | M71: ='RESUMEN TOTAL'!S80 -> 0 | ... AJ71: ='RESUMEN TOTAL'!AP80 -> 0
A72: ='RESUMEN TOTAL'!A81 -> CENTRO | B72: ='RESUMEN TOTAL'!B81 -> CEN48 | C72: ='RESUMEN TOTAL'!D81 -> Velez Sarsfield y Las Heras | D72: ='RESUMEN TOTAL'!E81 -> Domo | E72: ='RESUMEN TOTAL'!F81 -> GPON | F72: ='RESUMEN TOTAL'!L81 -> 0 | G72: ='RESUMEN TOTAL'!M81 -> 0 | H72: ='RESUMEN TOTAL'!N81 -> 0 | I72: ='RESUMEN TOTAL'!O81 -> 0 | J72: ='RESUMEN TOTAL'!P81 -> 0 | K72: ='RESUMEN TOTAL'!Q81 -> 0 | L72: ='RESUMEN TOTAL'!R81 -> 0 | M72: ='RESUMEN TOTAL'!S81 -> 0 | ... Z72: ='RESUMEN TOTAL'!AF81 -> 0 | AA72: ='RESUMEN TOTAL'!#REF! -> #REF! | AB72: ='RESUMEN TOTAL'!AH81 -> 0 | AC72: ='RESUMEN TOTAL'!AI81 -> 0 | AD72: ='RESUMEN TOTAL'!AJ81 -> 0 | AE72: ='RESUMEN TOTAL'!AK81 -> 0 | AF72: ='RESUMEN TOTAL'!AL81 -> 0 | AG72: ='RESUMEN TOTAL'!AM81 -> 0 | AH72: ='RESUMEN TOTAL'!AN81 -> 0 | AI72: ='RESUMEN TOTAL'!AO81 -> 0 | AJ72: ='RESUMEN TOTAL'!AP81 -> 0
A73: ='RESUMEN TOTAL'!A82 -> CENTRO | B73: ='RESUMEN TOTAL'!B82 -> CEN49 | C73: ='RESUMEN TOTAL'!D82 -> Av. San Martin y Florencio Sanchez | D73: ='RESUMEN TOTAL'!E82 -> Domo | E73: ='RESUMEN TOTAL'!F82 -> Fibra Optica | F73: ='RESUMEN TOTAL'!L82 -> 0 | G73: ='RESUMEN TOTAL'!M82 -> 0 | H73: ='RESUMEN TOTAL'!N82 -> 0 | I73: ='RESUMEN TOTAL'!O82 -> 0 | J73: ='RESUMEN TOTAL'!P82 -> 0 | K73: ='RESUMEN TOTAL'!Q82 -> 0 | L73: ='RESUMEN TOTAL'!R82 -> 0 | M73: ='RESUMEN TOTAL'!S82 -> 0 | ... AJ73: ='RESUMEN TOTAL'!AP82 -> 0
A74: ='RESUMEN TOTAL'!A83 -> CENTRO | B74: ='RESUMEN TOTAL'!B83 -> CEN 50 | C74: ='RESUMEN TOTAL'!D83 -> Av. San Martin y Newbery | D74: ='RESUMEN TOTAL'!E83 -> Domo | E74: ='RESUMEN TOTAL'!F83 -> Fibra Optica | F74: ='RESUMEN TOTAL'!L83 -> 0 | G74: ='RESUMEN TOTAL'!M83 -> 0 | H74: ='RESUMEN TOTAL'!N83 -> 0 | I74: ='RESUMEN TOTAL'!O83 -> 0 | J74: ='RESUMEN TOTAL'!P83 -> 0 | K74: ='RESUMEN TOTAL'!Q83 -> 0 | L74: ='RESUMEN TOTAL'!R83 -> 0 | M74: ='RESUMEN TOTAL'!S83 -> 0 | ... AJ74: ='RESUMEN TOTAL'!AP83 -> 0
...
