Workbook
Name _25_de_agosto: 'RESUMEN TOTAL'!$A$7:$D$414
Name _25_de_agosto_3: 'RESUMEN TOTAL'!$A$7:$D$426
Name _30_mar: #REF!
Name BONOMOcam: Hoja1!$B$2
Name CANTIDAD_DE_CAMARAS: 'RESUMEN TOTAL'!$B$1
Name COSEIDIcam: Hoja1!$B$4

Sheet RESUMEN TOTAL
A1: CANTIDAD DE CAMARAS | B1: =COUNTA(B8:B646) -> 485 | D1: PORCIENTO DE CAIDAS | L1: =(L3)/(L2+L3) -> 0.12612613 | M1: =(M3)/(M2+M3) -> 0.10845588 | N1: =(N3)/(N2+N3) -> 0.106814 | O1: =(O3)/(O2+O3) -> 0.11657559 | P1: =(P3)/(P2+P3) -> 0.10845588 | Q1: =(Q3)/(Q2+Q3) -> 0.098513011 | R1: =(R3)/(R2+R3) -> 0.14612676 | S1: =(S3)/(S2+S3) -> 0.12296564 | ... X1: =(X3)/(X2+X3) -> 0.11978221 | Z1: =(Z3)/(Z2+Z3) -> 0 | AA1: =(AA3)/(AA2+AA3) -> 0 | AB1: =(AB3)/(AB2+AB3) -> 0.10351201 | AC1: =(AC3)/(AC2+AC3) -> 0.12296564 | AD1: =(AD3)/(AD2+AD3) -> 0.083175803 | AE1: =(AE3)/(AE2+AE3) -> 0.12296564 | AF1: =(AF3)/(AF2+AF3) -> 0.086629002 | AG1: =(AG3)/(AG2+AG3) -> 0.13392857 | ... AO1: =(AO3)/(AO2+AO3) -> 0
D2: FUNCIONAN | L2: =CANTIDAD_DE_CAMARAS -> 485 | M2: =CANTIDAD_DE_CAMARAS -> 485 | N2: =CANTIDAD_DE_CAMARAS -> 485 | O2: =CANTIDAD_DE_CAMARAS -> 485 | P2: =CANTIDAD_DE_CAMARAS -> 485 | Q2: =CANTIDAD_DE_CAMARAS -> 485 | R2: =CANTIDAD_DE_CAMARAS -> 485 | S2: =CANTIDAD_DE_CAMARAS -> 485 | ... AO2: =CANTIDAD_DE_CAMARAS -> 485
D3: CAIDAS | L3: =COUNTIF(L7:L646, "apagado") -> 70 | M3: =COUNTIF(M7:M646, "apagado") -> 59 | N3: =COUNTIF(N7:N646, "apagado") -> 58 | O3: =COUNTIF(O7:O646, "apagado") -> 64 | P3: =COUNTIF(P7:P646, "apagado") -> 59 | Q3: =COUNTIF(Q7:Q646, "apagado") -> 53 | R3: =COUNTIF(R7:R646, "apagado") -> 83 | S3: =COUNTIF(S7:S646, "apagado") -> 68 | ... AO3: =COUNTIF(AO7:AO646, "apagado") -> 0
D4: APAGADOS FIBRA | L4: =COUNTIFS(L8:L600, "=APAGADO",F8:F600,"=Fibra Optica") -> 42 | M4: =COUNTIFS(M8:M600, "=APAGADO",F8:F600,"=Fibra Optica") -> 36 | N4: =COUNTIFS(N8:N600, "=APAGADO",F8:F600,"=Fibra Optica") -> 35 | O4: =COUNTIFS(O8:O600, "=APAGADO",F8:F600,"=Fibra Optica") -> 44 | P4: =COUNTIFS(P8:P600, "=APAGADO",F8:F600,"=Fibra Optica") -> 35 | Q4: =COUNTIFS(Q8:Q600, "=APAGADO",F8:F600,"=Fibra Optica") -> 30 | R4: =COUNTIFS(R8:R600, "=APAGADO",F8:F600,"=Fibra Optica") -> 63 | S4: =COUNTIFS(S8:S600, "=APAGADO",F8:F600,"=Fibra Optica") -> 48 | T4: =COUNTIFS(T8:T600, "=APAGADO",F8:F600,"=Fibra Optica") -> 50 | U4: =COUNTIFS(U8:U600, "=APAGADO",F8:F600,"=Fibra Optica") -> 54 | V4: =COUNTIFS(V8:V600, "=APAGADO",F8:F600,"=Fibra Optica") -> 42 | W4: =COUNTIFS(W8:W600, "=APAGADO",F8:F600,"=Fibra Optica") -> 39 | X4: =COUNTIFS(X8:X600, "=APAGADO",F8:F600,"=Fibra Optica") -> 40 | Y4: =COUNTIFS(Y8:Y600, "=APAGADO",F8:F600,"=Fibra Optica") -> 0 | Z4: =COUNTIFS(Z8:Z600, "=APAGADO",F8:F600,"=Fibra Optica") -> 0 | AA4: =COUNTIFS(AA8:AA600, "=APAGADO",F8:F600,"=Fibra Optica") -> 0 | AB4: =COUNTIFS(AB8:AB600, "=APAGADO",F8:F600,"=Fibra Optica") -> 29 | AC4: =COUNTIFS(AC8:AC600, "=APAGADO",F8:F600,"=Fibra Optica") -> 47 | AD4: =COUNTIFS(AD8:AD600, "=APAGADO",F8:F600,"=Fibra Optica") -> 28 | AE4: =COUNTIFS(AE8:AE600, "=APAGADO",F8:F600,"=Fibra Optica") -> 52 | AF4: =COUNTIFS(AF8:AF600, "=APAGADO",F8:F600,"=Fibra Optica") -> 29 | AG4: =COUNTIFS(AG8:AG600, "=APAGADO",F8:F600,"=Fibra Optica") -> 56 | AH4: =COUNTIFS(AH8:AH600, "=APAGADO",F8:F600,"=Fibra Optica") -> 64 | AI4: =COUNTIFS(AI8:AI600, "=APAGADO",F8:F600,"=Fibra Optica") -> 0 | AJ4: =COUNTIFS(AJ8:AJ600, "=APAGADO",F8:F600,"=Fibra Optica") -> 0 | AK4: =COUNTIFS(AK8:AK600, "=APAGADO",F8:F600,"=Fibra Optica") -> 0 | AL4: =COUNTIFS(AL8:AL600, "=APAGADO",F8:F600,"=Fibra Optica") -> 0 | AM4: =COUNTIFS(AM8:AM600, "=APAGADO",F8:F600,"=Fibra Optica") -> 0 | AN4: =COUNTIFS(AN8:AN600, "=APAGADO",F8:F600,"=Fibra Optica") -> 0 | AO4: =COUNTIFS(AO8:AO600, "=APAGADO",F8:F600,"=Fibra Optica") -> 0
D5: APAGADOS RADIO | L5: =COUNTIFS(L8:L600, "=APAGADO",F8:F600,"=RADIO") -> 15 | M5: =COUNTIFS(M8:M600, "=APAGADO",F8:F600,"=RADIO") -> 13 | N5: =COUNTIFS(N8:N600, "=APAGADO",F8:F600,"=RADIO") -> 14 | O5: =COUNTIFS(O8:O600, "=APAGADO",F8:F600,"=RADIO") -> 11 | P5: =COUNTIFS(P8:P600, "=APAGADO",F8:F600,"=RADIO") -> 15 | Q5: =COUNTIFS(Q8:Q600, "=APAGADO",F8:F600,"=RADIO") -> 13 | R5: =COUNTIFS(R8:R600, "=APAGADO",F8:F600,"=RADIO") -> 11 | S5: =COUNTIFS(S8:S600, "=APAGADO",F8:F600,"=RADIO") -> 11 | T5: =COUNTIFS(T8:T600, "=APAGADO",F8:F600,"=RADIO") -> 12 | U5: =COUNTIFS(U8:U600, "=APAGADO",F8:F600,"=RADIO") -> 16 | V5: =COUNTIFS(V8:V600, "=APAGADO",F8:F600,"=RADIO") -> 12 | W5: =COUNTIFS(W8:W600, "=APAGADO",F8:F600,"=RADIO") -> 14 | X5: =COUNTIFS(X8:X600, "=APAGADO",F8:F600,"=RADIO") -> 15 | Y5: =COUNTIFS(Y8:Y600, "=APAGADO",F8:F600,"=RADIO") -> 0 | Z5: =COUNTIFS(Z8:Z600, "=APAGADO",F8:F600,"=RADIO") -> 0 | AA5: =COUNTIFS(AA8:AA600, "=APAGADO",F8:F600,"=RADIO") -> 0 | AB5: =COUNTIFS(AB8:AB600, "=APAGADO",F8:F600,"=RADIO") -> 19 | AC5: =COUNTIFS(AC8:AC600, "=APAGADO",F8:F600,"=RADIO") -> 14 | AD5: =COUNTIFS(AD8:AD600, "=APAGADO",F8:F600,"=RADIO") -> 10 | AE5: =COUNTIFS(AE8:AE600, "=APAGADO",F8:F600,"=RADIO") -> 9 | AF5: =COUNTIFS(AF8:AF600, "=APAGADO",F8:F600,"=RADIO") -> 10 | AG5: =COUNTIFS(AG8:AG600, "=APAGADO",F8:F600,"=RADIO") -> 9 | AH5: =COUNTIFS(AH8:AH600, "=APAGADO",F8:F600,"=RADIO") -> 10 | AI5: =COUNTIFS(AI8:AI600, "=APAGADO",F8:F600,"=RADIO") -> 0 | AJ5: =COUNTIFS(AJ8:AJ600, "=APAGADO",F8:F600,"=RADIO") -> 0 | AK5: =COUNTIFS(AK8:AK600, "=APAGADO",F8:F600,"=RADIO") -> 0 | AL5: =COUNTIFS(AL8:AL600, "=APAGADO",F8:F600,"=RADIO") -> 0 | AM5: =COUNTIFS(AM8:AM600, "=APAGADO",F8:F600,"=RADIO") -> 0 | AN5: =COUNTIFS(AN8:AN600, "=APAGADO",F8:F600,"=RADIO") -> 0 | AO5: =COUNTIFS(AO8:AO600, "=APAGADO",F8:F600,"=RADIO") -> 0
D6: APAGADOS ANTENA | L6: =COUNTIFS(L8:L600, "=APAGADO",F8:F600,"=PTO A FO") -> 12 | M6: =COUNTIFS(M8:M600, "=APAGADO",F8:F600,"=PTO A FO") -> 9 | N6: =COUNTIFS(N8:N600, "=APAGADO",F8:F600,"=PTO A FO") -> 8 | O6: =COUNTIFS(O8:O600, "=APAGADO",F8:F600,"=PTO A FO") -> 8 | P6: =COUNTIFS(P8:P600, "=APAGADO",F8:F600,"=PTO A FO") -> 8 | Q6: =COUNTIFS(Q8:Q600, "=APAGADO",F8:F600,"=PTO A FO") -> 8 | R6: =COUNTIFS(R8:R600, "=APAGADO",F8:F600,"=PTO A FO") -> 8 | S6: =COUNTIFS(S8:S600, "=APAGADO",F8:F600,"=PTO A FO") -> 8 | T6: =COUNTIFS(T8:T600, "=APAGADO",F8:F600,"=PTO A FO") -> 7 | U6: =COUNTIFS(U8:U600, "=APAGADO",F8:F600,"=PTO A FO") -> 7 | V6: =COUNTIFS(V8:V600, "=APAGADO",F8:F600,"=PTO A FO") -> 6 | W6: =COUNTIFS(W8:W600, "=APAGADO",F8:F600,"=PTO A FO") -> 8 | X6: =COUNTIFS(X8:X600, "=APAGADO",F8:F600,"=PTO A FO") -> 10 | Y6: =COUNTIFS(Y8:Y600, "=APAGADO",F8:F600,"=PTO A FO") -> 0 | Z6: =COUNTIFS(Z8:Z600, "=APAGADO",F8:F600,"=PTO A FO") -> 0 | AA6: =COUNTIFS(AA8:AA600, "=APAGADO",F8:F600,"=PTO A FO") -> 0 | AB6: =COUNTIFS(AB8:AB600, "=APAGADO",F8:F600,"=PTO A FO") -> 7 | AC6: =COUNTIFS(AC8:AC600, "=APAGADO",F8:F600,"=PTO A FO") -> 6 | AD6: =COUNTIFS(AD8:AD600, "=APAGADO",F8:F600,"=PTO A FO") -> 6 | AE6: =COUNTIFS(AE8:AE600, "=APAGADO",F8:F600,"=PTO A FO") -> 7 | AF6: =COUNTIFS(AF8:AF600, "=APAGADO",F8:F600,"=PTO A FO") -> 6 | AG6: =COUNTIFS(AG8:AG600, "=APAGADO",F8:F600,"=PTO A FO") -> 9 | AH6: =COUNTIFS(AH8:AH600, "=APAGADO",F8:F600,"=PTO A FO") -> 13 | AI6: =COUNTIFS(AI8:AI600, "=APAGADO",F8:F600,"=PTO A FO") -> 0 | AJ6: =COUNTIFS(AJ8:AJ600, "=APAGADO",F8:F600,"=PTO A FO") -> 0 | AK6: =COUNTIFS(AK8:AK600, "=APAGADO",F8:F600,"=PTO A FO") -> 0 | AL6: =COUNTIFS(AL8:AL600, "=APAGADO",F8:F600,"=PTO A FO") -> 0 | AM6: =COUNTIFS(AM8:AM600, "=APAGADO",F8:F600,"=PTO A FO") -> 0 | AN6: =COUNTIFS(AN8:AN600, "=APAGADO",F8:F600,"=PTO A FO") -> 0 | AO6: =COUNTIFS(AO8:AO600, "=APAGADO",F8:F600,"=PTO A FO") -> 0
A7: Barrio | B7: [Denominacion] | C7: [Empresa Mantenimiento] | D7: [Ubicacion] | E7: [Tipo de Camara] | F7: [Tipo de Conexion] | G7: Destino | I7: DIAS FUNCIONANDO | J7: DIAS CAIDA | K7: EFECTIVIDAD | L7: 45809 | M7: 45810 | N7: 45811 | O7: 45812 | P7: 45813 | Q7: 45814 | R7: 45815 | S7: 45816 | T7: 45817 | U7: 45818 | V7: 45819 | W7: 45820 | X7: 45821 | Y7: 45822 | Z7: 45823 | AA7: 45824 | AB7: 45825 | AC7: 45826 | AD7: 45827 | AE7: 45828 | AF7: 45829 | AG7: 45830 | AH7: 45831 | AI7: 45832 | AJ7: 45833 | AK7: 45834 | AL7: 45835 | AM7: 45836 | AN7: 45837 | AO7: 45838
A8: ALTAMIRA | B8: ALT01 | C8: BONOMO | D8: Calchaqui y Sgto. Cabral | E8: Domo | F8: Fibra Optica | H8: 172.20.10.6 | I8: =COUNTIF(L8:AM8,"") -> 28 | J8: =COUNTIF(L8:AM8,"APAGADO") -> 0 | K8: =(I8)/(J8+I8) -> 1
A9: ALTAMIRA | B9: ALT02 | C9: BONOMO | D9: Calchaqui y Lope de Vega | E9: Domo | F9: PTO A FO | G9: CABRAL Y CALCHAQUI | H9: 172.20.12.218 | I9: =COUNTIF(L9:AM9,"") -> 28 | J9: =COUNTIF(L9:AM9,"APAGADO") -> 0 | K9: =(I9)/(J9+I9) -> 1
A10: ALTAMIRA | B10: ALT 03 | C10: BONOMO | D10: Bombero Galarza y Necochea | E10: Domo | F10: Fibra Optica | H10: 172.20.12.54 | I10: =COUNTIF(L10:AM10,"") -> 8 | J10: =COUNTIF(L10:AM10,"APAGADO") -> 20 | K10: =(I10)/(J10+I10) -> 0.28571429 | L10: APAGADO | M10: APAGADO | N10: APAGADO | O10: APAGADO | P10: APAGADO | Q10: APAGADO | R10: APAGADO | S10: APAGADO | T10: APAGADO | U10: APAGADO | V10: APAGADO | W10: APAGADO | X10: APAGADO | AB10: APAGADO | AC10: APAGADO | AD10: APAGADO | AE10: APAGADO | AF10: APAGADO | AG10: APAGADO | AH10: APAGADO
A11: ALTAMIRA | B11: ALT 04 | C11: BONOMO | D11: Francia y Necochea | E11: Domo | F11: Fibra Optica | H11: 172.20.12.55 | I11: =COUNTIF(L11:AM11,"") -> 8 | J11: =COUNTIF(L11:AM11,"APAGADO") -> 20 | K11: =(I11)/(J11+I11) -> 0.28571429 | L11: APAGADO | M11: APAGADO | N11: APAGADO | O11: APAGADO | P11: APAGADO | Q11: APAGADO | R11: APAGADO | S11: APAGADO | T11: APAGADO | U11: APAGADO | V11: APAGADO | W11: APAGADO | X11: APAGADO | AB11: APAGADO | AC11: APAGADO | AD11: APAGADO | AE11: APAGADO | AF11: APAGADO | AG11: APAGADO | AH11: APAGADO
A12: ALTAMIRA | B12: ALT05 | C12: BONOMO | D12: Av. Calchaqui y Bombero Galarza | E12: Domo | F12: PTO A FO | G12: NECOCHEA Y GALARZA | H12: 172.20.12.216 | I12: =COUNTIF(L12:AM12,"") -> 24 | J12: =COUNTIF(L12:AM12,"APAGADO") -> 4 | K12: =(I12)/(J12+I12) -> 0.85714286 | L12: APAGADO | M12: APAGADO | N12: APAGADO | O12: APAGADO
A13: ALTAMIRA | B13: ALT 06 | C13: BONOMO | D13: LOPE DE VEGA Y NECOCHEA | E13: Domo | F13: PTO A FO | G13: NECOCHEA Y GALARZA | H13: 172.20.12.12 | I13: =COUNTIF(L13:AM13,"") -> 8 | J13: =COUNTIF(L13:AM13,"APAGADO") -> 20 | K13: =(I13)/(J13+I13) -> 0.28571429 | L13: APAGADO | M13: APAGADO | N13: APAGADO | O13: APAGADO | P13: APAGADO | Q13: APAGADO | R13: APAGADO | S13: APAGADO | T13: APAGADO | U13: APAGADO | V13: APAGADO | W13: APAGADO | X13: APAGADO | AB13: APAGADO | AC13: APAGADO | AD13: APAGADO | AE13: APAGADO | AF13: APAGADO | AG13: APAGADO | AH13: APAGADO
A14: ALTAMIRA | B14: ALT07 | C14: BONOMO | D14: AV. CALCHAQUI Y AV. DEL TRABAJO | E14: DOMO | F14: PTO A FO | G14: CABRAL Y CALCHAQUI | H14: 172.20.10.57 | I14: =COUNTIF(L14:AM14,"") -> 28 | J14: =COUNTIF(L14:AM14,"APAGADO") -> 0 | K14: =(I14)/(J14+I14) -> 1
A15: ALTAMIRA | B15: ALT 08 | C15: BONOMO | D15: HUMAITA Y NECOCHEA | E15: DOMO | F15: Fibra Optica | H15: 172.20.11.215 | I15: =COUNTIF(L15:AM15,"") -> 28 | J15: =COUNTIF(L15:AM15,"APAGADO") -> 0 | K15: =(I15)/(J15+I15) -> 1
A16: ALTAMIRA | B16: ALT 09 | C16: BONOMO | D16: NECOCHEA Y CURUPAITY | E16: DOMO | F16: Fibra Optica | H16: 172.20.11.216 | I16: =COUNTIF(L16:AM16,"") -> 28 | J16: =COUNTIF(L16:AM16,"APAGADO") -> 0 | K16: =(I16)/(J16+I16) -> 1
A17: ALTAMIRA | B17: ALT 10 | C17: BONOMO | D17: Calchaqui y Francia | E17: Domo | F17: Radio | H17: 172.20.12.156 | I17: =COUNTIF(L17:AM17,"") -> 24 | J17: =COUNTIF(L17:AM17,"APAGADO") -> 4 | K17: =(I17)/(J17+I17) -> 0.85714286 | L17: APAGADO | M17: APAGADO | N17: APAGADO | O17: APAGADO
A18: AGUSTIN RAMIREZ | B18: ARA 01 | C18: BONOMO | D18: Malambo y Tranquera | E18: Domo | F18: Fibra Optica | H18: 172.20.12.110 | I18: =COUNTIF(L18:AM18,"") -> 25 | J18: =COUNTIF(L18:AM18,"APAGADO") -> 3 | K18: =(I18)/(J18+I18) -> 0.89285714 | AF18: APAGADO | AG18: APAGADO | AH18: APAGADO
A19: BELGRANO | B19: BEL 01 | C19: BONOMO | D19: San Martin y Dardo Rocha | E19: DOMO | F19: Fibra Optica | H19: 172.20.12.64 | I19: =COUNTIF(L19:AM19,"") -> 28 | J19: =COUNTIF(L19:AM19,"APAGADO") -> 0 | K19: =(I19)/(J19+I19) -> 1
A20: BELGRANO | B20: BEL 02 | C20: BONOMO | D20: Guardia vieja y Fronteriz | E20: DOMO | F20: Fibra Optica | H20: 172.20.10.117 | I20: =COUNTIF(L20:AM20,"") -> 28 | J20: =COUNTIF(L20:AM20,"APAGADO") -> 0 | K20: =(I20)/(J20+I20) -> 1
A21: BOSQUES CENTRO | B21: BOSQC 01 | C21: COSEIDI | D21: LUIS AGOTE E/DANUNCIO Y CAMPOAMOR | E21: Fija | F21: Radio | H21: 172.20.11.15 | I21: =COUNTIF(L21:AM21,"") -> 28 | J21: =COUNTIF(L21:AM21,"APAGADO") -> 0 | K21: =(I21)/(J21+I21) -> 1
A22: BOSQUES CENTRO | B22: BOSQC 02 | C22: COSEIDI | D22: LUIS AGOTE E/DANUNCIO Y CAMPOAMOR | E22: Fija | F22: Radio | H22: 172.20.11.16 | I22: =COUNTIF(L22:AM22,"") -> 28 | J22: =COUNTIF(L22:AM22,"APAGADO") -> 0 | K22: =(I22)/(J22+I22) -> 1
A23: BOSQUES CENTRO | B23: BOSQC 03 | C23: COSEIDI | D23: BENAVENTE Y LUIS AGOTE | E23: Fija | F23: Radio | H23: 172.20.11.13 | I23: =COUNTIF(L23:AM23,"") -> 27 | J23: =COUNTIF(L23:AM23,"APAGADO") -> 1 | K23: =(I23)/(J23+I23) -> 0.96428571 | W23: APAGADO
A24: BOSQUES CENTRO | B24: BOSQC 04 | C24: COSEIDI | D24: BENAVENTE Y LUIS AGOTE | E24: Fija | F24: Radio | H24: 172.20.11.113 | I24: =COUNTIF(L24:AM24,"") -> 27 | J24: =COUNTIF(L24:AM24,"APAGADO") -> 1 | K24: =(I24)/(J24+I24) -> 0.96428571 | W24: APAGADO
A25: BOSQUES CENTRO | B25: BOSQC 05 | C25: COSEIDI | D25: LUIS AGOTE Y RUTA 36 | E25: Fija | F25: Radio | H25: 172.20.11.17 | I25: =COUNTIF(L25:AM25,"") -> 28 | J25: =COUNTIF(L25:AM25,"APAGADO") -> 0 | K25: =(I25)/(J25+I25) -> 1
A26: BOSQUES CENTRO | B26: BOSQC 06 | C26: COSEIDI | D26: LUIS AGOTE Y RUTA 36 | E26: Fija | F26: Radio | H26: 172.20.11.18 | I26: =COUNTIF(L26:AM26,"") -> 28 | J26: =COUNTIF(L26:AM26,"APAGADO") -> 0 | K26: =(I26)/(J26+I26) -> 1
A27: BOSQUES CENTRO | B27: BOSQC 07 | C27: BONOMO | D27: Touring club y Sta Teresita | E27: Domo | F27: Fibra Optica | H27: 172.20.10.141 | I27: =COUNTIF(L27:AM27,"") -> 28 | J27: =COUNTIF(L27:AM27,"APAGADO") -> 0 | K27: =(I27)/(J27+I27) -> 1
A28: BOSQUES CENTRO | B28: PAVE01 | C28: COSEIDI | D28: Touring Club y Ramallo | E28: Domo | F28: Fibra Optica | H28: 172.20.10.144 | I28: =COUNTIF(L28:AM28,"") -> 12 | J28: =COUNTIF(L28:AM28,"APAGADO") -> 16 | K28: =(I28)/(J28+I28) -> 0.42857143 | O28: APAGADO | P28: APAGADO | Q28: APAGADO | R28: APAGADO | S28: APAGADO | T28: APAGADO | U28: APAGADO | V28: APAGADO | W28: APAGADO | X28: APAGADO | AB28: APAGADO | AC28: APAGADO | AD28: APAGADO | AE28: APAGADO | AG28: APAGADO | AH28: APAGADO
A29: BOSQUES CENTRO | B29: PAVE02 | C29: COSEIDI | D29: Ramallo y Calingasta | F29: Fibra Optica | H29: 172.20.10.37 | I29: =COUNTIF(L29:AM29,"") -> 9 | J29: =COUNTIF(L29:AM29,"APAGADO") -> 19 | K29: =(I29)/(J29+I29) -> 0.32142857 | L29: APAGADO | M29: APAGADO | N29: APAGADO | O29: APAGADO | P29: APAGADO | Q29: APAGADO | R29: APAGADO | S29: APAGADO | T29: APAGADO | U29: APAGADO | V29: APAGADO | W29: APAGADO | X29: APAGADO | AB29: APAGADO | AC29: APAGADO | AD29: APAGADO | AE29: APAGADO | AG29: APAGADO | AH29: APAGADO
A30: LA CAROLINA 2 | B30: CAR01 (Fija 1) | C30: COSEIDI | D30: Azurduy y Vergara | E30: Fija | F30: Fibra Optica | H30: 172.20.10.60 | I30: =COUNTIF(L30:AM30,"") -> 9 | J30: =COUNTIF(L30:AM30,"APAGADO") -> 19 | K30: =(I30)/(J30+I30) -> 0.32142857 | L30: APAGADO | M30: APAGADO | N30: APAGADO | P30: APAGADO | Q30: APAGADO | R30: APAGADO | S30: APAGADO | T30: APAGADO | U30: APAGADO | V30: APAGADO | W30: APAGADO | X30: APAGADO | AB30: APAGADO | AC30: APAGADO | AD30: APAGADO | AE30: APAGADO | AF30: APAGADO | AG30: APAGADO | AH30: APAGADO
A31: LA CAROLINA 2 | B31: CAR02 (Fija 2) | C31: COSEIDI | D31: Azurduy y Vergara | E31: Fija | F31: Fibra Optica | H31: 172.20.10.73 | I31: =COUNTIF(L31:AM31,"") -> 9 | J31: =COUNTIF(L31:AM31,"APAGADO") -> 19 | K31: =(I31)/(J31+I31) -> 0.32142857 | L31: APAGADO | M31: APAGADO | N31: APAGADO | P31: APAGADO | Q31: APAGADO | R31: APAGADO | S31: APAGADO | T31: APAGADO | U31: APAGADO | V31: APAGADO | W31: APAGADO | X31: APAGADO | AB31: APAGADO | AC31: APAGADO | AD31: APAGADO | AE31: APAGADO | AF31: APAGADO | AG31: APAGADO | AH31: APAGADO
A32: CENTRO | B32: CEN01 | C32: BONOMO | D32: San Martin y 9 de Julio | E32: Fija | F32: Fibra Optica | H32: 172.20.11.10 | I32: =COUNTIF(L32:AM32,"") -> 27 | J32: =COUNTIF(L32:AM32,"APAGADO") -> 1 | K32: =(I32)/(J32+I32) -> 0.96428571 | O32: APAGADO
A33: CENTRO | B33: CEN02 | C33: BONOMO | D33: San Martin y Almafuerte | E33: Fija | F33: Fibra Optica | H33: 172.20.11.11 | I33: =COUNTIF(L33:AM33,"") -> 27 | J33: =COUNTIF(L33:AM33,"APAGADO") -> 1 | K33: =(I33)/(J33+I33) -> 0.96428571 | O33: APAGADO
A34: CENTRO | B34: CEN03 | C34: BONOMO | D34: San Martin y Sallares | E34: Domo | F34: Fibra Optica | H34: 172.20.12.30 | I34: =COUNTIF(L34:AM34,"") -> 28 | J34: =COUNTIF(L34:AM34,"APAGADO") -> 0 | K34: =(I34)/(J34+I34) -> 1
A35: CENTRO | B35: CEN04 | C35: BONOMO | D35: San Martin y Contreras | E35: Domo | F35: Fibra Optica | H35: 172.20.12.29 | I35: =COUNTIF(L35:AM35,"") -> 28 | J35: =COUNTIF(L35:AM35,"APAGADO") -> 0 | K35: =(I35)/(J35+I35) -> 1
A36: CENTRO | B36: CEN 05 | C36: BONOMO | D36: Bocuzzi e/España y San Martin | E36: DOMO | F36: Fibra Optica | H36: 172.20.10.200 | I36: =COUNTIF(L36:AM36,"") -> 28 | J36: =COUNTIF(L36:AM36,"APAGADO") -> 0 | K36: =(I36)/(J36+I36) -> 1
A37: CENTRO | B37: CEN06 | C37: BONOMO | D37: Monteagudo y A.del Valle | E37: Fija | F37: Fibra Optica | H37: 172.20.10.02 | I37: =COUNTIF(L37:AM37,"") -> 8 | J37: =COUNTIF(L37:AM37,"APAGADO") -> 20 | K37: =(I37)/(J37+I37) -> 0.28571429 | L37: APAGADO | M37: APAGADO | N37: APAGADO | O37: APAGADO | P37: APAGADO | Q37: APAGADO | R37: APAGADO | S37: APAGADO | T37: APAGADO | U37: APAGADO | V37: APAGADO | W37: APAGADO | X37: APAGADO | AB37: APAGADO | AC37: APAGADO | AD37: APAGADO | AE37: APAGADO | AF37: APAGADO | AG37: APAGADO | AH37: APAGADO
A38: CENTRO | B38: CEN07 | C38: BONOMO | D38: San Martin y Guemes | E38: DOMO | F38: Fibra Optica | H38: 172.20.11.20 | I38: =COUNTIF(L38:AM38,"") -> 28 | J38: =COUNTIF(L38:AM38,"APAGADO") -> 0 | K38: =(I38)/(J38+I38) -> 1
A39: CENTRO | B39: CEN08 | C39: BONOMO | D39: San Martin y Pte.Peron | E39: Domo | F39: Fibra Optica | H39: 172.20.11.21 | I39: =COUNTIF(L39:AM39,"") -> 28 | J39: =COUNTIF(L39:AM39,"APAGADO") -> 0 | K39: =(I39)/(J39+I39) -> 1
A40: CENTRO | B40: CEN09 | C40: BONOMO | D40: Chacabuco y 25 de Mayo | E40: Domo | F40: Fibra Optica | H40: 172.20.11.22 | I40: =COUNTIF(L40:AM40,"") -> 28 | J40: =COUNTIF(L40:AM40,"APAGADO") -> 0 | K40: =(I40)/(J40+I40) -> 1
...

Sheet AUXILIAR

Sheet informe
C1: CANTIDAD | D1: APAGADAS | E1: %
B2: TOTAL | C2: =CANTIDAD_DE_CAMARAS -> 485 | F2: 45809
A3: L | B3: CAIDAS | C3: ='RESUMEN TOTAL'!L3 -> 70 | E3: =C3/C2 -> 0.1443299
B4: LLEGAMOS NOSOTROS | C4: 0 | D4: =C3-C4 -> 70 | E4: =D4/C2 -> 0.1443299
B5: NO ESTA LA CAMARA | C5: 0 | D5: =D4-C5 -> 70 | E5: =D5/C2 -> 0.1443299
A6: L | B6: RADIO | C6: ='RESUMEN TOTAL'!L5 -> 15 | D6: =D5-C6 -> 55 | E6: =D6/C2 -> 0.11340206
B7: ANTENA DESMONTADA | D7: =D6-C7 -> 55 | E7: =D7/C2 -> 0.11340206
C8: CANTIDAD | D8: APAGADAS | E8: %
A9: F | B9: BONOMO | C9: =BONOMOcam -> 263 | D9: =Hoja1!F3 -> 27 | E9: =D9/C9 -> 0.1026616
A10: F | B10: COSEIDI | C10: =COSEIDIcam -> 222 | D10: =Hoja1!F5 -> 43 | E10: =D10/C10 -> 0.19369369
C12: CANTIDAD | D12: APAGADAS | E12: %
B13: TOTAL | C13: =CANTIDAD_DE_CAMARAS -> 485 | F13: 45810
A14: M | B14: CAIDAS | C14: ='RESUMEN TOTAL'!M3 -> 59 | E14: =C14/C13 -> 0.12164948
B15: LLEGAMOS NOSOTROS | C15: 0 | D15: =C14-C15 -> 59 | E15: =D15/C13 -> 0.12164948
B16: NO ESTA LA CAMARA | C16: 0 | D16: =D15-C16 -> 59 | E16: =D16/C13 -> 0.12164948
A17: M | B17: RADIO | C17: ='RESUMEN TOTAL'!M5 -> 13 | D17: =D16-C17 -> 46 | E17: =D17/C13 -> 0.094845361
B18: ANTENA DESMONTADA | D18: =D17-C18 -> 46 | E18: =D18/C13 -> 0.094845361
C19: CANTIDAD | D19: APAGADAS | E19: %
A20: G | B20: BONOMO | C20: =BONOMOcam -> 263 | D20: =Hoja1!G3 -> 27 | E20: =D20/C20 -> 0.1026616
A21: G | B21: COSEIDI | C21: =COSEIDIcam -> 222 | D21: =Hoja1!G5 -> 32 | E21: =D21/C21 -> 0.14414414
C23: CANTIDAD | D23: APAGADAS | E23: %
B24: TOTAL | C24: =CANTIDAD_DE_CAMARAS -> 485 | F24: 45811
A25: N | B25: CAIDAS | C25: ='RESUMEN TOTAL'!N3 -> 58 | E25: =C25/C24 -> 0.11958763
B26: LLEGAMOS NOSOTROS | C26: 0 | D26: =C25-C26 -> 58 | E26: =D26/C24 -> 0.11958763
B27: NO ESTA LA CAMARA | C27: 0 | D27: =D26-C27 -> 58 | E27: =D27/C24 -> 0.11958763
A28: N | B28: RADIO | C28: ='RESUMEN TOTAL'!N5 -> 14 | D28: =D27-C28 -> 44 | E28: =D28/C24 -> 0.090721649
B29: ANTENA DESMONTADA | D29: =D28-C29 -> 44 | E29: =D29/C24 -> 0.090721649
C30: CANTIDAD | D30: APAGADAS | E30: %
B31: BONOMO | C31: =BONOMOcam -> 263 | D31: =Hoja1!H3 -> 26 | E31: =D31/C31 -> 0.098859316
B32: COSEIDI | C32: =COSEIDIcam -> 222 | D32: =Hoja1!H5 -> 32 | E32: =D32/C32 -> 0.14414414
C34: CANTIDAD | D34: APAGADAS | E34: %
B35: TOTAL | C35: =CANTIDAD_DE_CAMARAS -> 485 | F35: 45812
A36: O | B36: CAIDAS | C36: ='RESUMEN TOTAL'!O3 -> 64 | E36: =C36/C35 -> 0.13195876
B37: LLEGAMOS NOSOTROS | C37: 0 | D37: =C36-C37 -> 64 | E37: =D37/C35 -> 0.13195876
B38: NO ESTA LA CAMARA | C38: 0 | D38: =D37-C38 -> 64 | E38: =D38/C35 -> 0.13195876
A39: O | B39: RADIO | C39: ='RESUMEN TOTAL'!O5 -> 11 | D39: =D38-C39 -> 53 | E39: =D39/C35 -> 0.10927835
B40: ANTENA DESMONTADA | D40: =D39-C40 -> 53 | E40: =D40/C35 -> 0.10927835
C41: CANTIDAD | D41: APAGADAS | E41: %
B42: BONOMO | C42: =BONOMOcam -> 263 | D42: =Hoja1!I3 -> 33 | E42: =D42/C42 -> 0.12547529
B43: COSEIDI | C43: =COSEIDIcam -> 222 | D43: =Hoja1!I5 -> 31 | E43: =D43/C43 -> 0.13963964
...

Sheet Hoja1
B1: CAMARAS
A2: BONOMO | B2: =COUNTIFS('RESUMEN TOTAL'!C8:C492,"=BONOMO") -> 263 | F2: 45809 | G2: 45810 | H2: 45811 | I2: 45812 | J2: 45813 | K2: 45814 | L2: 45815 | M2: 45816 | N2: 45817 | O2: 45818 | P2: 45819 | Q2: 45820 | R2: 45821 | S2: 45822 | T2: 45823 | U2: 45824 | V2: 45825 | W2: 45826 | X2: 45827 | Y2: 45828 | Z2: 45829 | AA2: 45830 | AB2: 45831 | AC2: 45832 | AD2: 45833 | AE2: 45834 | AF2: 45835 | AG2: 45836 | AH2: 45837 | AI2: 45838
D3: BONOMO | E3: APAGADAS BONOMO | F3: =COUNTIFS('RESUMEN TOTAL'!L8:L600,"=APAGADO",'RESUMEN TOTAL'!C8:C600,"=BONOMO") -> 27 | G3: =COUNTIFS('RESUMEN TOTAL'!M8:M600,"=APAGADO",'RESUMEN TOTAL'!C8:C600,"=BONOMO") -> 27 | H3: =COUNTIFS('RESUMEN TOTAL'!N8:N600,"=APAGADO",'RESUMEN TOTAL'!C8:C600,"=BONOMO") -> 26 | I3: =COUNTIFS('RESUMEN TOTAL'!O8:O600,"=APAGADO",'RESUMEN TOTAL'!C8:C600,"=BONOMO") -> 33 | J3: =COUNTIFS('RESUMEN TOTAL'!P8:P600,"=APAGADO",'RESUMEN TOTAL'!C8:C600,"=BONOMO") -> 26 | K3: =COUNTIFS('RESUMEN TOTAL'!Q8:Q600,"=APAGADO",'RESUMEN TOTAL'!C8:C600,"=BONOMO") -> 24 | L3: =COUNTIFS('RESUMEN TOTAL'!R8:R600,"=APAGADO",'RESUMEN TOTAL'!C8:C600,"=BONOMO") -> 44 | M3: =COUNTIFS('RESUMEN TOTAL'!S8:S600,"=APAGADO",'RESUMEN TOTAL'!C8:C600,"=BONOMO") -> 41 | N3: =COUNTIFS('RESUMEN TOTAL'!T8:T600,"=APAGADO",'RESUMEN TOTAL'!C8:C600,"=BONOMO") -> 42 | O3: =COUNTIFS('RESUMEN TOTAL'!U8:U600,"=APAGADO",'RESUMEN TOTAL'!C8:C600,"=BONOMO") -> 51 | P3: =COUNTIFS('RESUMEN TOTAL'!V8:V600,"=APAGADO",'RESUMEN TOTAL'!C8:C600,"=BONOMO") -> 28 | Q3: =COUNTIFS('RESUMEN TOTAL'!W8:W600,"=APAGADO",'RESUMEN TOTAL'!C8:C600,"=BONOMO") -> 23 | R3: =COUNTIFS('RESUMEN TOTAL'!X8:X600,"=APAGADO",'RESUMEN TOTAL'!C8:C600,"=BONOMO") -> 27 | S3: =COUNTIFS('RESUMEN TOTAL'!Y8:Y600,"=APAGADO",'RESUMEN TOTAL'!C8:C600,"=BONOMO") -> 0 | T3: =COUNTIFS('RESUMEN TOTAL'!Z8:Z600,"=APAGADO",'RESUMEN TOTAL'!C8:C600,"=BONOMO") -> 0 | U3: 55 | V3: =COUNTIFS('RESUMEN TOTAL'!AB8:AB600,"=APAGADO",'RESUMEN TOTAL'!C8:C600,"=BONOMO") -> 24 | W3: =COUNTIFS('RESUMEN TOTAL'!AC8:AC600,"=APAGADO",'RESUMEN TOTAL'!C8:C600,"=BONOMO") -> 40 | X3: =COUNTIFS('RESUMEN TOTAL'!AD8:AD600,"=APAGADO",'RESUMEN TOTAL'!C8:C600,"=BONOMO") -> 19 | Y3: =COUNTIFS('RESUMEN TOTAL'!AE8:AE600,"=APAGADO",'RESUMEN TOTAL'!C8:C600,"=BONOMO") -> 41 | Z3: =COUNTIFS('RESUMEN TOTAL'!AF8:AF600,"=APAGADO",'RESUMEN TOTAL'!C8:C600,"=BONOMO") -> 25 | AA3: =COUNTIFS('RESUMEN TOTAL'!AG8:AG600,"=APAGADO",'RESUMEN TOTAL'!C8:C600,"=BONOMO") -> 42 | AB3: =COUNTIFS('RESUMEN TOTAL'!AH8:AH600,"=APAGADO",'RESUMEN TOTAL'!C8:C600,"=BONOMO") -> 55 | AC3: =COUNTIFS('RESUMEN TOTAL'!AI8:AI600,"=APAGADO",'RESUMEN TOTAL'!C8:C600,"=BONOMO") -> 0 | AD3: =COUNTIFS('RESUMEN TOTAL'!AJ8:AJ600,"=APAGADO",'RESUMEN TOTAL'!C8:C600,"=BONOMO") -> 0 | AE3: =COUNTIFS('RESUMEN TOTAL'!AK8:AK600,"=APAGADO",'RESUMEN TOTAL'!S8:S600,"=BONOMO") -> 0 | AF3: =COUNTIFS('RESUMEN TOTAL'!AL8:AL600,"=APAGADO",'RESUMEN TOTAL'!C8:C600,"=BONOMO") -> 0 | AG3: =COUNTIFS('RESUMEN TOTAL'!AM8:AM600,"=APAGADO",'RESUMEN TOTAL'!C8:C600,"=BONOMO") -> 0 | AH3: =COUNTIFS('RESUMEN TOTAL'!AN8:AN600,"=APAGADO",'RESUMEN TOTAL'!C8:C600,"=BONOMO") -> 0 | AI3: =COUNTIFS('RESUMEN TOTAL'!AO8:AO600,"=APAGADO",'RESUMEN TOTAL'!C8:C600,"=BONOMO") -> 0
A4: COSEIDI | B4: =COUNTIFS('RESUMEN TOTAL'!C8:C492,"=COSEIDI") -> 222 | E4: % BONOMO | F4: =F3/BONOMOcam -> 0.1026616 | G4: =G3/BONOMOcam -> 0.1026616 | H4: =H3/BONOMOcam -> 0.098859316 | I4: =I3/BONOMOcam -> 0.12547529 | J4: =J3/BONOMOcam -> 0.098859316 | K4: =K3/BONOMOcam -> 0.091254753 | L4: =L3/BONOMOcam -> 0.16730038 | M4: =M3/BONOMOcam -> 0.15589354 | ... O4: =O3/BONOMOcam -> 0.19391635 | P4: 0 | Q4: 0 | R4: 10,27% | S4: 0 | T4: 0 | U4: 0 | V4: 0 | W4: 15,21% | X4: 7,22% | Y4: 0 | Z4: 0 | AA4: 0 | AB4: 0 | AC4: 0 | AD4: 0 | AE4: =AE3/BONOMOcam -> 0 | AF4: 0 | AG4: =AG3/BONOMOcam -> 0 | AH4: =AH3/BONOMOcam -> 0 | AI4: =AI3/BONOMOcam -> 0
D5: COSEIDI | E5: APAGADAS COSEIDI | F5: =COUNTIFS('RESUMEN TOTAL'!L10:L602,"=APAGADO",'RESUMEN TOTAL'!C10:C602,"=COSEIDI") -> 43 | G5: =COUNTIFS('RESUMEN TOTAL'!M10:M602,"=APAGADO",'RESUMEN TOTAL'!C10:C602,"=COSEIDI") -> 32 | H5: =COUNTIFS('RESUMEN TOTAL'!N10:N602,"=APAGADO",'RESUMEN TOTAL'!C10:C602,"=COSEIDI") -> 32 | I5: =COUNTIFS('RESUMEN TOTAL'!O10:O602,"=APAGADO",'RESUMEN TOTAL'!C10:C602,"=COSEIDI") -> 31 | J5: =COUNTIFS('RESUMEN TOTAL'!P10:P602,"=APAGADO",'RESUMEN TOTAL'!C10:C602,"=COSEIDI") -> 33 | K5: =COUNTIFS('RESUMEN TOTAL'!Q10:Q602,"=APAGADO",'RESUMEN TOTAL'!C10:C602,"=COSEIDI") -> 29 | L5: =COUNTIFS('RESUMEN TOTAL'!R10:R602,"=APAGADO",'RESUMEN TOTAL'!C10:C602,"=COSEIDI") -> 39 | M5: =COUNTIFS('RESUMEN TOTAL'!S10:S602,"=APAGADO",'RESUMEN TOTAL'!C10:C602,"=COSEIDI") -> 27 | N5: =COUNTIFS('RESUMEN TOTAL'!T10:T602,"=APAGADO",'RESUMEN TOTAL'!C10:C602,"=COSEIDI") -> 28 | O5: =COUNTIFS('RESUMEN TOTAL'!U10:U602,"=APAGADO",'RESUMEN TOTAL'!C10:C602,"=COSEIDI") -> 28 | P5: =COUNTIFS('RESUMEN TOTAL'!V10:V602,"=APAGADO",'RESUMEN TOTAL'!C10:C602,"=COSEIDI") -> 34 | Q5: =COUNTIFS('RESUMEN TOTAL'!W10:W602,"=APAGADO",'RESUMEN TOTAL'!C10:C602,"=COSEIDI") -> 39 | R5: =COUNTIFS('RESUMEN TOTAL'!X10:X602,"=APAGADO",'RESUMEN TOTAL'!C10:C602,"=COSEIDI") -> 39 | S5: =COUNTIFS('RESUMEN TOTAL'!Y10:Y602,"=APAGADO",'RESUMEN TOTAL'!C10:C602,"=COSEIDI") -> 0 | T5: =COUNTIFS('RESUMEN TOTAL'!Z10:Z602,"=APAGADO",'RESUMEN TOTAL'!C10:C602,"=COSEIDI") -> 0 | U5: =COUNTIFS('RESUMEN TOTAL'!AA10:AA602,"=APAGADO",'RESUMEN TOTAL'!C10:C602,"=COSEIDI") -> 0 | V5: =COUNTIFS('RESUMEN TOTAL'!AB10:AB602,"=APAGADO",'RESUMEN TOTAL'!C10:C602,"=COSEIDI") -> 32 | W5: =COUNTIFS('RESUMEN TOTAL'!AC10:AC602,"=APAGADO",'RESUMEN TOTAL'!C10:C602,"=COSEIDI") -> 28 | X5: =COUNTIFS('RESUMEN TOTAL'!AD10:AD602,"=APAGADO",'RESUMEN TOTAL'!C10:C602,"=COSEIDI") -> 25 | Y5: =COUNTIFS('RESUMEN TOTAL'!AE10:AE602,"=APAGADO",'RESUMEN TOTAL'!C10:C602,"=COSEIDI") -> 27 | Z5: =COUNTIFS('RESUMEN TOTAL'!AF10:AF602,"=APAGADO",'RESUMEN TOTAL'!C10:C602,"=COSEIDI") -> 21 | AA5: =COUNTIFS('RESUMEN TOTAL'!AG10:AG602,"=APAGADO",'RESUMEN TOTAL'!C10:C602,"=COSEIDI") -> 33 | AB5: =COUNTIFS('RESUMEN TOTAL'!AH10:AH602,"=APAGADO",'RESUMEN TOTAL'!C10:C602,"=COSEIDI") -> 35 | AC5: =COUNTIFS('RESUMEN TOTAL'!AI10:AI602,"=APAGADO",'RESUMEN TOTAL'!C10:C602,"=COSEIDI") -> 0 | AD5: =COUNTIFS('RESUMEN TOTAL'!AJ10:AJ602,"=APAGADO",'RESUMEN TOTAL'!C10:C602,"=COSEIDI") -> 0 | AE5: =COUNTIFS('RESUMEN TOTAL'!AK10:AK602,"=APAGADO",'RESUMEN TOTAL'!C10:C602,"=COSEIDI") -> 0 | AF5: =COUNTIFS('RESUMEN TOTAL'!AL10:AL602,"=APAGADO",'RESUMEN TOTAL'!C10:C602,"=COSEIDI") -> 0 | AG5: =COUNTIFS('RESUMEN TOTAL'!AM10:AM602,"=APAGADO",'RESUMEN TOTAL'!C10:C602,"=COSEIDI") -> 0 | AH5: =COUNTIFS('RESUMEN TOTAL'!AN10:AN602,"=APAGADO",'RESUMEN TOTAL'!C10:C602,"=COSEIDI") -> 0 | AI5: =COUNTIFS('RESUMEN TOTAL'!AO10:AO602,"=APAGADO",'RESUMEN TOTAL'!C10:C602,"=COSEIDI") -> 0
E6: % COSEIDI | F6: =F5/COSEIDIcam -> 0.19369369 | G6: =G5/COSEIDIcam -> 0.14414414 | H6: =H5/COSEIDIcam -> 0.14414414 | I6: =I5/COSEIDIcam -> 0.13963964 | J6: =J5/COSEIDIcam -> 0.14864865 | K6: =K5/COSEIDIcam -> 0.13063063 | L6: =L5/COSEIDIcam -> 0.17567568 | M6: =M5/COSEIDIcam -> 0.12162162 | ... O6: =O5/COSEIDIcam -> 0.12612613 | P6: 0 | Q6: 0 | R6: 17,57% | S6: 0 | T6: 0 | U6: 0 | V6: 0 | W6: 12,61% | X6: 11,26% | Y6: 0 | Z6: 0 | AA6: 0 | AB6: 0 | AC6: 0 | AD6: 0 | AE6: 0 | AF6: 0 | AG6: 0 | AH6: 0 | AI6: 0

Sheet paradas
C1: TOTAL PARADAS | D1: =COUNTIFS(A5:A601,"=paradas seguras")/2 -> 0 | E1: TOTAL DE CAMARAS EN PARADAS | H1: =COUNTIFS(A5:A601,"=paradas seguras") -> 0 | I1: TOTAL DE CAMARAS | K1: =COUNTIFS(D5:D601,"=GFIJA") -> 0 | L1: TOTAL DE INTERCOMUNICADORES | O1: =COUNTIFS(D5:D601,"=INTERCOMUNICADOR") -> 0
E2: FIJAS | F2: =COUNTIFS(F4:F600, "=APAGADO",D4:D600,"=GFIJA") -> 0 | G2: =COUNTIFS(G4:G600, "=APAGADO",D4:D600,"=GFIJA") -> 0 | H2: =COUNTIFS(H4:H600, "=APAGADO",D4:D600,"=GFIJA") -> 0 | I2: =COUNTIFS(I4:I600, "=APAGADO",D4:D600,"=GFIJA") -> 0 | J2: =COUNTIFS(J4:J600, "=APAGADO",D4:D600,"=GFIJA") -> 0 | K2: =COUNTIFS(K4:K600, "=APAGADO",D4:D600,"=GFIJA") -> 0 | L2: =COUNTIFS(L4:L600, "=APAGADO",D4:D600,"=GFIJA") -> 0 | M2: =COUNTIFS(M4:M600, "=APAGADO",D4:D600,"=GFIJA") -> 0 | N2: =COUNTIFS(N4:N600, "=APAGADO",D4:D600,"=GFIJA") -> 0 | O2: =COUNTIFS(O4:O600, "=APAGADO",D4:D600,"=GFIJA") -> 0 | P2: =COUNTIFS(P4:P600, "=APAGADO",D4:D600,"=GFIJA") -> 0 | Q2: =COUNTIFS(Q4:Q600, "=APAGADO",D4:D600,"=GFIJA") -> 0 | R2: =COUNTIFS(R4:R600, "=APAGADO",D4:D600,"=GFIJA") -> 0 | S2: =COUNTIFS(S4:S600, "=APAGADO",D4:D600,"=GFIJA") -> 0 | T2: =COUNTIFS(T4:T600, "=APAGADO",D4:D600,"=GFIJA") -> 0 | U2: =COUNTIFS(U4:U600, "=APAGADO",D4:D600,"=GFIJA") -> 0 | V2: =COUNTIFS(V4:V600, "=APAGADO",D4:D600,"=GFIJA") -> 0 | W2: =COUNTIFS(W4:W600, "=APAGADO",D4:D600,"=GFIJA") -> 0 | X2: =COUNTIFS(X4:X600, "=APAGADO",D4:D600,"=GFIJA") -> 0 | Y2: =COUNTIFS(Y4:Y600, "=APAGADO",D4:D600,"=GFIJA") -> 0 | Z2: =COUNTIFS(Z4:Z600, "=APAGADO",D4:D600,"=GFIJA") -> 0 | AA2: =COUNTIFS(AA4:AA600, "=APAGADO",D4:D600,"=GFIJA") -> 0 | AB2: =COUNTIFS(AB4:AB600, "=APAGADO",D4:D600,"=GFIJA") -> 0 | AC2: =COUNTIFS(AC4:AC600, "=APAGADO",D4:D600,"=GFIJA") -> 0 | AD2: =COUNTIFS(AD4:AD600, "=APAGADO",D4:D600,"=GFIJA") -> 0 | AE2: =COUNTIFS(AE4:AE600, "=APAGADO",D4:D600,"=GFIJA") -> 0 | AF2: =COUNTIFS(AF4:AF600, "=APAGADO",D4:D600,"=GFIJA") -> 0 | AG2: =COUNTIFS(AG4:AG600, "=APAGADO",D4:D600,"=GFIJA") -> 0 | AH2: =COUNTIFS(AH4:AH600, "=APAGADO",D4:D600,"=GFIJA") -> 0 | AI2: =COUNTIFS(AI4:AI600, "=APAGADO",D4:D600,"=GFIJA") -> 0
E3: INTERCOMUNICADOR | F3: =COUNTIFS(F6:F602, "=APAGADO",D4:D600,"=INTERCOMUNICADOR") -> 0 | G3: =COUNTIFS(G6:G602, "=APAGADO",D4:D600,"=INTERCOMUNICADOR") -> 0 | H3: =COUNTIFS(H6:H602, "=APAGADO",D4:D600,"=INTERCOMUNICADOR") -> 0 | I3: =COUNTIFS(I6:I602, "=APAGADO",D4:D600,"=INTERCOMUNICADOR") -> 0 | J3: =COUNTIFS(J6:J602, "=APAGADO",D4:D600,"=INTERCOMUNICADOR") -> 0 | K3: =COUNTIFS(K6:K602, "=APAGADO",D4:D600,"=INTERCOMUNICADOR") -> 0 | L3: =COUNTIFS(L6:L602, "=APAGADO",D4:D600,"=INTERCOMUNICADOR") -> 0 | M3: =COUNTIFS(M6:M602, "=APAGADO",D4:D600,"=INTERCOMUNICADOR") -> 0 | N3: =COUNTIFS(N6:N602, "=APAGADO",D4:D600,"=INTERCOMUNICADOR") -> 0 | O3: =COUNTIFS(O6:O602, "=APAGADO",D4:D600,"=INTERCOMUNICADOR") -> 0 | P3: =COUNTIFS(P6:P602, "=APAGADO",D4:D600,"=INTERCOMUNICADOR") -> 0 | Q3: =COUNTIFS(Q6:Q602, "=APAGADO",D4:D600,"=INTERCOMUNICADOR") -> 0 | R3: =COUNTIFS(R6:R602, "=APAGADO",D4:D600,"=INTERCOMUNICADOR") -> 0 | S3: =COUNTIFS(S6:S602, "=APAGADO",D4:D600,"=INTERCOMUNICADOR") -> 0 | T3: =COUNTIFS(T6:T602, "=APAGADO",D4:D600,"=INTERCOMUNICADOR") -> 0 | U3: =COUNTIFS(U6:U602, "=APAGADO",D4:D600,"=INTERCOMUNICADOR") -> 0 | V3: =COUNTIFS(V6:V602, "=APAGADO",D4:D600,"=INTERCOMUNICADOR") -> 0 | W3: =COUNTIFS(W6:W602, "=APAGADO",D4:D600,"=INTERCOMUNICADOR") -> 0 | X3: =COUNTIFS(X6:X602, "=APAGADO",D4:D600,"=INTERCOMUNICADOR") -> 0 | Y3: =COUNTIFS(Y6:Y602, "=APAGADO",D4:D600,"=INTERCOMUNICADOR") -> 0 | Z3: =COUNTIFS(Z6:Z602, "=APAGADO",D4:D600,"=INTERCOMUNICADOR") -> 0 | AA3: =COUNTIFS(AA6:AA602, "=APAGADO",D4:D600,"=INTERCOMUNICADOR") -> 0 | AB3: =COUNTIFS(AB6:AB602, "=APAGADO",D4:D600,"=INTERCOMUNICADOR") -> 0 | AC3: =COUNTIFS(AC6:AC602, "=APAGADO",D4:D600,"=INTERCOMUNICADOR") -> 0 | AD3: =COUNTIFS(AD6:AD602, "=APAGADO",D4:D600,"=INTERCOMUNICADOR") -> 0 | AE3: =COUNTIFS(AE6:AE602, "=APAGADO",D4:D600,"=INTERCOMUNICADOR") -> 0 | AF3: =COUNTIFS(AF6:AF602, "=APAGADO",D4:D600,"=INTERCOMUNICADOR") -> 0 | AG3: =COUNTIFS(AG6:AG602, "=APAGADO",D4:D600,"=INTERCOMUNICADOR") -> 0 | AH3: =COUNTIFS(AH6:AH602, "=APAGADO",D4:D600,"=INTERCOMUNICADOR") -> 0 | AI3: =COUNTIFS(AI6:AI602, "=APAGADO",D4:D600,"=INTERCOMUNICADOR") -> 0
A4: ='RESUMEN TOTAL'!A7 -> Barrio | B4: ='RESUMEN TOTAL'!B7 -> [Denominacion] | C4: ='RESUMEN TOTAL'!D7 -> [Ubicacion] | D4: ='RESUMEN TOTAL'!E7 -> [Tipo de Camara] | E4: ='RESUMEN TOTAL'!F7 -> [Tipo de Conexion] | F4: ='RESUMEN TOTAL'!L7 -> 45809 | G4: ='RESUMEN TOTAL'!M7 -> 45810 | H4: ='RESUMEN TOTAL'!N7 -> 45811 | I4: ='RESUMEN TOTAL'!O7 -> 45812 | J4: ='RESUMEN TOTAL'!P7 -> 45813 | K4: ='RESUMEN TOTAL'!Q7 -> 45814 | L4: ='RESUMEN TOTAL'!R7 -> 45815 | M4: ='RESUMEN TOTAL'!S7 -> 45816 | ... AI4: ='RESUMEN TOTAL'!AO7 -> 45838 | XFC4: =SUM(F4:XFB4) -> 1374705
A5: ='RESUMEN TOTAL'!A8 -> ALTAMIRA | B5: ='RESUMEN TOTAL'!B8 -> ALT01 | C5: ='RESUMEN TOTAL'!D8 -> Calchaqui y Sgto. Cabral | D5: ='RESUMEN TOTAL'!E8 -> Domo | E5: ='RESUMEN TOTAL'!F8 -> Fibra Optica | F5: ='RESUMEN TOTAL'!L8 -> 0 | G5: ='RESUMEN TOTAL'!M8 -> 0 | H5: ='RESUMEN TOTAL'!N8 -> 0 | I5: ='RESUMEN TOTAL'!O8 -> 0 | J5: ='RESUMEN TOTAL'!P8 -> 0 | K5: ='RESUMEN TOTAL'!Q8 -> 0 | L5: ='RESUMEN TOTAL'!R8 -> 0 | M5: ='RESUMEN TOTAL'!S8 -> 0 | ... AI5: ='RESUMEN TOTAL'!AO8 -> 0
A6: ='RESUMEN TOTAL'!A9 -> ALTAMIRA | B6: ='RESUMEN TOTAL'!B9 -> ALT02 | C6: ='RESUMEN TOTAL'!D9 -> Calchaqui y Lope de Vega | D6: ='RESUMEN TOTAL'!E9 -> Domo | E6: ='RESUMEN TOTAL'!F9 -> PTO A FO | F6: ='RESUMEN TOTAL'!L9 -> 0 | G6: ='RESUMEN TOTAL'!M9 -> 0 | H6: ='RESUMEN TOTAL'!N9 -> 0 | I6: ='RESUMEN TOTAL'!O9 -> 0 | J6: ='RESUMEN TOTAL'!P9 -> 0 | K6: ='RESUMEN TOTAL'!Q9 -> 0 | L6: ='RESUMEN TOTAL'!R9 -> 0 | M6: ='RESUMEN TOTAL'!S9 -> 0 | ... AI6: ='RESUMEN TOTAL'!AO9 -> 0
A7: ='RESUMEN TOTAL'!A10 -> ALTAMIRA | B7: ='RESUMEN TOTAL'!B10 -> ALT 03 | C7: ='RESUMEN TOTAL'!D10 -> Bombero Galarza y Necochea | D7: ='RESUMEN TOTAL'!E10 -> Domo | E7: ='RESUMEN TOTAL'!F10 -> Fibra Optica | F7: ='RESUMEN TOTAL'!L10 -> APAGADO | G7: ='RESUMEN TOTAL'!M10 -> APAGADO | H7: ='RESUMEN TOTAL'!N10 -> APAGADO | I7: ='RESUMEN TOTAL'!O10 -> APAGADO | J7: ='RESUMEN TOTAL'!P10 -> APAGADO | K7: ='RESUMEN TOTAL'!Q10 -> APAGADO | L7: ='RESUMEN TOTAL'!R10 -> APAGADO | M7: ='RESUMEN TOTAL'!S10 -> APAGADO | ... AI7: ='RESUMEN TOTAL'!AO10 -> 0
A8: ='RESUMEN TOTAL'!A11 -> ALTAMIRA | B8: ='RESUMEN TOTAL'!B11 -> ALT 04 | C8: ='RESUMEN TOTAL'!D11 -> Francia y Necochea | D8: ='RESUMEN TOTAL'!E11 -> Domo | E8: ='RESUMEN TOTAL'!F11 -> Fibra Optica | F8: ='RESUMEN TOTAL'!L11 -> APAGADO | G8: ='RESUMEN TOTAL'!M11 -> APAGADO | H8: ='RESUMEN TOTAL'!N11 -> APAGADO | I8: ='RESUMEN TOTAL'!O11 -> APAGADO | J8: ='RESUMEN TOTAL'!P11 -> APAGADO | K8: ='RESUMEN TOTAL'!Q11 -> APAGADO | L8: ='RESUMEN TOTAL'!R11 -> APAGADO | M8: ='RESUMEN TOTAL'!S11 -> APAGADO | ... AI8: ='RESUMEN TOTAL'!AO11 -> 0
A9: ='RESUMEN TOTAL'!A12 -> ALTAMIRA | B9: ='RESUMEN TOTAL'!B12 -> ALT05 | C9: ='RESUMEN TOTAL'!D12 -> Av. Calchaqui y Bombero Galarza | D9: ='RESUMEN TOTAL'!E12 -> Domo | E9: ='RESUMEN TOTAL'!F12 -> PTO A FO | F9: ='RESUMEN TOTAL'!L12 -> APAGADO | G9: ='RESUMEN TOTAL'!M12 -> APAGADO | H9: ='RESUMEN TOTAL'!N12 -> APAGADO | I9: ='RESUMEN TOTAL'!O12 -> APAGADO | J9: ='RESUMEN TOTAL'!P12 -> 0 | K9: ='RESUMEN TOTAL'!Q12 -> 0 | L9: ='RESUMEN TOTAL'!R12 -> 0 | M9: ='RESUMEN TOTAL'!S12 -> 0 | ... AI9: ='RESUMEN TOTAL'!AO12 -> 0
A10: ='RESUMEN TOTAL'!A13 -> ALTAMIRA | B10: ='RESUMEN TOTAL'!B13 -> ALT 06 | C10: ='RESUMEN TOTAL'!D13 -> LOPE DE VEGA Y NECOCHEA | D10: ='RESUMEN TOTAL'!E13 -> Domo | E10: ='RESUMEN TOTAL'!F13 -> PTO A FO | F10: ='RESUMEN TOTAL'!L13 -> APAGADO | G10: ='RESUMEN TOTAL'!M13 -> APAGADO | H10: ='RESUMEN TOTAL'!N13 -> APAGADO | I10: ='RESUMEN TOTAL'!O13 -> APAGADO | J10: ='RESUMEN TOTAL'!P13 -> APAGADO | K10: ='RESUMEN TOTAL'!Q13 -> APAGADO | L10: ='RESUMEN TOTAL'!R13 -> APAGADO | M10: ='RESUMEN TOTAL'!S13 -> APAGADO | ... AI10: ='RESUMEN TOTAL'!AO13 -> 0
A11: ='RESUMEN TOTAL'!A14 -> ALTAMIRA | B11: ='RESUMEN TOTAL'!B14 -> ALT07 | C11: ='RESUMEN TOTAL'!D14 -> AV. CALCHAQUI Y AV. DEL TRABAJO | D11: ='RESUMEN TOTAL'!E14 -> DOMO | E11: ='RESUMEN TOTAL'!F14 -> PTO A FO | F11: ='RESUMEN TOTAL'!L14 -> 0 | G11: ='RESUMEN TOTAL'!M14 -> 0 | H11: ='RESUMEN TOTAL'!N14 -> 0 | I11: ='RESUMEN TOTAL'!O14 -> 0 | J11: ='RESUMEN TOTAL'!P14 -> 0 | K11: ='RESUMEN TOTAL'!Q14 -> 0 | L11: ='RESUMEN TOTAL'!R14 -> 0 | M11: ='RESUMEN TOTAL'!S14 -> 0 | ... AI11: ='RESUMEN TOTAL'!AO14 -> 0
A12: ='RESUMEN TOTAL'!A15 -> ALTAMIRA | B12: ='RESUMEN TOTAL'!B15 -> ALT 08 | C12: ='RESUMEN TOTAL'!D15 -> HUMAITA Y NECOCHEA | D12: ='RESUMEN TOTAL'!E15 -> DOMO | E12: ='RESUMEN TOTAL'!F15 -> Fibra Optica | F12: ='RESUMEN TOTAL'!L15 -> 0 | G12: ='RESUMEN TOTAL'!M15 -> 0 | H12: ='RESUMEN TOTAL'!N15 -> 0 | I12: ='RESUMEN TOTAL'!O15 -> 0 | J12: ='RESUMEN TOTAL'!P15 -> 0 | K12: ='RESUMEN TOTAL'!Q15 -> 0 | L12: ='RESUMEN TOTAL'!R15 -> 0 | M12: ='RESUMEN TOTAL'!S15 -> 0 | ... AI12: ='RESUMEN TOTAL'!AO15 -> 0
A13: ='RESUMEN TOTAL'!A16 -> ALTAMIRA | B13: ='RESUMEN TOTAL'!B16 -> ALT 09 | C13: ='RESUMEN TOTAL'!D16 -> NECOCHEA Y CURUPAITY | D13: ='RESUMEN TOTAL'!E16 -> DOMO | E13: ='RESUMEN TOTAL'!F16 -> Fibra Optica | F13: ='RESUMEN TOTAL'!L16 -> 0 | G13: ='RESUMEN TOTAL'!M16 -> 0 | H13: ='RESUMEN TOTAL'!N16 -> 0 | I13: ='RESUMEN TOTAL'!O16 -> 0 | J13: ='RESUMEN TOTAL'!P16 -> 0 | K13: ='RESUMEN TOTAL'!Q16 -> 0 | L13: ='RESUMEN TOTAL'!R16 -> 0 | M13: ='RESUMEN TOTAL'!S16 -> 0 | ... AI13: ='RESUMEN TOTAL'!AO16 -> 0
A14: ='RESUMEN TOTAL'!A17 -> ALTAMIRA | B14: ='RESUMEN TOTAL'!B17 -> ALT 10 | C14: ='RESUMEN TOTAL'!D17 -> Calchaqui y Francia | D14: ='RESUMEN TOTAL'!E17 -> Domo | E14: ='RESUMEN TOTAL'!F17 -> Radio | F14: ='RESUMEN TOTAL'!L17 -> APAGADO | G14: ='RESUMEN TOTAL'!M17 -> APAGADO | H14: ='RESUMEN TOTAL'!N17 -> APAGADO | I14: ='RESUMEN TOTAL'!O17 -> APAGADO | J14: ='RESUMEN TOTAL'!P17 -> 0 | K14: ='RESUMEN TOTAL'!Q17 -> 0 | L14: ='RESUMEN TOTAL'!R17 -> 0 | M14: ='RESUMEN TOTAL'!S17 -> 0 | ... AI14: ='RESUMEN TOTAL'!AO17 -> 0
A15: ='RESUMEN TOTAL'!A18 -> AGUSTIN RAMIREZ | B15: ='RESUMEN TOTAL'!B18 -> ARA 01 | C15: ='RESUMEN TOTAL'!D18 -> Malambo y Tranquera | D15: ='RESUMEN TOTAL'!E18 -> Domo | E15: ='RESUMEN TOTAL'!F18 -> Fibra Optica | F15: ='RESUMEN TOTAL'!L18 -> 0 | G15: ='RESUMEN TOTAL'!M18 -> 0 | H15: ='RESUMEN TOTAL'!N18 -> 0 | I15: ='RESUMEN TOTAL'!O18 -> 0 | J15: ='RESUMEN TOTAL'!P18 -> 0 | K15: ='RESUMEN TOTAL'!Q18 -> 0 | L15: ='RESUMEN TOTAL'!R18 -> 0 | M15: ='RESUMEN TOTAL'!S18 -> 0 | ... AI15: ='RESUMEN TOTAL'!AO18 -> 0
A16: ='RESUMEN TOTAL'!A19 -> BELGRANO | B16: ='RESUMEN TOTAL'!B19 -> BEL 01 | C16: ='RESUMEN TOTAL'!D19 -> San Martin y Dardo Rocha | D16: ='RESUMEN TOTAL'!E19 -> DOMO | E16: ='RESUMEN TOTAL'!F19 -> Fibra Optica | F16: ='RESUMEN TOTAL'!L19 -> 0 | G16: ='RESUMEN TOTAL'!M19 -> 0 | H16: ='RESUMEN TOTAL'!N19 -> 0 | I16: ='RESUMEN TOTAL'!O19 -> 0 | J16: ='RESUMEN TOTAL'!P19 -> 0 | K16: ='RESUMEN TOTAL'!Q19 -> 0 | L16: ='RESUMEN TOTAL'!R19 -> 0 | M16: ='RESUMEN TOTAL'!S19 -> 0 | ... AI16: ='RESUMEN TOTAL'!AO19 -> 0
... A23: ='RESUMEN TOTAL'!A26 -> BOSQUES CENTRO | B23: ='RESUMEN TOTAL'!B26 -> BOSQC 06 | C23: ='RESUMEN TOTAL'!D26 -> LUIS AGOTE Y RUTA 36 | D23: ='RESUMEN TOTAL'!E26 -> Fija | E23: ='RESUMEN TOTAL'!F26 -> Radio | F23: ='RESUMEN TOTAL'!L26 -> 0 | G23: ='RESUMEN TOTAL'!M26 -> 0 | H23: ='RESUMEN TOTAL'!N26 -> 0 | I23: ='RESUMEN TOTAL'!O26 -> 0 | J23: ='RESUMEN TOTAL'!P26 -> 0 | K23: ='RESUMEN TOTAL'!Q26 -> 0 | L23: ='RESUMEN TOTAL'!R26 -> 0 | M23: ='RESUMEN TOTAL'!S26 -> 0 | ... AI23: ='RESUMEN TOTAL'!AO26 -> 0
A24: ='RESUMEN TOTAL'!A32 -> CENTRO | B24: ='RESUMEN TOTAL'!B32 -> CEN01 | C24: ='RESUMEN TOTAL'!D32 -> San Martin y 9 de Julio | D24: ='RESUMEN TOTAL'!E32 -> Fija | E24: ='RESUMEN TOTAL'!F32 -> Fibra Optica | F24: ='RESUMEN TOTAL'!L32 -> 0 | G24: ='RESUMEN TOTAL'!M32 -> 0 | H24: ='RESUMEN TOTAL'!N32 -> 0 | I24: ='RESUMEN TOTAL'!O32 -> APAGADO | J24: ='RESUMEN TOTAL'!P32 -> 0 | K24: ='RESUMEN TOTAL'!Q32 -> 0 | L24: ='RESUMEN TOTAL'!R32 -> 0 | M24: ='RESUMEN TOTAL'!S32 -> 0 | ... AI24: ='RESUMEN TOTAL'!AO32 -> 0
A25: ='RESUMEN TOTAL'!A33 -> CENTRO | B25: ='RESUMEN TOTAL'!B33 -> CEN02 | C25: ='RESUMEN TOTAL'!D33 -> San Martin y Almafuerte | D25: ='RESUMEN TOTAL'!E33 -> Fija | E25: ='RESUMEN TOTAL'!F33 -> Fibra Optica | F25: ='RESUMEN TOTAL'!L33 -> 0 | G25: ='RESUMEN TOTAL'!M33 -> 0 | H25: ='RESUMEN TOTAL'!N33 -> 0 | I25: ='RESUMEN TOTAL'!O33 -> APAGADO | J25: ='RESUMEN TOTAL'!P33 -> 0 | K25: ='RESUMEN TOTAL'!Q33 -> 0 | L25: ='RESUMEN TOTAL'!R33 -> 0 | M25: ='RESUMEN TOTAL'!S33 -> 0 | ... AI25: ='RESUMEN TOTAL'!AO33 -> 0
A26: ='RESUMEN TOTAL'!A34 -> CENTRO | B26: ='RESUMEN TOTAL'!B34 -> CEN03 | C26: ='RESUMEN TOTAL'!D34 -> San Martin y Sallares | D26: ='RESUMEN TOTAL'!E34 -> Domo | E26: ='RESUMEN TOTAL'!F34 -> Fibra Optica | F26: ='RESUMEN TOTAL'!L34 -> 0 | G26: ='RESUMEN TOTAL'!M34 -> 0 | H26: ='RESUMEN TOTAL'!N34 -> 0 | I26: ='RESUMEN TOTAL'!O34 -> 0 | J26: ='RESUMEN TOTAL'!P34 -> 0 | K26: ='RESUMEN TOTAL'!Q34 -> 0 | L26: ='RESUMEN TOTAL'!R34 -> 0 | M26: ='RESUMEN TOTAL'!S34 -> 0 | ... AI26: ='RESUMEN TOTAL'!AO34 -> 0
A27: ='RESUMEN TOTAL'!A35 -> CENTRO | B27: ='RESUMEN TOTAL'!B35 -> CEN04 | C27: ='RESUMEN TOTAL'!D35 -> San Martin y Contreras | D27: ='RESUMEN TOTAL'!E35 -> Domo | E27: ='RESUMEN TOTAL'!F35 -> Fibra Optica | F27: ='RESUMEN TOTAL'!L35 -> 0 | G27: ='RESUMEN TOTAL'!M35 -> 0 | H27: ='RESUMEN TOTAL'!N35 -> 0 | I27: ='RESUMEN TOTAL'!O35 -> 0 | J27: ='RESUMEN TOTAL'!P35 -> 0 | K27: ='RESUMEN TOTAL'!Q35 -> 0 | L27: ='RESUMEN TOTAL'!R35 -> 0 | M27: ='RESUMEN TOTAL'!S35 -> 0 | ... AI27: ='RESUMEN TOTAL'!AO35 -> 0
A28: ='RESUMEN TOTAL'!A36 -> CENTRO | B28: ='RESUMEN TOTAL'!B36 -> CEN 05 | C28: ='RESUMEN TOTAL'!D36 -> Bocuzzi e/España y San Martin | D28: ='RESUMEN TOTAL'!E36 -> DOMO | E28: ='RESUMEN TOTAL'!F36 -> Fibra Optica | F28: ='RESUMEN TOTAL'!L36 -> 0 | G28: ='RESUMEN TOTAL'!M36 -> 0 | H28: ='RESUMEN TOTAL'!N36 -> 0 | I28: ='RESUMEN TOTAL'!O36 -> 0 | J28: ='RESUMEN TOTAL'!P36 -> 0 | K28: ='RESUMEN TOTAL'!Q36 -> 0 | L28: ='RESUMEN TOTAL'!R36 -> 0 | M28: ='RESUMEN TOTAL'!S36 -> 0 | ... AI28: ='RESUMEN TOTAL'!AO36 -> 0
A29: ='RESUMEN TOTAL'!A37 -> CENTRO | B29: ='RESUMEN TOTAL'!B37 -> CEN06 | C29: ='RESUMEN TOTAL'!D37 -> Monteagudo y A.del Valle | D29: ='RESUMEN TOTAL'!E37 -> Fija | E29: ='RESUMEN TOTAL'!F37 -> Fibra Optica | F29: ='RESUMEN TOTAL'!L37 -> APAGADO | G29: ='RESUMEN TOTAL'!M37 -> APAGADO | H29: ='RESUMEN TOTAL'!N37 -> APAGADO | I29: ='RESUMEN TOTAL'!O37 -> APAGADO | J29: ='RESUMEN TOTAL'!P37 -> APAGADO | K29: ='RESUMEN TOTAL'!Q37 -> APAGADO | L29: ='RESUMEN TOTAL'!R37 -> APAGADO | M29: ='RESUMEN TOTAL'!S37 -> APAGADO | ... AI29: ='RESUMEN TOTAL'!AO37 -> 0
A30: ='RESUMEN TOTAL'!A38 -> CENTRO | B30: ='RESUMEN TOTAL'!B38 -> CEN07 | C30: ='RESUMEN TOTAL'!D38 -> San Martin y Guemes | D30: ='RESUMEN TOTAL'!E38 -> DOMO | E30: ='RESUMEN TOTAL'!F38 -> Fibra Optica | F30: ='RESUMEN TOTAL'!L38 -> 0 | G30: ='RESUMEN TOTAL'!M38 -> 0 | H30: ='RESUMEN TOTAL'!N38 -> 0 | I30: ='RESUMEN TOTAL'!O38 -> 0 | J30: ='RESUMEN TOTAL'!P38 -> 0 | K30: ='RESUMEN TOTAL'!Q38 -> 0 | L30: ='RESUMEN TOTAL'!R38 -> 0 | M30: ='RESUMEN TOTAL'!S38 -> 0 | ... AI30: ='RESUMEN TOTAL'!AO38 -> 0
A31: ='RESUMEN TOTAL'!A39 -> CENTRO | B31: ='RESUMEN TOTAL'!B39 -> CEN08 | C31: ='RESUMEN TOTAL'!D39 -> San Martin y Pte.Peron | D31: ='RESUMEN TOTAL'!E39 -> Domo | E31: ='RESUMEN TOTAL'!F39 -> Fibra Optica | F31: ='RESUMEN TOTAL'!L39 -> 0 | G31: ='RESUMEN TOTAL'!M39 -> 0 | H31: ='RESUMEN TOTAL'!N39 -> 0 | I31: ='RESUMEN TOTAL'!O39 -> 0 | J31: ='RESUMEN TOTAL'!P39 -> 0 | K31: ='RESUMEN TOTAL'!Q39 -> 0 | L31: ='RESUMEN TOTAL'!R39 -> 0 | M31: ='RESUMEN TOTAL'!S39 -> 0 | ... AI31: ='RESUMEN TOTAL'!AO39 -> 0
A32: ='RESUMEN TOTAL'!A40 -> CENTRO | B32: ='RESUMEN TOTAL'!B40 -> CEN09 | C32: ='RESUMEN TOTAL'!D40 -> Chacabuco y 25 de Mayo | D32: ='RESUMEN TOTAL'!E40 -> Domo | E32: ='RESUMEN TOTAL'!F40 -> Fibra Optica | F32: ='RESUMEN TOTAL'!L40 -> 0 | G32: ='RESUMEN TOTAL'!M40 -> 0 | H32: ='RESUMEN TOTAL'!N40 -> 0 | I32: ='RESUMEN TOTAL'!O40 -> 0 | J32: ='RESUMEN TOTAL'!P40 -> 0 | K32: ='RESUMEN TOTAL'!Q40 -> 0 | L32: ='RESUMEN TOTAL'!R40 -> 0 | M32: ='RESUMEN TOTAL'!S40 -> 0 | ... AI32: ='RESUMEN TOTAL'!AO40 -> 0
A33: ='RESUMEN TOTAL'!A41 -> CENTRO | B33: ='RESUMEN TOTAL'!B41 -> CEN10 | C33: ='RESUMEN TOTAL'!D41 -> Monteagudo y Pte. Peron | D33: ='RESUMEN TOTAL'!E41 -> Domo | E33: ='RESUMEN TOTAL'!F41 -> Fibra Optica | F33: ='RESUMEN TOTAL'!L41 -> 0 | G33: ='RESUMEN TOTAL'!M41 -> 0 | H33: ='RESUMEN TOTAL'!N41 -> 0 | I33: ='RESUMEN TOTAL'!O41 -> 0 | J33: ='RESUMEN TOTAL'!P41 -> 0 | K33: ='RESUMEN TOTAL'!Q41 -> 0 | L33: ='RESUMEN TOTAL'!R41 -> 0 | M33: ='RESUMEN TOTAL'!S41 -> 0 | ... AI33: ='RESUMEN TOTAL'!AO41 -> 0
A34: ='RESUMEN TOTAL'!A42 -> CENTRO | B34: ='RESUMEN TOTAL'!B42 -> CEN11 | C34: ='RESUMEN TOTAL'!D42 -> Monteagudo y Bocuzzi | D34: ='RESUMEN TOTAL'!E42 -> Domo | E34: ='RESUMEN TOTAL'!F42 -> Fibra Optica | F34: ='RESUMEN TOTAL'!L42 -> 0 | G34: ='RESUMEN TOTAL'!M42 -> 0 | H34: ='RESUMEN TOTAL'!N42 -> 0 | I34: ='RESUMEN TOTAL'!O42 -> 0 | J34: ='RESUMEN TOTAL'!P42 -> 0 | K34: ='RESUMEN TOTAL'!Q42 -> 0 | L34: ='RESUMEN TOTAL'!R42 -> 0 | M34: ='RESUMEN TOTAL'!S42 -> 0 | ... AI34: ='RESUMEN TOTAL'!AO42 -> 0
A35: ='RESUMEN TOTAL'!A43 -> CENTRO | B35: ='RESUMEN TOTAL'!B43 -> CEN 12 | C35: ='RESUMEN TOTAL'!D43 -> Monteagudo y Mitre | D35: ='RESUMEN TOTAL'!E43 -> Domo | E35: ='RESUMEN TOTAL'!F43 -> Fibra Optica | F35: ='RESUMEN TOTAL'!L43 -> 0 | G35: ='RESUMEN TOTAL'!M43 -> 0 | H35: ='RESUMEN TOTAL'!N43 -> 0 | I35: ='RESUMEN TOTAL'!O43 -> 0 | J35: ='RESUMEN TOTAL'!P43 -> 0 | K35: ='RESUMEN TOTAL'!Q43 -> 0 | L35: ='RESUMEN TOTAL'!R43 -> APAGADO | M35: ='RESUMEN TOTAL'!S43 -> APAGADO | ... AI35: ='RESUMEN TOTAL'!AO43 -> 0
... A70: ='RESUMEN TOTAL'!A78 -> CENTRO | B70: ='RESUMEN TOTAL'!B78 -> CEN47 | C70: ='RESUMEN TOTAL'!D78 -> Sallares y Brown | D70: ='RESUMEN TOTAL'!E78 -> Domo | E70: ='RESUMEN TOTAL'!F78 -> Fibra Optica | F70: ='RESUMEN TOTAL'!L78 -> 0 | G70: ='RESUMEN TOTAL'!M78 -> 0 | H70: ='RESUMEN TOTAL'!N78 -> 0 | I70: ='RESUMEN TOTAL'!O78 -> APAGADO | J70: ='RESUMEN TOTAL'!P78 -> APAGADO | K70: ='RESUMEN TOTAL'!Q78 -> 0 | L70: ='RESUMEN TOTAL'!R78 -> APAGADO | M70: ='RESUMEN TOTAL'!S78 -> APAGADO | ... AI70: ='RESUMEN TOTAL'!AO78 -> 0
A71: ='RESUMEN TOTAL'!A79 -> CENTRO | B71: ='RESUMEN TOTAL'!B79 -> CEN48 | C71: ='RESUMEN TOTAL'!D79 -> Velez Sarsfield y Las Heras | D71: ='RESUMEN TOTAL'!E79 -> Domo | E71: ='RESUMEN TOTAL'!F79 -> GPON | F71: ='RESUMEN TOTAL'!L79 -> 0 | G71: ='RESUMEN TOTAL'!M79 -> 0 | H71: ='RESUMEN TOTAL'!N79 -> 0 | I71: ='RESUMEN TOTAL'!O79 -> 0 | J71: ='RESUMEN TOTAL'!P79 -> 0 | K71: ='RESUMEN TOTAL'!Q79 -> APAGADO | L71: ='RESUMEN TOTAL'!R79 -> 0 | M71: ='RESUMEN TOTAL'!S79 -> 0 | ... Z71: ='RESUMEN TOTAL'!AF79 -> 0 | AA71: ='RESUMEN TOTAL'!#REF! -> #REF! | AB71: ='RESUMEN TOTAL'!AH79 -> 0 | AC71: ='RESUMEN TOTAL'!AI79 -> 0 | AD71: ='RESUMEN TOTAL'!AJ79 -> 0 | AE71: ='RESUMEN TOTAL'!AK79 -> 0 | AF71: ='RESUMEN TOTAL'!AL79 -> 0 | AG71: ='RESUMEN TOTAL'!AM79 -> 0 | AH71: ='RESUMEN TOTAL'!AN79 -> 0 | AI71: ='RESUMEN TOTAL'!AO79 -> 0
A72: ='RESUMEN TOTAL'!A80 -> CENTRO | B72: ='RESUMEN TOTAL'!B80 -> CEN49 | C72: ='RESUMEN TOTAL'!D80 -> Av. San Martin y Florencio Sanchez | D72: ='RESUMEN TOTAL'!E80 -> Domo | E72: ='RESUMEN TOTAL'!F80 -> Fibra Optica | F72: ='RESUMEN TOTAL'!L80 -> 0 | G72: ='RESUMEN TOTAL'!M80 -> 0 | H72: ='RESUMEN TOTAL'!N80 -> 0 | I72: ='RESUMEN TOTAL'!O80 -> 0 | J72: ='RESUMEN TOTAL'!P80 -> 0 | K72: ='RESUMEN TOTAL'!Q80 -> 0 | L72: ='RESUMEN TOTAL'!R80 -> 0 | M72: ='RESUMEN TOTAL'!S80 -> 0 | ... AI72: ='RESUMEN TOTAL'!AO80 -> 0
A73: ='RESUMEN TOTAL'!A81 -> CENTRO | B73: ='RESUMEN TOTAL'!B81 -> CEN 50 | C73: ='RESUMEN TOTAL'!D81 -> Av. San Martin y Newbery | D73: ='RESUMEN TOTAL'!E81 -> Domo | E73: ='RESUMEN TOTAL'!F81 -> Fibra Optica | F73: ='RESUMEN TOTAL'!L81 -> 0 | G73: ='RESUMEN TOTAL'!M81 -> 0 | H73: ='RESUMEN TOTAL'!N81 -> 0 | I73: ='RESUMEN TOTAL'!O81 -> APAGADO | J73: ='RESUMEN TOTAL'!P81 -> 0 | K73: ='RESUMEN TOTAL'!Q81 -> 0 | L73: ='RESUMEN TOTAL'!R81 -> 0 | M73: ='RESUMEN TOTAL'!S81 -> 0 | ... AI73: ='RESUMEN TOTAL'!AO81 -> 0
A74: ='RESUMEN TOTAL'!A82 -> CENTRO | B74: ='RESUMEN TOTAL'!B82 -> CEN 51 | C74: ='RESUMEN TOTAL'!D82 -> ILLIA Y LAS HERAS | D74: ='RESUMEN TOTAL'!E82 -> FIJA | E74: ='RESUMEN TOTAL'!F82 -> Fibra Optica | F74: ='RESUMEN TOTAL'!L82 -> 0 | G74: ='RESUMEN TOTAL'!M82 -> 0 | H74: ='RESUMEN TOTAL'!N82 -> 0 | I74: ='RESUMEN TOTAL'!O82 -> 0 | J74: ='RESUMEN TOTAL'!P82 -> 0 | K74: ='RESUMEN TOTAL'!Q82 -> 0 | L74: ='RESUMEN TOTAL'!R82 -> 0 | M74: ='RESUMEN TOTAL'!S82 -> 0 | ... AI74: ='RESUMEN TOTAL'!AO82 -> 0
A75: ='RESUMEN TOTAL'!A83 -> CENTRO | B75: ='RESUMEN TOTAL'!B83 -> CEN52 | C75: ='RESUMEN TOTAL'!D83 -> San Martin y Almafuerte (ex San Martin y Dorrego) | D75: ='RESUMEN TOTAL'!E83 -> DOMO | E75: ='RESUMEN TOTAL'!F83 -> Radio | F75: ='RESUMEN TOTAL'!L83 -> 0 | G75: ='RESUMEN TOTAL'!M83 -> 0 | H75: ='RESUMEN TOTAL'!N83 -> 0 | I75: ='RESUMEN TOTAL'!O83 -> 0 | J75: ='RESUMEN TOTAL'!P83 -> 0 | K75: ='RESUMEN TOTAL'!Q83 -> 0 | L75: ='RESUMEN TOTAL'!R83 -> 0 | M75: ='RESUMEN TOTAL'!S83 -> 0 | ... AI75: ='RESUMEN TOTAL'!AO83 -> 0
A76: ='RESUMEN TOTAL'!A84 -> CENTRO | B76: ='RESUMEN TOTAL'!B84 -> CEN 53 | C76: ='RESUMEN TOTAL'!D84 -> GUTIERREZ Y BROWN | D76: ='RESUMEN TOTAL'!E84 -> Domo | E76: ='RESUMEN TOTAL'!F84 -> Fibra Optica | F76: ='RESUMEN TOTAL'!L84 -> 0 | G76: ='RESUMEN TOTAL'!M84 -> 0 | H76: ='RESUMEN TOTAL'!N84 -> 0 | I76: ='RESUMEN TOTAL'!O84 -> 0 | J76: ='RESUMEN TOTAL'!P84 -> 0 | K76: ='RESUMEN TOTAL'!Q84 -> 0 | L76: ='RESUMEN TOTAL'!R84 -> 0 | M76: ='RESUMEN TOTAL'!S84 -> 0 | ... AI76: ='RESUMEN TOTAL'!AO84 -> 0
A77: ='RESUMEN TOTAL'!A85 -> CENTRO | B77: ='RESUMEN TOTAL'!B85 -> CEN 54 | C77: ='RESUMEN TOTAL'!D85 -> GUTIERREZ Y PRINGLES | D77: ='RESUMEN TOTAL'!E85 -> Domo | E77: ='RESUMEN TOTAL'!F85 -> Fibra Optica | F77: ='RESUMEN TOTAL'!L85 -> 0 | G77: ='RESUMEN TOTAL'!M85 -> 0 | H77: ='RESUMEN TOTAL'!N85 -> 0 | I77: ='RESUMEN TOTAL'!O85 -> 0 | J77: ='RESUMEN TOTAL'!P85 -> 0 | K77: ='RESUMEN TOTAL'!Q85 -> 0 | L77: ='RESUMEN TOTAL'!R85 -> 0 | M77: ='RESUMEN TOTAL'!S85 -> 0 | ... AI77: ='RESUMEN TOTAL'!AO85 -> 0
A78: ='RESUMEN TOTAL'!A86 -> CENTRO | B78: ='RESUMEN TOTAL'!B86 -> CEN 55 | C78: ='RESUMEN TOTAL'!D86 -> BOUREL Y URQUIZA | D78: ='RESUMEN TOTAL'!E86 -> Domo | E78: ='RESUMEN TOTAL'!F86 -> Radio | F78: ='RESUMEN TOTAL'!L86 -> 0 | G78: ='RESUMEN TOTAL'!M86 -> 0 | H78: ='RESUMEN TOTAL'!N86 -> 0 | I78: ='RESUMEN TOTAL'!O86 -> 0 | J78: ='RESUMEN TOTAL'!P86 -> 0 | K78: ='RESUMEN TOTAL'!Q86 -> 0 | L78: ='RESUMEN TOTAL'!R86 -> 0 | M78: ='RESUMEN TOTAL'!S86 -> 0 | ... AI78: ='RESUMEN TOTAL'!AO86 -> 0
A79: ='RESUMEN TOTAL'!A87 -> CENTRO | B79: ='RESUMEN TOTAL'!B87 -> CEN 56 | C79: ='RESUMEN TOTAL'!D87 -> Newbery y Falucho | D79: ='RESUMEN TOTAL'!E87 -> DOMO | E79: ='RESUMEN TOTAL'!F87 -> Radio | F79: ='RESUMEN TOTAL'!L87 -> 0 | G79: ='RESUMEN TOTAL'!M87 -> 0 | H79: ='RESUMEN TOTAL'!N87 -> 0 | I79: ='RESUMEN TOTAL'!O87 -> 0 | J79: ='RESUMEN TOTAL'!P87 -> 0 | K79: ='RESUMEN TOTAL'!Q87 -> 0 | L79: ='RESUMEN TOTAL'!R87 -> 0 | M79: ='RESUMEN TOTAL'!S87 -> 0 | ... AI79: ='RESUMEN TOTAL'!AO87 -> 0
A80: ='RESUMEN TOTAL'!A88 -> CENTRO | B80: ='RESUMEN TOTAL'!B88 -> CEN 57 | C80: ='RESUMEN TOTAL'!D88 -> 25 DE MAYO Y DORREGO | D80: ='RESUMEN TOTAL'!E88 -> DOMO | E80: ='RESUMEN TOTAL'!F88 -> Fibra Optica | F80: ='RESUMEN TOTAL'!L88 -> 0 | G80: ='RESUMEN TOTAL'!M88 -> 0 | H80: ='RESUMEN TOTAL'!N88 -> 0 | I80: ='RESUMEN TOTAL'!O88 -> 0 | J80: ='RESUMEN TOTAL'!P88 -> 0 | K80: ='RESUMEN TOTAL'!Q88 -> 0 | L80: ='RESUMEN TOTAL'!R88 -> 0 | M80: ='RESUMEN TOTAL'!S88 -> 0 | ... AI80: ='RESUMEN TOTAL'!AO88 -> 0
...
