Workbook
Name _25_de_agosto: 'RESUMEN TOTAL'!$A$7:$D$465
Name _25_de_agosto_3: 'RESUMEN TOTAL'!$A$7:$D$477
Name _30_mar: #REF!
Name BONOMOcam: Hoja1!$B$2
Name CANTIDAD_DE_CAMARAS: 'RESUMEN TOTAL'!$B$1
Name COSEIDIcam: Hoja1!$B$4

Sheet RESUMEN TOTAL
A1: CANTIDAD DE CAMARAS | B1: =COUNTA(B8:B702) -> 541 | D1: PORCIENTO DE CAIDAS | M1: =(M3)/(M2+M3) -> 0.11311475 | N1: =(N3)/(N2+N3) -> 0.11456628 | O1: =(O3)/(O2+O3) -> 0.11165846 | P1: =(P3)/(P2+P3) -> 0.10430464 | Q1: =(Q3)/(Q2+Q3) -> 0.089225589 | R1: =(R3)/(R2+R3) -> 0.12882448 | S1: =(S3)/(S2+S3) -> 0.11601307 | T1: =(T3)/(T2+T3) -> 0.10281924 | ... Y1: =(Y3)/(Y2+Y3) -> 0.086148649 | AA1: =(AA3)/(AA2+AA3) -> 0.090756303 | AB1: =(AB3)/(AB2+AB3) -> 0.090756303 | AC1: =(AC3)/(AC2+AC3) -> 0.092281879 | AD1: =(AD3)/(AD2+AD3) -> 0.083050847 | AE1: =(AE3)/(AE2+AE3) -> 0.12600969 | AF1: =(AF3)/(AF2+AF3) -> 0.13716108 | AG1: =(AG3)/(AG2+AG3) -> 0.18768769 | AH1: =(AH3)/(AH2+AH3) -> 0.14937107 | ... AP1: =(AP3)/(AP2+AP3) -> 0
D2: FUNCIONAN | M2: =CANTIDAD_DE_CAMARAS -> 541 | N2: =CANTIDAD_DE_CAMARAS -> 541 | O2: =CANTIDAD_DE_CAMARAS -> 541 | P2: =CANTIDAD_DE_CAMARAS -> 541 | Q2: =CANTIDAD_DE_CAMARAS -> 541 | R2: =CANTIDAD_DE_CAMARAS -> 541 | S2: =CANTIDAD_DE_CAMARAS -> 541 | T2: =CANTIDAD_DE_CAMARAS -> 541 | ... AP2: =CANTIDAD_DE_CAMARAS -> 541
D3: CAIDAS | M3: =COUNTIF(M7:M702, "apagado") -> 69 | N3: =COUNTIF(N7:N702, "apagado") -> 70 | O3: =COUNTIF(O7:O702, "apagado") -> 68 | P3: =COUNTIF(P7:P702, "apagado") -> 63 | Q3: =COUNTIF(Q7:Q702, "apagado") -> 53 | R3: =COUNTIF(R7:R702, "apagado") -> 80 | S3: =COUNTIF(S7:S702, "apagado") -> 71 | T3: =COUNTIF(T7:T702, "apagado") -> 62 | ... AP3: =COUNTIF(AP7:AP702, "apagado") -> 0
D4: APAGADOS FIBRA | M4: =COUNTIFS(M8:M656, "=APAGADO",F8:F656,"=Fibra Optica") -> 29 | N4: =COUNTIFS(N8:N656, "=APAGADO",F8:F656,"=Fibra Optica") -> 29 | O4: =COUNTIFS(O8:O656, "=APAGADO",F8:F656,"=Fibra Optica") -> 29 | P4: =COUNTIFS(P8:P656, "=APAGADO",F8:F656,"=Fibra Optica") -> 27 | Q4: =COUNTIFS(Q8:Q656, "=APAGADO",F8:F656,"=Fibra Optica") -> 23 | R4: =COUNTIFS(R8:R656, "=APAGADO",F8:F656,"=Fibra Optica") -> 46 | S4: =COUNTIFS(S8:S656, "=APAGADO",F8:F656,"=Fibra Optica") -> 32 | T4: =COUNTIFS(T8:T656, "=APAGADO",F8:F656,"=Fibra Optica") -> 26 | U4: =COUNTIFS(U8:U656, "=APAGADO",F8:F656,"=Fibra Optica") -> 24 | V4: =COUNTIFS(V8:V656, "=APAGADO",F8:F656,"=Fibra Optica") -> 27 | W4: =COUNTIFS(W8:W656, "=APAGADO",F8:F656,"=Fibra Optica") -> 45 | X4: =COUNTIFS(X8:X656, "=APAGADO",F8:F656,"=Fibra Optica") -> 42 | Y4: =COUNTIFS(Y8:Y656, "=APAGADO",F8:F656,"=Fibra Optica") -> 24 | Z4: =COUNTIFS(Z8:Z656, "=APAGADO",F8:F656,"=Fibra Optica") -> 22 | AA4: =COUNTIFS(AA8:AA656, "=APAGADO",F8:F656,"=Fibra Optica") -> 28 | AB4: =COUNTIFS(AB8:AB656, "=APAGADO",F8:F656,"=Fibra Optica") -> 24 | AC4: =COUNTIFS(AC8:AC656, "=APAGADO",F8:F656,"=Fibra Optica") -> 25 | AD4: =COUNTIFS(AD8:AD656, "=APAGADO",F8:F656,"=Fibra Optica") -> 19 | AE4: =COUNTIFS(AE8:AE656, "=APAGADO",F8:F656,"=Fibra Optica") -> 40 | AF4: =COUNTIFS(AF8:AF656, "=APAGADO",F8:F656,"=Fibra Optica") -> 44 | AG4: =COUNTIFS(AG8:AG656, "=APAGADO",F8:F656,"=Fibra Optica") -> 78 | AH4: =COUNTIFS(AH8:AH656, "=APAGADO",F8:F656,"=Fibra Optica") -> 49 | AI4: =COUNTIFS(AI8:AI656, "=APAGADO",F8:F656,"=Fibra Optica") -> 23 | AJ4: =COUNTIFS(AJ8:AJ656, "=APAGADO",F8:F656,"=Fibra Optica") -> 20 | AK4: =COUNTIFS(AK8:AK656, "=APAGADO",F8:F656,"=Fibra Optica") -> 20 | AL4: =COUNTIFS(AL8:AL656, "=APAGADO",F8:F656,"=Fibra Optica") -> 0 | AM4: =COUNTIFS(AM8:AM656, "=APAGADO",F8:F656,"=Fibra Optica") -> 0 | AN4: =COUNTIFS(AN8:AN656, "=APAGADO",F8:F656,"=Fibra Optica") -> 0 | AO4: =COUNTIFS(AO8:AO656, "=APAGADO",F8:F656,"=Fibra Optica") -> 0 | AP4: =COUNTIFS(AP8:AP656, "=APAGADO",F8:F656,"=Fibra Optica") -> 0
D5: APAGADOS RADIO | M5: =COUNTIFS(M8:M656, "=APAGADO",F8:F656,"=RADIO") -> 11 | N5: =COUNTIFS(N8:N656, "=APAGADO",F8:F656,"=RADIO") -> 12 | O5: =COUNTIFS(O8:O656, "=APAGADO",F8:F656,"=RADIO") -> 11 | P5: =COUNTIFS(P8:P656, "=APAGADO",F8:F656,"=RADIO") -> 12 | Q5: =COUNTIFS(Q8:Q656, "=APAGADO",F8:F656,"=RADIO") -> 11 | R5: =COUNTIFS(R8:R656, "=APAGADO",F8:F656,"=RADIO") -> 11 | S5: =COUNTIFS(S8:S656, "=APAGADO",F8:F656,"=RADIO") -> 14 | T5: =COUNTIFS(T8:T656, "=APAGADO",F8:F656,"=RADIO") -> 14 | U5: =COUNTIFS(U8:U656, "=APAGADO",F8:F656,"=RADIO") -> 10 | V5: =COUNTIFS(V8:V656, "=APAGADO",F8:F656,"=RADIO") -> 13 | W5: =COUNTIFS(W8:W656, "=APAGADO",F8:F656,"=RADIO") -> 10 | X5: =COUNTIFS(X8:X656, "=APAGADO",F8:F656,"=RADIO") -> 8 | Y5: =COUNTIFS(Y8:Y656, "=APAGADO",F8:F656,"=RADIO") -> 8 | Z5: =COUNTIFS(Z8:Z656, "=APAGADO",F8:F656,"=RADIO") -> 8 | AA5: =COUNTIFS(AA8:AA656, "=APAGADO",F8:F656,"=RADIO") -> 9 | AB5: =COUNTIFS(AB8:AB656, "=APAGADO",F8:F656,"=RADIO") -> 13 | AC5: =COUNTIFS(AC8:AC656, "=APAGADO",F8:F656,"=RADIO") -> 11 | AD5: =COUNTIFS(AD8:AD656, "=APAGADO",F8:F656,"=RADIO") -> 12 | AE5: =COUNTIFS(AE8:AE656, "=APAGADO",F8:F656,"=RADIO") -> 17 | AF5: =COUNTIFS(AF8:AF656, "=APAGADO",F8:F656,"=RADIO") -> 19 | AG5: =COUNTIFS(AG8:AG656, "=APAGADO",F8:F656,"=RADIO") -> 21 | AH5: =COUNTIFS(AH8:AH656, "=APAGADO",F8:F656,"=RADIO") -> 21 | AI5: =COUNTIFS(AI8:AI656, "=APAGADO",F8:F656,"=RADIO") -> 12 | AJ5: =COUNTIFS(AJ8:AJ656, "=APAGADO",F8:F656,"=RADIO") -> 10 | AK5: =COUNTIFS(AK8:AK656, "=APAGADO",F8:F656,"=RADIO") -> 10 | AL5: =COUNTIFS(AL8:AL656, "=APAGADO",F8:F656,"=RADIO") -> 0 | AM5: =COUNTIFS(AM8:AM656, "=APAGADO",F8:F656,"=RADIO") -> 0 | AN5: =COUNTIFS(AN8:AN656, "=APAGADO",F8:F656,"=RADIO") -> 0 | AO5: =COUNTIFS(AO8:AO656, "=APAGADO",F8:F656,"=RADIO") -> 0 | AP5: =COUNTIFS(AP8:AP656, "=APAGADO",F8:F656,"=RADIO") -> 0
D6: APAGADOS ANTENA | M6: =COUNTIFS(M8:M656, "=APAGADO",F8:F656,"=PTO A FO") -> 6 | N6: =COUNTIFS(N8:N656, "=APAGADO",F8:F656,"=PTO A FO") -> 7 | O6: =COUNTIFS(O8:O656, "=APAGADO",F8:F656,"=PTO A FO") -> 6 | P6: =COUNTIFS(P8:P656, "=APAGADO",F8:F656,"=PTO A FO") -> 5 | Q6: =COUNTIFS(Q8:Q656, "=APAGADO",F8:F656,"=PTO A FO") -> 5 | R6: =COUNTIFS(R8:R656, "=APAGADO",F8:F656,"=PTO A FO") -> 6 | S6: =COUNTIFS(S8:S656, "=APAGADO",F8:F656,"=PTO A FO") -> 6 | T6: =COUNTIFS(T8:T656, "=APAGADO",F8:F656,"=PTO A FO") -> 6 | U6: =COUNTIFS(U8:U656, "=APAGADO",F8:F656,"=PTO A FO") -> 6 | V6: =COUNTIFS(V8:V656, "=APAGADO",F8:F656,"=PTO A FO") -> 6 | W6: =COUNTIFS(W8:W656, "=APAGADO",F8:F656,"=PTO A FO") -> 6 | X6: =COUNTIFS(X8:X656, "=APAGADO",F8:F656,"=PTO A FO") -> 4 | Y6: =COUNTIFS(Y8:Y656, "=APAGADO",F8:F656,"=PTO A FO") -> 3 | Z6: =COUNTIFS(Z8:Z656, "=APAGADO",F8:F656,"=PTO A FO") -> 3 | AA6: =COUNTIFS(AA8:AA656, "=APAGADO",F8:F656,"=PTO A FO") -> 3 | AB6: =COUNTIFS(AB8:AB656, "=APAGADO",F8:F656,"=PTO A FO") -> 3 | AC6: =COUNTIFS(AC8:AC656, "=APAGADO",F8:F656,"=PTO A FO") -> 3 | AD6: =COUNTIFS(AD8:AD656, "=APAGADO",F8:F656,"=PTO A FO") -> 3 | AE6: =COUNTIFS(AE8:AE656, "=APAGADO",F8:F656,"=PTO A FO") -> 6 | AF6: =COUNTIFS(AF8:AF656, "=APAGADO",F8:F656,"=PTO A FO") -> 7 | AG6: =COUNTIFS(AG8:AG656, "=APAGADO",F8:F656,"=PTO A FO") -> 7 | AH6: =COUNTIFS(AH8:AH656, "=APAGADO",F8:F656,"=PTO A FO") -> 8 | AI6: =COUNTIFS(AI8:AI656, "=APAGADO",F8:F656,"=PTO A FO") -> 5 | AJ6: =COUNTIFS(AJ8:AJ656, "=APAGADO",F8:F656,"=PTO A FO") -> 4 | AK6: =COUNTIFS(AK8:AK656, "=APAGADO",F8:F656,"=PTO A FO") -> 4 | AL6: =COUNTIFS(AL8:AL656, "=APAGADO",F8:F656,"=PTO A FO") -> 0 | AM6: =COUNTIFS(AM8:AM656, "=APAGADO",F8:F656,"=PTO A FO") -> 0 | AN6: =COUNTIFS(AN8:AN656, "=APAGADO",F8:F656,"=PTO A FO") -> 0 | AO6: =COUNTIFS(AO8:AO656, "=APAGADO",F8:F656,"=PTO A FO") -> 0 | AP6: =COUNTIFS(AP8:AP656, "=APAGADO",F8:F656,"=PTO A FO") -> 0
A7: Barrio | B7: [Denominacion] | C7: [Empresa Mantenimiento] | D7: [Ubicacion] | E7: [Tipo de Camara] | F7: [Tipo de Conexion] | G7: Destino | I7: DIAS FUNCIONANDO | J7: MAC | K7: DIAS CAIDA | L7: EFECTIVIDAD | M7: 45901 | N7: 45902 | O7: 45903 | P7: 45904 | Q7: 45905 | R7: 45906 | S7: 45907 | T7: 45908 | U7: 45909 | V7: 45910 | W7: 45911 | X7: 45912 | Y7: 45913 | Z7: 45914 | AA7: 45915 | AB7: 45916 | AC7: 45917 | AD7: 45918 | AE7: 45919 | AF7: 45920 | AG7: 45921 | AH7: 45922 | AI7: 45923 | AJ7: 45924 | AK7: 45925 | AL7: 45926 | AM7: 45927 | AN7: 45928 | AO7: 45929 | AP7: 45930
A8: ALTAMIRA | B8: ALT01 | C8: BONOMO | D8: Calchaqui y Sgto. Cabral | E8: Domo | F8: Fibra Optica | H8: 172.20.10.6 | I8: =COUNTIF(M8:AN8,"") -> 28 | J8: 00-07-5F-87-83-56 | K8: =COUNTIF(M8:AN8,"APAGADO") -> 0 | L8: =(I8)/(K8+I8) -> 1
A9: ALTAMIRA | B9: ALT02 | C9: BONOMO | D9: Calchaqui y Lope de Vega | E9: Domo | F9: PTO A FO | G9: CABRAL Y CALCHAQUI | H9: 172.20.12.218 | I9: =COUNTIF(M9:AN9,"") -> 28 | J9: 00-04-63-50-42-A4 | K9: =COUNTIF(M9:AN9,"APAGADO") -> 0 | L9: =(I9)/(K9+I9) -> 1
A10: ALTAMIRA | B10: ALT 03 | C10: BONOMO | D10: Bombero Galarza y Necochea | E10: Domo | F10: GPON | H10: 172.20.12.54 | I10: =COUNTIF(M10:AN10,"") -> 28 | J10: 00-07-5F-87-9D-EF | K10: =COUNTIF(M10:AN10,"APAGADO") -> 0 | L10: =(I10)/(K10+I10) -> 1
A11: ALTAMIRA | B11: ALT 04 | C11: BONOMO | D11: Francia y Necochea | E11: Domo | F11: GPON | H11: 172.20.12.55 | I11: =COUNTIF(M11:AN11,"") -> 28 | J11: 00-04-63-59-22-57 | K11: =COUNTIF(M11:AN11,"APAGADO") -> 0 | L11: =(I11)/(K11+I11) -> 1
A12: ALTAMIRA | B12: ALT05 | C12: BONOMO | D12: Av. Calchaqui y Bombero Galarza | E12: Domo | F12: GPON | G12: NECOCHEA Y GALARZA | H12: 172.20.12.216 | I12: =COUNTIF(M12:AN12,"") -> 28 | J12: 00-07-5F-77-02-85 | K12: =COUNTIF(M12:AN12,"APAGADO") -> 0 | L12: =(I12)/(K12+I12) -> 1
A13: ALTAMIRA | B13: ALT 06 | C13: BONOMO | D13: LOPE DE VEGA Y NECOCHEA | E13: Domo | F13: GPON | G13: NECOCHEA Y GALARZA | H13: 172.20.12.12 | I13: =COUNTIF(M13:AN13,"") -> 28 | J13: 00-04-63-4F-DD-DB | K13: =COUNTIF(M13:AN13,"APAGADO") -> 0 | L13: =(I13)/(K13+I13) -> 1
A14: ALTAMIRA | B14: ALT07 | C14: BONOMO | D14: AV. CALCHAQUI Y AV. DEL TRABAJO | E14: DOMO | F14: PTO A FO | G14: CABRAL Y CALCHAQUI | H14: 172.20.10.57 | I14: =COUNTIF(M14:AN14,"") -> 28 | J14: 00-04-63-4F-DE-CA | K14: =COUNTIF(M14:AN14,"APAGADO") -> 0 | L14: =(I14)/(K14+I14) -> 1
A15: ALTAMIRA | B15: ALT 08 | C15: BONOMO | D15: HUMAITA Y NECOCHEA | E15: DOMO | F15: Fibra Optica | H15: 172.20.11.215 | I15: =COUNTIF(M15:AN15,"") -> 27 | J15: 00-07-5F-BE-59-2D | K15: =COUNTIF(M15:AN15,"APAGADO") -> 1 | L15: =(I15)/(K15+I15) -> 0.96428571 | V15: APAGADO
A16: ALTAMIRA | B16: ALT 09 | C16: BONOMO | D16: NECOCHEA Y CURUPAITY | E16: DOMO | F16: Fibra Optica | H16: 172.20.11.216 | I16: =COUNTIF(M16:AN16,"") -> 28 | J16: 00-07-5F-BE-59-27 | K16: =COUNTIF(M16:AN16,"APAGADO") -> 0 | L16: =(I16)/(K16+I16) -> 1
A17: ALTAMIRA | B17: ALT 10 | C17: BONOMO | D17: Calchaqui y Francia | E17: Domo | F17: GPON | H17: 172.20.12.156 | I17: =COUNTIF(M17:AN17,"") -> 25 | J17: 00-07-5F-AB-BB-41 | K17: =COUNTIF(M17:AN17,"APAGADO") -> 3 | L17: =(I17)/(K17+I17) -> 0.89285714 | M17: APAGADO | N17: APAGADO | O17: APAGADO
A18: ALTAMIRA | B18: ALT 11 | C18: BONOMO | D18: CALCHAQUÍ Y GALARZA FIJA | E18: Fija | F18: Fibra Optica | H18: 172.20.12.241 | I18: =COUNTIF(M18:AN18,"") -> 28 | K18: =COUNTIF(M18:AN18,"APAGADO") -> 0 | L18: =(I18)/(K18+I18) -> 1
A19: AGUSTIN RAMIREZ | B19: ARA 01 | C19: BONOMO | D19: Malambo y Tranquera | E19: Domo | F19: Fibra Optica | H19: 172.20.12.110 | I19: =COUNTIF(M19:AN19,"") -> 28 | J19: 00-04-63-4F-DB-B6 | K19: =COUNTIF(M19:AN19,"APAGADO") -> 0 | L19: =(I19)/(K19+I19) -> 1
A20: AGUSTIN RAMIREZ | B20: ARA 02 | C20: BONOMO | D20: El malambo y La Tranquera | E20: Fija | F20: GPON | H20: 172.20.12.235 | J20: C0:6D:ED:A3:E6:63
A21: AGUSTIN RAMIREZ | B21: ARA 03 | C21: BONOMO | D21: 437 Y La Tranquera | E21: Fija | F21: GPON | H21: 172.20.10.232 | J21: C0:6D:ED:A3:66:6A
A22: BELGRANO | B22: BEL 01 | C22: BONOMO | D22: San Martin y Dardo Rocha | E22: DOMO | F22: Fibra Optica | H22: 172.20.12.64 | I22: =COUNTIF(M22:AN22,"") -> 3 | J22: 00-07-5F-81-B9-E9 | K22: =COUNTIF(M22:AN22,"APAGADO") -> 25 | L22: =(I22)/(K22+I22) -> 0.10714286 | M22: APAGADO | N22: APAGADO | O22: APAGADO | P22: APAGADO | Q22: APAGADO | R22: APAGADO | S22: APAGADO | T22: APAGADO | U22: APAGADO | V22: APAGADO | W22: APAGADO | X22: APAGADO | Y22: APAGADO | Z22: APAGADO | AA22: APAGADO | AB22: APAGADO | AC22: APAGADO | AD22: APAGADO | AE22: APAGADO | AF22: APAGADO | AG22: APAGADO | AH22: APAGADO | AI22: APAGADO | AJ22: APAGADO | AK22: APAGADO
A23: BELGRANO | B23: BEL 02 | C23: BONOMO | D23: Guardia vieja y Fronteriz | E23: DOMO | F23: Fibra Optica | H23: 172.20.10.117 | I23: =COUNTIF(M23:AN23,"") -> 28 | J23: E4-30-22-4F-9E-62 | K23: =COUNTIF(M23:AN23,"APAGADO") -> 0 | L23: =(I23)/(K23+I23) -> 1
A24: BOSQUES CENTRO | B24: BOSQC 01 | C24: COSEIDI | D24: LUIS AGOTE E/DANUNCIO Y CAMPOAMOR | E24: Fija | F24: Radio | H24: 172.20.11.15 | I24: =COUNTIF(M24:AN24,"") -> 24 | J24: 00-07-5F-B7-56-89 | K24: =COUNTIF(M24:AN24,"APAGADO") -> 4 | L24: =(I24)/(K24+I24) -> 0.85714286 | AE24: APAGADO | AF24: APAGADO | AG24: APAGADO | AH24: APAGADO
A25: BOSQUES CENTRO | B25: BOSQC 02 | C25: COSEIDI | D25: LUIS AGOTE E/DANUNCIO Y CAMPOAMOR | E25: Fija | F25: Radio | H25: 172.20.11.16 | I25: =COUNTIF(M25:AN25,"") -> 24 | J25: 00-07-5F-B4-17-A8 | K25: =COUNTIF(M25:AN25,"APAGADO") -> 4 | L25: =(I25)/(K25+I25) -> 0.85714286 | AE25: APAGADO | AF25: APAGADO | AG25: APAGADO | AH25: APAGADO
A26: BOSQUES CENTRO | B26: BOSQC 03 | C26: COSEIDI | D26: BENAVENTE Y LUIS AGOTE | E26: Fija | F26: Radio | H26: 172.20.11.13 | I26: =COUNTIF(M26:AN26,"") -> 24 | J26: 00-07-5F-B6-B8-A5 | K26: =COUNTIF(M26:AN26,"APAGADO") -> 4 | L26: =(I26)/(K26+I26) -> 0.85714286 | AE26: APAGADO | AF26: APAGADO | AG26: APAGADO | AH26: APAGADO
A27: BOSQUES CENTRO | B27: BOSQC 04 | C27: COSEIDI | D27: BENAVENTE Y LUIS AGOTE | E27: Fija | F27: Radio | H27: 172.20.11.113 | I27: =COUNTIF(M27:AN27,"") -> 24 | J27: 00-07-5F-B6-B8-D3 | K27: =COUNTIF(M27:AN27,"APAGADO") -> 4 | L27: =(I27)/(K27+I27) -> 0.85714286 | AE27: APAGADO | AF27: APAGADO | AG27: APAGADO | AH27: APAGADO
A28: BOSQUES CENTRO | B28: BOSQC 05 | C28: COSEIDI | D28: LUIS AGOTE Y RUTA 36 | E28: Fija | F28: Radio | H28: 172.20.11.17 | I28: =COUNTIF(M28:AN28,"") -> 24 | J28: 00-07-5F-B4-42-C7 | K28: =COUNTIF(M28:AN28,"APAGADO") -> 4 | L28: =(I28)/(K28+I28) -> 0.85714286 | AE28: APAGADO | AF28: APAGADO | AG28: APAGADO | AH28: APAGADO
A29: BOSQUES CENTRO | B29: BOSQC 06 | C29: COSEIDI | D29: LUIS AGOTE Y RUTA 36 | E29: Fija | F29: Radio | H29: 172.20.11.18 | I29: =COUNTIF(M29:AN29,"") -> 24 | J29: 00-07-5F-B4-16-8D | K29: =COUNTIF(M29:AN29,"APAGADO") -> 4 | L29: =(I29)/(K29+I29) -> 0.85714286 | AE29: APAGADO | AF29: APAGADO | AG29: APAGADO | AH29: APAGADO
A30: BOSQUES CENTRO | B30: BOSQC 07 | C30: BONOMO | D30: Touring club y Sta Teresita | E30: Domo | F30: GPON | H30: 172.20.10.141 | I30: =COUNTIF(M30:AN30,"") -> 28 | J30: A0-FF-0C-D1-BD-7F | K30: =COUNTIF(M30:AN30,"APAGADO") -> 0 | L30: =(I30)/(K30+I30) -> 1
A31: BOSQUES CENTRO | B31: BOSQC 08 | C31: COSEIDI | D31: D'Anuncio Y J.B Justo (Plaza) | E31: Fija | F31: GPON | H31: 172.20.10.222
A32: BOSQUES CENTRO | B32: BOSQC 09 | C32: COSEIDI | D32: D'Anuncio e/Lisandro de la Torre y J.B Justo | E32: Fija | F32: GPON | H32: 172.20.10.227
A33: BOSQUES CENTRO | B33: BOSQC 10 | C33: COSEIDI | D33: D'Anuncio e/Lisandro de la Torre y J.B Justo | E33: Fija | F33: GPON | H33: 172.20.10.228
A34: BOSQUES CENTRO | B34: PAVE01 | C34: COSEIDI | D34: Touring Club y Ramallo | E34: Domo | F34: Fibra Optica | H34: 172.20.10.144 | I34: =COUNTIF(M34:AN34,"") -> 4 | J34: A0-FF-0C-D4-AF-AD | K34: =COUNTIF(M34:AN34,"APAGADO") -> 24 | L34: =(I34)/(K34+I34) -> 0.14285714 | M34: APAGADO | N34: APAGADO | O34: APAGADO | P34: APAGADO | Q34: APAGADO | R34: APAGADO | S34: APAGADO | T34: APAGADO | U34: APAGADO | V34: APAGADO | W34: APAGADO | X34: APAGADO | Y34: APAGADO | AA34: APAGADO | AB34: APAGADO | AC34: APAGADO | AD34: APAGADO | AE34: APAGADO | AF34: APAGADO | AG34: APAGADO | AH34: APAGADO | AI34: APAGADO | AJ34: APAGADO | AK34: APAGADO
A35: BOSQUES CENTRO | B35: PAVE02 | C35: COSEIDI | D35: Ramallo y Calingasta | E35: Domo | F35: GPON | H35: 172.20.10.37 | I35: =COUNTIF(M35:AN35,"") -> 4 | K35: =COUNTIF(M35:AN35,"APAGADO") -> 24 | L35: =(I35)/(K35+I35) -> 0.14285714 | M35: APAGADO | N35: APAGADO | O35: APAGADO | P35: APAGADO | Q35: APAGADO | R35: APAGADO | S35: APAGADO | T35: APAGADO | U35: APAGADO | V35: APAGADO | W35: APAGADO | X35: APAGADO | Y35: APAGADO | AA35: APAGADO | AB35: APAGADO | AC35: APAGADO | AD35: APAGADO | AE35: APAGADO | AF35: APAGADO | AG35: APAGADO | AH35: APAGADO | AI35: APAGADO | AJ35: APAGADO | AK35: APAGADO
A36: BOSQUES CENTRO | B36: CVA01 | C36: COSEIDI | D36: CACHEUTA Y 1355 | E36: Domo | F36: GPON | H36: 172.20.10.59 | M36: APAGADO | N36: APAGADO | O36: APAGADO | P36: APAGADO
A37: LA CAROLINA 2 | B37: CAR01 (Fija 1) | C37: COSEIDI | D37: Azurduy y Vergara | E37: Fija | F37: Fibra Optica | H37: 172.20.10.60 | I37: =COUNTIF(M37:AN37,"") -> 28 | J37: A0:FF:0C:EF:DF:AB | K37: =COUNTIF(M37:AN37,"APAGADO") -> 0 | L37: =(I37)/(K37+I37) -> 1
A38: LA CAROLINA 2 | B38: CAR02 (Fija 2) | C38: COSEIDI | D38: Azurduy y Vergara | E38: Fija | F38: Fibra Optica | H38: 172.20.10.73 | I38: =COUNTIF(M38:AN38,"") -> 28 | J38: A0:FF:0C:EF:DF:AD | K38: =COUNTIF(M38:AN38,"APAGADO") -> 0 | L38: =(I38)/(K38+I38) -> 1
A39: LA CAROLINA 2 | B39: CAR03(Fija1) | C39: COSEIDI | D39: Hudson e/1362 Y 1356 | E39: Fija | F39: Fibra Optica | H39: 172.20.8.39
A40: LA CAROLINA 2 | B40: CAR04(Fija2) | C40: COSEIDI | D40: Hudson e/1362 Y 1356 | E40: Fija | F40: Fibra Optica | H40: 172.20.8.40
...

Sheet AUXILIAR

Sheet informe
C1: CANTIDAD | D1: APAGADAS | E1: %
B2: TOTAL | C2: =CANTIDAD_DE_CAMARAS -> 541 | F2: 45901
A3: L | B3: CAIDAS | C3: ='RESUMEN TOTAL'!M3 -> 69 | E3: =C3/C2 -> 0.12754159
B4: LLEGAMOS NOSOTROS | C4: 7 | D4: 62 | E4: =D4/C2 -> 0.11460259
B5: NO ESTA LA CAMARA | C5: 6 | D5: 56 | E5: =D5/C2 -> 0.10351201
A6: L | B6: RADIO | C6: ='RESUMEN TOTAL'!M5 -> 11 | D6: 44 | E6: =D6/C2 -> 0.081330869
B7: ANTENA DESMONTADA | C7: 9 | D7: 35 | E7: =D7/C2 -> 0.064695009
C8: CANTIDAD | D8: APAGADAS | E8: %
A9: F | B9: BONOMO | C9: =BONOMOcam -> 290 | D9: =Hoja1!F3 -> 38 | E9: =D9/C9 -> 0.13103448
A10: F | B10: COSEIDI | C10: =COSEIDIcam -> 251 | D10: =Hoja1!F5 -> 31 | E10: 0.12
C12: CANTIDAD | D12: APAGADAS | E12: %
B13: TOTAL | C13: =CANTIDAD_DE_CAMARAS -> 541 | F13: 45902
A14: M | B14: CAIDAS | C14: ='RESUMEN TOTAL'!N3 -> 70 | E14: =C14/C13 -> 0.12939002
B15: LLEGAMOS NOSOTROS | C15: 0 | D15: 70 | E15: =D15/C13 -> 0.12939002
B16: NO ESTA LA CAMARA | C16: 6 | D16: =D15-C16 -> 64 | E16: =D16/C13 -> 0.11829945
A17: M | B17: RADIO | C17: ='RESUMEN TOTAL'!N5 -> 12 | D17: =D16-C17 -> 52 | E17: =D17/C13 -> 0.096118299
B18: ANTENA DESMONTADA | C18: 9 | D18: =D17-C18 -> 43 | E18: =D18/C13 -> 0.07948244
C19: CANTIDAD | D19: APAGADAS | E19: %
A20: G | B20: BONOMO | C20: =BONOMOcam -> 290 | D20: =Hoja1!G3 -> 36 | E20: 0.13
A21: G | B21: COSEIDI | C21: =COSEIDIcam -> 251 | D21: =Hoja1!G5 -> 34 | E21: 0.12
C23: CANTIDAD | D23: APAGADAS | E23: %
B24: TOTAL | C24: =CANTIDAD_DE_CAMARAS -> 541 | F24: 45903
A25: N | B25: CAIDAS | C25: ='RESUMEN TOTAL'!O3 -> 68 | E25: =C25/C24 -> 0.12569316
B26: LLEGAMOS NOSOTROS | C26: 0 | D26: =C25-C26 -> 68 | E26: =D26/C24 -> 0.12569316
B27: NO ESTA LA CAMARA | C27: 0 | D27: =D26-C27 -> 68 | E27: =D27/C24 -> 0.12569316
A28: N | B28: RADIO | C28: ='RESUMEN TOTAL'!O5 -> 11 | D28: =D27-C28 -> 57 | E28: =D28/C24 -> 0.10536044
B29: ANTENA DESMONTADA | C29: 0 | D29: =D28-C29 -> 57 | E29: =D29/C24 -> 0.10536044
C30: CANTIDAD | D30: APAGADAS | E30: %
B31: BONOMO | C31: =BONOMOcam -> 290 | D31: =Hoja1!H3 -> 34 | E31: =D31/C31 -> 0.11724138
B32: COSEIDI | C32: =COSEIDIcam -> 251 | D32: =Hoja1!H5 -> 34 | E32: =D32/C32 -> 0.13545817
C34: CANTIDAD | D34: APAGADAS | E34: %
B35: TOTAL | C35: =CANTIDAD_DE_CAMARAS -> 541 | F35: 45904
A36: O | B36: CAIDAS | C36: ='RESUMEN TOTAL'!P3 -> 63 | E36: =C36/C35 -> 0.11645102
B37: LLEGAMOS NOSOTROS | C37: 6 | D37: 57 | E37: =D37/C35 -> 0.10536044
B38: NO ESTA LA CAMARA | C38: 6 | D38: =D37-C38 -> 51 | E38: =D38/C35 -> 0.094269871
A39: O | B39: RADIO | C39: ='RESUMEN TOTAL'!P5 -> 12 | D39: =D38-C39 -> 39 | E39: =D39/C35 -> 0.072088725
B40: ANTENA DESMONTADA | C40: 9 | D40: 30 | E40: =D40/C35 -> 0.055452865
C41: CANTIDAD | D41: APAGADAS | E41: %
B42: BONOMO | C42: =BONOMOcam -> 290 | D42: =Hoja1!I3 -> 35 | E42: =D42/C42 -> 0.12068966
B43: COSEIDI | C43: =COSEIDIcam -> 251 | D43: =Hoja1!I5 -> 28 | E43: 0.1
...

Sheet paradas
C1: TOTAL PARADAS | D1: =COUNTIFS(A5:A602,"=paradas seguras")/2 -> 0 | E1: TOTAL DE CAMARAS EN PARADAS | H1: =COUNTIFS(A5:A602,"=paradas seguras") -> 0 | I1: TOTAL DE CAMARAS | K1: =COUNTIFS(D5:D602,"=GFIJA") -> 0 | L1: TOTAL DE INTERCOMUNICADORES | O1: =COUNTIFS(D5:D602,"=INTERCOMUNICADOR") -> 0
E2: FIJAS | F2: =COUNTIFS(F4:F601, "=APAGADO",D4:D601,"=GFIJA") -> 0 | G2: =COUNTIFS(G4:G601, "=APAGADO",D4:D601,"=GFIJA") -> 0 | H2: =COUNTIFS(H4:H601, "=APAGADO",D4:D601,"=GFIJA") -> 0 | I2: =COUNTIFS(I4:I601, "=APAGADO",D4:D601,"=GFIJA") -> 0 | J2: =COUNTIFS(J4:J601, "=APAGADO",D4:D601,"=GFIJA") -> 0 | K2: =COUNTIFS(K4:K601, "=APAGADO",D4:D601,"=GFIJA") -> 0 | L2: =COUNTIFS(L4:L601, "=APAGADO",D4:D601,"=GFIJA") -> 0 | M2: =COUNTIFS(M4:M601, "=APAGADO",D4:D601,"=GFIJA") -> 0 | N2: =COUNTIFS(N4:N601, "=APAGADO",D4:D601,"=GFIJA") -> 0 | O2: =COUNTIFS(O4:O601, "=APAGADO",D4:D601,"=GFIJA") -> 0 | P2: =COUNTIFS(P4:P601, "=APAGADO",D4:D601,"=GFIJA") -> 0 | Q2: =COUNTIFS(Q4:Q601, "=APAGADO",D4:D601,"=GFIJA") -> 0 | R2: =COUNTIFS(R4:R601, "=APAGADO",D4:D601,"=GFIJA") -> 0 | S2: =COUNTIFS(S4:S601, "=APAGADO",D4:D601,"=GFIJA") -> 0 | T2: =COUNTIFS(T4:T601, "=APAGADO",D4:D601,"=GFIJA") -> 0 | U2: =COUNTIFS(U4:U601, "=APAGADO",D4:D601,"=GFIJA") -> 0 | V2: =COUNTIFS(V4:V601, "=APAGADO",D4:D601,"=GFIJA") -> 0 | W2: =COUNTIFS(W4:W601, "=APAGADO",D4:D601,"=GFIJA") -> 0 | X2: =COUNTIFS(X4:X601, "=APAGADO",D4:D601,"=GFIJA") -> 0 | Y2: =COUNTIFS(Y4:Y601, "=APAGADO",D4:D601,"=GFIJA") -> 0 | Z2: =COUNTIFS(Z4:Z601, "=APAGADO",D4:D601,"=GFIJA") -> 0 | AA2: =COUNTIFS(AA4:AA601, "=APAGADO",D4:D601,"=GFIJA") -> 0 | AB2: =COUNTIFS(AB4:AB601, "=APAGADO",D4:D601,"=GFIJA") -> 0 | AC2: =COUNTIFS(AC4:AC601, "=APAGADO",D4:D601,"=GFIJA") -> 0 | AD2: =COUNTIFS(AD4:AD601, "=APAGADO",D4:D601,"=GFIJA") -> 0 | AE2: =COUNTIFS(AE4:AE601, "=APAGADO",D4:D601,"=GFIJA") -> 0 | AF2: =COUNTIFS(AF4:AF601, "=APAGADO",D4:D601,"=GFIJA") -> 0 | AG2: =COUNTIFS(AG4:AG601, "=APAGADO",D4:D601,"=GFIJA") -> 0 | AH2: =COUNTIFS(AH4:AH601, "=APAGADO",D4:D601,"=GFIJA") -> 0 | AI2: =COUNTIFS(AI4:AI601, "=APAGADO",D4:D601,"=GFIJA") -> 0
E3: INTERCOMUNICADOR | F3: =COUNTIFS(F6:F603, "=APAGADO",D4:D601,"=INTERCOMUNICADOR") -> 0 | G3: =COUNTIFS(G6:G603, "=APAGADO",D4:D601,"=INTERCOMUNICADOR") -> 0 | H3: =COUNTIFS(H6:H603, "=APAGADO",D4:D601,"=INTERCOMUNICADOR") -> 0 | I3: =COUNTIFS(I6:I603, "=APAGADO",D4:D601,"=INTERCOMUNICADOR") -> 0 | J3: =COUNTIFS(J6:J603, "=APAGADO",D4:D601,"=INTERCOMUNICADOR") -> 0 | K3: =COUNTIFS(K6:K603, "=APAGADO",D4:D601,"=INTERCOMUNICADOR") -> 0 | L3: =COUNTIFS(L6:L603, "=APAGADO",D4:D601,"=INTERCOMUNICADOR") -> 0 | M3: =COUNTIFS(M6:M603, "=APAGADO",D4:D601,"=INTERCOMUNICADOR") -> 0 | N3: =COUNTIFS(N6:N603, "=APAGADO",D4:D601,"=INTERCOMUNICADOR") -> 0 | O3: =COUNTIFS(O6:O603, "=APAGADO",D4:D601,"=INTERCOMUNICADOR") -> 0 | P3: =COUNTIFS(P6:P603, "=APAGADO",D4:D601,"=INTERCOMUNICADOR") -> 0 | Q3: =COUNTIFS(Q6:Q603, "=APAGADO",D4:D601,"=INTERCOMUNICADOR") -> 0 | R3: =COUNTIFS(R6:R603, "=APAGADO",D4:D601,"=INTERCOMUNICADOR") -> 0 | S3: =COUNTIFS(S6:S603, "=APAGADO",D4:D601,"=INTERCOMUNICADOR") -> 0 | T3: =COUNTIFS(T6:T603, "=APAGADO",D4:D601,"=INTERCOMUNICADOR") -> 0 | U3: =COUNTIFS(U6:U603, "=APAGADO",D4:D601,"=INTERCOMUNICADOR") -> 0 | V3: =COUNTIFS(V6:V603, "=APAGADO",D4:D601,"=INTERCOMUNICADOR") -> 0 | W3: =COUNTIFS(W6:W603, "=APAGADO",D4:D601,"=INTERCOMUNICADOR") -> 0 | X3: =COUNTIFS(X6:X603, "=APAGADO",D4:D601,"=INTERCOMUNICADOR") -> 0 | Y3: =COUNTIFS(Y6:Y603, "=APAGADO",D4:D601,"=INTERCOMUNICADOR") -> 0 | Z3: =COUNTIFS(Z6:Z603, "=APAGADO",D4:D601,"=INTERCOMUNICADOR") -> 0 | AA3: =COUNTIFS(AA6:AA603, "=APAGADO",D4:D601,"=INTERCOMUNICADOR") -> 0 | AB3: =COUNTIFS(AB6:AB603, "=APAGADO",D4:D601,"=INTERCOMUNICADOR") -> 0 | AC3: =COUNTIFS(AC6:AC603, "=APAGADO",D4:D601,"=INTERCOMUNICADOR") -> 0 | AD3: =COUNTIFS(AD6:AD603, "=APAGADO",D4:D601,"=INTERCOMUNICADOR") -> 0 | AE3: =COUNTIFS(AE6:AE603, "=APAGADO",D4:D601,"=INTERCOMUNICADOR") -> 0 | AF3: =COUNTIFS(AF6:AF603, "=APAGADO",D4:D601,"=INTERCOMUNICADOR") -> 0 | AG3: =COUNTIFS(AG6:AG603, "=APAGADO",D4:D601,"=INTERCOMUNICADOR") -> 0 | AH3: =COUNTIFS(AH6:AH603, "=APAGADO",D4:D601,"=INTERCOMUNICADOR") -> 0 | AI3: =COUNTIFS(AI6:AI603, "=APAGADO",D4:D601,"=INTERCOMUNICADOR") -> 0
A4: ='RESUMEN TOTAL'!A7 -> Barrio | B4: ='RESUMEN TOTAL'!B7 -> [Denominacion] | C4: ='RESUMEN TOTAL'!D7 -> [Ubicacion] | D4: ='RESUMEN TOTAL'!E7 -> [Tipo de Camara] | E4: ='RESUMEN TOTAL'!F7 -> [Tipo de Conexion] | F4: ='RESUMEN TOTAL'!M7 -> 45901 | G4: ='RESUMEN TOTAL'!N7 -> 45902 | H4: ='RESUMEN TOTAL'!O7 -> 45903 | I4: ='RESUMEN TOTAL'!P7 -> 45904 | J4: ='RESUMEN TOTAL'!Q7 -> 45905 | K4: ='RESUMEN TOTAL'!R7 -> 45906 | L4: ='RESUMEN TOTAL'!S7 -> 45907 | M4: ='RESUMEN TOTAL'!T7 -> 45908 | ... AI4: ='RESUMEN TOTAL'!AP7 -> 45930 | XFB4: =SUM(F4:XFA4) -> 1377465
A5: ='RESUMEN TOTAL'!A8 -> ALTAMIRA | B5: ='RESUMEN TOTAL'!B8 -> ALT01 | C5: ='RESUMEN TOTAL'!D8 -> Calchaqui y Sgto. Cabral | D5: ='RESUMEN TOTAL'!E8 -> Domo | E5: ='RESUMEN TOTAL'!F8 -> Fibra Optica | F5: ='RESUMEN TOTAL'!M8 -> 0 | G5: ='RESUMEN TOTAL'!N8 -> 0 | H5: ='RESUMEN TOTAL'!O8 -> 0 | I5: ='RESUMEN TOTAL'!P8 -> 0 | J5: ='RESUMEN TOTAL'!Q8 -> 0 | K5: ='RESUMEN TOTAL'!R8 -> 0 | L5: ='RESUMEN TOTAL'!S8 -> 0 | M5: ='RESUMEN TOTAL'!T8 -> 0 | ... AI5: ='RESUMEN TOTAL'!AP8 -> 0
A6: ='RESUMEN TOTAL'!A9 -> ALTAMIRA | B6: ='RESUMEN TOTAL'!B9 -> ALT02 | C6: ='RESUMEN TOTAL'!D9 -> Calchaqui y Lope de Vega | D6: ='RESUMEN TOTAL'!E9 -> Domo | E6: ='RESUMEN TOTAL'!F9 -> PTO A FO | F6: ='RESUMEN TOTAL'!M9 -> 0 | G6: ='RESUMEN TOTAL'!N9 -> 0 | H6: ='RESUMEN TOTAL'!O9 -> 0 | I6: ='RESUMEN TOTAL'!P9 -> 0 | J6: ='RESUMEN TOTAL'!Q9 -> 0 | K6: ='RESUMEN TOTAL'!R9 -> 0 | L6: ='RESUMEN TOTAL'!S9 -> 0 | M6: ='RESUMEN TOTAL'!T9 -> 0 | ... AI6: ='RESUMEN TOTAL'!AP9 -> 0
A7: ='RESUMEN TOTAL'!A10 -> ALTAMIRA | B7: ='RESUMEN TOTAL'!B10 -> ALT 03 | C7: ='RESUMEN TOTAL'!D10 -> Bombero Galarza y Necochea | D7: ='RESUMEN TOTAL'!E10 -> Domo | E7: ='RESUMEN TOTAL'!F10 -> GPON | F7: ='RESUMEN TOTAL'!M10 -> 0 | G7: ='RESUMEN TOTAL'!N10 -> 0 | H7: ='RESUMEN TOTAL'!O10 -> 0 | I7: ='RESUMEN TOTAL'!P10 -> 0 | J7: ='RESUMEN TOTAL'!Q10 -> 0 | K7: ='RESUMEN TOTAL'!R10 -> 0 | L7: ='RESUMEN TOTAL'!S10 -> 0 | M7: ='RESUMEN TOTAL'!T10 -> 0 | ... AI7: ='RESUMEN TOTAL'!AP10 -> 0
A8: ='RESUMEN TOTAL'!A11 -> ALTAMIRA | B8: ='RESUMEN TOTAL'!B11 -> ALT 04 | C8: ='RESUMEN TOTAL'!D11 -> Francia y Necochea | D8: ='RESUMEN TOTAL'!E11 -> Domo | E8: ='RESUMEN TOTAL'!F11 -> GPON | F8: ='RESUMEN TOTAL'!M11 -> 0 | G8: ='RESUMEN TOTAL'!N11 -> 0 | H8: ='RESUMEN TOTAL'!O11 -> 0 | I8: ='RESUMEN TOTAL'!P11 -> 0 | J8: ='RESUMEN TOTAL'!Q11 -> 0 | K8: ='RESUMEN TOTAL'!R11 -> 0 | L8: ='RESUMEN TOTAL'!S11 -> 0 | M8: ='RESUMEN TOTAL'!T11 -> 0 | ... AI8: ='RESUMEN TOTAL'!AP11 -> 0
A9: ='RESUMEN TOTAL'!A12 -> ALTAMIRA | B9: ='RESUMEN TOTAL'!B12 -> ALT05 | C9: ='RESUMEN TOTAL'!D12 -> Av. Calchaqui y Bombero Galarza | D9: ='RESUMEN TOTAL'!E12 -> Domo | E9: ='RESUMEN TOTAL'!F12 -> GPON | F9: ='RESUMEN TOTAL'!M12 -> 0 | G9: ='RESUMEN TOTAL'!N12 -> 0 | H9: ='RESUMEN TOTAL'!O12 -> 0 | I9: ='RESUMEN TOTAL'!P12 -> 0 | J9: ='RESUMEN TOTAL'!Q12 -> 0 | K9: ='RESUMEN TOTAL'!R12 -> 0 | L9: ='RESUMEN TOTAL'!S12 -> 0 | M9: ='RESUMEN TOTAL'!T12 -> 0 | ... AI9: ='RESUMEN TOTAL'!AP12 -> 0
A10: ='RESUMEN TOTAL'!A13 -> ALTAMIRA | B10: ='RESUMEN TOTAL'!B13 -> ALT 06 | C10: ='RESUMEN TOTAL'!D13 -> LOPE DE VEGA Y NECOCHEA | D10: ='RESUMEN TOTAL'!E13 -> Domo | E10: ='RESUMEN TOTAL'!F13 -> GPON | F10: ='RESUMEN TOTAL'!M13 -> 0 | G10: ='RESUMEN TOTAL'!N13 -> 0 | H10: ='RESUMEN TOTAL'!O13 -> 0 | I10: ='RESUMEN TOTAL'!P13 -> 0 | J10: ='RESUMEN TOTAL'!Q13 -> 0 | K10: ='RESUMEN TOTAL'!R13 -> 0 | L10: ='RESUMEN TOTAL'!S13 -> 0 | M10: ='RESUMEN TOTAL'!T13 -> 0 | ... AI10: ='RESUMEN TOTAL'!AP13 -> 0
A11: ='RESUMEN TOTAL'!A14 -> ALTAMIRA | B11: ='RESUMEN TOTAL'!B14 -> ALT07 | C11: ='RESUMEN TOTAL'!D14 -> AV. CALCHAQUI Y AV. DEL TRABAJO | D11: ='RESUMEN TOTAL'!E14 -> DOMO | E11: ='RESUMEN TOTAL'!F14 -> PTO A FO | F11: ='RESUMEN TOTAL'!M14 -> 0 | G11: ='RESUMEN TOTAL'!N14 -> 0 | H11: ='RESUMEN TOTAL'!O14 -> 0 | I11: ='RESUMEN TOTAL'!P14 -> 0 | J11: ='RESUMEN TOTAL'!Q14 -> 0 | K11: ='RESUMEN TOTAL'!R14 -> 0 | L11: ='RESUMEN TOTAL'!S14 -> 0 | M11: ='RESUMEN TOTAL'!T14 -> 0 | ... AI11: ='RESUMEN TOTAL'!AP14 -> 0
A12: ='RESUMEN TOTAL'!A15 -> ALTAMIRA | B12: ='RESUMEN TOTAL'!B15 -> ALT 08 | C12: ='RESUMEN TOTAL'!D15 -> HUMAITA Y NECOCHEA | D12: ='RESUMEN TOTAL'!E15 -> DOMO | E12: ='RESUMEN TOTAL'!F15 -> Fibra Optica | F12: ='RESUMEN TOTAL'!M15 -> 0 | G12: ='RESUMEN TOTAL'!N15 -> 0 | H12: ='RESUMEN TOTAL'!O15 -> 0 | I12: ='RESUMEN TOTAL'!P15 -> 0 | J12: ='RESUMEN TOTAL'!Q15 -> 0 | K12: ='RESUMEN TOTAL'!R15 -> 0 | L12: ='RESUMEN TOTAL'!S15 -> 0 | M12: ='RESUMEN TOTAL'!T15 -> 0 | ... AI12: ='RESUMEN TOTAL'!AP15 -> 0
A13: ='RESUMEN TOTAL'!A16 -> ALTAMIRA | B13: ='RESUMEN TOTAL'!B16 -> ALT 09 | C13: ='RESUMEN TOTAL'!D16 -> NECOCHEA Y CURUPAITY | D13: ='RESUMEN TOTAL'!E16 -> DOMO | E13: ='RESUMEN TOTAL'!F16 -> Fibra Optica | F13: ='RESUMEN TOTAL'!M16 -> 0 | G13: ='RESUMEN TOTAL'!N16 -> 0 | H13: ='RESUMEN TOTAL'!O16 -> 0 | I13: ='RESUMEN TOTAL'!P16 -> 0 | J13: ='RESUMEN TOTAL'!Q16 -> 0 | K13: ='RESUMEN TOTAL'!R16 -> 0 | L13: ='RESUMEN TOTAL'!S16 -> 0 | M13: ='RESUMEN TOTAL'!T16 -> 0 | ... AI13: ='RESUMEN TOTAL'!AP16 -> 0
A14: ='RESUMEN TOTAL'!A17 -> ALTAMIRA | B14: ='RESUMEN TOTAL'!B17 -> ALT 10 | C14: ='RESUMEN TOTAL'!D17 -> Calchaqui y Francia | D14: ='RESUMEN TOTAL'!E17 -> Domo | E14: ='RESUMEN TOTAL'!F17 -> GPON | F14: ='RESUMEN TOTAL'!M17 -> APAGADO | G14: ='RESUMEN TOTAL'!N17 -> APAGADO | H14: ='RESUMEN TOTAL'!O17 -> APAGADO | I14: ='RESUMEN TOTAL'!P17 -> 0 | J14: ='RESUMEN TOTAL'!Q17 -> 0 | K14: ='RESUMEN TOTAL'!R17 -> 0 | L14: ='RESUMEN TOTAL'!S17 -> 0 | M14: ='RESUMEN TOTAL'!T17 -> 0 | ... AI14: ='RESUMEN TOTAL'!AP17 -> 0
A15: ='RESUMEN TOTAL'!A18 -> ALTAMIRA | B15: ='RESUMEN TOTAL'!B18 -> ALT 11 | C15: CALCHAQUÍ Y GALARZA FIJA | D15: ='RESUMEN TOTAL'!E18 -> Fija | F15: ='RESUMEN TOTAL'!M18 -> 0 | G15: ='RESUMEN TOTAL'!N18 -> 0 | H15: ='RESUMEN TOTAL'!O18 -> 0 | I15: ='RESUMEN TOTAL'!P18 -> 0 | J15: ='RESUMEN TOTAL'!Q18 -> 0 | K15: ='RESUMEN TOTAL'!R18 -> 0 | L15: ='RESUMEN TOTAL'!S18 -> 0 | M15: ='RESUMEN TOTAL'!T18 -> 0 | ... AI15: ='RESUMEN TOTAL'!AP18 -> 0
A16: ='RESUMEN TOTAL'!A19 -> AGUSTIN RAMIREZ | B16: ='RESUMEN TOTAL'!B19 -> ARA 01 | C16: ='RESUMEN TOTAL'!D19 -> Malambo y Tranquera | D16: ='RESUMEN TOTAL'!E19 -> Domo | E16: ='RESUMEN TOTAL'!F19 -> Fibra Optica | F16: ='RESUMEN TOTAL'!M19 -> 0 | G16: ='RESUMEN TOTAL'!N19 -> 0 | H16: ='RESUMEN TOTAL'!O19 -> 0 | I16: ='RESUMEN TOTAL'!P19 -> 0 | J16: ='RESUMEN TOTAL'!Q19 -> 0 | K16: ='RESUMEN TOTAL'!R19 -> 0 | L16: ='RESUMEN TOTAL'!S19 -> 0 | M16: ='RESUMEN TOTAL'!T19 -> 0 | ... AI16: ='RESUMEN TOTAL'!AP19 -> 0
A17: ='RESUMEN TOTAL'!A22 -> BELGRANO | B17: ='RESUMEN TOTAL'!B22 -> BEL 01 | C17: ='RESUMEN TOTAL'!D22 -> San Martin y Dardo Rocha | D17: ='RESUMEN TOTAL'!E22 -> DOMO | E17: ='RESUMEN TOTAL'!F22 -> Fibra Optica | F17: ='RESUMEN TOTAL'!M22 -> APAGADO | G17: ='RESUMEN TOTAL'!N22 -> APAGADO | H17: ='RESUMEN TOTAL'!O22 -> APAGADO | I17: ='RESUMEN TOTAL'!P22 -> APAGADO | J17: ='RESUMEN TOTAL'!Q22 -> APAGADO | K17: ='RESUMEN TOTAL'!R22 -> APAGADO | L17: ='RESUMEN TOTAL'!S22 -> APAGADO | M17: ='RESUMEN TOTAL'!T22 -> APAGADO | ... AI17: ='RESUMEN TOTAL'!AP22 -> 0
A18: ='RESUMEN TOTAL'!A23 -> BELGRANO | B18: ='RESUMEN TOTAL'!B23 -> BEL 02 | C18: ='RESUMEN TOTAL'!D23 -> Guardia vieja y Fronteriz | D18: ='RESUMEN TOTAL'!E23 -> DOMO | E18: ='RESUMEN TOTAL'!F23 -> Fibra Optica | F18: ='RESUMEN TOTAL'!M23 -> 0 | G18: ='RESUMEN TOTAL'!N23 -> 0 | H18: ='RESUMEN TOTAL'!O23 -> 0 | I18: ='RESUMEN TOTAL'!P23 -> 0 | J18: ='RESUMEN TOTAL'!Q23 -> 0 | K18: ='RESUMEN TOTAL'!R23 -> 0 | L18: ='RESUMEN TOTAL'!S23 -> 0 | M18: ='RESUMEN TOTAL'!T23 -> 0 | ... AI18: ='RESUMEN TOTAL'!AP23 -> 0
A19: ='RESUMEN TOTAL'!A24 -> BOSQUES CENTRO | B19: ='RESUMEN TOTAL'!B24 -> BOSQC 01 | C19: ='RESUMEN TOTAL'!D24 -> LUIS AGOTE E/DANUNCIO Y CAMPOAMOR | D19: ='RESUMEN TOTAL'!E24 -> Fija | E19: ='RESUMEN TOTAL'!F24 -> Radio | F19: ='RESUMEN TOTAL'!M24 -> 0 | G19: ='RESUMEN TOTAL'!N24 -> 0 | H19: ='RESUMEN TOTAL'!O24 -> 0 | I19: ='RESUMEN TOTAL'!P24 -> 0 | J19: ='RESUMEN TOTAL'!Q24 -> 0 | K19: ='RESUMEN TOTAL'!R24 -> 0 | L19: ='RESUMEN TOTAL'!S24 -> 0 | M19: ='RESUMEN TOTAL'!T24 -> 0 | ... AI19: ='RESUMEN TOTAL'!AP24 -> 0
A20: ='RESUMEN TOTAL'!A25 -> BOSQUES CENTRO | B20: ='RESUMEN TOTAL'!B25 -> BOSQC 02 | C20: ='RESUMEN TOTAL'!D25 -> LUIS AGOTE E/DANUNCIO Y CAMPOAMOR | D20: ='RESUMEN TOTAL'!E25 -> Fija | E20: ='RESUMEN TOTAL'!F25 -> Radio | F20: ='RESUMEN TOTAL'!M25 -> 0 | G20: ='RESUMEN TOTAL'!N25 -> 0 | H20: ='RESUMEN TOTAL'!O25 -> 0 | I20: ='RESUMEN TOTAL'!P25 -> 0 | J20: ='RESUMEN TOTAL'!Q25 -> 0 | K20: ='RESUMEN TOTAL'!R25 -> 0 | L20: ='RESUMEN TOTAL'!S25 -> 0 | M20: ='RESUMEN TOTAL'!T25 -> 0 | ... AI20: ='RESUMEN TOTAL'!AP25 -> 0
A21: ='RESUMEN TOTAL'!A26 -> BOSQUES CENTRO | B21: ='RESUMEN TOTAL'!B26 -> BOSQC 03 | C21: ='RESUMEN TOTAL'!D26 -> BENAVENTE Y LUIS AGOTE | D21: ='RESUMEN TOTAL'!E26 -> Fija | E21: ='RESUMEN TOTAL'!F26 -> Radio | F21: ='RESUMEN TOTAL'!M26 -> 0 | G21: ='RESUMEN TOTAL'!N26 -> 0 | H21: ='RESUMEN TOTAL'!O26 -> 0 | I21: ='RESUMEN TOTAL'!P26 -> 0 | J21: ='RESUMEN TOTAL'!Q26 -> 0 | K21: ='RESUMEN TOTAL'!R26 -> 0 | L21: ='RESUMEN TOTAL'!S26 -> 0 | M21: ='RESUMEN TOTAL'!T26 -> 0 | ... AI21: ='RESUMEN TOTAL'!AP26 -> 0
A22: ='RESUMEN TOTAL'!A27 -> BOSQUES CENTRO | B22: ='RESUMEN TOTAL'!B27 -> BOSQC 04 | C22: ='RESUMEN TOTAL'!D27 -> BENAVENTE Y LUIS AGOTE | D22: ='RESUMEN TOTAL'!E27 -> Fija | E22: ='RESUMEN TOTAL'!F27 -> Radio | F22: ='RESUMEN TOTAL'!M27 -> 0 | G22: ='RESUMEN TOTAL'!N27 -> 0 | H22: ='RESUMEN TOTAL'!O27 -> 0 | I22: ='RESUMEN TOTAL'!P27 -> 0 | J22: ='RESUMEN TOTAL'!Q27 -> 0 | K22: ='RESUMEN TOTAL'!R27 -> 0 | L22: ='RESUMEN TOTAL'!S27 -> 0 | M22: ='RESUMEN TOTAL'!T27 -> 0 | ... AI22: ='RESUMEN TOTAL'!AP27 -> 0
A23: ='RESUMEN TOTAL'!A28 -> BOSQUES CENTRO | B23: ='RESUMEN TOTAL'!B28 -> BOSQC 05 | C23: ='RESUMEN TOTAL'!D28 -> LUIS AGOTE Y RUTA 36 | D23: ='RESUMEN TOTAL'!E28 -> Fija | E23: ='RESUMEN TOTAL'!F28 -> Radio | F23: ='RESUMEN TOTAL'!M28 -> 0 | G23: ='RESUMEN TOTAL'!N28 -> 0 | H23: ='RESUMEN TOTAL'!O28 -> 0 | I23: ='RESUMEN TOTAL'!P28 -> 0 | J23: ='RESUMEN TOTAL'!Q28 -> 0 | K23: ='RESUMEN TOTAL'!R28 -> 0 | L23: ='RESUMEN TOTAL'!S28 -> 0 | M23: ='RESUMEN TOTAL'!T28 -> 0 | ... AI23: ='RESUMEN TOTAL'!AP28 -> 0
A24: ='RESUMEN TOTAL'!A29 -> BOSQUES CENTRO | B24: ='RESUMEN TOTAL'!B29 -> BOSQC 06 | C24: ='RESUMEN TOTAL'!D29 -> LUIS AGOTE Y RUTA 36 | D24: ='RESUMEN TOTAL'!E29 -> Fija | E24: ='RESUMEN TOTAL'!F29 -> Radio | F24: ='RESUMEN TOTAL'!M29 -> 0 | G24: ='RESUMEN TOTAL'!N29 -> 0 | H24: ='RESUMEN TOTAL'!O29 -> 0 | I24: ='RESUMEN TOTAL'!P29 -> 0 | J24: ='RESUMEN TOTAL'!Q29 -> 0 | K24: ='RESUMEN TOTAL'!R29 -> 0 | L24: ='RESUMEN TOTAL'!S29 -> 0 | M24: ='RESUMEN TOTAL'!T29 -> 0 | ... AI24: ='RESUMEN TOTAL'!AP29 -> 0
A25: ='RESUMEN TOTAL'!A43 -> CENTRO | B25: ='RESUMEN TOTAL'!B43 -> CEN01 | C25: ='RESUMEN TOTAL'!D43 -> San Martin y 9 de Julio | D25: ='RESUMEN TOTAL'!E43 -> Fija | E25: ='RESUMEN TOTAL'!F43 -> Fibra Optica | F25: ='RESUMEN TOTAL'!M43 -> 0 | G25: ='RESUMEN TOTAL'!N43 -> 0 | H25: ='RESUMEN TOTAL'!O43 -> 0 | I25: ='RESUMEN TOTAL'!P43 -> 0 | J25: ='RESUMEN TOTAL'!Q43 -> 0 | K25: ='RESUMEN TOTAL'!R43 -> 0 | L25: ='RESUMEN TOTAL'!S43 -> 0 | M25: ='RESUMEN TOTAL'!T43 -> 0 | ... AI25: ='RESUMEN TOTAL'!AP43 -> 0
A26: ='RESUMEN TOTAL'!A44 -> CENTRO | B26: ='RESUMEN TOTAL'!B44 -> CEN02 | C26: ='RESUMEN TOTAL'!D44 -> San Martin y Almafuerte | D26: ='RESUMEN TOTAL'!E44 -> Fija | E26: ='RESUMEN TOTAL'!F44 -> Fibra Optica | F26: ='RESUMEN TOTAL'!M44 -> 0 | G26: ='RESUMEN TOTAL'!N44 -> 0 | H26: ='RESUMEN TOTAL'!O44 -> 0 | I26: ='RESUMEN TOTAL'!P44 -> 0 | J26: ='RESUMEN TOTAL'!Q44 -> 0 | K26: ='RESUMEN TOTAL'!R44 -> 0 | L26: ='RESUMEN TOTAL'!S44 -> 0 | M26: ='RESUMEN TOTAL'!T44 -> 0 | ... AI26: ='RESUMEN TOTAL'!AP44 -> 0
A27: ='RESUMEN TOTAL'!A45 -> CENTRO | B27: ='RESUMEN TOTAL'!B45 -> CEN03 | C27: ='RESUMEN TOTAL'!D45 -> San Martin y Sallares | D27: ='RESUMEN TOTAL'!E45 -> Domo | E27: ='RESUMEN TOTAL'!F45 -> Fibra Optica | F27: ='RESUMEN TOTAL'!M45 -> 0 | G27: ='RESUMEN TOTAL'!N45 -> 0 | H27: ='RESUMEN TOTAL'!O45 -> 0 | I27: ='RESUMEN TOTAL'!P45 -> 0 | J27: ='RESUMEN TOTAL'!Q45 -> 0 | K27: ='RESUMEN TOTAL'!R45 -> 0 | L27: ='RESUMEN TOTAL'!S45 -> 0 | M27: ='RESUMEN TOTAL'!T45 -> 0 | ... AI27: ='RESUMEN TOTAL'!AP45 -> 0
A28: ='RESUMEN TOTAL'!A46 -> CENTRO | B28: ='RESUMEN TOTAL'!B46 -> CEN04 | C28: ='RESUMEN TOTAL'!D46 -> San Martin y Contreras | D28: ='RESUMEN TOTAL'!E46 -> Domo | E28: ='RESUMEN TOTAL'!F46 -> Fibra Optica | F28: ='RESUMEN TOTAL'!M46 -> 0 | G28: ='RESUMEN TOTAL'!N46 -> 0 | H28: ='RESUMEN TOTAL'!O46 -> 0 | I28: ='RESUMEN TOTAL'!P46 -> 0 | J28: ='RESUMEN TOTAL'!Q46 -> 0 | K28: ='RESUMEN TOTAL'!R46 -> 0 | L28: ='RESUMEN TOTAL'!S46 -> 0 | M28: ='RESUMEN TOTAL'!T46 -> 0 | ... AI28: ='RESUMEN TOTAL'!AP46 -> 0
A29: ='RESUMEN TOTAL'!A47 -> CENTRO | B29: ='RESUMEN TOTAL'!B47 -> CEN 05 | C29: ='RESUMEN TOTAL'!D47 -> Bocuzzi e/España y San Martin | D29: ='RESUMEN TOTAL'!E47 -> DOMO | E29: ='RESUMEN TOTAL'!F47 -> Fibra Optica | F29: ='RESUMEN TOTAL'!M47 -> 0 | G29: ='RESUMEN TOTAL'!N47 -> 0 | H29: ='RESUMEN TOTAL'!O47 -> 0 | I29: ='RESUMEN TOTAL'!P47 -> 0 | J29: ='RESUMEN TOTAL'!Q47 -> 0 | K29: ='RESUMEN TOTAL'!R47 -> 0 | L29: ='RESUMEN TOTAL'!S47 -> 0 | M29: ='RESUMEN TOTAL'!T47 -> 0 | ... AI29: ='RESUMEN TOTAL'!AP47 -> 0
A30: ='RESUMEN TOTAL'!A48 -> CENTRO | B30: ='RESUMEN TOTAL'!B48 -> CEN06 | C30: ='RESUMEN TOTAL'!D48 -> Monteagudo y A.del Valle | D30: ='RESUMEN TOTAL'!E48 -> Fija | E30: ='RESUMEN TOTAL'!F48 -> Fibra Optica | F30: ='RESUMEN TOTAL'!M48 -> 0 | G30: ='RESUMEN TOTAL'!N48 -> 0 | H30: ='RESUMEN TOTAL'!O48 -> 0 | I30: ='RESUMEN TOTAL'!P48 -> 0 | J30: ='RESUMEN TOTAL'!Q48 -> 0 | K30: ='RESUMEN TOTAL'!R48 -> 0 | L30: ='RESUMEN TOTAL'!S48 -> 0 | M30: ='RESUMEN TOTAL'!T48 -> 0 | ... AI30: ='RESUMEN TOTAL'!AP48 -> 0
A31: ='RESUMEN TOTAL'!A49 -> CENTRO | B31: ='RESUMEN TOTAL'!B49 -> CEN07 | C31: ='RESUMEN TOTAL'!D49 -> San Martin y Guemes | D31: ='RESUMEN TOTAL'!E49 -> DOMO | E31: ='RESUMEN TOTAL'!F49 -> Fibra Optica | F31: ='RESUMEN TOTAL'!M49 -> 0 | G31: ='RESUMEN TOTAL'!N49 -> 0 | H31: ='RESUMEN TOTAL'!O49 -> 0 | I31: ='RESUMEN TOTAL'!P49 -> 0 | J31: ='RESUMEN TOTAL'!Q49 -> 0 | K31: ='RESUMEN TOTAL'!R49 -> 0 | L31: ='RESUMEN TOTAL'!S49 -> 0 | M31: ='RESUMEN TOTAL'!T49 -> 0 | ... AI31: ='RESUMEN TOTAL'!AP49 -> 0
A32: ='RESUMEN TOTAL'!A50 -> CENTRO | B32: ='RESUMEN TOTAL'!B50 -> CEN08 | C32: ='RESUMEN TOTAL'!D50 -> San Martin y Pte.Peron | D32: ='RESUMEN TOTAL'!E50 -> Domo | E32: ='RESUMEN TOTAL'!F50 -> Fibra Optica | F32: ='RESUMEN TOTAL'!M50 -> 0 | G32: ='RESUMEN TOTAL'!N50 -> 0 | H32: ='RESUMEN TOTAL'!O50 -> 0 | I32: ='RESUMEN TOTAL'!P50 -> 0 | J32: ='RESUMEN TOTAL'!Q50 -> 0 | K32: ='RESUMEN TOTAL'!R50 -> 0 | L32: ='RESUMEN TOTAL'!S50 -> 0 | M32: ='RESUMEN TOTAL'!T50 -> 0 | ... AI32: ='RESUMEN TOTAL'!AP50 -> 0
A33: ='RESUMEN TOTAL'!A51 -> CENTRO | B33: ='RESUMEN TOTAL'!B51 -> CEN09 | C33: ='RESUMEN TOTAL'!D51 -> Chacabuco y 25 de Mayo | D33: ='RESUMEN TOTAL'!E51 -> Domo | E33: ='RESUMEN TOTAL'!F51 -> Fibra Optica | F33: ='RESUMEN TOTAL'!M51 -> 0 | G33: ='RESUMEN TOTAL'!N51 -> 0 | H33: ='RESUMEN TOTAL'!O51 -> 0 | I33: ='RESUMEN TOTAL'!P51 -> 0 | J33: ='RESUMEN TOTAL'!Q51 -> 0 | K33: ='RESUMEN TOTAL'!R51 -> 0 | L33: ='RESUMEN TOTAL'!S51 -> 0 | M33: ='RESUMEN TOTAL'!T51 -> 0 | ... AI33: ='RESUMEN TOTAL'!AP51 -> 0
A34: ='RESUMEN TOTAL'!A52 -> CENTRO | B34: ='RESUMEN TOTAL'!B52 -> CEN10 | C34: ='RESUMEN TOTAL'!D52 -> Monteagudo y Pte. Peron | D34: ='RESUMEN TOTAL'!E52 -> Domo | E34: ='RESUMEN TOTAL'!F52 -> Fibra Optica | F34: ='RESUMEN TOTAL'!M52 -> 0 | G34: ='RESUMEN TOTAL'!N52 -> 0 | H34: ='RESUMEN TOTAL'!O52 -> 0 | I34: ='RESUMEN TOTAL'!P52 -> 0 | J34: ='RESUMEN TOTAL'!Q52 -> 0 | K34: ='RESUMEN TOTAL'!R52 -> 0 | L34: ='RESUMEN TOTAL'!S52 -> 0 | M34: ='RESUMEN TOTAL'!T52 -> 0 | ... AI34: ='RESUMEN TOTAL'!AP52 -> 0
A35: ='RESUMEN TOTAL'!A53 -> CENTRO | B35: ='RESUMEN TOTAL'!B53 -> CEN11 | C35: ='RESUMEN TOTAL'!D53 -> Monteagudo y Bocuzzi | D35: ='RESUMEN TOTAL'!E53 -> Domo | E35: ='RESUMEN TOTAL'!F53 -> Fibra Optica | F35: ='RESUMEN TOTAL'!M53 -> 0 | G35: ='RESUMEN TOTAL'!N53 -> 0 | H35: ='RESUMEN TOTAL'!O53 -> 0 | I35: ='RESUMEN TOTAL'!P53 -> 0 | J35: ='RESUMEN TOTAL'!Q53 -> 0 | K35: ='RESUMEN TOTAL'!R53 -> 0 | L35: ='RESUMEN TOTAL'!S53 -> 0 | M35: ='RESUMEN TOTAL'!T53 -> 0 | ... AI35: ='RESUMEN TOTAL'!AP53 -> 0
A36: ='RESUMEN TOTAL'!A54 -> CENTRO | B36: ='RESUMEN TOTAL'!B54 -> CEN 12 | C36: ='RESUMEN TOTAL'!D54 -> Monteagudo y Mitre | D36: ='RESUMEN TOTAL'!E54 -> Domo | E36: ='RESUMEN TOTAL'!F54 -> Fibra Optica | F36: ='RESUMEN TOTAL'!M54 -> 0 | G36: ='RESUMEN TOTAL'!N54 -> 0 | H36: ='RESUMEN TOTAL'!O54 -> 0 | I36: ='RESUMEN TOTAL'!P54 -> 0 | J36: ='RESUMEN TOTAL'!Q54 -> 0 | K36: ='RESUMEN TOTAL'!R54 -> 0 | L36: ='RESUMEN TOTAL'!S54 -> 0 | M36: ='RESUMEN TOTAL'!T54 -> 0 | ... AI36: ='RESUMEN TOTAL'!AP54 -> 0
... A71: ='RESUMEN TOTAL'!A89 -> CENTRO | B71: ='RESUMEN TOTAL'!B89 -> CEN47 | C71: ='RESUMEN TOTAL'!D89 -> Sallares y Brown | D71: ='RESUMEN TOTAL'!E89 -> Domo | E71: ='RESUMEN TOTAL'!F89 -> Fibra Optica | F71: ='RESUMEN TOTAL'!M89 -> 0 | G71: ='RESUMEN TOTAL'!N89 -> 0 | H71: ='RESUMEN TOTAL'!O89 -> 0 | I71: ='RESUMEN TOTAL'!P89 -> 0 | J71: ='RESUMEN TOTAL'!Q89 -> 0 | K71: ='RESUMEN TOTAL'!R89 -> 0 | L71: ='RESUMEN TOTAL'!S89 -> 0 | M71: ='RESUMEN TOTAL'!T89 -> 0 | ... AI71: ='RESUMEN TOTAL'!AP89 -> 0
A72: ='RESUMEN TOTAL'!A90 -> CENTRO | B72: ='RESUMEN TOTAL'!B90 -> CEN48 | C72: ='RESUMEN TOTAL'!D90 -> Velez Sarsfield y Las Heras | D72: ='RESUMEN TOTAL'!E90 -> Domo | E72: ='RESUMEN TOTAL'!F90 -> GPON | F72: ='RESUMEN TOTAL'!M90 -> 0 | G72: ='RESUMEN TOTAL'!N90 -> 0 | H72: ='RESUMEN TOTAL'!O90 -> 0 | I72: ='RESUMEN TOTAL'!P90 -> 0 | J72: ='RESUMEN TOTAL'!Q90 -> 0 | K72: ='RESUMEN TOTAL'!R90 -> 0 | L72: ='RESUMEN TOTAL'!S90 -> 0 | M72: ='RESUMEN TOTAL'!T90 -> 0 | ... Z72: ='RESUMEN TOTAL'!AG90 -> 0 | AA72: ='RESUMEN TOTAL'!#REF! -> #REF! | AB72: ='RESUMEN TOTAL'!AI90 -> 0 | AC72: ='RESUMEN TOTAL'!AJ90 -> 0 | AD72: ='RESUMEN TOTAL'!AK90 -> 0 | AE72: ='RESUMEN TOTAL'!AL90 -> 0 | AF72: ='RESUMEN TOTAL'!AM90 -> 0 | AG72: ='RESUMEN TOTAL'!AN90 -> 0 | AH72: ='RESUMEN TOTAL'!AO90 -> 0 | AI72: ='RESUMEN TOTAL'!AP90 -> 0
A73: ='RESUMEN TOTAL'!A91 -> CENTRO | B73: ='RESUMEN TOTAL'!B91 -> CEN49 | C73: ='RESUMEN TOTAL'!D91 -> Av. San Martin y Florencio Sanchez | D73: ='RESUMEN TOTAL'!E91 -> Domo | E73: ='RESUMEN TOTAL'!F91 -> Fibra Optica | F73: ='RESUMEN TOTAL'!M91 -> 0 | G73: ='RESUMEN TOTAL'!N91 -> 0 | H73: ='RESUMEN TOTAL'!O91 -> 0 | I73: ='RESUMEN TOTAL'!P91 -> 0 | J73: ='RESUMEN TOTAL'!Q91 -> 0 | K73: ='RESUMEN TOTAL'!R91 -> 0 | L73: ='RESUMEN TOTAL'!S91 -> 0 | M73: ='RESUMEN TOTAL'!T91 -> 0 | ... AI73: ='RESUMEN TOTAL'!AP91 -> 0
A74: ='RESUMEN TOTAL'!A92 -> CENTRO | B74: ='RESUMEN TOTAL'!B92 -> CEN 50 | C74: ='RESUMEN TOTAL'!D92 -> Av. San Martin y Newbery | D74: ='RESUMEN TOTAL'!E92 -> Domo | E74: ='RESUMEN TOTAL'!F92 -> GPON | F74: ='RESUMEN TOTAL'!M92 -> 0 | G74: ='RESUMEN TOTAL'!N92 -> 0 | H74: ='RESUMEN TOTAL'!O92 -> 0 | I74: ='RESUMEN TOTAL'!P92 -> 0 | J74: ='RESUMEN TOTAL'!Q92 -> 0 | K74: ='RESUMEN TOTAL'!R92 -> 0 | L74: ='RESUMEN TOTAL'!S92 -> 0 | M74: ='RESUMEN TOTAL'!T92 -> 0 | ... AI74: ='RESUMEN TOTAL'!AP92 -> 0
...

Sheet Hoja1
B1: CAMARAS | C1: 45890
A2: BONOMO | B2: =COUNTIFS('RESUMEN TOTAL'!C8:C548,"=BONOMO") -> 290 | C2: 57 | F2: 45901 | G2: 45902 | H2: 45903 | I2: 45904 | J2: 45905 | K2: 45906 | L2: 45907 | M2: 45908 | N2: 45909 | O2: 45910 | P2: 45911 | Q2: 45912 | R2: 45913 | S2: 45914 | T2: 45915 | U2: 45916 | V2: 45917 | W2: 45918 | X2: 45919 | Y2: 45920 | Z2: 45921 | AA2: 45922 | AB2: 45923 | AC2: 45924 | AD2: 45925 | AE2: 45926 | AF2: 45927 | AG2: 45928 | AH2: 45929 | AI2: 45930
C3: 0.2103321 | D3: BONOMO | E3: APAGADAS BONOMO | F3: =COUNTIFS('RESUMEN TOTAL'!M8:M656,"=APAGADO",'RESUMEN TOTAL'!C8:C656,"=BONOMO") -> 38 | G3: =COUNTIFS('RESUMEN TOTAL'!N8:N656,"=APAGADO",'RESUMEN TOTAL'!C8:C656,"=BONOMO") -> 36 | H3: =COUNTIFS('RESUMEN TOTAL'!O8:O656,"=APAGADO",'RESUMEN TOTAL'!C8:C656,"=BONOMO") -> 34 | I3: =COUNTIFS('RESUMEN TOTAL'!P8:P656,"=APAGADO",'RESUMEN TOTAL'!C8:C656,"=BONOMO") -> 35 | J3: =COUNTIFS('RESUMEN TOTAL'!Q8:Q656,"=APAGADO",'RESUMEN TOTAL'!C8:C656,"=BONOMO") -> 25 | K3: =COUNTIFS('RESUMEN TOTAL'!R8:R656,"=APAGADO",'RESUMEN TOTAL'!C8:C656,"=BONOMO") -> 46 | L3: =COUNTIFS('RESUMEN TOTAL'!S8:S656,"=APAGADO",'RESUMEN TOTAL'!C8:C656,"=BONOMO") -> 34 | M3: =COUNTIFS('RESUMEN TOTAL'!T8:T656,"=APAGADO",'RESUMEN TOTAL'!C8:C656,"=BONOMO") -> 25 | N3: =COUNTIFS('RESUMEN TOTAL'!U8:U656,"=APAGADO",'RESUMEN TOTAL'!C8:C656,"=BONOMO") -> 26 | O3: =COUNTIFS('RESUMEN TOTAL'!V8:V656,"=APAGADO",'RESUMEN TOTAL'!C8:C656,"=BONOMO") -> 29 | P3: =COUNTIFS('RESUMEN TOTAL'!W8:W656,"=APAGADO",'RESUMEN TOTAL'!C8:C656,"=BONOMO") -> 47 | Q3: =COUNTIFS('RESUMEN TOTAL'!X8:X656,"=APAGADO",'RESUMEN TOTAL'!C8:C656,"=BONOMO") -> 48 | R3: =COUNTIFS('RESUMEN TOTAL'!Y8:Y656,"=APAGADO",'RESUMEN TOTAL'!C8:C656,"=BONOMO") -> 30 | S3: =COUNTIFS('RESUMEN TOTAL'!Z8:Z656,"=APAGADO",'RESUMEN TOTAL'!C8:C656,"=BONOMO") -> 29 | T3: =COUNTIFS('RESUMEN TOTAL'!AA8:AA656,"=APAGADO",'RESUMEN TOTAL'!C8:C656,"=BONOMO") -> 33 | U3: =COUNTIFS('RESUMEN TOTAL'!AB8:AB656,"=APAGADO",'RESUMEN TOTAL'!C8:C656,"=BONOMO") -> 29 | V3: =COUNTIFS('RESUMEN TOTAL'!AC8:AC656,"=APAGADO",'RESUMEN TOTAL'!C8:C656,"=BONOMO") -> 26 | W3: =COUNTIFS('RESUMEN TOTAL'!AD8:AD656,"=APAGADO",'RESUMEN TOTAL'!C8:C656,"=BONOMO") -> 25 | X3: =COUNTIFS('RESUMEN TOTAL'!AE8:AE656,"=APAGADO",'RESUMEN TOTAL'!C8:C656,"=BONOMO") -> 22 | Y3: =COUNTIFS('RESUMEN TOTAL'!AF8:AF656,"=APAGADO",'RESUMEN TOTAL'!C8:C656,"=BONOMO") -> 31 | Z3: =COUNTIFS('RESUMEN TOTAL'!AG8:AG656,"=APAGADO",'RESUMEN TOTAL'!C8:C656,"=BONOMO") -> 31 | AA3: =COUNTIFS('RESUMEN TOTAL'!AH8:AH656,"=APAGADO",'RESUMEN TOTAL'!C8:C656,"=BONOMO") -> 35 | AB3: =COUNTIFS('RESUMEN TOTAL'!AI8:AI656,"=APAGADO",'RESUMEN TOTAL'!C8:C656,"=BONOMO") -> 36 | AC3: =COUNTIFS('RESUMEN TOTAL'!AJ8:AJ656,"=APAGADO",'RESUMEN TOTAL'!C8:C656,"=BONOMO") -> 29 | AD3: =COUNTIFS('RESUMEN TOTAL'!AK8:AK656,"=APAGADO",'RESUMEN TOTAL'!C8:C656,"=BONOMO") -> 29 | AE3: 0 | AF3: =COUNTIFS('RESUMEN TOTAL'!AM8:AM656,"=APAGADO",'RESUMEN TOTAL'!C8:C656,"=BONOMO") -> 0 | AG3: =COUNTIFS('RESUMEN TOTAL'!AN8:AN656,"=APAGADO",'RESUMEN TOTAL'!C8:C656,"=BONOMO") -> 0 | AH3: =COUNTIFS('RESUMEN TOTAL'!AO8:AO656,"=APAGADO",'RESUMEN TOTAL'!C8:C656,"=BONOMO") -> 0 | AI3: 0
A4: COSEIDI | B4: =COUNTIFS('RESUMEN TOTAL'!C8:C548,"=COSEIDI") -> 251 | C4: 52 | E4: % BONOMO | F4: =F3/BONOMOcam -> 0.13103448 | G4: =G3/BONOMOcam -> 0.12413793 | H4: =H3/BONOMOcam -> 0.11724138 | I4: =I3/BONOMOcam -> 0.12068966 | J4: 0 | K4: =K3/BONOMOcam -> 0.15862069 | L4: =L3/BONOMOcam -> 0.11724138 | M4: =M3/BONOMOcam -> 0.086206897 | N4: =N3/BONOMOcam -> 0.089655172 | O4: =O3/BONOMOcam -> 0.1 | P4: =P3/BONOMOcam -> 0.16206897 | Q4: =Q3/BONOMOcam -> 0.16551724 | R4: =R3/BONOMOcam -> 0.10344828 | ... AB4: =AB3/BONOMOcam -> 0.12413793 | AC4: 0.11 | AD4: =AD3/BONOMOcam -> 0.1 | AE4: =AE3/BONOMOcam -> 0 | AF4: =AF3/BONOMOcam -> 0 | AG4: =AG3/BONOMOcam -> 0 | AH4: =AH3/BONOMOcam -> 0 | AI4: 0
C5: 0.22317597 | D5: COSEIDI | E5: APAGADAS COSEIDI | F5: =COUNTIFS('RESUMEN TOTAL'!M10:M658,"=APAGADO",'RESUMEN TOTAL'!C10:C658,"=COSEIDI") -> 31 | G5: =COUNTIFS('RESUMEN TOTAL'!N10:N658,"=APAGADO",'RESUMEN TOTAL'!C10:C658,"=COSEIDI") -> 34 | H5: =COUNTIFS('RESUMEN TOTAL'!O10:O658,"=APAGADO",'RESUMEN TOTAL'!C10:C658,"=COSEIDI") -> 34 | I5: =COUNTIFS('RESUMEN TOTAL'!P10:P658,"=APAGADO",'RESUMEN TOTAL'!C10:C658,"=COSEIDI") -> 28 | J5: =COUNTIFS('RESUMEN TOTAL'!Q10:Q658,"=APAGADO",'RESUMEN TOTAL'!C10:C658,"=COSEIDI") -> 28 | K5: =COUNTIFS('RESUMEN TOTAL'!R10:R658,"=APAGADO",'RESUMEN TOTAL'!C10:C658,"=COSEIDI") -> 34 | L5: =COUNTIFS('RESUMEN TOTAL'!S10:S658,"=APAGADO",'RESUMEN TOTAL'!C10:C658,"=COSEIDI") -> 37 | M5: =COUNTIFS('RESUMEN TOTAL'!T10:T658,"=APAGADO",'RESUMEN TOTAL'!C10:C658,"=COSEIDI") -> 37 | N5: =COUNTIFS('RESUMEN TOTAL'!U10:U658,"=APAGADO",'RESUMEN TOTAL'!C10:C658,"=COSEIDI") -> 28 | O5: =COUNTIFS('RESUMEN TOTAL'!V10:V658,"=APAGADO",'RESUMEN TOTAL'!C10:C658,"=COSEIDI") -> 31 | P5: =COUNTIFS('RESUMEN TOTAL'!W10:W658,"=APAGADO",'RESUMEN TOTAL'!C10:C658,"=COSEIDI") -> 27 | Q5: =COUNTIFS('RESUMEN TOTAL'!X10:X658,"=APAGADO",'RESUMEN TOTAL'!C10:C658,"=COSEIDI") -> 21 | R5: =COUNTIFS('RESUMEN TOTAL'!Y10:Y658,"=APAGADO",'RESUMEN TOTAL'!C10:C658,"=COSEIDI") -> 21 | S5: =COUNTIFS('RESUMEN TOTAL'!Z10:Z658,"=APAGADO",'RESUMEN TOTAL'!C10:C658,"=COSEIDI") -> 16 | T5: =COUNTIFS('RESUMEN TOTAL'!AA10:AA658,"=APAGADO",'RESUMEN TOTAL'!C10:C658,"=COSEIDI") -> 21 | U5: 26 | V5: =COUNTIFS('RESUMEN TOTAL'!AC10:AC658,"=APAGADO",'RESUMEN TOTAL'!C10:C658,"=COSEIDI") -> 29 | W5: =COUNTIFS('RESUMEN TOTAL'!AD10:AD658,"=APAGADO",'RESUMEN TOTAL'!C10:C658,"=COSEIDI") -> 24 | X5: =COUNTIFS('RESUMEN TOTAL'!AE10:AE658,"=APAGADO",'RESUMEN TOTAL'!C10:C658,"=COSEIDI") -> 56 | Y5: =COUNTIFS('RESUMEN TOTAL'!AF10:AF658,"=APAGADO",'RESUMEN TOTAL'!C10:C658,"=COSEIDI") -> 55 | Z5: =COUNTIFS('RESUMEN TOTAL'!AG10:AG658,"=APAGADO",'RESUMEN TOTAL'!C10:C658,"=COSEIDI") -> 94 | AA5: =COUNTIFS('RESUMEN TOTAL'!AH10:AH658,"=APAGADO",'RESUMEN TOTAL'!C10:C658,"=COSEIDI") -> 60 | AB5: =COUNTIFS('RESUMEN TOTAL'!AI10:AI658,"=APAGADO",'RESUMEN TOTAL'!C10:C658,"=COSEIDI") -> 26 | AC5: =COUNTIFS('RESUMEN TOTAL'!AJ10:AJ658,"=APAGADO",'RESUMEN TOTAL'!C10:C658,"=COSEIDI") -> 24 | AD5: =COUNTIFS('RESUMEN TOTAL'!AK10:AK658,"=APAGADO",'RESUMEN TOTAL'!C10:C658,"=COSEIDI") -> 22 | AE5: =COUNTIFS('RESUMEN TOTAL'!AL10:AL658,"=APAGADO",'RESUMEN TOTAL'!C10:C658,"=COSEIDI") -> 0 | AF5: =COUNTIFS('RESUMEN TOTAL'!AM10:AM658,"=APAGADO",'RESUMEN TOTAL'!C10:C658,"=COSEIDI") -> 0 | AG5: =COUNTIFS('RESUMEN TOTAL'!AN10:AN658,"=APAGADO",'RESUMEN TOTAL'!C10:C658,"=COSEIDI") -> 0 | AH5: =COUNTIFS('RESUMEN TOTAL'!AO10:AO658,"=APAGADO",'RESUMEN TOTAL'!C10:C658,"=COSEIDI") -> 0 | AI5: =COUNTIFS('RESUMEN TOTAL'!AP10:AP658,"=APAGADO",'RESUMEN TOTAL'!C10:C658,"=COSEIDI") -> 0
E6: % COSEIDI | F6: 0.12 | G6: 0.12 | H6: =H5/COSEIDIcam -> 0.13545817 | I6: 0.1 | J6: 0 | K6: =K5/COSEIDIcam -> 0.13545817 | L6: =L5/COSEIDIcam -> 0.14741036 | M6: =M5/COSEIDIcam -> 0.14741036 | N6: =N5/COSEIDIcam -> 0.11155378 | O6: =O5/COSEIDIcam -> 0.12350598 | P6: =P5/COSEIDIcam -> 0.10756972 | Q6: =Q5/COSEIDIcam -> 0.083665339 | R6: =R5/COSEIDIcam -> 0.083665339 | ... V6: =V5/COSEIDIcam -> 0.11553785 | W6: 0.08 | X6: =X5/COSEIDIcam -> 0.22310757 | Y6: =Y5/COSEIDIcam -> 0.21912351 | Z6: =Z5/COSEIDIcam -> 0.37450199 | AA6: =AA5/COSEIDIcam -> 0.23904382 | AB6: =AB5/COSEIDIcam -> 0.10358566 | AC6: 0.09 | AD6: =AD5/COSEIDIcam -> 0.087649402 | AE6: =AE5/COSEIDIcam -> 0 | AF6: =AF5/COSEIDIcam -> 0 | AG6: =AG5/COSEIDIcam -> 0 | AH6: =AH5/COSEIDIcam -> 0 | AI6: 0
