Workbook
Name _25_de_agosto: 'RESUMEN TOTAL'!$A$7:$D$443
Name _25_de_agosto_3: 'RESUMEN TOTAL'!$A$7:$D$455
Name _30_mar: #REF!
Name BONOMOcam: Hoja1!$B$2
Name CANTIDAD_DE_CAMARAS: 'RESUMEN TOTAL'!$B$1
Name COSEIDIcam: Hoja1!$B$4

Sheet RESUMEN TOTAL
A1: CANTIDAD DE CAMARAS | B1: =COUNTA(B8:B678) -> 517 | D1: PORCIENTO DE CAIDAS | L1: =(L3)/(L2+L3) -> 0.14686469 | M1: =(M3)/(M2+M3) -> 0 | N1: =(N3)/(N2+N3) -> 0.14262023 | O1: =(O3)/(O2+O3) -> 0.14545455 | P1: =(P3)/(P2+P3) -> 0.11623932 | Q1: =(Q3)/(Q2+Q3) -> 0.12816189 | R1: =(R3)/(R2+R3) -> 0.10553633 | S1: =(S3)/(S2+S3) -> 0.12372881 | ... X1: =(X3)/(X2+X3) -> 0.13109244 | Z1: =(Z3)/(Z2+Z3) -> 0.12962963 | AA1: =(AA3)/(AA2+AA3) -> 0.15245902 | AB1: =(AB3)/(AB2+AB3) -> 0.15384615 | AC1: =(AC3)/(AC2+AC3) -> 0.14686469 | AD1: =(AD3)/(AD2+AD3) -> 0.14827018 | AE1: =(AE3)/(AE2+AE3) -> 0.17014446 | AF1: =(AF3)/(AF2+AF3) -> 0.17412141 | AG1: =(AG3)/(AG2+AG3) -> 0.13400335 | ... AP1: =(AP3)/(AP2+AP3) -> 0
D2: FUNCIONAN | L2: =CANTIDAD_DE_CAMARAS -> 517 | M2: =CANTIDAD_DE_CAMARAS -> 517 | N2: =CANTIDAD_DE_CAMARAS -> 517 | O2: =CANTIDAD_DE_CAMARAS -> 517 | P2: =CANTIDAD_DE_CAMARAS -> 517 | Q2: =CANTIDAD_DE_CAMARAS -> 517 | R2: =CANTIDAD_DE_CAMARAS -> 517 | S2: =CANTIDAD_DE_CAMARAS -> 517 | ... AP2: =CANTIDAD_DE_CAMARAS -> 517
D3: CAIDAS | L3: =COUNTIF(L7:L678, "apagado") -> 89 | M3: =COUNTIF(M7:M678, "apagado") -> 0 | N3: =COUNTIF(N7:N678, "apagado") -> 86 | O3: =COUNTIF(O7:O678, "apagado") -> 88 | P3: =COUNTIF(P7:P678, "apagado") -> 68 | Q3: =COUNTIF(Q7:Q678, "apagado") -> 76 | R3: =COUNTIF(R7:R678, "apagado") -> 61 | S3: =COUNTIF(S7:S678, "apagado") -> 73 | ... AP3: =COUNTIF(AP7:AP678, "apagado") -> 0
D4: APAGADOS FIBRA | L4: =COUNTIFS(L8:L632, "=APAGADO",F8:F632,"=Fibra Optica") -> 57 | M4: =COUNTIFS(M8:M632, "=APAGADO",F8:F632,"=Fibra Optica") -> 0 | N4: =COUNTIFS(N8:N632, "=APAGADO",F8:F632,"=Fibra Optica") -> 59 | O4: =COUNTIFS(O8:O632, "=APAGADO",F8:F632,"=Fibra Optica") -> 61 | P4: =COUNTIFS(P8:P632, "=APAGADO",F8:F632,"=Fibra Optica") -> 39 | Q4: =COUNTIFS(Q8:Q632, "=APAGADO",F8:F632,"=Fibra Optica") -> 54 | R4: =COUNTIFS(R8:R632, "=APAGADO",F8:F632,"=Fibra Optica") -> 39 | S4: =COUNTIFS(S8:S632, "=APAGADO",F8:F632,"=Fibra Optica") -> 49 | T4: =COUNTIFS(T8:T632, "=APAGADO",F8:F632,"=Fibra Optica") -> 43 | U4: =COUNTIFS(U8:U632, "=APAGADO",F8:F632,"=Fibra Optica") -> 43 | V4: =COUNTIFS(V8:V632, "=APAGADO",F8:F632,"=Fibra Optica") -> 44 | W4: =COUNTIFS(W8:W632, "=APAGADO",F8:F632,"=Fibra Optica") -> 43 | X4: =COUNTIFS(X8:X632, "=APAGADO",F8:F632,"=Fibra Optica") -> 50 | Y4: =COUNTIFS(Y8:Y632, "=APAGADO",F8:F632,"=Fibra Optica") -> 71 | Z4: =COUNTIFS(Z8:Z632, "=APAGADO",F8:F632,"=Fibra Optica") -> 50 | AA4: =COUNTIFS(AA8:AA632, "=APAGADO",F8:F632,"=Fibra Optica") -> 64 | AB4: =COUNTIFS(AB8:AB632, "=APAGADO",F8:F632,"=Fibra Optica") -> 62 | AC4: =COUNTIFS(AC8:AC632, "=APAGADO",F8:F632,"=Fibra Optica") -> 58 | AD4: =COUNTIFS(AD8:AD632, "=APAGADO",F8:F632,"=Fibra Optica") -> 59 | AE4: =COUNTIFS(AE8:AE632, "=APAGADO",F8:F632,"=Fibra Optica") -> 72 | AF4: =COUNTIFS(AF8:AF632, "=APAGADO",F8:F632,"=Fibra Optica") -> 69 | AG4: =COUNTIFS(AG8:AG632, "=APAGADO",F8:F632,"=Fibra Optica") -> 42 | AH4: =COUNTIFS(AH8:AH632, "=APAGADO",F8:F632,"=Fibra Optica") -> 46 | AI4: =COUNTIFS(AI8:AI632, "=APAGADO",F8:F632,"=Fibra Optica") -> 49 | AJ4: =COUNTIFS(AJ8:AJ632, "=APAGADO",F8:F632,"=Fibra Optica") -> 48 | AK4: =COUNTIFS(AK8:AK632, "=APAGADO",F8:F632,"=Fibra Optica") -> 42 | AL4: =COUNTIFS(AL8:AL632, "=APAGADO",F8:F632,"=Fibra Optica") -> 53 | AM4: =COUNTIFS(AM8:AM632, "=APAGADO",F8:F632,"=Fibra Optica") -> 43 | AN4: =COUNTIFS(AN8:AN632, "=APAGADO",F8:F632,"=Fibra Optica") -> 0 | AO4: =COUNTIFS(AO8:AO632, "=APAGADO",F8:F632,"=Fibra Optica") -> 0 | AP4: =COUNTIFS(AP8:AP632, "=APAGADO",G8:G632,"=Fibra Optica") -> 0
D5: APAGADOS RADIO | L5: =COUNTIFS(L8:L632, "=APAGADO",F8:F632,"=RADIO") -> 14 | M5: =COUNTIFS(M8:M632, "=APAGADO",F8:F632,"=RADIO") -> 0 | N5: =COUNTIFS(N8:N632, "=APAGADO",F8:F632,"=RADIO") -> 14 | O5: =COUNTIFS(O8:O632, "=APAGADO",F8:F632,"=RADIO") -> 14 | P5: =COUNTIFS(P8:P632, "=APAGADO",F8:F632,"=RADIO") -> 17 | Q5: =COUNTIFS(Q8:Q632, "=APAGADO",F8:F632,"=RADIO") -> 13 | R5: =COUNTIFS(R8:R632, "=APAGADO",F8:F632,"=RADIO") -> 13 | S5: =COUNTIFS(S8:S632, "=APAGADO",F8:F632,"=RADIO") -> 16 | T5: =COUNTIFS(T8:T632, "=APAGADO",F8:F632,"=RADIO") -> 15 | U5: =COUNTIFS(U8:U632, "=APAGADO",F8:F632,"=RADIO") -> 17 | V5: =COUNTIFS(V8:V632, "=APAGADO",F8:F632,"=RADIO") -> 19 | W5: =COUNTIFS(W8:W632, "=APAGADO",F8:F632,"=RADIO") -> 15 | X5: =COUNTIFS(X8:X632, "=APAGADO",F8:F632,"=RADIO") -> 16 | Y5: =COUNTIFS(Y8:Y632, "=APAGADO",F8:F632,"=RADIO") -> 20 | Z5: =COUNTIFS(Z8:Z632, "=APAGADO",F8:F632,"=RADIO") -> 14 | AA5: =COUNTIFS(AA8:AA632, "=APAGADO",F8:F632,"=RADIO") -> 14 | AB5: =COUNTIFS(AB8:AB632, "=APAGADO",F8:F632,"=RADIO") -> 15 | AC5: =COUNTIFS(AC8:AC632, "=APAGADO",F8:F632,"=RADIO") -> 16 | AD5: =COUNTIFS(AD8:AD632, "=APAGADO",F8:F632,"=RADIO") -> 17 | AE5: =COUNTIFS(AE8:AE632, "=APAGADO",F8:F632,"=RADIO") -> 18 | AF5: =COUNTIFS(AF8:AF632, "=APAGADO",F8:F632,"=RADIO") -> 23 | AG5: =COUNTIFS(AG8:AG632, "=APAGADO",F8:F632,"=RADIO") -> 24 | AH5: =COUNTIFS(AH8:AH632, "=APAGADO",F8:F632,"=RADIO") -> 21 | AI5: =COUNTIFS(AI8:AI632, "=APAGADO",F8:F632,"=RADIO") -> 21 | AJ5: =COUNTIFS(AJ8:AJ632, "=APAGADO",F8:F632,"=RADIO") -> 24 | AK5: =COUNTIFS(AK8:AK632, "=APAGADO",F8:F632,"=RADIO") -> 24 | AL5: =COUNTIFS(AL8:AL632, "=APAGADO",F8:F632,"=RADIO") -> 21 | AM5: =COUNTIFS(AM8:AM632, "=APAGADO",F8:F632,"=RADIO") -> 19 | AN5: =COUNTIFS(AN8:AN632, "=APAGADO",F8:F632,"=RADIO") -> 0 | AO5: =COUNTIFS(AO8:AO632, "=APAGADO",F8:F632,"=RADIO") -> 0 | AP5: =COUNTIFS(AP8:AP632, "=APAGADO",G8:G632,"=RADIO") -> 0
D6: APAGADOS ANTENA | L6: =COUNTIFS(L8:L632, "=APAGADO",F8:F632,"=PTO A FO") -> 10 | M6: =COUNTIFS(M8:M632, "=APAGADO",F8:F632,"=PTO A FO") -> 0 | N6: =COUNTIFS(N8:N632, "=APAGADO",F8:F632,"=PTO A FO") -> 8 | O6: =COUNTIFS(O8:O632, "=APAGADO",F8:F632,"=PTO A FO") -> 8 | P6: =COUNTIFS(P8:P632, "=APAGADO",F8:F632,"=PTO A FO") -> 8 | Q6: =COUNTIFS(Q8:Q632, "=APAGADO",F8:F632,"=PTO A FO") -> 6 | R6: =COUNTIFS(R8:R632, "=APAGADO",F8:F632,"=PTO A FO") -> 7 | S6: =COUNTIFS(S8:S632, "=APAGADO",F8:F632,"=PTO A FO") -> 7 | T6: =COUNTIFS(T8:T632, "=APAGADO",F8:F632,"=PTO A FO") -> 7 | U6: =COUNTIFS(U8:U632, "=APAGADO",F8:F632,"=PTO A FO") -> 7 | V6: =COUNTIFS(V8:V632, "=APAGADO",F8:F632,"=PTO A FO") -> 6 | W6: =COUNTIFS(W8:W632, "=APAGADO",F8:F632,"=PTO A FO") -> 6 | X6: =COUNTIFS(X8:X632, "=APAGADO",F8:F632,"=PTO A FO") -> 8 | Y6: =COUNTIFS(Y8:Y632, "=APAGADO",F8:F632,"=PTO A FO") -> 9 | Z6: =COUNTIFS(Z8:Z632, "=APAGADO",F8:F632,"=PTO A FO") -> 8 | AA6: =COUNTIFS(AA8:AA632, "=APAGADO",F8:F632,"=PTO A FO") -> 8 | AB6: =COUNTIFS(AB8:AB632, "=APAGADO",F8:F632,"=PTO A FO") -> 9 | AC6: =COUNTIFS(AC8:AC632, "=APAGADO",F8:F632,"=PTO A FO") -> 9 | AD6: =COUNTIFS(AD8:AD632, "=APAGADO",F8:F632,"=PTO A FO") -> 8 | AE6: =COUNTIFS(AE8:AE632, "=APAGADO",F8:F632,"=PTO A FO") -> 10 | AF6: =COUNTIFS(AF8:AF632, "=APAGADO",F8:F632,"=PTO A FO") -> 11 | AG6: =COUNTIFS(AG8:AG632, "=APAGADO",F8:F632,"=PTO A FO") -> 7 | AH6: =COUNTIFS(AH8:AH632, "=APAGADO",F8:F632,"=PTO A FO") -> 7 | AI6: =COUNTIFS(AI8:AI632, "=APAGADO",F8:F632,"=PTO A FO") -> 8 | AJ6: =COUNTIFS(AJ8:AJ632, "=APAGADO",F8:F632,"=PTO A FO") -> 8 | AK6: =COUNTIFS(AK8:AK632, "=APAGADO",F8:F632,"=PTO A FO") -> 8 | AL6: =COUNTIFS(AL8:AL632, "=APAGADO",F8:F632,"=PTO A FO") -> 10 | AM6: =COUNTIFS(AM8:AM632, "=APAGADO",F8:F632,"=PTO A FO") -> 8 | AN6: =COUNTIFS(AN8:AN632, "=APAGADO",F8:F632,"=PTO A FO") -> 0 | AO6: =COUNTIFS(AO8:AO632, "=APAGADO",F8:F632,"=PTO A FO") -> 0 | AP6: =COUNTIFS(AP8:AP632, "=APAGADO",G8:G632,"=PTO A FO") -> 0
A7: Barrio | B7: [Denominacion] | C7: [Empresa Mantenimiento] | D7: [Ubicacion] | E7: [Tipo de Camara] | F7: [Tipo de Conexion] | G7: Destino | I7: DIAS FUNCIONANDO | J7: DIAS CAIDA | K7: EFECTIVIDAD | L7: 45870 | M7: 45871 | N7: 45872 | O7: 45873 | P7: 45874 | Q7: 45875 | R7: 45876 | S7: 45877 | T7: 45878 | U7: 45879 | V7: 45880 | W7: 45881 | X7: 45882 | Y7: 45883 | Z7: 45884 | AA7: 45885 | AB7: 45886 | AC7: 45887 | AD7: 45888 | AE7: 45889 | AF7: 45890 | AG7: 45891 | AH7: 45892 | AI7: 45893 | AJ7: 45894 | AK7: 45895 | AL7: 45896 | AM7: 45897 | AN7: 45898 | AO7: 45899 | AP7: 45900
A8: ALTAMIRA | B8: ALT01 | C8: BONOMO | D8: Calchaqui y Sgto. Cabral | E8: Domo | F8: Fibra Optica | H8: 172.20.10.6 | I8: =COUNTIF(L8:AM8,"") -> 28 | J8: =COUNTIF(L8:AM8,"APAGADO") -> 0 | K8: =(I8)/(J8+I8) -> 1
A9: ALTAMIRA | B9: ALT02 | C9: BONOMO | D9: Calchaqui y Lope de Vega | E9: Domo | F9: PTO A FO | G9: CABRAL Y CALCHAQUI | H9: 172.20.12.218 | I9: =COUNTIF(L9:AM9,"") -> 28 | J9: =COUNTIF(L9:AM9,"APAGADO") -> 0 | K9: =(I9)/(J9+I9) -> 1
A10: ALTAMIRA | B10: ALT 03 | C10: BONOMO | D10: Bombero Galarza y Necochea | E10: Domo | F10: Fibra Optica | H10: 172.20.12.54 | I10: =COUNTIF(L10:AM10,"") -> 28 | J10: =COUNTIF(L10:AM10,"APAGADO") -> 0 | K10: =(I10)/(J10+I10) -> 1
A11: ALTAMIRA | B11: ALT 04 | C11: BONOMO | D11: Francia y Necochea | E11: Domo | F11: GPON | H11: 172.20.12.55 | I11: =COUNTIF(L11:AM11,"") -> 24 | J11: =COUNTIF(L11:AM11,"APAGADO") -> 4 | K11: =(I11)/(J11+I11) -> 0.85714286 | L11: APAGADO | P11: APAGADO | Q11: APAGADO | AB11: APAGADO
A12: ALTAMIRA | B12: ALT05 | C12: BONOMO | D12: Av. Calchaqui y Bombero Galarza | E12: Domo | F12: PTO A FO | G12: NECOCHEA Y GALARZA | H12: 172.20.12.216 | I12: =COUNTIF(L12:AM12,"") -> 2 | J12: =COUNTIF(L12:AM12,"APAGADO") -> 26 | K12: =(I12)/(J12+I12) -> 0.071428571 | L12: APAGADO | N12: APAGADO | O12: APAGADO | P12: APAGADO | R12: APAGADO | S12: APAGADO | T12: APAGADO | U12: APAGADO | V12: APAGADO | W12: APAGADO | X12: APAGADO | Y12: APAGADO | Z12: APAGADO | AA12: APAGADO | AB12: APAGADO | AC12: APAGADO | AD12: APAGADO | AE12: APAGADO | AF12: APAGADO | AG12: APAGADO | AH12: APAGADO | AI12: APAGADO | AJ12: APAGADO | AK12: APAGADO | AL12: APAGADO | AM12: APAGADO
A13: ALTAMIRA | B13: ALT 06 | C13: BONOMO | D13: LOPE DE VEGA Y NECOCHEA | E13: Domo | F13: PTO A FO | G13: NECOCHEA Y GALARZA | H13: 172.20.12.12 | I13: =COUNTIF(L13:AM13,"") -> 28 | J13: =COUNTIF(L13:AM13,"APAGADO") -> 0 | K13: =(I13)/(J13+I13) -> 1
A14: ALTAMIRA | B14: ALT07 | C14: BONOMO | D14: AV. CALCHAQUI Y AV. DEL TRABAJO | E14: DOMO | F14: PTO A FO | G14: CABRAL Y CALCHAQUI | H14: 172.20.10.57 | I14: =COUNTIF(L14:AM14,"") -> 28 | J14: =COUNTIF(L14:AM14,"APAGADO") -> 0 | K14: =(I14)/(J14+I14) -> 1
A15: ALTAMIRA | B15: ALT 08 | C15: BONOMO | D15: HUMAITA Y NECOCHEA | E15: DOMO | F15: Fibra Optica | H15: 172.20.11.215 | I15: =COUNTIF(L15:AM15,"") -> 28 | J15: =COUNTIF(L15:AM15,"APAGADO") -> 0 | K15: =(I15)/(J15+I15) -> 1
A16: ALTAMIRA | B16: ALT 09 | C16: BONOMO | D16: NECOCHEA Y CURUPAITY | E16: DOMO | F16: Fibra Optica | H16: 172.20.11.216 | I16: =COUNTIF(L16:AM16,"") -> 28 | J16: =COUNTIF(L16:AM16,"APAGADO") -> 0 | K16: =(I16)/(J16+I16) -> 1
A17: ALTAMIRA | B17: ALT 10 | C17: BONOMO | D17: Calchaqui y Francia | E17: Domo | F17: Radio | H17: 172.20.12.156 | I17: =COUNTIF(L17:AM17,"") -> 1 | J17: =COUNTIF(L17:AM17,"APAGADO") -> 27 | K17: =(I17)/(J17+I17) -> 0.035714286 | L17: APAGADO | N17: APAGADO | O17: APAGADO | P17: APAGADO | Q17: APAGADO | R17: APAGADO | S17: APAGADO | T17: APAGADO | U17: APAGADO | V17: APAGADO | W17: APAGADO | X17: APAGADO | Y17: APAGADO | Z17: APAGADO | AA17: APAGADO | AB17: APAGADO | AC17: APAGADO | AD17: APAGADO | AE17: APAGADO | AF17: APAGADO | AG17: APAGADO | AH17: APAGADO | AI17: APAGADO | AJ17: APAGADO | AK17: APAGADO | AL17: APAGADO | AM17: APAGADO
A18: ALTAMIRA | B18: ALT 11 | C18: BONOMO | D18: CALCHAQUÍ Y GALARZA FIJA | E18: Fija | F18: Fibra Optica | H18: 172.20.12.241 | I18: =COUNTIF(L18:AM18,"") -> 1 | J18: =COUNTIF(L18:AM18,"APAGADO") -> 27 | K18: =(I18)/(J18+I18) -> 0.035714286 | L18: APAGADO | N18: APAGADO | O18: APAGADO | P18: APAGADO | Q18: APAGADO | R18: APAGADO | S18: APAGADO | T18: APAGADO | U18: APAGADO | V18: APAGADO | W18: APAGADO | X18: APAGADO | Y18: APAGADO | Z18: APAGADO | AA18: APAGADO | AB18: APAGADO | AC18: APAGADO | AD18: APAGADO | AE18: APAGADO | AF18: APAGADO | AG18: APAGADO | AH18: APAGADO | AI18: APAGADO | AJ18: APAGADO | AK18: APAGADO | AL18: APAGADO | AM18: APAGADO
A19: AGUSTIN RAMIREZ | B19: ARA 01 | C19: BONOMO | D19: Malambo y Tranquera | E19: Domo | F19: Fibra Optica | H19: 172.20.12.110 | I19: =COUNTIF(L19:AM19,"") -> 28 | J19: =COUNTIF(L19:AM19,"APAGADO") -> 0 | K19: =(I19)/(J19+I19) -> 1
A20: AGUSTIN RAMIREZ | B20: ARA 02 | C20: BONOMO | D20: El malambo y La Tranquera | E20: Fija | F20: GPON | H20: 172.20.12.235
A21: AGUSTIN RAMIREZ | B21: ARA 03 | C21: BONOMO | D21: 437 Y La Tranquera | F21: GPON | H21: 172.20.10.232
A22: BELGRANO | B22: BEL 01 | C22: BONOMO | D22: San Martin y Dardo Rocha | E22: DOMO | F22: Fibra Optica | H22: 172.20.12.64 | I22: =COUNTIF(L22:AM22,"") -> 16 | J22: =COUNTIF(L22:AM22,"APAGADO") -> 12 | K22: =(I22)/(J22+I22) -> 0.57142857 | AB22: APAGADO | AC22: APAGADO | AD22: APAGADO | AE22: APAGADO | AF22: APAGADO | AG22: APAGADO | AH22: APAGADO | AI22: APAGADO | AJ22: APAGADO | AK22: APAGADO | AL22: APAGADO | AM22: APAGADO
A23: BELGRANO | B23: BEL 02 | C23: BONOMO | D23: Guardia vieja y Fronteriz | E23: DOMO | F23: Fibra Optica | H23: 172.20.10.117 | I23: =COUNTIF(L23:AM23,"") -> 28 | J23: =COUNTIF(L23:AM23,"APAGADO") -> 0 | K23: =(I23)/(J23+I23) -> 1
A24: BOSQUES CENTRO | B24: BOSQC 01 | C24: COSEIDI | D24: LUIS AGOTE E/DANUNCIO Y CAMPOAMOR | E24: Fija | F24: Radio | H24: 172.20.11.15 | I24: =COUNTIF(L24:AM24,"") -> 17 | J24: =COUNTIF(L24:AM24,"APAGADO") -> 11 | K24: =(I24)/(J24+I24) -> 0.60714286 | U24: APAGADO | V24: APAGADO | Y24: APAGADO | AF24: APAGADO | AG24: APAGADO | AH24: APAGADO | AI24: APAGADO | AJ24: APAGADO | AK24: APAGADO | AL24: APAGADO | AM24: APAGADO
A25: BOSQUES CENTRO | B25: BOSQC 02 | C25: COSEIDI | D25: LUIS AGOTE E/DANUNCIO Y CAMPOAMOR | E25: Fija | F25: Radio | H25: 172.20.11.16 | I25: =COUNTIF(L25:AM25,"") -> 17 | J25: =COUNTIF(L25:AM25,"APAGADO") -> 11 | K25: =(I25)/(J25+I25) -> 0.60714286 | U25: APAGADO | V25: APAGADO | Y25: APAGADO | AF25: APAGADO | AG25: APAGADO | AH25: APAGADO | AI25: APAGADO | AJ25: APAGADO | AK25: APAGADO | AL25: APAGADO | AM25: APAGADO
A26: BOSQUES CENTRO | B26: BOSQC 03 | C26: COSEIDI | D26: BENAVENTE Y LUIS AGOTE | E26: Fija | F26: Radio | H26: 172.20.11.13 | I26: =COUNTIF(L26:AM26,"") -> 17 | J26: =COUNTIF(L26:AM26,"APAGADO") -> 11 | K26: =(I26)/(J26+I26) -> 0.60714286 | U26: APAGADO | V26: APAGADO | Y26: APAGADO | AF26: APAGADO | AG26: APAGADO | AH26: APAGADO | AI26: APAGADO | AJ26: APAGADO | AK26: APAGADO | AL26: APAGADO | AM26: APAGADO
A27: BOSQUES CENTRO | B27: BOSQC 04 | C27: COSEIDI | D27: BENAVENTE Y LUIS AGOTE | E27: Fija | F27: Radio | H27: 172.20.11.113 | I27: =COUNTIF(L27:AM27,"") -> 17 | J27: =COUNTIF(L27:AM27,"APAGADO") -> 11 | K27: =(I27)/(J27+I27) -> 0.60714286 | U27: APAGADO | V27: APAGADO | Y27: APAGADO | AF27: APAGADO | AG27: APAGADO | AH27: APAGADO | AI27: APAGADO | AJ27: APAGADO | AK27: APAGADO | AL27: APAGADO | AM27: APAGADO
A28: BOSQUES CENTRO | B28: BOSQC 05 | C28: COSEIDI | D28: LUIS AGOTE Y RUTA 36 | E28: Fija | F28: Radio | H28: 172.20.11.17 | I28: =COUNTIF(L28:AM28,"") -> 27 | J28: =COUNTIF(L28:AM28,"APAGADO") -> 1 | K28: =(I28)/(J28+I28) -> 0.96428571 | Y28: APAGADO
A29: BOSQUES CENTRO | B29: BOSQC 06 | C29: COSEIDI | D29: LUIS AGOTE Y RUTA 36 | E29: Fija | F29: Radio | H29: 172.20.11.18 | I29: =COUNTIF(L29:AM29,"") -> 27 | J29: =COUNTIF(L29:AM29,"APAGADO") -> 1 | K29: =(I29)/(J29+I29) -> 0.96428571 | Y29: APAGADO
A30: BOSQUES CENTRO | B30: BOSQC 07 | C30: BONOMO | D30: Touring club y Sta Teresita | E30: Domo | F30: Fibra Optica | H30: 172.20.10.141 | I30: =COUNTIF(L30:AM30,"") -> 28 | J30: =COUNTIF(L30:AM30,"APAGADO") -> 0 | K30: =(I30)/(J30+I30) -> 1
A31: BOSQUES CENTRO | B31: PAVE01 | C31: COSEIDI | D31: Touring Club y Ramallo | E31: Domo | F31: Fibra Optica | H31: 172.20.10.144 | I31: =COUNTIF(L31:AM31,"") -> 2 | J31: =COUNTIF(L31:AM31,"APAGADO") -> 26 | K31: =(I31)/(J31+I31) -> 0.071428571 | L31: APAGADO | N31: APAGADO | O31: APAGADO | P31: APAGADO | Q31: APAGADO | R31: APAGADO | S31: APAGADO | T31: APAGADO | U31: APAGADO | V31: APAGADO | W31: APAGADO | X31: APAGADO | Y31: APAGADO | Z31: APAGADO | AA31: APAGADO | AB31: APAGADO | AC31: APAGADO | AD31: APAGADO | AE31: APAGADO | AF31: APAGADO | AG31: APAGADO | AH31: APAGADO | AI31: APAGADO | AJ31: APAGADO | AK31: APAGADO | AM31: APAGADO
A32: BOSQUES CENTRO | B32: PAVE02 | C32: COSEIDI | D32: Ramallo y Calingasta | F32: Fibra Optica | H32: 172.20.10.37 | I32: =COUNTIF(L32:AM32,"") -> 24 | J32: =COUNTIF(L32:AM32,"APAGADO") -> 4 | K32: =(I32)/(J32+I32) -> 0.85714286 | O32: APAGADO | P32: APAGADO | AK32: APAGADO | AM32: APAGADO
A33: BOSQUES CENTRO | B33: CVA01 | C33: COSEIDI | D33: CACHEUTA Y 1355 | F33: Fibra Optica | H33: 172.20.10.59
A34: LA CAROLINA 2 | B34: CAR01 (Fija 1) | C34: COSEIDI | D34: Azurduy y Vergara | E34: Fija | F34: Fibra Optica | H34: 172.20.10.60 | I34: =COUNTIF(L34:AM34,"") -> 28 | J34: =COUNTIF(L34:AM34,"APAGADO") -> 0 | K34: =(I34)/(J34+I34) -> 1
A35: LA CAROLINA 2 | B35: CAR02 (Fija 2) | C35: COSEIDI | D35: Azurduy y Vergara | E35: Fija | F35: Fibra Optica | H35: 172.20.10.73 | I35: =COUNTIF(L35:AM35,"") -> 28 | J35: =COUNTIF(L35:AM35,"APAGADO") -> 0 | K35: =(I35)/(J35+I35) -> 1
A36: CENTRO | B36: CEN01 | C36: BONOMO | D36: San Martin y 9 de Julio | E36: Fija | F36: Fibra Optica | H36: 172.20.11.10 | I36: =COUNTIF(L36:AM36,"") -> 28 | J36: =COUNTIF(L36:AM36,"APAGADO") -> 0 | K36: =(I36)/(J36+I36) -> 1
A37: CENTRO | B37: CEN02 | C37: BONOMO | D37: San Martin y Almafuerte | E37: Fija | F37: Fibra Optica | H37: 172.20.11.11 | I37: =COUNTIF(L37:AM37,"") -> 28 | J37: =COUNTIF(L37:AM37,"APAGADO") -> 0 | K37: =(I37)/(J37+I37) -> 1
A38: CENTRO | B38: CEN03 | C38: BONOMO | D38: San Martin y Sallares | E38: Domo | F38: Fibra Optica | H38: 172.20.12.30 | I38: =COUNTIF(L38:AM38,"") -> 28 | J38: =COUNTIF(L38:AM38,"APAGADO") -> 0 | K38: =(I38)/(J38+I38) -> 1
A39: CENTRO | B39: CEN04 | C39: BONOMO | D39: San Martin y Contreras | E39: Domo | F39: Fibra Optica | H39: 172.20.12.29 | I39: =COUNTIF(L39:AM39,"") -> 28 | J39: =COUNTIF(L39:AM39,"APAGADO") -> 0 | K39: =(I39)/(J39+I39) -> 1
A40: CENTRO | B40: CEN 05 | C40: BONOMO | D40: Bocuzzi e/España y San Martin | E40: DOMO | F40: Fibra Optica | H40: 172.20.10.200 | I40: =COUNTIF(L40:AM40,"") -> 4 | J40: =COUNTIF(L40:AM40,"APAGADO") -> 24 | K40: =(I40)/(J40+I40) -> 0.14285714 | L40: APAGADO | N40: APAGADO | O40: APAGADO | P40: APAGADO | Q40: APAGADO | R40: APAGADO | S40: APAGADO | T40: APAGADO | U40: APAGADO | V40: APAGADO | W40: APAGADO | X40: APAGADO | Y40: APAGADO | Z40: APAGADO | AA40: APAGADO | AB40: APAGADO | AC40: APAGADO | AD40: APAGADO | AE40: APAGADO | AF40: APAGADO | AG40: APAGADO | AH40: APAGADO | AI40: APAGADO | AJ40: APAGADO
...

Sheet AUXILIAR

Sheet informe
C1: CANTIDAD | D1: APAGADAS | E1: %
B2: TOTAL | C2: =CANTIDAD_DE_CAMARAS -> 517 | F2: 45870
A3: L | B3: CAIDAS | C3: ='RESUMEN TOTAL'!L3 -> 89 | E3: =C3/C2 -> 0.172147
B4: LLEGAMOS NOSOTROS | C4: 5 | D4: 84 | E4: =D4/C2 -> 0.16247582
B5: NO ESTA LA CAMARA | C5: 6 | D5: 78 | E5: =D5/C2 -> 0.15087041
A6: L | B6: RADIO | C6: ='RESUMEN TOTAL'!L5 -> 14 | D6: 63 | E6: =D6/C2 -> 0.12185687
B7: ANTENA DESMONTADA | C7: 9 | D7: =D6-C7 -> 54 | E7: =D7/C2 -> 0.10444874
C8: CANTIDAD | D8: APAGADAS | E8: %
A9: F | B9: BONOMO | C9: =BONOMOcam -> 281 | D9: =Hoja1!F3 -> 52 | E9: =D9/C9 -> 0.18505338
A10: F | B10: COSEIDI | C10: =COSEIDIcam -> 236 | D10: =Hoja1!F5 -> 37 | E10: =D10/C10 -> 0.15677966
C12: CANTIDAD | D12: APAGADAS | E12: %
B13: TOTAL | C13: =CANTIDAD_DE_CAMARAS -> 517 | F13: 45871
A14: M | B14: CAIDAS | C14: ='RESUMEN TOTAL'!M3 -> 0 | E14: =C14/C13 -> 0
B15: LLEGAMOS NOSOTROS | C15: 0 | D15: 0 | E15: =D15/C13 -> 0
B16: NO ESTA LA CAMARA | C16: 0 | D16: =D15-C16 -> 0 | E16: =D16/C13 -> 0
A17: M | B17: RADIO | C17: ='RESUMEN TOTAL'!M5 -> 0 | D17: =D16-C17 -> 0 | E17: =D17/C13 -> 0
B18: ANTENA DESMONTADA | C18: 0 | D18: =D17-C18 -> 0 | E18: =D18/C13 -> 0
C19: CANTIDAD | D19: APAGADAS | E19: %
A20: G | B20: BONOMO | C20: =BONOMOcam -> 281 | D20: =Hoja1!G3 -> 0 | E20: =D20/C20 -> 0
A21: G | B21: COSEIDI | C21: =COSEIDIcam -> 236 | D21: =Hoja1!G5 -> 0 | E21: =D21/C21 -> 0
C23: CANTIDAD | D23: APAGADAS | E23: %
B24: TOTAL | C24: =CANTIDAD_DE_CAMARAS -> 517 | F24: 45872
A25: N | B25: CAIDAS | C25: ='RESUMEN TOTAL'!N3 -> 86 | E25: =C25/C24 -> 0.16634429
B26: LLEGAMOS NOSOTROS | C26: 0 | D26: =C25-C26 -> 86 | E26: =D26/C24 -> 0.16634429
B27: NO ESTA LA CAMARA | C27: 0 | D27: =D26-C27 -> 86 | E27: =D27/C24 -> 0.16634429
A28: N | B28: RADIO | C28: ='RESUMEN TOTAL'!N5 -> 14 | D28: =D27-C28 -> 72 | E28: =D28/C24 -> 0.13926499
B29: ANTENA DESMONTADA | C29: 0 | D29: =D28-C29 -> 72 | E29: =D29/C24 -> 0.13926499
C30: CANTIDAD | D30: APAGADAS | E30: %
B31: BONOMO | C31: =BONOMOcam -> 281 | D31: =Hoja1!H3 -> 47 | E31: =D31/C31 -> 0.16725979
B32: COSEIDI | C32: =COSEIDIcam -> 236 | D32: =Hoja1!H5 -> 39 | E32: =D32/C32 -> 0.16525424
C34: CANTIDAD | D34: APAGADAS | E34: %
B35: TOTAL | C35: =CANTIDAD_DE_CAMARAS -> 517 | F35: 45873
A36: O | B36: CAIDAS | C36: ='RESUMEN TOTAL'!O3 -> 88 | E36: =C36/C35 -> 0.17021277
B37: LLEGAMOS NOSOTROS | C37: 3 | D37: =C36-C37 -> 85 | E37: =D37/C35 -> 0.16441006
B38: NO ESTA LA CAMARA | C38: 6 | D38: =D37-C38 -> 79 | E38: =D38/C35 -> 0.15280464
A39: O | B39: RADIO | C39: ='RESUMEN TOTAL'!O5 -> 14 | D39: =D38-C39 -> 65 | E39: =D39/C35 -> 0.12572534
B40: ANTENA DESMONTADA | C40: 9 | D40: =D39-C40 -> 56 | E40: =D40/C35 -> 0.10831721
C41: CANTIDAD | D41: APAGADAS | E41: %
B42: BONOMO | C42: =BONOMOcam -> 281 | D42: =Hoja1!I3 -> 48 | E42: =D42/C42 -> 0.17081851
B43: COSEIDI | C43: =COSEIDIcam -> 236 | D43: =Hoja1!I5 -> 40 | E43: 0.16
...

Sheet paradas
C1: TOTAL PARADAS | D1: =COUNTIFS(A5:A602,"=paradas seguras")/2 -> 0 | E1: TOTAL DE CAMARAS EN PARADAS | H1: =COUNTIFS(A5:A602,"=paradas seguras") -> 0 | I1: TOTAL DE CAMARAS | K1: =COUNTIFS(D5:D602,"=GFIJA") -> 0 | L1: TOTAL DE INTERCOMUNICADORES | O1: =COUNTIFS(D5:D602,"=INTERCOMUNICADOR") -> 0
E2: FIJAS | F2: =COUNTIFS(F4:F601, "=APAGADO",D4:D601,"=GFIJA") -> 0 | G2: =COUNTIFS(G4:G601, "=APAGADO",D4:D601,"=GFIJA") -> 0 | H2: =COUNTIFS(H4:H601, "=APAGADO",D4:D601,"=GFIJA") -> 0 | I2: =COUNTIFS(I4:I601, "=APAGADO",D4:D601,"=GFIJA") -> 0 | J2: =COUNTIFS(J4:J601, "=APAGADO",D4:D601,"=GFIJA") -> 0 | K2: =COUNTIFS(K4:K601, "=APAGADO",D4:D601,"=GFIJA") -> 0 | L2: =COUNTIFS(L4:L601, "=APAGADO",D4:D601,"=GFIJA") -> 0 | M2: =COUNTIFS(M4:M601, "=APAGADO",D4:D601,"=GFIJA") -> 0 | N2: =COUNTIFS(N4:N601, "=APAGADO",D4:D601,"=GFIJA") -> 0 | O2: =COUNTIFS(O4:O601, "=APAGADO",D4:D601,"=GFIJA") -> 0 | P2: =COUNTIFS(P4:P601, "=APAGADO",D4:D601,"=GFIJA") -> 0 | Q2: =COUNTIFS(Q4:Q601, "=APAGADO",D4:D601,"=GFIJA") -> 0 | R2: =COUNTIFS(R4:R601, "=APAGADO",D4:D601,"=GFIJA") -> 0 | S2: =COUNTIFS(S4:S601, "=APAGADO",D4:D601,"=GFIJA") -> 0 | T2: =COUNTIFS(T4:T601, "=APAGADO",D4:D601,"=GFIJA") -> 0 | U2: =COUNTIFS(U4:U601, "=APAGADO",D4:D601,"=GFIJA") -> 0 | V2: =COUNTIFS(V4:V601, "=APAGADO",D4:D601,"=GFIJA") -> 0 | W2: =COUNTIFS(W4:W601, "=APAGADO",D4:D601,"=GFIJA") -> 0 | X2: =COUNTIFS(X4:X601, "=APAGADO",D4:D601,"=GFIJA") -> 0 | Y2: =COUNTIFS(Y4:Y601, "=APAGADO",D4:D601,"=GFIJA") -> 0 | Z2: =COUNTIFS(Z4:Z601, "=APAGADO",D4:D601,"=GFIJA") -> 0 | AA2: =COUNTIFS(AA4:AA601, "=APAGADO",D4:D601,"=GFIJA") -> 0 | AB2: =COUNTIFS(AB4:AB601, "=APAGADO",D4:D601,"=GFIJA") -> 0 | AC2: =COUNTIFS(AC4:AC601, "=APAGADO",D4:D601,"=GFIJA") -> 0 | AD2: =COUNTIFS(AD4:AD601, "=APAGADO",D4:D601,"=GFIJA") -> 0 | AE2: =COUNTIFS(AE4:AE601, "=APAGADO",D4:D601,"=GFIJA") -> 0 | AF2: =COUNTIFS(AF4:AF601, "=APAGADO",D4:D601,"=GFIJA") -> 0 | AG2: =COUNTIFS(AG4:AG601, "=APAGADO",D4:D601,"=GFIJA") -> 0 | AH2: =COUNTIFS(AH4:AH601, "=APAGADO",D4:D601,"=GFIJA") -> 0 | AI2: =COUNTIFS(AI4:AI601, "=APAGADO",D4:D601,"=GFIJA") -> 0 | AJ2: =COUNTIFS(AJ4:AJ601, "=APAGADO",E4:E601,"=GFIJA") -> 0
E3: INTERCOMUNICADOR | F3: =COUNTIFS(F6:F603, "=APAGADO",D4:D601,"=INTERCOMUNICADOR") -> 0 | G3: =COUNTIFS(G6:G603, "=APAGADO",D4:D601,"=INTERCOMUNICADOR") -> 0 | H3: =COUNTIFS(H6:H603, "=APAGADO",D4:D601,"=INTERCOMUNICADOR") -> 0 | I3: =COUNTIFS(I6:I603, "=APAGADO",D4:D601,"=INTERCOMUNICADOR") -> 0 | J3: =COUNTIFS(J6:J603, "=APAGADO",D4:D601,"=INTERCOMUNICADOR") -> 0 | K3: =COUNTIFS(K6:K603, "=APAGADO",D4:D601,"=INTERCOMUNICADOR") -> 0 | L3: =COUNTIFS(L6:L603, "=APAGADO",D4:D601,"=INTERCOMUNICADOR") -> 0 | M3: =COUNTIFS(M6:M603, "=APAGADO",D4:D601,"=INTERCOMUNICADOR") -> 0 | N3: =COUNTIFS(N6:N603, "=APAGADO",D4:D601,"=INTERCOMUNICADOR") -> 0 | O3: =COUNTIFS(O6:O603, "=APAGADO",D4:D601,"=INTERCOMUNICADOR") -> 0 | P3: =COUNTIFS(P6:P603, "=APAGADO",D4:D601,"=INTERCOMUNICADOR") -> 0 | Q3: =COUNTIFS(Q6:Q603, "=APAGADO",D4:D601,"=INTERCOMUNICADOR") -> 0 | R3: =COUNTIFS(R6:R603, "=APAGADO",D4:D601,"=INTERCOMUNICADOR") -> 0 | S3: =COUNTIFS(S6:S603, "=APAGADO",D4:D601,"=INTERCOMUNICADOR") -> 0 | T3: =COUNTIFS(T6:T603, "=APAGADO",D4:D601,"=INTERCOMUNICADOR") -> 0 | U3: =COUNTIFS(U6:U603, "=APAGADO",D4:D601,"=INTERCOMUNICADOR") -> 0 | V3: =COUNTIFS(V6:V603, "=APAGADO",D4:D601,"=INTERCOMUNICADOR") -> 0 | W3: =COUNTIFS(W6:W603, "=APAGADO",D4:D601,"=INTERCOMUNICADOR") -> 0 | X3: =COUNTIFS(X6:X603, "=APAGADO",D4:D601,"=INTERCOMUNICADOR") -> 0 | Y3: =COUNTIFS(Y6:Y603, "=APAGADO",D4:D601,"=INTERCOMUNICADOR") -> 0 | Z3: =COUNTIFS(Z6:Z603, "=APAGADO",D4:D601,"=INTERCOMUNICADOR") -> 0 | AA3: =COUNTIFS(AA6:AA603, "=APAGADO",D4:D601,"=INTERCOMUNICADOR") -> 0 | AB3: =COUNTIFS(AB6:AB603, "=APAGADO",D4:D601,"=INTERCOMUNICADOR") -> 0 | AC3: =COUNTIFS(AC6:AC603, "=APAGADO",D4:D601,"=INTERCOMUNICADOR") -> 0 | AD3: =COUNTIFS(AD6:AD603, "=APAGADO",D4:D601,"=INTERCOMUNICADOR") -> 0 | AE3: =COUNTIFS(AE6:AE603, "=APAGADO",D4:D601,"=INTERCOMUNICADOR") -> 0 | AF3: =COUNTIFS(AF6:AF603, "=APAGADO",D4:D601,"=INTERCOMUNICADOR") -> 0 | AG3: =COUNTIFS(AG6:AG603, "=APAGADO",D4:D601,"=INTERCOMUNICADOR") -> 0 | AH3: =COUNTIFS(AH6:AH603, "=APAGADO",D4:D601,"=INTERCOMUNICADOR") -> 0 | AI3: =COUNTIFS(AI6:AI603, "=APAGADO",D4:D601,"=INTERCOMUNICADOR") -> 0 | AJ3: =COUNTIFS(AJ6:AJ603, "=APAGADO",E4:E601,"=INTERCOMUNICADOR") -> 0
A4: ='RESUMEN TOTAL'!A7 -> Barrio | B4: ='RESUMEN TOTAL'!B7 -> [Denominacion] | C4: ='RESUMEN TOTAL'!D7 -> [Ubicacion] | D4: ='RESUMEN TOTAL'!E7 -> [Tipo de Camara] | E4: ='RESUMEN TOTAL'!F7 -> [Tipo de Conexion] | F4: ='RESUMEN TOTAL'!L7 -> 45870 | G4: ='RESUMEN TOTAL'!M7 -> 45871 | H4: ='RESUMEN TOTAL'!N7 -> 45872 | I4: ='RESUMEN TOTAL'!O7 -> 45873 | J4: ='RESUMEN TOTAL'!P7 -> 45874 | K4: ='RESUMEN TOTAL'!Q7 -> 45875 | L4: ='RESUMEN TOTAL'!R7 -> 45876 | M4: ='RESUMEN TOTAL'!S7 -> 45877 | ... AJ4: ='RESUMEN TOTAL'!AP7 -> 45900 | XFC4: =SUM(F4:XFB4) -> 1422435
A5: ='RESUMEN TOTAL'!A8 -> ALTAMIRA | B5: ='RESUMEN TOTAL'!B8 -> ALT01 | C5: ='RESUMEN TOTAL'!D8 -> Calchaqui y Sgto. Cabral | D5: ='RESUMEN TOTAL'!E8 -> Domo | E5: ='RESUMEN TOTAL'!F8 -> Fibra Optica | F5: ='RESUMEN TOTAL'!L8 -> 0 | G5: ='RESUMEN TOTAL'!M8 -> 0 | H5: ='RESUMEN TOTAL'!N8 -> 0 | I5: ='RESUMEN TOTAL'!O8 -> 0 | J5: ='RESUMEN TOTAL'!P8 -> 0 | K5: ='RESUMEN TOTAL'!Q8 -> 0 | L5: ='RESUMEN TOTAL'!R8 -> 0 | M5: ='RESUMEN TOTAL'!S8 -> 0 | ... AJ5: ='RESUMEN TOTAL'!AP8 -> 0
A6: ='RESUMEN TOTAL'!A9 -> ALTAMIRA | B6: ='RESUMEN TOTAL'!B9 -> ALT02 | C6: ='RESUMEN TOTAL'!D9 -> Calchaqui y Lope de Vega | D6: ='RESUMEN TOTAL'!E9 -> Domo | E6: ='RESUMEN TOTAL'!F9 -> PTO A FO | F6: ='RESUMEN TOTAL'!L9 -> 0 | G6: ='RESUMEN TOTAL'!M9 -> 0 | H6: ='RESUMEN TOTAL'!N9 -> 0 | I6: ='RESUMEN TOTAL'!O9 -> 0 | J6: ='RESUMEN TOTAL'!P9 -> 0 | K6: ='RESUMEN TOTAL'!Q9 -> 0 | L6: ='RESUMEN TOTAL'!R9 -> 0 | M6: ='RESUMEN TOTAL'!S9 -> 0 | ... AJ6: ='RESUMEN TOTAL'!AP9 -> 0
A7: ='RESUMEN TOTAL'!A10 -> ALTAMIRA | B7: ='RESUMEN TOTAL'!B10 -> ALT 03 | C7: ='RESUMEN TOTAL'!D10 -> Bombero Galarza y Necochea | D7: ='RESUMEN TOTAL'!E10 -> Domo | E7: ='RESUMEN TOTAL'!F10 -> Fibra Optica | F7: ='RESUMEN TOTAL'!L10 -> 0 | G7: ='RESUMEN TOTAL'!M10 -> 0 | H7: ='RESUMEN TOTAL'!N10 -> 0 | I7: ='RESUMEN TOTAL'!O10 -> 0 | J7: ='RESUMEN TOTAL'!P10 -> 0 | K7: ='RESUMEN TOTAL'!Q10 -> 0 | L7: ='RESUMEN TOTAL'!R10 -> 0 | M7: ='RESUMEN TOTAL'!S10 -> 0 | ... AJ7: ='RESUMEN TOTAL'!AP10 -> 0
A8: ='RESUMEN TOTAL'!A11 -> ALTAMIRA | B8: ='RESUMEN TOTAL'!B11 -> ALT 04 | C8: ='RESUMEN TOTAL'!D11 -> Francia y Necochea | D8: ='RESUMEN TOTAL'!E11 -> Domo | E8: ='RESUMEN TOTAL'!F11 -> GPON | F8: ='RESUMEN TOTAL'!L11 -> APAGADO | G8: ='RESUMEN TOTAL'!M11 -> 0 | H8: ='RESUMEN TOTAL'!N11 -> 0 | I8: ='RESUMEN TOTAL'!O11 -> 0 | J8: ='RESUMEN TOTAL'!P11 -> APAGADO | K8: ='RESUMEN TOTAL'!Q11 -> APAGADO | L8: ='RESUMEN TOTAL'!R11 -> 0 | M8: ='RESUMEN TOTAL'!S11 -> 0 | ... AJ8: ='RESUMEN TOTAL'!AP11 -> 0
A9: ='RESUMEN TOTAL'!A12 -> ALTAMIRA | B9: ='RESUMEN TOTAL'!B12 -> ALT05 | C9: ='RESUMEN TOTAL'!D12 -> Av. Calchaqui y Bombero Galarza | D9: ='RESUMEN TOTAL'!E12 -> Domo | E9: ='RESUMEN TOTAL'!F12 -> PTO A FO | F9: ='RESUMEN TOTAL'!L12 -> APAGADO | G9: ='RESUMEN TOTAL'!M12 -> 0 | H9: ='RESUMEN TOTAL'!N12 -> APAGADO | I9: ='RESUMEN TOTAL'!O12 -> APAGADO | J9: ='RESUMEN TOTAL'!P12 -> APAGADO | K9: ='RESUMEN TOTAL'!Q12 -> 0 | L9: ='RESUMEN TOTAL'!R12 -> APAGADO | M9: ='RESUMEN TOTAL'!S12 -> APAGADO | ... AJ9: ='RESUMEN TOTAL'!AP12 -> 0
A10: ='RESUMEN TOTAL'!A13 -> ALTAMIRA | B10: ='RESUMEN TOTAL'!B13 -> ALT 06 | C10: ='RESUMEN TOTAL'!D13 -> LOPE DE VEGA Y NECOCHEA | D10: ='RESUMEN TOTAL'!E13 -> Domo | E10: ='RESUMEN TOTAL'!F13 -> PTO A FO | F10: ='RESUMEN TOTAL'!L13 -> 0 | G10: ='RESUMEN TOTAL'!M13 -> 0 | H10: ='RESUMEN TOTAL'!N13 -> 0 | I10: ='RESUMEN TOTAL'!O13 -> 0 | J10: ='RESUMEN TOTAL'!P13 -> 0 | K10: ='RESUMEN TOTAL'!Q13 -> 0 | L10: ='RESUMEN TOTAL'!R13 -> 0 | M10: ='RESUMEN TOTAL'!S13 -> 0 | ... AJ10: ='RESUMEN TOTAL'!AP13 -> 0
A11: ='RESUMEN TOTAL'!A14 -> ALTAMIRA | B11: ='RESUMEN TOTAL'!B14 -> ALT07 | C11: ='RESUMEN TOTAL'!D14 -> AV. CALCHAQUI Y AV. DEL TRABAJO | D11: ='RESUMEN TOTAL'!E14 -> DOMO | E11: ='RESUMEN TOTAL'!F14 -> PTO A FO | F11: ='RESUMEN TOTAL'!L14 -> 0 | G11: ='RESUMEN TOTAL'!M14 -> 0 | H11: ='RESUMEN TOTAL'!N14 -> 0 | I11: ='RESUMEN TOTAL'!O14 -> 0 | J11: ='RESUMEN TOTAL'!P14 -> 0 | K11: ='RESUMEN TOTAL'!Q14 -> 0 | L11: ='RESUMEN TOTAL'!R14 -> 0 | M11: ='RESUMEN TOTAL'!S14 -> 0 | ... AJ11: ='RESUMEN TOTAL'!AP14 -> 0
A12: ='RESUMEN TOTAL'!A15 -> ALTAMIRA | B12: ='RESUMEN TOTAL'!B15 -> ALT 08 | C12: ='RESUMEN TOTAL'!D15 -> HUMAITA Y NECOCHEA | D12: ='RESUMEN TOTAL'!E15 -> DOMO | E12: ='RESUMEN TOTAL'!F15 -> Fibra Optica | F12: ='RESUMEN TOTAL'!L15 -> 0 | G12: ='RESUMEN TOTAL'!M15 -> 0 | H12: ='RESUMEN TOTAL'!N15 -> 0 | I12: ='RESUMEN TOTAL'!O15 -> 0 | J12: ='RESUMEN TOTAL'!P15 -> 0 | K12: ='RESUMEN TOTAL'!Q15 -> 0 | L12: ='RESUMEN TOTAL'!R15 -> 0 | M12: ='RESUMEN TOTAL'!S15 -> 0 | ... AJ12: ='RESUMEN TOTAL'!AP15 -> 0
A13: ='RESUMEN TOTAL'!A16 -> ALTAMIRA | B13: ='RESUMEN TOTAL'!B16 -> ALT 09 | C13: ='RESUMEN TOTAL'!D16 -> NECOCHEA Y CURUPAITY | D13: ='RESUMEN TOTAL'!E16 -> DOMO | E13: ='RESUMEN TOTAL'!F16 -> Fibra Optica | F13: ='RESUMEN TOTAL'!L16 -> 0 | G13: ='RESUMEN TOTAL'!M16 -> 0 | H13: ='RESUMEN TOTAL'!N16 -> 0 | I13: ='RESUMEN TOTAL'!O16 -> 0 | J13: ='RESUMEN TOTAL'!P16 -> 0 | K13: ='RESUMEN TOTAL'!Q16 -> 0 | L13: ='RESUMEN TOTAL'!R16 -> 0 | M13: ='RESUMEN TOTAL'!S16 -> 0 | ... AJ13: ='RESUMEN TOTAL'!AP16 -> 0
A14: ='RESUMEN TOTAL'!A17 -> ALTAMIRA | B14: ='RESUMEN TOTAL'!B17 -> ALT 10 | C14: ='RESUMEN TOTAL'!D17 -> Calchaqui y Francia | D14: ='RESUMEN TOTAL'!E17 -> Domo | E14: ='RESUMEN TOTAL'!F17 -> Radio | F14: ='RESUMEN TOTAL'!L17 -> APAGADO | G14: ='RESUMEN TOTAL'!M17 -> 0 | H14: ='RESUMEN TOTAL'!N17 -> APAGADO | I14: ='RESUMEN TOTAL'!O17 -> APAGADO | J14: ='RESUMEN TOTAL'!P17 -> APAGADO | K14: ='RESUMEN TOTAL'!Q17 -> APAGADO | L14: ='RESUMEN TOTAL'!R17 -> APAGADO | M14: ='RESUMEN TOTAL'!S17 -> APAGADO | ... AJ14: ='RESUMEN TOTAL'!AP17 -> 0
A15: ='RESUMEN TOTAL'!A18 -> ALTAMIRA | B15: ='RESUMEN TOTAL'!B18 -> ALT 11 | C15: CALCHAQUÍ Y GALARZA FIJA | D15: ='RESUMEN TOTAL'!E18 -> Fija | F15: ='RESUMEN TOTAL'!L18 -> APAGADO | G15: ='RESUMEN TOTAL'!M18 -> 0 | H15: ='RESUMEN TOTAL'!N18 -> APAGADO | I15: ='RESUMEN TOTAL'!O18 -> APAGADO | J15: ='RESUMEN TOTAL'!P18 -> APAGADO | K15: ='RESUMEN TOTAL'!Q18 -> APAGADO | L15: ='RESUMEN TOTAL'!R18 -> APAGADO | M15: ='RESUMEN TOTAL'!S18 -> APAGADO | ... AJ15: ='RESUMEN TOTAL'!AP18 -> 0
A16: ='RESUMEN TOTAL'!A19 -> AGUSTIN RAMIREZ | B16: ='RESUMEN TOTAL'!B19 -> ARA 01 | C16: ='RESUMEN TOTAL'!D19 -> Malambo y Tranquera | D16: ='RESUMEN TOTAL'!E19 -> Domo | E16: ='RESUMEN TOTAL'!F19 -> Fibra Optica | F16: ='RESUMEN TOTAL'!L19 -> 0 | G16: ='RESUMEN TOTAL'!M19 -> 0 | H16: ='RESUMEN TOTAL'!N19 -> 0 | I16: ='RESUMEN TOTAL'!O19 -> 0 | J16: ='RESUMEN TOTAL'!P19 -> 0 | K16: ='RESUMEN TOTAL'!Q19 -> 0 | L16: ='RESUMEN TOTAL'!R19 -> 0 | M16: ='RESUMEN TOTAL'!S19 -> 0 | ... AJ16: ='RESUMEN TOTAL'!AP19 -> 0
A17: ='RESUMEN TOTAL'!A22 -> BELGRANO | B17: ='RESUMEN TOTAL'!B22 -> BEL 01 | C17: ='RESUMEN TOTAL'!D22 -> San Martin y Dardo Rocha | D17: ='RESUMEN TOTAL'!E22 -> DOMO | E17: ='RESUMEN TOTAL'!F22 -> Fibra Optica | F17: ='RESUMEN TOTAL'!L22 -> 0 | G17: ='RESUMEN TOTAL'!M22 -> 0 | H17: ='RESUMEN TOTAL'!N22 -> 0 | I17: ='RESUMEN TOTAL'!O22 -> 0 | J17: ='RESUMEN TOTAL'!P22 -> 0 | K17: ='RESUMEN TOTAL'!Q22 -> 0 | L17: ='RESUMEN TOTAL'!R22 -> 0 | M17: ='RESUMEN TOTAL'!S22 -> 0 | ... AJ17: ='RESUMEN TOTAL'!AP22 -> 0
A18: ='RESUMEN TOTAL'!A23 -> BELGRANO | B18: ='RESUMEN TOTAL'!B23 -> BEL 02 | C18: ='RESUMEN TOTAL'!D23 -> Guardia vieja y Fronteriz | D18: ='RESUMEN TOTAL'!E23 -> DOMO | E18: ='RESUMEN TOTAL'!F23 -> Fibra Optica | F18: ='RESUMEN TOTAL'!L23 -> 0 | G18: ='RESUMEN TOTAL'!M23 -> 0 | H18: ='RESUMEN TOTAL'!N23 -> 0 | I18: ='RESUMEN TOTAL'!O23 -> 0 | J18: ='RESUMEN TOTAL'!P23 -> 0 | K18: ='RESUMEN TOTAL'!Q23 -> 0 | L18: ='RESUMEN TOTAL'!R23 -> 0 | M18: ='RESUMEN TOTAL'!S23 -> 0 | ... AJ18: ='RESUMEN TOTAL'!AP23 -> 0
A19: ='RESUMEN TOTAL'!A24 -> BOSQUES CENTRO | B19: ='RESUMEN TOTAL'!B24 -> BOSQC 01 | C19: ='RESUMEN TOTAL'!D24 -> LUIS AGOTE E/DANUNCIO Y CAMPOAMOR | D19: ='RESUMEN TOTAL'!E24 -> Fija | E19: ='RESUMEN TOTAL'!F24 -> Radio | F19: ='RESUMEN TOTAL'!L24 -> 0 | G19: ='RESUMEN TOTAL'!M24 -> 0 | H19: ='RESUMEN TOTAL'!N24 -> 0 | I19: ='RESUMEN TOTAL'!O24 -> 0 | J19: ='RESUMEN TOTAL'!P24 -> 0 | K19: ='RESUMEN TOTAL'!Q24 -> 0 | L19: ='RESUMEN TOTAL'!R24 -> 0 | M19: ='RESUMEN TOTAL'!S24 -> 0 | ... AJ19: ='RESUMEN TOTAL'!AP24 -> 0
A20: ='RESUMEN TOTAL'!A25 -> BOSQUES CENTRO | B20: ='RESUMEN TOTAL'!B25 -> BOSQC 02 | C20: ='RESUMEN TOTAL'!D25 -> LUIS AGOTE E/DANUNCIO Y CAMPOAMOR | D20: ='RESUMEN TOTAL'!E25 -> Fija | E20: ='RESUMEN TOTAL'!F25 -> Radio | F20: ='RESUMEN TOTAL'!L25 -> 0 | G20: ='RESUMEN TOTAL'!M25 -> 0 | H20: ='RESUMEN TOTAL'!N25 -> 0 | I20: ='RESUMEN TOTAL'!O25 -> 0 | J20: ='RESUMEN TOTAL'!P25 -> 0 | K20: ='RESUMEN TOTAL'!Q25 -> 0 | L20: ='RESUMEN TOTAL'!R25 -> 0 | M20: ='RESUMEN TOTAL'!S25 -> 0 | ... AJ20: ='RESUMEN TOTAL'!AP25 -> 0
A21: ='RESUMEN TOTAL'!A26 -> BOSQUES CENTRO | B21: ='RESUMEN TOTAL'!B26 -> BOSQC 03 | C21: ='RESUMEN TOTAL'!D26 -> BENAVENTE Y LUIS AGOTE | D21: ='RESUMEN TOTAL'!E26 -> Fija | E21: ='RESUMEN TOTAL'!F26 -> Radio | F21: ='RESUMEN TOTAL'!L26 -> 0 | G21: ='RESUMEN TOTAL'!M26 -> 0 | H21: ='RESUMEN TOTAL'!N26 -> 0 | I21: ='RESUMEN TOTAL'!O26 -> 0 | J21: ='RESUMEN TOTAL'!P26 -> 0 | K21: ='RESUMEN TOTAL'!Q26 -> 0 | L21: ='RESUMEN TOTAL'!R26 -> 0 | M21: ='RESUMEN TOTAL'!S26 -> 0 | ... AJ21: ='RESUMEN TOTAL'!AP26 -> 0
A22: ='RESUMEN TOTAL'!A27 -> BOSQUES CENTRO | B22: ='RESUMEN TOTAL'!B27 -> BOSQC 04 | C22: ='RESUMEN TOTAL'!D27 -> BENAVENTE Y LUIS AGOTE | D22: ='RESUMEN TOTAL'!E27 -> Fija | E22: ='RESUMEN TOTAL'!F27 -> Radio | F22: ='RESUMEN TOTAL'!L27 -> 0 | G22: ='RESUMEN TOTAL'!M27 -> 0 | H22: ='RESUMEN TOTAL'!N27 -> 0 | I22: ='RESUMEN TOTAL'!O27 -> 0 | J22: ='RESUMEN TOTAL'!P27 -> 0 | K22: ='RESUMEN TOTAL'!Q27 -> 0 | L22: ='RESUMEN TOTAL'!R27 -> 0 | M22: ='RESUMEN TOTAL'!S27 -> 0 | ... AJ22: ='RESUMEN TOTAL'!AP27 -> 0
A23: ='RESUMEN TOTAL'!A28 -> BOSQUES CENTRO | B23: ='RESUMEN TOTAL'!B28 -> BOSQC 05 | C23: ='RESUMEN TOTAL'!D28 -> LUIS AGOTE Y RUTA 36 | D23: ='RESUMEN TOTAL'!E28 -> Fija | E23: ='RESUMEN TOTAL'!F28 -> Radio | F23: ='RESUMEN TOTAL'!L28 -> 0 | G23: ='RESUMEN TOTAL'!M28 -> 0 | H23: ='RESUMEN TOTAL'!N28 -> 0 | I23: ='RESUMEN TOTAL'!O28 -> 0 | J23: ='RESUMEN TOTAL'!P28 -> 0 | K23: ='RESUMEN TOTAL'!Q28 -> 0 | L23: ='RESUMEN TOTAL'!R28 -> 0 | M23: ='RESUMEN TOTAL'!S28 -> 0 | ... AJ23: ='RESUMEN TOTAL'!AP28 -> 0
A24: ='RESUMEN TOTAL'!A29 -> BOSQUES CENTRO | B24: ='RESUMEN TOTAL'!B29 -> BOSQC 06 | C24: ='RESUMEN TOTAL'!D29 -> LUIS AGOTE Y RUTA 36 | D24: ='RESUMEN TOTAL'!E29 -> Fija | E24: ='RESUMEN TOTAL'!F29 -> Radio | F24: ='RESUMEN TOTAL'!L29 -> 0 | G24: ='RESUMEN TOTAL'!M29 -> 0 | H24: ='RESUMEN TOTAL'!N29 -> 0 | I24: ='RESUMEN TOTAL'!O29 -> 0 | J24: ='RESUMEN TOTAL'!P29 -> 0 | K24: ='RESUMEN TOTAL'!Q29 -> 0 | L24: ='RESUMEN TOTAL'!R29 -> 0 | M24: ='RESUMEN TOTAL'!S29 -> 0 | ... AJ24: ='RESUMEN TOTAL'!AP29 -> 0
A25: ='RESUMEN TOTAL'!A36 -> CENTRO | B25: ='RESUMEN TOTAL'!B36 -> CEN01 | C25: ='RESUMEN TOTAL'!D36 -> San Martin y 9 de Julio | D25: ='RESUMEN TOTAL'!E36 -> Fija | E25: ='RESUMEN TOTAL'!F36 -> Fibra Optica | F25: ='RESUMEN TOTAL'!L36 -> 0 | G25: ='RESUMEN TOTAL'!M36 -> 0 | H25: ='RESUMEN TOTAL'!N36 -> 0 | I25: ='RESUMEN TOTAL'!O36 -> 0 | J25: ='RESUMEN TOTAL'!P36 -> 0 | K25: ='RESUMEN TOTAL'!Q36 -> 0 | L25: ='RESUMEN TOTAL'!R36 -> 0 | M25: ='RESUMEN TOTAL'!S36 -> 0 | ... AJ25: ='RESUMEN TOTAL'!AP36 -> 0
A26: ='RESUMEN TOTAL'!A37 -> CENTRO | B26: ='RESUMEN TOTAL'!B37 -> CEN02 | C26: ='RESUMEN TOTAL'!D37 -> San Martin y Almafuerte | D26: ='RESUMEN TOTAL'!E37 -> Fija | E26: ='RESUMEN TOTAL'!F37 -> Fibra Optica | F26: ='RESUMEN TOTAL'!L37 -> 0 | G26: ='RESUMEN TOTAL'!M37 -> 0 | H26: ='RESUMEN TOTAL'!N37 -> 0 | I26: ='RESUMEN TOTAL'!O37 -> 0 | J26: ='RESUMEN TOTAL'!P37 -> 0 | K26: ='RESUMEN TOTAL'!Q37 -> 0 | L26: ='RESUMEN TOTAL'!R37 -> 0 | M26: ='RESUMEN TOTAL'!S37 -> 0 | ... AJ26: ='RESUMEN TOTAL'!AP37 -> 0
A27: ='RESUMEN TOTAL'!A38 -> CENTRO | B27: ='RESUMEN TOTAL'!B38 -> CEN03 | C27: ='RESUMEN TOTAL'!D38 -> San Martin y Sallares | D27: ='RESUMEN TOTAL'!E38 -> Domo | E27: ='RESUMEN TOTAL'!F38 -> Fibra Optica | F27: ='RESUMEN TOTAL'!L38 -> 0 | G27: ='RESUMEN TOTAL'!M38 -> 0 | H27: ='RESUMEN TOTAL'!N38 -> 0 | I27: ='RESUMEN TOTAL'!O38 -> 0 | J27: ='RESUMEN TOTAL'!P38 -> 0 | K27: ='RESUMEN TOTAL'!Q38 -> 0 | L27: ='RESUMEN TOTAL'!R38 -> 0 | M27: ='RESUMEN TOTAL'!S38 -> 0 | ... AJ27: ='RESUMEN TOTAL'!AP38 -> 0
A28: ='RESUMEN TOTAL'!A39 -> CENTRO | B28: ='RESUMEN TOTAL'!B39 -> CEN04 | C28: ='RESUMEN TOTAL'!D39 -> San Martin y Contreras | D28: ='RESUMEN TOTAL'!E39 -> Domo | E28: ='RESUMEN TOTAL'!F39 -> Fibra Optica | F28: ='RESUMEN TOTAL'!L39 -> 0 | G28: ='RESUMEN TOTAL'!M39 -> 0 | H28: ='RESUMEN TOTAL'!N39 -> 0 | I28: ='RESUMEN TOTAL'!O39 -> 0 | J28: ='RESUMEN TOTAL'!P39 -> 0 | K28: ='RESUMEN TOTAL'!Q39 -> 0 | L28: ='RESUMEN TOTAL'!R39 -> 0 | M28: ='RESUMEN TOTAL'!S39 -> 0 | ... AJ28: ='RESUMEN TOTAL'!AP39 -> 0
A29: ='RESUMEN TOTAL'!A40 -> CENTRO | B29: ='RESUMEN TOTAL'!B40 -> CEN 05 | C29: ='RESUMEN TOTAL'!D40 -> Bocuzzi e/España y San Martin | D29: ='RESUMEN TOTAL'!E40 -> DOMO | E29: ='RESUMEN TOTAL'!F40 -> Fibra Optica | F29: ='RESUMEN TOTAL'!L40 -> APAGADO | G29: ='RESUMEN TOTAL'!M40 -> 0 | H29: ='RESUMEN TOTAL'!N40 -> APAGADO | I29: ='RESUMEN TOTAL'!O40 -> APAGADO | J29: ='RESUMEN TOTAL'!P40 -> APAGADO | K29: ='RESUMEN TOTAL'!Q40 -> APAGADO | L29: ='RESUMEN TOTAL'!R40 -> APAGADO | M29: ='RESUMEN TOTAL'!S40 -> APAGADO | ... AJ29: ='RESUMEN TOTAL'!AP40 -> 0
A30: ='RESUMEN TOTAL'!A41 -> CENTRO | B30: ='RESUMEN TOTAL'!B41 -> CEN06 | C30: ='RESUMEN TOTAL'!D41 -> Monteagudo y A.del Valle | D30: ='RESUMEN TOTAL'!E41 -> Fija | E30: ='RESUMEN TOTAL'!F41 -> Fibra Optica | F30: ='RESUMEN TOTAL'!L41 -> APAGADO | G30: ='RESUMEN TOTAL'!M41 -> 0 | H30: ='RESUMEN TOTAL'!N41 -> APAGADO | I30: ='RESUMEN TOTAL'!O41 -> APAGADO | J30: ='RESUMEN TOTAL'!P41 -> APAGADO | K30: ='RESUMEN TOTAL'!Q41 -> APAGADO | L30: ='RESUMEN TOTAL'!R41 -> APAGADO | M30: ='RESUMEN TOTAL'!S41 -> APAGADO | ... AJ30: ='RESUMEN TOTAL'!AP41 -> 0
A31: ='RESUMEN TOTAL'!A42 -> CENTRO | B31: ='RESUMEN TOTAL'!B42 -> CEN07 | C31: ='RESUMEN TOTAL'!D42 -> San Martin y Guemes | D31: ='RESUMEN TOTAL'!E42 -> DOMO | E31: ='RESUMEN TOTAL'!F42 -> Fibra Optica | F31: ='RESUMEN TOTAL'!L42 -> 0 | G31: ='RESUMEN TOTAL'!M42 -> 0 | H31: ='RESUMEN TOTAL'!N42 -> 0 | I31: ='RESUMEN TOTAL'!O42 -> 0 | J31: ='RESUMEN TOTAL'!P42 -> 0 | K31: ='RESUMEN TOTAL'!Q42 -> 0 | L31: ='RESUMEN TOTAL'!R42 -> 0 | M31: ='RESUMEN TOTAL'!S42 -> 0 | ... AJ31: ='RESUMEN TOTAL'!AP42 -> 0
A32: ='RESUMEN TOTAL'!A43 -> CENTRO | B32: ='RESUMEN TOTAL'!B43 -> CEN08 | C32: ='RESUMEN TOTAL'!D43 -> San Martin y Pte.Peron | D32: ='RESUMEN TOTAL'!E43 -> Domo | E32: ='RESUMEN TOTAL'!F43 -> Fibra Optica | F32: ='RESUMEN TOTAL'!L43 -> 0 | G32: ='RESUMEN TOTAL'!M43 -> 0 | H32: ='RESUMEN TOTAL'!N43 -> 0 | I32: ='RESUMEN TOTAL'!O43 -> 0 | J32: ='RESUMEN TOTAL'!P43 -> 0 | K32: ='RESUMEN TOTAL'!Q43 -> 0 | L32: ='RESUMEN TOTAL'!R43 -> 0 | M32: ='RESUMEN TOTAL'!S43 -> 0 | ... AJ32: ='RESUMEN TOTAL'!AP43 -> 0
A33: ='RESUMEN TOTAL'!A44 -> CENTRO | B33: ='RESUMEN TOTAL'!B44 -> CEN09 | C33: ='RESUMEN TOTAL'!D44 -> Chacabuco y 25 de Mayo | D33: ='RESUMEN TOTAL'!E44 -> Domo | E33: ='RESUMEN TOTAL'!F44 -> Fibra Optica | F33: ='RESUMEN TOTAL'!L44 -> 0 | G33: ='RESUMEN TOTAL'!M44 -> 0 | H33: ='RESUMEN TOTAL'!N44 -> 0 | I33: ='RESUMEN TOTAL'!O44 -> 0 | J33: ='RESUMEN TOTAL'!P44 -> 0 | K33: ='RESUMEN TOTAL'!Q44 -> 0 | L33: ='RESUMEN TOTAL'!R44 -> 0 | M33: ='RESUMEN TOTAL'!S44 -> 0 | ... AJ33: ='RESUMEN TOTAL'!AP44 -> 0
A34: ='RESUMEN TOTAL'!A45 -> CENTRO | B34: ='RESUMEN TOTAL'!B45 -> CEN10 | C34: ='RESUMEN TOTAL'!D45 -> Monteagudo y Pte. Peron | D34: ='RESUMEN TOTAL'!E45 -> Domo | E34: ='RESUMEN TOTAL'!F45 -> Fibra Optica | F34: ='RESUMEN TOTAL'!L45 -> 0 | G34: ='RESUMEN TOTAL'!M45 -> 0 | H34: ='RESUMEN TOTAL'!N45 -> 0 | I34: ='RESUMEN TOTAL'!O45 -> 0 | J34: ='RESUMEN TOTAL'!P45 -> 0 | K34: ='RESUMEN TOTAL'!Q45 -> 0 | L34: ='RESUMEN TOTAL'!R45 -> 0 | M34: ='RESUMEN TOTAL'!S45 -> 0 | ... AJ34: ='RESUMEN TOTAL'!AP45 -> 0
A35: ='RESUMEN TOTAL'!A46 -> CENTRO | B35: ='RESUMEN TOTAL'!B46 -> CEN11 | C35: ='RESUMEN TOTAL'!D46 -> Monteagudo y Bocuzzi | D35: ='RESUMEN TOTAL'!E46 -> Domo | E35: ='RESUMEN TOTAL'!F46 -> Fibra Optica | F35: ='RESUMEN TOTAL'!L46 -> 0 | G35: ='RESUMEN TOTAL'!M46 -> 0 | H35: ='RESUMEN TOTAL'!N46 -> 0 | I35: ='RESUMEN TOTAL'!O46 -> 0 | J35: ='RESUMEN TOTAL'!P46 -> 0 | K35: ='RESUMEN TOTAL'!Q46 -> 0 | L35: ='RESUMEN TOTAL'!R46 -> 0 | M35: ='RESUMEN TOTAL'!S46 -> 0 | ... AJ35: ='RESUMEN TOTAL'!AP46 -> 0
A36: ='RESUMEN TOTAL'!A47 -> CENTRO | B36: ='RESUMEN TOTAL'!B47 -> CEN 12 | C36: ='RESUMEN TOTAL'!D47 -> Monteagudo y Mitre | D36: ='RESUMEN TOTAL'!E47 -> Domo | E36: ='RESUMEN TOTAL'!F47 -> Fibra Optica | F36: ='RESUMEN TOTAL'!L47 -> 0 | G36: ='RESUMEN TOTAL'!M47 -> 0 | H36: ='RESUMEN TOTAL'!N47 -> APAGADO | I36: ='RESUMEN TOTAL'!O47 -> APAGADO | J36: ='RESUMEN TOTAL'!P47 -> 0 | K36: ='RESUMEN TOTAL'!Q47 -> 0 | L36: ='RESUMEN TOTAL'!R47 -> 0 | M36: ='RESUMEN TOTAL'!S47 -> 0 | ... AJ36: ='RESUMEN TOTAL'!AP47 -> 0
... A71: ='RESUMEN TOTAL'!A82 -> CENTRO | B71: ='RESUMEN TOTAL'!B82 -> CEN47 | C71: ='RESUMEN TOTAL'!D82 -> Sallares y Brown | D71: ='RESUMEN TOTAL'!E82 -> Domo | E71: ='RESUMEN TOTAL'!F82 -> Fibra Optica | F71: ='RESUMEN TOTAL'!L82 -> 0 | G71: ='RESUMEN TOTAL'!M82 -> 0 | H71: ='RESUMEN TOTAL'!N82 -> APAGADO | I71: ='RESUMEN TOTAL'!O82 -> APAGADO | J71: ='RESUMEN TOTAL'!P82 -> 0 | K71: ='RESUMEN TOTAL'!Q82 -> 0 | L71: ='RESUMEN TOTAL'!R82 -> 0 | M71: ='RESUMEN TOTAL'!S82 -> 0 | ... AJ71: ='RESUMEN TOTAL'!AP82 -> 0
A72: ='RESUMEN TOTAL'!A83 -> CENTRO | B72: ='RESUMEN TOTAL'!B83 -> CEN48 | C72: ='RESUMEN TOTAL'!D83 -> Velez Sarsfield y Las Heras | D72: ='RESUMEN TOTAL'!E83 -> Domo | E72: ='RESUMEN TOTAL'!F83 -> GPON | F72: ='RESUMEN TOTAL'!L83 -> 0 | G72: ='RESUMEN TOTAL'!M83 -> 0 | H72: ='RESUMEN TOTAL'!N83 -> 0 | I72: ='RESUMEN TOTAL'!O83 -> 0 | J72: ='RESUMEN TOTAL'!P83 -> 0 | K72: ='RESUMEN TOTAL'!Q83 -> 0 | L72: ='RESUMEN TOTAL'!R83 -> 0 | M72: ='RESUMEN TOTAL'!S83 -> 0 | ... Z72: ='RESUMEN TOTAL'!AF83 -> 0 | AA72: ='RESUMEN TOTAL'!#REF! -> #REF! | AB72: ='RESUMEN TOTAL'!AH83 -> 0 | AC72: ='RESUMEN TOTAL'!AI83 -> 0 | AD72: ='RESUMEN TOTAL'!AJ83 -> 0 | AE72: ='RESUMEN TOTAL'!AK83 -> 0 | AF72: ='RESUMEN TOTAL'!AL83 -> 0 | AG72: ='RESUMEN TOTAL'!AM83 -> 0 | AH72: ='RESUMEN TOTAL'!AN83 -> 0 | AI72: ='RESUMEN TOTAL'!AO83 -> 0 | AJ72: ='RESUMEN TOTAL'!AP83 -> 0
A73: ='RESUMEN TOTAL'!A84 -> CENTRO | B73: ='RESUMEN TOTAL'!B84 -> CEN49 | C73: ='RESUMEN TOTAL'!D84 -> Av. San Martin y Florencio Sanchez | D73: ='RESUMEN TOTAL'!E84 -> Domo | E73: ='RESUMEN TOTAL'!F84 -> Fibra Optica | F73: ='RESUMEN TOTAL'!L84 -> 0 | G73: ='RESUMEN TOTAL'!M84 -> 0 | H73: ='RESUMEN TOTAL'!N84 -> 0 | I73: ='RESUMEN TOTAL'!O84 -> 0 | J73: ='RESUMEN TOTAL'!P84 -> 0 | K73: ='RESUMEN TOTAL'!Q84 -> 0 | L73: ='RESUMEN TOTAL'!R84 -> 0 | M73: ='RESUMEN TOTAL'!S84 -> 0 | ... AJ73: ='RESUMEN TOTAL'!AP84 -> 0
A74: ='RESUMEN TOTAL'!A85 -> CENTRO | B74: ='RESUMEN TOTAL'!B85 -> CEN 50 | C74: ='RESUMEN TOTAL'!D85 -> Av. San Martin y Newbery | D74: ='RESUMEN TOTAL'!E85 -> Domo | E74: ='RESUMEN TOTAL'!F85 -> Fibra Optica | F74: ='RESUMEN TOTAL'!L85 -> 0 | G74: ='RESUMEN TOTAL'!M85 -> 0 | H74: ='RESUMEN TOTAL'!N85 -> 0 | I74: ='RESUMEN TOTAL'!O85 -> 0 | J74: ='RESUMEN TOTAL'!P85 -> 0 | K74: ='RESUMEN TOTAL'!Q85 -> 0 | L74: ='RESUMEN TOTAL'!R85 -> 0 | M74: ='RESUMEN TOTAL'!S85 -> 0 | ... AJ74: ='RESUMEN TOTAL'!AP85 -> 0
...

Sheet Hoja1
B1: CAMARAS | C1: 45890
A2: BONOMO | B2: =COUNTIFS('RESUMEN TOTAL'!C8:C524,"=BONOMO") -> 281 | C2: 57 | F2: 45870 | G2: 45871 | H2: 45872 | I2: 45873 | J2: 45874 | K2: 45875 | L2: 45876 | M2: 45877 | N2: 45878 | O2: 45879 | P2: 45880 | Q2: 45881 | R2: 45882 | S2: 45883 | T2: 45884 | U2: 45885 | V2: 45886 | W2: 45887 | X2: 45888 | Y2: 45889 | Z2: 45890 | AA2: 45891 | AB2: 45892 | AC2: 45893 | AD2: 45894 | AE2: 45895 | AF2: 45896 | AG2: 45897 | AH2: 45898 | AI2: 45899 | AJ2: 45900
C3: 0.2103321 | D3: BONOMO | E3: APAGADAS BONOMO | F3: =COUNTIFS('RESUMEN TOTAL'!L8:L632,"=APAGADO",'RESUMEN TOTAL'!C8:C632,"=BONOMO") -> 52 | G3: =COUNTIFS('RESUMEN TOTAL'!M8:M632,"=APAGADO",'RESUMEN TOTAL'!C8:C632,"=BONOMO") -> 0 | H3: =COUNTIFS('RESUMEN TOTAL'!N8:N632,"=APAGADO",'RESUMEN TOTAL'!C8:C632,"=BONOMO") -> 47 | I3: =COUNTIFS('RESUMEN TOTAL'!O8:O632,"=APAGADO",'RESUMEN TOTAL'!C8:C632,"=BONOMO") -> 48 | J3: =COUNTIFS('RESUMEN TOTAL'!P8:P632,"=APAGADO",'RESUMEN TOTAL'!C8:C632,"=BONOMO") -> 36 | K3: =COUNTIFS('RESUMEN TOTAL'!Q8:Q632,"=APAGADO",'RESUMEN TOTAL'!C8:C632,"=BONOMO") -> 47 | L3: =COUNTIFS('RESUMEN TOTAL'!R8:R632,"=APAGADO",'RESUMEN TOTAL'!C8:C632,"=BONOMO") -> 34 | M3: =COUNTIFS('RESUMEN TOTAL'!S8:S632,"=APAGADO",'RESUMEN TOTAL'!C8:C632,"=BONOMO") -> 39 | N3: =COUNTIFS('RESUMEN TOTAL'!T8:T632,"=APAGADO",'RESUMEN TOTAL'!C8:C632,"=BONOMO") -> 37 | O3: =COUNTIFS('RESUMEN TOTAL'!U8:U632,"=APAGADO",'RESUMEN TOTAL'!C8:C632,"=BONOMO") -> 35 | P3: =COUNTIFS('RESUMEN TOTAL'!V8:V632,"=APAGADO",'RESUMEN TOTAL'!C8:C632,"=BONOMO") -> 34 | Q3: =COUNTIFS('RESUMEN TOTAL'!W8:W632,"=APAGADO",'RESUMEN TOTAL'!C8:C632,"=BONOMO") -> 36 | R3: =COUNTIFS('RESUMEN TOTAL'!X8:X632,"=APAGADO",'RESUMEN TOTAL'!C8:C632,"=BONOMO") -> 48 | S3: =COUNTIFS('RESUMEN TOTAL'!Y8:Y632,"=APAGADO",'RESUMEN TOTAL'!C8:C632,"=BONOMO") -> 51 | T3: =COUNTIFS('RESUMEN TOTAL'!Z8:Z632,"=APAGADO",'RESUMEN TOTAL'!C8:C632,"=BONOMO") -> 49 | U3: =COUNTIFS('RESUMEN TOTAL'!AA8:AA632,"=APAGADO",'RESUMEN TOTAL'!C8:C632,"=BONOMO") -> 50 | V3: =COUNTIFS('RESUMEN TOTAL'!AB8:AB632,"=APAGADO",'RESUMEN TOTAL'!C8:C632,"=BONOMO") -> 53 | W3: =COUNTIFS('RESUMEN TOTAL'!AC8:AC632,"=APAGADO",'RESUMEN TOTAL'!C8:C632,"=BONOMO") -> 54 | X3: =COUNTIFS('RESUMEN TOTAL'!AD8:AD632,"=APAGADO",'RESUMEN TOTAL'!C8:C632,"=BONOMO") -> 59 | Y3: =COUNTIFS('RESUMEN TOTAL'!AE8:AE632,"=APAGADO",'RESUMEN TOTAL'!C8:C632,"=BONOMO") -> 60 | Z3: =COUNTIFS('RESUMEN TOTAL'!AF8:AF632,"=APAGADO",'RESUMEN TOTAL'!C8:C632,"=BONOMO") -> 59 | AA3: =COUNTIFS('RESUMEN TOTAL'!AG8:AG632,"=APAGADO",'RESUMEN TOTAL'!C8:C632,"=BONOMO") -> 44 | AB3: =COUNTIFS('RESUMEN TOTAL'!AH8:AH632,"=APAGADO",'RESUMEN TOTAL'!C8:C632,"=BONOMO") -> 44 | AC3: =COUNTIFS('RESUMEN TOTAL'!AI8:AI632,"=APAGADO",'RESUMEN TOTAL'!C8:C632,"=BONOMO") -> 48 | AD3: =COUNTIFS('RESUMEN TOTAL'!AJ8:AJ632,"=APAGADO",'RESUMEN TOTAL'!C8:C632,"=BONOMO") -> 49 | AE3: 0 | AF3: =COUNTIFS('RESUMEN TOTAL'!AL8:AL632,"=APAGADO",'RESUMEN TOTAL'!C8:C632,"=BONOMO") -> 60 | AG3: =COUNTIFS('RESUMEN TOTAL'!AM8:AM632,"=APAGADO",'RESUMEN TOTAL'!C8:C632,"=BONOMO") -> 35 | AH3: =COUNTIFS('RESUMEN TOTAL'!AN8:AN632,"=APAGADO",'RESUMEN TOTAL'!C8:C632,"=BONOMO") -> 0 | AI3: 0 | AJ3: 0
A4: COSEIDI | B4: =COUNTIFS('RESUMEN TOTAL'!C8:C524,"=COSEIDI") -> 236 | C4: 52 | E4: % BONOMO | F4: =F3/BONOMOcam -> 0.18505338 | G4: =G3/BONOMOcam -> 0 | H4: =H3/BONOMOcam -> 0.16725979 | I4: =I3/BONOMOcam -> 0.17081851 | J4: 0.14 | K4: =K3/BONOMOcam -> 0.16725979 | L4: =L3/BONOMOcam -> 0.12099644 | M4: =M3/BONOMOcam -> 0.13879004 | N4: =N3/BONOMOcam -> 0.1316726 | O4: =O3/BONOMOcam -> 0.12455516 | P4: =P3/BONOMOcam -> 0.12099644 | Q4: =Q3/BONOMOcam -> 0.12811388 | R4: =R3/BONOMOcam -> 0.17081851 | ... AH4: =AH3/BONOMOcam -> 0 | AI4: 0 | AJ4: 0
C5: 0.22317597 | D5: COSEIDI | E5: APAGADAS COSEIDI | F5: =COUNTIFS('RESUMEN TOTAL'!L10:L634,"=APAGADO",'RESUMEN TOTAL'!C10:C634,"=COSEIDI") -> 37 | G5: =COUNTIFS('RESUMEN TOTAL'!M10:M634,"=APAGADO",'RESUMEN TOTAL'!C10:C634,"=COSEIDI") -> 0 | H5: =COUNTIFS('RESUMEN TOTAL'!N10:N634,"=APAGADO",'RESUMEN TOTAL'!C10:C634,"=COSEIDI") -> 39 | I5: =COUNTIFS('RESUMEN TOTAL'!O10:O634,"=APAGADO",'RESUMEN TOTAL'!C10:C634,"=COSEIDI") -> 40 | J5: =COUNTIFS('RESUMEN TOTAL'!P10:P634,"=APAGADO",'RESUMEN TOTAL'!C10:C634,"=COSEIDI") -> 32 | K5: =COUNTIFS('RESUMEN TOTAL'!Q10:Q634,"=APAGADO",'RESUMEN TOTAL'!C10:C634,"=COSEIDI") -> 29 | L5: =COUNTIFS('RESUMEN TOTAL'!R10:R634,"=APAGADO",'RESUMEN TOTAL'!C10:C634,"=COSEIDI") -> 27 | M5: =COUNTIFS('RESUMEN TOTAL'!S10:S634,"=APAGADO",'RESUMEN TOTAL'!C10:C634,"=COSEIDI") -> 34 | N5: =COUNTIFS('RESUMEN TOTAL'!T10:T634,"=APAGADO",'RESUMEN TOTAL'!C10:C634,"=COSEIDI") -> 30 | O5: =COUNTIFS('RESUMEN TOTAL'!U10:U634,"=APAGADO",'RESUMEN TOTAL'!C10:C634,"=COSEIDI") -> 34 | P5: =COUNTIFS('RESUMEN TOTAL'!V10:V634,"=APAGADO",'RESUMEN TOTAL'!C10:C634,"=COSEIDI") -> 37 | Q5: =COUNTIFS('RESUMEN TOTAL'!W10:W634,"=APAGADO",'RESUMEN TOTAL'!C10:C634,"=COSEIDI") -> 30 | R5: =COUNTIFS('RESUMEN TOTAL'!X10:X634,"=APAGADO",'RESUMEN TOTAL'!C10:C634,"=COSEIDI") -> 30 | S5: =COUNTIFS('RESUMEN TOTAL'!Y10:Y634,"=APAGADO",'RESUMEN TOTAL'!C10:C634,"=COSEIDI") -> 54 | T5: =COUNTIFS('RESUMEN TOTAL'!Z10:Z634,"=APAGADO",'RESUMEN TOTAL'!C10:C634,"=COSEIDI") -> 28 | U5: =COUNTIFS('RESUMEN TOTAL'!AA10:AA634,"=APAGADO",'RESUMEN TOTAL'!C10:C634,"=COSEIDI") -> 43 | V5: =COUNTIFS('RESUMEN TOTAL'!AB10:AB634,"=APAGADO",'RESUMEN TOTAL'!C10:C634,"=COSEIDI") -> 41 | W5: =COUNTIFS('RESUMEN TOTAL'!AC10:AC634,"=APAGADO",'RESUMEN TOTAL'!C10:C634,"=COSEIDI") -> 35 | X5: =COUNTIFS('RESUMEN TOTAL'!AD10:AD634,"=APAGADO",'RESUMEN TOTAL'!C10:C634,"=COSEIDI") -> 31 | Y5: =COUNTIFS('RESUMEN TOTAL'!AE10:AE634,"=APAGADO",'RESUMEN TOTAL'!C10:C634,"=COSEIDI") -> 46 | Z5: =COUNTIFS('RESUMEN TOTAL'!AF10:AF634,"=APAGADO",'RESUMEN TOTAL'!C10:C634,"=COSEIDI") -> 50 | AA5: =COUNTIFS('RESUMEN TOTAL'!AG10:AG634,"=APAGADO",'RESUMEN TOTAL'!C10:C634,"=COSEIDI") -> 36 | AB5: =COUNTIFS('RESUMEN TOTAL'!AH10:AH634,"=APAGADO",'RESUMEN TOTAL'!C10:C634,"=COSEIDI") -> 37 | AC5: =COUNTIFS('RESUMEN TOTAL'!AI10:AI634,"=APAGADO",'RESUMEN TOTAL'!C10:C634,"=COSEIDI") -> 36 | AD5: =COUNTIFS('RESUMEN TOTAL'!AJ10:AJ634,"=APAGADO",'RESUMEN TOTAL'!C10:C634,"=COSEIDI") -> 37 | AE5: =COUNTIFS('RESUMEN TOTAL'!AK10:AK634,"=APAGADO",'RESUMEN TOTAL'!C10:C634,"=COSEIDI") -> 34 | AF5: =COUNTIFS('RESUMEN TOTAL'!AL10:AL634,"=APAGADO",'RESUMEN TOTAL'!C10:C634,"=COSEIDI") -> 32 | AG5: =COUNTIFS('RESUMEN TOTAL'!AM10:AM634,"=APAGADO",'RESUMEN TOTAL'!C10:C634,"=COSEIDI") -> 41 | AH5: =COUNTIFS('RESUMEN TOTAL'!AN10:AN634,"=APAGADO",'RESUMEN TOTAL'!C10:C634,"=COSEIDI") -> 0 | AI5: =COUNTIFS('RESUMEN TOTAL'!AO10:AO634,"=APAGADO",'RESUMEN TOTAL'!C10:C634,"=COSEIDI") -> 0 | AJ5: 0
E6: % COSEIDI | F6: =F5/COSEIDIcam -> 0.15677966 | G6: =G5/COSEIDIcam -> 0 | H6: =H5/COSEIDIcam -> 0.16525424 | I6: =I5/COSEIDIcam -> 0.16949153 | J6: 0.12 | K6: =K5/COSEIDIcam -> 0.12288136 | L6: =L5/COSEIDIcam -> 0.11440678 | M6: =M5/COSEIDIcam -> 0.1440678 | N6: =N5/COSEIDIcam -> 0.12711864 | O6: =O5/COSEIDIcam -> 0.1440678 | P6: =P5/COSEIDIcam -> 0.15677966 | Q6: =Q5/COSEIDIcam -> 0.12711864 | R6: =R5/COSEIDIcam -> 0.12711864 | ... AH6: =AH5/COSEIDIcam -> 0 | AI6: 0 | AJ6: 0
B16: CAMARAS | C16: 45890
A17: COSEIDI | B17: 233 | C17: 52
C18: 0.22317597
