Workbook
Name _25_de_agosto: 'RESUMEN TOTAL'!$A$7:$D$489
Name _25_de_agosto_3: 'RESUMEN TOTAL'!$A$7:$D$501
Name _30_mar: #REF!
Name BONOMOcam: Hoja1!$B$2
Name CANTIDAD_DE_CAMARAS: 'RESUMEN TOTAL'!$B$1
Name COSEIDIcam: Hoja1!$B$4

Sheet RESUMEN TOTAL
A1: CANTIDAD DE CAMARAS | B1: =COUNTA(B8:B735) -> 574 | D1: PORCIENTO DE CAIDAS | M1: =(M3)/(M2+M3) -> 0 | N1: =(N3)/(N2+N3) -> 0 | O1: =(O3)/(O2+O3) -> 0 | P1: =(P3)/(P2+P3) -> 0 | Q1: =(Q3)/(Q2+Q3) -> 0 | R1: =(R3)/(R2+R3) -> 0 | S1: =(S3)/(S2+S3) -> 0 | T1: =(T3)/(T2+T3) -> 0 | ... Y1: =(Y3)/(Y2+Y3) -> 0 | AA1: =(AA3)/(AA2+AA3) -> 0 | AB1: =(AB3)/(AB2+AB3) -> 0 | AC1: =(AC3)/(AC2+AC3) -> 0 | AD1: =(AD3)/(AD2+AD3) -> 0 | AE1: =(AE3)/(AE2+AE3) -> 0 | AF1: =(AF3)/(AF2+AF3) -> 0 | AG1: =(AG3)/(AG2+AG3) -> 0 | AH1: =(AH3)/(AH2+AH3) -> 0 | ... AQ1: =(AQ3)/(AQ2+AQ3) -> 0
D2: FUNCIONAN | M2: =CANTIDAD_DE_CAMARAS -> 574 | N2: =CANTIDAD_DE_CAMARAS -> 574 | O2: =CANTIDAD_DE_CAMARAS -> 574 | P2: =CANTIDAD_DE_CAMARAS -> 574 | Q2: =CANTIDAD_DE_CAMARAS -> 574 | R2: =CANTIDAD_DE_CAMARAS -> 574 | S2: =CANTIDAD_DE_CAMARAS -> 574 | T2: =CANTIDAD_DE_CAMARAS -> 574 | ... AQ2: =CANTIDAD_DE_CAMARAS -> 574
D3: CAIDAS | M3: =COUNTIF(M7:M735, "apagado") -> 0 | N3: =COUNTIF(N7:N735, "apagado") -> 0 | O3: =COUNTIF(O7:O735, "apagado") -> 0 | P3: =COUNTIF(P7:P735, "apagado") -> 0 | Q3: =COUNTIF(Q7:Q735, "apagado") -> 0 | R3: =COUNTIF(R7:R735, "apagado") -> 0 | S3: =COUNTIF(S7:S735, "apagado") -> 0 | T3: =COUNTIF(T7:T735, "apagado") -> 0 | ... AQ3: =COUNTIF(AQ7:AQ735, "apagado") -> 0
D4: APAGADOS FIBRA | M4: =COUNTIFS(M8:M689, "=APAGADO",F8:F689,"=Fibra Optica") -> 0 | N4: =COUNTIFS(N8:N689, "=APAGADO",F8:F689,"=Fibra Optica") -> 0 | O4: =COUNTIFS(O8:O689, "=APAGADO",F8:F689,"=Fibra Optica") -> 0 | P4: =COUNTIFS(P8:P689, "=APAGADO",F8:F689,"=Fibra Optica") -> 0 | Q4: =COUNTIFS(Q8:Q689, "=APAGADO",F8:F689,"=Fibra Optica") -> 0 | R4: =COUNTIFS(R8:R689, "=APAGADO",F8:F689,"=Fibra Optica") -> 0 | S4: =COUNTIFS(S8:S689, "=APAGADO",F8:F689,"=Fibra Optica") -> 0 | T4: =COUNTIFS(T8:T689, "=APAGADO",F8:F689,"=Fibra Optica") -> 0 | U4: =COUNTIFS(U8:U689, "=APAGADO",F8:F689,"=Fibra Optica") -> 0 | V4: =COUNTIFS(V8:V689, "=APAGADO",F8:F689,"=Fibra Optica") -> 0 | W4: =COUNTIFS(W8:W689, "=APAGADO",F8:F689,"=Fibra Optica") -> 0 | X4: =COUNTIFS(X8:X689, "=APAGADO",F8:F689,"=Fibra Optica") -> 0 | Y4: =COUNTIFS(Y8:Y689, "=APAGADO",F8:F689,"=Fibra Optica") -> 0 | Z4: =COUNTIFS(Z8:Z689, "=APAGADO",F8:F689,"=Fibra Optica") -> 0 | AA4: =COUNTIFS(AA8:AA689, "=APAGADO",F8:F689,"=Fibra Optica") -> 0 | AB4: =COUNTIFS(AB8:AB689, "=APAGADO",F8:F689,"=Fibra Optica") -> 0 | AC4: =COUNTIFS(AC8:AC689, "=APAGADO",F8:F689,"=Fibra Optica") -> 0 | AD4: =COUNTIFS(AD8:AD689, "=APAGADO",F8:F689,"=Fibra Optica") -> 0 | AE4: =COUNTIFS(AE8:AE689, "=APAGADO",F8:F689,"=Fibra Optica") -> 0 | AF4: =COUNTIFS(AF8:AF689, "=APAGADO",F8:F689,"=Fibra Optica") -> 0 | AG4: =COUNTIFS(AG8:AG689, "=APAGADO",F8:F689,"=Fibra Optica") -> 0 | AH4: =COUNTIFS(AH8:AH689, "=APAGADO",F8:F689,"=Fibra Optica") -> 0 | AI4: =COUNTIFS(AI8:AI689, "=APAGADO",F8:F689,"=Fibra Optica") -> 0 | AJ4: =COUNTIFS(AJ8:AJ689, "=APAGADO",F8:F689,"=Fibra Optica") -> 0 | AK4: =COUNTIFS(AK8:AK689, "=APAGADO",F8:F689,"=Fibra Optica") -> 0 | AL4: =COUNTIFS(AL8:AL689, "=APAGADO",F8:F689,"=Fibra Optica") -> 0 | AM4: =COUNTIFS(AM8:AM689, "=APAGADO",F8:F689,"=Fibra Optica") -> 0 | AN4: =COUNTIFS(AN8:AN689, "=APAGADO",F8:F689,"=Fibra Optica") -> 0 | AO4: =COUNTIFS(AO8:AO689, "=APAGADO",F8:F689,"=Fibra Optica") -> 0 | AP4: =COUNTIFS(AP8:AP689, "=APAGADO",F8:F689,"=Fibra Optica") -> 0 | AQ4: =COUNTIFS(AQ8:AQ689, "=APAGADO",G8:G689,"=Fibra Optica") -> 0
D5: APAGADOS RADIO | M5: =COUNTIFS(M8:M689, "=APAGADO",F8:F689,"=RADIO") -> 0 | N5: =COUNTIFS(N8:N689, "=APAGADO",F8:F689,"=RADIO") -> 0 | O5: =COUNTIFS(O8:O689, "=APAGADO",F8:F689,"=RADIO") -> 0 | P5: =COUNTIFS(P8:P689, "=APAGADO",F8:F689,"=RADIO") -> 0 | Q5: =COUNTIFS(Q8:Q689, "=APAGADO",F8:F689,"=RADIO") -> 0 | R5: =COUNTIFS(R8:R689, "=APAGADO",F8:F689,"=RADIO") -> 0 | S5: =COUNTIFS(S8:S689, "=APAGADO",F8:F689,"=RADIO") -> 0 | T5: =COUNTIFS(T8:T689, "=APAGADO",F8:F689,"=RADIO") -> 0 | U5: =COUNTIFS(U8:U689, "=APAGADO",F8:F689,"=RADIO") -> 0 | V5: =COUNTIFS(V8:V689, "=APAGADO",F8:F689,"=RADIO") -> 0 | W5: =COUNTIFS(W8:W689, "=APAGADO",F8:F689,"=RADIO") -> 0 | X5: =COUNTIFS(X8:X689, "=APAGADO",F8:F689,"=RADIO") -> 0 | Y5: =COUNTIFS(Y8:Y689, "=APAGADO",F8:F689,"=RADIO") -> 0 | Z5: =COUNTIFS(Z8:Z689, "=APAGADO",F8:F689,"=RADIO") -> 0 | AA5: =COUNTIFS(AA8:AA689, "=APAGADO",F8:F689,"=RADIO") -> 0 | AB5: =COUNTIFS(AB8:AB689, "=APAGADO",F8:F689,"=RADIO") -> 0 | AC5: =COUNTIFS(AC8:AC689, "=APAGADO",F8:F689,"=RADIO") -> 0 | AD5: =COUNTIFS(AD8:AD689, "=APAGADO",F8:F689,"=RADIO") -> 0 | AE5: =COUNTIFS(AE8:AE689, "=APAGADO",F8:F689,"=RADIO") -> 0 | AF5: =COUNTIFS(AF8:AF689, "=APAGADO",F8:F689,"=RADIO") -> 0 | AG5: =COUNTIFS(AG8:AG689, "=APAGADO",F8:F689,"=RADIO") -> 0 | AH5: =COUNTIFS(AH8:AH689, "=APAGADO",F8:F689,"=RADIO") -> 0 | AI5: =COUNTIFS(AI8:AI689, "=APAGADO",F8:F689,"=RADIO") -> 0 | AJ5: =COUNTIFS(AJ8:AJ689, "=APAGADO",F8:F689,"=RADIO") -> 0 | AK5: =COUNTIFS(AK8:AK689, "=APAGADO",F8:F689,"=RADIO") -> 0 | AL5: =COUNTIFS(AL8:AL689, "=APAGADO",F8:F689,"=RADIO") -> 0 | AM5: =COUNTIFS(AM8:AM689, "=APAGADO",F8:F689,"=RADIO") -> 0 | AN5: =COUNTIFS(AN8:AN689, "=APAGADO",F8:F689,"=RADIO") -> 0 | AO5: =COUNTIFS(AO8:AO689, "=APAGADO",F8:F689,"=RADIO") -> 0 | AP5: =COUNTIFS(AP8:AP689, "=APAGADO",F8:F689,"=RADIO") -> 0 | AQ5: =COUNTIFS(AQ8:AQ689, "=APAGADO",G8:G689,"=RADIO") -> 0
D6: APAGADOS ANTENA | M6: =COUNTIFS(M8:M689, "=APAGADO",F8:F689,"=PTO A FO") -> 0 | N6: =COUNTIFS(N8:N689, "=APAGADO",F8:F689,"=PTO A FO") -> 0 | O6: =COUNTIFS(O8:O689, "=APAGADO",F8:F689,"=PTO A FO") -> 0 | P6: =COUNTIFS(P8:P689, "=APAGADO",F8:F689,"=PTO A FO") -> 0 | Q6: =COUNTIFS(Q8:Q689, "=APAGADO",F8:F689,"=PTO A FO") -> 0 | R6: =COUNTIFS(R8:R689, "=APAGADO",F8:F689,"=PTO A FO") -> 0 | S6: =COUNTIFS(S8:S689, "=APAGADO",F8:F689,"=PTO A FO") -> 0 | T6: =COUNTIFS(T8:T689, "=APAGADO",F8:F689,"=PTO A FO") -> 0 | U6: =COUNTIFS(U8:U689, "=APAGADO",F8:F689,"=PTO A FO") -> 0 | V6: =COUNTIFS(V8:V689, "=APAGADO",F8:F689,"=PTO A FO") -> 0 | W6: =COUNTIFS(W8:W689, "=APAGADO",F8:F689,"=PTO A FO") -> 0 | X6: =COUNTIFS(X8:X689, "=APAGADO",F8:F689,"=PTO A FO") -> 0 | Y6: =COUNTIFS(Y8:Y689, "=APAGADO",F8:F689,"=PTO A FO") -> 0 | Z6: =COUNTIFS(Z8:Z689, "=APAGADO",F8:F689,"=PTO A FO") -> 0 | AA6: =COUNTIFS(AA8:AA689, "=APAGADO",F8:F689,"=PTO A FO") -> 0 | AB6: =COUNTIFS(AB8:AB689, "=APAGADO",F8:F689,"=PTO A FO") -> 0 | AC6: =COUNTIFS(AC8:AC689, "=APAGADO",F8:F689,"=PTO A FO") -> 0 | AD6: =COUNTIFS(AD8:AD689, "=APAGADO",F8:F689,"=PTO A FO") -> 0 | AE6: =COUNTIFS(AE8:AE689, "=APAGADO",F8:F689,"=PTO A FO") -> 0 | AF6: =COUNTIFS(AF8:AF689, "=APAGADO",F8:F689,"=PTO A FO") -> 0 | AG6: =COUNTIFS(AG8:AG689, "=APAGADO",F8:F689,"=PTO A FO") -> 0 | AH6: =COUNTIFS(AH8:AH689, "=APAGADO",F8:F689,"=PTO A FO") -> 0 | AI6: =COUNTIFS(AI8:AI689, "=APAGADO",F8:F689,"=PTO A FO") -> 0 | AJ6: =COUNTIFS(AJ8:AJ689, "=APAGADO",F8:F689,"=PTO A FO") -> 0 | AK6: =COUNTIFS(AK8:AK689, "=APAGADO",F8:F689,"=PTO A FO") -> 0 | AL6: =COUNTIFS(AL8:AL689, "=APAGADO",F8:F689,"=PTO A FO") -> 0 | AM6: =COUNTIFS(AM8:AM689, "=APAGADO",F8:F689,"=PTO A FO") -> 0 | AN6: =COUNTIFS(AN8:AN689, "=APAGADO",F8:F689,"=PTO A FO") -> 0 | AO6: =COUNTIFS(AO8:AO689, "=APAGADO",F8:F689,"=PTO A FO") -> 0 | AP6: =COUNTIFS(AP8:AP689, "=APAGADO",F8:F689,"=PTO A FO") -> 0 | AQ6: =COUNTIFS(AQ8:AQ689, "=APAGADO",G8:G689,"=PTO A FO") -> 0
A7: Barrio | B7: [Denominacion] | C7: [Empresa Mantenimiento] | D7: [Ubicacion] | E7: [Tipo de Camara] | F7: [Tipo de Conexion] | G7: Destino | I7: DIAS FUNCIONANDO | J7: MAC | K7: DIAS CAIDA | L7: EFECTIVIDAD | M7: 46023 | N7: 46024 | O7: 46025 | P7: 46026 | Q7: 46027 | R7: 46028 | S7: 46029 | T7: 46030 | U7: 46031 | V7: 46032 | W7: 46033 | X7: 46034 | Y7: 46035 | Z7: 46036 | AA7: 46037 | AB7: 46038 | AC7: 46039 | AD7: 46040 | AE7: 46041 | AF7: 46042 | AG7: 46043 | AH7: 46044 | AI7: 46045 | AJ7: 46046 | AK7: 46047 | AL7: 46048 | AM7: 46049 | AN7: 46050 | AO7: 46051 | AP7: 46052 | AQ7: 46053
A8: ALTAMIRA | B8: ALT01 | C8: BONOMO | D8: Calchaqui y Sgto. Cabral | E8: Domo | F8: Fibra Optica | H8: 172.20.10.6 | I8: =COUNTIF(M8:AN8,"") -> 28 | J8: 00-07-5F-87-83-56 | K8: =COUNTIF(M8:AN8,"APAGADO") -> 0 | L8: =(I8)/(K8+I8) -> 1
A9: ALTAMIRA | B9: ALT02 | C9: BONOMO | D9: Calchaqui y Lope de Vega | E9: Domo | F9: PTO A FO | G9: CABRAL Y CALCHAQUI | H9: 172.20.12.218 | I9: =COUNTIF(M9:AN9,"") -> 28 | J9: 00-04-63-50-42-A4 | K9: =COUNTIF(M9:AN9,"APAGADO") -> 0 | L9: =(I9)/(K9+I9) -> 1
A10: ALTAMIRA | B10: ALT 03 | C10: BONOMO | D10: Bombero Galarza y Necochea | E10: Domo | F10: GPON | H10: 172.20.12.54 | I10: =COUNTIF(M10:AN10,"") -> 28 | J10: 00-07-5F-87-9D-EF | K10: =COUNTIF(M10:AN10,"APAGADO") -> 0 | L10: =(I10)/(K10+I10) -> 1
A11: ALTAMIRA | B11: ALT 04 | C11: BONOMO | D11: Francia y Necochea | E11: Domo | F11: GPON | H11: 172.20.12.55 | I11: =COUNTIF(M11:AN11,"") -> 28 | J11: 00-04-63-59-22-57 | K11: =COUNTIF(M11:AN11,"APAGADO") -> 0 | L11: =(I11)/(K11+I11) -> 1
A12: ALTAMIRA | B12: ALT05 | C12: BONOMO | D12: Av. Calchaqui y Bombero Galarza | E12: Domo | F12: GPON | G12: NECOCHEA Y GALARZA | H12: 172.20.12.216 | I12: =COUNTIF(M12:AN12,"") -> 28 | J12: 00-07-5F-77-02-85 | K12: =COUNTIF(M12:AN12,"APAGADO") -> 0 | L12: =(I12)/(K12+I12) -> 1
A13: ALTAMIRA | B13: ALT 06 | C13: BONOMO | D13: LOPE DE VEGA Y NECOCHEA | E13: Domo | F13: GPON | G13: NECOCHEA Y GALARZA | H13: 172.20.12.12 | I13: =COUNTIF(M13:AN13,"") -> 28 | J13: 00-04-63-4F-DD-DB | K13: =COUNTIF(M13:AN13,"APAGADO") -> 0 | L13: =(I13)/(K13+I13) -> 1
A14: ALTAMIRA | B14: ALT07 | C14: BONOMO | D14: AV. CALCHAQUI Y AV. DEL TRABAJO | E14: DOMO | F14: PTO A FO | G14: CABRAL Y CALCHAQUI | H14: 172.20.10.57 | I14: =COUNTIF(M14:AN14,"") -> 28 | J14: 00-04-63-4F-DE-CA | K14: =COUNTIF(M14:AN14,"APAGADO") -> 0 | L14: =(I14)/(K14+I14) -> 1
A15: ALTAMIRA | B15: ALT 08 | C15: BONOMO | D15: HUMAITA Y NECOCHEA | E15: DOMO | F15: Fibra Optica | H15: 172.20.11.215 | I15: =COUNTIF(M15:AN15,"") -> 28 | J15: 00-07-5F-BE-59-2D | K15: =COUNTIF(M15:AN15,"APAGADO") -> 0 | L15: =(I15)/(K15+I15) -> 1
A16: ALTAMIRA | B16: ALT 09 | C16: BONOMO | D16: NECOCHEA Y CURUPAITY | E16: DOMO | F16: Fibra Optica | H16: 172.20.11.216 | I16: =COUNTIF(M16:AN16,"") -> 28 | J16: 00-07-5F-BE-59-27 | K16: =COUNTIF(M16:AN16,"APAGADO") -> 0 | L16: =(I16)/(K16+I16) -> 1
A17: ALTAMIRA | B17: ALT 10 | C17: BONOMO | D17: Calchaqui y Francia | E17: Domo | F17: GPON | H17: 172.20.12.156 | I17: =COUNTIF(M17:AN17,"") -> 28 | J17: 00-07-5F-AB-BB-41 | K17: =COUNTIF(M17:AN17,"APAGADO") -> 0 | L17: =(I17)/(K17+I17) -> 1
A18: ALTAMIRA | B18: ALT 11 | C18: BONOMO | D18: CALCHAQUÍ Y GALARZA FIJA | E18: Fija | F18: GPON | H18: 172.20.12.241 | I18: =COUNTIF(M18:AN18,"") -> 28 | J18: 3c-1b-f8-df-95-58 | K18: =COUNTIF(M18:AN18,"APAGADO") -> 0 | L18: =(I18)/(K18+I18) -> 1
A19: AGUSTIN RAMIREZ | B19: ARA 01 | C19: BONOMO | D19: Malambo y Tranquera | E19: Domo | F19: Fibra Optica | H19: 172.20.12.110 | I19: =COUNTIF(M19:AN19,"") -> 28 | J19: 00-04-63-4F-DB-B6 | K19: =COUNTIF(M19:AN19,"APAGADO") -> 0 | L19: =(I19)/(K19+I19) -> 1
A20: AGUSTIN RAMIREZ | B20: ARA 02 | C20: BONOMO | D20: El malambo y La Tranquera | E20: Fija | F20: GPON | H20: 172.20.12.235 | I20: =COUNTIF(M20:AN20,"") -> 28 | J20: C0:6D:ED:A3:E6:63 | K20: =COUNTIF(M20:AN20,"APAGADO") -> 0 | L20: =(I20)/(K20+I20) -> 1
A21: AGUSTIN RAMIREZ | B21: ARA 03 | C21: BONOMO | D21: 437 Y La Tranquera | E21: Fija | F21: GPON | H21: 172.20.10.232 | I21: =COUNTIF(M21:AN21,"") -> 28 | J21: C0:6D:ED:A3:66:6A | K21: =COUNTIF(M21:AN21,"APAGADO") -> 0 | L21: =(I21)/(K21+I21) -> 1
A22: BELGRANO | B22: BEL 01 | C22: BONOMO | D22: San Martin y Dardo Rocha | E22: DOMO | F22: Fibra Optica | H22: 172.20.12.64 | I22: =COUNTIF(M22:AN22,"") -> 28 | J22: 00-07-5F-81-B9-E9 | K22: =COUNTIF(M22:AN22,"APAGADO") -> 0 | L22: =(I22)/(K22+I22) -> 1
A23: BELGRANO | B23: BEL 02 | C23: BONOMO | D23: Guardia vieja y Fronteriz | E23: DOMO | F23: Fibra Optica | H23: 172.20.10.117 | I23: =COUNTIF(M23:AN23,"") -> 28 | J23: E4-30-22-4F-9E-62 | K23: =COUNTIF(M23:AN23,"APAGADO") -> 0 | L23: =(I23)/(K23+I23) -> 1
A24: BOSQUES CENTRO | B24: BOSQC 01 | C24: COSEIDI | D24: LUIS AGOTE E/DANUNCIO Y CAMPOAMOR | E24: Fija | F24: PTO A FO | H24: 172.20.11.15 | I24: =COUNTIF(M24:AN24,"") -> 28 | J24: 00-07-5F-B7-56-89 | K24: =COUNTIF(M24:AN24,"APAGADO") -> 0 | L24: =(I24)/(K24+I24) -> 1
A25: BOSQUES CENTRO | B25: BOSQC 02 | C25: COSEIDI | D25: LUIS AGOTE E/DANUNCIO Y CAMPOAMOR | E25: Fija | F25: PTO A FO | H25: 172.20.11.16 | I25: =COUNTIF(M25:AN25,"") -> 28 | J25: 00-07-5F-B4-17-A8 | K25: =COUNTIF(M25:AN25,"APAGADO") -> 0 | L25: =(I25)/(K25+I25) -> 1
A26: BOSQUES CENTRO | B26: BOSQC 03 | C26: COSEIDI | D26: BENAVENTE Y LUIS AGOTE | E26: Fija | F26: PTO A FO | H26: 172.20.11.13 | I26: =COUNTIF(M26:AN26,"") -> 28 | J26: 00-07-5F-B6-B8-A5 | K26: =COUNTIF(M26:AN26,"APAGADO") -> 0 | L26: =(I26)/(K26+I26) -> 1
... A50: CENTRO | B50: CEN 05 | C50: BONOMO | D50: Bocuzzi e/España y San Martin | E50: DOMO | F50: Fibra Optica | H50: 172.20.10.200 | I50: =COUNTIF(M50:AN50,"") -> 28 | J50: 00-07-5F-81-9C-7F | K50: =COUNTIF(M50:AN50,"APAGADO") -> 0 | L50: =(I50)/(K50+I50) -> 1
A51: CENTRO | B51: CEN06 | C51: BONOMO | D51: Monteagudo y A.del Valle | E51: Fija | F51: Fibra Optica | H51: 172.20.10.02 | I51: =COUNTIF(M51:AN51,"") -> 28 | K51: =COUNTIF(M51:AN51,"APAGADO") -> 0 | L51: =(I51)/(K51+I51) -> 1
A52: CENTRO | B52: CEN07 | C52: BONOMO | D52: San Martin y Guemes | E52: DOMO | F52: Fibra Optica | H52: 172.20.11.20 | I52: =COUNTIF(M52:AN52,"") -> 28 | J52: 00-07-5F-77-25-57 | K52: =COUNTIF(M52:AN52,"APAGADO") -> 0 | L52: =(I52)/(K52+I52) -> 1
A53: CENTRO | B53: CEN08 | C53: BONOMO | D53: San Martin y Pte.Peron | E53: Domo | F53: Fibra Optica | H53: 172.20.11.21 | I53: =COUNTIF(M53:AN53,"") -> 28 | J53: 00-07-5F-7A-71-56 | K53: =COUNTIF(M53:AN53,"APAGADO") -> 0 | L53: =(I53)/(K53+I53) -> 1
A54: CENTRO | B54: CEN09 | C54: BONOMO | D54: Chacabuco y 25 de Mayo | E54: Domo | F54: Fibra Optica | H54: 172.20.11.22 | I54: =COUNTIF(M54:AN54,"") -> 28 | J54: 00-07-5F-76-FB-07 | K54: =COUNTIF(M54:AN54,"APAGADO") -> 0 | L54: =(I54)/(K54+I54) -> 1
A55: CENTRO | B55: CEN10 | C55: BONOMO | D55: Monteagudo y Pte. Peron | E55: Domo | F55: Fibra Optica | H55: 172.20.11.23 | I55: =COUNTIF(M55:AN55,"") -> 28 | J55: 00-07-5F-76-FC-7B | K55: =COUNTIF(M55:AN55,"APAGADO") -> 0 | L55: =(I55)/(K55+I55) -> 1
A56: CENTRO | B56: CEN11 | C56: BONOMO | D56: Monteagudo y Bocuzzi | E56: Domo | F56: Fibra Optica | H56: 172.20.10.24 | I56: =COUNTIF(M56:AN56,"") -> 28 | J56: 00-07-5F-77-26-89 | K56: =COUNTIF(M56:AN56,"APAGADO") -> 0 | L56: =(I56)/(K56+I56) -> 1
A57: CENTRO | B57: CEN 12 | C57: BONOMO | D57: Monteagudo y Mitre | E57: Domo | F57: Fibra Optica | H57: 172.20.10.23 | I57: =COUNTIF(M57:AN57,"") -> 28 | J57: 00-07-5F-75-24-A1 | K57: =COUNTIF(M57:AN57,"APAGADO") -> 0 | L57: =(I57)/(K57+I57) -> 1
A58: CENTRO | B58: CEN 13 | C58: BONOMO | D58: 25 de Mayo y Maipu | E58: DOMO | F58: GPON | H58: 172.20.10.20 | I58: =COUNTIF(M58:AN58,"") -> 28 | J58: 00-07-5F-77-2B-1B | K58: =COUNTIF(M58:AN58,"APAGADO") -> 0 | L58: =(I58)/(K58+I58) -> 1
A59: CENTRO | B59: CEN14 | C59: BONOMO | D59: Pte.Peron e/Pringles y Brown | E59: Domo | F59: Fibra Optica | H59: 172.20.10.21 | I59: =COUNTIF(M59:AN59,"") -> 28 | J59: 00-04-63-50-44-82 | K59: =COUNTIF(M59:AN59,"APAGADO") -> 0 | L59: =(I59)/(K59+I59) -> 1
A60: CENTRO | B60: CEN15 | C60: BONOMO | D60: Alberdi y A.del Valle | E60: Domo | F60: GPON | H60: 172.20.10.35 | I60: =COUNTIF(M60:AN60,"") -> 28 | J60: 00-07-5F-75-23-66 | K60: =COUNTIF(M60:AN60,"APAGADO") -> 0 | L60: =(I60)/(K60+I60) -> 1
A61: CENTRO | B61: CEN16 | C61: BONOMO | D61: San Martin y Pte. Peron | E61: Fija | F61: Fibra Optica | H61: 172.20.12.36 | I61: =COUNTIF(M61:AN61,"") -> 28 | J61: 00-07-5F-95-ED-8E | K61: =COUNTIF(M61:AN61,"APAGADO") -> 0 | L61: =(I61)/(K61+I61) -> 1
A62: CENTRO | B62: CEN17 | C62: BONOMO | D62: San Martin y Mitre | E62: Domo | F62: PTO A FO | G62: SAN MARTIN Y SALLARES | H62: 172.20.12.200 | I62: =COUNTIF(M62:AN62,"") -> 28 | J62: 00-04-63-5A-E0-93 | K62: =COUNTIF(M62:AN62,"APAGADO") -> 0 | L62: =(I62)/(K62+I62) -> 1
A63: CENTRO | B63: CEN18 | C63: BONOMO | D63: Monteagudo e/Mitre y Sallares | E63: Fija | F63: Fibra Optica | H63: 172.20.10.26 | I63: =COUNTIF(M63:AN63,"") -> 28 | J63: 00-04-63-32-84-B7 | K63: =COUNTIF(M63:AN63,"APAGADO") -> 0 | L63: =(I63)/(K63+I63) -> 1
...

Sheet AUXILIAR

Sheet informe
C1: CANTIDAD | D1: APAGADAS | E1: %
B2: TOTAL | C2: =CANTIDAD_DE_CAMARAS -> 574 | F2: 46023
A3: L | B3: CAIDAS | C3: ='RESUMEN TOTAL'!M3 -> 0 | E3: =C3/C2 -> 0
B4: LLEGAMOS NOSOTROS | C4: 0 | D4: 0 | E4: =D4/C2 -> 0
B5: NO ESTA LA CAMARA | C5: 0 | D5: 0 | E5: =D5/C2 -> 0
A6: L | B6: RADIO | C6: 0 | D6: 0 | E6: =D6/C2 -> 0
C7: 0 | D7: 0 | E7: =D7/C2 -> 0
C8: CANTIDAD | D8: APAGADAS | E8: %
A9: F | B9: BONOMO | C9: 304
A10: F | B10: COSEIDI | C10: =COSEIDIcam -> 270 | D10: =Hoja1!F5 -> 0
C12: CANTIDAD | D12: APAGADAS | E12: %
B13: TOTAL | C13: =CANTIDAD_DE_CAMARAS -> 574 | F13: 46024
A14: M | B14: CAIDAS | C14: ='RESUMEN TOTAL'!N3 -> 0 | E14: =C14/C13 -> 0
B15: LLEGAMOS NOSOTROS | C15: 0 | D15: 0 | E15: =D15/C13 -> 0
B16: NO ESTA LA CAMARA | C16: 0 | D16: =D15-C16 -> 0 | E16: =D16/C13 -> 0
A17: M | B17: RADIO | C17: ='RESUMEN TOTAL'!N5 -> 0 | D17: =D16-C17 -> 0 | E17: =D17/C13 -> 0
D18: 0 | E18: =D18/C13 -> 0
C19: CANTIDAD | D19: APAGADAS | E19: %
A20: G | B20: BONOMO | C20: 304 | D20: =Hoja1!G3 -> 0 | E20: =D20/C20 -> 0
A21: G | B21: COSEIDI | C21: =COSEIDIcam -> 270 | D21: =Hoja1!G5 -> 0 | E21: =D21/C21 -> 0
C23: CANTIDAD | D23: APAGADAS | E23: %
B24: TOTAL | C24: =CANTIDAD_DE_CAMARAS -> 574 | F24: 46025
A25: N | B25: CAIDAS | C25: ='RESUMEN TOTAL'!O3 -> 0 | E25: =C25/C24 -> 0
B26: LLEGAMOS NOSOTROS | C26: 0 | D26: =C25-C26 -> 0 | E26: =D26/C24 -> 0
B27: NO ESTA LA CAMARA | C27: 0 | D27: =D26-C27 -> 0 | E27: =D27/C24 -> 0
A28: N | B28: RADIO | C28: ='RESUMEN TOTAL'!O5 -> 0 | D28: =D27-C28 -> 0 | E28: =D28/C24 -> 0
C29: 0 | D29: =D28-C29 -> 0 | E29: =D29/C24 -> 0
C30: CANTIDAD | D30: APAGADAS | E30: %
B31: BONOMO | C31: 304 | D31: 0 | E31: =D31/C31 -> 0
B32: COSEIDI | C32: =COSEIDIcam -> 270 | D32: 0 | E32: =D32/C32 -> 0
C34: CANTIDAD | D34: APAGADAS | E34: %
B35: TOTAL | C35: =CANTIDAD_DE_CAMARAS -> 574 | F35: 46026
A36: O | B36: CAIDAS | C36: ='RESUMEN TOTAL'!P3 -> 0 | E36: =C36/C35 -> 0
B37: LLEGAMOS NOSOTROS | C37: 0 | D37: 0 | E37: =D37/C35 -> 0
B38: NO ESTA LA CAMARA | C38: 0 | D38: 0 | E38: =D38/C35 -> 0
A39: O | B39: RADIO | C39: 0 | D39: =D38-C39 -> 0 | E39: =D39/C35 -> 0
C40: 0 | D40: 0 | E40: =D40/C35 -> 0
C41: CANTIDAD | D41: APAGADAS | E41: %
B42: BONOMO | C42: 304 | D42: 0 | E42: =D42/C42 -> 0
B43: COSEIDI | C43: =COSEIDIcam -> 270 | D43: =Hoja1!I5 -> 0 | E43: 0.24
...

Sheet paradas
C1: TOTAL PARADAS | D1: =COUNTIFS(A5:A602,"=paradas seguras")/2 -> 0 | E1: TOTAL DE CAMARAS EN PARADAS | H1: =COUNTIFS(A5:A602,"=paradas seguras") -> 0 | I1: TOTAL DE CAMARAS | K1: =COUNTIFS(D5:D602,"=GFIJA") -> 0 | L1: TOTAL DE INTERCOMUNICADORES | O1: =COUNTIFS(D5:D602,"=INTERCOMUNICADOR") -> 0
E2: FIJAS | F2: =COUNTIFS(F4:F601, "=APAGADO",D4:D601,"=GFIJA") -> 0 | G2: =COUNTIFS(G4:G601, "=APAGADO",D4:D601,"=GFIJA") -> 0 | H2: =COUNTIFS(H4:H601, "=APAGADO",D4:D601,"=GFIJA") -> 0 | I2: =COUNTIFS(I4:I601, "=APAGADO",D4:D601,"=GFIJA") -> 0 | J2: =COUNTIFS(J4:J601, "=APAGADO",D4:D601,"=GFIJA") -> 0 | K2: =COUNTIFS(K4:K601, "=APAGADO",D4:D601,"=GFIJA") -> 0 | L2: =COUNTIFS(L4:L601, "=APAGADO",D4:D601,"=GFIJA") -> 0 | M2: =COUNTIFS(M4:M601, "=APAGADO",D4:D601,"=GFIJA") -> 0 | N2: =COUNTIFS(N4:N601, "=APAGADO",D4:D601,"=GFIJA") -> 0 | O2: =COUNTIFS(O4:O601, "=APAGADO",D4:D601,"=GFIJA") -> 0 | P2: =COUNTIFS(P4:P601, "=APAGADO",D4:D601,"=GFIJA") -> 0 | Q2: =COUNTIFS(Q4:Q601, "=APAGADO",D4:D601,"=GFIJA") -> 0 | R2: =COUNTIFS(R4:R601, "=APAGADO",D4:D601,"=GFIJA") -> 0 | S2: =COUNTIFS(S4:S601, "=APAGADO",D4:D601,"=GFIJA") -> 0 | T2: =COUNTIFS(T4:T601, "=APAGADO",D4:D601,"=GFIJA") -> 0 | U2: =COUNTIFS(U4:U601, "=APAGADO",D4:D601,"=GFIJA") -> 0 | V2: =COUNTIFS(V4:V601, "=APAGADO",D4:D601,"=GFIJA") -> 0 | W2: =COUNTIFS(W4:W601, "=APAGADO",D4:D601,"=GFIJA") -> 0 | X2: =COUNTIFS(X4:X601, "=APAGADO",D4:D601,"=GFIJA") -> 0 | Y2: =COUNTIFS(Y4:Y601, "=APAGADO",D4:D601,"=GFIJA") -> 0 | Z2: =COUNTIFS(Z4:Z601, "=APAGADO",D4:D601,"=GFIJA") -> 0 | AA2: =COUNTIFS(AA4:AA601, "=APAGADO",D4:D601,"=GFIJA") -> 0 | AB2: =COUNTIFS(AB4:AB601, "=APAGADO",D4:D601,"=GFIJA") -> 0 | AC2: =COUNTIFS(AC4:AC601, "=APAGADO",D4:D601,"=GFIJA") -> 0 | AD2: =COUNTIFS(AD4:AD601, "=APAGADO",D4:D601,"=GFIJA") -> 0 | AE2: =COUNTIFS(AE4:AE601, "=APAGADO",D4:D601,"=GFIJA") -> 0 | AF2: =COUNTIFS(AF4:AF601, "=APAGADO",D4:D601,"=GFIJA") -> 0 | AG2: =COUNTIFS(AG4:AG601, "=APAGADO",D4:D601,"=GFIJA") -> 0 | AH2: =COUNTIFS(AH4:AH601, "=APAGADO",D4:D601,"=GFIJA") -> 0 | AI2: =COUNTIFS(AI4:AI601, "=APAGADO",D4:D601,"=GFIJA") -> 0 | AJ2: =COUNTIFS(AJ4:AJ601, "=APAGADO",E4:E601,"=GFIJA") -> 0
E3: INTERCOMUNICADOR | F3: =COUNTIFS(F6:F603, "=APAGADO",D4:D601,"=INTERCOMUNICADOR") -> 0 | G3: =COUNTIFS(G6:G603, "=APAGADO",D4:D601,"=INTERCOMUNICADOR") -> 0 | H3: =COUNTIFS(H6:H603, "=APAGADO",D4:D601,"=INTERCOMUNICADOR") -> 0 | I3: =COUNTIFS(I6:I603, "=APAGADO",D4:D601,"=INTERCOMUNICADOR") -> 0 | J3: =COUNTIFS(J6:J603, "=APAGADO",D4:D601,"=INTERCOMUNICADOR") -> 0 | K3: =COUNTIFS(K6:K603, "=APAGADO",D4:D601,"=INTERCOMUNICADOR") -> 0 | L3: =COUNTIFS(L6:L603, "=APAGADO",D4:D601,"=INTERCOMUNICADOR") -> 0 | M3: =COUNTIFS(M6:M603, "=APAGADO",D4:D601,"=INTERCOMUNICADOR") -> 0 | N3: =COUNTIFS(N6:N603, "=APAGADO",D4:D601,"=INTERCOMUNICADOR") -> 0 | O3: =COUNTIFS(O6:O603, "=APAGADO",D4:D601,"=INTERCOMUNICADOR") -> 0 | P3: =COUNTIFS(P6:P603, "=APAGADO",D4:D601,"=INTERCOMUNICADOR") -> 0 | Q3: =COUNTIFS(Q6:Q603, "=APAGADO",D4:D601,"=INTERCOMUNICADOR") -> 0 | R3: =COUNTIFS(R6:R603, "=APAGADO",D4:D601,"=INTERCOMUNICADOR") -> 0 | S3: =COUNTIFS(S6:S603, "=APAGADO",D4:D601,"=INTERCOMUNICADOR") -> 0 | T3: =COUNTIFS(T6:T603, "=APAGADO",D4:D601,"=INTERCOMUNICADOR") -> 0 | U3: =COUNTIFS(U6:U603, "=APAGADO",D4:D601,"=INTERCOMUNICADOR") -> 0 | V3: =COUNTIFS(V6:V603, "=APAGADO",D4:D601,"=INTERCOMUNICADOR") -> 0 | W3: =COUNTIFS(W6:W603, "=APAGADO",D4:D601,"=INTERCOMUNICADOR") -> 0 | X3: =COUNTIFS(X6:X603, "=APAGADO",D4:D601,"=INTERCOMUNICADOR") -> 0 | Y3: =COUNTIFS(Y6:Y603, "=APAGADO",D4:D601,"=INTERCOMUNICADOR") -> 0 | Z3: =COUNTIFS(Z6:Z603, "=APAGADO",D4:D601,"=INTERCOMUNICADOR") -> 0 | AA3: =COUNTIFS(AA6:AA603, "=APAGADO",D4:D601,"=INTERCOMUNICADOR") -> 0 | AB3: =COUNTIFS(AB6:AB603, "=APAGADO",D4:D601,"=INTERCOMUNICADOR") -> 0 | AC3: =COUNTIFS(AC6:AC603, "=APAGADO",D4:D601,"=INTERCOMUNICADOR") -> 0 | AD3: =COUNTIFS(AD6:AD603, "=APAGADO",D4:D601,"=INTERCOMUNICADOR") -> 0 | AE3: =COUNTIFS(AE6:AE603, "=APAGADO",D4:D601,"=INTERCOMUNICADOR") -> 0 | AF3: =COUNTIFS(AF6:AF603, "=APAGADO",D4:D601,"=INTERCOMUNICADOR") -> 0 | AG3: =COUNTIFS(AG6:AG603, "=APAGADO",D4:D601,"=INTERCOMUNICADOR") -> 0 | AH3: =COUNTIFS(AH6:AH603, "=APAGADO",D4:D601,"=INTERCOMUNICADOR") -> 0 | AI3: =COUNTIFS(AI6:AI603, "=APAGADO",D4:D601,"=INTERCOMUNICADOR") -> 0 | AJ3: =COUNTIFS(AJ6:AJ603, "=APAGADO",E4:E601,"=INTERCOMUNICADOR") -> 0
A4: ='RESUMEN TOTAL'!A7 -> Barrio | B4: ='RESUMEN TOTAL'!B7 -> [Denominacion] | C4: ='RESUMEN TOTAL'!D7 -> [Ubicacion] | D4: ='RESUMEN TOTAL'!E7 -> [Tipo de Camara] | E4: ='RESUMEN TOTAL'!F7 -> [Tipo de Conexion] | F4: ='RESUMEN TOTAL'!M7 -> 46023 | G4: ='RESUMEN TOTAL'!N7 -> 46024 | H4: ='RESUMEN TOTAL'!O7 -> 46025 | I4: ='RESUMEN TOTAL'!P7 -> 46026 | J4: ='RESUMEN TOTAL'!Q7 -> 46027 | K4: ='RESUMEN TOTAL'!R7 -> 46028 | L4: ='RESUMEN TOTAL'!S7 -> 46029 | M4: ='RESUMEN TOTAL'!T7 -> 46030 | ... AJ4: ='RESUMEN TOTAL'!AQ7 -> 46053 | XFB4: =SUM(F4:XFA4) -> 1427178
A5: ='RESUMEN TOTAL'!A8 -> ALTAMIRA | B5: ='RESUMEN TOTAL'!B8 -> ALT01 | C5: ='RESUMEN TOTAL'!D8 -> Calchaqui y Sgto. Cabral | D5: ='RESUMEN TOTAL'!E8 -> Domo | E5: ='RESUMEN TOTAL'!F8 -> Fibra Optica | F5: ='RESUMEN TOTAL'!M8 -> 0 | G5: ='RESUMEN TOTAL'!N8 -> 0 | H5: ='RESUMEN TOTAL'!O8 -> 0 | I5: ='RESUMEN TOTAL'!P8 -> 0 | J5: ='RESUMEN TOTAL'!Q8 -> 0 | K5: ='RESUMEN TOTAL'!R8 -> 0 | L5: ='RESUMEN TOTAL'!S8 -> 0 | M5: ='RESUMEN TOTAL'!T8 -> 0 | ... AJ5: ='RESUMEN TOTAL'!AQ8 -> 0
A6: ='RESUMEN TOTAL'!A9 -> ALTAMIRA | B6: ='RESUMEN TOTAL'!B9 -> ALT02 | C6: ='RESUMEN TOTAL'!D9 -> Calchaqui y Lope de Vega | D6: ='RESUMEN TOTAL'!E9 -> Domo | E6: ='RESUMEN TOTAL'!F9 -> PTO A FO | F6: ='RESUMEN TOTAL'!M9 -> 0 | G6: ='RESUMEN TOTAL'!N9 -> 0 | H6: ='RESUMEN TOTAL'!O9 -> 0 | I6: ='RESUMEN TOTAL'!P9 -> 0 | J6: ='RESUMEN TOTAL'!Q9 -> 0 | K6: ='RESUMEN TOTAL'!R9 -> 0 | L6: ='RESUMEN TOTAL'!S9 -> 0 | M6: ='RESUMEN TOTAL'!T9 -> 0 | ... AJ6: ='RESUMEN TOTAL'!AQ9 -> 0
A7: ='RESUMEN TOTAL'!A10 -> ALTAMIRA | B7: ='RESUMEN TOTAL'!B10 -> ALT 03 | C7: ='RESUMEN TOTAL'!D10 -> Bombero Galarza y Necochea | D7: ='RESUMEN TOTAL'!E10 -> Domo | E7: ='RESUMEN TOTAL'!F10 -> GPON | F7: ='RESUMEN TOTAL'!M10 -> 0 | G7: ='RESUMEN TOTAL'!N10 -> 0 | H7: ='RESUMEN TOTAL'!O10 -> 0 | I7: ='RESUMEN TOTAL'!P10 -> 0 | J7: ='RESUMEN TOTAL'!Q10 -> 0 | K7: ='RESUMEN TOTAL'!R10 -> 0 | L7: ='RESUMEN TOTAL'!S10 -> 0 | M7: ='RESUMEN TOTAL'!T10 -> 0 | ... AJ7: ='RESUMEN TOTAL'!AQ10 -> 0
A8: ='RESUMEN TOTAL'!A11 -> ALTAMIRA | B8: ='RESUMEN TOTAL'!B11 -> ALT 04 | C8: ='RESUMEN TOTAL'!D11 -> Francia y Necochea | D8: ='RESUMEN TOTAL'!E11 -> Domo | E8: ='RESUMEN TOTAL'!F11 -> GPON | F8: ='RESUMEN TOTAL'!M11 -> 0 | G8: ='RESUMEN TOTAL'!N11 -> 0 | H8: ='RESUMEN TOTAL'!O11 -> 0 | I8: ='RESUMEN TOTAL'!P11 -> 0 | J8: ='RESUMEN TOTAL'!Q11 -> 0 | K8: ='RESUMEN TOTAL'!R11 -> 0 | L8: ='RESUMEN TOTAL'!S11 -> 0 | M8: ='RESUMEN TOTAL'!T11 -> 0 | ... AJ8: ='RESUMEN TOTAL'!AQ11 -> 0
A9: ='RESUMEN TOTAL'!A12 -> ALTAMIRA | B9: ='RESUMEN TOTAL'!B12 -> ALT05 | C9: ='RESUMEN TOTAL'!D12 -> Av. Calchaqui y Bombero Galarza | D9: ='RESUMEN TOTAL'!E12 -> Domo | E9: ='RESUMEN TOTAL'!F12 -> GPON | F9: ='RESUMEN TOTAL'!M12 -> 0 | G9: ='RESUMEN TOTAL'!N12 -> 0 | H9: ='RESUMEN TOTAL'!O12 -> 0 | I9: ='RESUMEN TOTAL'!P12 -> 0 | J9: ='RESUMEN TOTAL'!Q12 -> 0 | K9: ='RESUMEN TOTAL'!R12 -> 0 | L9: ='RESUMEN TOTAL'!S12 -> 0 | M9: ='RESUMEN TOTAL'!T12 -> 0 | ... AJ9: ='RESUMEN TOTAL'!AQ12 -> 0
A10: ='RESUMEN TOTAL'!A13 -> ALTAMIRA | B10: ='RESUMEN TOTAL'!B13 -> ALT 06 | C10: ='RESUMEN TOTAL'!D13 -> LOPE DE VEGA Y NECOCHEA | D10: ='RESUMEN TOTAL'!E13 -> Domo | E10: ='RESUMEN TOTAL'!F13 -> GPON | F10: ='RESUMEN TOTAL'!M13 -> 0 | G10: ='RESUMEN TOTAL'!N13 -> 0 | H10: ='RESUMEN TOTAL'!O13 -> 0 | I10: ='RESUMEN TOTAL'!P13 -> 0 | J10: ='RESUMEN TOTAL'!Q13 -> 0 | K10: ='RESUMEN TOTAL'!R13 -> 0 | L10: ='RESUMEN TOTAL'!S13 -> 0 | M10: ='RESUMEN TOTAL'!T13 -> 0 | ... AJ10: ='RESUMEN TOTAL'!AQ13 -> 0
A11: ='RESUMEN TOTAL'!A14 -> ALTAMIRA | B11: ='RESUMEN TOTAL'!B14 -> ALT07 | C11: ='RESUMEN TOTAL'!D14 -> AV. CALCHAQUI Y AV. DEL TRABAJO | D11: ='RESUMEN TOTAL'!E14 -> DOMO | E11: ='RESUMEN TOTAL'!F14 -> PTO A FO | F11: ='RESUMEN TOTAL'!M14 -> 0 | G11: ='RESUMEN TOTAL'!N14 -> 0 | H11: ='RESUMEN TOTAL'!O14 -> 0 | I11: ='RESUMEN TOTAL'!P14 -> 0 | J11: ='RESUMEN TOTAL'!Q14 -> 0 | K11: ='RESUMEN TOTAL'!R14 -> 0 | L11: ='RESUMEN TOTAL'!S14 -> 0 | M11: ='RESUMEN TOTAL'!T14 -> 0 | ... AJ11: ='RESUMEN TOTAL'!AQ14 -> 0
A12: ='RESUMEN TOTAL'!A15 -> ALTAMIRA | B12: ='RESUMEN TOTAL'!B15 -> ALT 08 | C12: ='RESUMEN TOTAL'!D15 -> HUMAITA Y NECOCHEA | D12: ='RESUMEN TOTAL'!E15 -> DOMO | E12: ='RESUMEN TOTAL'!F15 -> Fibra Optica | F12: ='RESUMEN TOTAL'!M15 -> 0 | G12: ='RESUMEN TOTAL'!N15 -> 0 | H12: ='RESUMEN TOTAL'!O15 -> 0 | I12: ='RESUMEN TOTAL'!P15 -> 0 | J12: ='RESUMEN TOTAL'!Q15 -> 0 | K12: ='RESUMEN TOTAL'!R15 -> 0 | L12: ='RESUMEN TOTAL'!S15 -> 0 | M12: ='RESUMEN TOTAL'!T15 -> 0 | ... AJ12: ='RESUMEN TOTAL'!AQ15 -> 0
A13: ='RESUMEN TOTAL'!A16 -> ALTAMIRA | B13: ='RESUMEN TOTAL'!B16 -> ALT 09 | C13: ='RESUMEN TOTAL'!D16 -> NECOCHEA Y CURUPAITY | D13: ='RESUMEN TOTAL'!E16 -> DOMO | E13: ='RESUMEN TOTAL'!F16 -> Fibra Optica | F13: ='RESUMEN TOTAL'!M16 -> 0 | G13: ='RESUMEN TOTAL'!N16 -> 0 | H13: ='RESUMEN TOTAL'!O16 -> 0 | I13: ='RESUMEN TOTAL'!P16 -> 0 | J13: ='RESUMEN TOTAL'!Q16 -> 0 | K13: ='RESUMEN TOTAL'!R16 -> 0 | L13: ='RESUMEN TOTAL'!S16 -> 0 | M13: ='RESUMEN TOTAL'!T16 -> 0 | ... AJ13: ='RESUMEN TOTAL'!AQ16 -> 0
A14: ='RESUMEN TOTAL'!A17 -> ALTAMIRA | B14: ='RESUMEN TOTAL'!B17 -> ALT 10 | C14: ='RESUMEN TOTAL'!D17 -> Calchaqui y Francia | D14: ='RESUMEN TOTAL'!E17 -> Domo | E14: ='RESUMEN TOTAL'!F17 -> GPON | F14: ='RESUMEN TOTAL'!M17 -> 0 | G14: ='RESUMEN TOTAL'!N17 -> 0 | H14: ='RESUMEN TOTAL'!O17 -> 0 | I14: ='RESUMEN TOTAL'!P17 -> 0 | J14: ='RESUMEN TOTAL'!Q17 -> 0 | K14: ='RESUMEN TOTAL'!R17 -> 0 | L14: ='RESUMEN TOTAL'!S17 -> 0 | M14: ='RESUMEN TOTAL'!T17 -> 0 | ... AJ14: ='RESUMEN TOTAL'!AQ17 -> 0
A15: ='RESUMEN TOTAL'!A18 -> ALTAMIRA | B15: ='RESUMEN TOTAL'!B18 -> ALT 11 | C15: CALCHAQUÍ Y GALARZA FIJA | D15: ='RESUMEN TOTAL'!E18 -> Fija | F15: ='RESUMEN TOTAL'!M18 -> 0 | G15: ='RESUMEN TOTAL'!N18 -> 0 | H15: ='RESUMEN TOTAL'!O18 -> 0 | I15: ='RESUMEN TOTAL'!P18 -> 0 | J15: ='RESUMEN TOTAL'!Q18 -> 0 | K15: ='RESUMEN TOTAL'!R18 -> 0 | L15: ='RESUMEN TOTAL'!S18 -> 0 | M15: ='RESUMEN TOTAL'!T18 -> 0 | ... AJ15: ='RESUMEN TOTAL'!AQ18 -> 0
A16: ='RESUMEN TOTAL'!A19 -> AGUSTIN RAMIREZ | B16: ='RESUMEN TOTAL'!B19 -> ARA 01 | C16: ='RESUMEN TOTAL'!D19 -> Malambo y Tranquera | D16: ='RESUMEN TOTAL'!E19 -> Domo | E16: ='RESUMEN TOTAL'!F19 -> Fibra Optica | F16: ='RESUMEN TOTAL'!M19 -> 0 | G16: ='RESUMEN TOTAL'!N19 -> 0 | H16: ='RESUMEN TOTAL'!O19 -> 0 | I16: ='RESUMEN TOTAL'!P19 -> 0 | J16: ='RESUMEN TOTAL'!Q19 -> 0 | K16: ='RESUMEN TOTAL'!R19 -> 0 | L16: ='RESUMEN TOTAL'!S19 -> 0 | M16: ='RESUMEN TOTAL'!T19 -> 0 | ... AJ16: ='RESUMEN TOTAL'!AQ19 -> 0
A17: ='RESUMEN TOTAL'!A22 -> BELGRANO | B17: ='RESUMEN TOTAL'!B22 -> BEL 01 | C17: ='RESUMEN TOTAL'!D22 -> San Martin y Dardo Rocha | D17: ='RESUMEN TOTAL'!E22 -> DOMO | E17: ='RESUMEN TOTAL'!F22 -> Fibra Optica | F17: ='RESUMEN TOTAL'!M22 -> 0 | G17: ='RESUMEN TOTAL'!N22 -> 0 | H17: ='RESUMEN TOTAL'!O22 -> 0 | I17: ='RESUMEN TOTAL'!P22 -> 0 | J17: ='RESUMEN TOTAL'!Q22 -> 0 | K17: ='RESUMEN TOTAL'!R22 -> 0 | L17: ='RESUMEN TOTAL'!S22 -> 0 | M17: ='RESUMEN TOTAL'!T22 -> 0 | ... AJ17: ='RESUMEN TOTAL'!AQ22 -> 0
A18: ='RESUMEN TOTAL'!A23 -> BELGRANO | B18: ='RESUMEN TOTAL'!B23 -> BEL 02 | C18: ='RESUMEN TOTAL'!D23 -> Guardia vieja y Fronteriz | D18: ='RESUMEN TOTAL'!E23 -> DOMO | E18: ='RESUMEN TOTAL'!F23 -> Fibra Optica | F18: ='RESUMEN TOTAL'!M23 -> 0 | G18: ='RESUMEN TOTAL'!N23 -> 0 | H18: ='RESUMEN TOTAL'!O23 -> 0 | I18: ='RESUMEN TOTAL'!P23 -> 0 | J18: ='RESUMEN TOTAL'!Q23 -> 0 | K18: ='RESUMEN TOTAL'!R23 -> 0 | L18: ='RESUMEN TOTAL'!S23 -> 0 | M18: ='RESUMEN TOTAL'!T23 -> 0 | ... AJ18: ='RESUMEN TOTAL'!AQ23 -> 0
A19: ='RESUMEN TOTAL'!A24 -> BOSQUES CENTRO | B19: ='RESUMEN TOTAL'!B24 -> BOSQC 01 | C19: ='RESUMEN TOTAL'!D24 -> LUIS AGOTE E/DANUNCIO Y CAMPOAMOR | D19: ='RESUMEN TOTAL'!E24 -> Fija | E19: ='RESUMEN TOTAL'!F24 -> PTO A FO | F19: ='RESUMEN TOTAL'!M24 -> 0 | G19: ='RESUMEN TOTAL'!N24 -> 0 | H19: ='RESUMEN TOTAL'!O24 -> 0 | I19: ='RESUMEN TOTAL'!P24 -> 0 | J19: ='RESUMEN TOTAL'!Q24 -> 0 | K19: ='RESUMEN TOTAL'!R24 -> 0 | L19: ='RESUMEN TOTAL'!S24 -> 0 | M19: ='RESUMEN TOTAL'!T24 -> 0 | ... AJ19: ='RESUMEN TOTAL'!AQ24 -> 0
A20: ='RESUMEN TOTAL'!A25 -> BOSQUES CENTRO | B20: ='RESUMEN TOTAL'!B25 -> BOSQC 02 | C20: ='RESUMEN TOTAL'!D25 -> LUIS AGOTE E/DANUNCIO Y CAMPOAMOR | D20: ='RESUMEN TOTAL'!E25 -> Fija | E20: ='RESUMEN TOTAL'!F25 -> PTO A FO | F20: ='RESUMEN TOTAL'!M25 -> 0 | G20: ='RESUMEN TOTAL'!N25 -> 0 | H20: ='RESUMEN TOTAL'!O25 -> 0 | I20: ='RESUMEN TOTAL'!P25 -> 0 | J20: ='RESUMEN TOTAL'!Q25 -> 0 | K20: ='RESUMEN TOTAL'!R25 -> 0 | L20: ='RESUMEN TOTAL'!S25 -> 0 | M20: ='RESUMEN TOTAL'!T25 -> 0 | ... AJ20: ='RESUMEN TOTAL'!AQ25 -> 0
A21: ='RESUMEN TOTAL'!A26 -> BOSQUES CENTRO | B21: ='RESUMEN TOTAL'!B26 -> BOSQC 03 | C21: ='RESUMEN TOTAL'!D26 -> BENAVENTE Y LUIS AGOTE | D21: ='RESUMEN TOTAL'!E26 -> Fija | E21: ='RESUMEN TOTAL'!F26 -> PTO A FO | F21: ='RESUMEN TOTAL'!M26 -> 0 | G21: ='RESUMEN TOTAL'!N26 -> 0 | H21: ='RESUMEN TOTAL'!O26 -> 0 | I21: ='RESUMEN TOTAL'!P26 -> 0 | J21: ='RESUMEN TOTAL'!Q26 -> 0 | K21: ='RESUMEN TOTAL'!R26 -> 0 | L21: ='RESUMEN TOTAL'!S26 -> 0 | M21: ='RESUMEN TOTAL'!T26 -> 0 | ... AJ21: ='RESUMEN TOTAL'!AQ26 -> 0
A22: ='RESUMEN TOTAL'!A27 -> BOSQUES CENTRO | B22: ='RESUMEN TOTAL'!B27 -> BOSQC 04 | C22: ='RESUMEN TOTAL'!D27 -> BENAVENTE Y LUIS AGOTE | D22: ='RESUMEN TOTAL'!E27 -> Fija | E22: ='RESUMEN TOTAL'!F27 -> PTO A FO | F22: ='RESUMEN TOTAL'!M27 -> 0 | G22: ='RESUMEN TOTAL'!N27 -> 0 | H22: ='RESUMEN TOTAL'!O27 -> 0 | I22: ='RESUMEN TOTAL'!P27 -> 0 | J22: ='RESUMEN TOTAL'!Q27 -> 0 | K22: ='RESUMEN TOTAL'!R27 -> 0 | L22: ='RESUMEN TOTAL'!S27 -> 0 | M22: ='RESUMEN TOTAL'!T27 -> 0 | ... AJ22: ='RESUMEN TOTAL'!AQ27 -> 0
A23: ='RESUMEN TOTAL'!A28 -> BOSQUES CENTRO | B23: ='RESUMEN TOTAL'!B28 -> BOSQC 05 | C23: ='RESUMEN TOTAL'!D28 -> LUIS AGOTE Y RUTA 36 | D23: ='RESUMEN TOTAL'!E28 -> Fija | E23: ='RESUMEN TOTAL'!F28 -> PTO A FO | F23: ='RESUMEN TOTAL'!M28 -> 0 | G23: ='RESUMEN TOTAL'!N28 -> 0 | H23: ='RESUMEN TOTAL'!O28 -> 0 | I23: ='RESUMEN TOTAL'!P28 -> 0 | J23: ='RESUMEN TOTAL'!Q28 -> 0 | K23: ='RESUMEN TOTAL'!R28 -> 0 | L23: ='RESUMEN TOTAL'!S28 -> 0 | M23: ='RESUMEN TOTAL'!T28 -> 0 | ... AJ23: ='RESUMEN TOTAL'!AQ28 -> 0
A24: ='RESUMEN TOTAL'!A29 -> BOSQUES CENTRO | B24: ='RESUMEN TOTAL'!B29 -> BOSQC 06 | C24: ='RESUMEN TOTAL'!D29 -> LUIS AGOTE Y RUTA 36 | D24: ='RESUMEN TOTAL'!E29 -> Fija | E24: ='RESUMEN TOTAL'!F29 -> PTO A FO | F24: ='RESUMEN TOTAL'!M29 -> 0 | G24: ='RESUMEN TOTAL'!N29 -> 0 | H24: ='RESUMEN TOTAL'!O29 -> 0 | I24: ='RESUMEN TOTAL'!P29 -> 0 | J24: ='RESUMEN TOTAL'!Q29 -> 0 | K24: ='RESUMEN TOTAL'!R29 -> 0 | L24: ='RESUMEN TOTAL'!S29 -> 0 | M24: ='RESUMEN TOTAL'!T29 -> 0 | ... AJ24: ='RESUMEN TOTAL'!AQ29 -> 0
A25: ='RESUMEN TOTAL'!A46 -> CENTRO | B25: ='RESUMEN TOTAL'!B46 -> CEN01 | C25: ='RESUMEN TOTAL'!D46 -> San Martin y 9 de Julio | D25: ='RESUMEN TOTAL'!E46 -> Fija | E25: ='RESUMEN TOTAL'!F46 -> Fibra Optica | F25: ='RESUMEN TOTAL'!M46 -> 0 | G25: ='RESUMEN TOTAL'!N46 -> 0 | H25: ='RESUMEN TOTAL'!O46 -> 0 | I25: ='RESUMEN TOTAL'!P46 -> 0 | J25: ='RESUMEN TOTAL'!Q46 -> 0 | K25: ='RESUMEN TOTAL'!R46 -> 0 | L25: ='RESUMEN TOTAL'!S46 -> 0 | M25: ='RESUMEN TOTAL'!T46 -> 0 | ... AJ25: ='RESUMEN TOTAL'!AQ46 -> 0
A26: ='RESUMEN TOTAL'!A47 -> CENTRO | B26: ='RESUMEN TOTAL'!B47 -> CEN02 | C26: ='RESUMEN TOTAL'!D47 -> San Martin y Almafuerte | D26: ='RESUMEN TOTAL'!E47 -> Fija | E26: ='RESUMEN TOTAL'!F47 -> Fibra Optica | F26: ='RESUMEN TOTAL'!M47 -> 0 | G26: ='RESUMEN TOTAL'!N47 -> 0 | H26: ='RESUMEN TOTAL'!O47 -> 0 | I26: ='RESUMEN TOTAL'!P47 -> 0 | J26: ='RESUMEN TOTAL'!Q47 -> 0 | K26: ='RESUMEN TOTAL'!R47 -> 0 | L26: ='RESUMEN TOTAL'!S47 -> 0 | M26: ='RESUMEN TOTAL'!T47 -> 0 | ... AJ26: ='RESUMEN TOTAL'!AQ47 -> 0
A27: ='RESUMEN TOTAL'!A48 -> CENTRO | B27: ='RESUMEN TOTAL'!B48 -> CEN03 | C27: ='RESUMEN TOTAL'!D48 -> San Martin y Sallares | D27: ='RESUMEN TOTAL'!E48 -> Domo | E27: ='RESUMEN TOTAL'!F48 -> Fibra Optica | F27: ='RESUMEN TOTAL'!M48 -> 0 | G27: ='RESUMEN TOTAL'!N48 -> 0 | H27: ='RESUMEN TOTAL'!O48 -> 0 | I27: ='RESUMEN TOTAL'!P48 -> 0 | J27: ='RESUMEN TOTAL'!Q48 -> 0 | K27: ='RESUMEN TOTAL'!R48 -> 0 | L27: ='RESUMEN TOTAL'!S48 -> 0 | M27: ='RESUMEN TOTAL'!T48 -> 0 | ... AJ27: ='RESUMEN TOTAL'!AQ48 -> 0
A28: ='RESUMEN TOTAL'!A49 -> CENTRO | B28: ='RESUMEN TOTAL'!B49 -> CEN04 | C28: ='RESUMEN TOTAL'!D49 -> San Martin y Contreras | D28: ='RESUMEN TOTAL'!E49 -> Domo | E28: ='RESUMEN TOTAL'!F49 -> Fibra Optica | F28: ='RESUMEN TOTAL'!M49 -> 0 | G28: ='RESUMEN TOTAL'!N49 -> 0 | H28: ='RESUMEN TOTAL'!O49 -> 0 | I28: ='RESUMEN TOTAL'!P49 -> 0 | J28: ='RESUMEN TOTAL'!Q49 -> 0 | K28: ='RESUMEN TOTAL'!R49 -> 0 | L28: ='RESUMEN TOTAL'!S49 -> 0 | M28: ='RESUMEN TOTAL'!T49 -> 0 | ... AJ28: ='RESUMEN TOTAL'!AQ49 -> 0
A29: ='RESUMEN TOTAL'!A50 -> CENTRO | B29: ='RESUMEN TOTAL'!B50 -> CEN 05 | C29: ='RESUMEN TOTAL'!D50 -> Bocuzzi e/España y San Martin | D29: ='RESUMEN TOTAL'!E50 -> DOMO | E29: ='RESUMEN TOTAL'!F50 -> Fibra Optica | F29: ='RESUMEN TOTAL'!M50 -> 0 | G29: ='RESUMEN TOTAL'!N50 -> 0 | H29: ='RESUMEN TOTAL'!O50 -> 0 | I29: ='RESUMEN TOTAL'!P50 -> 0 | J29: ='RESUMEN TOTAL'!Q50 -> 0 | K29: ='RESUMEN TOTAL'!R50 -> 0 | L29: ='RESUMEN TOTAL'!S50 -> 0 | M29: ='RESUMEN TOTAL'!T50 -> 0 | ... AJ29: ='RESUMEN TOTAL'!AQ50 -> 0
A30: ='RESUMEN TOTAL'!A51 -> CENTRO | B30: ='RESUMEN TOTAL'!B51 -> CEN06 | C30: ='RESUMEN TOTAL'!D51 -> Monteagudo y A.del Valle | D30: ='RESUMEN TOTAL'!E51 -> Fija | E30: ='RESUMEN TOTAL'!F51 -> Fibra Optica | F30: ='RESUMEN TOTAL'!M51 -> 0 | G30: ='RESUMEN TOTAL'!N51 -> 0 | H30: ='RESUMEN TOTAL'!O51 -> 0 | I30: ='RESUMEN TOTAL'!P51 -> 0 | J30: ='RESUMEN TOTAL'!Q51 -> 0 | K30: ='RESUMEN TOTAL'!R51 -> 0 | L30: ='RESUMEN TOTAL'!S51 -> 0 | M30: ='RESUMEN TOTAL'!T51 -> 0 | ... AJ30: ='RESUMEN TOTAL'!AQ51 -> 0
A31: ='RESUMEN TOTAL'!A52 -> CENTRO | B31: ='RESUMEN TOTAL'!B52 -> CEN07 | C31: ='RESUMEN TOTAL'!D52 -> San Martin y Guemes | D31: ='RESUMEN TOTAL'!E52 -> DOMO | E31: ='RESUMEN TOTAL'!F52 -> Fibra Optica | F31: ='RESUMEN TOTAL'!M52 -> 0 | G31: ='RESUMEN TOTAL'!N52 -> 0 | H31: ='RESUMEN TOTAL'!O52 -> 0 | I31: ='RESUMEN TOTAL'!P52 -> 0 | J31: ='RESUMEN TOTAL'!Q52 -> 0 | K31: ='RESUMEN TOTAL'!R52 -> 0 | L31: ='RESUMEN TOTAL'!S52 -> 0 | M31: ='RESUMEN TOTAL'!T52 -> 0 | ... AJ31: ='RESUMEN TOTAL'!AQ52 -> 0
A32: ='RESUMEN TOTAL'!A53 -> CENTRO | B32: ='RESUMEN TOTAL'!B53 -> CEN08 | C32: ='RESUMEN TOTAL'!D53 -> San Martin y Pte.Peron | D32: ='RESUMEN TOTAL'!E53 -> Domo | E32: ='RESUMEN TOTAL'!F53 -> Fibra Optica | F32: ='RESUMEN TOTAL'!M53 -> 0 | G32: ='RESUMEN TOTAL'!N53 -> 0 | H32: ='RESUMEN TOTAL'!O53 -> 0 | I32: ='RESUMEN TOTAL'!P53 -> 0 | J32: ='RESUMEN TOTAL'!Q53 -> 0 | K32: ='RESUMEN TOTAL'!R53 -> 0 | L32: ='RESUMEN TOTAL'!S53 -> 0 | M32: ='RESUMEN TOTAL'!T53 -> 0 | ... AJ32: ='RESUMEN TOTAL'!AQ53 -> 0
A33: ='RESUMEN TOTAL'!A54 -> CENTRO | B33: ='RESUMEN TOTAL'!B54 -> CEN09 | C33: ='RESUMEN TOTAL'!D54 -> Chacabuco y 25 de Mayo | D33: ='RESUMEN TOTAL'!E54 -> Domo | E33: ='RESUMEN TOTAL'!F54 -> Fibra Optica | F33: ='RESUMEN TOTAL'!M54 -> 0 | G33: ='RESUMEN TOTAL'!N54 -> 0 | H33: ='RESUMEN TOTAL'!O54 -> 0 | I33: ='RESUMEN TOTAL'!P54 -> 0 | J33: ='RESUMEN TOTAL'!Q54 -> 0 | K33: ='RESUMEN TOTAL'!R54 -> 0 | L33: ='RESUMEN TOTAL'!S54 -> 0 | M33: ='RESUMEN TOTAL'!T54 -> 0 | ... AJ33: ='RESUMEN TOTAL'!AQ54 -> 0
A34: ='RESUMEN TOTAL'!A55 -> CENTRO | B34: ='RESUMEN TOTAL'!B55 -> CEN10 | C34: ='RESUMEN TOTAL'!D55 -> Monteagudo y Pte. Peron | D34: ='RESUMEN TOTAL'!E55 -> Domo | E34: ='RESUMEN TOTAL'!F55 -> Fibra Optica | F34: ='RESUMEN TOTAL'!M55 -> 0 | G34: ='RESUMEN TOTAL'!N55 -> 0 | H34: ='RESUMEN TOTAL'!O55 -> 0 | I34: ='RESUMEN TOTAL'!P55 -> 0 | J34: ='RESUMEN TOTAL'!Q55 -> 0 | K34: ='RESUMEN TOTAL'!R55 -> 0 | L34: ='RESUMEN TOTAL'!S55 -> 0 | M34: ='RESUMEN TOTAL'!T55 -> 0 | ... AJ34: ='RESUMEN TOTAL'!AQ55 -> 0
A35: ='RESUMEN TOTAL'!A56 -> CENTRO | B35: ='RESUMEN TOTAL'!B56 -> CEN11 | C35: ='RESUMEN TOTAL'!D56 -> Monteagudo y Bocuzzi | D35: ='RESUMEN TOTAL'!E56 -> Domo | E35: ='RESUMEN TOTAL'!F56 -> Fibra Optica | F35: ='RESUMEN TOTAL'!M56 -> 0 | G35: ='RESUMEN TOTAL'!N56 -> 0 | H35: ='RESUMEN TOTAL'!O56 -> 0 | I35: ='RESUMEN TOTAL'!P56 -> 0 | J35: ='RESUMEN TOTAL'!Q56 -> 0 | K35: ='RESUMEN TOTAL'!R56 -> 0 | L35: ='RESUMEN TOTAL'!S56 -> 0 | M35: ='RESUMEN TOTAL'!T56 -> 0 | ... AJ35: ='RESUMEN TOTAL'!AQ56 -> 0
A36: ='RESUMEN TOTAL'!A57 -> CENTRO | B36: ='RESUMEN TOTAL'!B57 -> CEN 12 | C36: ='RESUMEN TOTAL'!D57 -> Monteagudo y Mitre | D36: ='RESUMEN TOTAL'!E57 -> Domo | E36: ='RESUMEN TOTAL'!F57 -> Fibra Optica | F36: ='RESUMEN TOTAL'!M57 -> 0 | G36: ='RESUMEN TOTAL'!N57 -> 0 | H36: ='RESUMEN TOTAL'!O57 -> 0 | I36: ='RESUMEN TOTAL'!P57 -> 0 | J36: ='RESUMEN TOTAL'!Q57 -> 0 | K36: ='RESUMEN TOTAL'!R57 -> 0 | L36: ='RESUMEN TOTAL'!S57 -> 0 | M36: ='RESUMEN TOTAL'!T57 -> 0 | ... AJ36: ='RESUMEN TOTAL'!AQ57 -> 0
... A71: ='RESUMEN TOTAL'!A92 -> CENTRO | B71: ='RESUMEN TOTAL'!B92 -> CEN47 | C71: ='RESUMEN TOTAL'!D92 -> Sallares y Brown | D71: ='RESUMEN TOTAL'!E92 -> Domo | E71: ='RESUMEN TOTAL'!F92 -> Fibra Optica | F71: ='RESUMEN TOTAL'!M92 -> 0 | G71: ='RESUMEN TOTAL'!N92 -> 0 | H71: ='RESUMEN TOTAL'!O92 -> 0 | I71: ='RESUMEN TOTAL'!P92 -> 0 | J71: ='RESUMEN TOTAL'!Q92 -> 0 | K71: ='RESUMEN TOTAL'!R92 -> 0 | L71: ='RESUMEN TOTAL'!S92 -> 0 | M71: ='RESUMEN TOTAL'!T92 -> 0 | ... AJ71: ='RESUMEN TOTAL'!AQ92 -> 0
A72: ='RESUMEN TOTAL'!A93 -> CENTRO | B72: ='RESUMEN TOTAL'!B93 -> CEN48 | C72: ='RESUMEN TOTAL'!D93 -> Velez Sarsfield y Las Heras | D72: ='RESUMEN TOTAL'!E93 -> Domo | E72: ='RESUMEN TOTAL'!F93 -> GPON | F72: ='RESUMEN TOTAL'!M93 -> 0 | G72: ='RESUMEN TOTAL'!N93 -> 0 | H72: ='RESUMEN TOTAL'!O93 -> 0 | I72: ='RESUMEN TOTAL'!P93 -> 0 | J72: ='RESUMEN TOTAL'!Q93 -> 0 | K72: ='RESUMEN TOTAL'!R93 -> 0 | L72: ='RESUMEN TOTAL'!S93 -> 0 | M72: ='RESUMEN TOTAL'!T93 -> 0 | ... Z72: ='RESUMEN TOTAL'!AG93 -> 0 | AA72: ='RESUMEN TOTAL'!#REF! -> #REF! | AB72: ='RESUMEN TOTAL'!AI93 -> 0 | AC72: ='RESUMEN TOTAL'!AJ93 -> 0 | AD72: ='RESUMEN TOTAL'!AK93 -> 0 | AE72: ='RESUMEN TOTAL'!AL93 -> 0 | AF72: ='RESUMEN TOTAL'!AM93 -> 0 | AG72: ='RESUMEN TOTAL'!AN93 -> 0 | AH72: ='RESUMEN TOTAL'!AO93 -> 0 | AI72: ='RESUMEN TOTAL'!AP93 -> 0 | AJ72: ='RESUMEN TOTAL'!AQ93 -> 0
A73: ='RESUMEN TOTAL'!A94 -> CENTRO | B73: ='RESUMEN TOTAL'!B94 -> CEN49 | C73: ='RESUMEN TOTAL'!D94 -> Av. San Martin y Florencio Sanchez | D73: ='RESUMEN TOTAL'!E94 -> Domo | E73: ='RESUMEN TOTAL'!F94 -> Fibra Optica | F73: ='RESUMEN TOTAL'!M94 -> 0 | G73: ='RESUMEN TOTAL'!N94 -> 0 | H73: ='RESUMEN TOTAL'!O94 -> 0 | I73: ='RESUMEN TOTAL'!P94 -> 0 | J73: ='RESUMEN TOTAL'!Q94 -> 0 | K73: ='RESUMEN TOTAL'!R94 -> 0 | L73: ='RESUMEN TOTAL'!S94 -> 0 | M73: ='RESUMEN TOTAL'!T94 -> 0 | ... AJ73: ='RESUMEN TOTAL'!AQ94 -> 0
A74: ='RESUMEN TOTAL'!A95 -> CENTRO | B74: ='RESUMEN TOTAL'!B95 -> CEN 50 | C74: ='RESUMEN TOTAL'!D95 -> Av. San Martin y Newbery | D74: ='RESUMEN TOTAL'!E95 -> Domo | E74: ='RESUMEN TOTAL'!F95 -> GPON | F74: ='RESUMEN TOTAL'!M95 -> 0 | G74: ='RESUMEN TOTAL'!N95 -> 0 | H74: ='RESUMEN TOTAL'!O95 -> 0 | I74: ='RESUMEN TOTAL'!P95 -> 0 | J74: ='RESUMEN TOTAL'!Q95 -> 0 | K74: ='RESUMEN TOTAL'!R95 -> 0 | L74: ='RESUMEN TOTAL'!S95 -> 0 | M74: ='RESUMEN TOTAL'!T95 -> 0 | ... AJ74: ='RESUMEN TOTAL'!AQ95 -> 0
...

Sheet Hoja1
B1: CAMARAS | C1: 45992
A2: BONOMO | B2: =COUNTIFS('RESUMEN TOTAL'!C8:C580,"=BONOMO") -> 303 | C2: 0 | F2: 46023 | G2: 46024 | H2: 46025 | I2: 46026 | J2: 46027 | K2: 46028 | L2: 46029 | M2: 46030 | N2: 46031 | O2: 46032 | P2: 46033 | Q2: 46034 | R2: 46035 | S2: 46036 | T2: 46037 | U2: 46038 | V2: 46039 | W2: 46040 | X2: 46041 | Y2: 46042 | Z2: 46043 | AA2: 46044 | AB2: 46045 | AC2: 46046 | AD2: 46047 | AE2: 46048 | AF2: 46049 | AG2: 46050 | AH2: 46051 | AI2: 46052 | AJ2: 46053
C3: 0 | D3: BONOMO | E3: APAGADAS BONOMO | F3: 0 | G3: =COUNTIFS('RESUMEN TOTAL'!N8:N689,"=APAGADO",'RESUMEN TOTAL'!C8:C689,"=BONOMO") -> 0 | H3: 0 | I3: 0 | J3: =COUNTIFS('RESUMEN TOTAL'!Q8:Q689,"=APAGADO",'RESUMEN TOTAL'!C8:C689,"=BONOMO") -> 0 | K3: =COUNTIFS('RESUMEN TOTAL'!R8:R689,"=APAGADO",'RESUMEN TOTAL'!C8:C689,"=BONOMO") -> 0 | L3: 0 | M3: 0 | N3: =COUNTIFS('RESUMEN TOTAL'!U8:U689,"=APAGADO",'RESUMEN TOTAL'!C8:C689,"=BONOMO") -> 0 | O3: =COUNTIFS('RESUMEN TOTAL'!V8:V689,"=APAGADO",'RESUMEN TOTAL'!C8:C689,"=BONOMO") -> 0 | P3: =COUNTIFS('RESUMEN TOTAL'!W8:W689,"=APAGADO",'RESUMEN TOTAL'!C8:C689,"=BONOMO") -> 0 | Q3: =COUNTIFS('RESUMEN TOTAL'!X8:X689,"=APAGADO",'RESUMEN TOTAL'!C8:C689,"=BONOMO") -> 0 | R3: =COUNTIFS('RESUMEN TOTAL'!Y8:Y689,"=APAGADO",'RESUMEN TOTAL'!C8:C689,"=BONOMO") -> 0 | S3: =COUNTIFS('RESUMEN TOTAL'!Z8:Z689,"=APAGADO",'RESUMEN TOTAL'!C8:C689,"=BONOMO") -> 0 | T3: =COUNTIFS('RESUMEN TOTAL'!AA8:AA689,"=APAGADO",'RESUMEN TOTAL'!C8:C689,"=BONOMO") -> 0 | U3: =COUNTIFS('RESUMEN TOTAL'!AB8:AB689,"=APAGADO",'RESUMEN TOTAL'!C8:C689,"=BONOMO") -> 0 | V3: =COUNTIFS('RESUMEN TOTAL'!AC8:AC689,"=APAGADO",'RESUMEN TOTAL'!C8:C689,"=BONOMO") -> 0 | W3: 0 | X3: =COUNTIFS('RESUMEN TOTAL'!AE8:AE689,"=APAGADO",'RESUMEN TOTAL'!C8:C689,"=BONOMO") -> 0 | Y3: =COUNTIFS('RESUMEN TOTAL'!AF8:AF689,"=APAGADO",'RESUMEN TOTAL'!C8:C689,"=BONOMO") -> 0 | Z3: =COUNTIFS('RESUMEN TOTAL'!AG8:AG689,"=APAGADO",'RESUMEN TOTAL'!C8:C689,"=BONOMO") -> 0 | AA3: =COUNTIFS('RESUMEN TOTAL'!AH8:AH689,"=APAGADO",'RESUMEN TOTAL'!C8:C689,"=BONOMO") -> 0 | AB3: =COUNTIFS('RESUMEN TOTAL'!AI8:AI689,"=APAGADO",'RESUMEN TOTAL'!C8:C689,"=BONOMO") -> 0 | AC3: =COUNTIFS('RESUMEN TOTAL'!AJ8:AJ689,"=APAGADO",'RESUMEN TOTAL'!C8:C689,"=BONOMO") -> 0 | AD3: =COUNTIFS('RESUMEN TOTAL'!AK8:AK689,"=APAGADO",'RESUMEN TOTAL'!C8:C689,"=BONOMO") -> 0 | AE3: 0 | AF3: =COUNTIFS('RESUMEN TOTAL'!AM8:AM689,"=APAGADO",'RESUMEN TOTAL'!C8:C689,"=BONOMO") -> 0 | AG3: =COUNTIFS('RESUMEN TOTAL'!AN8:AN689,"=APAGADO",'RESUMEN TOTAL'!C8:C689,"=BONOMO") -> 0 | AH3: =COUNTIFS('RESUMEN TOTAL'!AO8:AO689,"=APAGADO",'RESUMEN TOTAL'!C8:C689,"=BONOMO") -> 0 | AI3: 0 | AJ3: 0
A4: COSEIDI | B4: =COUNTIFS('RESUMEN TOTAL'!C8:C580,"=COSEIDI") -> 270 | C4: 0 | E4: % BONOMO | F4: 0 | G4: =G3/BONOMOcam -> 0 | H4: =H3/BONOMOcam -> 0 | I4: =I3/BONOMOcam -> 0 | J4: 0 | K4: =K3/BONOMOcam -> 0 | L4: =L3/BONOMOcam -> 0 | M4: 0 | N4: =N3/BONOMOcam -> 0 | O4: =O3/BONOMOcam -> 0 | P4: =P3/BONOMOcam -> 0 | Q4: =Q3/BONOMOcam -> 0 | R4: =R3/BONOMOcam -> 0 | S4: =S3/BONOMOcam -> 0 | T4: =T3/BONOMOcam -> 0 | U4: =U3/BONOMOcam -> 0 | V4: =V3/BONOMOcam -> 0 | W4: 0 | X4: =X3/BONOMOcam -> 0 | Y4: =Y3/BONOMOcam -> 0 | Z4: =Z3/BONOMOcam -> 0 | AA4: =AA3/BONOMOcam -> 0 | AB4: =AB3/BONOMOcam -> 0 | AC4: 0 | AD4: =AD3/BONOMOcam -> 0 | AE4: =AE3/BONOMOcam -> 0 | AF4: =AF3/BONOMOcam -> 0 | AG4: =AG3/BONOMOcam -> 0 | AH4: =AH3/BONOMOcam -> 0 | AI4: 0 | AJ4: 0
C5: 0 | D5: COSEIDI | E5: APAGADAS COSEIDI | F5: =COUNTIFS('RESUMEN TOTAL'!M8:M691,"=APAGADO",'RESUMEN TOTAL'!C8:C691,"=COSEIDI") -> 0 | G5: =COUNTIFS('RESUMEN TOTAL'!N8:N689,"=APAGADO",'RESUMEN TOTAL'!C8:C689,"=COSEIDI") -> 0 | H5: 0 | I5: =COUNTIFS('RESUMEN TOTAL'!P10:P691,"=APAGADO",'RESUMEN TOTAL'!C10:C691,"=COSEIDI") -> 0 | J5: =COUNTIFS('RESUMEN TOTAL'!Q10:Q691,"=APAGADO",'RESUMEN TOTAL'!C10:C691,"=COSEIDI") -> 0 | K5: =COUNTIFS('RESUMEN TOTAL'!R10:R691,"=APAGADO",'RESUMEN TOTAL'!C10:C691,"=COSEIDI") -> 0 | L5: =COUNTIFS('RESUMEN TOTAL'!S10:S691,"=APAGADO",'RESUMEN TOTAL'!C10:C691,"=COSEIDI") -> 0 | M5: 0 | N5: =COUNTIFS('RESUMEN TOTAL'!U10:U691,"=APAGADO",'RESUMEN TOTAL'!C10:C691,"=COSEIDI") -> 0 | O5: 0 | P5: =COUNTIFS('RESUMEN TOTAL'!W10:W691,"=APAGADO",'RESUMEN TOTAL'!C10:C691,"=COSEIDI") -> 0 | Q5: =COUNTIFS('RESUMEN TOTAL'!X10:X691,"=APAGADO",'RESUMEN TOTAL'!C10:C691,"=COSEIDI") -> 0 | R5: =COUNTIFS('RESUMEN TOTAL'!Y10:Y691,"=APAGADO",'RESUMEN TOTAL'!C10:C691,"=COSEIDI") -> 0 | S5: =COUNTIFS('RESUMEN TOTAL'!Z10:Z691,"=APAGADO",'RESUMEN TOTAL'!C10:C691,"=COSEIDI") -> 0 | T5: 0 | U5: 0 | V5: =COUNTIFS('RESUMEN TOTAL'!AC10:AC691,"=APAGADO",'RESUMEN TOTAL'!C10:C691,"=COSEIDI") -> 0 | W5: =COUNTIFS('RESUMEN TOTAL'!AD10:AD691,"=APAGADO",'RESUMEN TOTAL'!C10:C691,"=COSEIDI") -> 0 | X5: =COUNTIFS('RESUMEN TOTAL'!AE10:AE691,"=APAGADO",'RESUMEN TOTAL'!C10:C691,"=COSEIDI") -> 0 | Y5: =COUNTIFS('RESUMEN TOTAL'!AF10:AF691,"=APAGADO",'RESUMEN TOTAL'!C10:C691,"=COSEIDI") -> 0 | Z5: =COUNTIFS('RESUMEN TOTAL'!AG10:AG691,"=APAGADO",'RESUMEN TOTAL'!C10:C691,"=COSEIDI") -> 0 | AA5: =COUNTIFS('RESUMEN TOTAL'!AH10:AH691,"=APAGADO",'RESUMEN TOTAL'!C10:C691,"=COSEIDI") -> 0 | AB5: =COUNTIFS('RESUMEN TOTAL'!AI10:AI691,"=APAGADO",'RESUMEN TOTAL'!C10:C691,"=COSEIDI") -> 0 | AC5: =COUNTIFS('RESUMEN TOTAL'!AJ10:AJ691,"=APAGADO",'RESUMEN TOTAL'!C10:C691,"=COSEIDI") -> 0 | AD5: =COUNTIFS('RESUMEN TOTAL'!AK10:AK691,"=APAGADO",'RESUMEN TOTAL'!C10:C691,"=COSEIDI") -> 0 | AE5: =COUNTIFS('RESUMEN TOTAL'!AL10:AL691,"=APAGADO",'RESUMEN TOTAL'!C10:C691,"=COSEIDI") -> 0 | AF5: =COUNTIFS('RESUMEN TOTAL'!AM10:AM691,"=APAGADO",'RESUMEN TOTAL'!C10:C691,"=COSEIDI") -> 0 | AG5: 0 | AH5: =COUNTIFS('RESUMEN TOTAL'!AO10:AO691,"=APAGADO",'RESUMEN TOTAL'!C10:C691,"=COSEIDI") -> 0 | AI5: 0 | AJ5: 0
E6: % COSEIDI | F6: 0 | G6: =G5/COSEIDIcam -> 0 | H6: 0 | I6: 0 | J6: 0 | K6: =K5/COSEIDIcam -> 0 | L6: =L5/COSEIDIcam -> 0 | M6: 0 | N6: =N5/COSEIDIcam -> 0 | O6: 0 | P6: 0 | Q6: =Q5/COSEIDIcam -> 0 | R6: =R5/COSEIDIcam -> 0 | S6: =S5/COSEIDIcam -> 0 | T6: 0 | U6: 0 | V6: 0 | W6: =W5/COSEIDIcam -> 0 | X6: =X5/COSEIDIcam -> 0 | Y6: =Y5/COSEIDIcam -> 0 | Z6: =Z5/COSEIDIcam -> 0 | AA6: =AA5/COSEIDIcam -> 0 | AB6: =AB5/COSEIDIcam -> 0 | AC6: 0 | AD6: =AD5/COSEIDIcam -> 0 | AE6: =AE5/COSEIDIcam -> 0 | AF6: =AF5/COSEIDIcam -> 0 | AG6: 0 | AH6: =AH5/COSEIDIcam -> 0 | AI6: 0 | AJ6: 0
