Workbook
Name _25_de_agosto: 'RESUMEN TOTAL'!$A$7:$D$498
Name _25_de_agosto_3: 'RESUMEN TOTAL'!$A$7:$D$510
Name _30_mar: #REF!
Name BONOMOcam: Hoja1!$B$2
Name CANTIDAD_DE_CAMARAS: 'RESUMEN TOTAL'!$B$1
Name COSEIDIcam: Hoja1!$B$4

Sheet RESUMEN TOTAL
A1: CANTIDAD DE CAMARAS | B1: =COUNTA(B8:B744) -> 584 | D1: PORCIENTO DE CAIDAS | N1: =(N3)/(N2+N3) -> 0.12048193 | O1: =(O3)/(O2+O3) -> 0.12965723 | P1: =(P3)/(P2+P3) -> 0.12443778 | Q1: =(Q3)/(Q2+Q3) -> 0.12705531 | R1: =(R3)/(R2+R3) -> 0.12705531 | S1: =(S3)/(S2+S3) -> 0.14369501 | T1: =(T3)/(T2+T3) -> 0.11915535 | U1: =(U3)/(U2+U3) -> 0 | ... Z1: =(Z3)/(Z2+Z3) -> 0.098765432 | AB1: =(AB3)/(AB2+AB3) -> 0 | AC1: =(AC3)/(AC2+AC3) -> 0.10703364 | AD1: =(AD3)/(AD2+AD3) -> 0.10429448 | AE1: =(AE3)/(AE2+AE3) -> 0 | AF1: =(AF3)/(AF2+AF3) -> 0 | AG1: =(AG3)/(AG2+AG3) -> 0 | AH1: =(AH3)/(AH2+AH3) -> 0 | AI1: =(AI3)/(AI2+AI3) -> 0 | ... AR1: =(AR3)/(AR2+AR3) -> 0
D2: FUNCIONAN | N2: =CANTIDAD_DE_CAMARAS -> 584 | O2: =CANTIDAD_DE_CAMARAS -> 584 | P2: =CANTIDAD_DE_CAMARAS -> 584 | Q2: =CANTIDAD_DE_CAMARAS -> 584 | R2: =CANTIDAD_DE_CAMARAS -> 584 | S2: =CANTIDAD_DE_CAMARAS -> 584 | T2: =CANTIDAD_DE_CAMARAS -> 584 | U2: =CANTIDAD_DE_CAMARAS -> 584 | ... AR2: =CANTIDAD_DE_CAMARAS -> 584
D3: CAIDAS | N3: =COUNTIF(N7:N744, "apagado") -> 80 | O3: =COUNTIF(O7:O744, "apagado") -> 87 | P3: =COUNTIF(P7:P744, "apagado") -> 83 | Q3: =COUNTIF(Q7:Q744, "apagado") -> 85 | R3: =COUNTIF(R7:R744, "apagado") -> 85 | S3: =COUNTIF(S7:S744, "apagado") -> 98 | T3: =COUNTIF(T7:T744, "apagado") -> 79 | U3: =COUNTIF(U7:U744, "apagado") -> 0 | ... AR3: =COUNTIF(AR7:AR744, "apagado") -> 0
D4: APAGADOS FIBRA | N4: =COUNTIFS(N8:N698, "=APAGADO",F8:F698,"=Fibra Optica") -> 37 | O4: =COUNTIFS(O8:O698, "=APAGADO",F8:F698,"=Fibra Optica") -> 39 | P4: =COUNTIFS(P8:P698, "=APAGADO",F8:F698,"=Fibra Optica") -> 37 | Q4: =COUNTIFS(Q8:Q698, "=APAGADO",F8:F698,"=Fibra Optica") -> 42 | R4: =COUNTIFS(R8:R698, "=APAGADO",F8:F698,"=Fibra Optica") -> 38 | S4: =COUNTIFS(S8:S698, "=APAGADO",F8:F698,"=Fibra Optica") -> 53 | T4: =COUNTIFS(T8:T698, "=APAGADO",F8:F698,"=Fibra Optica") -> 39 | U4: =COUNTIFS(U8:U698, "=APAGADO",F8:F698,"=Fibra Optica") -> 0 | V4: =COUNTIFS(V8:V698, "=APAGADO",F8:F698,"=Fibra Optica") -> 36 | W4: =COUNTIFS(W8:W698, "=APAGADO",F8:F698,"=Fibra Optica") -> 31 | X4: =COUNTIFS(X8:X698, "=APAGADO",F8:F698,"=Fibra Optica") -> 27 | Y4: =COUNTIFS(Y8:Y698, "=APAGADO",F8:F698,"=Fibra Optica") -> 32 | Z4: =COUNTIFS(Z8:Z698, "=APAGADO",F8:F698,"=Fibra Optica") -> 30 | AA4: =COUNTIFS(AA8:AA698, "=APAGADO",F8:F698,"=Fibra Optica") -> 0 | AB4: =COUNTIFS(AB8:AB698, "=APAGADO",F8:F698,"=Fibra Optica") -> 0 | AC4: =COUNTIFS(AC8:AC698, "=APAGADO",F8:F698,"=Fibra Optica") -> 32 | AD4: =COUNTIFS(AD8:AD698, "=APAGADO",F8:F698,"=Fibra Optica") -> 30 | AE4: =COUNTIFS(AE8:AE698, "=APAGADO",F8:F698,"=Fibra Optica") -> 0 | AF4: =COUNTIFS(AF8:AF698, "=APAGADO",F8:F698,"=Fibra Optica") -> 0 | AG4: =COUNTIFS(AG8:AG698, "=APAGADO",F8:F698,"=Fibra Optica") -> 0 | AH4: =COUNTIFS(AH8:AH698, "=APAGADO",F8:F698,"=Fibra Optica") -> 0 | AI4: =COUNTIFS(AI8:AI698, "=APAGADO",F8:F698,"=Fibra Optica") -> 0 | AJ4: =COUNTIFS(AJ8:AJ698, "=APAGADO",F8:F698,"=Fibra Optica") -> 0 | AK4: =COUNTIFS(AK8:AK698, "=APAGADO",F8:F698,"=Fibra Optica") -> 0 | AL4: =COUNTIFS(AL8:AL698, "=APAGADO",F8:F698,"=Fibra Optica") -> 0 | AM4: =COUNTIFS(AM8:AM698, "=APAGADO",F8:F698,"=Fibra Optica") -> 0 | AN4: =COUNTIFS(AN8:AN698, "=APAGADO",F8:F698,"=Fibra Optica") -> 0 | AO4: =COUNTIFS(AO8:AO698, "=APAGADO",F8:F698,"=Fibra Optica") -> 0 | AP4: =COUNTIFS(AP8:AP698, "=APAGADO",G8:G698,"=Fibra Optica") -> 0 | AQ4: =COUNTIFS(AQ8:AQ698, "=APAGADO",H8:H698,"=Fibra Optica") -> 0 | AR4: =COUNTIFS(AR8:AR698, "=APAGADO",J8:J698,"=Fibra Optica") -> 0
D5: APAGADOS RADIO | N5: =COUNTIFS(N8:N698, "=APAGADO",F8:F698,"=RADIO") -> 3 | O5: =COUNTIFS(O8:O698, "=APAGADO",F8:F698,"=RADIO") -> 5 | P5: =COUNTIFS(P8:P698, "=APAGADO",F8:F698,"=RADIO") -> 5 | Q5: =COUNTIFS(Q8:Q698, "=APAGADO",F8:F698,"=RADIO") -> 6 | R5: =COUNTIFS(R8:R698, "=APAGADO",F8:F698,"=RADIO") -> 6 | S5: =COUNTIFS(S8:S698, "=APAGADO",F8:F698,"=RADIO") -> 5 | T5: =COUNTIFS(T8:T698, "=APAGADO",F8:F698,"=RADIO") -> 4 | U5: =COUNTIFS(U8:U698, "=APAGADO",F8:F698,"=RADIO") -> 0 | V5: =COUNTIFS(V8:V698, "=APAGADO",F8:F698,"=RADIO") -> 5 | W5: =COUNTIFS(W8:W698, "=APAGADO",F8:F698,"=RADIO") -> 5 | X5: =COUNTIFS(X8:X698, "=APAGADO",F8:F698,"=RADIO") -> 5 | Y5: =COUNTIFS(Y8:Y698, "=APAGADO",F8:F698,"=RADIO") -> 4 | Z5: =COUNTIFS(Z8:Z698, "=APAGADO",F8:F698,"=RADIO") -> 5 | AA5: =COUNTIFS(AA8:AA698, "=APAGADO",F8:F698,"=RADIO") -> 0 | AB5: =COUNTIFS(AB8:AB698, "=APAGADO",F8:F698,"=RADIO") -> 0 | AC5: =COUNTIFS(AC8:AC698, "=APAGADO",F8:F698,"=RADIO") -> 5 | AD5: =COUNTIFS(AD8:AD698, "=APAGADO",F8:F698,"=RADIO") -> 8 | AE5: =COUNTIFS(AE8:AE698, "=APAGADO",F8:F698,"=RADIO") -> 0 | AF5: =COUNTIFS(AF8:AF698, "=APAGADO",F8:F698,"=RADIO") -> 0 | AG5: =COUNTIFS(AG8:AG698, "=APAGADO",F8:F698,"=RADIO") -> 0 | AH5: =COUNTIFS(AH8:AH698, "=APAGADO",F8:F698,"=RADIO") -> 0 | AI5: =COUNTIFS(AI8:AI698, "=APAGADO",F8:F698,"=RADIO") -> 0 | AJ5: =COUNTIFS(AJ8:AJ698, "=APAGADO",F8:F698,"=RADIO") -> 0 | AK5: =COUNTIFS(AK8:AK698, "=APAGADO",F8:F698,"=RADIO") -> 0 | AL5: =COUNTIFS(AL8:AL698, "=APAGADO",F8:F698,"=RADIO") -> 0 | AM5: =COUNTIFS(AM8:AM698, "=APAGADO",F8:F698,"=RADIO") -> 0 | AN5: =COUNTIFS(AN8:AN698, "=APAGADO",F8:F698,"=RADIO") -> 0 | AO5: =COUNTIFS(AO8:AO698, "=APAGADO",F8:F698,"=RADIO") -> 0 | AP5: =COUNTIFS(AP8:AP698, "=APAGADO",G8:G698,"=RADIO") -> 0 | AQ5: =COUNTIFS(AQ8:AQ698, "=APAGADO",H8:H698,"=RADIO") -> 0 | AR5: =COUNTIFS(AR8:AR698, "=APAGADO",J8:J698,"=RADIO") -> 0
D6: APAGADOS ANTENA | N6: =COUNTIFS(N8:N698, "=APAGADO",F8:F698,"=PTO A FO") -> 9 | O6: =COUNTIFS(O8:O698, "=APAGADO",F8:F698,"=PTO A FO") -> 10 | P6: =COUNTIFS(P8:P698, "=APAGADO",F8:F698,"=PTO A FO") -> 7 | Q6: =COUNTIFS(Q8:Q698, "=APAGADO",F8:F698,"=PTO A FO") -> 8 | R6: =COUNTIFS(R8:R698, "=APAGADO",F8:F698,"=PTO A FO") -> 9 | S6: =COUNTIFS(S8:S698, "=APAGADO",F8:F698,"=PTO A FO") -> 10 | T6: =COUNTIFS(T8:T698, "=APAGADO",F8:F698,"=PTO A FO") -> 6 | U6: =COUNTIFS(U8:U698, "=APAGADO",F8:F698,"=PTO A FO") -> 0 | V6: =COUNTIFS(V8:V698, "=APAGADO",F8:F698,"=PTO A FO") -> 8 | W6: =COUNTIFS(W8:W698, "=APAGADO",F8:F698,"=PTO A FO") -> 8 | X6: =COUNTIFS(X8:X698, "=APAGADO",F8:F698,"=PTO A FO") -> 7 | Y6: =COUNTIFS(Y8:Y698, "=APAGADO",F8:F698,"=PTO A FO") -> 6 | Z6: =COUNTIFS(Z8:Z698, "=APAGADO",F8:F698,"=PTO A FO") -> 4 | AA6: =COUNTIFS(AA8:AA698, "=APAGADO",F8:F698,"=PTO A FO") -> 0 | AB6: =COUNTIFS(AB8:AB698, "=APAGADO",F8:F698,"=PTO A FO") -> 0 | AC6: =COUNTIFS(AC8:AC698, "=APAGADO",F8:F698,"=PTO A FO") -> 6 | AD6: =COUNTIFS(AD8:AD698, "=APAGADO",F8:F698,"=PTO A FO") -> 5 | AE6: =COUNTIFS(AE8:AE698, "=APAGADO",F8:F698,"=PTO A FO") -> 0 | AF6: =COUNTIFS(AF8:AF698, "=APAGADO",F8:F698,"=PTO A FO") -> 0 | AG6: =COUNTIFS(AG8:AG698, "=APAGADO",F8:F698,"=PTO A FO") -> 0 | AH6: =COUNTIFS(AH8:AH698, "=APAGADO",F8:F698,"=PTO A FO") -> 0 | AI6: =COUNTIFS(AI8:AI698, "=APAGADO",F8:F698,"=PTO A FO") -> 0 | AJ6: =COUNTIFS(AJ8:AJ698, "=APAGADO",F8:F698,"=PTO A FO") -> 0 | AK6: =COUNTIFS(AK8:AK698, "=APAGADO",F8:F698,"=PTO A FO") -> 0 | AL6: =COUNTIFS(AL8:AL698, "=APAGADO",F8:F698,"=PTO A FO") -> 0 | AM6: =COUNTIFS(AM8:AM698, "=APAGADO",F8:F698,"=PTO A FO") -> 0 | AN6: =COUNTIFS(AN8:AN698, "=APAGADO",F8:F698,"=PTO A FO") -> 0 | AO6: =COUNTIFS(AO8:AO698, "=APAGADO",F8:F698,"=PTO A FO") -> 0 | AP6: =COUNTIFS(AP8:AP698, "=APAGADO",G8:G698,"=PTO A FO") -> 0 | AQ6: =COUNTIFS(AQ8:AQ698, "=APAGADO",H8:H698,"=PTO A FO") -> 0 | AR6: =COUNTIFS(AR8:AR698, "=APAGADO",J8:J698,"=PTO A FO") -> 0
A7: Barrio | B7: [Denominacion] | C7: [Empresa Mantenimiento] | D7: [Ubicacion] | E7: [Tipo de Camara] | F7: [Tipo de Conexion] | G7: Destino | I7: Switch | J7: DIAS FUNCIONANDO | K7: MAC | L7: DIAS CAIDA | M7: EFECTIVIDAD | N7: 46082 | O7: 46083 | P7: 46084 | Q7: 46085 | R7: 46086 | S7: 46087 | T7: 46088 | U7: 46089 | V7: 46090 | W7: 46091 | X7: 46092 | Y7: 46093 | Z7: 46094 | AA7: 46095 | AB7: 46096 | AC7: 46097 | AD7: 46098 | AE7: 46099 | AF7: 46100 | AG7: 46101 | AH7: 46102 | AI7: 46103 | AJ7: 46104 | AK7: 46105 | AL7: 46106 | AM7: 46107 | AN7: 46108 | AO7: 46109 | AP7: 46110 | AQ7: 46111 | AR7: 46112
A8: ALTAMIRA | B8: ALT01 | C8: BONOMO | D8: Calchaqui y Sgto. Cabral | E8: Domo | F8: Fibra Optica | H8: 172.20.10.6 | J8: =COUNTIF(N8:AO8,"") -> 28 | K8: 00-07-5F-87-83-56 | L8: =COUNTIF(N8:AO8,"APAGADO") -> 0 | M8: =(J8)/(L8+J8) -> 1
A9: ALTAMIRA | B9: ALT02 | C9: BONOMO | D9: Calchaqui y Lope de Vega | E9: Domo | F9: PTO A FO | G9: CABRAL Y CALCHAQUI | H9: 172.20.12.218 | J9: =COUNTIF(N9:AO9,"") -> 19 | K9: 00-04-63-50-42-A4 | L9: =COUNTIF(N9:AO9,"APAGADO") -> 9 | M9: =(J9)/(L9+J9) -> 0.67857143 | N9: APAGADO | O9: APAGADO | P9: APAGADO | Q9: APAGADO | R9: APAGADO | S9: APAGADO | T9: APAGADO | V9: APAGADO | W9: APAGADO
A10: ALTAMIRA | B10: ALT 03 | C10: BONOMO | D10: Bombero Galarza y Necochea | E10: Domo | F10: GPON | H10: 172.20.12.54 | J10: =COUNTIF(N10:AO10,"") -> 28 | K10: 00-07-5F-87-9D-EF | L10: =COUNTIF(N10:AO10,"APAGADO") -> 0 | M10: =(J10)/(L10+J10) -> 1
A11: ALTAMIRA | B11: ALT 04 | C11: BONOMO | D11: Francia y Necochea | E11: Domo | F11: GPON | H11: 172.20.12.55 | J11: =COUNTIF(N11:AO11,"") -> 28 | K11: 00-04-63-59-22-57 | L11: =COUNTIF(N11:AO11,"APAGADO") -> 0 | M11: =(J11)/(L11+J11) -> 1
A12: ALTAMIRA | B12: ALT05 | C12: BONOMO | D12: Av. Calchaqui y Bombero Galarza | E12: Domo | F12: GPON | G12: NECOCHEA Y GALARZA | H12: 172.20.12.216 | J12: =COUNTIF(N12:AO12,"") -> 28 | K12: 00-07-5F-77-02-85 | L12: =COUNTIF(N12:AO12,"APAGADO") -> 0 | M12: =(J12)/(L12+J12) -> 1
A13: ALTAMIRA | B13: ALT 06 | C13: BONOMO | D13: LOPE DE VEGA Y NECOCHEA | E13: Domo | F13: GPON | G13: NECOCHEA Y GALARZA | H13: 172.20.12.12 | J13: =COUNTIF(N13:AO13,"") -> 28 | K13: 00-04-63-4F-DD-DB | L13: =COUNTIF(N13:AO13,"APAGADO") -> 0 | M13: =(J13)/(L13+J13) -> 1
A14: ALTAMIRA | B14: ALT07 | C14: BONOMO | D14: AV. CALCHAQUI Y AV. DEL TRABAJO | E14: DOMO | F14: PTO A FO | G14: CABRAL Y CALCHAQUI | H14: 172.20.10.57 | J14: =COUNTIF(N14:AO14,"") -> 28 | K14: 00-04-63-4F-DE-CA | L14: =COUNTIF(N14:AO14,"APAGADO") -> 0 | M14: =(J14)/(L14+J14) -> 1
A15: ALTAMIRA | B15: ALT 08 | C15: BONOMO | D15: HUMAITA Y NECOCHEA | E15: DOMO | F15: Fibra Optica | H15: 172.20.11.215 | J15: =COUNTIF(N15:AO15,"") -> 28 | K15: 00-07-5F-BE-59-2D | L15: =COUNTIF(N15:AO15,"APAGADO") -> 0 | M15: =(J15)/(L15+J15) -> 1
A16: ALTAMIRA | B16: ALT 09 | C16: BONOMO | D16: NECOCHEA Y CURUPAITY | E16: DOMO | F16: Fibra Optica | H16: 172.20.11.216 | J16: =COUNTIF(N16:AO16,"") -> 28 | K16: 00-07-5F-BE-59-27 | L16: =COUNTIF(N16:AO16,"APAGADO") -> 0 | M16: =(J16)/(L16+J16) -> 1
A17: ALTAMIRA | B17: ALT 10 | C17: BONOMO | D17: Calchaqui y Francia | E17: Domo | F17: GPON | H17: 172.20.12.156 | J17: =COUNTIF(N17:AO17,"") -> 28 | K17: 00-07-5F-AB-BB-41 | L17: =COUNTIF(N17:AO17,"APAGADO") -> 0 | M17: =(J17)/(L17+J17) -> 1
A18: ALTAMIRA | B18: ALT 11 | C18: BONOMO | D18: CALCHAQUÍ Y GALARZA FIJA | E18: Fija | F18: GPON | H18: 172.20.12.241 | J18: =COUNTIF(N18:AO18,"") -> 28 | K18: 3c-1b-f8-df-95-58 | L18: =COUNTIF(N18:AO18,"APAGADO") -> 0 | M18: =(J18)/(L18+J18) -> 1
A19: AGUSTIN RAMIREZ | B19: ARA 01 | C19: BONOMO | D19: Malambo y Tranquera | E19: Domo | F19: Fibra Optica | H19: 172.20.12.110 | J19: =COUNTIF(N19:AO19,"") -> 15 | K19: 00-04-63-4F-DB-B6 | L19: =COUNTIF(N19:AO19,"APAGADO") -> 13 | M19: =(J19)/(L19+J19) -> 0.53571429 | N19: APAGADO | O19: APAGADO | P19: APAGADO | Q19: APAGADO | R19: APAGADO | S19: APAGADO | T19: APAGADO | V19: APAGADO | W19: APAGADO | X19: APAGADO | Z19: APAGADO | AC19: APAGADO | AD19: APAGADO
A20: AGUSTIN RAMIREZ | B20: ARA 02 | C20: BONOMO | D20: El malambo y La Tranquera | E20: Fija | F20: GPON | H20: 172.20.12.235 | J20: =COUNTIF(N20:AO20,"") -> 14 | K20: C0:6D:ED:A3:E6:63 | L20: =COUNTIF(N20:AO20,"APAGADO") -> 14 | M20: =(J20)/(L20+J20) -> 0.5 | N20: APAGADO | O20: APAGADO | P20: APAGADO | Q20: APAGADO | R20: APAGADO | S20: APAGADO | T20: APAGADO | V20: APAGADO | W20: APAGADO | X20: APAGADO | Y20: APAGADO | Z20: APAGADO | AC20: APAGADO | AD20: APAGADO
A21: AGUSTIN RAMIREZ | B21: ARA 03 | C21: BONOMO | D21: 437 Y La Tranquera | E21: Fija | F21: GPON | H21: 172.20.10.232 | J21: =COUNTIF(N21:AO21,"") -> 27 | K21: C0:6D:ED:A3:66:6A | L21: =COUNTIF(N21:AO21,"APAGADO") -> 1 | M21: =(J21)/(L21+J21) -> 0.96428571 | Y21: APAGADO
A22: BELGRANO | B22: BEL 01 | C22: BONOMO | D22: San Martin y Dardo Rocha | E22: DOMO | F22: Fibra Optica | H22: 172.20.12.64 | I22: A03 | J22: =COUNTIF(N22:AO22,"") -> 28 | K22: 00-07-5F-9F-A1-64 | L22: =COUNTIF(N22:AO22,"APAGADO") -> 0 | M22: =(J22)/(L22+J22) -> 1
A23: BELGRANO | B23: BEL 02 | C23: BONOMO | D23: Guardia vieja y Fronteriz | E23: DOMO | F23: Fibra Optica | H23: 172.20.10.117 | J23: =COUNTIF(N23:AO23,"") -> 28 | K23: E4-30-22-4F-9E-62 | L23: =COUNTIF(N23:AO23,"APAGADO") -> 0 | M23: =(J23)/(L23+J23) -> 1
A24: BOSQUES CENTRO | B24: BOSQC 01 | C24: COSEIDI | D24: LUIS AGOTE E/DANUNCIO Y CAMPOAMOR | E24: Fija | F24: PTO A FO | H24: 172.20.11.15 | J24: =COUNTIF(N24:AO24,"") -> 28 | K24: 00-07-5F-B7-56-89 | L24: =COUNTIF(N24:AO24,"APAGADO") -> 0 | M24: =(J24)/(L24+J24) -> 1
A25: BOSQUES CENTRO | B25: BOSQC 02 | C25: COSEIDI | D25: LUIS AGOTE E/DANUNCIO Y CAMPOAMOR | E25: Fija | F25: PTO A FO | H25: 172.20.11.16 | J25: =COUNTIF(N25:AO25,"") -> 28 | K25: 00-07-5F-B4-17-A8 | L25: =COUNTIF(N25:AO25,"APAGADO") -> 0 | M25: =(J25)/(L25+J25) -> 1
A26: BOSQUES CENTRO | B26: BOSQC 03 | C26: COSEIDI | D26: BENAVENTE Y LUIS AGOTE | E26: Fija | F26: PTO A FO | H26: 172.20.11.13 | J26: =COUNTIF(N26:AO26,"") -> 28 | K26: 00-07-5F-B6-B8-A5 | L26: =COUNTIF(N26:AO26,"APAGADO") -> 0 | M26: =(J26)/(L26+J26) -> 1
A27: BOSQUES CENTRO | B27: BOSQC 04 | C27: COSEIDI | D27: BENAVENTE Y LUIS AGOTE | E27: Fija | F27: PTO A FO | H27: 172.20.11.113 | J27: =COUNTIF(N27:AO27,"") -> 28 | K27: 00-07-5F-B6-B8-D3 | L27: =COUNTIF(N27:AO27,"APAGADO") -> 0 | M27: =(J27)/(L27+J27) -> 1
A28: BOSQUES CENTRO | B28: BOSQC 05 | C28: COSEIDI | D28: LUIS AGOTE Y RUTA 36 | E28: Fija | F28: PTO A FO | H28: 172.20.11.17 | J28: =COUNTIF(N28:AO28,"") -> 28 | K28: 00-07-5F-B4-42-C7 | L28: =COUNTIF(N28:AO28,"APAGADO") -> 0 | M28: =(J28)/(L28+J28) -> 1
A29: BOSQUES CENTRO | B29: BOSQC 06 | C29: COSEIDI | D29: LUIS AGOTE Y RUTA 36 | E29: Fija | F29: PTO A FO | H29: 172.20.11.18 | J29: =COUNTIF(N29:AO29,"") -> 28 | K29: 00-07-5F-B4-16-8D | L29: =COUNTIF(N29:AO29,"APAGADO") -> 0 | M29: =(J29)/(L29+J29) -> 1
A30: BOSQUES CENTRO | B30: BOSQ 07 | C30: COSEIDI | D30: Touring club y Sta Teresita | E30: Domo | F30: GPON | H30: 172.20.10.141 | J30: =COUNTIF(N30:AO30,"") -> 27 | K30: A0-FF-0C-D1-BD-7F | L30: =COUNTIF(N30:AO30,"APAGADO") -> 1 | M30: =(J30)/(L30+J30) -> 0.96428571 | R30: APAGADO
A31: BOSQUES CENTRO | B31: BOSQ 08 | C31: COSEIDI | D31: D'Anuncio Y J.B Justo (Plaza) | E31: Domo | F31: GPON | H31: 172.20.10.222 | J31: =COUNTIF(N31:AO31,"") -> 28 | K31: a4-18-94-05-51-13 | L31: =COUNTIF(N31:AO31,"APAGADO") -> 0 | M31: =(J31)/(L31+J31) -> 1
A32: BOSQUES CENTRO | B32: BOSQ 09 | C32: COSEIDI | D32: D'Anuncio e/Lisandro de la Torre y J.B Justo | E32: Fija | F32: GPON | H32: 172.20.10.227 | J32: =COUNTIF(N32:AO32,"") -> 28 | K32: c0-6d-ed-a3-e4-4c | L32: =COUNTIF(N32:AO32,"APAGADO") -> 0 | M32: =(J32)/(L32+J32) -> 1
A33: BOSQUES CENTRO | B33: BOSQ 10 | C33: COSEIDI | D33: D'Anuncio e/Lisandro de la Torre y J.B Justo | E33: Fija | F33: GPON | H33: 172.20.10.228 | J33: =COUNTIF(N33:AO33,"") -> 28 | K33: c0-6d-ed-a3-e4-5b | L33: =COUNTIF(N33:AO33,"APAGADO") -> 0 | M33: =(J33)/(L33+J33) -> 1
A34: BOSQUES CENTRO | B34: BOSQ 11 | C34: COSEIDI | D34: AV Bosques y Altagracia | E34: Domo | F34: GPON | H34: 172.20.8.52 | J34: =COUNTIF(N34:AO34,"") -> 28 | K34: A4-18-94-05-A4-68 | L34: =COUNTIF(N34:AO34,"APAGADO") -> 0 | M34: =(J34)/(L34+J34) -> 1
A35: PRESIDENTE AVELLANEDA | B35: PAVE01 | C35: COSEIDI | D35: Touring Club y Ramallo | E35: Domo | F35: Fibra Optica | H35: 172.20.10.144 | J35: =COUNTIF(N35:AO35,"") -> 27 | K35: A0-FF-0C-D4-AF-AD | L35: =COUNTIF(N35:AO35,"APAGADO") -> 1 | M35: =(J35)/(L35+J35) -> 0.96428571 | R35: APAGADO
A36: PRESIDENTE AVELLANEDA | B36: PAVE02 | C36: COSEIDI | D36: Ramallo y Calingasta | E36: Domo | F36: GPON | H36: 172.20.10.37 | J36: =COUNTIF(N36:AO36,"") -> 14 | K36: a4-18-94-05-47-33 | L36: =COUNTIF(N36:AO36,"APAGADO") -> 14 | M36: =(J36)/(L36+J36) -> 0.5 | N36: APAGADO | O36: APAGADO | P36: APAGADO | Q36: APAGADO | R36: APAGADO | S36: APAGADO | T36: APAGADO | V36: APAGADO | W36: APAGADO | X36: APAGADO | Y36: APAGADO | Z36: APAGADO | AC36: APAGADO | AD36: APAGADO
A37: PRESIDENTE AVELLANEDA | B37: PAVE03 | C37: COSEIDI | D37: Ptagones e Irala | E37: Domo | F37: GPON | H37: 172,20,12,201 | J37: =COUNTIF(N37:AO37,"") -> 14 | K37: a4-18-94-05-50-c9 | L37: =COUNTIF(N37:AO37,"APAGADO") -> 14 | M37: =(J37)/(L37+J37) -> 0.5 | N37: APAGADO | O37: APAGADO | P37: APAGADO | Q37: APAGADO | R37: APAGADO | S37: APAGADO | T37: APAGADO | V37: APAGADO | W37: APAGADO | X37: APAGADO | Y37: APAGADO | Z37: APAGADO | AC37: APAGADO | AD37: APAGADO
A38: BOSQUES CENTRO | B38: CVA01 | C38: COSEIDI | D38: CACHEUTA Y 1355 | E38: Domo | F38: GPON | H38: 172.20.10.59 | J38: =COUNTIF(N38:AO38,"") -> 28 | K38: c0-6d-ed-a7-2f-76 | L38: =COUNTIF(N38:AO38,"APAGADO") -> 0 | M38: =(J38)/(L38+J38) -> 1
A39: LA CAROLINA 2 | B39: CAR01 (Fija 1) | C39: COSEIDI | D39: Azurduy y Vergara | E39: Fija | F39: Fibra Optica | H39: 172.20.10.60 | J39: =COUNTIF(N39:AO39,"") -> 25 | K39: A0:FF:0C:EF:DF:AB | L39: =COUNTIF(N39:AO39,"APAGADO") -> 3 | M39: =(J39)/(L39+J39) -> 0.89285714 | N39: APAGADO | O39: APAGADO | P39: APAGADO
A40: LA CAROLINA 2 | B40: CAR02 (Fija 2) | C40: COSEIDI | D40: Azurduy y Vergara | E40: Fija | F40: Fibra Optica | H40: 172.20.10.73 | J40: =COUNTIF(N40:AO40,"") -> 25 | K40: A0:FF:0C:EF:DF:AD | L40: =COUNTIF(N40:AO40,"APAGADO") -> 3 | M40: =(J40)/(L40+J40) -> 0.89285714 | N40: APAGADO | O40: APAGADO | P40: APAGADO
...

Sheet AUXILIAR

Sheet paradas
C1: TOTAL PARADAS | D1: =COUNTIFS(A5:A602,"=paradas seguras")/2 -> 0 | E1: TOTAL DE CAMARAS EN PARADAS | H1: =COUNTIFS(A5:A602,"=paradas seguras") -> 0 | I1: TOTAL DE CAMARAS | K1: =COUNTIFS(D5:D602,"=GFIJA") -> 0 | L1: TOTAL DE INTERCOMUNICADORES | O1: =COUNTIFS(D5:D602,"=INTERCOMUNICADOR") -> 0
E2: FIJAS | F2: =COUNTIFS(F4:F601, "=APAGADO",D4:D601,"=GFIJA") -> 0 | G2: =COUNTIFS(G4:G601, "=APAGADO",D4:D601,"=GFIJA") -> 0 | H2: =COUNTIFS(H4:H601, "=APAGADO",D4:D601,"=GFIJA") -> 0 | I2: =COUNTIFS(I4:I601, "=APAGADO",D4:D601,"=GFIJA") -> 0 | J2: =COUNTIFS(J4:J601, "=APAGADO",D4:D601,"=GFIJA") -> 0 | K2: =COUNTIFS(K4:K601, "=APAGADO",D4:D601,"=GFIJA") -> 0 | L2: =COUNTIFS(L4:L601, "=APAGADO",D4:D601,"=GFIJA") -> 0 | M2: =COUNTIFS(M4:M601, "=APAGADO",D4:D601,"=GFIJA") -> 0 | N2: =COUNTIFS(N4:N601, "=APAGADO",D4:D601,"=GFIJA") -> 0 | O2: =COUNTIFS(O4:O601, "=APAGADO",D4:D601,"=GFIJA") -> 0 | P2: =COUNTIFS(P4:P601, "=APAGADO",D4:D601,"=GFIJA") -> 0 | Q2: =COUNTIFS(Q4:Q601, "=APAGADO",D4:D601,"=GFIJA") -> 0 | R2: =COUNTIFS(R4:R601, "=APAGADO",D4:D601,"=GFIJA") -> 0 | S2: =COUNTIFS(S4:S601, "=APAGADO",D4:D601,"=GFIJA") -> 0 | T2: =COUNTIFS(T4:T601, "=APAGADO",D4:D601,"=GFIJA") -> 0 | U2: =COUNTIFS(U4:U601, "=APAGADO",D4:D601,"=GFIJA") -> 0 | V2: =COUNTIFS(V4:V601, "=APAGADO",D4:D601,"=GFIJA") -> 0 | W2: =COUNTIFS(W4:W601, "=APAGADO",D4:D601,"=GFIJA") -> 0 | X2: =COUNTIFS(X4:X601, "=APAGADO",D4:D601,"=GFIJA") -> 0 | Y2: =COUNTIFS(Y4:Y601, "=APAGADO",D4:D601,"=GFIJA") -> 0 | Z2: =COUNTIFS(Z4:Z601, "=APAGADO",D4:D601,"=GFIJA") -> 0 | AA2: =COUNTIFS(AA4:AA601, "=APAGADO",D4:D601,"=GFIJA") -> 0 | AB2: =COUNTIFS(AB4:AB601, "=APAGADO",D4:D601,"=GFIJA") -> 0 | AC2: =COUNTIFS(AC4:AC601, "=APAGADO",D4:D601,"=GFIJA") -> 0 | AD2: =COUNTIFS(AD4:AD601, "=APAGADO",D4:D601,"=GFIJA") -> 0 | AE2: =COUNTIFS(AE4:AE601, "=APAGADO",D4:D601,"=GFIJA") -> 0 | AF2: =COUNTIFS(AF4:AF601, "=APAGADO",D4:D601,"=GFIJA") -> 0 | AG2: =COUNTIFS(AG4:AG601, "=APAGADO",D4:D601,"=GFIJA") -> 0 | AH2: =COUNTIFS(AH4:AH601, "=APAGADO",E4:E601,"=GFIJA") -> 0 | AI2: =COUNTIFS(AI4:AI601, "=APAGADO",F4:F601,"=GFIJA") -> 0 | AJ2: =COUNTIFS(AJ4:AJ601, "=APAGADO",G4:G601,"=GFIJA") -> 0
E3: INTERCOMUNICADOR | F3: =COUNTIFS(F6:F603, "=APAGADO",D4:D601,"=INTERCOMUNICADOR") -> 0 | G3: =COUNTIFS(G6:G603, "=APAGADO",D4:D601,"=INTERCOMUNICADOR") -> 0 | H3: =COUNTIFS(H6:H603, "=APAGADO",D4:D601,"=INTERCOMUNICADOR") -> 0 | I3: =COUNTIFS(I6:I603, "=APAGADO",D4:D601,"=INTERCOMUNICADOR") -> 0 | J3: =COUNTIFS(J6:J603, "=APAGADO",D4:D601,"=INTERCOMUNICADOR") -> 0 | K3: =COUNTIFS(K6:K603, "=APAGADO",D4:D601,"=INTERCOMUNICADOR") -> 0 | L3: =COUNTIFS(L6:L603, "=APAGADO",D4:D601,"=INTERCOMUNICADOR") -> 0 | M3: =COUNTIFS(M6:M603, "=APAGADO",D4:D601,"=INTERCOMUNICADOR") -> 0 | N3: =COUNTIFS(N6:N603, "=APAGADO",D4:D601,"=INTERCOMUNICADOR") -> 0 | O3: =COUNTIFS(O6:O603, "=APAGADO",D4:D601,"=INTERCOMUNICADOR") -> 0 | P3: =COUNTIFS(P6:P603, "=APAGADO",D4:D601,"=INTERCOMUNICADOR") -> 0 | Q3: =COUNTIFS(Q6:Q603, "=APAGADO",D4:D601,"=INTERCOMUNICADOR") -> 0 | R3: =COUNTIFS(R6:R603, "=APAGADO",D4:D601,"=INTERCOMUNICADOR") -> 0 | S3: =COUNTIFS(S6:S603, "=APAGADO",D4:D601,"=INTERCOMUNICADOR") -> 0 | T3: =COUNTIFS(T6:T603, "=APAGADO",D4:D601,"=INTERCOMUNICADOR") -> 0 | U3: =COUNTIFS(U6:U603, "=APAGADO",D4:D601,"=INTERCOMUNICADOR") -> 0 | V3: =COUNTIFS(V6:V603, "=APAGADO",D4:D601,"=INTERCOMUNICADOR") -> 0 | W3: =COUNTIFS(W6:W603, "=APAGADO",D4:D601,"=INTERCOMUNICADOR") -> 0 | X3: =COUNTIFS(X6:X603, "=APAGADO",D4:D601,"=INTERCOMUNICADOR") -> 0 | Y3: =COUNTIFS(Y6:Y603, "=APAGADO",D4:D601,"=INTERCOMUNICADOR") -> 0 | Z3: =COUNTIFS(Z6:Z603, "=APAGADO",D4:D601,"=INTERCOMUNICADOR") -> 0 | AA3: =COUNTIFS(AA6:AA603, "=APAGADO",D4:D601,"=INTERCOMUNICADOR") -> 0 | AB3: =COUNTIFS(AB6:AB603, "=APAGADO",D4:D601,"=INTERCOMUNICADOR") -> 0 | AC3: =COUNTIFS(AC6:AC603, "=APAGADO",D4:D601,"=INTERCOMUNICADOR") -> 0 | AD3: =COUNTIFS(AD6:AD603, "=APAGADO",D4:D601,"=INTERCOMUNICADOR") -> 0 | AE3: =COUNTIFS(AE6:AE603, "=APAGADO",D4:D601,"=INTERCOMUNICADOR") -> 0 | AF3: =COUNTIFS(AF6:AF603, "=APAGADO",D4:D601,"=INTERCOMUNICADOR") -> 0 | AG3: =COUNTIFS(AG6:AG603, "=APAGADO",D4:D601,"=INTERCOMUNICADOR") -> 0 | AH3: =COUNTIFS(AH6:AH603, "=APAGADO",E4:E601,"=INTERCOMUNICADOR") -> 0 | AI3: =COUNTIFS(AI6:AI603, "=APAGADO",F4:F601,"=INTERCOMUNICADOR") -> 0 | AJ3: =COUNTIFS(AJ6:AJ603, "=APAGADO",G4:G601,"=INTERCOMUNICADOR") -> 0
A4: ='RESUMEN TOTAL'!A7 -> Barrio | B4: ='RESUMEN TOTAL'!B7 -> [Denominacion] | C4: ='RESUMEN TOTAL'!D7 -> [Ubicacion] | D4: ='RESUMEN TOTAL'!E7 -> [Tipo de Camara] | E4: ='RESUMEN TOTAL'!F7 -> [Tipo de Conexion] | F4: ='RESUMEN TOTAL'!N7 -> 46082 | G4: ='RESUMEN TOTAL'!O7 -> 46083 | H4: ='RESUMEN TOTAL'!P7 -> 46084 | I4: ='RESUMEN TOTAL'!Q7 -> 46085 | J4: ='RESUMEN TOTAL'!R7 -> 46086 | K4: ='RESUMEN TOTAL'!S7 -> 46087 | L4: ='RESUMEN TOTAL'!T7 -> 46088 | M4: ='RESUMEN TOTAL'!U7 -> 46089 | ... AJ4: ='RESUMEN TOTAL'!AR7 -> 46112 | XEY4: =SUM(F4:XEX4) -> 1429007
A5: ='RESUMEN TOTAL'!A8 -> ALTAMIRA | B5: ='RESUMEN TOTAL'!B8 -> ALT01 | C5: ='RESUMEN TOTAL'!D8 -> Calchaqui y Sgto. Cabral | D5: ='RESUMEN TOTAL'!E8 -> Domo | E5: ='RESUMEN TOTAL'!F8 -> Fibra Optica | F5: ='RESUMEN TOTAL'!N8 -> 0 | G5: ='RESUMEN TOTAL'!O8 -> 0 | H5: ='RESUMEN TOTAL'!P8 -> 0 | I5: ='RESUMEN TOTAL'!Q8 -> 0 | J5: ='RESUMEN TOTAL'!R8 -> 0 | K5: ='RESUMEN TOTAL'!S8 -> 0 | L5: ='RESUMEN TOTAL'!T8 -> 0 | M5: ='RESUMEN TOTAL'!U8 -> 0 | ... AJ5: ='RESUMEN TOTAL'!AR8 -> 0
A6: ='RESUMEN TOTAL'!A9 -> ALTAMIRA | B6: ='RESUMEN TOTAL'!B9 -> ALT02 | C6: ='RESUMEN TOTAL'!D9 -> Calchaqui y Lope de Vega | D6: ='RESUMEN TOTAL'!E9 -> Domo | E6: ='RESUMEN TOTAL'!F9 -> PTO A FO | F6: ='RESUMEN TOTAL'!N9 -> APAGADO | G6: ='RESUMEN TOTAL'!O9 -> APAGADO | H6: ='RESUMEN TOTAL'!P9 -> APAGADO | I6: ='RESUMEN TOTAL'!Q9 -> APAGADO | J6: ='RESUMEN TOTAL'!R9 -> APAGADO | K6: ='RESUMEN TOTAL'!S9 -> APAGADO | L6: ='RESUMEN TOTAL'!T9 -> APAGADO | M6: ='RESUMEN TOTAL'!U9 -> 0 | ... AJ6: ='RESUMEN TOTAL'!AR9 -> 0
A7: ='RESUMEN TOTAL'!A10 -> ALTAMIRA | B7: ='RESUMEN TOTAL'!B10 -> ALT 03 | C7: ='RESUMEN TOTAL'!D10 -> Bombero Galarza y Necochea | D7: ='RESUMEN TOTAL'!E10 -> Domo | E7: ='RESUMEN TOTAL'!F10 -> GPON | F7: ='RESUMEN TOTAL'!N10 -> 0 | G7: ='RESUMEN TOTAL'!O10 -> 0 | H7: ='RESUMEN TOTAL'!P10 -> 0 | I7: ='RESUMEN TOTAL'!Q10 -> 0 | J7: ='RESUMEN TOTAL'!R10 -> 0 | K7: ='RESUMEN TOTAL'!S10 -> 0 | L7: ='RESUMEN TOTAL'!T10 -> 0 | M7: ='RESUMEN TOTAL'!U10 -> 0 | ... AJ7: ='RESUMEN TOTAL'!AR10 -> 0
A8: ='RESUMEN TOTAL'!A11 -> ALTAMIRA | B8: ='RESUMEN TOTAL'!B11 -> ALT 04 | C8: ='RESUMEN TOTAL'!D11 -> Francia y Necochea | D8: ='RESUMEN TOTAL'!E11 -> Domo | E8: ='RESUMEN TOTAL'!F11 -> GPON | F8: ='RESUMEN TOTAL'!N11 -> 0 | G8: ='RESUMEN TOTAL'!O11 -> 0 | H8: ='RESUMEN TOTAL'!P11 -> 0 | I8: ='RESUMEN TOTAL'!Q11 -> 0 | J8: ='RESUMEN TOTAL'!R11 -> 0 | K8: ='RESUMEN TOTAL'!S11 -> 0 | L8: ='RESUMEN TOTAL'!T11 -> 0 | M8: ='RESUMEN TOTAL'!U11 -> 0 | ... AJ8: ='RESUMEN TOTAL'!AR11 -> 0
A9: ='RESUMEN TOTAL'!A12 -> ALTAMIRA | B9: ='RESUMEN TOTAL'!B12 -> ALT05 | C9: ='RESUMEN TOTAL'!D12 -> Av. Calchaqui y Bombero Galarza | D9: ='RESUMEN TOTAL'!E12 -> Domo | E9: ='RESUMEN TOTAL'!F12 -> GPON | F9: ='RESUMEN TOTAL'!N12 -> 0 | G9: ='RESUMEN TOTAL'!O12 -> 0 | H9: ='RESUMEN TOTAL'!P12 -> 0 | I9: ='RESUMEN TOTAL'!Q12 -> 0 | J9: ='RESUMEN TOTAL'!R12 -> 0 | K9: ='RESUMEN TOTAL'!S12 -> 0 | L9: ='RESUMEN TOTAL'!T12 -> 0 | M9: ='RESUMEN TOTAL'!U12 -> 0 | ... AJ9: ='RESUMEN TOTAL'!AR12 -> 0
A10: ='RESUMEN TOTAL'!A13 -> ALTAMIRA | B10: ='RESUMEN TOTAL'!B13 -> ALT 06 | C10: ='RESUMEN TOTAL'!D13 -> LOPE DE VEGA Y NECOCHEA | D10: ='RESUMEN TOTAL'!E13 -> Domo | E10: ='RESUMEN TOTAL'!F13 -> GPON | F10: ='RESUMEN TOTAL'!N13 -> 0 | G10: ='RESUMEN TOTAL'!O13 -> 0 | H10: ='RESUMEN TOTAL'!P13 -> 0 | I10: ='RESUMEN TOTAL'!Q13 -> 0 | J10: ='RESUMEN TOTAL'!R13 -> 0 | K10: ='RESUMEN TOTAL'!S13 -> 0 | L10: ='RESUMEN TOTAL'!T13 -> 0 | M10: ='RESUMEN TOTAL'!U13 -> 0 | ... AJ10: ='RESUMEN TOTAL'!AR13 -> 0
A11: ='RESUMEN TOTAL'!A14 -> ALTAMIRA | B11: ='RESUMEN TOTAL'!B14 -> ALT07 | C11: ='RESUMEN TOTAL'!D14 -> AV. CALCHAQUI Y AV. DEL TRABAJO | D11: ='RESUMEN TOTAL'!E14 -> DOMO | E11: ='RESUMEN TOTAL'!F14 -> PTO A FO | F11: ='RESUMEN TOTAL'!N14 -> 0 | G11: ='RESUMEN TOTAL'!O14 -> 0 | H11: ='RESUMEN TOTAL'!P14 -> 0 | I11: ='RESUMEN TOTAL'!Q14 -> 0 | J11: ='RESUMEN TOTAL'!R14 -> 0 | K11: ='RESUMEN TOTAL'!S14 -> 0 | L11: ='RESUMEN TOTAL'!T14 -> 0 | M11: ='RESUMEN TOTAL'!U14 -> 0 | ... AJ11: ='RESUMEN TOTAL'!AR14 -> 0
A12: ='RESUMEN TOTAL'!A15 -> ALTAMIRA | B12: ='RESUMEN TOTAL'!B15 -> ALT 08 | C12: ='RESUMEN TOTAL'!D15 -> HUMAITA Y NECOCHEA | D12: ='RESUMEN TOTAL'!E15 -> DOMO | E12: ='RESUMEN TOTAL'!F15 -> Fibra Optica | F12: ='RESUMEN TOTAL'!N15 -> 0 | G12: ='RESUMEN TOTAL'!O15 -> 0 | H12: ='RESUMEN TOTAL'!P15 -> 0 | I12: ='RESUMEN TOTAL'!Q15 -> 0 | J12: ='RESUMEN TOTAL'!R15 -> 0 | K12: ='RESUMEN TOTAL'!S15 -> 0 | L12: ='RESUMEN TOTAL'!T15 -> 0 | M12: ='RESUMEN TOTAL'!U15 -> 0 | ... AJ12: ='RESUMEN TOTAL'!AR15 -> 0
A13: ='RESUMEN TOTAL'!A16 -> ALTAMIRA | B13: ='RESUMEN TOTAL'!B16 -> ALT 09 | C13: ='RESUMEN TOTAL'!D16 -> NECOCHEA Y CURUPAITY | D13: ='RESUMEN TOTAL'!E16 -> DOMO | E13: ='RESUMEN TOTAL'!F16 -> Fibra Optica | F13: ='RESUMEN TOTAL'!N16 -> 0 | G13: ='RESUMEN TOTAL'!O16 -> 0 | H13: ='RESUMEN TOTAL'!P16 -> 0 | I13: ='RESUMEN TOTAL'!Q16 -> 0 | J13: ='RESUMEN TOTAL'!R16 -> 0 | K13: ='RESUMEN TOTAL'!S16 -> 0 | L13: ='RESUMEN TOTAL'!T16 -> 0 | M13: ='RESUMEN TOTAL'!U16 -> 0 | ... AJ13: ='RESUMEN TOTAL'!AR16 -> 0
A14: ='RESUMEN TOTAL'!A17 -> ALTAMIRA | B14: ='RESUMEN TOTAL'!B17 -> ALT 10 | C14: ='RESUMEN TOTAL'!D17 -> Calchaqui y Francia | D14: ='RESUMEN TOTAL'!E17 -> Domo | E14: ='RESUMEN TOTAL'!F17 -> GPON | F14: ='RESUMEN TOTAL'!N17 -> 0 | G14: ='RESUMEN TOTAL'!O17 -> 0 | H14: ='RESUMEN TOTAL'!P17 -> 0 | I14: ='RESUMEN TOTAL'!Q17 -> 0 | J14: ='RESUMEN TOTAL'!R17 -> 0 | K14: ='RESUMEN TOTAL'!S17 -> 0 | L14: ='RESUMEN TOTAL'!T17 -> 0 | M14: ='RESUMEN TOTAL'!U17 -> 0 | ... AJ14: ='RESUMEN TOTAL'!AR17 -> 0
A15: ='RESUMEN TOTAL'!A18 -> ALTAMIRA | B15: ='RESUMEN TOTAL'!B18 -> ALT 11 | C15: CALCHAQUÍ Y GALARZA FIJA | D15: ='RESUMEN TOTAL'!E18 -> Fija | F15: ='RESUMEN TOTAL'!N18 -> 0 | G15: ='RESUMEN TOTAL'!O18 -> 0 | H15: ='RESUMEN TOTAL'!P18 -> 0 | I15: ='RESUMEN TOTAL'!Q18 -> 0 | J15: ='RESUMEN TOTAL'!R18 -> 0 | K15: ='RESUMEN TOTAL'!S18 -> 0 | L15: ='RESUMEN TOTAL'!T18 -> 0 | M15: ='RESUMEN TOTAL'!U18 -> 0 | ... AJ15: ='RESUMEN TOTAL'!AR18 -> 0
A16: ='RESUMEN TOTAL'!A19 -> AGUSTIN RAMIREZ | B16: ='RESUMEN TOTAL'!B19 -> ARA 01 | C16: ='RESUMEN TOTAL'!D19 -> Malambo y Tranquera | D16: ='RESUMEN TOTAL'!E19 -> Domo | E16: ='RESUMEN TOTAL'!F19 -> Fibra Optica | F16: ='RESUMEN TOTAL'!N19 -> APAGADO | G16: ='RESUMEN TOTAL'!O19 -> APAGADO | H16: ='RESUMEN TOTAL'!P19 -> APAGADO | I16: ='RESUMEN TOTAL'!Q19 -> APAGADO | J16: ='RESUMEN TOTAL'!R19 -> APAGADO | K16: ='RESUMEN TOTAL'!S19 -> APAGADO | L16: ='RESUMEN TOTAL'!T19 -> APAGADO | M16: ='RESUMEN TOTAL'!U19 -> 0 | ... AJ16: ='RESUMEN TOTAL'!AR19 -> 0
A17: ='RESUMEN TOTAL'!A22 -> BELGRANO | B17: ='RESUMEN TOTAL'!B22 -> BEL 01 | C17: ='RESUMEN TOTAL'!D22 -> San Martin y Dardo Rocha | D17: ='RESUMEN TOTAL'!E22 -> DOMO | E17: ='RESUMEN TOTAL'!F22 -> Fibra Optica | F17: ='RESUMEN TOTAL'!N22 -> 0 | G17: ='RESUMEN TOTAL'!O22 -> 0 | H17: ='RESUMEN TOTAL'!P22 -> 0 | I17: ='RESUMEN TOTAL'!Q22 -> 0 | J17: ='RESUMEN TOTAL'!R22 -> 0 | K17: ='RESUMEN TOTAL'!S22 -> 0 | L17: ='RESUMEN TOTAL'!T22 -> 0 | M17: ='RESUMEN TOTAL'!U22 -> 0 | ... AJ17: ='RESUMEN TOTAL'!AR22 -> 0
A18: ='RESUMEN TOTAL'!A23 -> BELGRANO | B18: ='RESUMEN TOTAL'!B23 -> BEL 02 | C18: ='RESUMEN TOTAL'!D23 -> Guardia vieja y Fronteriz | D18: ='RESUMEN TOTAL'!E23 -> DOMO | E18: ='RESUMEN TOTAL'!F23 -> Fibra Optica | F18: ='RESUMEN TOTAL'!N23 -> 0 | G18: ='RESUMEN TOTAL'!O23 -> 0 | H18: ='RESUMEN TOTAL'!P23 -> 0 | I18: ='RESUMEN TOTAL'!Q23 -> 0 | J18: ='RESUMEN TOTAL'!R23 -> 0 | K18: ='RESUMEN TOTAL'!S23 -> 0 | L18: ='RESUMEN TOTAL'!T23 -> 0 | M18: ='RESUMEN TOTAL'!U23 -> 0 | ... AJ18: ='RESUMEN TOTAL'!AR23 -> 0
A19: ='RESUMEN TOTAL'!A24 -> BOSQUES CENTRO | B19: ='RESUMEN TOTAL'!B24 -> BOSQC 01 | C19: ='RESUMEN TOTAL'!D24 -> LUIS AGOTE E/DANUNCIO Y CAMPOAMOR | D19: ='RESUMEN TOTAL'!E24 -> Fija | E19: ='RESUMEN TOTAL'!F24 -> PTO A FO | F19: ='RESUMEN TOTAL'!N24 -> 0 | G19: ='RESUMEN TOTAL'!O24 -> 0 | H19: ='RESUMEN TOTAL'!P24 -> 0 | I19: ='RESUMEN TOTAL'!Q24 -> 0 | J19: ='RESUMEN TOTAL'!R24 -> 0 | K19: ='RESUMEN TOTAL'!S24 -> 0 | L19: ='RESUMEN TOTAL'!T24 -> 0 | M19: ='RESUMEN TOTAL'!U24 -> 0 | ... AJ19: ='RESUMEN TOTAL'!AR24 -> 0
A20: ='RESUMEN TOTAL'!A25 -> BOSQUES CENTRO | B20: ='RESUMEN TOTAL'!B25 -> BOSQC 02 | C20: ='RESUMEN TOTAL'!D25 -> LUIS AGOTE E/DANUNCIO Y CAMPOAMOR | D20: ='RESUMEN TOTAL'!E25 -> Fija | E20: ='RESUMEN TOTAL'!F25 -> PTO A FO | F20: ='RESUMEN TOTAL'!N25 -> 0 | G20: ='RESUMEN TOTAL'!O25 -> 0 | H20: ='RESUMEN TOTAL'!P25 -> 0 | I20: ='RESUMEN TOTAL'!Q25 -> 0 | J20: ='RESUMEN TOTAL'!R25 -> 0 | K20: ='RESUMEN TOTAL'!S25 -> 0 | L20: ='RESUMEN TOTAL'!T25 -> 0 | M20: ='RESUMEN TOTAL'!U25 -> 0 | ... AJ20: ='RESUMEN TOTAL'!AR25 -> 0
A21: ='RESUMEN TOTAL'!A26 -> BOSQUES CENTRO | B21: ='RESUMEN TOTAL'!B26 -> BOSQC 03 | C21: ='RESUMEN TOTAL'!D26 -> BENAVENTE Y LUIS AGOTE | D21: ='RESUMEN TOTAL'!E26 -> Fija | E21: ='RESUMEN TOTAL'!F26 -> PTO A FO | F21: ='RESUMEN TOTAL'!N26 -> 0 | G21: ='RESUMEN TOTAL'!O26 -> 0 | H21: ='RESUMEN TOTAL'!P26 -> 0 | I21: ='RESUMEN TOTAL'!Q26 -> 0 | J21: ='RESUMEN TOTAL'!R26 -> 0 | K21: ='RESUMEN TOTAL'!S26 -> 0 | L21: ='RESUMEN TOTAL'!T26 -> 0 | M21: ='RESUMEN TOTAL'!U26 -> 0 | ... AJ21: ='RESUMEN TOTAL'!AR26 -> 0
A22: ='RESUMEN TOTAL'!A27 -> BOSQUES CENTRO | B22: ='RESUMEN TOTAL'!B27 -> BOSQC 04 | C22: ='RESUMEN TOTAL'!D27 -> BENAVENTE Y LUIS AGOTE | D22: ='RESUMEN TOTAL'!E27 -> Fija | E22: ='RESUMEN TOTAL'!F27 -> PTO A FO | F22: ='RESUMEN TOTAL'!N27 -> 0 | G22: ='RESUMEN TOTAL'!O27 -> 0 | H22: ='RESUMEN TOTAL'!P27 -> 0 | I22: ='RESUMEN TOTAL'!Q27 -> 0 | J22: ='RESUMEN TOTAL'!R27 -> 0 | K22: ='RESUMEN TOTAL'!S27 -> 0 | L22: ='RESUMEN TOTAL'!T27 -> 0 | M22: ='RESUMEN TOTAL'!U27 -> 0 | ... AJ22: ='RESUMEN TOTAL'!AR27 -> 0
A23: ='RESUMEN TOTAL'!A28 -> BOSQUES CENTRO | B23: ='RESUMEN TOTAL'!B28 -> BOSQC 05 | C23: ='RESUMEN TOTAL'!D28 -> LUIS AGOTE Y RUTA 36 | D23: ='RESUMEN TOTAL'!E28 -> Fija | E23: ='RESUMEN TOTAL'!F28 -> PTO A FO | F23: ='RESUMEN TOTAL'!N28 -> 0 | G23: ='RESUMEN TOTAL'!O28 -> 0 | H23: ='RESUMEN TOTAL'!P28 -> 0 | I23: ='RESUMEN TOTAL'!Q28 -> 0 | J23: ='RESUMEN TOTAL'!R28 -> 0 | K23: ='RESUMEN TOTAL'!S28 -> 0 | L23: ='RESUMEN TOTAL'!T28 -> 0 | M23: ='RESUMEN TOTAL'!U28 -> 0 | ... AJ23: ='RESUMEN TOTAL'!AR28 -> 0
A24: ='RESUMEN TOTAL'!A29 -> BOSQUES CENTRO | B24: ='RESUMEN TOTAL'!B29 -> BOSQC 06 | C24: ='RESUMEN TOTAL'!D29 -> LUIS AGOTE Y RUTA 36 | D24: ='RESUMEN TOTAL'!E29 -> Fija | E24: ='RESUMEN TOTAL'!F29 -> PTO A FO | F24: ='RESUMEN TOTAL'!N29 -> 0 | G24: ='RESUMEN TOTAL'!O29 -> 0 | H24: ='RESUMEN TOTAL'!P29 -> 0 | I24: ='RESUMEN TOTAL'!Q29 -> 0 | J24: ='RESUMEN TOTAL'!R29 -> 0 | K24: ='RESUMEN TOTAL'!S29 -> 0 | L24: ='RESUMEN TOTAL'!T29 -> 0 | M24: ='RESUMEN TOTAL'!U29 -> 0 | ... AJ24: ='RESUMEN TOTAL'!AR29 -> 0
A25: ='RESUMEN TOTAL'!A47 -> CENTRO | B25: ='RESUMEN TOTAL'!B47 -> CEN01 | C25: ='RESUMEN TOTAL'!D47 -> San Martin y 9 de Julio | D25: ='RESUMEN TOTAL'!E47 -> Fija | E25: ='RESUMEN TOTAL'!F47 -> Fibra Optica | F25: ='RESUMEN TOTAL'!N47 -> 0 | G25: ='RESUMEN TOTAL'!O47 -> 0 | H25: ='RESUMEN TOTAL'!P47 -> 0 | I25: ='RESUMEN TOTAL'!Q47 -> 0 | J25: ='RESUMEN TOTAL'!R47 -> 0 | K25: ='RESUMEN TOTAL'!S47 -> APAGADO | L25: ='RESUMEN TOTAL'!T47 -> 0 | M25: ='RESUMEN TOTAL'!U47 -> 0 | ... AJ25: ='RESUMEN TOTAL'!AR47 -> 0
A26: ='RESUMEN TOTAL'!A48 -> CENTRO | B26: ='RESUMEN TOTAL'!B48 -> CEN02 | C26: ='RESUMEN TOTAL'!D48 -> San Martin y Almafuerte | D26: ='RESUMEN TOTAL'!E48 -> Fija | E26: ='RESUMEN TOTAL'!F48 -> Fibra Optica | F26: ='RESUMEN TOTAL'!N48 -> 0 | G26: ='RESUMEN TOTAL'!O48 -> 0 | H26: ='RESUMEN TOTAL'!P48 -> 0 | I26: ='RESUMEN TOTAL'!Q48 -> 0 | J26: ='RESUMEN TOTAL'!R48 -> 0 | K26: ='RESUMEN TOTAL'!S48 -> APAGADO | L26: ='RESUMEN TOTAL'!T48 -> 0 | M26: ='RESUMEN TOTAL'!U48 -> 0 | ... AJ26: ='RESUMEN TOTAL'!AR48 -> 0
A27: ='RESUMEN TOTAL'!A49 -> CENTRO | B27: ='RESUMEN TOTAL'!B49 -> CEN03 | C27: ='RESUMEN TOTAL'!D49 -> San Martin y Sallares | D27: ='RESUMEN TOTAL'!E49 -> Domo | E27: ='RESUMEN TOTAL'!F49 -> Fibra Optica | F27: ='RESUMEN TOTAL'!N49 -> 0 | G27: ='RESUMEN TOTAL'!O49 -> 0 | H27: ='RESUMEN TOTAL'!P49 -> 0 | I27: ='RESUMEN TOTAL'!Q49 -> 0 | J27: ='RESUMEN TOTAL'!R49 -> 0 | K27: ='RESUMEN TOTAL'!S49 -> 0 | L27: ='RESUMEN TOTAL'!T49 -> 0 | M27: ='RESUMEN TOTAL'!U49 -> 0 | ... AJ27: ='RESUMEN TOTAL'!AR49 -> 0
A28: ='RESUMEN TOTAL'!A50 -> CENTRO | B28: ='RESUMEN TOTAL'!B50 -> CEN04 | C28: ='RESUMEN TOTAL'!D50 -> San Martin y Contreras | D28: ='RESUMEN TOTAL'!E50 -> Domo | E28: ='RESUMEN TOTAL'!F50 -> Fibra Optica | F28: ='RESUMEN TOTAL'!N50 -> 0 | G28: ='RESUMEN TOTAL'!O50 -> 0 | H28: ='RESUMEN TOTAL'!P50 -> 0 | I28: ='RESUMEN TOTAL'!Q50 -> 0 | J28: ='RESUMEN TOTAL'!R50 -> 0 | K28: ='RESUMEN TOTAL'!S50 -> 0 | L28: ='RESUMEN TOTAL'!T50 -> 0 | M28: ='RESUMEN TOTAL'!U50 -> 0 | ... AJ28: ='RESUMEN TOTAL'!AR50 -> 0
A29: ='RESUMEN TOTAL'!A51 -> CENTRO | B29: ='RESUMEN TOTAL'!B51 -> CEN 05 | C29: ='RESUMEN TOTAL'!D51 -> Bocuzzi e/España y San Martin | D29: ='RESUMEN TOTAL'!E51 -> DOMO | E29: ='RESUMEN TOTAL'!F51 -> Fibra Optica | F29: ='RESUMEN TOTAL'!N51 -> 0 | G29: ='RESUMEN TOTAL'!O51 -> 0 | H29: ='RESUMEN TOTAL'!P51 -> 0 | I29: ='RESUMEN TOTAL'!Q51 -> 0 | J29: ='RESUMEN TOTAL'!R51 -> 0 | K29: ='RESUMEN TOTAL'!S51 -> 0 | L29: ='RESUMEN TOTAL'!T51 -> 0 | M29: ='RESUMEN TOTAL'!U51 -> 0 | ... AJ29: ='RESUMEN TOTAL'!AR51 -> 0
A30: ='RESUMEN TOTAL'!A52 -> CENTRO | B30: ='RESUMEN TOTAL'!B52 -> CEN06 | C30: ='RESUMEN TOTAL'!D52 -> Monteagudo y A.del Valle | D30: ='RESUMEN TOTAL'!E52 -> Fija | E30: ='RESUMEN TOTAL'!F52 -> Fibra Optica | F30: ='RESUMEN TOTAL'!N52 -> 0 | G30: ='RESUMEN TOTAL'!O52 -> APAGADO | H30: ='RESUMEN TOTAL'!P52 -> APAGADO | I30: ='RESUMEN TOTAL'!Q52 -> APAGADO | J30: ='RESUMEN TOTAL'!R52 -> 0 | K30: ='RESUMEN TOTAL'!S52 -> 0 | L30: ='RESUMEN TOTAL'!T52 -> 0 | M30: ='RESUMEN TOTAL'!U52 -> 0 | ... AJ30: ='RESUMEN TOTAL'!AR52 -> 0
A31: ='RESUMEN TOTAL'!A53 -> CENTRO | B31: ='RESUMEN TOTAL'!B53 -> CEN07 | C31: ='RESUMEN TOTAL'!D53 -> San Martin y Guemes | D31: ='RESUMEN TOTAL'!E53 -> DOMO | E31: ='RESUMEN TOTAL'!F53 -> Fibra Optica | F31: ='RESUMEN TOTAL'!N53 -> 0 | G31: ='RESUMEN TOTAL'!O53 -> 0 | H31: ='RESUMEN TOTAL'!P53 -> 0 | I31: ='RESUMEN TOTAL'!Q53 -> 0 | J31: ='RESUMEN TOTAL'!R53 -> 0 | K31: ='RESUMEN TOTAL'!S53 -> 0 | L31: ='RESUMEN TOTAL'!T53 -> 0 | M31: ='RESUMEN TOTAL'!U53 -> 0 | ... AJ31: ='RESUMEN TOTAL'!AR53 -> 0
A32: ='RESUMEN TOTAL'!A54 -> CENTRO | B32: ='RESUMEN TOTAL'!B54 -> CEN08 | C32: ='RESUMEN TOTAL'!D54 -> San Martin y Pte.Peron | D32: ='RESUMEN TOTAL'!E54 -> Domo | E32: ='RESUMEN TOTAL'!F54 -> Fibra Optica | F32: ='RESUMEN TOTAL'!N54 -> 0 | G32: ='RESUMEN TOTAL'!O54 -> 0 | H32: ='RESUMEN TOTAL'!P54 -> 0 | I32: ='RESUMEN TOTAL'!Q54 -> 0 | J32: ='RESUMEN TOTAL'!R54 -> 0 | K32: ='RESUMEN TOTAL'!S54 -> 0 | L32: ='RESUMEN TOTAL'!T54 -> 0 | M32: ='RESUMEN TOTAL'!U54 -> 0 | ... AJ32: ='RESUMEN TOTAL'!AR54 -> 0
A33: ='RESUMEN TOTAL'!A55 -> CENTRO | B33: ='RESUMEN TOTAL'!B55 -> CEN09 | C33: ='RESUMEN TOTAL'!D55 -> Chacabuco y 25 de Mayo | D33: ='RESUMEN TOTAL'!E55 -> Domo | E33: ='RESUMEN TOTAL'!F55 -> Fibra Optica | F33: ='RESUMEN TOTAL'!N55 -> 0 | G33: ='RESUMEN TOTAL'!O55 -> 0 | H33: ='RESUMEN TOTAL'!P55 -> 0 | I33: ='RESUMEN TOTAL'!Q55 -> 0 | J33: ='RESUMEN TOTAL'!R55 -> 0 | K33: ='RESUMEN TOTAL'!S55 -> 0 | L33: ='RESUMEN TOTAL'!T55 -> 0 | M33: ='RESUMEN TOTAL'!U55 -> 0 | ... AJ33: ='RESUMEN TOTAL'!AR55 -> 0
A34: ='RESUMEN TOTAL'!A56 -> CENTRO | B34: ='RESUMEN TOTAL'!B56 -> CEN10 | C34: ='RESUMEN TOTAL'!D56 -> Monteagudo y Pte. Peron | D34: ='RESUMEN TOTAL'!E56 -> Domo | E34: ='RESUMEN TOTAL'!F56 -> Fibra Optica | F34: ='RESUMEN TOTAL'!N56 -> 0 | G34: ='RESUMEN TOTAL'!O56 -> 0 | H34: ='RESUMEN TOTAL'!P56 -> 0 | I34: ='RESUMEN TOTAL'!Q56 -> 0 | J34: ='RESUMEN TOTAL'!R56 -> 0 | K34: ='RESUMEN TOTAL'!S56 -> 0 | L34: ='RESUMEN TOTAL'!T56 -> 0 | M34: ='RESUMEN TOTAL'!U56 -> 0 | ... AJ34: ='RESUMEN TOTAL'!AR56 -> 0
A35: ='RESUMEN TOTAL'!A57 -> CENTRO | B35: ='RESUMEN TOTAL'!B57 -> CEN11 | C35: ='RESUMEN TOTAL'!D57 -> Monteagudo y Bocuzzi | D35: ='RESUMEN TOTAL'!E57 -> Domo | E35: ='RESUMEN TOTAL'!F57 -> Fibra Optica | F35: ='RESUMEN TOTAL'!N57 -> 0 | G35: ='RESUMEN TOTAL'!O57 -> 0 | H35: ='RESUMEN TOTAL'!P57 -> 0 | I35: ='RESUMEN TOTAL'!Q57 -> 0 | J35: ='RESUMEN TOTAL'!R57 -> 0 | K35: ='RESUMEN TOTAL'!S57 -> 0 | L35: ='RESUMEN TOTAL'!T57 -> 0 | M35: ='RESUMEN TOTAL'!U57 -> 0 | ... AJ35: ='RESUMEN TOTAL'!AR57 -> 0
A36: ='RESUMEN TOTAL'!A58 -> CENTRO | B36: ='RESUMEN TOTAL'!B58 -> CEN 12 | C36: ='RESUMEN TOTAL'!D58 -> Monteagudo y Mitre | D36: ='RESUMEN TOTAL'!E58 -> Domo | E36: ='RESUMEN TOTAL'!F58 -> Fibra Optica | F36: ='RESUMEN TOTAL'!N58 -> 0 | G36: ='RESUMEN TOTAL'!O58 -> 0 | H36: ='RESUMEN TOTAL'!P58 -> 0 | I36: ='RESUMEN TOTAL'!Q58 -> 0 | J36: ='RESUMEN TOTAL'!R58 -> 0 | K36: ='RESUMEN TOTAL'!S58 -> 0 | L36: ='RESUMEN TOTAL'!T58 -> 0 | M36: ='RESUMEN TOTAL'!U58 -> 0 | ... AJ36: ='RESUMEN TOTAL'!AR58 -> 0
... A71: ='RESUMEN TOTAL'!A93 -> CENTRO | B71: ='RESUMEN TOTAL'!B93 -> CEN47 | C71: ='RESUMEN TOTAL'!D93 -> Sallares y Brown | D71: ='RESUMEN TOTAL'!E93 -> Domo | E71: ='RESUMEN TOTAL'!F93 -> Fibra Optica | F71: ='RESUMEN TOTAL'!N93 -> 0 | G71: ='RESUMEN TOTAL'!O93 -> 0 | H71: ='RESUMEN TOTAL'!P93 -> 0 | I71: ='RESUMEN TOTAL'!Q93 -> 0 | J71: ='RESUMEN TOTAL'!R93 -> 0 | K71: ='RESUMEN TOTAL'!S93 -> 0 | L71: ='RESUMEN TOTAL'!T93 -> 0 | M71: ='RESUMEN TOTAL'!U93 -> 0 | ... AJ71: ='RESUMEN TOTAL'!AR93 -> 0
A72: ='RESUMEN TOTAL'!A94 -> CENTRO | B72: ='RESUMEN TOTAL'!B94 -> CEN48 | C72: ='RESUMEN TOTAL'!D94 -> Velez Sarsfield y Las Heras | D72: ='RESUMEN TOTAL'!E94 -> Domo | E72: ='RESUMEN TOTAL'!F94 -> GPON | F72: ='RESUMEN TOTAL'!N94 -> 0 | G72: ='RESUMEN TOTAL'!O94 -> 0 | H72: ='RESUMEN TOTAL'!P94 -> 0 | I72: ='RESUMEN TOTAL'!Q94 -> 0 | J72: ='RESUMEN TOTAL'!R94 -> 0 | K72: ='RESUMEN TOTAL'!S94 -> 0 | L72: ='RESUMEN TOTAL'!T94 -> 0 | M72: ='RESUMEN TOTAL'!U94 -> 0 | ... Z72: ='RESUMEN TOTAL'!AH94 -> 0 | AA72: ='RESUMEN TOTAL'!#REF! -> #REF! | AB72: ='RESUMEN TOTAL'!AJ94 -> 0 | AC72: ='RESUMEN TOTAL'!AK94 -> 0 | AD72: ='RESUMEN TOTAL'!AL94 -> 0 | AE72: ='RESUMEN TOTAL'!AM94 -> 0 | AF72: ='RESUMEN TOTAL'!AN94 -> 0 | AG72: ='RESUMEN TOTAL'!AO94 -> 0 | AH72: ='RESUMEN TOTAL'!AP94 -> 0 | AI72: ='RESUMEN TOTAL'!AQ94 -> 0 | AJ72: ='RESUMEN TOTAL'!AR94 -> 0
A73: ='RESUMEN TOTAL'!A95 -> CENTRO | B73: ='RESUMEN TOTAL'!B95 -> CEN49 | C73: ='RESUMEN TOTAL'!D95 -> Av. San Martin y Florencio Sanchez | D73: ='RESUMEN TOTAL'!E95 -> Domo | E73: ='RESUMEN TOTAL'!F95 -> Fibra Optica | F73: ='RESUMEN TOTAL'!N95 -> APAGADO | G73: ='RESUMEN TOTAL'!O95 -> APAGADO | H73: ='RESUMEN TOTAL'!P95 -> APAGADO | I73: ='RESUMEN TOTAL'!Q95 -> APAGADO | J73: ='RESUMEN TOTAL'!R95 -> APAGADO | K73: ='RESUMEN TOTAL'!S95 -> APAGADO | L73: ='RESUMEN TOTAL'!T95 -> APAGADO | M73: ='RESUMEN TOTAL'!U95 -> 0 | ... AJ73: ='RESUMEN TOTAL'!AR95 -> 0
A74: ='RESUMEN TOTAL'!A96 -> CENTRO | B74: ='RESUMEN TOTAL'!B96 -> CEN 50 | C74: ='RESUMEN TOTAL'!D96 -> Av. San Martin y Newbery | D74: ='RESUMEN TOTAL'!E96 -> Domo | E74: ='RESUMEN TOTAL'!F96 -> GPON | F74: ='RESUMEN TOTAL'!N96 -> APAGADO | G74: ='RESUMEN TOTAL'!O96 -> 0 | H74: ='RESUMEN TOTAL'!P96 -> 0 | I74: ='RESUMEN TOTAL'!Q96 -> 0 | J74: ='RESUMEN TOTAL'!R96 -> 0 | K74: ='RESUMEN TOTAL'!S96 -> 0 | L74: ='RESUMEN TOTAL'!T96 -> 0 | M74: ='RESUMEN TOTAL'!U96 -> 0 | ... AJ74: ='RESUMEN TOTAL'!AR96 -> 0
...

Sheet Hoja1
B1: CAMARAS | C1: 45992
A2: BONOMO | B2: =COUNTIFS('RESUMEN TOTAL'!C8:C621,"=BONOMO") -> 307 | C2: 0 | F2: 46082 | G2: 46083 | H2: 46084 | I2: 46085 | J2: 46086 | K2: 46087 | L2: 46088 | M2: 46089 | N2: 46090 | O2: 46091 | P2: 46092 | Q2: 46093 | R2: 46094 | S2: 46095 | T2: 46096 | U2: 46097 | V2: 46098 | W2: 46099 | X2: 46100 | Y2: 46101 | Z2: 46102 | AA2: 46103 | AB2: 46104 | AC2: 46105 | AD2: 46106 | AE2: 46107 | AF2: 46108 | AG2: 46109 | AH2: 46110 | AI2: 46111 | AJ2: 46112
C3: 0 | D3: BONOMO | E3: APAGADAS BONOMO | F3: 0 | G3: 27 | H3: 31 | I3: 29 | J3: 29 | K3: =COUNTIFS('RESUMEN TOTAL'!S8:S698,"=APAGADO",'RESUMEN TOTAL'!C8:C698,"=BONOMO") -> 44 | L3: 0 | M3: 0 | N3: =COUNTIFS('RESUMEN TOTAL'!V8:V698,"=APAGADO",'RESUMEN TOTAL'!C8:C698,"=BONOMO") -> 25 | O3: =COUNTIFS('RESUMEN TOTAL'!W8:W698,"=APAGADO",'RESUMEN TOTAL'!C8:C698,"=BONOMO") -> 28 | P3: =COUNTIFS('RESUMEN TOTAL'!X8:X698,"=APAGADO",'RESUMEN TOTAL'!C8:C698,"=BONOMO") -> 26 | Q3: =COUNTIFS('RESUMEN TOTAL'!Y8:Y698,"=APAGADO",'RESUMEN TOTAL'!C8:C698,"=BONOMO") -> 27 | R3: =COUNTIFS('RESUMEN TOTAL'!Z8:Z698,"=APAGADO",'RESUMEN TOTAL'!C8:C698,"=BONOMO") -> 27 | S3: =COUNTIFS('RESUMEN TOTAL'!AA8:AA698,"=APAGADO",'RESUMEN TOTAL'!C8:C698,"=BONOMO") -> 0 | T3: =COUNTIFS('RESUMEN TOTAL'!AB8:AB698,"=APAGADO",'RESUMEN TOTAL'!C8:C698,"=BONOMO") -> 0 | U3: =COUNTIFS('RESUMEN TOTAL'!AC8:AC698,"=APAGADO",'RESUMEN TOTAL'!C8:C698,"=BONOMO") -> 30 | V3: =COUNTIFS('RESUMEN TOTAL'!AD8:AD698,"=APAGADO",'RESUMEN TOTAL'!C8:C698,"=BONOMO") -> 26 | W3: =COUNTIFS('RESUMEN TOTAL'!AE8:AE698,"=APAGADO",'RESUMEN TOTAL'!C8:C698,"=BONOMO") -> 0 | X3: =COUNTIFS('RESUMEN TOTAL'!AF8:AF698,"=APAGADO",'RESUMEN TOTAL'!C8:C698,"=BONOMO") -> 0 | Y3: =COUNTIFS('RESUMEN TOTAL'!AG8:AG698,"=APAGADO",'RESUMEN TOTAL'!C8:C698,"=BONOMO") -> 0 | Z3: =COUNTIFS('RESUMEN TOTAL'!AH8:AH698,"=APAGADO",'RESUMEN TOTAL'!C8:C698,"=BONOMO") -> 0 | AA3: =COUNTIFS('RESUMEN TOTAL'!AI8:AI698,"=APAGADO",'RESUMEN TOTAL'!C8:C698,"=BONOMO") -> 0 | AB3: =COUNTIFS('RESUMEN TOTAL'!AJ8:AJ698,"=APAGADO",'RESUMEN TOTAL'!C8:C698,"=BONOMO") -> 0 | AC3: =COUNTIFS('RESUMEN TOTAL'!AK8:AK698,"=APAGADO",'RESUMEN TOTAL'!C8:C698,"=BONOMO") -> 0 | AD3: =COUNTIFS('RESUMEN TOTAL'!AL8:AL698,"=APAGADO",'RESUMEN TOTAL'!C8:C698,"=BONOMO") -> 0 | AE3: 29 | AF3: =COUNTIFS('RESUMEN TOTAL'!AN8:AN698,"=APAGADO",'RESUMEN TOTAL'!C8:C698,"=BONOMO") -> 0 | AG3: =COUNTIFS('RESUMEN TOTAL'!AO8:AO698,"=APAGADO",'RESUMEN TOTAL'!C8:C698,"=BONOMO") -> 0 | AH3: =COUNTIFS('RESUMEN TOTAL'!AP8:AP698,"=APAGADO",'RESUMEN TOTAL'!D8:D698,"=BONOMO") -> 0 | AI3: =COUNTIFS('RESUMEN TOTAL'!AQ8:AQ698,"=APAGADO",'RESUMEN TOTAL'!E8:E698,"=BONOMO") -> 0 | AJ3: =COUNTIFS('RESUMEN TOTAL'!AR8:AR698,"=APAGADO",'RESUMEN TOTAL'!F8:F698,"=BONOMO") -> 0
A4: COSEIDI | B4: =COUNTIFS('RESUMEN TOTAL'!C8:C621,"=COSEIDI") -> 277 | C4: 0 | E4: % BONOMO | F4: 0 | G4: =G3/BONOMOcam -> 0.087947883 | H4: =H3/BONOMOcam -> 0.1009772 | I4: 0 | J4: 0.09 | K4: =K3/BONOMOcam -> 0.14332248 | L4: =L3/BONOMOcam -> 0 | M4: 0 | N4: =N3/BONOMOcam -> 0.081433225 | O4: =O3/BONOMOcam -> 0.091205212 | P4: =P3/BONOMOcam -> 0.084690554 | Q4: =Q3/BONOMOcam -> 0.087947883 | R4: =R3/BONOMOcam -> 0.087947883 | S4: =S3/BONOMOcam -> 0 | T4: =T3/BONOMOcam -> 0 | U4: =U3/BONOMOcam -> 0.09771987 | V4: =V3/BONOMOcam -> 0.084690554 | W4: 0 | X4: =X3/BONOMOcam -> 0 | Y4: =Y3/BONOMOcam -> 0 | Z4: =Z3/BONOMOcam -> 0 | AA4: =AA3/BONOMOcam -> 0 | AB4: =AB3/BONOMOcam -> 0 | AC4: 0 | AD4: =AD3/BONOMOcam -> 0 | AE4: =AE3/BONOMOcam -> 0.094462541 | AF4: =AF3/BONOMOcam -> 0 | AG4: =AG3/BONOMOcam -> 0 | AH4: =AH3/BONOMOcam -> 0 | AI4: =AI3/BONOMOcam -> 0 | AJ4: =AJ3/BONOMOcam -> 0
C5: 0 | D5: COSEIDI | E5: APAGADAS COSEIDI | F5: 0 | G5: 41 | H5: 52 | I5: 56 | J5: =COUNTIFS('RESUMEN TOTAL'!R10:R700,"=APAGADO",'RESUMEN TOTAL'!C10:C700,"=COSEIDI") -> 60 | K5: =COUNTIFS('RESUMEN TOTAL'!S10:S700,"=APAGADO",'RESUMEN TOTAL'!C10:C700,"=COSEIDI") -> 54 | L5: =COUNTIFS('RESUMEN TOTAL'!T10:T700,"=APAGADO",'RESUMEN TOTAL'!C10:C700,"=COSEIDI") -> 50 | M5: 0 | N5: =COUNTIFS('RESUMEN TOTAL'!V10:V700,"=APAGADO",'RESUMEN TOTAL'!C10:C700,"=COSEIDI") -> 55 | O5: =COUNTIFS('RESUMEN TOTAL'!W10:W700,"=APAGADO",'RESUMEN TOTAL'!C10:C700,"=COSEIDI") -> 45 | P5: =COUNTIFS('RESUMEN TOTAL'!X10:X700,"=APAGADO",'RESUMEN TOTAL'!C10:C700,"=COSEIDI") -> 41 | Q5: =COUNTIFS('RESUMEN TOTAL'!Y10:Y700,"=APAGADO",'RESUMEN TOTAL'!C10:C700,"=COSEIDI") -> 41 | R5: =COUNTIFS('RESUMEN TOTAL'!Z10:Z700,"=APAGADO",'RESUMEN TOTAL'!C10:C700,"=COSEIDI") -> 37 | S5: =COUNTIFS('RESUMEN TOTAL'!AA10:AA700,"=APAGADO",'RESUMEN TOTAL'!C10:C700,"=COSEIDI") -> 0 | T5: 0 | U5: =COUNTIFS('RESUMEN TOTAL'!Z10:Z700,"=APAGADO",'RESUMEN TOTAL'!C10:C700,"=COSEIDI") -> 37 | V5: =COUNTIFS('RESUMEN TOTAL'!AD10:AD700,"=APAGADO",'RESUMEN TOTAL'!C10:C700,"=COSEIDI") -> 42 | W5: =COUNTIFS('RESUMEN TOTAL'!AE10:AE700,"=APAGADO",'RESUMEN TOTAL'!C10:C700,"=COSEIDI") -> 0 | X5: =COUNTIFS('RESUMEN TOTAL'!AF10:AF700,"=APAGADO",'RESUMEN TOTAL'!C10:C700,"=COSEIDI") -> 0 | Y5: =COUNTIFS('RESUMEN TOTAL'!AG10:AG700,"=APAGADO",'RESUMEN TOTAL'!C10:C700,"=COSEIDI") -> 0 | Z5: =COUNTIFS('RESUMEN TOTAL'!AH10:AH700,"=APAGADO",'RESUMEN TOTAL'!C10:C700,"=COSEIDI") -> 0 | AA5: =COUNTIFS('RESUMEN TOTAL'!AI10:AI700,"=APAGADO",'RESUMEN TOTAL'!C10:C700,"=COSEIDI") -> 0 | AB5: =COUNTIFS('RESUMEN TOTAL'!AJ10:AJ700,"=APAGADO",'RESUMEN TOTAL'!C10:C700,"=COSEIDI") -> 0 | AC5: =COUNTIFS('RESUMEN TOTAL'!AK10:AK700,"=APAGADO",'RESUMEN TOTAL'!C10:C700,"=COSEIDI") -> 0 | AD5: =COUNTIFS('RESUMEN TOTAL'!AL10:AL700,"=APAGADO",'RESUMEN TOTAL'!C10:C700,"=COSEIDI") -> 0 | AE5: =COUNTIFS('RESUMEN TOTAL'!AM10:AM700,"=APAGADO",'RESUMEN TOTAL'!C10:C700,"=COSEIDI") -> 0 | AF5: =COUNTIFS('RESUMEN TOTAL'!AN10:AN700,"=APAGADO",'RESUMEN TOTAL'!C10:C700,"=COSEIDI") -> 0 | AG5: 0 | AH5: 0 | AI5: 0 | AJ5: 0
E6: % COSEIDI | F6: 0 | G6: =G5/COSEIDIcam -> 0.14801444 | H6: 0.18 | I6: 0 | J6: 0.14 | K6: =K5/COSEIDIcam -> 0.19494585 | L6: =L5/COSEIDIcam -> 0.18050542 | M6: 0 | N6: =N5/COSEIDIcam -> 0.19855596 | O6: =O5/COSEIDIcam -> 0.16245487 | P6: 0 | Q6: =Q5/COSEIDIcam -> 0.14801444 | R6: =R5/COSEIDIcam -> 0.13357401 | S6: =S5/COSEIDIcam -> 0 | T6: 0 | U6: 0 | V6: 0 | W6: =W5/COSEIDIcam -> 0 | X6: =X5/COSEIDIcam -> 0 | Y6: =Y5/COSEIDIcam -> 0 | Z6: =Z5/COSEIDIcam -> 0 | AA6: =AA5/COSEIDIcam -> 0 | AB6: =AB5/COSEIDIcam -> 0 | AC6: 0 | AD6: =AD5/COSEIDIcam -> 0 | AE6: =AE5/COSEIDIcam -> 0 | AF6: =AF5/COSEIDIcam -> 0 | AG6: 0 | AH6: 0 | AI6: 0 | AJ6: 0

Sheet informe
C1: CANTIDAD | D1: APAGADAS | E1: %
B2: TOTAL | C2: =CANTIDAD_DE_CAMARAS -> 584 | F2: 46082
A3: L | B3: CAIDAS | C3: ='RESUMEN TOTAL'!N3 -> 80 | E3: =C3/C2 -> 0.1369863
B4: LLEGAMOS NOSOTROS | C4: 0 | D4: 0 | E4: =D4/C2 -> 0
B5: NO ESTA LA CAMARA | C5: 0 | D5: 0 | E5: =D5/C2 -> 0
A6: L | B6: RADIO | C6: 0 | D6: 0 | E6: =D6/C2 -> 0
C7: 0 | D7: 0 | E7: =D7/C2 -> 0
C8: CANTIDAD | D8: APAGADAS | E8: %
A9: F | B9: BONOMO | C9: 307
A10: F | B10: COSEIDI | C10: =COSEIDIcam -> 277 | D10: =Hoja1!F5 -> 0
C12: CANTIDAD | D12: APAGADAS | E12: %
B13: TOTAL | C13: =CANTIDAD_DE_CAMARAS -> 584 | F13: 46083
A14: M | B14: CAIDAS | C14: 87 | E14: =C14/C13 -> 0.1489726
B15: LLEGAMOS NOSOTROS | C15: 3 | D15: 84 | E15: =D15/C13 -> 0.14383562
B16: NO ESTA LA CAMARA | C16: 7 | D16: 77 | E16: =D16/C13 -> 0.13184932
A17: M | B17: RADIO | C17: 5 | D17: 72 | E17: =D17/C13 -> 0.12328767
D18: 0 | E18: =D18/C13 -> 0
C19: CANTIDAD | D19: APAGADAS | E19: %
A20: G | B20: BONOMO | C20: 307 | D20: 32 | E20: =D20/C20 -> 0.10423453
A21: G | B21: COSEIDI | C21: =COSEIDIcam -> 277 | D21: 55 | E21: =D21/C21 -> 0.19855596
C23: CANTIDAD | D23: APAGADAS | E23: %
B24: TOTAL | C24: =CANTIDAD_DE_CAMARAS -> 584 | F24: 46084
A25: N | B25: CAIDAS | C25: ='RESUMEN TOTAL'!P3 -> 83 | E25: =C25/C24 -> 0.14212329
B26: LLEGAMOS NOSOTROS | C26: 6 | D26: =C25-C26 -> 77 | E26: =D26/C24 -> 0.13184932
B27: NO ESTA LA CAMARA | C27: 7 | D27: =D26-C27 -> 70 | E27: =D27/C24 -> 0.11986301
A28: N | B28: RADIO | C28: ='RESUMEN TOTAL'!P5 -> 5 | D28: =D27-C28 -> 65 | E28: =D28/C24 -> 0.11130137
C29: 0 | D29: 0 | E29: =D29/C24 -> 0
C30: CANTIDAD | D30: APAGADAS | E30: %
B31: BONOMO | C31: 307 | D31: 31 | E31: =D31/C31 -> 0.1009772
B32: COSEIDI | C32: =COSEIDIcam -> 277 | D32: 52 | E32: =D32/C32 -> 0.18772563
C34: CANTIDAD | D34: APAGADAS | E34: %
B35: TOTAL | C35: =CANTIDAD_DE_CAMARAS -> 584 | F35: 46085
A36: O | B36: CAIDAS | C36: ='RESUMEN TOTAL'!Q3 -> 85 | E36: =C36/C35 -> 0.14554795
B37: LLEGAMOS NOSOTROS | C37: 7 | D37: =C36-C37 -> 78 | E37: =D37/C35 -> 0.13356164
B38: NO ESTA LA CAMARA | C38: 7 | D38: =D37-C38 -> 71 | E38: =D38/C35 -> 0.12157534
A39: O | B39: RADIO | C39: 6 | D39: =D38-C39 -> 65 | E39: =D39/C35 -> 0.11130137
C40: 0 | D40: 0 | E40: =D40/C35 -> 0
C41: CANTIDAD | D41: APAGADAS | E41: %
B42: BONOMO | C42: 307 | D42: =Hoja1!I3 -> 29 | E42: =D42/C42 -> 0.094462541
B43: COSEIDI | C43: =COSEIDIcam -> 277 | D43: =Hoja1!I5 -> 56 | E43: =D43/C43 -> 0.20216606
...
