Workbook
Name _25_de_agosto: 'RESUMEN TOTAL'!$F$7:$I$503
Name _25_de_agosto_3: 'RESUMEN TOTAL'!$F$7:$I$515
Name _30_mar: #REF!
Name BONOMOcam: Hoja1!$B$2
Name CANTIDAD_DE_CAMARAS: 'RESUMEN TOTAL'!$G$1
Name COSEIDIcam: Hoja1!$B$4

Sheet RESUMEN TOTAL
E1: < | F1: CANTIDAD DE CAMARAS | G1: =COUNTA(G8:G752) -> 591 | I1: PORCIENTO DE CAIDAS | S1: =(S3)/(S2+S3) -> 0 | T1: =(T3)/(T2+T3) -> 0 | U1: =(U3)/(U2+U3) -> 0 | V1: =(V3)/(V2+V3) -> 0.16288952 | W1: =(W3)/(W2+W3) -> 0.15811966 | X1: =(X3)/(X2+X3) -> 0.15691869 | Y1: =(Y3)/(Y2+Y3) -> 0.16407355 | Z1: =(Z3)/(Z2+Z3) -> 0.14223512 | ... AE1: =(AE3)/(AE2+AE3) -> 0.16407355 | AG1: =(AG3)/(AG2+AG3) -> 0.16994382 | AH1: =(AH3)/(AH2+AH3) -> 0 | AI1: =(AI3)/(AI2+AI3) -> 0 | AJ1: =(AJ3)/(AJ2+AJ3) -> 0.15691869 | AK1: =(AK3)/(AK2+AK3) -> 0.15450644 | AL1: =(AL3)/(AL2+AL3) -> 0.1447178 | AM1: =(AM3)/(AM2+AM3) -> 0.1231454 | AN1: =(AN3)/(AN2+AN3) -> 0 | ... AV1: =(AV3)/(AV2+AV3) -> 0
I2: FUNCIONAN | S2: =CANTIDAD_DE_CAMARAS -> 591 | T2: =CANTIDAD_DE_CAMARAS -> 591 | U2: =CANTIDAD_DE_CAMARAS -> 591 | V2: =CANTIDAD_DE_CAMARAS -> 591 | W2: =CANTIDAD_DE_CAMARAS -> 591 | X2: =CANTIDAD_DE_CAMARAS -> 591 | Y2: =CANTIDAD_DE_CAMARAS -> 591 | Z2: =CANTIDAD_DE_CAMARAS -> 591 | ... AV2: =CANTIDAD_DE_CAMARAS -> 591
I3: CAIDAS | S3: =COUNTIF(S7:S752, "apagado") -> 0 | T3: =COUNTIF(T7:T752, "apagado") -> 0 | U3: =COUNTIF(U7:U752, "apagado") -> 0 | V3: =COUNTIF(V7:V752, "apagado") -> 115 | W3: =COUNTIF(W7:W752, "apagado") -> 111 | X3: =COUNTIF(X7:X752, "apagado") -> 110 | Y3: =COUNTIF(Y7:Y752, "apagado") -> 116 | Z3: =COUNTIF(Z7:Z752, "apagado") -> 98 | ... AV3: =COUNTIF(AV7:AV752, "apagado") -> 0
I4: APAGADOS FIBRA | S4: =COUNTIFS(S8:S706, "=APAGADO",K8:K706,"=Fibra Optica") -> 0 | T4: =COUNTIFS(T8:T706, "=APAGADO",K8:K706,"=Fibra Optica") -> 0 | U4: =COUNTIFS(U8:U706, "=APAGADO",K8:K706,"=Fibra Optica") -> 0 | V4: =COUNTIFS(V8:V706, "=APAGADO",K8:K706,"=Fibra Optica") -> 44 | W4: =COUNTIFS(W8:W706, "=APAGADO",K8:K706,"=Fibra Optica") -> 43 | X4: =COUNTIFS(X8:X706, "=APAGADO",K8:K706,"=Fibra Optica") -> 44 | Y4: =COUNTIFS(Y8:Y706, "=APAGADO",K8:K706,"=Fibra Optica") -> 51 | Z4: =COUNTIFS(Z8:Z706, "=APAGADO",K8:K706,"=Fibra Optica") -> 43 | AA4: =COUNTIFS(AA8:AA706, "=APAGADO",K8:K706,"=Fibra Optica") -> 0 | AB4: =COUNTIFS(AB8:AB706, "=APAGADO",K8:K706,"=Fibra Optica") -> 0 | AC4: =COUNTIFS(AC8:AC706, "=APAGADO",K8:K706,"=Fibra Optica") -> 47 | AD4: =COUNTIFS(AD8:AD706, "=APAGADO",K8:K706,"=Fibra Optica") -> 42 | AE4: =COUNTIFS(AE8:AE706, "=APAGADO",K8:K706,"=Fibra Optica") -> 48 | AF4: =COUNTIFS(AF8:AF706, "=APAGADO",K8:K706,"=Fibra Optica") -> 46 | AG4: =COUNTIFS(AG8:AG706, "=APAGADO",K8:K706,"=Fibra Optica") -> 50 | AH4: =COUNTIFS(AH8:AH706, "=APAGADO",K8:K706,"=Fibra Optica") -> 0 | AI4: =COUNTIFS(AI8:AI706, "=APAGADO",K8:K706,"=Fibra Optica") -> 0 | AJ4: =COUNTIFS(AJ8:AJ706, "=APAGADO",K8:K706,"=Fibra Optica") -> 42 | AK4: =COUNTIFS(AK8:AK706, "=APAGADO",K8:K706,"=Fibra Optica") -> 34 | AL4: =COUNTIFS(AL8:AL706, "=APAGADO",K8:K706,"=Fibra Optica") -> 29 | AM4: =COUNTIFS(AM8:AM706, "=APAGADO",K8:K706,"=Fibra Optica") -> 25 | AN4: =COUNTIFS(AN8:AN706, "=APAGADO",K8:K706,"=Fibra Optica") -> 0 | AO4: =COUNTIFS(AO8:AO706, "=APAGADO",K8:K706,"=Fibra Optica") -> 0 | AP4: =COUNTIFS(AP8:AP706, "=APAGADO",K8:K706,"=Fibra Optica") -> 0 | AQ4: =COUNTIFS(AQ8:AQ706, "=APAGADO",K8:K706,"=Fibra Optica") -> 0 | AR4: =COUNTIFS(AR8:AR706, "=APAGADO",K8:K706,"=Fibra Optica") -> 0 | AS4: =COUNTIFS(AS8:AS706, "=APAGADO",K8:K706,"=Fibra Optica") -> 0 | AT4: =COUNTIFS(AT8:AT706, "=APAGADO",K8:K706,"=Fibra Optica") -> 0 | AU4: =COUNTIFS(AU8:AU706, "=APAGADO",L8:L706,"=Fibra Optica") -> 0 | AV4: =COUNTIFS(AV8:AV706, "=APAGADO",M8:M706,"=Fibra Optica") -> 0
I5: APAGADOS RADIO | S5: =COUNTIFS(S8:S706, "=APAGADO",K8:K706,"=RADIO") -> 0 | T5: =COUNTIFS(T8:T706, "=APAGADO",K8:K706,"=RADIO") -> 0 | U5: =COUNTIFS(U8:U706, "=APAGADO",K8:K706,"=RADIO") -> 0 | V5: =COUNTIFS(V8:V706, "=APAGADO",K8:K706,"=RADIO") -> 5 | W5: =COUNTIFS(W8:W706, "=APAGADO",K8:K706,"=RADIO") -> 5 | X5: =COUNTIFS(X8:X706, "=APAGADO",K8:K706,"=RADIO") -> 6 | Y5: =COUNTIFS(Y8:Y706, "=APAGADO",K8:K706,"=RADIO") -> 6 | Z5: =COUNTIFS(Z8:Z706, "=APAGADO",K8:K706,"=RADIO") -> 5 | AA5: =COUNTIFS(AA8:AA706, "=APAGADO",K8:K706,"=RADIO") -> 0 | AB5: =COUNTIFS(AB8:AB706, "=APAGADO",K8:K706,"=RADIO") -> 0 | AC5: =COUNTIFS(AC8:AC706, "=APAGADO",K8:K706,"=RADIO") -> 6 | AD5: =COUNTIFS(AD8:AD706, "=APAGADO",K8:K706,"=RADIO") -> 5 | AE5: =COUNTIFS(AE8:AE706, "=APAGADO",K8:K706,"=RADIO") -> 6 | AF5: =COUNTIFS(AF8:AF706, "=APAGADO",K8:K706,"=RADIO") -> 5 | AG5: =COUNTIFS(AG8:AG706, "=APAGADO",K8:K706,"=RADIO") -> 5 | AH5: =COUNTIFS(AH8:AH706, "=APAGADO",K8:K706,"=RADIO") -> 0 | AI5: =COUNTIFS(AI8:AI706, "=APAGADO",K8:K706,"=RADIO") -> 0 | AJ5: =COUNTIFS(AJ8:AJ706, "=APAGADO",K8:K706,"=RADIO") -> 6 | AK5: =COUNTIFS(AK8:AK706, "=APAGADO",K8:K706,"=RADIO") -> 6 | AL5: =COUNTIFS(AL8:AL706, "=APAGADO",K8:K706,"=RADIO") -> 6 | AM5: =COUNTIFS(AM8:AM706, "=APAGADO",K8:K706,"=RADIO") -> 5 | AN5: =COUNTIFS(AN8:AN706, "=APAGADO",K8:K706,"=RADIO") -> 0 | AO5: =COUNTIFS(AO8:AO706, "=APAGADO",K8:K706,"=RADIO") -> 0 | AP5: =COUNTIFS(AP8:AP706, "=APAGADO",K8:K706,"=RADIO") -> 0 | AQ5: =COUNTIFS(AQ8:AQ706, "=APAGADO",K8:K706,"=RADIO") -> 0 | AR5: =COUNTIFS(AR8:AR706, "=APAGADO",K8:K706,"=RADIO") -> 0 | AS5: =COUNTIFS(AS8:AS706, "=APAGADO",K8:K706,"=RADIO") -> 0 | AT5: =COUNTIFS(AT8:AT706, "=APAGADO",K8:K706,"=RADIO") -> 0 | AU5: =COUNTIFS(AU8:AU706, "=APAGADO",L8:L706,"=RADIO") -> 0 | AV5: =COUNTIFS(AV8:AV706, "=APAGADO",M8:M706,"=RADIO") -> 0
I6: APAGADOS ANTENA | S6: =COUNTIFS(S8:S706, "=APAGADO",K8:K706,"=PTO A FO") -> 0 | T6: =COUNTIFS(T8:T706, "=APAGADO",K8:K706,"=PTO A FO") -> 0 | U6: =COUNTIFS(U8:U706, "=APAGADO",K8:K706,"=PTO A FO") -> 0 | V6: =COUNTIFS(V8:V706, "=APAGADO",K8:K706,"=PTO A FO") -> 12 | W6: =COUNTIFS(W8:W706, "=APAGADO",K8:K706,"=PTO A FO") -> 12 | X6: =COUNTIFS(X8:X706, "=APAGADO",K8:K706,"=PTO A FO") -> 11 | Y6: =COUNTIFS(Y8:Y706, "=APAGADO",K8:K706,"=PTO A FO") -> 14 | Z6: =COUNTIFS(Z8:Z706, "=APAGADO",K8:K706,"=PTO A FO") -> 10 | AA6: =COUNTIFS(AA8:AA706, "=APAGADO",K8:K706,"=PTO A FO") -> 0 | AB6: =COUNTIFS(AB8:AB706, "=APAGADO",K8:K706,"=PTO A FO") -> 0 | AC6: =COUNTIFS(AC8:AC706, "=APAGADO",K8:K706,"=PTO A FO") -> 8 | AD6: =COUNTIFS(AD8:AD706, "=APAGADO",K8:K706,"=PTO A FO") -> 9 | AE6: =COUNTIFS(AE8:AE706, "=APAGADO",K8:K706,"=PTO A FO") -> 9 | AF6: =COUNTIFS(AF8:AF706, "=APAGADO",K8:K706,"=PTO A FO") -> 11 | AG6: =COUNTIFS(AG8:AG706, "=APAGADO",K8:K706,"=PTO A FO") -> 11 | AH6: =COUNTIFS(AH8:AH706, "=APAGADO",K8:K706,"=PTO A FO") -> 0 | AI6: =COUNTIFS(AI8:AI706, "=APAGADO",K8:K706,"=PTO A FO") -> 0 | AJ6: =COUNTIFS(AJ8:AJ706, "=APAGADO",K8:K706,"=PTO A FO") -> 10 | AK6: =COUNTIFS(AK8:AK706, "=APAGADO",K8:K706,"=PTO A FO") -> 13 | AL6: =COUNTIFS(AL8:AL706, "=APAGADO",K8:K706,"=PTO A FO") -> 12 | AM6: =COUNTIFS(AM8:AM706, "=APAGADO",K8:K706,"=PTO A FO") -> 7 | AN6: =COUNTIFS(AN8:AN706, "=APAGADO",K8:K706,"=PTO A FO") -> 0 | AO6: =COUNTIFS(AO8:AO706, "=APAGADO",K8:K706,"=PTO A FO") -> 0 | AP6: =COUNTIFS(AP8:AP706, "=APAGADO",K8:K706,"=PTO A FO") -> 0 | AQ6: =COUNTIFS(AQ8:AQ706, "=APAGADO",K8:K706,"=PTO A FO") -> 0 | AR6: =COUNTIFS(AR8:AR706, "=APAGADO",K8:K706,"=PTO A FO") -> 0 | AS6: =COUNTIFS(AS8:AS706, "=APAGADO",K8:K706,"=PTO A FO") -> 0 | AT6: =COUNTIFS(AT8:AT706, "=APAGADO",K8:K706,"=PTO A FO") -> 0 | AU6: =COUNTIFS(AU8:AU706, "=APAGADO",L8:L706,"=PTO A FO") -> 0 | AV6: =COUNTIFS(AV8:AV706, "=APAGADO",M8:M706,"=PTO A FO") -> 0
A7: BANDEJA | B7: PELO | C7: SWITCH | D7: PUERTO | E7: NOMBRE | F7: Barrio | G7: [Denominacion] | H7: [Empresa Mantenimiento] | I7: [Ubicacion] | J7: [Tipo de Camara] | K7: [Tipo de Conexion] | L7: Destino | M7: [IP] | N7: Switch | O7: DIAS FUNCIONANDO | P7: MAC | Q7: DIAS CAIDA | R7: EFECTIVIDAD | S7: 46143 | T7: 46144 | U7: 46145 | V7: 46146 | W7: 46147 | X7: 46148 | Y7: 46149 | Z7: 46150 | AA7: 46151 | AB7: 46152 | AC7: 46153 | AD7: 46154 | AE7: 46155 | AF7: 46156 | AG7: 46157 | AH7: 46158 | AI7: 46159 | AJ7: 46160 | AK7: 46161 | AL7: 46162 | AM7: 46163 | AN7: 46164 | AO7: 46165 | AP7: 46166 | AQ7: 46167 | AR7: 46168 | AS7: 46169 | AT7: 46170 | AU7: 46171 | AV7: 46172 | AW7: 46173
E8: PON 13 | F8: ALTAMIRA | G8: ALT 03 | H8: BONOMO | I8: Bombero Galarza y Necochea | J8: Domo | K8: GPON | M8: 172.20.12.54 | O8: =COUNTIF(S8:AT8,"") -> 28 | P8: 00-07-5F-87-9D-EF | Q8: =COUNTIF(S8:AT8,"APAGADO") -> 0 | R8: =(O8)/(Q8+O8) -> 1
E9: PON 13 | F9: ALTAMIRA | G9: ALT 04 | H9: BONOMO | I9: Francia y Necochea | J9: Domo | K9: GPON | M9: 172.20.12.55 | O9: =COUNTIF(S9:AT9,"") -> 28 | P9: 00-04-63-59-22-57 | Q9: =COUNTIF(S9:AT9,"APAGADO") -> 0 | R9: =(O9)/(Q9+O9) -> 1
E10: PON 13 | F10: ALTAMIRA | G10: ALT 06 | H10: BONOMO | I10: LOPE DE VEGA Y NECOCHEA | J10: Domo | K10: GPON | L10: NECOCHEA Y GALARZA | M10: 172.20.12.12 | O10: =COUNTIF(S10:AT10,"") -> 28 | P10: 00-04-63-4F-DD-DB | Q10: =COUNTIF(S10:AT10,"APAGADO") -> 0 | R10: =(O10)/(Q10+O10) -> 1
E11: PON 13 | F11: ALTAMIRA | G11: ALT 08 | H11: BONOMO | I11: HUMAITA Y NECOCHEA | J11: DOMO | K11: GPON A FO | M11: 172.20.11.215 | O11: =COUNTIF(S11:AT11,"") -> 26 | P11: 00-07-5F-BE-59-2D | Q11: =COUNTIF(S11:AT11,"APAGADO") -> 2 | R11: =(O11)/(Q11+O11) -> 0.92857143 | V11: APAGADO | W11: APAGADO
E12: PON 13 | F12: ALTAMIRA | G12: ALT 09 | H12: BONOMO | I12: NECOCHEA Y CURUPAITY | J12: DOMO | K12: GPON A FO | M12: 172.20.11.216 | O12: =COUNTIF(S12:AT12,"") -> 26 | P12: 00-07-5F-BE-59-27 | Q12: =COUNTIF(S12:AT12,"APAGADO") -> 2 | R12: =(O12)/(Q12+O12) -> 0.92857143 | V12: APAGADO | W12: APAGADO
E13: PON 13 | F13: ALTAMIRA | G13: ALT 10 | H13: BONOMO | I13: Calchaqui y Francia | J13: Domo | K13: GPON | M13: 172.20.12.156 | O13: =COUNTIF(S13:AT13,"") -> 28 | P13: 00-07-5F-AB-BB-41 | Q13: =COUNTIF(S13:AT13,"APAGADO") -> 0 | R13: =(O13)/(Q13+O13) -> 1
E14: PON 13 | F14: ALTAMIRA | G14: ALT 11 | H14: BONOMO | I14: CALCHAQUÍ Y GALARZA FIJA | J14: Fija | K14: GPON | M14: 172.20.12.241 | O14: =COUNTIF(S14:AT14,"") -> 28 | P14: 3c-1b-f8-df-95-58 | Q14: =COUNTIF(S14:AT14,"APAGADO") -> 0 | R14: =(O14)/(Q14+O14) -> 1
A15: 1 | B15: 19 | E15: YRIGOYEN-ISLAS ORCADAS | F15: ALTAMIRA | G15: ALT01 | H15: BONOMO | I15: Calchaqui y Sgto. Cabral | J15: Domo | K15: Fibra Optica | M15: 172.20.10.6 | O15: =COUNTIF(S15:AT15,"") -> 28 | P15: 00-07-5F-87-83-56 | Q15: =COUNTIF(S15:AT15,"APAGADO") -> 0 | R15: =(O15)/(Q15+O15) -> 1
A16: 1 | B16: 19 | E16: YRIGOYEN-ISLAS ORCADAS | F16: ALTAMIRA | G16: ALT02 | H16: BONOMO | I16: Calchaqui y Lope de Vega | J16: Domo | K16: PTO A FO | L16: CABRAL Y CALCHAQUI | M16: 172.20.12.218 | O16: =COUNTIF(S16:AT16,"") -> 28 | P16: 00-04-63-50-42-A4 | Q16: =COUNTIF(S16:AT16,"APAGADO") -> 0 | R16: =(O16)/(Q16+O16) -> 1
E17: PON 13 | F17: ALTAMIRA | G17: ALT05 | H17: BONOMO | I17: Av. Calchaqui y Bombero Galarza | J17: Domo | K17: GPON | L17: NECOCHEA Y GALARZA | M17: 172.20.12.216 | O17: =COUNTIF(S17:AT17,"") -> 28 | P17: 00-07-5F-77-02-85 | Q17: =COUNTIF(S17:AT17,"APAGADO") -> 0 | R17: =(O17)/(Q17+O17) -> 1
A18: 1 | B18: 19 | E18: YRIGOYEN-ISLAS ORCADAS | F18: ALTAMIRA | G18: ALT07 | H18: BONOMO | I18: AV. CALCHAQUI Y AV. DEL TRABAJO | J18: DOMO | K18: PTO A FO | L18: CABRAL Y CALCHAQUI | M18: 172.20.10.57 | O18: =COUNTIF(S18:AT18,"") -> 28 | P18: 00-04-63-4F-DE-CA | Q18: =COUNTIF(S18:AT18,"APAGADO") -> 0 | R18: =(O18)/(Q18+O18) -> 1
E19: PON 10 | F19: AGUSTIN RAMIREZ | G19: ARA 01 | H19: BONOMO | I19: Malambo y Tranquera | J19: Domo | K19: GPON | M19: 172.20.12.110 | O19: =COUNTIF(S19:AT19,"") -> 28 | P19: 00-04-63-4F-DB-B6 | Q19: =COUNTIF(S19:AT19,"APAGADO") -> 0 | R19: =(O19)/(Q19+O19) -> 1
E20: PON 10 | F20: AGUSTIN RAMIREZ | G20: ARA 02 | H20: BONOMO | I20: El malambo y La Tranquera | J20: Fija | K20: GPON | M20: 172.20.12.235 | O20: =COUNTIF(S20:AT20,"") -> 28 | P20: C0:6D:ED:A3:E6:63 | Q20: =COUNTIF(S20:AT20,"APAGADO") -> 0 | R20: =(O20)/(Q20+O20) -> 1
E21: PON 10 | F21: AGUSTIN RAMIREZ | G21: ARA 03 | H21: BONOMO | I21: 437 Y La Tranquera | J21: Fija | K21: GPON | M21: 172.20.10.232 | O21: =COUNTIF(S21:AT21,"") -> 28 | P21: C0:6D:ED:A3:66:6A | Q21: =COUNTIF(S21:AT21,"APAGADO") -> 0 | R21: =(O21)/(Q21+O21) -> 1
A22: 1 | B22: 15 | E22: TROPILLA | F22: BELGRANO | G22: BEL 01 | H22: BONOMO | I22: San Martin y Dardo Rocha | J22: DOMO | K22: Fibra Optica | M22: 172.20.12.64 | N22: A03 | O22: =COUNTIF(S22:AT22,"") -> 18 | P22: 00-07-5F-9F-A1-64 | Q22: =COUNTIF(S22:AT22,"APAGADO") -> 10 | R22: =(O22)/(Q22+O22) -> 0.64285714 | X22: APAGADO | Y22: APAGADO | Z22: APAGADO | AC22: APAGADO | AD22: APAGADO | AE22: APAGADO | AF22: APAGADO | AG22: APAGADO | AJ22: APAGADO | AK22: APAGADO
A23: 1 | B23: 15 | E23: TROPILLA | F23: BELGRANO | G23: BEL 02 | H23: BONOMO | I23: Guardia vieja y Fronteriz | J23: DOMO | K23: Fibra Optica | M23: 172.20.10.117 | O23: =COUNTIF(S23:AT23,"") -> 18 | P23: E4-30-22-4F-9E-62 | Q23: =COUNTIF(S23:AT23,"APAGADO") -> 10 | R23: =(O23)/(Q23+O23) -> 0.64285714 | X23: APAGADO | Y23: APAGADO | Z23: APAGADO | AC23: APAGADO | AD23: APAGADO | AE23: APAGADO | AF23: APAGADO | AG23: APAGADO | AJ23: APAGADO | AK23: APAGADO
E24: PON 08 | F24: BOSQUES CENTRO | G24: BOSQ 07 | H24: COSEIDI | I24: Touring club y Sta Teresita | J24: Domo | K24: GPON | M24: 172.20.10.141 | O24: =COUNTIF(S24:AT24,"") -> 28 | P24: A0-FF-0C-D1-BD-7F | Q24: =COUNTIF(S24:AT24,"APAGADO") -> 0 | R24: =(O24)/(Q24+O24) -> 1
E25: PON 08 | F25: BOSQUES CENTRO | G25: BOSQ 08 | H25: COSEIDI | I25: D'Anuncio Y J.B Justo (Plaza) | J25: Domo | K25: GPON | M25: 172.20.10.222 | O25: =COUNTIF(S25:AT25,"") -> 28 | P25: a4-18-94-05-51-13 | Q25: =COUNTIF(S25:AT25,"APAGADO") -> 0 | R25: =(O25)/(Q25+O25) -> 1
E26: PON 08 | F26: BOSQUES CENTRO | G26: BOSQ 09 | H26: COSEIDI | I26: D'Anuncio e/Lisandro de la Torre y J.B Justo | J26: Fija | K26: GPON | M26: 172.20.10.227 | O26: =COUNTIF(S26:AT26,"") -> 28 | P26: c0-6d-ed-a3-e4-4c | Q26: =COUNTIF(S26:AT26,"APAGADO") -> 0 | R26: =(O26)/(Q26+O26) -> 1
E27: PON 08 | F27: BOSQUES CENTRO | G27: BOSQ 10 | H27: COSEIDI | I27: D'Anuncio e/Lisandro de la Torre y J.B Justo | J27: Fija | K27: GPON | M27: 172.20.10.228 | O27: =COUNTIF(S27:AT27,"") -> 28 | P27: c0-6d-ed-a3-e4-5b | Q27: =COUNTIF(S27:AT27,"APAGADO") -> 0 | R27: =(O27)/(Q27+O27) -> 1
E28: PON 08 | F28: BOSQUES CENTRO | G28: BOSQ 11 | H28: COSEIDI | I28: AV Bosques y Altagracia | J28: Domo | K28: GPON | M28: 172.20.8.52 | O28: =COUNTIF(S28:AT28,"") -> 28 | P28: A4-18-94-05-A4-68 | Q28: =COUNTIF(S28:AT28,"APAGADO") -> 0 | R28: =(O28)/(Q28+O28) -> 1
E29: TUNEL COSEIDI | F29: BOSQUES CENTRO | G29: BOSQ 12 | H29: COSEIDI | I29: Colectora R.36 y San Antonio | K29: Fibra Optica | M29: 172.20.8.84 | P29: 5C-34-5B-4B-DC-29
E30: TUNEL COSEIDI | F30: BOSQUES CENTRO | G30: BOSQC 01 | H30: COSEIDI | I30: LUIS AGOTE E/DANUNCIO Y CAMPOAMOR | J30: Fija | K30: PTO A FO | M30: 172.20.11.15 | O30: =COUNTIF(S30:AT30,"") -> 25 | P30: 00-07-5F-B7-56-89 | Q30: =COUNTIF(S30:AT30,"APAGADO") -> 3 | R30: =(O30)/(Q30+O30) -> 0.89285714 | Y30: APAGADO | AK30: APAGADO | AL30: APAGADO
E31: TUNEL COSEIDI | F31: BOSQUES CENTRO | G31: BOSQC 02 | H31: COSEIDI | I31: LUIS AGOTE E/DANUNCIO Y CAMPOAMOR | J31: Fija | K31: PTO A FO | M31: 172.20.11.16 | O31: =COUNTIF(S31:AT31,"") -> 25 | P31: 00-07-5F-B4-17-A8 | Q31: =COUNTIF(S31:AT31,"APAGADO") -> 3 | R31: =(O31)/(Q31+O31) -> 0.89285714 | Y31: APAGADO | AK31: APAGADO | AL31: APAGADO
E32: TUNEL COSEIDI | F32: BOSQUES CENTRO | G32: BOSQC 03 | H32: COSEIDI | I32: BENAVENTE Y LUIS AGOTE | J32: Fija | K32: PTO A FO | M32: 172.20.11.13 | O32: =COUNTIF(S32:AT32,"") -> 14 | P32: 00-07-5F-B6-B8-A5 | Q32: =COUNTIF(S32:AT32,"APAGADO") -> 14 | R32: =(O32)/(Q32+O32) -> 0.5 | V32: APAGADO | W32: APAGADO | X32: APAGADO | Y32: APAGADO | Z32: APAGADO | AC32: APAGADO | AD32: APAGADO | AE32: APAGADO | AF32: APAGADO | AG32: APAGADO | AJ32: APAGADO | AK32: APAGADO | AL32: APAGADO | AM32: APAGADO
E33: TUNEL COSEIDI | F33: BOSQUES CENTRO | G33: BOSQC 04 | H33: COSEIDI | I33: BENAVENTE Y LUIS AGOTE | J33: Fija | K33: PTO A FO | M33: 172.20.11.113 | O33: =COUNTIF(S33:AT33,"") -> 25 | P33: 00-07-5F-B6-B8-D3 | Q33: =COUNTIF(S33:AT33,"APAGADO") -> 3 | R33: =(O33)/(Q33+O33) -> 0.89285714 | Y33: APAGADO | AK33: APAGADO | AL33: APAGADO
E34: TUNEL COSEIDI | F34: BOSQUES CENTRO | G34: BOSQC 05 | H34: COSEIDI | I34: LUIS AGOTE Y RUTA 36 | J34: Fija | K34: PTO A FO | M34: 172.20.11.17 | O34: =COUNTIF(S34:AT34,"") -> 28 | P34: 00-07-5F-B4-42-C7 | Q34: =COUNTIF(S34:AT34,"APAGADO") -> 0 | R34: =(O34)/(Q34+O34) -> 1
E35: TUNEL COSEIDI | F35: BOSQUES CENTRO | G35: BOSQC 06 | H35: COSEIDI | I35: LUIS AGOTE Y RUTA 36 | J35: Fija | K35: PTO A FO | M35: 172.20.11.18 | O35: =COUNTIF(S35:AT35,"") -> 28 | P35: 00-07-5F-B4-16-8D | Q35: =COUNTIF(S35:AT35,"APAGADO") -> 0 | R35: =(O35)/(Q35+O35) -> 1
A36: 2 | B36: 2 | E36: AZURDUY | F36: LA CAROLINA 2 | G36: CAR01 (Fija 1) | H36: COSEIDI | I36: Azurduy y Vergara | J36: Fija | K36: Fibra Optica | M36: 172.20.10.60 | O36: =COUNTIF(S36:AT36,"") -> 28 | P36: A0:FF:0C:EF:DF:AB | Q36: =COUNTIF(S36:AT36,"APAGADO") -> 0 | R36: =(O36)/(Q36+O36) -> 1
A37: 2 | B37: 2 | E37: AZURDUY | F37: LA CAROLINA 2 | G37: CAR02 (Fija 2) | H37: COSEIDI | I37: Azurduy y Vergara | J37: Fija | K37: Fibra Optica | M37: 172.20.10.73 | O37: =COUNTIF(S37:AT37,"") -> 28 | P37: A0:FF:0C:EF:DF:AD | Q37: =COUNTIF(S37:AT37,"APAGADO") -> 0 | R37: =(O37)/(Q37+O37) -> 1
E38: PON 15 | F38: LA CAROLINA 2 | G38: CAR03(Fija1) | H38: COSEIDI | I38: Hudson e/1362 Y 1356 | J38: Fija | K38: GPON | M38: 172.20.8.39 | O38: =COUNTIF(S38:AT38,"") -> 28 | P38: c0-6d-ed-a3-e5-ad | Q38: =COUNTIF(S38:AT38,"APAGADO") -> 0 | R38: =(O38)/(Q38+O38) -> 1
E39: PON 15 | F39: LA CAROLINA 2 | G39: CAR04(Fija2) | H39: COSEIDI | I39: Hudson e/1362 Y 1356 | J39: Fija | K39: GPON | M39: 172.20.8.40 | O39: =COUNTIF(S39:AT39,"") -> 28 | P39: c0-6d-ed-a3-e6-3a | Q39: =COUNTIF(S39:AT39,"APAGADO") -> 0 | R39: =(O39)/(Q39+O39) -> 1
E40: PON 15 | F40: LA CAROLINA 2 | G40: CAR05 | H40: COSEIDI | I40: Hudson e/1362 Y 1356 | J40: Domo | K40: GPON | M40: 172.20.8.34 | O40: =COUNTIF(S40:AT40,"") -> 28 | P40: a4-18-94-05-4a-70 | Q40: =COUNTIF(S40:AT40,"APAGADO") -> 0 | R40: =(O40)/(Q40+O40) -> 1
...

Sheet AUXILIAR

Sheet paradas
C1: TOTAL PARADAS | D1: =COUNTIFS(A5:A602,"=paradas seguras")/2 -> 0 | E1: TOTAL DE CAMARAS EN PARADAS | H1: =COUNTIFS(A5:A602,"=paradas seguras") -> 0 | I1: TOTAL DE CAMARAS | K1: =COUNTIFS(D5:D602,"=GFIJA") -> 0 | L1: TOTAL DE INTERCOMUNICADORES | O1: =COUNTIFS(D5:D602,"=INTERCOMUNICADOR") -> 0
E2: FIJAS | F2: =COUNTIFS(F4:F601, "=APAGADO",D4:D601,"=GFIJA") -> 0 | G2: =COUNTIFS(G4:G601, "=APAGADO",D4:D601,"=GFIJA") -> 0 | H2: =COUNTIFS(H4:H601, "=APAGADO",D4:D601,"=GFIJA") -> 0 | I2: =COUNTIFS(I4:I601, "=APAGADO",D4:D601,"=GFIJA") -> 0 | J2: =COUNTIFS(J4:J601, "=APAGADO",D4:D601,"=GFIJA") -> 0 | K2: =COUNTIFS(K4:K601, "=APAGADO",D4:D601,"=GFIJA") -> 0 | L2: =COUNTIFS(L4:L601, "=APAGADO",D4:D601,"=GFIJA") -> 0 | M2: =COUNTIFS(M4:M601, "=APAGADO",D4:D601,"=GFIJA") -> 0 | N2: =COUNTIFS(N4:N601, "=APAGADO",D4:D601,"=GFIJA") -> 0 | O2: =COUNTIFS(O4:O601, "=APAGADO",D4:D601,"=GFIJA") -> 0 | P2: =COUNTIFS(P4:P601, "=APAGADO",D4:D601,"=GFIJA") -> 0 | Q2: =COUNTIFS(Q4:Q601, "=APAGADO",D4:D601,"=GFIJA") -> 0 | R2: =COUNTIFS(R4:R601, "=APAGADO",D4:D601,"=GFIJA") -> 0 | S2: =COUNTIFS(S4:S601, "=APAGADO",D4:D601,"=GFIJA") -> 0 | T2: =COUNTIFS(T4:T601, "=APAGADO",D4:D601,"=GFIJA") -> 0 | U2: =COUNTIFS(U4:U601, "=APAGADO",D4:D601,"=GFIJA") -> 0 | V2: =COUNTIFS(V4:V601, "=APAGADO",D4:D601,"=GFIJA") -> 0 | W2: =COUNTIFS(W4:W601, "=APAGADO",D4:D601,"=GFIJA") -> 0 | X2: =COUNTIFS(X4:X601, "=APAGADO",D4:D601,"=GFIJA") -> 0 | Y2: =COUNTIFS(Y4:Y601, "=APAGADO",D4:D601,"=GFIJA") -> 0 | Z2: =COUNTIFS(Z4:Z601, "=APAGADO",D4:D601,"=GFIJA") -> 0 | AA2: =COUNTIFS(AA4:AA601, "=APAGADO",D4:D601,"=GFIJA") -> 0 | AB2: =COUNTIFS(AB4:AB601, "=APAGADO",D4:D601,"=GFIJA") -> 0 | AC2: =COUNTIFS(AC4:AC601, "=APAGADO",D4:D601,"=GFIJA") -> 0 | AD2: =COUNTIFS(AD4:AD601, "=APAGADO",D4:D601,"=GFIJA") -> 0 | AE2: =COUNTIFS(AE4:AE601, "=APAGADO",D4:D601,"=GFIJA") -> 0 | AF2: =COUNTIFS(AF4:AF601, "=APAGADO",D4:D601,"=GFIJA") -> 0 | AG2: =COUNTIFS(AG4:AG601, "=APAGADO",D4:D601,"=GFIJA") -> 0 | AH2: =COUNTIFS(AH4:AH601, "=APAGADO",E4:E601,"=GFIJA") -> 0 | AI2: =COUNTIFS(AI4:AI601, "=APAGADO",F4:F601,"=GFIJA") -> 0 | AJ2: =COUNTIFS(AJ4:AJ601, "=APAGADO",G4:G601,"=GFIJA") -> 0
E3: INTERCOMUNICADOR | F3: =COUNTIFS(F6:F603, "=APAGADO",D4:D601,"=INTERCOMUNICADOR") -> 0 | G3: =COUNTIFS(G6:G603, "=APAGADO",D4:D601,"=INTERCOMUNICADOR") -> 0 | H3: =COUNTIFS(H6:H603, "=APAGADO",D4:D601,"=INTERCOMUNICADOR") -> 0 | I3: =COUNTIFS(I6:I603, "=APAGADO",D4:D601,"=INTERCOMUNICADOR") -> 0 | J3: =COUNTIFS(J6:J603, "=APAGADO",D4:D601,"=INTERCOMUNICADOR") -> 0 | K3: =COUNTIFS(K6:K603, "=APAGADO",D4:D601,"=INTERCOMUNICADOR") -> 0 | L3: =COUNTIFS(L6:L603, "=APAGADO",D4:D601,"=INTERCOMUNICADOR") -> 0 | M3: =COUNTIFS(M6:M603, "=APAGADO",D4:D601,"=INTERCOMUNICADOR") -> 0 | N3: =COUNTIFS(N6:N603, "=APAGADO",D4:D601,"=INTERCOMUNICADOR") -> 0 | O3: =COUNTIFS(O6:O603, "=APAGADO",D4:D601,"=INTERCOMUNICADOR") -> 0 | P3: =COUNTIFS(P6:P603, "=APAGADO",D4:D601,"=INTERCOMUNICADOR") -> 0 | Q3: =COUNTIFS(Q6:Q603, "=APAGADO",D4:D601,"=INTERCOMUNICADOR") -> 0 | R3: =COUNTIFS(R6:R603, "=APAGADO",D4:D601,"=INTERCOMUNICADOR") -> 0 | S3: =COUNTIFS(S6:S603, "=APAGADO",D4:D601,"=INTERCOMUNICADOR") -> 0 | T3: =COUNTIFS(T6:T603, "=APAGADO",D4:D601,"=INTERCOMUNICADOR") -> 0 | U3: =COUNTIFS(U6:U603, "=APAGADO",D4:D601,"=INTERCOMUNICADOR") -> 0 | V3: =COUNTIFS(V6:V603, "=APAGADO",D4:D601,"=INTERCOMUNICADOR") -> 0 | W3: =COUNTIFS(W6:W603, "=APAGADO",D4:D601,"=INTERCOMUNICADOR") -> 0 | X3: =COUNTIFS(X6:X603, "=APAGADO",D4:D601,"=INTERCOMUNICADOR") -> 0 | Y3: =COUNTIFS(Y6:Y603, "=APAGADO",D4:D601,"=INTERCOMUNICADOR") -> 0 | Z3: =COUNTIFS(Z6:Z603, "=APAGADO",D4:D601,"=INTERCOMUNICADOR") -> 0 | AA3: =COUNTIFS(AA6:AA603, "=APAGADO",D4:D601,"=INTERCOMUNICADOR") -> 0 | AB3: =COUNTIFS(AB6:AB603, "=APAGADO",D4:D601,"=INTERCOMUNICADOR") -> 0 | AC3: =COUNTIFS(AC6:AC603, "=APAGADO",D4:D601,"=INTERCOMUNICADOR") -> 0 | AD3: =COUNTIFS(AD6:AD603, "=APAGADO",D4:D601,"=INTERCOMUNICADOR") -> 0 | AE3: =COUNTIFS(AE6:AE603, "=APAGADO",D4:D601,"=INTERCOMUNICADOR") -> 0 | AF3: =COUNTIFS(AF6:AF603, "=APAGADO",D4:D601,"=INTERCOMUNICADOR") -> 0 | AG3: =COUNTIFS(AG6:AG603, "=APAGADO",D4:D601,"=INTERCOMUNICADOR") -> 0 | AH3: =COUNTIFS(AH6:AH603, "=APAGADO",E4:E601,"=INTERCOMUNICADOR") -> 0 | AI3: =COUNTIFS(AI6:AI603, "=APAGADO",F4:F601,"=INTERCOMUNICADOR") -> 0 | AJ3: =COUNTIFS(AJ6:AJ603, "=APAGADO",G4:G601,"=INTERCOMUNICADOR") -> 0
A4: ='RESUMEN TOTAL'!F7 -> Barrio | B4: ='RESUMEN TOTAL'!G7 -> [Denominacion] | C4: ='RESUMEN TOTAL'!I7 -> [Ubicacion] | D4: ='RESUMEN TOTAL'!J7 -> [Tipo de Camara] | E4: ='RESUMEN TOTAL'!K7 -> [Tipo de Conexion] | F4: ='RESUMEN TOTAL'!S7 -> 46143 | G4: ='RESUMEN TOTAL'!T7 -> 46144 | H4: ='RESUMEN TOTAL'!U7 -> 46145 | I4: ='RESUMEN TOTAL'!V7 -> 46146 | J4: ='RESUMEN TOTAL'!W7 -> 46147 | K4: ='RESUMEN TOTAL'!X7 -> 46148 | L4: ='RESUMEN TOTAL'!Y7 -> 46149 | M4: ='RESUMEN TOTAL'!Z7 -> 46150 | ... AI4: ='RESUMEN TOTAL'!AV7 -> 46172 | AJ4: ='RESUMEN TOTAL'!#REF! -> #REF! | XEY4: =SUM(F4:XEX4) -> #REF!
A5: ='RESUMEN TOTAL'!F8 -> ALTAMIRA | B5: ='RESUMEN TOTAL'!G8 -> ALT 03 | C5: ='RESUMEN TOTAL'!I8 -> Bombero Galarza y Necochea | D5: ='RESUMEN TOTAL'!J8 -> Domo | E5: ='RESUMEN TOTAL'!K8 -> GPON | F5: ='RESUMEN TOTAL'!S8 -> 0 | G5: ='RESUMEN TOTAL'!T8 -> 0 | H5: ='RESUMEN TOTAL'!U8 -> 0 | I5: ='RESUMEN TOTAL'!V8 -> 0 | J5: ='RESUMEN TOTAL'!W8 -> 0 | K5: ='RESUMEN TOTAL'!X8 -> 0 | L5: ='RESUMEN TOTAL'!Y8 -> 0 | M5: ='RESUMEN TOTAL'!Z8 -> 0 | ... AI5: ='RESUMEN TOTAL'!AV8 -> 0 | AJ5: ='RESUMEN TOTAL'!#REF! -> #REF!
A6: ='RESUMEN TOTAL'!F9 -> ALTAMIRA | B6: ='RESUMEN TOTAL'!G9 -> ALT 04 | C6: ='RESUMEN TOTAL'!I9 -> Francia y Necochea | D6: ='RESUMEN TOTAL'!J9 -> Domo | E6: ='RESUMEN TOTAL'!K9 -> GPON | F6: ='RESUMEN TOTAL'!S9 -> 0 | G6: ='RESUMEN TOTAL'!T9 -> 0 | H6: ='RESUMEN TOTAL'!U9 -> 0 | I6: ='RESUMEN TOTAL'!V9 -> 0 | J6: ='RESUMEN TOTAL'!W9 -> 0 | K6: ='RESUMEN TOTAL'!X9 -> 0 | L6: ='RESUMEN TOTAL'!Y9 -> 0 | M6: ='RESUMEN TOTAL'!Z9 -> 0 | ... AI6: ='RESUMEN TOTAL'!AV9 -> 0 | AJ6: ='RESUMEN TOTAL'!#REF! -> #REF!
A7: ='RESUMEN TOTAL'!F10 -> ALTAMIRA | B7: ='RESUMEN TOTAL'!G10 -> ALT 06 | C7: ='RESUMEN TOTAL'!I10 -> LOPE DE VEGA Y NECOCHEA | D7: ='RESUMEN TOTAL'!J10 -> Domo | E7: ='RESUMEN TOTAL'!K10 -> GPON | F7: ='RESUMEN TOTAL'!S10 -> 0 | G7: ='RESUMEN TOTAL'!T10 -> 0 | H7: ='RESUMEN TOTAL'!U10 -> 0 | I7: ='RESUMEN TOTAL'!V10 -> 0 | J7: ='RESUMEN TOTAL'!W10 -> 0 | K7: ='RESUMEN TOTAL'!X10 -> 0 | L7: ='RESUMEN TOTAL'!Y10 -> 0 | M7: ='RESUMEN TOTAL'!Z10 -> 0 | ... AI7: ='RESUMEN TOTAL'!AV10 -> 0 | AJ7: ='RESUMEN TOTAL'!#REF! -> #REF!
A8: ='RESUMEN TOTAL'!F11 -> ALTAMIRA | B8: ='RESUMEN TOTAL'!G11 -> ALT 08 | C8: ='RESUMEN TOTAL'!I11 -> HUMAITA Y NECOCHEA | D8: ='RESUMEN TOTAL'!J11 -> DOMO | E8: ='RESUMEN TOTAL'!K11 -> GPON A FO | F8: ='RESUMEN TOTAL'!S11 -> 0 | G8: ='RESUMEN TOTAL'!T11 -> 0 | H8: ='RESUMEN TOTAL'!U11 -> 0 | I8: ='RESUMEN TOTAL'!V11 -> APAGADO | J8: ='RESUMEN TOTAL'!W11 -> APAGADO | K8: ='RESUMEN TOTAL'!X11 -> 0 | L8: ='RESUMEN TOTAL'!Y11 -> 0 | M8: ='RESUMEN TOTAL'!Z11 -> 0 | ... AI8: ='RESUMEN TOTAL'!AV11 -> 0 | AJ8: ='RESUMEN TOTAL'!#REF! -> #REF!
A9: ='RESUMEN TOTAL'!F12 -> ALTAMIRA | B9: ='RESUMEN TOTAL'!G12 -> ALT 09 | C9: ='RESUMEN TOTAL'!I12 -> NECOCHEA Y CURUPAITY | D9: ='RESUMEN TOTAL'!J12 -> DOMO | E9: ='RESUMEN TOTAL'!K12 -> GPON A FO | F9: ='RESUMEN TOTAL'!S12 -> 0 | G9: ='RESUMEN TOTAL'!T12 -> 0 | H9: ='RESUMEN TOTAL'!U12 -> 0 | I9: ='RESUMEN TOTAL'!V12 -> APAGADO | J9: ='RESUMEN TOTAL'!W12 -> APAGADO | K9: ='RESUMEN TOTAL'!X12 -> 0 | L9: ='RESUMEN TOTAL'!Y12 -> 0 | M9: ='RESUMEN TOTAL'!Z12 -> 0 | ... AI9: ='RESUMEN TOTAL'!AV12 -> 0 | AJ9: ='RESUMEN TOTAL'!#REF! -> #REF!
A10: ='RESUMEN TOTAL'!F13 -> ALTAMIRA | B10: ='RESUMEN TOTAL'!G13 -> ALT 10 | C10: ='RESUMEN TOTAL'!I13 -> Calchaqui y Francia | D10: ='RESUMEN TOTAL'!J13 -> Domo | E10: ='RESUMEN TOTAL'!K13 -> GPON | F10: ='RESUMEN TOTAL'!S13 -> 0 | G10: ='RESUMEN TOTAL'!T13 -> 0 | H10: ='RESUMEN TOTAL'!U13 -> 0 | I10: ='RESUMEN TOTAL'!V13 -> 0 | J10: ='RESUMEN TOTAL'!W13 -> 0 | K10: ='RESUMEN TOTAL'!X13 -> 0 | L10: ='RESUMEN TOTAL'!Y13 -> 0 | M10: ='RESUMEN TOTAL'!Z13 -> 0 | ... AI10: ='RESUMEN TOTAL'!AV13 -> 0 | AJ10: ='RESUMEN TOTAL'!#REF! -> #REF!
A11: ='RESUMEN TOTAL'!F14 -> ALTAMIRA | B11: ='RESUMEN TOTAL'!G14 -> ALT 11 | C11: ='RESUMEN TOTAL'!I14 -> CALCHAQUÍ Y GALARZA FIJA | D11: ='RESUMEN TOTAL'!J14 -> Fija | E11: ='RESUMEN TOTAL'!K14 -> GPON | F11: ='RESUMEN TOTAL'!S14 -> 0 | G11: ='RESUMEN TOTAL'!T14 -> 0 | H11: ='RESUMEN TOTAL'!U14 -> 0 | I11: ='RESUMEN TOTAL'!V14 -> 0 | J11: ='RESUMEN TOTAL'!W14 -> 0 | K11: ='RESUMEN TOTAL'!X14 -> 0 | L11: ='RESUMEN TOTAL'!Y14 -> 0 | M11: ='RESUMEN TOTAL'!Z14 -> 0 | ... AI11: ='RESUMEN TOTAL'!AV14 -> 0 | AJ11: ='RESUMEN TOTAL'!#REF! -> #REF!
A12: ='RESUMEN TOTAL'!F15 -> ALTAMIRA | B12: ='RESUMEN TOTAL'!G15 -> ALT01 | C12: ='RESUMEN TOTAL'!I15 -> Calchaqui y Sgto. Cabral | D12: ='RESUMEN TOTAL'!J15 -> Domo | E12: ='RESUMEN TOTAL'!K15 -> Fibra Optica | F12: ='RESUMEN TOTAL'!S15 -> 0 | G12: ='RESUMEN TOTAL'!T15 -> 0 | H12: ='RESUMEN TOTAL'!U15 -> 0 | I12: ='RESUMEN TOTAL'!V15 -> 0 | J12: ='RESUMEN TOTAL'!W15 -> 0 | K12: ='RESUMEN TOTAL'!X15 -> 0 | L12: ='RESUMEN TOTAL'!Y15 -> 0 | M12: ='RESUMEN TOTAL'!Z15 -> 0 | ... AI12: ='RESUMEN TOTAL'!AV15 -> 0 | AJ12: ='RESUMEN TOTAL'!#REF! -> #REF!
A13: ='RESUMEN TOTAL'!F16 -> ALTAMIRA | B13: ='RESUMEN TOTAL'!G16 -> ALT02 | C13: ='RESUMEN TOTAL'!I16 -> Calchaqui y Lope de Vega | D13: ='RESUMEN TOTAL'!J16 -> Domo | E13: ='RESUMEN TOTAL'!K16 -> PTO A FO | F13: ='RESUMEN TOTAL'!S16 -> 0 | G13: ='RESUMEN TOTAL'!T16 -> 0 | H13: ='RESUMEN TOTAL'!U16 -> 0 | I13: ='RESUMEN TOTAL'!V16 -> 0 | J13: ='RESUMEN TOTAL'!W16 -> 0 | K13: ='RESUMEN TOTAL'!X16 -> 0 | L13: ='RESUMEN TOTAL'!Y16 -> 0 | M13: ='RESUMEN TOTAL'!Z16 -> 0 | ... AI13: ='RESUMEN TOTAL'!AV16 -> 0 | AJ13: ='RESUMEN TOTAL'!#REF! -> #REF!
A14: ='RESUMEN TOTAL'!F17 -> ALTAMIRA | B14: ='RESUMEN TOTAL'!G17 -> ALT05 | C14: ='RESUMEN TOTAL'!I17 -> Av. Calchaqui y Bombero Galarza | D14: ='RESUMEN TOTAL'!J17 -> Domo | E14: ='RESUMEN TOTAL'!K17 -> GPON | F14: ='RESUMEN TOTAL'!S17 -> 0 | G14: ='RESUMEN TOTAL'!T17 -> 0 | H14: ='RESUMEN TOTAL'!U17 -> 0 | I14: ='RESUMEN TOTAL'!V17 -> 0 | J14: ='RESUMEN TOTAL'!W17 -> 0 | K14: ='RESUMEN TOTAL'!X17 -> 0 | L14: ='RESUMEN TOTAL'!Y17 -> 0 | M14: ='RESUMEN TOTAL'!Z17 -> 0 | ... AI14: ='RESUMEN TOTAL'!AV17 -> 0 | AJ14: ='RESUMEN TOTAL'!#REF! -> #REF!
A15: ='RESUMEN TOTAL'!F18 -> ALTAMIRA | B15: ='RESUMEN TOTAL'!G18 -> ALT07 | C15: CALCHAQUÍ Y GALARZA FIJA | D15: ='RESUMEN TOTAL'!J18 -> DOMO | F15: ='RESUMEN TOTAL'!S18 -> 0 | G15: ='RESUMEN TOTAL'!T18 -> 0 | H15: ='RESUMEN TOTAL'!U18 -> 0 | I15: ='RESUMEN TOTAL'!V18 -> 0 | J15: ='RESUMEN TOTAL'!W18 -> 0 | K15: ='RESUMEN TOTAL'!X18 -> 0 | L15: ='RESUMEN TOTAL'!Y18 -> 0 | M15: ='RESUMEN TOTAL'!Z18 -> 0 | ... AI15: ='RESUMEN TOTAL'!AV18 -> 0 | AJ15: ='RESUMEN TOTAL'!#REF! -> #REF!
A16: ='RESUMEN TOTAL'!F19 -> AGUSTIN RAMIREZ | B16: ='RESUMEN TOTAL'!G19 -> ARA 01 | C16: ='RESUMEN TOTAL'!I19 -> Malambo y Tranquera | D16: ='RESUMEN TOTAL'!J19 -> Domo | E16: ='RESUMEN TOTAL'!K19 -> GPON | F16: ='RESUMEN TOTAL'!S19 -> 0 | G16: ='RESUMEN TOTAL'!T19 -> 0 | H16: ='RESUMEN TOTAL'!U19 -> 0 | I16: ='RESUMEN TOTAL'!V19 -> 0 | J16: ='RESUMEN TOTAL'!W19 -> 0 | K16: ='RESUMEN TOTAL'!X19 -> 0 | L16: ='RESUMEN TOTAL'!Y19 -> 0 | M16: ='RESUMEN TOTAL'!Z19 -> 0 | ... AI16: ='RESUMEN TOTAL'!AV19 -> 0 | AJ16: ='RESUMEN TOTAL'!#REF! -> #REF!
A17: ='RESUMEN TOTAL'!F22 -> BELGRANO | B17: ='RESUMEN TOTAL'!G22 -> BEL 01 | C17: ='RESUMEN TOTAL'!I22 -> San Martin y Dardo Rocha | D17: ='RESUMEN TOTAL'!J22 -> DOMO | E17: ='RESUMEN TOTAL'!K22 -> Fibra Optica | F17: ='RESUMEN TOTAL'!S22 -> 0 | G17: ='RESUMEN TOTAL'!T22 -> 0 | H17: ='RESUMEN TOTAL'!U22 -> 0 | I17: ='RESUMEN TOTAL'!V22 -> 0 | J17: ='RESUMEN TOTAL'!W22 -> 0 | K17: ='RESUMEN TOTAL'!X22 -> APAGADO | L17: ='RESUMEN TOTAL'!Y22 -> APAGADO | M17: ='RESUMEN TOTAL'!Z22 -> APAGADO | ... AI17: ='RESUMEN TOTAL'!AV22 -> 0 | AJ17: ='RESUMEN TOTAL'!#REF! -> #REF!
A18: ='RESUMEN TOTAL'!F23 -> BELGRANO | B18: ='RESUMEN TOTAL'!G23 -> BEL 02 | C18: ='RESUMEN TOTAL'!I23 -> Guardia vieja y Fronteriz | D18: ='RESUMEN TOTAL'!J23 -> DOMO | E18: ='RESUMEN TOTAL'!K23 -> Fibra Optica | F18: ='RESUMEN TOTAL'!S23 -> 0 | G18: ='RESUMEN TOTAL'!T23 -> 0 | H18: ='RESUMEN TOTAL'!U23 -> 0 | I18: ='RESUMEN TOTAL'!V23 -> 0 | J18: ='RESUMEN TOTAL'!W23 -> 0 | K18: ='RESUMEN TOTAL'!X23 -> APAGADO | L18: ='RESUMEN TOTAL'!Y23 -> APAGADO | M18: ='RESUMEN TOTAL'!Z23 -> APAGADO | ... AI18: ='RESUMEN TOTAL'!AV23 -> 0 | AJ18: ='RESUMEN TOTAL'!#REF! -> #REF!
A19: ='RESUMEN TOTAL'!F24 -> BOSQUES CENTRO | B19: ='RESUMEN TOTAL'!G24 -> BOSQ 07 | C19: ='RESUMEN TOTAL'!I24 -> Touring club y Sta Teresita | D19: ='RESUMEN TOTAL'!J24 -> Domo | E19: ='RESUMEN TOTAL'!K24 -> GPON | F19: ='RESUMEN TOTAL'!S24 -> 0 | G19: ='RESUMEN TOTAL'!T24 -> 0 | H19: ='RESUMEN TOTAL'!U24 -> 0 | I19: ='RESUMEN TOTAL'!V24 -> 0 | J19: ='RESUMEN TOTAL'!W24 -> 0 | K19: ='RESUMEN TOTAL'!X24 -> 0 | L19: ='RESUMEN TOTAL'!Y24 -> 0 | M19: ='RESUMEN TOTAL'!Z24 -> 0 | ... AI19: ='RESUMEN TOTAL'!AV24 -> 0 | AJ19: ='RESUMEN TOTAL'!#REF! -> #REF!
A20: ='RESUMEN TOTAL'!F25 -> BOSQUES CENTRO | B20: ='RESUMEN TOTAL'!G25 -> BOSQ 08 | C20: ='RESUMEN TOTAL'!I25 -> D'Anuncio Y J.B Justo (Plaza) | D20: ='RESUMEN TOTAL'!J25 -> Domo | E20: ='RESUMEN TOTAL'!K25 -> GPON | F20: ='RESUMEN TOTAL'!S25 -> 0 | G20: ='RESUMEN TOTAL'!T25 -> 0 | H20: ='RESUMEN TOTAL'!U25 -> 0 | I20: ='RESUMEN TOTAL'!V25 -> 0 | J20: ='RESUMEN TOTAL'!W25 -> 0 | K20: ='RESUMEN TOTAL'!X25 -> 0 | L20: ='RESUMEN TOTAL'!Y25 -> 0 | M20: ='RESUMEN TOTAL'!Z25 -> 0 | ... AI20: ='RESUMEN TOTAL'!AV25 -> 0 | AJ20: ='RESUMEN TOTAL'!#REF! -> #REF!
A21: ='RESUMEN TOTAL'!F26 -> BOSQUES CENTRO | B21: ='RESUMEN TOTAL'!G26 -> BOSQ 09 | C21: ='RESUMEN TOTAL'!I26 -> D'Anuncio e/Lisandro de la Torre y J.B Justo | D21: ='RESUMEN TOTAL'!J26 -> Fija | E21: ='RESUMEN TOTAL'!K26 -> GPON | F21: ='RESUMEN TOTAL'!S26 -> 0 | G21: ='RESUMEN TOTAL'!T26 -> 0 | H21: ='RESUMEN TOTAL'!U26 -> 0 | I21: ='RESUMEN TOTAL'!V26 -> 0 | J21: ='RESUMEN TOTAL'!W26 -> 0 | K21: ='RESUMEN TOTAL'!X26 -> 0 | L21: ='RESUMEN TOTAL'!Y26 -> 0 | M21: ='RESUMEN TOTAL'!Z26 -> 0 | ... AI21: ='RESUMEN TOTAL'!AV26 -> 0 | AJ21: ='RESUMEN TOTAL'!#REF! -> #REF!
A22: ='RESUMEN TOTAL'!F27 -> BOSQUES CENTRO | B22: ='RESUMEN TOTAL'!G27 -> BOSQ 10 | C22: ='RESUMEN TOTAL'!I27 -> D'Anuncio e/Lisandro de la Torre y J.B Justo | D22: ='RESUMEN TOTAL'!J27 -> Fija | E22: ='RESUMEN TOTAL'!K27 -> GPON | F22: ='RESUMEN TOTAL'!S27 -> 0 | G22: ='RESUMEN TOTAL'!T27 -> 0 | H22: ='RESUMEN TOTAL'!U27 -> 0 | I22: ='RESUMEN TOTAL'!V27 -> 0 | J22: ='RESUMEN TOTAL'!W27 -> 0 | K22: ='RESUMEN TOTAL'!X27 -> 0 | L22: ='RESUMEN TOTAL'!Y27 -> 0 | M22: ='RESUMEN TOTAL'!Z27 -> 0 | ... AI22: ='RESUMEN TOTAL'!AV27 -> 0 | AJ22: ='RESUMEN TOTAL'!#REF! -> #REF!
A23: ='RESUMEN TOTAL'!F28 -> BOSQUES CENTRO | B23: ='RESUMEN TOTAL'!G28 -> BOSQ 11 | C23: ='RESUMEN TOTAL'!I28 -> AV Bosques y Altagracia | D23: ='RESUMEN TOTAL'!J28 -> Domo | E23: ='RESUMEN TOTAL'!K28 -> GPON | F23: ='RESUMEN TOTAL'!S28 -> 0 | G23: ='RESUMEN TOTAL'!T28 -> 0 | H23: ='RESUMEN TOTAL'!U28 -> 0 | I23: ='RESUMEN TOTAL'!V28 -> 0 | J23: ='RESUMEN TOTAL'!W28 -> 0 | K23: ='RESUMEN TOTAL'!X28 -> 0 | L23: ='RESUMEN TOTAL'!Y28 -> 0 | M23: ='RESUMEN TOTAL'!Z28 -> 0 | ... AI23: ='RESUMEN TOTAL'!AV28 -> 0 | AJ23: ='RESUMEN TOTAL'!#REF! -> #REF!
A24: ='RESUMEN TOTAL'!F29 -> BOSQUES CENTRO | B24: ='RESUMEN TOTAL'!G29 -> BOSQ 12 | C24: ='RESUMEN TOTAL'!I29 -> Colectora R.36 y San Antonio | D24: ='RESUMEN TOTAL'!J29 -> 0 | E24: ='RESUMEN TOTAL'!K29 -> Fibra Optica | F24: ='RESUMEN TOTAL'!S29 -> 0 | G24: ='RESUMEN TOTAL'!T29 -> 0 | H24: ='RESUMEN TOTAL'!U29 -> 0 | I24: ='RESUMEN TOTAL'!V29 -> 0 | J24: ='RESUMEN TOTAL'!W29 -> 0 | K24: ='RESUMEN TOTAL'!X29 -> 0 | L24: ='RESUMEN TOTAL'!Y29 -> 0 | M24: ='RESUMEN TOTAL'!Z29 -> 0 | ... AI24: ='RESUMEN TOTAL'!AV29 -> 0 | AJ24: ='RESUMEN TOTAL'!#REF! -> #REF!
A25: ='RESUMEN TOTAL'!F48 -> CENTRO | B25: ='RESUMEN TOTAL'!G48 -> CEN 50 | C25: ='RESUMEN TOTAL'!I48 -> Av. San Martin y Newbery | D25: ='RESUMEN TOTAL'!J48 -> Domo | E25: ='RESUMEN TOTAL'!K48 -> GPON | F25: ='RESUMEN TOTAL'!S48 -> 0 | G25: ='RESUMEN TOTAL'!T48 -> 0 | H25: ='RESUMEN TOTAL'!U48 -> 0 | I25: ='RESUMEN TOTAL'!V48 -> APAGADO | J25: ='RESUMEN TOTAL'!W48 -> APAGADO | K25: ='RESUMEN TOTAL'!X48 -> APAGADO | L25: ='RESUMEN TOTAL'!Y48 -> APAGADO | M25: ='RESUMEN TOTAL'!Z48 -> APAGADO | ... AI25: ='RESUMEN TOTAL'!AV48 -> 0 | AJ25: ='RESUMEN TOTAL'!#REF! -> #REF!
A26: ='RESUMEN TOTAL'!F49 -> CENTRO | B26: ='RESUMEN TOTAL'!G49 -> CEN 51 | C26: ='RESUMEN TOTAL'!I49 -> ILLIA Y LAS HERAS | D26: ='RESUMEN TOTAL'!J49 -> FIJA | E26: ='RESUMEN TOTAL'!K49 -> GPON | F26: ='RESUMEN TOTAL'!S49 -> 0 | G26: ='RESUMEN TOTAL'!T49 -> 0 | H26: ='RESUMEN TOTAL'!U49 -> 0 | I26: ='RESUMEN TOTAL'!V49 -> 0 | J26: ='RESUMEN TOTAL'!W49 -> 0 | K26: ='RESUMEN TOTAL'!X49 -> 0 | L26: ='RESUMEN TOTAL'!Y49 -> 0 | M26: ='RESUMEN TOTAL'!Z49 -> 0 | ... AI26: ='RESUMEN TOTAL'!AV49 -> 0 | AJ26: ='RESUMEN TOTAL'!#REF! -> #REF!
A27: ='RESUMEN TOTAL'!F50 -> CENTRO | B27: ='RESUMEN TOTAL'!G50 -> CEN 53 | C27: ='RESUMEN TOTAL'!I50 -> GUTIERREZ Y BROWN | D27: ='RESUMEN TOTAL'!J50 -> Domo | E27: ='RESUMEN TOTAL'!K50 -> GPON | F27: ='RESUMEN TOTAL'!S50 -> 0 | G27: ='RESUMEN TOTAL'!T50 -> 0 | H27: ='RESUMEN TOTAL'!U50 -> 0 | I27: ='RESUMEN TOTAL'!V50 -> 0 | J27: ='RESUMEN TOTAL'!W50 -> 0 | K27: ='RESUMEN TOTAL'!X50 -> 0 | L27: ='RESUMEN TOTAL'!Y50 -> 0 | M27: ='RESUMEN TOTAL'!Z50 -> 0 | ... AI27: ='RESUMEN TOTAL'!AV50 -> 0 | AJ27: ='RESUMEN TOTAL'!#REF! -> #REF!
A28: ='RESUMEN TOTAL'!F51 -> CENTRO | B28: ='RESUMEN TOTAL'!G51 -> CEN 54 | C28: ='RESUMEN TOTAL'!I51 -> GUTIERREZ Y PRINGLES | D28: ='RESUMEN TOTAL'!J51 -> Domo | E28: ='RESUMEN TOTAL'!K51 -> GPON | F28: ='RESUMEN TOTAL'!S51 -> 0 | G28: ='RESUMEN TOTAL'!T51 -> 0 | H28: ='RESUMEN TOTAL'!U51 -> 0 | I28: ='RESUMEN TOTAL'!V51 -> APAGADO | J28: ='RESUMEN TOTAL'!W51 -> APAGADO | K28: ='RESUMEN TOTAL'!X51 -> APAGADO | L28: ='RESUMEN TOTAL'!Y51 -> APAGADO | M28: ='RESUMEN TOTAL'!Z51 -> APAGADO | ... AI28: ='RESUMEN TOTAL'!AV51 -> 0 | AJ28: ='RESUMEN TOTAL'!#REF! -> #REF!
A29: ='RESUMEN TOTAL'!F52 -> CENTRO | B29: ='RESUMEN TOTAL'!G52 -> CEN 55 | C29: ='RESUMEN TOTAL'!I52 -> BOUREL Y URQUIZA | D29: ='RESUMEN TOTAL'!J52 -> Domo | E29: ='RESUMEN TOTAL'!K52 -> GPON | F29: ='RESUMEN TOTAL'!S52 -> 0 | G29: ='RESUMEN TOTAL'!T52 -> 0 | H29: ='RESUMEN TOTAL'!U52 -> 0 | I29: ='RESUMEN TOTAL'!V52 -> 0 | J29: ='RESUMEN TOTAL'!W52 -> 0 | K29: ='RESUMEN TOTAL'!X52 -> 0 | L29: ='RESUMEN TOTAL'!Y52 -> 0 | M29: ='RESUMEN TOTAL'!Z52 -> 0 | ... AI29: ='RESUMEN TOTAL'!AV52 -> 0 | AJ29: ='RESUMEN TOTAL'!#REF! -> #REF!
A30: ='RESUMEN TOTAL'!F53 -> CENTRO | B30: ='RESUMEN TOTAL'!G53 -> CEN 56 | C30: ='RESUMEN TOTAL'!I53 -> Newbery y Falucho | D30: ='RESUMEN TOTAL'!J53 -> DOMO | E30: ='RESUMEN TOTAL'!K53 -> GPON | F30: ='RESUMEN TOTAL'!S53 -> 0 | G30: ='RESUMEN TOTAL'!T53 -> 0 | H30: ='RESUMEN TOTAL'!U53 -> 0 | I30: ='RESUMEN TOTAL'!V53 -> 0 | J30: ='RESUMEN TOTAL'!W53 -> 0 | K30: ='RESUMEN TOTAL'!X53 -> 0 | L30: ='RESUMEN TOTAL'!Y53 -> 0 | M30: ='RESUMEN TOTAL'!Z53 -> 0 | ... AI30: ='RESUMEN TOTAL'!AV53 -> 0 | AJ30: ='RESUMEN TOTAL'!#REF! -> #REF!
A31: ='RESUMEN TOTAL'!F54 -> CENTRO | B31: ='RESUMEN TOTAL'!G54 -> CEN 57 | C31: ='RESUMEN TOTAL'!I54 -> 25 DE MAYO Y DORREGO | D31: ='RESUMEN TOTAL'!J54 -> DOMO | E31: ='RESUMEN TOTAL'!K54 -> GPON | F31: ='RESUMEN TOTAL'!S54 -> 0 | G31: ='RESUMEN TOTAL'!T54 -> 0 | H31: ='RESUMEN TOTAL'!U54 -> 0 | I31: ='RESUMEN TOTAL'!V54 -> 0 | J31: ='RESUMEN TOTAL'!W54 -> 0 | K31: ='RESUMEN TOTAL'!X54 -> 0 | L31: ='RESUMEN TOTAL'!Y54 -> 0 | M31: ='RESUMEN TOTAL'!Z54 -> 0 | ... AI31: ='RESUMEN TOTAL'!AV54 -> 0 | AJ31: ='RESUMEN TOTAL'!#REF! -> #REF!
A32: ='RESUMEN TOTAL'!F55 -> CENTRO | B32: ='RESUMEN TOTAL'!G55 -> CEN 58 | C32: ='RESUMEN TOTAL'!I55 -> EEUU Y MORENO | D32: ='RESUMEN TOTAL'!J55 -> DOMO | E32: ='RESUMEN TOTAL'!K55 -> Fibra Optica | F32: ='RESUMEN TOTAL'!S55 -> 0 | G32: ='RESUMEN TOTAL'!T55 -> 0 | H32: ='RESUMEN TOTAL'!U55 -> 0 | I32: ='RESUMEN TOTAL'!V55 -> 0 | J32: ='RESUMEN TOTAL'!W55 -> 0 | K32: ='RESUMEN TOTAL'!X55 -> 0 | L32: ='RESUMEN TOTAL'!Y55 -> 0 | M32: ='RESUMEN TOTAL'!Z55 -> 0 | ... AI32: ='RESUMEN TOTAL'!AV55 -> 0 | AJ32: ='RESUMEN TOTAL'!#REF! -> #REF!
A33: ='RESUMEN TOTAL'!F56 -> CENTRO | B33: ='RESUMEN TOTAL'!G56 -> CEN 60 | C33: ='RESUMEN TOTAL'!I56 -> RECONQUISTA Y ILLIA | D33: ='RESUMEN TOTAL'!J56 -> DOMO | E33: ='RESUMEN TOTAL'!K56 -> PTO A GPON | F33: ='RESUMEN TOTAL'!S56 -> 0 | G33: ='RESUMEN TOTAL'!T56 -> 0 | H33: ='RESUMEN TOTAL'!U56 -> 0 | I33: ='RESUMEN TOTAL'!V56 -> 0 | J33: ='RESUMEN TOTAL'!W56 -> 0 | K33: ='RESUMEN TOTAL'!X56 -> 0 | L33: ='RESUMEN TOTAL'!Y56 -> 0 | M33: ='RESUMEN TOTAL'!Z56 -> 0 | ... AI33: ='RESUMEN TOTAL'!AV56 -> 0 | AJ33: ='RESUMEN TOTAL'!#REF! -> #REF!
A34: ='RESUMEN TOTAL'!F57 -> CENTRO | B34: ='RESUMEN TOTAL'!G57 -> CEN 61 | C34: ='RESUMEN TOTAL'!I57 -> BOUREL Y MAIPU | D34: ='RESUMEN TOTAL'!J57 -> DOMO | E34: ='RESUMEN TOTAL'!K57 -> GPON | F34: ='RESUMEN TOTAL'!S57 -> 0 | G34: ='RESUMEN TOTAL'!T57 -> 0 | H34: ='RESUMEN TOTAL'!U57 -> 0 | I34: ='RESUMEN TOTAL'!V57 -> 0 | J34: ='RESUMEN TOTAL'!W57 -> 0 | K34: ='RESUMEN TOTAL'!X57 -> 0 | L34: ='RESUMEN TOTAL'!Y57 -> 0 | M34: ='RESUMEN TOTAL'!Z57 -> 0 | ... AI34: ='RESUMEN TOTAL'!AV57 -> 0 | AJ34: ='RESUMEN TOTAL'!#REF! -> #REF!
A35: ='RESUMEN TOTAL'!F58 -> CENTRO | B35: ='RESUMEN TOTAL'!G58 -> CEN 65 | C35: ='RESUMEN TOTAL'!I58 -> SAN MARTIN Y JUAN PERON | D35: ='RESUMEN TOTAL'!J58 -> FIJA | E35: ='RESUMEN TOTAL'!K58 -> GPON | F35: ='RESUMEN TOTAL'!S58 -> 0 | G35: ='RESUMEN TOTAL'!T58 -> 0 | H35: ='RESUMEN TOTAL'!U58 -> 0 | I35: ='RESUMEN TOTAL'!V58 -> 0 | J35: ='RESUMEN TOTAL'!W58 -> 0 | K35: ='RESUMEN TOTAL'!X58 -> 0 | L35: ='RESUMEN TOTAL'!Y58 -> 0 | M35: ='RESUMEN TOTAL'!Z58 -> 0 | ... AI35: ='RESUMEN TOTAL'!AV58 -> 0 | AJ35: ='RESUMEN TOTAL'!#REF! -> #REF!
A36: ='RESUMEN TOTAL'!F59 -> CENTRO | B36: ='RESUMEN TOTAL'!G59 -> CEN 70 | C36: ='RESUMEN TOTAL'!I59 -> RIVADAVIA Y 25 MAYO | D36: ='RESUMEN TOTAL'!J59 -> Domo | E36: ='RESUMEN TOTAL'!K59 -> Fibra Optica | F36: ='RESUMEN TOTAL'!S59 -> 0 | G36: ='RESUMEN TOTAL'!T59 -> 0 | H36: ='RESUMEN TOTAL'!U59 -> 0 | I36: ='RESUMEN TOTAL'!V59 -> 0 | J36: ='RESUMEN TOTAL'!W59 -> 0 | K36: ='RESUMEN TOTAL'!X59 -> 0 | L36: ='RESUMEN TOTAL'!Y59 -> 0 | M36: ='RESUMEN TOTAL'!Z59 -> 0 | ... AI36: ='RESUMEN TOTAL'!AV59 -> 0 | AJ36: ='RESUMEN TOTAL'!#REF! -> #REF!
... A71: ='RESUMEN TOTAL'!F94 -> CENTRO | B71: ='RESUMEN TOTAL'!G94 -> CEN24 | C71: ='RESUMEN TOTAL'!I94 -> Sallares y España | D71: ='RESUMEN TOTAL'!J94 -> Domo | E71: ='RESUMEN TOTAL'!K94 -> GPON | F71: ='RESUMEN TOTAL'!S94 -> 0 | G71: ='RESUMEN TOTAL'!T94 -> 0 | H71: ='RESUMEN TOTAL'!U94 -> 0 | I71: ='RESUMEN TOTAL'!V94 -> 0 | J71: ='RESUMEN TOTAL'!W94 -> 0 | K71: ='RESUMEN TOTAL'!X94 -> 0 | L71: ='RESUMEN TOTAL'!Y94 -> 0 | M71: ='RESUMEN TOTAL'!Z94 -> 0 | ... AI71: ='RESUMEN TOTAL'!AV94 -> 0 | AJ71: ='RESUMEN TOTAL'!#REF! -> #REF!
A72: ='RESUMEN TOTAL'!F95 -> CENTRO | B72: ='RESUMEN TOTAL'!G95 -> CEN25 | C72: ='RESUMEN TOTAL'!I95 -> SAN MARTIN Y 9 DE JULIO | D72: ='RESUMEN TOTAL'!J95 -> Domo | E72: ='RESUMEN TOTAL'!K95 -> GPON | F72: ='RESUMEN TOTAL'!S95 -> 0 | G72: ='RESUMEN TOTAL'!T95 -> 0 | H72: ='RESUMEN TOTAL'!U95 -> 0 | I72: ='RESUMEN TOTAL'!V95 -> 0 | J72: ='RESUMEN TOTAL'!W95 -> 0 | K72: ='RESUMEN TOTAL'!X95 -> 0 | L72: ='RESUMEN TOTAL'!Y95 -> 0 | M72: ='RESUMEN TOTAL'!Z95 -> 0 | ... Z72: ='RESUMEN TOTAL'!AM95 -> 0 | AA72: ='RESUMEN TOTAL'!#REF! -> #REF! | AB72: ='RESUMEN TOTAL'!AO95 -> 0 | AC72: ='RESUMEN TOTAL'!AP95 -> 0 | AD72: ='RESUMEN TOTAL'!AQ95 -> 0 | AE72: ='RESUMEN TOTAL'!AR95 -> 0 | AF72: ='RESUMEN TOTAL'!AS95 -> 0 | AG72: ='RESUMEN TOTAL'!AT95 -> 0 | AH72: ='RESUMEN TOTAL'!AU95 -> 0 | AI72: ='RESUMEN TOTAL'!AV95 -> 0 | AJ72: ='RESUMEN TOTAL'!#REF! -> #REF!
A73: ='RESUMEN TOTAL'!F96 -> CENTRO | B73: ='RESUMEN TOTAL'!G96 -> CEN26 | C73: ='RESUMEN TOTAL'!I96 -> Mitre y España | D73: ='RESUMEN TOTAL'!J96 -> Domo | E73: ='RESUMEN TOTAL'!K96 -> Fibra Optica | F73: ='RESUMEN TOTAL'!S96 -> 0 | G73: ='RESUMEN TOTAL'!T96 -> 0 | H73: ='RESUMEN TOTAL'!U96 -> 0 | I73: ='RESUMEN TOTAL'!V96 -> 0 | J73: ='RESUMEN TOTAL'!W96 -> 0 | K73: ='RESUMEN TOTAL'!X96 -> 0 | L73: ='RESUMEN TOTAL'!Y96 -> 0 | M73: ='RESUMEN TOTAL'!Z96 -> 0 | ... AI73: ='RESUMEN TOTAL'!AV96 -> 0 | AJ73: ='RESUMEN TOTAL'!#REF! -> #REF!
A74: ='RESUMEN TOTAL'!F97 -> CENTRO | B74: ='RESUMEN TOTAL'!G97 -> CEN27 | C74: ='RESUMEN TOTAL'!I97 -> San Juan y España | D74: ='RESUMEN TOTAL'!J97 -> Domo | E74: ='RESUMEN TOTAL'!K97 -> Fibra Optica | F74: ='RESUMEN TOTAL'!S97 -> 0 | G74: ='RESUMEN TOTAL'!T97 -> 0 | H74: ='RESUMEN TOTAL'!U97 -> 0 | I74: ='RESUMEN TOTAL'!V97 -> 0 | J74: ='RESUMEN TOTAL'!W97 -> 0 | K74: ='RESUMEN TOTAL'!X97 -> 0 | L74: ='RESUMEN TOTAL'!Y97 -> 0 | M74: ='RESUMEN TOTAL'!Z97 -> 0 | ... AI74: ='RESUMEN TOTAL'!AV97 -> 0 | AJ74: ='RESUMEN TOTAL'!#REF! -> #REF!
...

Sheet Hoja1
B1: CAMARAS | C1: 45992
A2: BONOMO | B2: =COUNTIFS('RESUMEN TOTAL'!H8:H629,"=BONOMO") -> 308 | C2: 0 | F2: 46143 | G2: 46144 | H2: 46145 | I2: 46146 | J2: 46147 | K2: 46148 | L2: 46149 | M2: 46150 | N2: 46151 | O2: 46152 | P2: 46153 | Q2: 46154 | R2: 46155 | S2: 46156 | T2: 46157 | U2: 46158 | V2: 46159 | W2: 46160 | X2: 46161 | Y2: 46162 | Z2: 46163 | AA2: 46164 | AB2: 46165 | AC2: 46166 | AD2: 46167 | AE2: 46168 | AF2: 46169 | AG2: 46170 | AH2: 46171 | AI2: 46172 | AJ2: 46173
C3: 0 | D3: BONOMO | E3: APAGADAS BONOMO | F3: 0 | G3: 27 | H3: 31 | I3: 29 | J3: =COUNTIFS('RESUMEN TOTAL'!W8:W706,"=APAGADO",'RESUMEN TOTAL'!H8:H706,"=BONOMO") -> 44 | K3: =COUNTIFS('RESUMEN TOTAL'!X8:X706,"=APAGADO",'RESUMEN TOTAL'!I8:I706,"=BONOMO") -> 0 | L3: =COUNTIFS('RESUMEN TOTAL'!Y8:Y706,"=APAGADO",'RESUMEN TOTAL'!J8:J706,"=BONOMO") -> 0 | M3: =COUNTIFS('RESUMEN TOTAL'!Z8:Z706,"=APAGADO",'RESUMEN TOTAL'!K8:K706,"=BONOMO") -> 0 | N3: =COUNTIFS('RESUMEN TOTAL'!AA8:AA706,"=APAGADO",'RESUMEN TOTAL'!L8:L706,"=BONOMO") -> 0 | O3: =COUNTIFS('RESUMEN TOTAL'!AB8:AB706,"=APAGADO",'RESUMEN TOTAL'!M8:M706,"=BONOMO") -> 0 | P3: =COUNTIFS('RESUMEN TOTAL'!AC8:AC706,"=APAGADO",'RESUMEN TOTAL'!N8:N706,"=BONOMO") -> 0 | Q3: =COUNTIFS('RESUMEN TOTAL'!AD8:AD706,"=APAGADO",'RESUMEN TOTAL'!O8:O706,"=BONOMO") -> 0 | ... AJ3: =COUNTIFS('RESUMEN TOTAL'!AW8:AW706,"=APAGADO",'RESUMEN TOTAL'!AH8:AH706,"=BONOMO") -> 0
A4: COSEIDI | B4: =COUNTIFS('RESUMEN TOTAL'!H8:H629,"=COSEIDI") -> 283 | C4: 0 | E4: % BONOMO | F4: 0 | G4: =G3/BONOMOcam -> 0.087662338 | H4: =H3/BONOMOcam -> 0.10064935 | I4: 0 | J4: 0.09 | K4: =K3/BONOMOcam -> 0 | L4: =L3/BONOMOcam -> 0 | M4: 0 | N4: =N3/BONOMOcam -> 0 | O4: =O3/BONOMOcam -> 0 | P4: =P3/BONOMOcam -> 0 | Q4: =Q3/BONOMOcam -> 0 | R4: =R3/BONOMOcam -> 0 | S4: =S3/BONOMOcam -> 0 | T4: =T3/BONOMOcam -> 0 | U4: =U3/BONOMOcam -> 0 | V4: =V3/BONOMOcam -> 0 | W4: 0 | X4: =X3/BONOMOcam -> 0 | Y4: =Y3/BONOMOcam -> 0 | Z4: =Z3/BONOMOcam -> 0 | AA4: =AA3/BONOMOcam -> 0 | AB4: =AB3/BONOMOcam -> 0 | AC4: 0 | AD4: =AD3/BONOMOcam -> 0 | AE4: =AE3/BONOMOcam -> 0 | AF4: =AF3/BONOMOcam -> 0 | AG4: =AG3/BONOMOcam -> 0 | AH4: =AH3/BONOMOcam -> 0 | AI4: =AI3/BONOMOcam -> 0 | AJ4: =AJ3/BONOMOcam -> 0
C5: 0 | D5: COSEIDI | E5: APAGADAS COSEIDI | F5: 0 | G5: 41 | H5: 52 | I5: 56 | J5: =COUNTIFS('RESUMEN TOTAL'!W10:W708,"=APAGADO",'RESUMEN TOTAL'!H10:H708,"=COSEIDI") -> 67 | K5: =COUNTIFS('RESUMEN TOTAL'!X10:X708,"=APAGADO",'RESUMEN TOTAL'!I10:I708,"=COSEIDI") -> 0 | L5: =COUNTIFS('RESUMEN TOTAL'!Y10:Y708,"=APAGADO",'RESUMEN TOTAL'!J10:J708,"=COSEIDI") -> 0 | M5: =COUNTIFS('RESUMEN TOTAL'!Z10:Z708,"=APAGADO",'RESUMEN TOTAL'!K10:K708,"=COSEIDI") -> 0 | N5: =COUNTIFS('RESUMEN TOTAL'!AA10:AA708,"=APAGADO",'RESUMEN TOTAL'!L10:L708,"=COSEIDI") -> 0 | O5: =COUNTIFS('RESUMEN TOTAL'!AB10:AB708,"=APAGADO",'RESUMEN TOTAL'!M10:M708,"=COSEIDI") -> 0 | P5: =COUNTIFS('RESUMEN TOTAL'!AC10:AC708,"=APAGADO",'RESUMEN TOTAL'!N10:N708,"=COSEIDI") -> 0 | Q5: =COUNTIFS('RESUMEN TOTAL'!AD10:AD708,"=APAGADO",'RESUMEN TOTAL'!O10:O708,"=COSEIDI") -> 0 | ... AJ5: =COUNTIFS('RESUMEN TOTAL'!AW10:AW708,"=APAGADO",'RESUMEN TOTAL'!AH10:AH708,"=COSEIDI") -> 0
E6: % COSEIDI | F6: 0 | G6: =G5/COSEIDIcam -> 0.14487633 | H6: 0.18 | I6: 0 | J6: 0.14 | K6: =K5/COSEIDIcam -> 0 | L6: =L5/COSEIDIcam -> 0 | M6: 0 | N6: =N5/COSEIDIcam -> 0 | O6: =O5/COSEIDIcam -> 0 | P6: 0 | Q6: =Q5/COSEIDIcam -> 0 | R6: =R5/COSEIDIcam -> 0 | S6: =S5/COSEIDIcam -> 0 | T6: 0 | U6: 0 | V6: 0 | W6: =W5/COSEIDIcam -> 0 | X6: =X5/COSEIDIcam -> 0 | Y6: =Y5/COSEIDIcam -> 0 | Z6: =Z5/COSEIDIcam -> 0 | AA6: =AA5/COSEIDIcam -> 0 | AB6: =AB5/COSEIDIcam -> 0 | AC6: 0 | AD6: =AD5/COSEIDIcam -> 0 | AE6: =AE5/COSEIDIcam -> 0 | AF6: =AF5/COSEIDIcam -> 0 | AG6: 0 | AH6: 0 | AI6: 0 | AJ6: 0

Sheet informe
C1: CANTIDAD | D1: APAGADAS | E1: %
B2: TOTAL | C2: =CANTIDAD_DE_CAMARAS -> 591 | F2: 46113
A3: L | B3: CAIDAS | C3: ='RESUMEN TOTAL'!S3 -> 0 | E3: =C3/C2 -> 0
B4: LLEGAMOS NOSOTROS | C4: 17 | D4: =C3-C4 -> -17 | E4: =D4/C2 -> -0.028764805
B5: NO ESTA LA CAMARA | C5: 11 | D5: =D4-C5 -> -28 | E5: =D5/C2 -> -0.047377327
A6: L | B6: RADIO | C6: 16 | D6: =D5-C6 -> -44 | E6: =D6/C2 -> -0.074450085
C7: 0 | D7: 0 | E7: =D7/C2 -> 0
C8: CANTIDAD | D8: APAGADAS | E8: %
A9: F | B9: BONOMO | C9: 307 | D9: 39 | E9: =D9/C9 -> 0.12703583
A10: F | B10: COSEIDI | C10: =COSEIDIcam -> 283 | D10: 68 | E10: =D10/C10 -> 0.24028269
C12: CANTIDAD | D12: APAGADAS | E12: %
B13: TOTAL | C13: =CANTIDAD_DE_CAMARAS -> 591 | F13: 46114
A14: M | B14: CAIDAS | C14: 87 | E14: =C14/C13 -> 0.14720812
B15: LLEGAMOS NOSOTROS | C15: 3 | D15: 84 | E15: =D15/C13 -> 0.14213198
B16: NO ESTA LA CAMARA | C16: 7 | D16: 77 | E16: =D16/C13 -> 0.13028765
A17: M | B17: RADIO | C17: 5 | D17: 72 | E17: =D17/C13 -> 0.12182741
D18: 0 | E18: =D18/C13 -> 0
C19: CANTIDAD | D19: APAGADAS | E19: %
A20: G | B20: BONOMO | C20: 307 | D20: 32 | E20: =D20/C20 -> 0.10423453
A21: G | B21: COSEIDI | C21: =COSEIDIcam -> 283 | D21: 55 | E21: =D21/C21 -> 0.19434629
C23: CANTIDAD | D23: APAGADAS | E23: %
B24: TOTAL | C24: =CANTIDAD_DE_CAMARAS -> 591 | F24: 46115
A25: N | B25: CAIDAS | C25: ='RESUMEN TOTAL'!U3 -> 0 | E25: =C25/C24 -> 0
B26: LLEGAMOS NOSOTROS | C26: 6 | D26: =C25-C26 -> -6 | E26: =D26/C24 -> -0.010152284
B27: NO ESTA LA CAMARA | C27: 7 | D27: =D26-C27 -> -13 | E27: =D27/C24 -> -0.021996616
A28: N | B28: RADIO | C28: ='RESUMEN TOTAL'!U5 -> 0 | D28: =D27-C28 -> -13 | E28: =D28/C24 -> -0.021996616
C29: 0 | D29: 0 | E29: =D29/C24 -> 0
C30: CANTIDAD | D30: APAGADAS | E30: %
B31: BONOMO | C31: 307 | D31: 31 | E31: =D31/C31 -> 0.1009772
B32: COSEIDI | C32: =COSEIDIcam -> 283 | D32: 52 | E32: =D32/C32 -> 0.18374558
C34: CANTIDAD | D34: APAGADAS | E34: %
B35: TOTAL | C35: =CANTIDAD_DE_CAMARAS -> 591 | F35: 46146
A36: O | B36: CAIDAS | C36: ='RESUMEN TOTAL'!V3 -> 115 | E36: =C36/C35 -> 0.19458545
B37: LLEGAMOS NOSOTROS | C37: 6 | D37: =C36-C37 -> 109 | E37: =D37/C35 -> 0.18443316
B38: NO ESTA LA CAMARA | C38: 12 | D38: =D37-C38 -> 97 | E38: =D38/C35 -> 0.1641286
A39: O | B39: RADIO | C39: 5 | D39: =D38-C39 -> 92 | E39: =D39/C35 -> 0.15566836
C40: 0 | D40: 0 | E40: =D40/C35 -> 0
C41: CANTIDAD | D41: APAGADAS | E41: %
B42: BONOMO | C42: 307 | D42: 47 | E42: =D42/C42 -> 0.15309446
B43: COSEIDI | C43: =COSEIDIcam -> 283 | D43: 68 | E43: =D43/C43 -> 0.24028269
...
