Workbook
Name _25_de_agosto: 'RESUMEN TOTAL'!$F$7:$I$503
Name _25_de_agosto_3: 'RESUMEN TOTAL'!$F$7:$I$515
Name _30_mar: #REF!
Name BONOMOcam: Hoja1!$B$2
Name CANTIDAD_DE_CAMARAS: 'RESUMEN TOTAL'!$G$1
Name COSEIDIcam: Hoja1!$B$4

Sheet RESUMEN TOTAL
E1: < | F1: CANTIDAD DE CAMARAS | G1: =COUNTA(G8:G750) -> 589 | I1: PORCIENTO DE CAIDAS | S1: =(S3)/(S2+S3) -> 0.15373563 | T1: =(T3)/(T2+T3) -> 0 | U1: =(U3)/(U2+U3) -> 0 | V1: =(V3)/(V2+V3) -> 0 | W1: =(W3)/(W2+W3) -> 0 | X1: =(X3)/(X2+X3) -> 0.15373563 | Y1: =(Y3)/(Y2+Y3) -> 0.14637681 | Z1: =(Z3)/(Z2+Z3) -> 0.15007215 | ... AE1: =(AE3)/(AE2+AE3) -> 0.15251799 | AG1: =(AG3)/(AG2+AG3) -> 0.16925247 | AH1: =(AH3)/(AH2+AH3) -> 0.15007215 | AI1: =(AI3)/(AI2+AI3) -> 0.17507003 | AJ1: =(AJ3)/(AJ2+AJ3) -> 0 | AK1: =(AK3)/(AK2+AK3) -> 0 | AL1: =(AL3)/(AL2+AL3) -> 0.15977175 | AM1: =(AM3)/(AM2+AM3) -> 0.14389535 | AN1: =(AN3)/(AN2+AN3) -> 0.1426492 | ... AV1: =(AV3)/(AV2+AV3) -> 0.16096866
I2: FUNCIONAN | S2: =CANTIDAD_DE_CAMARAS -> 589 | T2: =CANTIDAD_DE_CAMARAS -> 589 | U2: =CANTIDAD_DE_CAMARAS -> 589 | V2: =CANTIDAD_DE_CAMARAS -> 589 | W2: =CANTIDAD_DE_CAMARAS -> 589 | X2: =CANTIDAD_DE_CAMARAS -> 589 | Y2: =CANTIDAD_DE_CAMARAS -> 589 | Z2: =CANTIDAD_DE_CAMARAS -> 589 | ... AV2: =CANTIDAD_DE_CAMARAS -> 589
I3: CAIDAS | S3: =COUNTIF(S7:S750, "apagado") -> 107 | T3: =COUNTIF(T7:T750, "apagado") -> 0 | U3: =COUNTIF(U7:U750, "apagado") -> 0 | V3: =COUNTIF(V7:V750, "apagado") -> 0 | W3: =COUNTIF(W7:W750, "apagado") -> 0 | X3: =COUNTIF(X7:X750, "apagado") -> 107 | Y3: =COUNTIF(Y7:Y750, "apagado") -> 101 | Z3: =COUNTIF(Z7:Z750, "apagado") -> 104 | ... AV3: =COUNTIF(AV7:AV750, "apagado") -> 113
I4: APAGADOS FIBRA | S4: =COUNTIFS(S8:S704, "=APAGADO",K8:K704,"=Fibra Optica") -> 48 | T4: =COUNTIFS(T8:T704, "=APAGADO",K8:K704,"=Fibra Optica") -> 0 | U4: =COUNTIFS(U8:U704, "=APAGADO",K8:K704,"=Fibra Optica") -> 0 | V4: =COUNTIFS(V8:V704, "=APAGADO",K8:K704,"=Fibra Optica") -> 0 | W4: =COUNTIFS(W8:W704, "=APAGADO",K8:K704,"=Fibra Optica") -> 0 | X4: =COUNTIFS(X8:X704, "=APAGADO",K8:K704,"=Fibra Optica") -> 46 | Y4: =COUNTIFS(Y8:Y704, "=APAGADO",K8:K704,"=Fibra Optica") -> 41 | Z4: =COUNTIFS(Z8:Z704, "=APAGADO",K8:K704,"=Fibra Optica") -> 43 | AA4: =COUNTIFS(AA8:AA704, "=APAGADO",K8:K704,"=Fibra Optica") -> 0 | AB4: =COUNTIFS(AB8:AB704, "=APAGADO",K8:K704,"=Fibra Optica") -> 0 | AC4: =COUNTIFS(AC8:AC704, "=APAGADO",K8:K704,"=Fibra Optica") -> 0 | AD4: =COUNTIFS(AD8:AD704, "=APAGADO",K8:K704,"=Fibra Optica") -> 0 | AE4: =COUNTIFS(AE8:AE704, "=APAGADO",K8:K704,"=Fibra Optica") -> 48 | AF4: =COUNTIFS(AF8:AF704, "=APAGADO",K8:K704,"=Fibra Optica") -> 69 | AG4: =COUNTIFS(AG8:AG704, "=APAGADO",K8:K704,"=Fibra Optica") -> 62 | AH4: =COUNTIFS(AH8:AH704, "=APAGADO",K8:K704,"=Fibra Optica") -> 51 | AI4: =COUNTIFS(AI8:AI704, "=APAGADO",K8:K704,"=Fibra Optica") -> 72 | AJ4: =COUNTIFS(AJ8:AJ704, "=APAGADO",K8:K704,"=Fibra Optica") -> 0 | AK4: =COUNTIFS(AK8:AK704, "=APAGADO",K8:K704,"=Fibra Optica") -> 0 | AL4: =COUNTIFS(AL8:AL704, "=APAGADO",K8:K704,"=Fibra Optica") -> 59 | AM4: =COUNTIFS(AM8:AM704, "=APAGADO",K8:K704,"=Fibra Optica") -> 51 | AN4: =COUNTIFS(AN8:AN704, "=APAGADO",K8:K704,"=Fibra Optica") -> 47 | AO4: =COUNTIFS(AO8:AO704, "=APAGADO",K8:K704,"=Fibra Optica") -> 77 | AP4: =COUNTIFS(AP8:AP704, "=APAGADO",K8:K704,"=Fibra Optica") -> 73 | AQ4: =COUNTIFS(AQ8:AQ704, "=APAGADO",K8:K704,"=Fibra Optica") -> 0 | AR4: =COUNTIFS(AR8:AR704, "=APAGADO",K8:K704,"=Fibra Optica") -> 0 | AS4: =COUNTIFS(AS8:AS704, "=APAGADO",K8:K704,"=Fibra Optica") -> 59 | AT4: =COUNTIFS(AT8:AT704, "=APAGADO",K8:K704,"=Fibra Optica") -> 62 | AU4: =COUNTIFS(AU8:AU704, "=APAGADO",L8:L704,"=Fibra Optica") -> 0 | AV4: =COUNTIFS(AV8:AV704, "=APAGADO",M8:M704,"=Fibra Optica") -> 0
I5: APAGADOS RADIO | S5: =COUNTIFS(S8:S704, "=APAGADO",K8:K704,"=RADIO") -> 16 | T5: =COUNTIFS(T8:T704, "=APAGADO",K8:K704,"=RADIO") -> 0 | U5: =COUNTIFS(U8:U704, "=APAGADO",K8:K704,"=RADIO") -> 0 | V5: =COUNTIFS(V8:V704, "=APAGADO",K8:K704,"=RADIO") -> 0 | W5: =COUNTIFS(W8:W704, "=APAGADO",K8:K704,"=RADIO") -> 0 | X5: =COUNTIFS(X8:X704, "=APAGADO",K8:K704,"=RADIO") -> 6 | Y5: =COUNTIFS(Y8:Y704, "=APAGADO",K8:K704,"=RADIO") -> 6 | Z5: =COUNTIFS(Z8:Z704, "=APAGADO",K8:K704,"=RADIO") -> 5 | AA5: =COUNTIFS(AA8:AA704, "=APAGADO",K8:K704,"=RADIO") -> 0 | AB5: =COUNTIFS(AB8:AB704, "=APAGADO",K8:K704,"=RADIO") -> 0 | AC5: =COUNTIFS(AC8:AC704, "=APAGADO",K8:K704,"=RADIO") -> 0 | AD5: =COUNTIFS(AD8:AD704, "=APAGADO",K8:K704,"=RADIO") -> 0 | AE5: =COUNTIFS(AE8:AE704, "=APAGADO",K8:K704,"=RADIO") -> 5 | AF5: =COUNTIFS(AF8:AF704, "=APAGADO",K8:K704,"=RADIO") -> 5 | AG5: =COUNTIFS(AG8:AG704, "=APAGADO",K8:K704,"=RADIO") -> 5 | AH5: =COUNTIFS(AH8:AH704, "=APAGADO",K8:K704,"=RADIO") -> 5 | AI5: =COUNTIFS(AI8:AI704, "=APAGADO",K8:K704,"=RADIO") -> 5 | AJ5: =COUNTIFS(AJ8:AJ704, "=APAGADO",K8:K704,"=RADIO") -> 0 | AK5: =COUNTIFS(AK8:AK704, "=APAGADO",K8:K704,"=RADIO") -> 0 | AL5: =COUNTIFS(AL8:AL704, "=APAGADO",K8:K704,"=RADIO") -> 5 | AM5: =COUNTIFS(AM8:AM704, "=APAGADO",K8:K704,"=RADIO") -> 5 | AN5: =COUNTIFS(AN8:AN704, "=APAGADO",K8:K704,"=RADIO") -> 5 | AO5: =COUNTIFS(AO8:AO704, "=APAGADO",K8:K704,"=RADIO") -> 5 | AP5: =COUNTIFS(AP8:AP704, "=APAGADO",K8:K704,"=RADIO") -> 6 | AQ5: =COUNTIFS(AQ8:AQ704, "=APAGADO",K8:K704,"=RADIO") -> 0 | AR5: =COUNTIFS(AR8:AR704, "=APAGADO",K8:K704,"=RADIO") -> 0 | AS5: =COUNTIFS(AS8:AS704, "=APAGADO",K8:K704,"=RADIO") -> 6 | AT5: =COUNTIFS(AT8:AT704, "=APAGADO",K8:K704,"=RADIO") -> 5 | AU5: =COUNTIFS(AU8:AU704, "=APAGADO",L8:L704,"=RADIO") -> 0 | AV5: =COUNTIFS(AV8:AV704, "=APAGADO",M8:M704,"=RADIO") -> 0
I6: APAGADOS ANTENA | S6: =COUNTIFS(S8:S704, "=APAGADO",K8:K704,"=PTO A FO") -> 8 | T6: =COUNTIFS(T8:T704, "=APAGADO",K8:K704,"=PTO A FO") -> 0 | U6: =COUNTIFS(U8:U704, "=APAGADO",K8:K704,"=PTO A FO") -> 0 | V6: =COUNTIFS(V8:V704, "=APAGADO",K8:K704,"=PTO A FO") -> 0 | W6: =COUNTIFS(W8:W704, "=APAGADO",K8:K704,"=PTO A FO") -> 0 | X6: =COUNTIFS(X8:X704, "=APAGADO",K8:K704,"=PTO A FO") -> 14 | Y6: =COUNTIFS(Y8:Y704, "=APAGADO",K8:K704,"=PTO A FO") -> 11 | Z6: =COUNTIFS(Z8:Z704, "=APAGADO",K8:K704,"=PTO A FO") -> 13 | AA6: =COUNTIFS(AA8:AA704, "=APAGADO",K8:K704,"=PTO A FO") -> 0 | AB6: =COUNTIFS(AB8:AB704, "=APAGADO",K8:K704,"=PTO A FO") -> 0 | AC6: =COUNTIFS(AC8:AC704, "=APAGADO",K8:K704,"=PTO A FO") -> 0 | AD6: =COUNTIFS(AD8:AD704, "=APAGADO",K8:K704,"=PTO A FO") -> 0 | AE6: =COUNTIFS(AE8:AE704, "=APAGADO",K8:K704,"=PTO A FO") -> 13 | AF6: =COUNTIFS(AF8:AF704, "=APAGADO",K8:K704,"=PTO A FO") -> 12 | AG6: =COUNTIFS(AG8:AG704, "=APAGADO",K8:K704,"=PTO A FO") -> 12 | AH6: =COUNTIFS(AH8:AH704, "=APAGADO",K8:K704,"=PTO A FO") -> 8 | AI6: =COUNTIFS(AI8:AI704, "=APAGADO",K8:K704,"=PTO A FO") -> 8 | AJ6: =COUNTIFS(AJ8:AJ704, "=APAGADO",K8:K704,"=PTO A FO") -> 0 | AK6: =COUNTIFS(AK8:AK704, "=APAGADO",K8:K704,"=PTO A FO") -> 0 | AL6: =COUNTIFS(AL8:AL704, "=APAGADO",K8:K704,"=PTO A FO") -> 7 | AM6: =COUNTIFS(AM8:AM704, "=APAGADO",K8:K704,"=PTO A FO") -> 6 | AN6: =COUNTIFS(AN8:AN704, "=APAGADO",K8:K704,"=PTO A FO") -> 5 | AO6: =COUNTIFS(AO8:AO704, "=APAGADO",K8:K704,"=PTO A FO") -> 11 | AP6: =COUNTIFS(AP8:AP704, "=APAGADO",K8:K704,"=PTO A FO") -> 8 | AQ6: =COUNTIFS(AQ8:AQ704, "=APAGADO",K8:K704,"=PTO A FO") -> 0 | AR6: =COUNTIFS(AR8:AR704, "=APAGADO",K8:K704,"=PTO A FO") -> 0 | AS6: =COUNTIFS(AS8:AS704, "=APAGADO",K8:K704,"=PTO A FO") -> 12 | AT6: =COUNTIFS(AT8:AT704, "=APAGADO",K8:K704,"=PTO A FO") -> 13 | AU6: =COUNTIFS(AU8:AU704, "=APAGADO",L8:L704,"=PTO A FO") -> 0 | AV6: =COUNTIFS(AV8:AV704, "=APAGADO",M8:M704,"=PTO A FO") -> 0
A7: BANDEJA | B7: PELO | C7: SWITCH | D7: PUERTO | E7: NOMBRE | F7: Barrio | G7: [Denominacion] | H7: [Empresa Mantenimiento] | I7: [Ubicacion] | J7: [Tipo de Camara] | K7: [Tipo de Conexion] | L7: Destino | M7: [IP] | N7: Switch | O7: DIAS FUNCIONANDO | P7: MAC | Q7: DIAS CAIDA | R7: EFECTIVIDAD | S7: 46113 | T7: 46114 | U7: 46115 | V7: 46116 | W7: 46117 | X7: 46118 | Y7: 46119 | Z7: 46120 | AA7: 46121 | AB7: 46122 | AC7: 46123 | AD7: 46124 | AE7: 46125 | AF7: 46126 | AG7: 46127 | AH7: 46128 | AI7: 46129 | AJ7: 46130 | AK7: 46131 | AL7: 46132 | AM7: 46133 | AN7: 46134 | AO7: 46135 | AP7: 46136 | AQ7: 46137 | AR7: 46138 | AS7: 46139 | AT7: 46140 | AU7: 46141 | AV7: 46142
F8: ZEBALLOS | G8: ZEB04 | H8: BONOMO | I8: THEVENET Y DIAGONAL GRANADEROS | J8: DOMO | K8: GPON | M8: 172.20.10.181 | O8: =COUNTIF(S8:AT8,"") -> 28 | P8: 00-07-5F-81-9C-84 | Q8: =COUNTIF(S8:AT8,"APAGADO") -> 0 | R8: =(O8)/(Q8+O8) -> 1
F9: 9 DE JULIO | G9: ZEB03 | H9: COSEIDI | I9: Quinquela Martin y Pte. Peron | J9: Domo | K9: GPON | M9: 172.20.10.153 | O9: =COUNTIF(S9:AT9,"") -> 28 | P9: 00-07-5F-8F-28-07 | Q9: =COUNTIF(S9:AT9,"APAGADO") -> 0 | R9: =(O9)/(Q9+O9) -> 1
F10: ZEBALLOS | G10: ZEB02 | H10: COSEIDI | I10: Quinquela Martin y Sgo. del Estero | J10: Domo | K10: GPON | M10: 172.20.10.155 | O10: =COUNTIF(S10:AT10,"") -> 28 | P10: 00-07-5F-75-24-78 | Q10: =COUNTIF(S10:AT10,"APAGADO") -> 0 | R10: =(O10)/(Q10+O10) -> 1
F11: ZEBALLOS | G11: ZEB 10 | H11: BONOMO | I11: Sallares y Jujuy | J11: DOMO | K11: GPON | M11: 172.20.8.56 | O11: =COUNTIF(S11:AT11,"") -> 28 | P11: a4-18-94-05-47-3f | Q11: =COUNTIF(S11:AT11,"APAGADO") -> 0 | R11: =(O11)/(Q11+O11) -> 1
F12: ZEBALLOS | G12: ZEB 09 | H12: BONOMO | I12: Tte.Gral Peron y Salta | J12: DOMO | K12: GPON | M12: 172.20.8.31 | O12: =COUNTIF(S12:AT12,"") -> 28 | P12: A4-18-94-05-51-15 | Q12: =COUNTIF(S12:AT12,"APAGADO") -> 0 | R12: =(O12)/(Q12+O12) -> 1
F13: ZEBALLOS | G13: ZEB 08 (Fija 2) | H13: BONOMO | I13: Quinquela Martin y 861 | J13: Fija | K13: GPON | M13: 172.20.10.99 | O13: =COUNTIF(S13:AT13,"") -> 28 | P13: 3C-1B-F8-DF-95-44 | Q13: =COUNTIF(S13:AT13,"APAGADO") -> 0 | R13: =(O13)/(Q13+O13) -> 1
F14: ZEBALLOS | G14: ZEB 07 (Fija 1) | H14: BONOMO | I14: Quinquela Martn y 861 | J14: Fija | K14: GPON | M14: 172.20.10.79 | O14: =COUNTIF(S14:AT14,"") -> 28 | P14: 3C-1B-F8-DF-95-45 | Q14: =COUNTIF(S14:AT14,"APAGADO") -> 0 | R14: =(O14)/(Q14+O14) -> 1
F15: ZEBALLOS | G15: ZEB 06 | H15: BONOMO | I15: Peron e/Ituzaingo y Buenos Aires | J15: FIJA | K15: GPON | M15: 172.20.10.58 | O15: =COUNTIF(S15:AT15,"") -> 28 | P15: A0-FF-0C-EF-DF-AE | Q15: =COUNTIF(S15:AT15,"APAGADO") -> 0 | R15: =(O15)/(Q15+O15) -> 1
F16: ZEBALLOS | G16: ZEB 05 | H16: BONOMO | I16: DIAG. GRANADEROS Y 214 BIS | J16: Domo | K16: GPON | M16: 172.20.10.183 | O16: =COUNTIF(S16:AT16,"") -> 14 | P16: 00-07-5F-81-9C-AC | Q16: =COUNTIF(S16:AT16,"APAGADO") -> 14 | R16: =(O16)/(Q16+O16) -> 0.5 | S16: APAGADO | X16: APAGADO | Y16: APAGADO | Z16: APAGADO | AE16: APAGADO | AF16: APAGADO | AG16: APAGADO | AH16: APAGADO | AL16: APAGADO | AM16: APAGADO | AN16: APAGADO | AO16: APAGADO | AP16: APAGADO | AS16: APAGADO
F17: VILLA SUSANA | G17: VSU01 | H17: COSEIDI | I17: CJAL. JUAN BROWN Y SANTA FE | J17: DOMO | K17: Radio | M17: 10.20.30.27 | O17: =COUNTIF(S17:AT17,"") -> 28 | P17: 00-07-5f-81-9b-f5 | Q17: =COUNTIF(S17:AT17,"APAGADO") -> 0 | R17: =(O17)/(Q17+O17) -> 1
A18: 4 | B18: 12 | E18: brasil y cabello | F18: VILLA SUSANA | G18: VSU 06 | H18: COSEIDI | I18: EE.UU Y BROWN | J18: DOMO | K18: Fibra Optica | M18: 172.20.11.111 | O18: =COUNTIF(S18:AT18,"") -> 28 | P18: 00-07-5F-D2-52-EE | Q18: =COUNTIF(S18:AT18,"APAGADO") -> 0 | R18: =(O18)/(Q18+O18) -> 1
A19: 4 | B19: 12 | E19: brasil y cabello | F19: VILLA SUSANA | G19: VSU 05 | H19: COSEIDI | I19: Aniceto Diaz y Cordoba | J19: fija | K19: Fibra Optica | M19: 172.20.11.48 | O19: =COUNTIF(S19:AT19,"") -> 27 | P19: 00-07-5F-BD-55-94 | Q19: =COUNTIF(S19:AT19,"APAGADO") -> 1 | R19: =(O19)/(Q19+O19) -> 0.96428571 | AI19: APAGADO
A20: 4 | B20: 12 | E20: brasil y cabello | F20: VILLA SUSANA | G20: VSU 04 | H20: COSEIDI | I20: Aniceto Diaz y Cordoba | J20: fija | K20: Fibra Optica | M20: 172.20.11.47 | O20: =COUNTIF(S20:AT20,"") -> 28 | P20: 00-07-5F-BC-DF-28 | Q20: =COUNTIF(S20:AT20,"APAGADO") -> 0 | R20: =(O20)/(Q20+O20) -> 1
F21: VILLA SUSANA | G21: VSU 03 | H21: COSEIDI | I21: EE.UU Y SERRANO | J21: DOMO | K21: Radio | M21: 10.20.30.32 | O21: =COUNTIF(S21:AT21,"") -> 28 | P21: 00-07-5f--81-9b-ec | Q21: =COUNTIF(S21:AT21,"APAGADO") -> 0 | R21: =(O21)/(Q21+O21) -> 1
F22: VILLA SUSANA | G22: VSU 02 | H22: COSEIDI | I22: CABELLO Y SANTA FE | J22: DOMO | K22: Radio | M22: 10.20.30.31 | O22: =COUNTIF(S22:AT22,"") -> 25 | P22: 00-04-63-4f-dd-ad | Q22: =COUNTIF(S22:AT22,"APAGADO") -> 3 | R22: =(O22)/(Q22+O22) -> 0.89285714 | S22: APAGADO | X22: APAGADO | Y22: APAGADO
F23: VILLA SAN LUIS | G23: VSL 03 | H23: COSEIDI | I23: 1314 y 1371 | J23: DOMO | K23: GPON | M23: 172.20.8.71 | O23: =COUNTIF(S23:AT23,"") -> 28 | Q23: =COUNTIF(S23:AT23,"APAGADO") -> 0 | R23: =(O23)/(Q23+O23) -> 1
F24: VILLA SAN LUIS | G24: VSL 02 | H24: COSEIDI | I24: 1355 Y 1314 | J24: DOMO | K24: GPON | M24: 172.20.8.70 | O24: =COUNTIF(S24:AT24,"") -> 28 | P24: A4-18-94-05-50-DC | Q24: =COUNTIF(S24:AT24,"APAGADO") -> 0 | R24: =(O24)/(Q24+O24) -> 1
F25: VILLA SAN LUIS | G25: VSL 01 | H25: COSEIDI | I25: AV. HUDSON Y CACHEUTA | J25: DOMO | K25: GPON | M25: 172.20.11.63 | O25: =COUNTIF(S25:AT25,"") -> 28 | P25: 00-07-5f-81-9c-af | Q25: =COUNTIF(S25:AT25,"APAGADO") -> 0 | R25: =(O25)/(Q25+O25) -> 1
A26: 6 | B26: 12 | E26: PUNTO SEGURO PICO DE ORO | F26: VILLA MONICA VIEJA | G26: VMOV04 (fija 2) | H26: COSEIDI | I26: ROMA E/ HOLANDA Y CAFFERATA | J26: Fija | K26: Fibra Optica | M26: 172.20.11.178 | O26: =COUNTIF(S26:AT26,"") -> 22 | P26: 00-07-5F-B4-43-5D | Q26: =COUNTIF(S26:AT26,"APAGADO") -> 6 | R26: =(O26)/(Q26+O26) -> 0.78571429 | S26: APAGADO | AI26: APAGADO | AO26: APAGADO | AP26: APAGADO | AS26: APAGADO | AT26: APAGADO | AU26: APAGADO | AV26: APAGADO
A27: 6 | B27: 12 | E27: PUNTO SEGURO PICO DE ORO | F27: VILLA MONICA VIEJA | G27: VMOV01 (fija 1) | H27: COSEIDI | I27: ATENAS E/ CAFFERATA Y ALEMANIA | J27: Fija | K27: Fibra Optica | M27: 172.20.11.175 | O27: =COUNTIF(S27:AT27,"") -> 23 | P27: 00-07-5F-B6-A1-33 | Q27: =COUNTIF(S27:AT27,"APAGADO") -> 5 | R27: =(O27)/(Q27+O27) -> 0.82142857 | S27: APAGADO | AI27: APAGADO | AO27: APAGADO | AP27: APAGADO | AT27: APAGADO | AU27: APAGADO | AV27: APAGADO
A28: 6 | B28: 12 | E28: PUNTO SEGURO PICO DE ORO | F28: VILLA MONICA VIEJA | G28: VMOV 03 (fija 1) | H28: COSEIDI | I28: ROMA E/ HOLANDA Y CAFFERATA | J28: Fija | K28: Fibra Optica | M28: 172.20.11.177 | O28: =COUNTIF(S28:AT28,"") -> 23 | P28: 00-07-5F-B4-42-D1 | Q28: =COUNTIF(S28:AT28,"APAGADO") -> 5 | R28: =(O28)/(Q28+O28) -> 0.82142857 | S28: APAGADO | AI28: APAGADO | AO28: APAGADO | AP28: APAGADO | AT28: APAGADO | AU28: APAGADO | AV28: APAGADO
A29: 6 | B29: 12 | E29: PUNTO SEGURO PICO DE ORO | F29: VILLA MONICA VIEJA | G29: VMOV 02 (fija 2) | H29: COSEIDI | I29: ATENAS E/ CAFFERATA Y ALEMANIA | J29: Fija | K29: Fibra Optica | M29: 172.20.11.176 | O29: =COUNTIF(S29:AT29,"") -> 23 | P29: 00-07-5F-B6-B9-5D | Q29: =COUNTIF(S29:AT29,"APAGADO") -> 5 | R29: =(O29)/(Q29+O29) -> 0.82142857 | S29: APAGADO | AI29: APAGADO | AO29: APAGADO | AP29: APAGADO | AT29: APAGADO | AU29: APAGADO | AV29: APAGADO
F30: VILLA MONICA NUEVA | G30: VMO01 | H30: COSEIDI | I30: Eva Peron y Monseñor de las Casas | J30: DOMO | K30: Fibra Optica | M30: 172.20.11.107 | O30: =COUNTIF(S30:AT30,"") -> 13 | P30: 00-04-63-4F-D3-F8 | Q30: =COUNTIF(S30:AT30,"APAGADO") -> 15 | R30: =(O30)/(Q30+O30) -> 0.46428571 | X30: APAGADO | Y30: APAGADO | Z30: APAGADO | AE30: APAGADO | AF30: APAGADO | AG30: APAGADO | AH30: APAGADO | AI30: APAGADO | AL30: APAGADO | AM30: APAGADO | AN30: APAGADO | AO30: APAGADO | AP30: APAGADO | AS30: APAGADO | AT30: APAGADO | AU30: APAGADO | AV30: APAGADO
A31: 6 | B31: 12 | E31: PUNTO SEGURO PICO DE ORO | F31: VILLA MONICA NUEVA | G31: VMO 05 | H31: COSEIDI | I31: OROÑO Y EVA PERON | J31: DOMO | K31: Fibra Optica | M31: 172.20.11.78 | O31: =COUNTIF(S31:AT31,"") -> 22 | P31: 00-07-5F-87-9F-8E | Q31: =COUNTIF(S31:AT31,"APAGADO") -> 6 | R31: =(O31)/(Q31+O31) -> 0.78571429 | S31: APAGADO | AI31: APAGADO | AO31: APAGADO | AP31: APAGADO | AS31: APAGADO | AT31: APAGADO | AU31: APAGADO | AV31: APAGADO
A32: 6 | B32: 12 | E32: PUNTO SEGURO PICO DE ORO | F32: VILLA MONICA NUEVA | G32: VMO 04 (fija 2) | H32: COSEIDI | I32: EVA PERON E/ OROÑO Y 734 A | J32: Fija | K32: Fibra Optica | M32: 172.20.11.80 | O32: =COUNTIF(S32:AT32,"") -> 22 | P32: 00-07-5F-B6-B8-C3 | Q32: =COUNTIF(S32:AT32,"APAGADO") -> 6 | R32: =(O32)/(Q32+O32) -> 0.78571429 | S32: APAGADO | AI32: APAGADO | AO32: APAGADO | AP32: APAGADO | AS32: APAGADO | AT32: APAGADO | AU32: APAGADO | AV32: APAGADO
A33: 6 | B33: 12 | E33: PUNTO SEGURO PICO DE ORO | F33: VILLA MONICA NUEVA | G33: VMO 03 (fija 1) | H33: COSEIDI | I33: EVA PERON E/ OROÑO Y 734 A | J33: Fija | K33: Fibra Optica | M33: 172.20.11.79 | O33: =COUNTIF(S33:AT33,"") -> 22 | P33: 00-07-5F-B4-17-0B | Q33: =COUNTIF(S33:AT33,"APAGADO") -> 6 | R33: =(O33)/(Q33+O33) -> 0.78571429 | S33: APAGADO | AI33: APAGADO | AO33: APAGADO | AP33: APAGADO | AS33: APAGADO | AT33: APAGADO | AU33: APAGADO | AV33: APAGADO
F34: VILLA MONICA NUEVA | G34: VMO 02 | H34: COSEIDI | I34: Rio Carapachay y Oroño | J34: Domo | K34: Radio | M34: 10.20.30.35 | O34: =COUNTIF(S34:AT34,"") -> 27 | P34: 00-07-5f-d2-53-05 | Q34: =COUNTIF(S34:AT34,"APAGADO") -> 1 | R34: =(O34)/(Q34+O34) -> 0.96428571 | AS34: APAGADO
F35: VILLA ARIAS | G35: VLA05 | H35: COSEIDI | I35: ESPORA Y 802 | J35: DOMO | K35: GPON | M35: 172.20.11.164 | O35: =COUNTIF(S35:AT35,"") -> 28 | P35: 00-07-5F-BE-58-FE | Q35: =COUNTIF(S35:AT35,"APAGADO") -> 0 | R35: =(O35)/(Q35+O35) -> 1
F36: VILLA ARIAS | G36: VLA04 | H36: COSEIDI | I36: ESPORA Y MARTIN GRASS | J36: DOMO | K36: Fibra Optica | M36: 172.20.11.163 | O36: =COUNTIF(S36:AT36,"") -> 28 | P36: 00-07-5F-AB-BB-55 | Q36: =COUNTIF(S36:AT36,"APAGADO") -> 0 | R36: =(O36)/(Q36+O36) -> 1
F37: VILLA ARIAS | G37: VLA03 (fija 2) | H37: COSEIDI | I37: 820 y SOLER | J37: Fija | K37: GPON | M37: 172.20.11.162 | O37: =COUNTIF(S37:AT37,"") -> 12 | P37: 00-07-5f-b7-85-79 | Q37: =COUNTIF(S37:AT37,"APAGADO") -> 16 | R37: =(O37)/(Q37+O37) -> 0.42857143 | S37: APAGADO | X37: APAGADO | Y37: APAGADO | Z37: APAGADO | AE37: APAGADO | AF37: APAGADO | AG37: APAGADO | AH37: APAGADO | AI37: APAGADO | AL37: APAGADO | AM37: APAGADO | AN37: APAGADO | AO37: APAGADO | AP37: APAGADO | AS37: APAGADO | AT37: APAGADO | AU37: APAGADO | AV37: APAGADO
F38: VILLA ARIAS | G38: VLA 02 | H38: COSEIDI | I38: ESPORA Y HUDSON | J38: DOMO | K38: Fibra Optica | M38: 172.20.11.165 | O38: =COUNTIF(S38:AT38,"") -> 28 | P38: 00-07-5F-BE-58-4E | Q38: =COUNTIF(S38:AT38,"APAGADO") -> 0 | R38: =(O38)/(Q38+O38) -> 1
F39: VILLA ARIAS | G39: VLA 01 (fija 1) | H39: COSEIDI | I39: 820 Y SOLER | J39: Fija | K39: GPON | M39: 172.20.11.161 | O39: =COUNTIF(S39:AT39,"") -> 12 | P39: 00-07-5f-b4-42-d3 | Q39: =COUNTIF(S39:AT39,"APAGADO") -> 16 | R39: =(O39)/(Q39+O39) -> 0.42857143 | S39: APAGADO | X39: APAGADO | Y39: APAGADO | Z39: APAGADO | AE39: APAGADO | AF39: APAGADO | AG39: APAGADO | AH39: APAGADO | AI39: APAGADO | AL39: APAGADO | AM39: APAGADO | AN39: APAGADO | AO39: APAGADO | AP39: APAGADO | AS39: APAGADO | AT39: APAGADO | AU39: APAGADO | AV39: APAGADO
F40: VILLA HUDSON | G40: VHS07 | H40: COSEIDI | I40: Hudson y Rincon | J40: DOMO | K40: GPON | M40: 172.20.8.30 | O40: =COUNTIF(S40:AT40,"") -> 28 | P40: a4-18-94-05-50-c8 | Q40: =COUNTIF(S40:AT40,"APAGADO") -> 0 | R40: =(O40)/(Q40+O40) -> 1
...

Sheet AUXILIAR

Sheet paradas
C1: TOTAL PARADAS | D1: =COUNTIFS(A5:A602,"=paradas seguras")/2 -> 0 | E1: TOTAL DE CAMARAS EN PARADAS | H1: =COUNTIFS(A5:A602,"=paradas seguras") -> 0 | I1: TOTAL DE CAMARAS | K1: =COUNTIFS(D5:D602,"=GFIJA") -> 0 | L1: TOTAL DE INTERCOMUNICADORES | O1: =COUNTIFS(D5:D602,"=INTERCOMUNICADOR") -> 0
E2: FIJAS | F2: =COUNTIFS(F4:F601, "=APAGADO",D4:D601,"=GFIJA") -> 0 | G2: =COUNTIFS(G4:G601, "=APAGADO",D4:D601,"=GFIJA") -> 0 | H2: =COUNTIFS(H4:H601, "=APAGADO",D4:D601,"=GFIJA") -> 0 | I2: =COUNTIFS(I4:I601, "=APAGADO",D4:D601,"=GFIJA") -> 0 | J2: =COUNTIFS(J4:J601, "=APAGADO",D4:D601,"=GFIJA") -> 0 | K2: =COUNTIFS(K4:K601, "=APAGADO",D4:D601,"=GFIJA") -> 0 | L2: =COUNTIFS(L4:L601, "=APAGADO",D4:D601,"=GFIJA") -> 0 | M2: =COUNTIFS(M4:M601, "=APAGADO",D4:D601,"=GFIJA") -> 0 | N2: =COUNTIFS(N4:N601, "=APAGADO",D4:D601,"=GFIJA") -> 0 | O2: =COUNTIFS(O4:O601, "=APAGADO",D4:D601,"=GFIJA") -> 0 | P2: =COUNTIFS(P4:P601, "=APAGADO",D4:D601,"=GFIJA") -> 0 | Q2: =COUNTIFS(Q4:Q601, "=APAGADO",D4:D601,"=GFIJA") -> 0 | R2: =COUNTIFS(R4:R601, "=APAGADO",D4:D601,"=GFIJA") -> 0 | S2: =COUNTIFS(S4:S601, "=APAGADO",D4:D601,"=GFIJA") -> 0 | T2: =COUNTIFS(T4:T601, "=APAGADO",D4:D601,"=GFIJA") -> 0 | U2: =COUNTIFS(U4:U601, "=APAGADO",D4:D601,"=GFIJA") -> 0 | V2: =COUNTIFS(V4:V601, "=APAGADO",D4:D601,"=GFIJA") -> 0 | W2: =COUNTIFS(W4:W601, "=APAGADO",D4:D601,"=GFIJA") -> 0 | X2: =COUNTIFS(X4:X601, "=APAGADO",D4:D601,"=GFIJA") -> 0 | Y2: =COUNTIFS(Y4:Y601, "=APAGADO",D4:D601,"=GFIJA") -> 0 | Z2: =COUNTIFS(Z4:Z601, "=APAGADO",D4:D601,"=GFIJA") -> 0 | AA2: =COUNTIFS(AA4:AA601, "=APAGADO",D4:D601,"=GFIJA") -> 0 | AB2: =COUNTIFS(AB4:AB601, "=APAGADO",D4:D601,"=GFIJA") -> 0 | AC2: =COUNTIFS(AC4:AC601, "=APAGADO",D4:D601,"=GFIJA") -> 0 | AD2: =COUNTIFS(AD4:AD601, "=APAGADO",D4:D601,"=GFIJA") -> 0 | AE2: =COUNTIFS(AE4:AE601, "=APAGADO",D4:D601,"=GFIJA") -> 0 | AF2: =COUNTIFS(AF4:AF601, "=APAGADO",D4:D601,"=GFIJA") -> 0 | AG2: =COUNTIFS(AG4:AG601, "=APAGADO",D4:D601,"=GFIJA") -> 0 | AH2: =COUNTIFS(AH4:AH601, "=APAGADO",E4:E601,"=GFIJA") -> 0 | AI2: =COUNTIFS(AI4:AI601, "=APAGADO",F4:F601,"=GFIJA") -> 0 | AJ2: =COUNTIFS(AJ4:AJ601, "=APAGADO",G4:G601,"=GFIJA") -> 0
E3: INTERCOMUNICADOR | F3: =COUNTIFS(F6:F603, "=APAGADO",D4:D601,"=INTERCOMUNICADOR") -> 0 | G3: =COUNTIFS(G6:G603, "=APAGADO",D4:D601,"=INTERCOMUNICADOR") -> 0 | H3: =COUNTIFS(H6:H603, "=APAGADO",D4:D601,"=INTERCOMUNICADOR") -> 0 | I3: =COUNTIFS(I6:I603, "=APAGADO",D4:D601,"=INTERCOMUNICADOR") -> 0 | J3: =COUNTIFS(J6:J603, "=APAGADO",D4:D601,"=INTERCOMUNICADOR") -> 0 | K3: =COUNTIFS(K6:K603, "=APAGADO",D4:D601,"=INTERCOMUNICADOR") -> 0 | L3: =COUNTIFS(L6:L603, "=APAGADO",D4:D601,"=INTERCOMUNICADOR") -> 0 | M3: =COUNTIFS(M6:M603, "=APAGADO",D4:D601,"=INTERCOMUNICADOR") -> 0 | N3: =COUNTIFS(N6:N603, "=APAGADO",D4:D601,"=INTERCOMUNICADOR") -> 0 | O3: =COUNTIFS(O6:O603, "=APAGADO",D4:D601,"=INTERCOMUNICADOR") -> 0 | P3: =COUNTIFS(P6:P603, "=APAGADO",D4:D601,"=INTERCOMUNICADOR") -> 0 | Q3: =COUNTIFS(Q6:Q603, "=APAGADO",D4:D601,"=INTERCOMUNICADOR") -> 0 | R3: =COUNTIFS(R6:R603, "=APAGADO",D4:D601,"=INTERCOMUNICADOR") -> 0 | S3: =COUNTIFS(S6:S603, "=APAGADO",D4:D601,"=INTERCOMUNICADOR") -> 0 | T3: =COUNTIFS(T6:T603, "=APAGADO",D4:D601,"=INTERCOMUNICADOR") -> 0 | U3: =COUNTIFS(U6:U603, "=APAGADO",D4:D601,"=INTERCOMUNICADOR") -> 0 | V3: =COUNTIFS(V6:V603, "=APAGADO",D4:D601,"=INTERCOMUNICADOR") -> 0 | W3: =COUNTIFS(W6:W603, "=APAGADO",D4:D601,"=INTERCOMUNICADOR") -> 0 | X3: =COUNTIFS(X6:X603, "=APAGADO",D4:D601,"=INTERCOMUNICADOR") -> 0 | Y3: =COUNTIFS(Y6:Y603, "=APAGADO",D4:D601,"=INTERCOMUNICADOR") -> 0 | Z3: =COUNTIFS(Z6:Z603, "=APAGADO",D4:D601,"=INTERCOMUNICADOR") -> 0 | AA3: =COUNTIFS(AA6:AA603, "=APAGADO",D4:D601,"=INTERCOMUNICADOR") -> 0 | AB3: =COUNTIFS(AB6:AB603, "=APAGADO",D4:D601,"=INTERCOMUNICADOR") -> 0 | AC3: =COUNTIFS(AC6:AC603, "=APAGADO",D4:D601,"=INTERCOMUNICADOR") -> 0 | AD3: =COUNTIFS(AD6:AD603, "=APAGADO",D4:D601,"=INTERCOMUNICADOR") -> 0 | AE3: =COUNTIFS(AE6:AE603, "=APAGADO",D4:D601,"=INTERCOMUNICADOR") -> 0 | AF3: =COUNTIFS(AF6:AF603, "=APAGADO",D4:D601,"=INTERCOMUNICADOR") -> 0 | AG3: =COUNTIFS(AG6:AG603, "=APAGADO",D4:D601,"=INTERCOMUNICADOR") -> 0 | AH3: =COUNTIFS(AH6:AH603, "=APAGADO",E4:E601,"=INTERCOMUNICADOR") -> 0 | AI3: =COUNTIFS(AI6:AI603, "=APAGADO",F4:F601,"=INTERCOMUNICADOR") -> 0 | AJ3: =COUNTIFS(AJ6:AJ603, "=APAGADO",G4:G601,"=INTERCOMUNICADOR") -> 0
A4: ='RESUMEN TOTAL'!F7 -> Barrio | B4: ='RESUMEN TOTAL'!G7 -> [Denominacion] | C4: ='RESUMEN TOTAL'!I7 -> [Ubicacion] | D4: ='RESUMEN TOTAL'!J7 -> [Tipo de Camara] | E4: ='RESUMEN TOTAL'!K7 -> [Tipo de Conexion] | F4: ='RESUMEN TOTAL'!S7 -> 46113 | G4: ='RESUMEN TOTAL'!T7 -> 46114 | H4: ='RESUMEN TOTAL'!U7 -> 46115 | I4: ='RESUMEN TOTAL'!V7 -> 46116 | J4: ='RESUMEN TOTAL'!W7 -> 46117 | K4: ='RESUMEN TOTAL'!X7 -> 46118 | L4: ='RESUMEN TOTAL'!Y7 -> 46119 | M4: ='RESUMEN TOTAL'!Z7 -> 46120 | ... AI4: ='RESUMEN TOTAL'!AV7 -> 46142 | AJ4: ='RESUMEN TOTAL'!#REF! -> #REF! | XEY4: =SUM(F4:XEX4) -> #REF!
A5: ='RESUMEN TOTAL'!F8 -> ZEBALLOS | B5: ='RESUMEN TOTAL'!G8 -> ZEB04 | C5: ='RESUMEN TOTAL'!I8 -> THEVENET Y DIAGONAL GRANADEROS | D5: ='RESUMEN TOTAL'!J8 -> DOMO | E5: ='RESUMEN TOTAL'!K8 -> GPON | F5: ='RESUMEN TOTAL'!S8 -> 0 | G5: ='RESUMEN TOTAL'!T8 -> 0 | H5: ='RESUMEN TOTAL'!U8 -> 0 | I5: ='RESUMEN TOTAL'!V8 -> 0 | J5: ='RESUMEN TOTAL'!W8 -> 0 | K5: ='RESUMEN TOTAL'!X8 -> 0 | L5: ='RESUMEN TOTAL'!Y8 -> 0 | M5: ='RESUMEN TOTAL'!Z8 -> 0 | ... AI5: ='RESUMEN TOTAL'!AV8 -> 0 | AJ5: ='RESUMEN TOTAL'!#REF! -> #REF!
A6: ='RESUMEN TOTAL'!F9 -> 9 DE JULIO | B6: ='RESUMEN TOTAL'!G9 -> ZEB03 | C6: ='RESUMEN TOTAL'!I9 -> Quinquela Martin y Pte. Peron | D6: ='RESUMEN TOTAL'!J9 -> Domo | E6: ='RESUMEN TOTAL'!K9 -> GPON | F6: ='RESUMEN TOTAL'!S9 -> 0 | G6: ='RESUMEN TOTAL'!T9 -> 0 | H6: ='RESUMEN TOTAL'!U9 -> 0 | I6: ='RESUMEN TOTAL'!V9 -> 0 | J6: ='RESUMEN TOTAL'!W9 -> 0 | K6: ='RESUMEN TOTAL'!X9 -> 0 | L6: ='RESUMEN TOTAL'!Y9 -> 0 | M6: ='RESUMEN TOTAL'!Z9 -> 0 | ... AI6: ='RESUMEN TOTAL'!AV9 -> 0 | AJ6: ='RESUMEN TOTAL'!#REF! -> #REF!
A7: ='RESUMEN TOTAL'!F10 -> ZEBALLOS | B7: ='RESUMEN TOTAL'!G10 -> ZEB02 | C7: ='RESUMEN TOTAL'!I10 -> Quinquela Martin y Sgo. del Estero | D7: ='RESUMEN TOTAL'!J10 -> Domo | E7: ='RESUMEN TOTAL'!K10 -> GPON | F7: ='RESUMEN TOTAL'!S10 -> 0 | G7: ='RESUMEN TOTAL'!T10 -> 0 | H7: ='RESUMEN TOTAL'!U10 -> 0 | I7: ='RESUMEN TOTAL'!V10 -> 0 | J7: ='RESUMEN TOTAL'!W10 -> 0 | K7: ='RESUMEN TOTAL'!X10 -> 0 | L7: ='RESUMEN TOTAL'!Y10 -> 0 | M7: ='RESUMEN TOTAL'!Z10 -> 0 | ... AI7: ='RESUMEN TOTAL'!AV10 -> 0 | AJ7: ='RESUMEN TOTAL'!#REF! -> #REF!
A8: ='RESUMEN TOTAL'!F11 -> ZEBALLOS | B8: ='RESUMEN TOTAL'!G11 -> ZEB 10 | C8: ='RESUMEN TOTAL'!I11 -> Sallares y Jujuy | D8: ='RESUMEN TOTAL'!J11 -> DOMO | E8: ='RESUMEN TOTAL'!K11 -> GPON | F8: ='RESUMEN TOTAL'!S11 -> 0 | G8: ='RESUMEN TOTAL'!T11 -> 0 | H8: ='RESUMEN TOTAL'!U11 -> 0 | I8: ='RESUMEN TOTAL'!V11 -> 0 | J8: ='RESUMEN TOTAL'!W11 -> 0 | K8: ='RESUMEN TOTAL'!X11 -> 0 | L8: ='RESUMEN TOTAL'!Y11 -> 0 | M8: ='RESUMEN TOTAL'!Z11 -> 0 | ... AI8: ='RESUMEN TOTAL'!AV11 -> 0 | AJ8: ='RESUMEN TOTAL'!#REF! -> #REF!
A9: ='RESUMEN TOTAL'!F12 -> ZEBALLOS | B9: ='RESUMEN TOTAL'!G12 -> ZEB 09 | C9: ='RESUMEN TOTAL'!I12 -> Tte.Gral Peron y Salta | D9: ='RESUMEN TOTAL'!J12 -> DOMO | E9: ='RESUMEN TOTAL'!K12 -> GPON | F9: ='RESUMEN TOTAL'!S12 -> 0 | G9: ='RESUMEN TOTAL'!T12 -> 0 | H9: ='RESUMEN TOTAL'!U12 -> 0 | I9: ='RESUMEN TOTAL'!V12 -> 0 | J9: ='RESUMEN TOTAL'!W12 -> 0 | K9: ='RESUMEN TOTAL'!X12 -> 0 | L9: ='RESUMEN TOTAL'!Y12 -> 0 | M9: ='RESUMEN TOTAL'!Z12 -> 0 | ... AI9: ='RESUMEN TOTAL'!AV12 -> 0 | AJ9: ='RESUMEN TOTAL'!#REF! -> #REF!
A10: ='RESUMEN TOTAL'!F13 -> ZEBALLOS | B10: ='RESUMEN TOTAL'!G13 -> ZEB 08 (Fija 2) | C10: ='RESUMEN TOTAL'!I13 -> Quinquela Martin y 861 | D10: ='RESUMEN TOTAL'!J13 -> Fija | E10: ='RESUMEN TOTAL'!K13 -> GPON | F10: ='RESUMEN TOTAL'!S13 -> 0 | G10: ='RESUMEN TOTAL'!T13 -> 0 | H10: ='RESUMEN TOTAL'!U13 -> 0 | I10: ='RESUMEN TOTAL'!V13 -> 0 | J10: ='RESUMEN TOTAL'!W13 -> 0 | K10: ='RESUMEN TOTAL'!X13 -> 0 | L10: ='RESUMEN TOTAL'!Y13 -> 0 | M10: ='RESUMEN TOTAL'!Z13 -> 0 | ... AI10: ='RESUMEN TOTAL'!AV13 -> 0 | AJ10: ='RESUMEN TOTAL'!#REF! -> #REF!
A11: ='RESUMEN TOTAL'!F14 -> ZEBALLOS | B11: ='RESUMEN TOTAL'!G14 -> ZEB 07 (Fija 1) | C11: ='RESUMEN TOTAL'!I14 -> Quinquela Martn y 861 | D11: ='RESUMEN TOTAL'!J14 -> Fija | E11: ='RESUMEN TOTAL'!K14 -> GPON | F11: ='RESUMEN TOTAL'!S14 -> 0 | G11: ='RESUMEN TOTAL'!T14 -> 0 | H11: ='RESUMEN TOTAL'!U14 -> 0 | I11: ='RESUMEN TOTAL'!V14 -> 0 | J11: ='RESUMEN TOTAL'!W14 -> 0 | K11: ='RESUMEN TOTAL'!X14 -> 0 | L11: ='RESUMEN TOTAL'!Y14 -> 0 | M11: ='RESUMEN TOTAL'!Z14 -> 0 | ... AI11: ='RESUMEN TOTAL'!AV14 -> 0 | AJ11: ='RESUMEN TOTAL'!#REF! -> #REF!
A12: ='RESUMEN TOTAL'!F15 -> ZEBALLOS | B12: ='RESUMEN TOTAL'!G15 -> ZEB 06 | C12: ='RESUMEN TOTAL'!I15 -> Peron e/Ituzaingo y Buenos Aires | D12: ='RESUMEN TOTAL'!J15 -> FIJA | E12: ='RESUMEN TOTAL'!K15 -> GPON | F12: ='RESUMEN TOTAL'!S15 -> 0 | G12: ='RESUMEN TOTAL'!T15 -> 0 | H12: ='RESUMEN TOTAL'!U15 -> 0 | I12: ='RESUMEN TOTAL'!V15 -> 0 | J12: ='RESUMEN TOTAL'!W15 -> 0 | K12: ='RESUMEN TOTAL'!X15 -> 0 | L12: ='RESUMEN TOTAL'!Y15 -> 0 | M12: ='RESUMEN TOTAL'!Z15 -> 0 | ... AI12: ='RESUMEN TOTAL'!AV15 -> 0 | AJ12: ='RESUMEN TOTAL'!#REF! -> #REF!
A13: ='RESUMEN TOTAL'!F16 -> ZEBALLOS | B13: ='RESUMEN TOTAL'!G16 -> ZEB 05 | C13: ='RESUMEN TOTAL'!I16 -> DIAG. GRANADEROS Y 214 BIS | D13: ='RESUMEN TOTAL'!J16 -> Domo | E13: ='RESUMEN TOTAL'!K16 -> GPON | F13: ='RESUMEN TOTAL'!S16 -> APAGADO | G13: ='RESUMEN TOTAL'!T16 -> 0 | H13: ='RESUMEN TOTAL'!U16 -> 0 | I13: ='RESUMEN TOTAL'!V16 -> 0 | J13: ='RESUMEN TOTAL'!W16 -> 0 | K13: ='RESUMEN TOTAL'!X16 -> APAGADO | L13: ='RESUMEN TOTAL'!Y16 -> APAGADO | M13: ='RESUMEN TOTAL'!Z16 -> APAGADO | ... AI13: ='RESUMEN TOTAL'!AV16 -> 0 | AJ13: ='RESUMEN TOTAL'!#REF! -> #REF!
A14: ='RESUMEN TOTAL'!F17 -> VILLA SUSANA | B14: ='RESUMEN TOTAL'!G17 -> VSU01 | C14: ='RESUMEN TOTAL'!I17 -> CJAL. JUAN BROWN Y SANTA FE | D14: ='RESUMEN TOTAL'!J17 -> DOMO | E14: ='RESUMEN TOTAL'!K17 -> Radio | F14: ='RESUMEN TOTAL'!S17 -> 0 | G14: ='RESUMEN TOTAL'!T17 -> 0 | H14: ='RESUMEN TOTAL'!U17 -> 0 | I14: ='RESUMEN TOTAL'!V17 -> 0 | J14: ='RESUMEN TOTAL'!W17 -> 0 | K14: ='RESUMEN TOTAL'!X17 -> 0 | L14: ='RESUMEN TOTAL'!Y17 -> 0 | M14: ='RESUMEN TOTAL'!Z17 -> 0 | ... AI14: ='RESUMEN TOTAL'!AV17 -> 0 | AJ14: ='RESUMEN TOTAL'!#REF! -> #REF!
A15: ='RESUMEN TOTAL'!F18 -> VILLA SUSANA | B15: ='RESUMEN TOTAL'!G18 -> VSU 06 | C15: CALCHAQUÍ Y GALARZA FIJA | D15: ='RESUMEN TOTAL'!J18 -> DOMO | F15: ='RESUMEN TOTAL'!S18 -> 0 | G15: ='RESUMEN TOTAL'!T18 -> 0 | H15: ='RESUMEN TOTAL'!U18 -> 0 | I15: ='RESUMEN TOTAL'!V18 -> 0 | J15: ='RESUMEN TOTAL'!W18 -> 0 | K15: ='RESUMEN TOTAL'!X18 -> 0 | L15: ='RESUMEN TOTAL'!Y18 -> 0 | M15: ='RESUMEN TOTAL'!Z18 -> 0 | ... AI15: ='RESUMEN TOTAL'!AV18 -> 0 | AJ15: ='RESUMEN TOTAL'!#REF! -> #REF!
A16: ='RESUMEN TOTAL'!F19 -> VILLA SUSANA | B16: ='RESUMEN TOTAL'!G19 -> VSU 05 | C16: ='RESUMEN TOTAL'!I19 -> Aniceto Diaz y Cordoba | D16: ='RESUMEN TOTAL'!J19 -> fija | E16: ='RESUMEN TOTAL'!K19 -> Fibra Optica | F16: ='RESUMEN TOTAL'!S19 -> 0 | G16: ='RESUMEN TOTAL'!T19 -> 0 | H16: ='RESUMEN TOTAL'!U19 -> 0 | I16: ='RESUMEN TOTAL'!V19 -> 0 | J16: ='RESUMEN TOTAL'!W19 -> 0 | K16: ='RESUMEN TOTAL'!X19 -> 0 | L16: ='RESUMEN TOTAL'!Y19 -> 0 | M16: ='RESUMEN TOTAL'!Z19 -> 0 | ... AI16: ='RESUMEN TOTAL'!AV19 -> 0 | AJ16: ='RESUMEN TOTAL'!#REF! -> #REF!
A17: ='RESUMEN TOTAL'!F22 -> VILLA SUSANA | B17: ='RESUMEN TOTAL'!G22 -> VSU 02 | C17: ='RESUMEN TOTAL'!I22 -> CABELLO Y SANTA FE | D17: ='RESUMEN TOTAL'!J22 -> DOMO | E17: ='RESUMEN TOTAL'!K22 -> Radio | F17: ='RESUMEN TOTAL'!S22 -> APAGADO | G17: ='RESUMEN TOTAL'!T22 -> 0 | H17: ='RESUMEN TOTAL'!U22 -> 0 | I17: ='RESUMEN TOTAL'!V22 -> 0 | J17: ='RESUMEN TOTAL'!W22 -> 0 | K17: ='RESUMEN TOTAL'!X22 -> APAGADO | L17: ='RESUMEN TOTAL'!Y22 -> APAGADO | M17: ='RESUMEN TOTAL'!Z22 -> 0 | ... AI17: ='RESUMEN TOTAL'!AV22 -> 0 | AJ17: ='RESUMEN TOTAL'!#REF! -> #REF!
A18: ='RESUMEN TOTAL'!F23 -> VILLA SAN LUIS | B18: ='RESUMEN TOTAL'!G23 -> VSL 03 | C18: ='RESUMEN TOTAL'!I23 -> 1314 y 1371 | D18: ='RESUMEN TOTAL'!J23 -> DOMO | E18: ='RESUMEN TOTAL'!K23 -> GPON | F18: ='RESUMEN TOTAL'!S23 -> 0 | G18: ='RESUMEN TOTAL'!T23 -> 0 | H18: ='RESUMEN TOTAL'!U23 -> 0 | I18: ='RESUMEN TOTAL'!V23 -> 0 | J18: ='RESUMEN TOTAL'!W23 -> 0 | K18: ='RESUMEN TOTAL'!X23 -> 0 | L18: ='RESUMEN TOTAL'!Y23 -> 0 | M18: ='RESUMEN TOTAL'!Z23 -> 0 | ... AI18: ='RESUMEN TOTAL'!AV23 -> 0 | AJ18: ='RESUMEN TOTAL'!#REF! -> #REF!
A19: ='RESUMEN TOTAL'!F24 -> VILLA SAN LUIS | B19: ='RESUMEN TOTAL'!G24 -> VSL 02 | C19: ='RESUMEN TOTAL'!I24 -> 1355 Y 1314 | D19: ='RESUMEN TOTAL'!J24 -> DOMO | E19: ='RESUMEN TOTAL'!K24 -> GPON | F19: ='RESUMEN TOTAL'!S24 -> 0 | G19: ='RESUMEN TOTAL'!T24 -> 0 | H19: ='RESUMEN TOTAL'!U24 -> 0 | I19: ='RESUMEN TOTAL'!V24 -> 0 | J19: ='RESUMEN TOTAL'!W24 -> 0 | K19: ='RESUMEN TOTAL'!X24 -> 0 | L19: ='RESUMEN TOTAL'!Y24 -> 0 | M19: ='RESUMEN TOTAL'!Z24 -> 0 | ... AI19: ='RESUMEN TOTAL'!AV24 -> 0 | AJ19: ='RESUMEN TOTAL'!#REF! -> #REF!
A20: ='RESUMEN TOTAL'!F25 -> VILLA SAN LUIS | B20: ='RESUMEN TOTAL'!G25 -> VSL 01 | C20: ='RESUMEN TOTAL'!I25 -> AV. HUDSON Y CACHEUTA | D20: ='RESUMEN TOTAL'!J25 -> DOMO | E20: ='RESUMEN TOTAL'!K25 -> GPON | F20: ='RESUMEN TOTAL'!S25 -> 0 | G20: ='RESUMEN TOTAL'!T25 -> 0 | H20: ='RESUMEN TOTAL'!U25 -> 0 | I20: ='RESUMEN TOTAL'!V25 -> 0 | J20: ='RESUMEN TOTAL'!W25 -> 0 | K20: ='RESUMEN TOTAL'!X25 -> 0 | L20: ='RESUMEN TOTAL'!Y25 -> 0 | M20: ='RESUMEN TOTAL'!Z25 -> 0 | ... AI20: ='RESUMEN TOTAL'!AV25 -> 0 | AJ20: ='RESUMEN TOTAL'!#REF! -> #REF!
A21: ='RESUMEN TOTAL'!F26 -> VILLA MONICA VIEJA | B21: ='RESUMEN TOTAL'!G26 -> VMOV04 (fija 2) | C21: ='RESUMEN TOTAL'!I26 -> ROMA E/ HOLANDA Y CAFFERATA | D21: ='RESUMEN TOTAL'!J26 -> Fija | E21: ='RESUMEN TOTAL'!K26 -> Fibra Optica | F21: ='RESUMEN TOTAL'!S26 -> APAGADO | G21: ='RESUMEN TOTAL'!T26 -> 0 | H21: ='RESUMEN TOTAL'!U26 -> 0 | I21: ='RESUMEN TOTAL'!V26 -> 0 | J21: ='RESUMEN TOTAL'!W26 -> 0 | K21: ='RESUMEN TOTAL'!X26 -> 0 | L21: ='RESUMEN TOTAL'!Y26 -> 0 | M21: ='RESUMEN TOTAL'!Z26 -> 0 | ... AI21: ='RESUMEN TOTAL'!AV26 -> APAGADO | AJ21: ='RESUMEN TOTAL'!#REF! -> #REF!
A22: ='RESUMEN TOTAL'!F27 -> VILLA MONICA VIEJA | B22: ='RESUMEN TOTAL'!G27 -> VMOV01 (fija 1) | C22: ='RESUMEN TOTAL'!I27 -> ATENAS E/ CAFFERATA Y ALEMANIA | D22: ='RESUMEN TOTAL'!J27 -> Fija | E22: ='RESUMEN TOTAL'!K27 -> Fibra Optica | F22: ='RESUMEN TOTAL'!S27 -> APAGADO | G22: ='RESUMEN TOTAL'!T27 -> 0 | H22: ='RESUMEN TOTAL'!U27 -> 0 | I22: ='RESUMEN TOTAL'!V27 -> 0 | J22: ='RESUMEN TOTAL'!W27 -> 0 | K22: ='RESUMEN TOTAL'!X27 -> 0 | L22: ='RESUMEN TOTAL'!Y27 -> 0 | M22: ='RESUMEN TOTAL'!Z27 -> 0 | ... AI22: ='RESUMEN TOTAL'!AV27 -> APAGADO | AJ22: ='RESUMEN TOTAL'!#REF! -> #REF!
A23: ='RESUMEN TOTAL'!F28 -> VILLA MONICA VIEJA | B23: ='RESUMEN TOTAL'!G28 -> VMOV 03 (fija 1) | C23: ='RESUMEN TOTAL'!I28 -> ROMA E/ HOLANDA Y CAFFERATA | D23: ='RESUMEN TOTAL'!J28 -> Fija | E23: ='RESUMEN TOTAL'!K28 -> Fibra Optica | F23: ='RESUMEN TOTAL'!S28 -> APAGADO | G23: ='RESUMEN TOTAL'!T28 -> 0 | H23: ='RESUMEN TOTAL'!U28 -> 0 | I23: ='RESUMEN TOTAL'!V28 -> 0 | J23: ='RESUMEN TOTAL'!W28 -> 0 | K23: ='RESUMEN TOTAL'!X28 -> 0 | L23: ='RESUMEN TOTAL'!Y28 -> 0 | M23: ='RESUMEN TOTAL'!Z28 -> 0 | ... AI23: ='RESUMEN TOTAL'!AV28 -> APAGADO | AJ23: ='RESUMEN TOTAL'!#REF! -> #REF!
A24: ='RESUMEN TOTAL'!F29 -> VILLA MONICA VIEJA | B24: ='RESUMEN TOTAL'!G29 -> VMOV 02 (fija 2) | C24: ='RESUMEN TOTAL'!I29 -> ATENAS E/ CAFFERATA Y ALEMANIA | D24: ='RESUMEN TOTAL'!J29 -> Fija | E24: ='RESUMEN TOTAL'!K29 -> Fibra Optica | F24: ='RESUMEN TOTAL'!S29 -> APAGADO | G24: ='RESUMEN TOTAL'!T29 -> 0 | H24: ='RESUMEN TOTAL'!U29 -> 0 | I24: ='RESUMEN TOTAL'!V29 -> 0 | J24: ='RESUMEN TOTAL'!W29 -> 0 | K24: ='RESUMEN TOTAL'!X29 -> 0 | L24: ='RESUMEN TOTAL'!Y29 -> 0 | M24: ='RESUMEN TOTAL'!Z29 -> 0 | ... AI24: ='RESUMEN TOTAL'!AV29 -> APAGADO | AJ24: ='RESUMEN TOTAL'!#REF! -> #REF!
A25: ='RESUMEN TOTAL'!F48 -> VILLA DEL PLATA | B25: ='RESUMEN TOTAL'!G48 -> VDPL08 | C25: ='RESUMEN TOTAL'!I48 -> Tte. Gral Perón y Tunez | D25: ='RESUMEN TOTAL'!J48 -> DOMO | E25: ='RESUMEN TOTAL'!K48 -> GPON | F25: ='RESUMEN TOTAL'!S48 -> 0 | G25: ='RESUMEN TOTAL'!T48 -> 0 | H25: ='RESUMEN TOTAL'!U48 -> 0 | I25: ='RESUMEN TOTAL'!V48 -> 0 | J25: ='RESUMEN TOTAL'!W48 -> 0 | K25: ='RESUMEN TOTAL'!X48 -> 0 | L25: ='RESUMEN TOTAL'!Y48 -> 0 | M25: ='RESUMEN TOTAL'!Z48 -> 0 | ... AI25: ='RESUMEN TOTAL'!AV48 -> 0 | AJ25: ='RESUMEN TOTAL'!#REF! -> #REF!
A26: ='RESUMEN TOTAL'!F49 -> VILLA ANGELICA | B26: ='RESUMEN TOTAL'!G49 -> VDPL07 | C26: ='RESUMEN TOTAL'!I49 -> Berutti y Casares | D26: ='RESUMEN TOTAL'!J49 -> DOMO | E26: ='RESUMEN TOTAL'!K49 -> GPON | F26: ='RESUMEN TOTAL'!S49 -> 0 | G26: ='RESUMEN TOTAL'!T49 -> 0 | H26: ='RESUMEN TOTAL'!U49 -> 0 | I26: ='RESUMEN TOTAL'!V49 -> 0 | J26: ='RESUMEN TOTAL'!W49 -> 0 | K26: ='RESUMEN TOTAL'!X49 -> 0 | L26: ='RESUMEN TOTAL'!Y49 -> 0 | M26: ='RESUMEN TOTAL'!Z49 -> 0 | ... AI26: ='RESUMEN TOTAL'!AV49 -> APAGADO | AJ26: ='RESUMEN TOTAL'!#REF! -> #REF!
A27: ='RESUMEN TOTAL'!F50 -> VILLA ANGELICA | B27: ='RESUMEN TOTAL'!G50 -> VDPL06 | C27: ='RESUMEN TOTAL'!I50 -> Thevenet e/ Islas Orcadas y Gardel | D27: ='RESUMEN TOTAL'!J50 -> Domo | E27: ='RESUMEN TOTAL'!K50 -> GPON | F27: ='RESUMEN TOTAL'!S50 -> 0 | G27: ='RESUMEN TOTAL'!T50 -> 0 | H27: ='RESUMEN TOTAL'!U50 -> 0 | I27: ='RESUMEN TOTAL'!V50 -> 0 | J27: ='RESUMEN TOTAL'!W50 -> 0 | K27: ='RESUMEN TOTAL'!X50 -> 0 | L27: ='RESUMEN TOTAL'!Y50 -> 0 | M27: ='RESUMEN TOTAL'!Z50 -> 0 | ... AI27: ='RESUMEN TOTAL'!AV50 -> 0 | AJ27: ='RESUMEN TOTAL'!#REF! -> #REF!
A28: ='RESUMEN TOTAL'!F51 -> VILLA DEL PLATA | B28: ='RESUMEN TOTAL'!G51 -> VDPL05 | C28: ='RESUMEN TOTAL'!I51 -> Ruta 36 y Abraham | D28: ='RESUMEN TOTAL'!J51 -> Domo | E28: ='RESUMEN TOTAL'!K51 -> PTO A FO | F28: ='RESUMEN TOTAL'!S51 -> 0 | G28: ='RESUMEN TOTAL'!T51 -> 0 | H28: ='RESUMEN TOTAL'!U51 -> 0 | I28: ='RESUMEN TOTAL'!V51 -> 0 | J28: ='RESUMEN TOTAL'!W51 -> 0 | K28: ='RESUMEN TOTAL'!X51 -> 0 | L28: ='RESUMEN TOTAL'!Y51 -> 0 | M28: ='RESUMEN TOTAL'!Z51 -> 0 | ... AI28: ='RESUMEN TOTAL'!AV51 -> APAGADO | AJ28: ='RESUMEN TOTAL'!#REF! -> #REF!
A29: ='RESUMEN TOTAL'!F52 -> VILLA DEL PLATA | B29: ='RESUMEN TOTAL'!G52 -> VDPL04 | C29: ='RESUMEN TOTAL'!I52 -> Neuquen y Diagonal Guemes | D29: ='RESUMEN TOTAL'!J52 -> Domo | E29: ='RESUMEN TOTAL'!K52 -> GPON | F29: ='RESUMEN TOTAL'!S52 -> APAGADO | G29: ='RESUMEN TOTAL'!T52 -> 0 | H29: ='RESUMEN TOTAL'!U52 -> 0 | I29: ='RESUMEN TOTAL'!V52 -> 0 | J29: ='RESUMEN TOTAL'!W52 -> 0 | K29: ='RESUMEN TOTAL'!X52 -> APAGADO | L29: ='RESUMEN TOTAL'!Y52 -> APAGADO | M29: ='RESUMEN TOTAL'!Z52 -> APAGADO | ... AI29: ='RESUMEN TOTAL'!AV52 -> 0 | AJ29: ='RESUMEN TOTAL'!#REF! -> #REF!
A30: ='RESUMEN TOTAL'!F53 -> VILLA DEL PLATA | B30: ='RESUMEN TOTAL'!G53 -> VDPL03 | C30: ='RESUMEN TOTAL'!I53 -> Neuquen y Alvarado | D30: ='RESUMEN TOTAL'!J53 -> Domo | E30: ='RESUMEN TOTAL'!K53 -> GPON | F30: ='RESUMEN TOTAL'!S53 -> 0 | G30: ='RESUMEN TOTAL'!T53 -> 0 | H30: ='RESUMEN TOTAL'!U53 -> 0 | I30: ='RESUMEN TOTAL'!V53 -> 0 | J30: ='RESUMEN TOTAL'!W53 -> 0 | K30: ='RESUMEN TOTAL'!X53 -> 0 | L30: ='RESUMEN TOTAL'!Y53 -> 0 | M30: ='RESUMEN TOTAL'!Z53 -> 0 | ... AI30: ='RESUMEN TOTAL'!AV53 -> 0 | AJ30: ='RESUMEN TOTAL'!#REF! -> #REF!
A31: ='RESUMEN TOTAL'!F54 -> VILLA DEL PLATA | B31: ='RESUMEN TOTAL'!G54 -> VDPL02 | C31: ='RESUMEN TOTAL'!I54 -> Thevenet y Berutti | D31: ='RESUMEN TOTAL'!J54 -> Domo | E31: ='RESUMEN TOTAL'!K54 -> Fibra Optica | F31: ='RESUMEN TOTAL'!S54 -> 0 | G31: ='RESUMEN TOTAL'!T54 -> 0 | H31: ='RESUMEN TOTAL'!U54 -> 0 | I31: ='RESUMEN TOTAL'!V54 -> 0 | J31: ='RESUMEN TOTAL'!W54 -> 0 | K31: ='RESUMEN TOTAL'!X54 -> 0 | L31: ='RESUMEN TOTAL'!Y54 -> 0 | M31: ='RESUMEN TOTAL'!Z54 -> 0 | ... AI31: ='RESUMEN TOTAL'!AV54 -> 0 | AJ31: ='RESUMEN TOTAL'!#REF! -> #REF!
A32: ='RESUMEN TOTAL'!F55 -> VILLA DEL PLATA | B32: ='RESUMEN TOTAL'!G55 -> VDPL01 | C32: ='RESUMEN TOTAL'!I55 -> Abrahan y Delgado | D32: ='RESUMEN TOTAL'!J55 -> DOMO | E32: ='RESUMEN TOTAL'!K55 -> GPON | F32: ='RESUMEN TOTAL'!S55 -> APAGADO | G32: ='RESUMEN TOTAL'!T55 -> 0 | H32: ='RESUMEN TOTAL'!U55 -> 0 | I32: ='RESUMEN TOTAL'!V55 -> 0 | J32: ='RESUMEN TOTAL'!W55 -> 0 | K32: ='RESUMEN TOTAL'!X55 -> APAGADO | L32: ='RESUMEN TOTAL'!Y55 -> APAGADO | M32: ='RESUMEN TOTAL'!Z55 -> APAGADO | ... AI32: ='RESUMEN TOTAL'!AV55 -> 0 | AJ32: ='RESUMEN TOTAL'!#REF! -> #REF!
A33: ='RESUMEN TOTAL'!F56 -> VILLA CIRIO | B33: ='RESUMEN TOTAL'!G56 -> VCIR01 | C33: ='RESUMEN TOTAL'!I56 -> San Martin e Yrigoyen | D33: ='RESUMEN TOTAL'!J56 -> FIJA | E33: ='RESUMEN TOTAL'!K56 -> Fibra Optica | F33: ='RESUMEN TOTAL'!S56 -> 0 | G33: ='RESUMEN TOTAL'!T56 -> 0 | H33: ='RESUMEN TOTAL'!U56 -> 0 | I33: ='RESUMEN TOTAL'!V56 -> 0 | J33: ='RESUMEN TOTAL'!W56 -> 0 | K33: ='RESUMEN TOTAL'!X56 -> 0 | L33: ='RESUMEN TOTAL'!Y56 -> 0 | M33: ='RESUMEN TOTAL'!Z56 -> 0 | ... AI33: ='RESUMEN TOTAL'!AV56 -> APAGADO | AJ33: ='RESUMEN TOTAL'!#REF! -> #REF!
A34: ='RESUMEN TOTAL'!F57 -> VILLA AURORA | B34: ='RESUMEN TOTAL'!G57 -> VAU08 | C34: ='RESUMEN TOTAL'!I57 -> MONTEVERDE Y WASHINGTON | D34: ='RESUMEN TOTAL'!J57 -> DOMO | E34: ='RESUMEN TOTAL'!K57 -> Fibra Optica | F34: ='RESUMEN TOTAL'!S57 -> 0 | G34: ='RESUMEN TOTAL'!T57 -> 0 | H34: ='RESUMEN TOTAL'!U57 -> 0 | I34: ='RESUMEN TOTAL'!V57 -> 0 | J34: ='RESUMEN TOTAL'!W57 -> 0 | K34: ='RESUMEN TOTAL'!X57 -> 0 | L34: ='RESUMEN TOTAL'!Y57 -> 0 | M34: ='RESUMEN TOTAL'!Z57 -> 0 | ... AI34: ='RESUMEN TOTAL'!AV57 -> 0 | AJ34: ='RESUMEN TOTAL'!#REF! -> #REF!
A35: ='RESUMEN TOTAL'!F58 -> VILLA AURORA | B35: ='RESUMEN TOTAL'!G58 -> VAU06 (fija 2) | C35: ='RESUMEN TOTAL'!I58 -> GUIDO SPANO Y VICTORINO DE LA PLAZA | D35: ='RESUMEN TOTAL'!J58 -> Fija | E35: ='RESUMEN TOTAL'!K58 -> Fibra Optica | F35: ='RESUMEN TOTAL'!S58 -> 0 | G35: ='RESUMEN TOTAL'!T58 -> 0 | H35: ='RESUMEN TOTAL'!U58 -> 0 | I35: ='RESUMEN TOTAL'!V58 -> 0 | J35: ='RESUMEN TOTAL'!W58 -> 0 | K35: ='RESUMEN TOTAL'!X58 -> 0 | L35: ='RESUMEN TOTAL'!Y58 -> 0 | M35: ='RESUMEN TOTAL'!Z58 -> 0 | ... AI35: ='RESUMEN TOTAL'!AV58 -> 0 | AJ35: ='RESUMEN TOTAL'!#REF! -> #REF!
A36: ='RESUMEN TOTAL'!F59 -> VILLA AURORA | B36: ='RESUMEN TOTAL'!G59 -> VAU05 (fija 1) | C36: ='RESUMEN TOTAL'!I59 -> GUIDO SPANO Y VICTORINO DE LA PLAZA | D36: ='RESUMEN TOTAL'!J59 -> Fija | E36: ='RESUMEN TOTAL'!K59 -> Fibra Optica | F36: ='RESUMEN TOTAL'!S59 -> 0 | G36: ='RESUMEN TOTAL'!T59 -> 0 | H36: ='RESUMEN TOTAL'!U59 -> 0 | I36: ='RESUMEN TOTAL'!V59 -> 0 | J36: ='RESUMEN TOTAL'!W59 -> 0 | K36: ='RESUMEN TOTAL'!X59 -> 0 | L36: ='RESUMEN TOTAL'!Y59 -> 0 | M36: ='RESUMEN TOTAL'!Z59 -> 0 | ... AI36: ='RESUMEN TOTAL'!AV59 -> 0 | AJ36: ='RESUMEN TOTAL'!#REF! -> #REF!
... A71: ='RESUMEN TOTAL'!F94 -> VILLA VATTEONE | B71: ='RESUMEN TOTAL'!G94 -> VAT 15 | C71: ='RESUMEN TOTAL'!I94 -> CORRIENTES Y VICENTE LOPEZ | D71: ='RESUMEN TOTAL'!J94 -> DOMO | E71: ='RESUMEN TOTAL'!K94 -> PTO A FO | F71: ='RESUMEN TOTAL'!S94 -> 0 | G71: ='RESUMEN TOTAL'!T94 -> 0 | H71: ='RESUMEN TOTAL'!U94 -> 0 | I71: ='RESUMEN TOTAL'!V94 -> 0 | J71: ='RESUMEN TOTAL'!W94 -> 0 | K71: ='RESUMEN TOTAL'!X94 -> 0 | L71: ='RESUMEN TOTAL'!Y94 -> 0 | M71: ='RESUMEN TOTAL'!Z94 -> 0 | ... AI71: ='RESUMEN TOTAL'!AV94 -> 0 | AJ71: ='RESUMEN TOTAL'!#REF! -> #REF!
A72: ='RESUMEN TOTAL'!F95 -> VILLA VATTEONE | B72: ='RESUMEN TOTAL'!G95 -> VAT 14 | C72: ='RESUMEN TOTAL'!I95 -> FLORIDA Y MONTEVIDEO | D72: ='RESUMEN TOTAL'!J95 -> DOMO | E72: ='RESUMEN TOTAL'!K95 -> Fibra Optica | F72: ='RESUMEN TOTAL'!S95 -> APAGADO | G72: ='RESUMEN TOTAL'!T95 -> 0 | H72: ='RESUMEN TOTAL'!U95 -> 0 | I72: ='RESUMEN TOTAL'!V95 -> 0 | J72: ='RESUMEN TOTAL'!W95 -> 0 | K72: ='RESUMEN TOTAL'!X95 -> APAGADO | L72: ='RESUMEN TOTAL'!Y95 -> APAGADO | M72: ='RESUMEN TOTAL'!Z95 -> APAGADO | ... Z72: ='RESUMEN TOTAL'!AM95 -> 0 | AA72: ='RESUMEN TOTAL'!#REF! -> #REF! | AB72: ='RESUMEN TOTAL'!AO95 -> 0 | AC72: ='RESUMEN TOTAL'!AP95 -> 0 | AD72: ='RESUMEN TOTAL'!AQ95 -> 0 | AE72: ='RESUMEN TOTAL'!AR95 -> 0 | AF72: ='RESUMEN TOTAL'!AS95 -> APAGADO | AG72: ='RESUMEN TOTAL'!AT95 -> APAGADO | AH72: ='RESUMEN TOTAL'!AU95 -> APAGADO | AI72: ='RESUMEN TOTAL'!AV95 -> APAGADO | AJ72: ='RESUMEN TOTAL'!#REF! -> #REF!
A73: ='RESUMEN TOTAL'!F96 -> VILLA VATTEONE CENTRO | B73: ='RESUMEN TOTAL'!G96 -> VAT 10 | C73: ='RESUMEN TOTAL'!I96 -> Belgrano y Quintana | D73: ='RESUMEN TOTAL'!J96 -> Domo | E73: ='RESUMEN TOTAL'!K96 -> Fibra Optica | F73: ='RESUMEN TOTAL'!S96 -> 0 | G73: ='RESUMEN TOTAL'!T96 -> 0 | H73: ='RESUMEN TOTAL'!U96 -> 0 | I73: ='RESUMEN TOTAL'!V96 -> 0 | J73: ='RESUMEN TOTAL'!W96 -> 0 | K73: ='RESUMEN TOTAL'!X96 -> 0 | L73: ='RESUMEN TOTAL'!Y96 -> 0 | M73: ='RESUMEN TOTAL'!Z96 -> 0 | ... AI73: ='RESUMEN TOTAL'!AV96 -> 0 | AJ73: ='RESUMEN TOTAL'!#REF! -> #REF!
A74: ='RESUMEN TOTAL'!F97 -> VILLA ARGENTINA | B74: ='RESUMEN TOTAL'!G97 -> VAR14 | C74: ='RESUMEN TOTAL'!I97 -> Pportela y 517 | D74: ='RESUMEN TOTAL'!J97 -> Domo | E74: ='RESUMEN TOTAL'!K97 -> Fibra Optica | F74: ='RESUMEN TOTAL'!S97 -> 0 | G74: ='RESUMEN TOTAL'!T97 -> 0 | H74: ='RESUMEN TOTAL'!U97 -> 0 | I74: ='RESUMEN TOTAL'!V97 -> 0 | J74: ='RESUMEN TOTAL'!W97 -> 0 | K74: ='RESUMEN TOTAL'!X97 -> 0 | L74: ='RESUMEN TOTAL'!Y97 -> 0 | M74: ='RESUMEN TOTAL'!Z97 -> 0 | ... AI74: ='RESUMEN TOTAL'!AV97 -> 0 | AJ74: ='RESUMEN TOTAL'!#REF! -> #REF!
...

Sheet Hoja1
B1: CAMARAS | C1: 45992
A2: BONOMO | B2: =COUNTIFS('RESUMEN TOTAL'!H8:H627,"=BONOMO") -> 308 | C2: 0 | F2: 46113 | G2: 46114 | H2: 46115 | I2: 46116 | J2: 46117 | K2: 46118 | L2: 46119 | M2: 46120 | N2: 46121 | O2: 46122 | P2: 46123 | Q2: 46124 | R2: 46125 | S2: 46126 | T2: 46127 | U2: 46128 | V2: 46129 | W2: 46130 | X2: 46131 | Y2: 46132 | Z2: 46133 | AA2: 46134 | AB2: 46135 | AC2: 46136 | AD2: 46137 | AE2: 46138 | AF2: 46139 | AG2: 46140 | AH2: 46141 | AI2: 46142 | AJ2: 46143
C3: 0 | D3: BONOMO | E3: APAGADAS BONOMO | F3: 0 | G3: 27 | H3: 31 | I3: 29 | J3: 29 | K3: =COUNTIFS('RESUMEN TOTAL'!X8:X704,"=APAGADO",'RESUMEN TOTAL'!H8:H704,"=BONOMO") -> 42 | L3: =COUNTIFS('RESUMEN TOTAL'!Y8:Y704,"=APAGADO",'RESUMEN TOTAL'!I8:I704,"=BONOMO") -> 0 | M3: 0 | N3: =COUNTIFS('RESUMEN TOTAL'!AA8:AA704,"=APAGADO",'RESUMEN TOTAL'!H8:H704,"=BONOMO") -> 0 | O3: =COUNTIFS('RESUMEN TOTAL'!AB8:AB704,"=APAGADO",'RESUMEN TOTAL'!H8:H704,"=BONOMO") -> 0 | P3: =COUNTIFS('RESUMEN TOTAL'!AC8:AC704,"=APAGADO",'RESUMEN TOTAL'!H8:H704,"=BONOMO") -> 0 | Q3: =COUNTIFS('RESUMEN TOTAL'!AD8:AD704,"=APAGADO",'RESUMEN TOTAL'!H8:H704,"=BONOMO") -> 0 | R3: =COUNTIFS('RESUMEN TOTAL'!AE8:AE704,"=APAGADO",'RESUMEN TOTAL'!H8:H704,"=BONOMO") -> 59 | S3: =COUNTIFS('RESUMEN TOTAL'!AF8:AF704,"=APAGADO",'RESUMEN TOTAL'!H8:H704,"=BONOMO") -> 84 | T3: =COUNTIFS('RESUMEN TOTAL'!AG8:AG704,"=APAGADO",'RESUMEN TOTAL'!H8:H704,"=BONOMO") -> 73 | U3: =COUNTIFS('RESUMEN TOTAL'!AH8:AH704,"=APAGADO",'RESUMEN TOTAL'!H8:H704,"=BONOMO") -> 59 | V3: =COUNTIFS('RESUMEN TOTAL'!AI8:AI704,"=APAGADO",'RESUMEN TOTAL'!H8:H704,"=BONOMO") -> 60 | W3: =COUNTIFS('RESUMEN TOTAL'!AJ8:AJ704,"=APAGADO",'RESUMEN TOTAL'!H8:H704,"=BONOMO") -> 0 | X3: =COUNTIFS('RESUMEN TOTAL'!AK8:AK704,"=APAGADO",'RESUMEN TOTAL'!H8:H704,"=BONOMO") -> 0 | Y3: =COUNTIFS('RESUMEN TOTAL'!AL8:AL704,"=APAGADO",'RESUMEN TOTAL'!H8:H704,"=BONOMO") -> 66 | Z3: =COUNTIFS('RESUMEN TOTAL'!AM8:AM704,"=APAGADO",'RESUMEN TOTAL'!H8:H704,"=BONOMO") -> 58 | AA3: =COUNTIFS('RESUMEN TOTAL'!AN8:AN704,"=APAGADO",'RESUMEN TOTAL'!H8:H704,"=BONOMO") -> 58 | AB3: =COUNTIFS('RESUMEN TOTAL'!AO8:AO704,"=APAGADO",'RESUMEN TOTAL'!H8:H704,"=BONOMO") -> 66 | AC3: =COUNTIFS('RESUMEN TOTAL'!AP8:AP704,"=APAGADO",'RESUMEN TOTAL'!H8:H704,"=BONOMO") -> 60 | AD3: =COUNTIFS('RESUMEN TOTAL'!AQ8:AQ704,"=APAGADO",'RESUMEN TOTAL'!H8:H704,"=BONOMO") -> 0 | AE3: 29 | AF3: =COUNTIFS('RESUMEN TOTAL'!AS8:AS704,"=APAGADO",'RESUMEN TOTAL'!H8:H704,"=BONOMO") -> 48 | AG3: =COUNTIFS('RESUMEN TOTAL'!AT8:AT704,"=APAGADO",'RESUMEN TOTAL'!H8:H704,"=BONOMO") -> 53 | AH3: =COUNTIFS('RESUMEN TOTAL'!AU8:AU704,"=APAGADO",'RESUMEN TOTAL'!I8:I704,"=BONOMO") -> 0 | AI3: 48 | AJ3: =COUNTIFS('RESUMEN TOTAL'!#REF!,"=APAGADO",'RESUMEN TOTAL'!K8:K704,"=BONOMO") -> #REF!
A4: COSEIDI | B4: =COUNTIFS('RESUMEN TOTAL'!H8:H627,"=COSEIDI") -> 281 | C4: 0 | E4: % BONOMO | F4: 0 | G4: =G3/BONOMOcam -> 0.087662338 | H4: =H3/BONOMOcam -> 0.10064935 | I4: 0 | J4: 0.09 | K4: =K3/BONOMOcam -> 0.13636364 | L4: =L3/BONOMOcam -> 0 | M4: 0 | N4: =N3/BONOMOcam -> 0 | O4: =O3/BONOMOcam -> 0 | P4: =P3/BONOMOcam -> 0 | Q4: =Q3/BONOMOcam -> 0 | R4: =R3/BONOMOcam -> 0.19155844 | S4: =S3/BONOMOcam -> 0.27272727 | T4: =T3/BONOMOcam -> 0.23701299 | U4: =U3/BONOMOcam -> 0.19155844 | V4: =V3/BONOMOcam -> 0.19480519 | W4: 0 | X4: =X3/BONOMOcam -> 0 | Y4: =Y3/BONOMOcam -> 0.21428571 | Z4: =Z3/BONOMOcam -> 0.18831169 | AA4: =AA3/BONOMOcam -> 0.18831169 | AB4: =AB3/BONOMOcam -> 0.21428571 | AC4: 0 | AD4: =AD3/BONOMOcam -> 0 | AE4: =AE3/BONOMOcam -> 0.094155844 | AF4: =AF3/BONOMOcam -> 0.15584416 | AG4: =AG3/BONOMOcam -> 0.17207792 | AH4: =AH3/BONOMOcam -> 0 | AI4: =AI3/BONOMOcam -> 0.15584416 | AJ4: =AJ3/BONOMOcam -> #REF!
C5: 0 | D5: COSEIDI | E5: APAGADAS COSEIDI | F5: 0 | G5: 41 | H5: 52 | I5: 56 | J5: =COUNTIFS('RESUMEN TOTAL'!W10:W706,"=APAGADO",'RESUMEN TOTAL'!H10:H706,"=COSEIDI") -> 0 | K5: =COUNTIFS('RESUMEN TOTAL'!X10:X706,"=APAGADO",'RESUMEN TOTAL'!H10:H706,"=COSEIDI") -> 65 | L5: =COUNTIFS('RESUMEN TOTAL'!Y10:Y706,"=APAGADO",'RESUMEN TOTAL'!H10:H706,"=COSEIDI") -> 52 | M5: 0 | N5: =COUNTIFS('RESUMEN TOTAL'!AA10:AA706,"=APAGADO",'RESUMEN TOTAL'!H10:H706,"=COSEIDI") -> 0 | O5: =COUNTIFS('RESUMEN TOTAL'!AB10:AB706,"=APAGADO",'RESUMEN TOTAL'!H10:H706,"=COSEIDI") -> 0 | P5: =COUNTIFS('RESUMEN TOTAL'!AC10:AC706,"=APAGADO",'RESUMEN TOTAL'!H10:H706,"=COSEIDI") -> 0 | Q5: =COUNTIFS('RESUMEN TOTAL'!AD10:AD706,"=APAGADO",'RESUMEN TOTAL'!H10:H706,"=COSEIDI") -> 0 | R5: =COUNTIFS('RESUMEN TOTAL'!AE10:AE706,"=APAGADO",'RESUMEN TOTAL'!H10:H706,"=COSEIDI") -> 47 | S5: =COUNTIFS('RESUMEN TOTAL'!AF10:AF706,"=APAGADO",'RESUMEN TOTAL'!H10:H706,"=COSEIDI") -> 47 | T5: 0 | U5: =COUNTIFS('RESUMEN TOTAL'!AE10:AE706,"=APAGADO",'RESUMEN TOTAL'!H10:H706,"=COSEIDI") -> 47 | V5: =COUNTIFS('RESUMEN TOTAL'!AI10:AI706,"=APAGADO",'RESUMEN TOTAL'!H10:H706,"=COSEIDI") -> 65 | W5: =COUNTIFS('RESUMEN TOTAL'!AJ10:AJ706,"=APAGADO",'RESUMEN TOTAL'!H10:H706,"=COSEIDI") -> 0 | X5: =COUNTIFS('RESUMEN TOTAL'!AK10:AK706,"=APAGADO",'RESUMEN TOTAL'!H10:H706,"=COSEIDI") -> 0 | Y5: =COUNTIFS('RESUMEN TOTAL'!AL10:AL706,"=APAGADO",'RESUMEN TOTAL'!H10:H706,"=COSEIDI") -> 46 | Z5: =COUNTIFS('RESUMEN TOTAL'!AM10:AM706,"=APAGADO",'RESUMEN TOTAL'!H10:H706,"=COSEIDI") -> 41 | AA5: =COUNTIFS('RESUMEN TOTAL'!AN10:AN706,"=APAGADO",'RESUMEN TOTAL'!H10:H706,"=COSEIDI") -> 40 | AB5: =COUNTIFS('RESUMEN TOTAL'!AO10:AO706,"=APAGADO",'RESUMEN TOTAL'!H10:H706,"=COSEIDI") -> 68 | AC5: =COUNTIFS('RESUMEN TOTAL'!AP10:AP706,"=APAGADO",'RESUMEN TOTAL'!H10:H706,"=COSEIDI") -> 64 | AD5: =COUNTIFS('RESUMEN TOTAL'!AQ10:AQ706,"=APAGADO",'RESUMEN TOTAL'!H10:H706,"=COSEIDI") -> 0 | AE5: =COUNTIFS('RESUMEN TOTAL'!AR10:AR706,"=APAGADO",'RESUMEN TOTAL'!H10:H706,"=COSEIDI") -> 0 | AF5: =COUNTIFS('RESUMEN TOTAL'!AS10:AS706,"=APAGADO",'RESUMEN TOTAL'!H10:H706,"=COSEIDI") -> 74 | AG5: 0 | AH5: 0 | AI5: 66 | AJ5: 0
E6: % COSEIDI | F6: 0 | G6: =G5/COSEIDIcam -> 0.14590747 | H6: 0.18 | I6: 0 | J6: 0.14 | K6: =K5/COSEIDIcam -> 0.23131673 | L6: =L5/COSEIDIcam -> 0.18505338 | M6: 0 | N6: =N5/COSEIDIcam -> 0 | O6: =O5/COSEIDIcam -> 0 | P6: 0 | Q6: =Q5/COSEIDIcam -> 0 | R6: =R5/COSEIDIcam -> 0.16725979 | S6: =S5/COSEIDIcam -> 0.16725979 | T6: 0 | U6: 0 | V6: 0 | W6: =W5/COSEIDIcam -> 0 | X6: =X5/COSEIDIcam -> 0 | Y6: =Y5/COSEIDIcam -> 0.16370107 | Z6: =Z5/COSEIDIcam -> 0.14590747 | AA6: =AA5/COSEIDIcam -> 0.14234875 | AB6: =AB5/COSEIDIcam -> 0.24199288 | AC6: 0 | AD6: =AD5/COSEIDIcam -> 0 | AE6: =AE5/COSEIDIcam -> 0 | AF6: =AF5/COSEIDIcam -> 0.2633452 | AG6: 0 | AH6: 0 | AI6: 0 | AJ6: 0

Sheet informe
C1: CANTIDAD | D1: APAGADAS | E1: %
B2: TOTAL | C2: =CANTIDAD_DE_CAMARAS -> 589 | F2: 46113
A3: L | B3: CAIDAS | C3: ='RESUMEN TOTAL'!S3 -> 107 | E3: =C3/C2 -> 0.18166384
B4: LLEGAMOS NOSOTROS | C4: 17 | D4: =C3-C4 -> 90 | E4: =D4/C2 -> 0.15280136
B5: NO ESTA LA CAMARA | C5: 11 | D5: =D4-C5 -> 79 | E5: =D5/C2 -> 0.13412564
A6: L | B6: RADIO | C6: 16 | D6: =D5-C6 -> 63 | E6: =D6/C2 -> 0.10696095
C7: 0 | D7: 0 | E7: =D7/C2 -> 0
C8: CANTIDAD | D8: APAGADAS | E8: %
A9: F | B9: BONOMO | C9: 307 | D9: 39 | E9: =D9/C9 -> 0.12703583
A10: F | B10: COSEIDI | C10: =COSEIDIcam -> 281 | D10: 68 | E10: =D10/C10 -> 0.24199288
C12: CANTIDAD | D12: APAGADAS | E12: %
B13: TOTAL | C13: =CANTIDAD_DE_CAMARAS -> 589 | F13: 46114
A14: M | B14: CAIDAS | C14: 87 | E14: =C14/C13 -> 0.14770798
B15: LLEGAMOS NOSOTROS | C15: 3 | D15: 84 | E15: =D15/C13 -> 0.1426146
B16: NO ESTA LA CAMARA | C16: 7 | D16: 77 | E16: =D16/C13 -> 0.13073005
A17: M | B17: RADIO | C17: 5 | D17: 72 | E17: =D17/C13 -> 0.12224109
D18: 0 | E18: =D18/C13 -> 0
C19: CANTIDAD | D19: APAGADAS | E19: %
A20: G | B20: BONOMO | C20: 307 | D20: 32 | E20: =D20/C20 -> 0.10423453
A21: G | B21: COSEIDI | C21: =COSEIDIcam -> 281 | D21: 55 | E21: =D21/C21 -> 0.19572954
C23: CANTIDAD | D23: APAGADAS | E23: %
B24: TOTAL | C24: =CANTIDAD_DE_CAMARAS -> 589
A25: N | B25: CAIDAS | C25: ='RESUMEN TOTAL'!U3 -> 0 | E25: =C25/C24 -> 0
B26: LLEGAMOS NOSOTROS | C26: 6 | D26: =C25-C26 -> -6 | E26: =D26/C24 -> -0.010186757
B27: NO ESTA LA CAMARA | C27: 7 | D27: =D26-C27 -> -13 | E27: =D27/C24 -> -0.022071307
A28: N | B28: RADIO | C28: ='RESUMEN TOTAL'!U5 -> 0 | D28: =D27-C28 -> -13 | E28: =D28/C24 -> -0.022071307
C29: 0 | D29: 0 | E29: =D29/C24 -> 0
C30: CANTIDAD | D30: APAGADAS | E30: %
B31: BONOMO | C31: 307 | D31: 31 | E31: =D31/C31 -> 0.1009772
B32: COSEIDI | C32: =COSEIDIcam -> 281 | D32: 52 | E32: =D32/C32 -> 0.18505338
C34: CANTIDAD | D34: APAGADAS | E34: %
B35: TOTAL | C35: =CANTIDAD_DE_CAMARAS -> 589
A36: O | B36: CAIDAS | C36: ='RESUMEN TOTAL'!V3 -> 0 | E36: =C36/C35 -> 0
B37: LLEGAMOS NOSOTROS | C37: 7 | D37: =C36-C37 -> -7 | E37: =D37/C35 -> -0.01188455
B38: NO ESTA LA CAMARA | C38: 7 | D38: =D37-C38 -> -14 | E38: =D38/C35 -> -0.0237691
A39: O | B39: RADIO | C39: 6 | D39: =D38-C39 -> -20 | E39: =D39/C35 -> -0.033955857
C40: 0 | D40: 0 | E40: =D40/C35 -> 0
C41: CANTIDAD | D41: APAGADAS | E41: %
B42: BONOMO | C42: 307 | D42: =Hoja1!I3 -> 29 | E42: =D42/C42 -> 0.094462541
B43: COSEIDI | C43: =COSEIDIcam -> 281 | D43: =Hoja1!I5 -> 56 | E43: =D43/C43 -> 0.19928826
...
